Workbook

Sheet Instruções
B1: Pareto e folha de verificação — Como usar esta planilha
B2: Modelo para planejar a coleta, lançar as contagens, ordenar as categorias e comparar o antes com o depois.
B4: Legenda: onde preencher
B5: Amarelo-claro | C5: Células de entrada. É aqui que você digita.
B6: Cinza | C6: Células calculadas ou fixas (rótulos, totais, ordem, acumulado, classes, avisos). Não altere.
B7: Cinza em itálico | C7: Linha de exemplo (marcada com “Ex.”). Mostra o formato esperado e não entra nas contagens.
B8: Listas suspensas | C8: A base do Pareto e o status do checklist aceitam apenas as opções da lista. As contagens aceitam números inteiros.
B9: Comentários | C9: Células com triângulo vermelho no canto trazem uma dica de preenchimento. Passe o mouse sobre elas.
B11: As regras de cálculo
B12: Ordem | C12: As categorias são ordenadas do maior valor para o menor. No empate, vale a ordem da aba Coleta. “Outros” fica sempre por último.
B13: Parte e acumulado | C13: Parte do total = valor da categoria ÷ total. Acumulado = soma das partes, da primeira categoria até a atual.
B14: Classe | C14: Prioridade: a categoria começa antes de 80% do acumulado, e por isso entra a que cruza o corte. Depois: começa em 80% ou mais.
B15: Base do Pareto | C15: Frequência: o valor é a contagem. Frequência × peso: o valor é a contagem vezes o peso por ocorrência da aba Coleta (custo, tempo, quilos).
B16: Taxa | C16: Ocorrências ÷ base × 100. A base é o número de oportunidades do período: entregas, requisições, peças.
B17: Avisos | C17: Menos de 50 ocorrências: poucos dados. “Outros” acima de 10%: abrir em categorias. Duas primeiras barras abaixo de 50%, com quatro categorias ou mais: Pareto plano.
B19: Ordem recomendada de preenchimento
B20: Passo 1 | C20: Aba Coleta: escreva o que se conta, o período, quem registra e a base. Cadastre as categorias, cada uma com a sua definição.
B21: Passo 2 | C21: Aba Folha: escreva o fator das colunas (dia, turno, área) e lance as contagens do período.
B22: Passo 3 | C22: Aba Pareto: leia a ordem, o acumulado, a classe e o aviso. Troque a base para frequência × peso, se as ocorrências não custam o mesmo.
B23: Passo 4 | C23: Leve as categorias da prioridade para a análise de causa, e registre a decisão.
B24: Passo 5 | C24: Aba Antes e depois: depois da ação, lance a nova contagem e a nova base, e leia a variação.
B25: Passo 6 | C25: Aba Checklist: valide a análise.
B27: Abas da planilha
B28: Coleta | C28: O plano da coleta e até 8 categorias, com definição e peso. “Outros” já está na lista.
B29: Folha | C29: As contagens por categoria, em até 7 colunas do segundo fator. Calcula os totais e a coluna com mais ocorrências.
B30: Pareto | C30: A ordem, a parte do total, o acumulado, a classe, o aviso e o gráfico.
B31: Antes e depois | C31: A contagem feita depois da ação. Calcula a taxa, a variação e a primeira categoria de agora.
B32: Checklist | C32: Doze verificações de qualidade da análise, com percentual de conclusão.
B33: Exemplo 1 - Pizzaria | C33: Os atrasos nas entregas, por motivo e por dia da semana, com o antes e o depois.
B34: Exemplo 2 - Compras | C34: As requisições devolvidas, por motivo e por área requisitante.
B36: Regras e premissas do modelo
B37: Categorias | C37: De quatro a oito, mais “Outros”. Com mais do que isso, junte as menores em “Outros” ou faça um segundo Pareto da primeira barra.
B38: Folha impressa | C38: A contagem é feita no papel, na hora, com um traço por ocorrência. A planilha recebe os totais do período.
B39: Gráfico | C39: As barras mostram a parte de cada categoria, e a linha, o acumulado, na mesma régua de 0 a 100%. A coluna “Linha do gráfico” fica vazia nas posições sem categoria.
B40: Exemplos | C40: Os dados das abas de exemplo são ilustrativos, criados para este material.

Sheet Coleta
B1: O plano da coleta
B2: Defina o que será contado, onde, quando e por quem. Cada categoria precisa de uma definição escrita.
B4: Organização e processo
B5: O que se conta (unidade e critério)
B6: Onde e em que período
B7: Quem registra, e como
B8: Base: oportunidades no período
B9: Nome da base (entregas, requisições, peças)
B11: # | C11: Categoria | D11: Definição: conta quando… | E11: Peso por ocorrência | F11: Conferência
C12: Nome curto, com as mesmas palavras sempre | D12: A regra que decide se a ocorrência entra nesta categoria | E12: Opcional: custo, tempo ou quilos | F12: Calculada
B13: Ex. | C13: Fila no forno | D13: O pedido esperou mais de 10 minutos para entrar no forno. | F13: OK
B14: 1 | F14: =IF(C14="","",IF(COUNTIF(C$14:C$21,C14)>1,"Categoria repetida",IF(D14="","Falta a definição","OK")))
B15: 2 | F15: =IF(C15="","",IF(COUNTIF(C$14:C$21,C15)>1,"Categoria repetida",IF(D15="","Falta a definição","OK")))
B16: 3 | F16: =IF(C16="","",IF(COUNTIF(C$14:C$21,C16)>1,"Categoria repetida",IF(D16="","Falta a definição","OK")))
B17: 4 | F17: =IF(C17="","",IF(COUNTIF(C$14:C$21,C17)>1,"Categoria repetida",IF(D17="","Falta a definição","OK")))
B18: 5 | F18: =IF(C18="","",IF(COUNTIF(C$14:C$21,C18)>1,"Categoria repetida",IF(D18="","Falta a definição","OK")))
B19: 6 | F19: =IF(C19="","",IF(COUNTIF(C$14:C$21,C19)>1,"Categoria repetida",IF(D19="","Falta a definição","OK")))
B20: 7 | F20: =IF(C20="","",IF(COUNTIF(C$14:C$21,C20)>1,"Categoria repetida",IF(D20="","Falta a definição","OK")))
B21: 8 | F21: =IF(C21="","",IF(COUNTIF(C$14:C$21,C21)>1,"Categoria repetida",IF(D21="","Falta a definição","OK")))
B22: — | C22: Outros | D22: O que não cabe nas categorias acima. Anotar o motivo ao lado do traço. | F22: Fica sempre por último
B24: Resumo automático
B25: Categorias cadastradas | D25: =COUNTA(C14:C21) -> 0
B26: Aviso | D26: =IF(D5="","Descreva o que se conta",IF(D25=0,"Cadastre as categorias",IF(COUNTIF(F14:F21,"OK")<D25,"Há categoria a rever: veja a coluna Conferência",IF(D25<4,"Poucas categorias: o usual é de quatro a oito","OK")))) -> Descreva o que se conta

Sheet Folha
B1: Folha de verificação
B2: Lance os totais do período, por categoria e por coluna. As categorias vêm da aba Coleta.
B4: Fator das colunas | H4: Dia da semana, turno, área, máquina, produto.
B6: # | C6: Categoria | K6: Total | L6: Parte do total
C7: Vem da aba Coleta | D7: Contagem | E7: Contagem | F7: Contagem | G7: Contagem | H7: Contagem | I7: Contagem | J7: Contagem | K7: Calculado | L7: Calculada
B8: 1 | C8: =IF(Coleta!C14="","",Coleta!C14) | K8: =IF(AND(C8="",COUNT(D8:J8)=0),"",SUM(D8:J8)) | L8: =IF(OR(K8="",$K$17=0),"",K8/$K$17)
B9: 2 | C9: =IF(Coleta!C15="","",Coleta!C15) | K9: =IF(AND(C9="",COUNT(D9:J9)=0),"",SUM(D9:J9)) | L9: =IF(OR(K9="",$K$17=0),"",K9/$K$17)
B10: 3 | C10: =IF(Coleta!C16="","",Coleta!C16) | K10: =IF(AND(C10="",COUNT(D10:J10)=0),"",SUM(D10:J10)) | L10: =IF(OR(K10="",$K$17=0),"",K10/$K$17)
B11: 4 | C11: =IF(Coleta!C17="","",Coleta!C17) | K11: =IF(AND(C11="",COUNT(D11:J11)=0),"",SUM(D11:J11)) | L11: =IF(OR(K11="",$K$17=0),"",K11/$K$17)
B12: 5 | C12: =IF(Coleta!C18="","",Coleta!C18) | K12: =IF(AND(C12="",COUNT(D12:J12)=0),"",SUM(D12:J12)) | L12: =IF(OR(K12="",$K$17=0),"",K12/$K$17)
B13: 6 | C13: =IF(Coleta!C19="","",Coleta!C19) | K13: =IF(AND(C13="",COUNT(D13:J13)=0),"",SUM(D13:J13)) | L13: =IF(OR(K13="",$K$17=0),"",K13/$K$17)
B14: 7 | C14: =IF(Coleta!C20="","",Coleta!C20) | K14: =IF(AND(C14="",COUNT(D14:J14)=0),"",SUM(D14:J14)) | L14: =IF(OR(K14="",$K$17=0),"",K14/$K$17)
B15: 8 | C15: =IF(Coleta!C21="","",Coleta!C21) | K15: =IF(AND(C15="",COUNT(D15:J15)=0),"",SUM(D15:J15)) | L15: =IF(OR(K15="",$K$17=0),"",K15/$K$17)
B16: — | C16: Outros | K16: =SUM(D16:J16) -> 0 | L16: =IF($K$17=0,"",K16/$K$17)
B17: Total | D17: =SUM(D8:D16) -> 0 | E17: =SUM(E8:E16) -> 0 | F17: =SUM(F8:F16) -> 0 | G17: =SUM(G8:G16) -> 0 | H17: =SUM(H8:H16) -> 0 | I17: =SUM(I8:I16) -> 0 | J17: =SUM(J8:J16) -> 0 | K17: =SUM(K8:K16) -> 0
B18: Parte do total | D18: =IF($K$17=0,"",D17/$K$17) | E18: =IF($K$17=0,"",E17/$K$17) | F18: =IF($K$17=0,"",F17/$K$17) | G18: =IF($K$17=0,"",G17/$K$17) | H18: =IF($K$17=0,"",H17/$K$17) | I18: =IF($K$17=0,"",I17/$K$17) | J18: =IF($K$17=0,"",J17/$K$17) | K18: =IF($K$17=0,"",K17/$K$17)
B20: Resumo automático
B21: Ocorrências registradas | D21: =K17 -> 0
B22: Coluna com mais ocorrências | D22: =IF(K17=0,"",INDEX(D6:J6,MATCH(MAX(D17:J17),D17:J17,0))&" · "&TEXT(MAX(D17:J17)/K17,"0%"))
B23: Ocorrências por 100 da base | D23: =IF(OR(Coleta!D8="",K17=0),"",100*K17/Coleta!D8)
B24: Aviso | D24: =IF(K17=0,"Lance as contagens",IF(SUMPRODUCT((C8:C15="")*ISNUMBER(K8:K15))>0,"Há contagem em linha sem categoria: cadastre na aba Coleta",IF(K17<50,"Poucos dados: menos de 50 ocorrências","OK"))) -> Lance as contagens

Sheet Pareto
B1: Gráfico de Pareto
B2: A ordem, a parte do total e o acumulado são calculados a partir da aba Folha. Escolha só a base.
B4: Base do Pareto | D4: Frequência | F4: Escolha na lista.
B5: O que se conta | D5: =IF(Coleta!D5="","",Coleta!D5)
I6: Base de cálculo: não altere
B7: Ordem | C7: Categoria | D7: Valor | E7: Parte do total | F7: Acumulado | G7: Classe | I7: Categoria, na ordem da folha | J7: Valor | K7: Chave de ordem | L7: Posição | M7: Linha do gráfico | N7: Corte
B8: 1 | C8: =IF(1<=$J$18,INDEX($I$8:$I$15,MATCH(1,$L$8:$L$15,0)),IF(AND(1=$J$18+1,$J$16>0),"Outros","")) | D8: =IF(C8="","",IF(1<=$J$18,INDEX($J$8:$J$15,MATCH(1,$L$8:$L$15,0)),$J$16)) | E8: =IF(D8="","",D8/$J$19) | F8: =IF(D8="","",SUM(D$8:D8)/$J$19) | G8: =IF(D8="","",IF(1>$J$18,"Outros",IF(ROUND(F8-E8,6)<0.8,"Prioridade","Depois"))) | I8: =IF(Folha!C8="","",Folha!C8) | J8: =IF(Folha!K8="","",IF($D$4="Frequência × peso",Folha!K8*N(Coleta!E14),Folha!K8)) | K8: =IF(OR(I8="",J8="",J8=0),"",J8-ROW()/1000000) | L8: =IF(K8="","",RANK(K8,K$8:K$15)) | M8: =IF(D8="",NA(),F8) -> #N/A | N8: 0.8
B9: 2 | C9: =IF(2<=$J$18,INDEX($I$8:$I$15,MATCH(2,$L$8:$L$15,0)),IF(AND(2=$J$18+1,$J$16>0),"Outros","")) | D9: =IF(C9="","",IF(2<=$J$18,INDEX($J$8:$J$15,MATCH(2,$L$8:$L$15,0)),$J$16)) | E9: =IF(D9="","",D9/$J$19) | F9: =IF(D9="","",SUM(D$8:D9)/$J$19) | G9: =IF(D9="","",IF(2>$J$18,"Outros",IF(ROUND(F9-E9,6)<0.8,"Prioridade","Depois"))) | I9: =IF(Folha!C9="","",Folha!C9) | J9: =IF(Folha!K9="","",IF($D$4="Frequência × peso",Folha!K9*N(Coleta!E15),Folha!K9)) | K9: =IF(OR(I9="",J9="",J9=0),"",J9-ROW()/1000000) | L9: =IF(K9="","",RANK(K9,K$8:K$15)) | M9: =IF(D9="",NA(),F9) -> #N/A | N9: 0.8
B10: 3 | C10: =IF(3<=$J$18,INDEX($I$8:$I$15,MATCH(3,$L$8:$L$15,0)),IF(AND(3=$J$18+1,$J$16>0),"Outros","")) | D10: =IF(C10="","",IF(3<=$J$18,INDEX($J$8:$J$15,MATCH(3,$L$8:$L$15,0)),$J$16)) | E10: =IF(D10="","",D10/$J$19) | F10: =IF(D10="","",SUM(D$8:D10)/$J$19) | G10: =IF(D10="","",IF(3>$J$18,"Outros",IF(ROUND(F10-E10,6)<0.8,"Prioridade","Depois"))) | I10: =IF(Folha!C10="","",Folha!C10) | J10: =IF(Folha!K10="","",IF($D$4="Frequência × peso",Folha!K10*N(Coleta!E16),Folha!K10)) | K10: =IF(OR(I10="",J10="",J10=0),"",J10-ROW()/1000000) | L10: =IF(K10="","",RANK(K10,K$8:K$15)) | M10: =IF(D10="",NA(),F10) -> #N/A | N10: 0.8
B11: 4 | C11: =IF(4<=$J$18,INDEX($I$8:$I$15,MATCH(4,$L$8:$L$15,0)),IF(AND(4=$J$18+1,$J$16>0),"Outros","")) | D11: =IF(C11="","",IF(4<=$J$18,INDEX($J$8:$J$15,MATCH(4,$L$8:$L$15,0)),$J$16)) | E11: =IF(D11="","",D11/$J$19) | F11: =IF(D11="","",SUM(D$8:D11)/$J$19) | G11: =IF(D11="","",IF(4>$J$18,"Outros",IF(ROUND(F11-E11,6)<0.8,"Prioridade","Depois"))) | I11: =IF(Folha!C11="","",Folha!C11) | J11: =IF(Folha!K11="","",IF($D$4="Frequência × peso",Folha!K11*N(Coleta!E17),Folha!K11)) | K11: =IF(OR(I11="",J11="",J11=0),"",J11-ROW()/1000000) | L11: =IF(K11="","",RANK(K11,K$8:K$15)) | M11: =IF(D11="",NA(),F11) -> #N/A | N11: 0.8
B12: 5 | C12: =IF(5<=$J$18,INDEX($I$8:$I$15,MATCH(5,$L$8:$L$15,0)),IF(AND(5=$J$18+1,$J$16>0),"Outros","")) | D12: =IF(C12="","",IF(5<=$J$18,INDEX($J$8:$J$15,MATCH(5,$L$8:$L$15,0)),$J$16)) | E12: =IF(D12="","",D12/$J$19) | F12: =IF(D12="","",SUM(D$8:D12)/$J$19) | G12: =IF(D12="","",IF(5>$J$18,"Outros",IF(ROUND(F12-E12,6)<0.8,"Prioridade","Depois"))) | I12: =IF(Folha!C12="","",Folha!C12) | J12: =IF(Folha!K12="","",IF($D$4="Frequência × peso",Folha!K12*N(Coleta!E18),Folha!K12)) | K12: =IF(OR(I12="",J12="",J12=0),"",J12-ROW()/1000000) | L12: =IF(K12="","",RANK(K12,K$8:K$15)) | M12: =IF(D12="",NA(),F12) -> #N/A | N12: 0.8
B13: 6 | C13: =IF(6<=$J$18,INDEX($I$8:$I$15,MATCH(6,$L$8:$L$15,0)),IF(AND(6=$J$18+1,$J$16>0),"Outros","")) | D13: =IF(C13="","",IF(6<=$J$18,INDEX($J$8:$J$15,MATCH(6,$L$8:$L$15,0)),$J$16)) | E13: =IF(D13="","",D13/$J$19) | F13: =IF(D13="","",SUM(D$8:D13)/$J$19) | G13: =IF(D13="","",IF(6>$J$18,"Outros",IF(ROUND(F13-E13,6)<0.8,"Prioridade","Depois"))) | I13: =IF(Folha!C13="","",Folha!C13) | J13: =IF(Folha!K13="","",IF($D$4="Frequência × peso",Folha!K13*N(Coleta!E19),Folha!K13)) | K13: =IF(OR(I13="",J13="",J13=0),"",J13-ROW()/1000000) | L13: =IF(K13="","",RANK(K13,K$8:K$15)) | M13: =IF(D13="",NA(),F13) -> #N/A | N13: 0.8
B14: 7 | C14: =IF(7<=$J$18,INDEX($I$8:$I$15,MATCH(7,$L$8:$L$15,0)),IF(AND(7=$J$18+1,$J$16>0),"Outros","")) | D14: =IF(C14="","",IF(7<=$J$18,INDEX($J$8:$J$15,MATCH(7,$L$8:$L$15,0)),$J$16)) | E14: =IF(D14="","",D14/$J$19) | F14: =IF(D14="","",SUM(D$8:D14)/$J$19) | G14: =IF(D14="","",IF(7>$J$18,"Outros",IF(ROUND(F14-E14,6)<0.8,"Prioridade","Depois"))) | I14: =IF(Folha!C14="","",Folha!C14) | J14: =IF(Folha!K14="","",IF($D$4="Frequência × peso",Folha!K14*N(Coleta!E20),Folha!K14)) | K14: =IF(OR(I14="",J14="",J14=0),"",J14-ROW()/1000000) | L14: =IF(K14="","",RANK(K14,K$8:K$15)) | M14: =IF(D14="",NA(),F14) -> #N/A | N14: 0.8
B15: 8 | C15: =IF(8<=$J$18,INDEX($I$8:$I$15,MATCH(8,$L$8:$L$15,0)),IF(AND(8=$J$18+1,$J$16>0),"Outros","")) | D15: =IF(C15="","",IF(8<=$J$18,INDEX($J$8:$J$15,MATCH(8,$L$8:$L$15,0)),$J$16)) | E15: =IF(D15="","",D15/$J$19) | F15: =IF(D15="","",SUM(D$8:D15)/$J$19) | G15: =IF(D15="","",IF(8>$J$18,"Outros",IF(ROUND(F15-E15,6)<0.8,"Prioridade","Depois"))) | I15: =IF(Folha!C15="","",Folha!C15) | J15: =IF(Folha!K15="","",IF($D$4="Frequência × peso",Folha!K15*N(Coleta!E21),Folha!K15)) | K15: =IF(OR(I15="",J15="",J15=0),"",J15-ROW()/1000000) | L15: =IF(K15="","",RANK(K15,K$8:K$15)) | M15: =IF(D15="",NA(),F15) -> #N/A | N15: 0.8
B16: 9 | C16: =IF(9<=$J$18,INDEX($I$8:$I$15,MATCH(9,$L$8:$L$15,0)),IF(AND(9=$J$18+1,$J$16>0),"Outros","")) | D16: =IF(C16="","",IF(9<=$J$18,INDEX($J$8:$J$15,MATCH(9,$L$8:$L$15,0)),$J$16)) | E16: =IF(D16="","",D16/$J$19) | F16: =IF(D16="","",SUM(D$8:D16)/$J$19) | G16: =IF(D16="","",IF(9>$J$18,"Outros",IF(ROUND(F16-E16,6)<0.8,"Prioridade","Depois"))) | I16: Outros | J16: =IF($D$4="Frequência × peso",Folha!K16*N(Coleta!E22),Folha!K16) -> 0 | M16: =IF(D16="",NA(),F16) -> #N/A | N16: 0.8
B18: Resumo automático | I18: Categorias com valor | J18: =COUNT(L8:L15) -> 0
B19: Total | D19: =IF($J$19=0,"",$J$19) | I19: Total | J19: =SUM(J8:J16) -> 0
B20: Primeira categoria | D20: =IF(C8="","",C8&" · "&TEXT(E8,"0%"))
B21: Prioridade | D21: =IF(COUNTIF(G8:G16,"Prioridade")=0,"",COUNTIF(G8:G16,"Prioridade")&" de "&$J$18&" categorias, com "&TEXT(INDEX(F8:F16,COUNTIF(G8:G16,"Prioridade")),"0%")&" do total")
B22: Outros | D22: =IF($J$19=0,"",$J$16/$J$19)
B23: Aviso | D23: =IF(Folha!K17=0,"Lance as contagens na aba Folha",IF(AND(D4="Frequência × peso",SUMPRODUCT(ISNUMBER(Folha!K8:K16)*(Folha!K8:K16<>0)*(Coleta!E14:E22=""))>0),"Falta o peso de uma categoria: veja a aba Coleta",IF(Folha!K17<50,"Poucos dados: menos de 50 ocorrências",IF(D22>0.1,"Outros acima de 10%: abra em categorias",IF(AND($J$18>=4,N(F9)<0.5),"Pareto plano: estratifique por outro fator","OK"))))) -> Lance as contagens na aba Folha

Sheet Antes e depois
B1: Antes e depois
B2: Depois da ação, conte de novo com as mesmas categorias. O antes vem da aba Folha.
B4: Período do antes | D4: =IF(Coleta!D6="","",Coleta!D6)
B5: Período do depois
B6: Base do antes | D6: =IF(Coleta!D8="","",Coleta!D8) | E6: Vem da aba Coleta.
B7: Base do depois | E7: =IF(AND(ISNUMBER(D6),ISNUMBER(D7)),IF(AND(D6>0,D7>0),"Taxa por 100","Contagem"),"Contagem") -> Contagem | F7: Como a comparação é feita. Com as duas bases, pela taxa.
B9: # | C9: Categoria | D9: Antes | E9: Depois | F9: Antes, comparável | G9: Depois, comparável | H9: Variação | I9: Leitura
C10: Vem da aba Coleta | D10: Da aba Folha | E10: Nova contagem | F10: Por 100, ou contagem | G10: Por 100, ou contagem | H10: Calculada | I10: Calculada
B11: 1 | C11: =IF(Folha!C8="","",Folha!C8) | D11: =IF(Folha!K8="","",Folha!K8) | F11: =IF(OR(C11="",D11=""),"",IF($E$7="Taxa por 100",100*D11/$D$6,D11)) | G11: =IF(OR(C11="",E11=""),"",IF($E$7="Taxa por 100",100*E11/$D$7,E11)) | H11: =IF(OR(F11="",G11=""),"",IF(F11=0,"",(G11-F11)/F11)) | I11: =IF(OR(F11="",G11=""),"",IF(AND(F11=0,G11>0),"Nova",IF(G11<F11,"Caiu",IF(G11>F11,"Subiu","Igual"))))
B12: 2 | C12: =IF(Folha!C9="","",Folha!C9) | D12: =IF(Folha!K9="","",Folha!K9) | F12: =IF(OR(C12="",D12=""),"",IF($E$7="Taxa por 100",100*D12/$D$6,D12)) | G12: =IF(OR(C12="",E12=""),"",IF($E$7="Taxa por 100",100*E12/$D$7,E12)) | H12: =IF(OR(F12="",G12=""),"",IF(F12=0,"",(G12-F12)/F12)) | I12: =IF(OR(F12="",G12=""),"",IF(AND(F12=0,G12>0),"Nova",IF(G12<F12,"Caiu",IF(G12>F12,"Subiu","Igual"))))
B13: 3 | C13: =IF(Folha!C10="","",Folha!C10) | D13: =IF(Folha!K10="","",Folha!K10) | F13: =IF(OR(C13="",D13=""),"",IF($E$7="Taxa por 100",100*D13/$D$6,D13)) | G13: =IF(OR(C13="",E13=""),"",IF($E$7="Taxa por 100",100*E13/$D$7,E13)) | H13: =IF(OR(F13="",G13=""),"",IF(F13=0,"",(G13-F13)/F13)) | I13: =IF(OR(F13="",G13=""),"",IF(AND(F13=0,G13>0),"Nova",IF(G13<F13,"Caiu",IF(G13>F13,"Subiu","Igual"))))
B14: 4 | C14: =IF(Folha!C11="","",Folha!C11) | D14: =IF(Folha!K11="","",Folha!K11) | F14: =IF(OR(C14="",D14=""),"",IF($E$7="Taxa por 100",100*D14/$D$6,D14)) | G14: =IF(OR(C14="",E14=""),"",IF($E$7="Taxa por 100",100*E14/$D$7,E14)) | H14: =IF(OR(F14="",G14=""),"",IF(F14=0,"",(G14-F14)/F14)) | I14: =IF(OR(F14="",G14=""),"",IF(AND(F14=0,G14>0),"Nova",IF(G14<F14,"Caiu",IF(G14>F14,"Subiu","Igual"))))
B15: 5 | C15: =IF(Folha!C12="","",Folha!C12) | D15: =IF(Folha!K12="","",Folha!K12) | F15: =IF(OR(C15="",D15=""),"",IF($E$7="Taxa por 100",100*D15/$D$6,D15)) | G15: =IF(OR(C15="",E15=""),"",IF($E$7="Taxa por 100",100*E15/$D$7,E15)) | H15: =IF(OR(F15="",G15=""),"",IF(F15=0,"",(G15-F15)/F15)) | I15: =IF(OR(F15="",G15=""),"",IF(AND(F15=0,G15>0),"Nova",IF(G15<F15,"Caiu",IF(G15>F15,"Subiu","Igual"))))
B16: 6 | C16: =IF(Folha!C13="","",Folha!C13) | D16: =IF(Folha!K13="","",Folha!K13) | F16: =IF(OR(C16="",D16=""),"",IF($E$7="Taxa por 100",100*D16/$D$6,D16)) | G16: =IF(OR(C16="",E16=""),"",IF($E$7="Taxa por 100",100*E16/$D$7,E16)) | H16: =IF(OR(F16="",G16=""),"",IF(F16=0,"",(G16-F16)/F16)) | I16: =IF(OR(F16="",G16=""),"",IF(AND(F16=0,G16>0),"Nova",IF(G16<F16,"Caiu",IF(G16>F16,"Subiu","Igual"))))
B17: 7 | C17: =IF(Folha!C14="","",Folha!C14) | D17: =IF(Folha!K14="","",Folha!K14) | F17: =IF(OR(C17="",D17=""),"",IF($E$7="Taxa por 100",100*D17/$D$6,D17)) | G17: =IF(OR(C17="",E17=""),"",IF($E$7="Taxa por 100",100*E17/$D$7,E17)) | H17: =IF(OR(F17="",G17=""),"",IF(F17=0,"",(G17-F17)/F17)) | I17: =IF(OR(F17="",G17=""),"",IF(AND(F17=0,G17>0),"Nova",IF(G17<F17,"Caiu",IF(G17>F17,"Subiu","Igual"))))
B18: 8 | C18: =IF(Folha!C15="","",Folha!C15) | D18: =IF(Folha!K15="","",Folha!K15) | F18: =IF(OR(C18="",D18=""),"",IF($E$7="Taxa por 100",100*D18/$D$6,D18)) | G18: =IF(OR(C18="",E18=""),"",IF($E$7="Taxa por 100",100*E18/$D$7,E18)) | H18: =IF(OR(F18="",G18=""),"",IF(F18=0,"",(G18-F18)/F18)) | I18: =IF(OR(F18="",G18=""),"",IF(AND(F18=0,G18>0),"Nova",IF(G18<F18,"Caiu",IF(G18>F18,"Subiu","Igual"))))
B19: — | C19: Outros | D19: =Folha!K16 -> 0 | F19: =IF(OR(C19="",D19=""),"",IF($E$7="Taxa por 100",100*D19/$D$6,D19)) -> 0 | G19: =IF(OR(C19="",E19=""),"",IF($E$7="Taxa por 100",100*E19/$D$7,E19)) | H19: =IF(OR(F19="",G19=""),"",IF(F19=0,"",(G19-F19)/F19)) | I19: =IF(OR(F19="",G19=""),"",IF(AND(F19=0,G19>0),"Nova",IF(G19<F19,"Caiu",IF(G19>F19,"Subiu","Igual"))))
B20: Total | D20: =SUM(D11:D19) -> 0 | E20: =IF(COUNT(E11:E19)=0,"",SUM(E11:E19)) | F20: =IF(OR(B20="",D20=""),"",IF($E$7="Taxa por 100",100*D20/$D$6,D20)) -> 0 | G20: =IF(OR(B20="",E20=""),"",IF($E$7="Taxa por 100",100*E20/$D$7,E20)) | H20: =IF(OR(F20="",G20=""),"",IF(F20=0,"",(G20-F20)/F20)) | I20: =IF(OR(F20="",G20=""),"",IF(AND(F20=0,G20>0),"Nova",IF(G20<F20,"Caiu",IF(G20>F20,"Subiu","Igual"))))
B22: Resumo automático
B23: Variação do total | D23: =IF(H20="","",H20)
B24: Primeira categoria do antes | D24: =IF(OR(Pareto!C8="",COUNT(E11:E19)=0),"",Pareto!C8&IF(IFERROR(INDEX(I11:I19,MATCH(Pareto!C8,C11:C19,0)),"")="","",": "&LOWER(IFERROR(INDEX(I11:I19,MATCH(Pareto!C8,C11:C19,0)),""))))
B25: Primeira categoria de agora | D25: =IF(COUNT(E11:E18)=0,"",INDEX(C11:C18,MATCH(MAX(E11:E18),E11:E18,0)))
B26: Aviso | D26: =IF(Folha!K17=0,"Lance as contagens na aba Folha",IF(COUNT(E11:E19)=0,"Lance as contagens do depois",IF(COUNT(E11:E19)<COUNT(D11:D19),"Faltam contagens do depois: escreva 0 onde não houve ocorrência",IF(E7<>"Taxa por 100","Informe as duas bases para comparar a taxa",IF(COUNTIF(I11:I19,"Subiu")+COUNTIF(I11:I19,"Nova")>0,"Há categoria que subiu: veja a coluna Leitura","OK"))))) -> Lance as contagens na aba Folha

Sheet Checklist
B1: Checklist do Pareto e da folha de verificação
B2: Escolha o status de cada item na lista suspensa (coluna em amarelo-claro).
B4: # | C4: Item de verificação | D4: Status | E4: Observações
B5: 1 | C5: O problema a contar está definido, com unidade: entrega atrasada, requisição devolvida, peça reprovada.
B6: 2 | C6: Cada categoria tem definição escrita, e duas pessoas classificam o mesmo caso do mesmo jeito.
B7: 3 | C7: A folha de verificação informa o que se conta, onde, em que período e quem registra.
B8: 4 | C8: O registro é feito na hora, por quem vê a ocorrência, e não de memória no fim do dia.
B9: 5 | C9: A folha guarda um segundo fator: dia, turno, área, máquina ou produto.
B10: 6 | C10: Há pelo menos 50 ocorrências no período, ou o período foi ampliado.
B11: 7 | C11: As barras estão em ordem decrescente, com “Outros” por último.
B12: 8 | C12: “Outros” não passa de 10% do total. Se passa, foi aberto em categorias.
B13: 9 | C13: O gráfico mostra o total, o período e a base, e o eixo da esquerda vai até o total.
B14: 10 | C14: O Pareto foi feito também por custo, tempo ou gravidade, quando as ocorrências não pesam igual.
B15: 11 | C15: As primeiras barras seguiram para a análise de causa, e a decisão está registrada.
B16: 12 | C16: Depois da ação, a contagem foi repetida com as mesmas categorias, e a comparação usa a taxa.
B18: Resumo automático
B19: Itens atendidos (Sim) | D19: =COUNTIF(D5:D16,"Sim") -> 0
B20: Itens parciais | D20: =COUNTIF(D5:D16,"Parcial") -> 0
B21: Itens não atendidos | D21: =COUNTIF(D5:D16,"Não") -> 0
B22: Itens sem resposta | D22: =COUNTBLANK(D5:D16) -> 12
B23: Percentual atendido | D23: =D19/ROWS(D5:D16) -> 0
B24: Situação | D24: =IF(D19=ROWS(D5:D16),"Validado",IF(D22>0,"Em andamento","Com pendências")) -> Em andamento

Sheet Exemplo 1 - Pizzaria
B1: Pareto e folha de verificação
B2: Exemplo preenchido, para consulta. Use as abas Coleta, Folha, Pareto e Antes e depois para a sua organização.
B4: Organização | D4: Pizzaria (loja com salão e delivery)
B5: O que se conta | D5: Entregas de delivery que chegaram depois de 40 minutos, pelo motivo principal do atraso.
B6: Período e fonte | D6: De 15/06 a 09/07/2026, todos os dias. Folha na bancada da expedição.
B7: Como se registra | D7: Um traço por entrega atrasada, feito quando o entregador volta e informa o motivo.
B8: Análise | D8: 10/07/2026, por líder da expedição. Base: 1.110 entregas.
B9: Origem | D9: Ciclo PDCA dos atrasos nas entregas: etapa de observação do problema.
B11: Folha do período · dia da semana nas colunas
B12: Categoria | D12: Seg | E12: Ter | F12: Qua | G12: Qui | H12: Sex | I12: Sáb | J12: Dom | K12: Total
B13: Pizza pronta esperando entregador | D13: 3 | E13: 2 | F13: 4 | G13: 5 | H13: 36 | I13: 38 | J13: 4 | K13: =SUM(D13:J13) -> 92
B14: Fila no forno | D14: 1 | E14: 1 | F14: 2 | G14: 3 | H14: 20 | I14: 24 | J14: 3 | K14: =SUM(D14:J14) -> 54
B15: Endereço incompleto | D15: 3 | E15: 4 | F15: 3 | G15: 4 | H15: 6 | I15: 6 | J15: 4 | K15: =SUM(D15:J15) -> 30
B16: Trânsito ou obras | D16: 1 | E16: 1 | F16: 1 | G16: 2 | H16: 2 | I16: 2 | J16: 1 | K16: =SUM(D16:J16) -> 10
B17: Outros | D17: 2 | E17: 1 | F17: 2 | G17: 2 | H17: 3 | I17: 3 | J17: 1 | K17: =SUM(D17:J17) -> 14
B18: Total | D18: =SUM(D13:D17) -> 10 | E18: =SUM(E13:E17) -> 9 | F18: =SUM(F13:F17) -> 12 | G18: =SUM(G13:G17) -> 16 | H18: =SUM(H13:H17) -> 67 | I18: =SUM(I13:I17) -> 73 | J18: =SUM(J13:J17) -> 13 | K18: =SUM(K13:K17) -> 200
B19: Parte do total | D19: =D18/$K$18 -> 0.05 | E19: =E18/$K$18 -> 0.045 | F19: =F18/$K$18 -> 0.06 | G19: =G18/$K$18 -> 0.08 | H19: =H18/$K$18 -> 0.335 | I19: =I18/$K$18 -> 0.365 | J19: =J18/$K$18 -> 0.065 | K19: =K18/$K$18 -> 1
B21: Pareto por motivo do atraso
B22: Ordem | C22: Motivo principal | D22: Atrasos | E22: Parte | F22: Acumulado | G22: Classe | I22: Corte | J22: Por 100 entregas
B23: 1 | C23: Pizza pronta esperando entregador | D23: 92 | E23: =D23/SUM(D$23:D$27) -> 0.46 | F23: =SUM(D$23:D23)/SUM(D$23:D$27) -> 0.46 | G23: =IF(C23="Outros","Outros",IF(ROUND(F23-E23,6)<0.8,"Prioridade","Depois")) -> Prioridade | I23: 0.8 | J23: =100*D23/1110 -> 8.2882883
B24: 2 | C24: Fila no forno | D24: 54 | E24: =D24/SUM(D$23:D$27) -> 0.27 | F24: =SUM(D$23:D24)/SUM(D$23:D$27) -> 0.73 | G24: =IF(C24="Outros","Outros",IF(ROUND(F24-E24,6)<0.8,"Prioridade","Depois")) -> Prioridade | I24: 0.8 | J24: =100*D24/1110 -> 4.8648649
B25: 3 | C25: Endereço incompleto | D25: 30 | E25: =D25/SUM(D$23:D$27) -> 0.15 | F25: =SUM(D$23:D25)/SUM(D$23:D$27) -> 0.88 | G25: =IF(C25="Outros","Outros",IF(ROUND(F25-E25,6)<0.8,"Prioridade","Depois")) -> Prioridade | I25: 0.8 | J25: =100*D25/1110 -> 2.7027027
B26: 4 | C26: Trânsito ou obras | D26: 10 | E26: =D26/SUM(D$23:D$27) -> 0.05 | F26: =SUM(D$23:D26)/SUM(D$23:D$27) -> 0.93 | G26: =IF(C26="Outros","Outros",IF(ROUND(F26-E26,6)<0.8,"Prioridade","Depois")) -> Depois | I26: 0.8 | J26: =100*D26/1110 -> 0.9009009
B27: 5 | C27: Outros | D27: 14 | E27: =D27/SUM(D$23:D$27) -> 0.07 | F27: =SUM(D$23:D27)/SUM(D$23:D$27) -> 1 | G27: =IF(C27="Outros","Outros",IF(ROUND(F27-E27,6)<0.8,"Prioridade","Depois")) -> Outros | I27: 0.8 | J27: =100*D27/1110 -> 1.2612613
B28: Total | D28: =SUM(D23:D27) -> 200 | E28: =SUM(E23:E27) -> 1 | J28: =100*D28/1110 -> 18.018018
B49: Antes e depois · depois: de 10/08 a 06/09/2026, com 1.380 entregas
B50: Motivo principal | D50: Antes | E50: Depois | F50: Antes por 100 | G50: Depois por 100 | H50: Variação | I50: Leitura
B51: Pizza pronta esperando entregador | D51: 92 | E51: 9 | F51: =100*D51/1110 -> 8.2882883 | G51: =100*E51/1380 -> 0.65217391 | H51: =(G51-F51)/F51 -> -0.9213138 | I51: =IF(G51<F51,"Caiu",IF(G51>F51,"Subiu","Igual")) -> Caiu
B52: Fila no forno | D52: 54 | E52: 38 | F52: =100*D52/1110 -> 4.8648649 | G52: =100*E52/1380 -> 2.7536232 | H52: =(G52-F52)/F52 -> -0.43397746 | I52: =IF(G52<F52,"Caiu",IF(G52>F52,"Subiu","Igual")) -> Caiu
B53: Endereço incompleto | D53: 30 | E53: 2 | F53: =100*D53/1110 -> 2.7027027 | G53: =100*E53/1380 -> 0.14492754 | H53: =(G53-F53)/F53 -> -0.94637681 | I53: =IF(G53<F53,"Caiu",IF(G53>F53,"Subiu","Igual")) -> Caiu
B54: Trânsito ou obras | D54: 10 | E54: 6 | F54: =100*D54/1110 -> 0.9009009 | G54: =100*E54/1380 -> 0.43478261 | H54: =(G54-F54)/F54 -> -0.5173913 | I54: =IF(G54<F54,"Caiu",IF(G54>F54,"Subiu","Igual")) -> Caiu
B55: Outros | D55: 14 | E55: 7 | F55: =100*D55/1110 -> 1.2612613 | G55: =100*E55/1380 -> 0.50724638 | H55: =(G55-F55)/F55 -> -0.59782609 | I55: =IF(G55<F55,"Caiu",IF(G55>F55,"Subiu","Igual")) -> Caiu
B56: Total | D56: =SUM(D51:D55) -> 200 | E56: =SUM(E51:E55) -> 62 | F56: =100*D56/1110 -> 18.018018 | G56: =100*E56/1380 -> 4.4927536 | H56: =(G56-F56)/F56 -> -0.75065217
B58: Resumo automático
B59: Atrasos no período do antes | F59: =D28 -> 200
B60: Primeira categoria | F60: =C23&" · "&TEXT(E23,"0%") -> Pizza pronta esperando entregador · 46%
B61: Prioridade | F61: =COUNTIF(G23:H27,"Prioridade")&" categorias, com "&TEXT(INDEX(F23:F27,COUNTIF(G23:H27,"Prioridade")),"0%")&" do total" -> 3 categorias, com 88% do total
B62: Atrasos por 100 entregas, antes e depois | F62: =TEXT(F56,"0,0")&" → "&TEXT(G56,"0,0") -> 18,0 → 4,5
B63: Primeira categoria de agora | F63: =INDEX(B51:B55,MATCH(MAX(E51:E54),E51:E54,0)) -> Fila no forno

Sheet Exemplo 2 - Compras
B1: Pareto e folha de verificação
B2: Exemplo preenchido, para consulta. Use as abas Coleta, Folha, Pareto e Antes e depois para a sua organização.
B4: Organização | D4: Distribuidora de materiais elétricos · Compras
B5: O que se conta | D5: Requisições de compra devolvidas ao requisitante, pelo motivo da devolução.
B6: Período e fonte | D6: De dezembro de 2025 a maio de 2026. Dados do sistema de compras, conferidos uma a uma.
B7: Como se registra | D7: Uma linha por requisição devolvida, com o motivo lido no campo de observação do comprador.
B8: Análise | D8: 19/06/2026, por analista de compras. Base: 250 requisições.
B9: Origem | D9: Ciclo PDCA do prazo de compra: etapa de observação do problema.
B11: Folha do período · área requisitante nas colunas
B12: Categoria | D12: Manutenção | E12: Produção | F12: Laboratório | G12: Logística | H12: Administrativo | I12: Total
B13: Especificação técnica em branco | D13: 24 | E13: 7 | F13: 4 | G13: 2 | H13: 1 | I13: =SUM(D13:H13) -> 38
B14: Quantidade ou unidade em branco | D14: 8 | E14: 6 | F14: 2 | G14: 2 | H14: 1 | I14: =SUM(D14:H14) -> 19
B15: Centro de custo em branco | D15: 4 | E15: 3 | F15: 2 | G15: 2 | H15: 4 | I15: =SUM(D15:H15) -> 15
B16: Descrição não identifica o item | D16: 8 | E16: 3 | F16: 1 | G16: 1 | H16: 0 | I16: =SUM(D16:H16) -> 13
B17: Falta a aprovação do gestor | D17: 2 | E17: 2 | F17: 1 | G17: 1 | H17: 2 | I17: =SUM(D17:H17) -> 8
B18: Outros | D18: 2 | E18: 2 | F18: 1 | G18: 1 | H18: 1 | I18: =SUM(D18:H18) -> 7
B19: Total | D19: =SUM(D13:D18) -> 48 | E19: =SUM(E13:E18) -> 23 | F19: =SUM(F13:F18) -> 11 | G19: =SUM(G13:G18) -> 9 | H19: =SUM(H13:H18) -> 9 | I19: =SUM(I13:I18) -> 100
B20: Parte do total | D20: =D19/$I$19 -> 0.48 | E20: =E19/$I$19 -> 0.23 | F20: =F19/$I$19 -> 0.11 | G20: =G19/$I$19 -> 0.09 | H20: =H19/$I$19 -> 0.09 | I20: =I19/$I$19 -> 1
B22: Pareto por motivo da devolução
B23: Ordem | C23: Motivo | D23: Devoluções | E23: Parte | F23: Acumulado | G23: Classe | I23: Corte | J23: Por 100 requisições
B24: 1 | C24: Especificação técnica em branco | D24: 38 | E24: =D24/SUM(D$24:D$29) -> 0.38 | F24: =SUM(D$24:D24)/SUM(D$24:D$29) -> 0.38 | G24: =IF(C24="Outros","Outros",IF(ROUND(F24-E24,6)<0.8,"Prioridade","Depois")) -> Prioridade | I24: 0.8 | J24: =100*D24/250 -> 15.2
B25: 2 | C25: Quantidade ou unidade em branco | D25: 19 | E25: =D25/SUM(D$24:D$29) -> 0.19 | F25: =SUM(D$24:D25)/SUM(D$24:D$29) -> 0.57 | G25: =IF(C25="Outros","Outros",IF(ROUND(F25-E25,6)<0.8,"Prioridade","Depois")) -> Prioridade | I25: 0.8 | J25: =100*D25/250 -> 7.6
B26: 3 | C26: Centro de custo em branco | D26: 15 | E26: =D26/SUM(D$24:D$29) -> 0.15 | F26: =SUM(D$24:D26)/SUM(D$24:D$29) -> 0.72 | G26: =IF(C26="Outros","Outros",IF(ROUND(F26-E26,6)<0.8,"Prioridade","Depois")) -> Prioridade | I26: 0.8 | J26: =100*D26/250 -> 6
B27: 4 | C27: Descrição não identifica o item | D27: 13 | E27: =D27/SUM(D$24:D$29) -> 0.13 | F27: =SUM(D$24:D27)/SUM(D$24:D$29) -> 0.85 | G27: =IF(C27="Outros","Outros",IF(ROUND(F27-E27,6)<0.8,"Prioridade","Depois")) -> Prioridade | I27: 0.8 | J27: =100*D27/250 -> 5.2
B28: 5 | C28: Falta a aprovação do gestor | D28: 8 | E28: =D28/SUM(D$24:D$29) -> 0.08 | F28: =SUM(D$24:D28)/SUM(D$24:D$29) -> 0.93 | G28: =IF(C28="Outros","Outros",IF(ROUND(F28-E28,6)<0.8,"Prioridade","Depois")) -> Depois | I28: 0.8 | J28: =100*D28/250 -> 3.2
B29: 6 | C29: Outros | D29: 7 | E29: =D29/SUM(D$24:D$29) -> 0.07 | F29: =SUM(D$24:D29)/SUM(D$24:D$29) -> 1 | G29: =IF(C29="Outros","Outros",IF(ROUND(F29-E29,6)<0.8,"Prioridade","Depois")) -> Outros | I29: 0.8 | J29: =100*D29/250 -> 2.8
B30: Total | D30: =SUM(D24:D29) -> 100 | E30: =SUM(E24:E29) -> 1 | J30: =100*D30/250 -> 40
B51: Pareto por área requisitante · as colunas da mesma folha, com as requisições de cada área
B52: Ordem | C52: Área requisitante | D52: Devoluções | E52: Parte | F52: Acumulado | G52: Classe | I52: Corte | J52: Requisições | K52: Por 100 requisições
B53: 1 | C53: Manutenção | D53: 48 | E53: =D53/SUM(D$53:D$57) -> 0.48 | F53: =SUM(D$53:D53)/SUM(D$53:D$57) -> 0.48 | G53: =IF(C53="Outros","Outros",IF(ROUND(F53-E53,6)<0.8,"Prioridade","Depois")) -> Prioridade | I53: 0.8 | J53: 80 | K53: =100*D53/J53 -> 60
B54: 2 | C54: Produção | D54: 23 | E54: =D54/SUM(D$53:D$57) -> 0.23 | F54: =SUM(D$53:D54)/SUM(D$53:D$57) -> 0.71 | G54: =IF(C54="Outros","Outros",IF(ROUND(F54-E54,6)<0.8,"Prioridade","Depois")) -> Prioridade | I54: 0.8 | J54: 75 | K54: =100*D54/J54 -> 30.666667
B55: 3 | C55: Laboratório | D55: 11 | E55: =D55/SUM(D$53:D$57) -> 0.11 | F55: =SUM(D$53:D55)/SUM(D$53:D$57) -> 0.82 | G55: =IF(C55="Outros","Outros",IF(ROUND(F55-E55,6)<0.8,"Prioridade","Depois")) -> Prioridade | I55: 0.8 | J55: 35 | K55: =100*D55/J55 -> 31.428571
B56: 4 | C56: Logística | D56: 9 | E56: =D56/SUM(D$53:D$57) -> 0.09 | F56: =SUM(D$53:D56)/SUM(D$53:D$57) -> 0.91 | G56: =IF(C56="Outros","Outros",IF(ROUND(F56-E56,6)<0.8,"Prioridade","Depois")) -> Depois | I56: 0.8 | J56: 30 | K56: =100*D56/J56 -> 30
B57: 5 | C57: Administrativo | D57: 9 | E57: =D57/SUM(D$53:D$57) -> 0.09 | F57: =SUM(D$53:D57)/SUM(D$53:D$57) -> 1 | G57: =IF(C57="Outros","Outros",IF(ROUND(F57-E57,6)<0.8,"Prioridade","Depois")) -> Depois | I57: 0.8 | J57: 30 | K57: =100*D57/J57 -> 30
B58: Total | D58: =SUM(D53:D57) -> 100 | E58: =SUM(E53:E57) -> 1 | J58: =SUM(J53:J57) -> 250 | K58: =100*D58/J58 -> 40
B60: Resumo automático
B61: Devoluções no período | F61: =D30 -> 100
B62: Primeira categoria | F62: =C24&" · "&TEXT(E24,"0%") -> Especificação técnica em branco · 38%
B63: Prioridade | F63: =COUNTIF(G24:H29,"Prioridade")&" categorias, com "&TEXT(INDEX(F24:F29,COUNTIF(G24:H29,"Prioridade")),"0%")&" do total" -> 4 categorias, com 85% do total
B64: Campos em branco: as três primeiras categorias | F64: =F26 -> 0.72
...
