Workbook

Sheet Instruções
B1: ISO 9001 — Como usar esta planilha
B2: Modelo para avaliar o atendimento a cada requisito, planejar as ações e conferir a informação documentada.
B4: Legenda: onde preencher
B5: Amarelo-claro | C5: Células de entrada. É aqui que você digita.
B6: Cinza | C6: Células calculadas ou fixas (requisitos, perguntas, contagens, avisos). Não altere.
B7: Listas suspensas | C7: Colunas de aplicabilidade, situação e status aceitam apenas as opções da lista. Datas são conferidas na digitação.
B8: Comentários | C8: Na aba Diagnóstico, o título de cada requisito traz um comentário com o resumo do que a norma pede. Passe o mouse sobre ele.
B10: As três situações
B11: Atende | C11: A evidência mostra que o requisito é atendido, de forma consistente. Vale 1 ponto.
B12: Atende em parte | C12: Parte do requisito é atendida, ou ele é atendido em parte dos casos. Vale meio ponto.
B13: Não atende | C13: Não há evidência de atendimento. Não vale ponto.
B15: Ordem recomendada de preenchimento
B16: Passo 1 | C16: Aba Diagnóstico: preencha o cabeçalho e marque como não aplicáveis os requisitos que não valem para a organização, com a justificativa.
B17: Passo 2 | C17: Aba Diagnóstico: para cada requisito, leia a pergunta, procure a evidência e registre a situação.
B18: Passo 3 | C18: Aba Diagnóstico: escreva a evidência encontrada e, quando houver lacuna, o que falta.
B19: Passo 4 | C19: Aba Resumo: leia o percentual por seção e o estágio do sistema.
B20: Passo 5 | C20: Aba Plano de ação: escreva uma ação para cada lacuna, com responsável e prazo.
B21: Passo 6 | C21: Aba Documentos: confira se a informação documentada exigida pela norma existe.
B22: Passo 7 | C22: Aba Checklist: valide o sistema antes da auditoria interna.
B24: Abas da planilha
B25: Diagnóstico | C25: Os 45 requisitos do estudo, com pergunta, aplicabilidade, situação, evidência e lacuna.
B26: Resumo | C26: Resultado por seção, percentual de atendimento, estágio do sistema e gráfico.
B27: Plano de ação | C27: Ações para as lacunas, com requisito, responsável, prazo e status.
B28: Documentos | C28: A informação documentada exigida pela norma, com o documento ou o registro da organização.
B29: Checklist | C29: Doze verificações do sistema, com percentual de conclusão.
B30: Exemplo 1 - Pizzaria | C30: Diagnóstico completo de uma organização pequena, nas sete seções.
B31: Exemplo 2 - Compras | C31: Diagnóstico de um processo, com os requisitos ligados a ele.
B33: Regras e premissas do modelo
B34: Requisitos | C34: A lista tem 45 itens. Os requisitos 7.1.1 e 7.1.2 foram reunidos, e os itens dos requisitos 8.3 e 9.3 foram tratados em conjunto. As perguntas e os resumos foram escritos com palavras próprias e não substituem o texto da norma.
B35: Percentual | C35: Atendimento = (requisitos atendidos + metade dos atendidos em parte) ÷ requisitos avaliados. Os requisitos não aplicáveis ficam fora da conta. A pontuação é uma convenção deste modelo.
B36: Estágio | C36: Abaixo de 50%: inicial. De 50% a 79%: em implantação. A partir de 80%, sem requisito não atendido: pronto para a auditoria interna. As faixas são uma convenção deste modelo.
B37: Não aplicável | C37: Todo requisito marcado como não aplicável pede justificativa na coluna de evidência. A justificativa também vai para o escopo do sistema.
B38: Diagnóstico e auditoria | C38: O diagnóstico é uma autoavaliação. Ele orienta a implantação e não substitui a auditoria interna, que pede auditor independente.
B39: Exemplos | C39: Os dados das abas de exemplo são ilustrativos, criados para este material.

Sheet Diagnóstico
B1: Diagnóstico de atendimento à ISO 9001:2015
B2: Registre a situação de cada requisito, com a evidência encontrada e o que falta.
B4: Organização ou processo | G4: Data do diagnóstico
B5: Escopo avaliado | G5: Responsável
B7: Requisito | C7: Título | D7: Pergunta de diagnóstico | E7: Aplicável? | F7: Situação | G7: Evidência encontrada | H7: O que falta | I7: Pontos | J7: Conferência | K7: Seção
B8: Da norma | C8: Passe o mouse para ler o resumo | D8: Responda com fatos | E8: Sim ou Não | F8: Escolha na lista | G8: Documento, registro, local e data | H8: Só quando houver lacuna | I8: Calculado | J8: Calculada
B9: Seção 4 · Contexto da organização
B10: 4.1 | C10: Entendendo a organização e seu contexto | D10: Que fatores, de dentro e de fora, mais afetam os resultados? | E10: Sim | I10: =IF(OR(E10="Não",F10=""),"",IF(F10="Atende",1,IF(F10="Atende em parte",0.5,0))) | J10: =IF(E10="Não",IF(G10="","Justifique a não aplicabilidade","Não aplicável"),IF(F10="","Não avaliado",IF(G10="","Falta a evidência",IF(AND(F10<>"Atende",H10=""),"Falta a lacuna","Completo")))) -> Não avaliado | K10: 4
B11: 4.2 | C11: Entendendo as necessidades e expectativas de partes interessadas | D11: Quem é afetado pelo sistema, e o que cada um espera? | E11: Sim | I11: =IF(OR(E11="Não",F11=""),"",IF(F11="Atende",1,IF(F11="Atende em parte",0.5,0))) | J11: =IF(E11="Não",IF(G11="","Justifique a não aplicabilidade","Não aplicável"),IF(F11="","Não avaliado",IF(G11="","Falta a evidência",IF(AND(F11<>"Atende",H11=""),"Falta a lacuna","Completo")))) -> Não avaliado | K11: 4
B12: 4.3 | C12: Determinando o escopo do sistema de gestão da qualidade | D12: O que está dentro do sistema, e por que algum requisito não se aplica? | E12: Sim | I12: =IF(OR(E12="Não",F12=""),"",IF(F12="Atende",1,IF(F12="Atende em parte",0.5,0))) | J12: =IF(E12="Não",IF(G12="","Justifique a não aplicabilidade","Não aplicável"),IF(F12="","Não avaliado",IF(G12="","Falta a evidência",IF(AND(F12<>"Atende",H12=""),"Falta a lacuna","Completo")))) -> Não avaliado | K12: 4
B13: 4.4 | C13: Sistema de gestão da qualidade e seus processos | D13: Quais são os processos, como se ligam e como se sabe que funcionam? | E13: Sim | I13: =IF(OR(E13="Não",F13=""),"",IF(F13="Atende",1,IF(F13="Atende em parte",0.5,0))) | J13: =IF(E13="Não",IF(G13="","Justifique a não aplicabilidade","Não aplicável"),IF(F13="","Não avaliado",IF(G13="","Falta a evidência",IF(AND(F13<>"Atende",H13=""),"Falta a lacuna","Completo")))) -> Não avaliado | K13: 4
B14: Seção 5 · Liderança
B15: 5.1.1 | C15: Liderança e comprometimento: generalidades | D15: Como a direção participa do sistema, além de assinar documentos? | E15: Sim | I15: =IF(OR(E15="Não",F15=""),"",IF(F15="Atende",1,IF(F15="Atende em parte",0.5,0))) | J15: =IF(E15="Não",IF(G15="","Justifique a não aplicabilidade","Não aplicável"),IF(F15="","Não avaliado",IF(G15="","Falta a evidência",IF(AND(F15<>"Atende",H15=""),"Falta a lacuna","Completo")))) -> Não avaliado | K15: 5
B16: 5.1.2 | C16: Foco no cliente | D16: Como a direção acompanha o que o cliente pede e o que ele recebe? | E16: Sim | I16: =IF(OR(E16="Não",F16=""),"",IF(F16="Atende",1,IF(F16="Atende em parte",0.5,0))) | J16: =IF(E16="Não",IF(G16="","Justifique a não aplicabilidade","Não aplicável"),IF(F16="","Não avaliado",IF(G16="","Falta a evidência",IF(AND(F16<>"Atende",H16=""),"Falta a lacuna","Completo")))) -> Não avaliado | K16: 5
B17: 5.2 | C17: Política | D17: O que a política diz, e como as pessoas a aplicam no trabalho? | E17: Sim | I17: =IF(OR(E17="Não",F17=""),"",IF(F17="Atende",1,IF(F17="Atende em parte",0.5,0))) | J17: =IF(E17="Não",IF(G17="","Justifique a não aplicabilidade","Não aplicável"),IF(F17="","Não avaliado",IF(G17="","Falta a evidência",IF(AND(F17<>"Atende",H17=""),"Falta a lacuna","Completo")))) -> Não avaliado | K17: 5
B18: 5.3 | C18: Papéis, responsabilidades e autoridades organizacionais | D18: Quem responde por quê, e quem pode decidir? | E18: Sim | I18: =IF(OR(E18="Não",F18=""),"",IF(F18="Atende",1,IF(F18="Atende em parte",0.5,0))) | J18: =IF(E18="Não",IF(G18="","Justifique a não aplicabilidade","Não aplicável"),IF(F18="","Não avaliado",IF(G18="","Falta a evidência",IF(AND(F18<>"Atende",H18=""),"Falta a lacuna","Completo")))) -> Não avaliado | K18: 5
B19: Seção 6 · Planejamento
B20: 6.1 | C20: Ações para abordar riscos e oportunidades | D20: O que pode dar errado, o que pode ser aproveitado, e o que foi feito? | E20: Sim | I20: =IF(OR(E20="Não",F20=""),"",IF(F20="Atende",1,IF(F20="Atende em parte",0.5,0))) | J20: =IF(E20="Não",IF(G20="","Justifique a não aplicabilidade","Não aplicável"),IF(F20="","Não avaliado",IF(G20="","Falta a evidência",IF(AND(F20<>"Atende",H20=""),"Falta a lacuna","Completo")))) -> Não avaliado | K20: 6
B21: 6.2 | C21: Objetivos da qualidade e planejamento para alcançá-los | D21: Quais são os objetivos, e qual é o plano para cada um? | E21: Sim | I21: =IF(OR(E21="Não",F21=""),"",IF(F21="Atende",1,IF(F21="Atende em parte",0.5,0))) | J21: =IF(E21="Não",IF(G21="","Justifique a não aplicabilidade","Não aplicável"),IF(F21="","Não avaliado",IF(G21="","Falta a evidência",IF(AND(F21<>"Atende",H21=""),"Falta a lacuna","Completo")))) -> Não avaliado | K21: 6
B22: 6.3 | C22: Planejamento de mudanças | D22: Como foi planejada a última mudança importante? | E22: Sim | I22: =IF(OR(E22="Não",F22=""),"",IF(F22="Atende",1,IF(F22="Atende em parte",0.5,0))) | J22: =IF(E22="Não",IF(G22="","Justifique a não aplicabilidade","Não aplicável"),IF(F22="","Não avaliado",IF(G22="","Falta a evidência",IF(AND(F22<>"Atende",H22=""),"Falta a lacuna","Completo")))) -> Não avaliado | K22: 6
B23: Seção 7 · Apoio
B24: 7.1.1 | C24: Recursos: generalidades e pessoas (7.1.1 e 7.1.2) | D24: Os recursos e as pessoas são suficientes para o que foi planejado? | E24: Sim | I24: =IF(OR(E24="Não",F24=""),"",IF(F24="Atende",1,IF(F24="Atende em parte",0.5,0))) | J24: =IF(E24="Não",IF(G24="","Justifique a não aplicabilidade","Não aplicável"),IF(F24="","Não avaliado",IF(G24="","Falta a evidência",IF(AND(F24<>"Atende",H24=""),"Falta a lacuna","Completo")))) -> Não avaliado | K24: 7
B25: 7.1.3 | C25: Infraestrutura | D25: Como os equipamentos e os sistemas são mantidos? | E25: Sim | I25: =IF(OR(E25="Não",F25=""),"",IF(F25="Atende",1,IF(F25="Atende em parte",0.5,0))) | J25: =IF(E25="Não",IF(G25="","Justifique a não aplicabilidade","Não aplicável"),IF(F25="","Não avaliado",IF(G25="","Falta a evidência",IF(AND(F25<>"Atende",H25=""),"Falta a lacuna","Completo")))) -> Não avaliado | K25: 7
B26: 7.1.4 | C26: Ambiente para a operação dos processos | D26: Que condições do ambiente afetam o produto ou o serviço? | E26: Sim | I26: =IF(OR(E26="Não",F26=""),"",IF(F26="Atende",1,IF(F26="Atende em parte",0.5,0))) | J26: =IF(E26="Não",IF(G26="","Justifique a não aplicabilidade","Não aplicável"),IF(F26="","Não avaliado",IF(G26="","Falta a evidência",IF(AND(F26<>"Atende",H26=""),"Falta a lacuna","Completo")))) -> Não avaliado | K26: 7
B27: 7.1.5 | C27: Recursos de monitoramento e medição | D27: Como se sabe que os instrumentos medem certo? | E27: Sim | I27: =IF(OR(E27="Não",F27=""),"",IF(F27="Atende",1,IF(F27="Atende em parte",0.5,0))) | J27: =IF(E27="Não",IF(G27="","Justifique a não aplicabilidade","Não aplicável"),IF(F27="","Não avaliado",IF(G27="","Falta a evidência",IF(AND(F27<>"Atende",H27=""),"Falta a lacuna","Completo")))) -> Não avaliado | K27: 7
B28: 7.1.6 | C28: Conhecimento organizacional | D28: O que acontece se a pessoa que sabe fazer sair da organização? | E28: Sim | I28: =IF(OR(E28="Não",F28=""),"",IF(F28="Atende",1,IF(F28="Atende em parte",0.5,0))) | J28: =IF(E28="Não",IF(G28="","Justifique a não aplicabilidade","Não aplicável"),IF(F28="","Não avaliado",IF(G28="","Falta a evidência",IF(AND(F28<>"Atende",H28=""),"Falta a lacuna","Completo")))) -> Não avaliado | K28: 7
B29: 7.2 | C29: Competência | D29: Que competência o cargo exige, e como se sabe que a pessoa a tem? | E29: Sim | I29: =IF(OR(E29="Não",F29=""),"",IF(F29="Atende",1,IF(F29="Atende em parte",0.5,0))) | J29: =IF(E29="Não",IF(G29="","Justifique a não aplicabilidade","Não aplicável"),IF(F29="","Não avaliado",IF(G29="","Falta a evidência",IF(AND(F29<>"Atende",H29=""),"Falta a lacuna","Completo")))) -> Não avaliado | K29: 7
B30: 7.3 | C30: Conscientização | D30: Para quem executa: como o seu trabalho afeta o cliente? | E30: Sim | I30: =IF(OR(E30="Não",F30=""),"",IF(F30="Atende",1,IF(F30="Atende em parte",0.5,0))) | J30: =IF(E30="Não",IF(G30="","Justifique a não aplicabilidade","Não aplicável"),IF(F30="","Não avaliado",IF(G30="","Falta a evidência",IF(AND(F30<>"Atende",H30=""),"Falta a lacuna","Completo")))) -> Não avaliado | K30: 7
B31: 7.4 | C31: Comunicação | D31: Como as informações importantes chegam a quem precisa? | E31: Sim | I31: =IF(OR(E31="Não",F31=""),"",IF(F31="Atende",1,IF(F31="Atende em parte",0.5,0))) | J31: =IF(E31="Não",IF(G31="","Justifique a não aplicabilidade","Não aplicável"),IF(F31="","Não avaliado",IF(G31="","Falta a evidência",IF(AND(F31<>"Atende",H31=""),"Falta a lacuna","Completo")))) -> Não avaliado | K31: 7
B32: 7.5 | C32: Informação documentada | D32: Como se sabe que o documento em uso é a versão válida? | E32: Sim | I32: =IF(OR(E32="Não",F32=""),"",IF(F32="Atende",1,IF(F32="Atende em parte",0.5,0))) | J32: =IF(E32="Não",IF(G32="","Justifique a não aplicabilidade","Não aplicável"),IF(F32="","Não avaliado",IF(G32="","Falta a evidência",IF(AND(F32<>"Atende",H32=""),"Falta a lacuna","Completo")))) -> Não avaliado | K32: 7
B33: Seção 8 · Operação
B34: 8.1 | C34: Planejamento e controle operacionais | D34: Como a operação é planejada e controlada? | E34: Sim | I34: =IF(OR(E34="Não",F34=""),"",IF(F34="Atende",1,IF(F34="Atende em parte",0.5,0))) | J34: =IF(E34="Não",IF(G34="","Justifique a não aplicabilidade","Não aplicável"),IF(F34="","Não avaliado",IF(G34="","Falta a evidência",IF(AND(F34<>"Atende",H34=""),"Falta a lacuna","Completo")))) -> Não avaliado | K34: 8
B35: 8.2.1 | C35: Comunicação com o cliente | D35: Por onde o cliente pergunta, pede e reclama? | E35: Sim | I35: =IF(OR(E35="Não",F35=""),"",IF(F35="Atende",1,IF(F35="Atende em parte",0.5,0))) | J35: =IF(E35="Não",IF(G35="","Justifique a não aplicabilidade","Não aplicável"),IF(F35="","Não avaliado",IF(G35="","Falta a evidência",IF(AND(F35<>"Atende",H35=""),"Falta a lacuna","Completo")))) -> Não avaliado | K35: 8
B36: 8.2.2 | C36: Determinação de requisitos relativos a produtos e serviços | D36: Onde estão definidos os requisitos do que é oferecido? | E36: Sim | I36: =IF(OR(E36="Não",F36=""),"",IF(F36="Atende",1,IF(F36="Atende em parte",0.5,0))) | J36: =IF(E36="Não",IF(G36="","Justifique a não aplicabilidade","Não aplicável"),IF(F36="","Não avaliado",IF(G36="","Falta a evidência",IF(AND(F36<>"Atende",H36=""),"Falta a lacuna","Completo")))) -> Não avaliado | K36: 8
B37: 8.2.3 | C37: Análise crítica de requisitos relativos a produtos e serviços | D37: Como se confirma, antes de aceitar o pedido, que é possível atendê-lo? | E37: Sim | I37: =IF(OR(E37="Não",F37=""),"",IF(F37="Atende",1,IF(F37="Atende em parte",0.5,0))) | J37: =IF(E37="Não",IF(G37="","Justifique a não aplicabilidade","Não aplicável"),IF(F37="","Não avaliado",IF(G37="","Falta a evidência",IF(AND(F37<>"Atende",H37=""),"Falta a lacuna","Completo")))) -> Não avaliado | K37: 8
B38: 8.2.4 | C38: Mudanças nos requisitos para produtos e serviços | D38: O que acontece quando o cliente muda o pedido? | E38: Sim | I38: =IF(OR(E38="Não",F38=""),"",IF(F38="Atende",1,IF(F38="Atende em parte",0.5,0))) | J38: =IF(E38="Não",IF(G38="","Justifique a não aplicabilidade","Não aplicável"),IF(F38="","Não avaliado",IF(G38="","Falta a evidência",IF(AND(F38<>"Atende",H38=""),"Falta a lacuna","Completo")))) -> Não avaliado | K38: 8
B39: 8.3 | C39: Projeto e desenvolvimento de produtos e serviços | D39: Como uma ideia vira produto ou serviço, e como se confirma que ele funciona? | E39: Sim | I39: =IF(OR(E39="Não",F39=""),"",IF(F39="Atende",1,IF(F39="Atende em parte",0.5,0))) | J39: =IF(E39="Não",IF(G39="","Justifique a não aplicabilidade","Não aplicável"),IF(F39="","Não avaliado",IF(G39="","Falta a evidência",IF(AND(F39<>"Atende",H39=""),"Falta a lacuna","Completo")))) -> Não avaliado | K39: 8
B40: 8.4.1 | C40: Provedores externos: generalidades | D40: Como os fornecedores são escolhidos e acompanhados? | E40: Sim | I40: =IF(OR(E40="Não",F40=""),"",IF(F40="Atende",1,IF(F40="Atende em parte",0.5,0))) | J40: =IF(E40="Não",IF(G40="","Justifique a não aplicabilidade","Não aplicável"),IF(F40="","Não avaliado",IF(G40="","Falta a evidência",IF(AND(F40<>"Atende",H40=""),"Falta a lacuna","Completo")))) -> Não avaliado | K40: 8
B41: 8.4.2 | C41: Provedores externos: tipo e extensão do controle | D41: O que é conferido no recebimento, e por que esse nível de controle? | E41: Sim | I41: =IF(OR(E41="Não",F41=""),"",IF(F41="Atende",1,IF(F41="Atende em parte",0.5,0))) | J41: =IF(E41="Não",IF(G41="","Justifique a não aplicabilidade","Não aplicável"),IF(F41="","Não avaliado",IF(G41="","Falta a evidência",IF(AND(F41<>"Atende",H41=""),"Falta a lacuna","Completo")))) -> Não avaliado | K41: 8
B42: 8.4.3 | C42: Provedores externos: informação | D42: O pedido de compra diz tudo o que o fornecedor precisa saber? | E42: Sim | I42: =IF(OR(E42="Não",F42=""),"",IF(F42="Atende",1,IF(F42="Atende em parte",0.5,0))) | J42: =IF(E42="Não",IF(G42="","Justifique a não aplicabilidade","Não aplicável"),IF(F42="","Não avaliado",IF(G42="","Falta a evidência",IF(AND(F42<>"Atende",H42=""),"Falta a lacuna","Completo")))) -> Não avaliado | K42: 8
...

Sheet Resumo
B1: Resumo do diagnóstico
B2: Resultado por seção da norma. Esta aba é calculada a partir da aba Diagnóstico.
B4: Organização ou processo | D4: =IF(Diagnóstico!D4="","",Diagnóstico!D4) | G4: Data do diagnóstico | H4: =IF(Diagnóstico!H4="","",Diagnóstico!H4)
B6: Seção | C6: Título | D6: Aplicáveis | E6: Avaliados | F6: Atende | G6: Atende em parte | H6: Não atende | I6: Atendimento
B7: 4 | C7: 4 · Contexto da organização | D7: =SUMPRODUCT((Diagnóstico!$K$9:$K$60=4)*(Diagnóstico!$E$9:$E$60<>"Não")) -> 4 | E7: =SUMPRODUCT((Diagnóstico!$K$9:$K$60=4)*(Diagnóstico!$E$9:$E$60<>"Não")*(Diagnóstico!$F$9:$F$60<>"")) -> 0 | F7: =SUMPRODUCT((Diagnóstico!$K$9:$K$60=4)*(Diagnóstico!$E$9:$E$60<>"Não")*(Diagnóstico!$F$9:$F$60="Atende")) -> 0 | G7: =SUMPRODUCT((Diagnóstico!$K$9:$K$60=4)*(Diagnóstico!$E$9:$E$60<>"Não")*(Diagnóstico!$F$9:$F$60="Atende em parte")) -> 0 | H7: =SUMPRODUCT((Diagnóstico!$K$9:$K$60=4)*(Diagnóstico!$E$9:$E$60<>"Não")*(Diagnóstico!$F$9:$F$60="Não atende")) -> 0 | I7: =IF(E7=0,"",(F7+0.5*G7)/E7)
B8: 5 | C8: 5 · Liderança | D8: =SUMPRODUCT((Diagnóstico!$K$9:$K$60=5)*(Diagnóstico!$E$9:$E$60<>"Não")) -> 4 | E8: =SUMPRODUCT((Diagnóstico!$K$9:$K$60=5)*(Diagnóstico!$E$9:$E$60<>"Não")*(Diagnóstico!$F$9:$F$60<>"")) -> 0 | F8: =SUMPRODUCT((Diagnóstico!$K$9:$K$60=5)*(Diagnóstico!$E$9:$E$60<>"Não")*(Diagnóstico!$F$9:$F$60="Atende")) -> 0 | G8: =SUMPRODUCT((Diagnóstico!$K$9:$K$60=5)*(Diagnóstico!$E$9:$E$60<>"Não")*(Diagnóstico!$F$9:$F$60="Atende em parte")) -> 0 | H8: =SUMPRODUCT((Diagnóstico!$K$9:$K$60=5)*(Diagnóstico!$E$9:$E$60<>"Não")*(Diagnóstico!$F$9:$F$60="Não atende")) -> 0 | I8: =IF(E8=0,"",(F8+0.5*G8)/E8)
B9: 6 | C9: 6 · Planejamento | D9: =SUMPRODUCT((Diagnóstico!$K$9:$K$60=6)*(Diagnóstico!$E$9:$E$60<>"Não")) -> 3 | E9: =SUMPRODUCT((Diagnóstico!$K$9:$K$60=6)*(Diagnóstico!$E$9:$E$60<>"Não")*(Diagnóstico!$F$9:$F$60<>"")) -> 0 | F9: =SUMPRODUCT((Diagnóstico!$K$9:$K$60=6)*(Diagnóstico!$E$9:$E$60<>"Não")*(Diagnóstico!$F$9:$F$60="Atende")) -> 0 | G9: =SUMPRODUCT((Diagnóstico!$K$9:$K$60=6)*(Diagnóstico!$E$9:$E$60<>"Não")*(Diagnóstico!$F$9:$F$60="Atende em parte")) -> 0 | H9: =SUMPRODUCT((Diagnóstico!$K$9:$K$60=6)*(Diagnóstico!$E$9:$E$60<>"Não")*(Diagnóstico!$F$9:$F$60="Não atende")) -> 0 | I9: =IF(E9=0,"",(F9+0.5*G9)/E9)
B10: 7 | C10: 7 · Apoio | D10: =SUMPRODUCT((Diagnóstico!$K$9:$K$60=7)*(Diagnóstico!$E$9:$E$60<>"Não")) -> 9 | E10: =SUMPRODUCT((Diagnóstico!$K$9:$K$60=7)*(Diagnóstico!$E$9:$E$60<>"Não")*(Diagnóstico!$F$9:$F$60<>"")) -> 0 | F10: =SUMPRODUCT((Diagnóstico!$K$9:$K$60=7)*(Diagnóstico!$E$9:$E$60<>"Não")*(Diagnóstico!$F$9:$F$60="Atende")) -> 0 | G10: =SUMPRODUCT((Diagnóstico!$K$9:$K$60=7)*(Diagnóstico!$E$9:$E$60<>"Não")*(Diagnóstico!$F$9:$F$60="Atende em parte")) -> 0 | H10: =SUMPRODUCT((Diagnóstico!$K$9:$K$60=7)*(Diagnóstico!$E$9:$E$60<>"Não")*(Diagnóstico!$F$9:$F$60="Não atende")) -> 0 | I10: =IF(E10=0,"",(F10+0.5*G10)/E10)
B11: 8 | C11: 8 · Operação | D11: =SUMPRODUCT((Diagnóstico!$K$9:$K$60=8)*(Diagnóstico!$E$9:$E$60<>"Não")) -> 17 | E11: =SUMPRODUCT((Diagnóstico!$K$9:$K$60=8)*(Diagnóstico!$E$9:$E$60<>"Não")*(Diagnóstico!$F$9:$F$60<>"")) -> 0 | F11: =SUMPRODUCT((Diagnóstico!$K$9:$K$60=8)*(Diagnóstico!$E$9:$E$60<>"Não")*(Diagnóstico!$F$9:$F$60="Atende")) -> 0 | G11: =SUMPRODUCT((Diagnóstico!$K$9:$K$60=8)*(Diagnóstico!$E$9:$E$60<>"Não")*(Diagnóstico!$F$9:$F$60="Atende em parte")) -> 0 | H11: =SUMPRODUCT((Diagnóstico!$K$9:$K$60=8)*(Diagnóstico!$E$9:$E$60<>"Não")*(Diagnóstico!$F$9:$F$60="Não atende")) -> 0 | I11: =IF(E11=0,"",(F11+0.5*G11)/E11)
B12: 9 | C12: 9 · Avaliação de desempenho | D12: =SUMPRODUCT((Diagnóstico!$K$9:$K$60=9)*(Diagnóstico!$E$9:$E$60<>"Não")) -> 5 | E12: =SUMPRODUCT((Diagnóstico!$K$9:$K$60=9)*(Diagnóstico!$E$9:$E$60<>"Não")*(Diagnóstico!$F$9:$F$60<>"")) -> 0 | F12: =SUMPRODUCT((Diagnóstico!$K$9:$K$60=9)*(Diagnóstico!$E$9:$E$60<>"Não")*(Diagnóstico!$F$9:$F$60="Atende")) -> 0 | G12: =SUMPRODUCT((Diagnóstico!$K$9:$K$60=9)*(Diagnóstico!$E$9:$E$60<>"Não")*(Diagnóstico!$F$9:$F$60="Atende em parte")) -> 0 | H12: =SUMPRODUCT((Diagnóstico!$K$9:$K$60=9)*(Diagnóstico!$E$9:$E$60<>"Não")*(Diagnóstico!$F$9:$F$60="Não atende")) -> 0 | I12: =IF(E12=0,"",(F12+0.5*G12)/E12)
B13: 10 | C13: 10 · Melhoria | D13: =SUMPRODUCT((Diagnóstico!$K$9:$K$60=10)*(Diagnóstico!$E$9:$E$60<>"Não")) -> 3 | E13: =SUMPRODUCT((Diagnóstico!$K$9:$K$60=10)*(Diagnóstico!$E$9:$E$60<>"Não")*(Diagnóstico!$F$9:$F$60<>"")) -> 0 | F13: =SUMPRODUCT((Diagnóstico!$K$9:$K$60=10)*(Diagnóstico!$E$9:$E$60<>"Não")*(Diagnóstico!$F$9:$F$60="Atende")) -> 0 | G13: =SUMPRODUCT((Diagnóstico!$K$9:$K$60=10)*(Diagnóstico!$E$9:$E$60<>"Não")*(Diagnóstico!$F$9:$F$60="Atende em parte")) -> 0 | H13: =SUMPRODUCT((Diagnóstico!$K$9:$K$60=10)*(Diagnóstico!$E$9:$E$60<>"Não")*(Diagnóstico!$F$9:$F$60="Não atende")) -> 0 | I13: =IF(E13=0,"",(F13+0.5*G13)/E13)
B14: Total | D14: =SUM(D7:D13) -> 45 | E14: =SUM(E7:E13) -> 0 | F14: =SUM(F7:F13) -> 0 | G14: =SUM(G7:G13) -> 0 | H14: =SUM(H7:H13) -> 0 | I14: =IF(E14=0,"",(F14+0.5*G14)/E14)
B16: Resumo automático
B17: Requisitos não aplicáveis | E17: =COUNTIF(Diagnóstico!$E$9:$E$60,"Não") -> 0
B18: Requisitos ainda não avaliados | E18: =D14-E14 -> 45
B19: Percentual de atendimento | E19: =I14
B20: Seção com o menor atendimento | E20: =IF(COUNT(I7:I13)=0,"",INDEX(C7:C13,MATCH(MIN(I7:I13),I7:I13,0)))
B21: Estágio do sistema | E21: =IF(I14="","Sem avaliação",IF(I14<0.5,"Inicial",IF(I14<0.8,"Em implantação",IF(H14>0,"Em implantação: há requisito não atendido","Pronto para a auditoria interna")))) -> Sem avaliação
B22: Aviso | E22: =IF(E14=0,"Preencha a aba Diagnóstico",IF(COUNTIF(Diagnóstico!$J$9:$J$60,"Justifique*")>0,"Há requisito não aplicável sem justificativa",IF(D14-E14>0,"Há requisito sem avaliação: o percentual é parcial",IF(COUNTIF(Diagnóstico!$J$9:$J$60,"Falta*")>0,"Há requisito sem evidência ou sem lacuna registrada","OK")))) -> Preencha a aba Diagnóstico

Sheet Plano de ação
B1: Plano de ação do diagnóstico
B2: Uma ação para cada lacuna. O título e a lacuna vêm da aba Diagnóstico.
B4: # | C4: Requisito | D4: Título | E4: O que falta | F4: Ação | G4: Responsável | H4: Prazo | I4: Status | J4: Concluída em | K4: Situação
C5: Escolha na lista | D5: Calculado | E5: Calculado | F5: Verbo no infinitivo e resultado esperado | G5: Cargo ou nome | H5: Data | I5: Da ação | J5: Data | K5: Calculada
B6: Ex. | C6: 4.3 | D6: Determinando o escopo do sistema de gestão da qualidade | E6: Escrever o escopo: produtos, loja, canais de venda e requisitos não aplicáveis. | F6: Escrever a declaração de escopo e aprová-la com o dono. | G6: Gerente da loja | H6: 46325 | I6: Em andamento | K6: No prazo
B7: 1 | D7: =IF(C7="","",IF(ISNUMBER(MATCH(C7&"",Diagnóstico!$B$9:$B$60,0)),INDEX(Diagnóstico!$C$9:$C$60,MATCH(C7&"",Diagnóstico!$B$9:$B$60,0)),"Requisito não encontrado")) | E7: =IF(C7="","",IF(ISNUMBER(MATCH(C7&"",Diagnóstico!$B$9:$B$60,0)),INDEX(Diagnóstico!$H$9:$H$60,MATCH(C7&"",Diagnóstico!$B$9:$B$60,0))&"","")) | K7: =IF(F7="","",IF(I7="Concluída","Concluída",IF(I7="Cancelada","Cancelada",IF(H7="","Sem prazo",IF(H7<TODAY(),"Atrasada","No prazo")))))
B8: 2 | D8: =IF(C8="","",IF(ISNUMBER(MATCH(C8&"",Diagnóstico!$B$9:$B$60,0)),INDEX(Diagnóstico!$C$9:$C$60,MATCH(C8&"",Diagnóstico!$B$9:$B$60,0)),"Requisito não encontrado")) | E8: =IF(C8="","",IF(ISNUMBER(MATCH(C8&"",Diagnóstico!$B$9:$B$60,0)),INDEX(Diagnóstico!$H$9:$H$60,MATCH(C8&"",Diagnóstico!$B$9:$B$60,0))&"","")) | K8: =IF(F8="","",IF(I8="Concluída","Concluída",IF(I8="Cancelada","Cancelada",IF(H8="","Sem prazo",IF(H8<TODAY(),"Atrasada","No prazo")))))
B9: 3 | D9: =IF(C9="","",IF(ISNUMBER(MATCH(C9&"",Diagnóstico!$B$9:$B$60,0)),INDEX(Diagnóstico!$C$9:$C$60,MATCH(C9&"",Diagnóstico!$B$9:$B$60,0)),"Requisito não encontrado")) | E9: =IF(C9="","",IF(ISNUMBER(MATCH(C9&"",Diagnóstico!$B$9:$B$60,0)),INDEX(Diagnóstico!$H$9:$H$60,MATCH(C9&"",Diagnóstico!$B$9:$B$60,0))&"","")) | K9: =IF(F9="","",IF(I9="Concluída","Concluída",IF(I9="Cancelada","Cancelada",IF(H9="","Sem prazo",IF(H9<TODAY(),"Atrasada","No prazo")))))
B10: 4 | D10: =IF(C10="","",IF(ISNUMBER(MATCH(C10&"",Diagnóstico!$B$9:$B$60,0)),INDEX(Diagnóstico!$C$9:$C$60,MATCH(C10&"",Diagnóstico!$B$9:$B$60,0)),"Requisito não encontrado")) | E10: =IF(C10="","",IF(ISNUMBER(MATCH(C10&"",Diagnóstico!$B$9:$B$60,0)),INDEX(Diagnóstico!$H$9:$H$60,MATCH(C10&"",Diagnóstico!$B$9:$B$60,0))&"","")) | K10: =IF(F10="","",IF(I10="Concluída","Concluída",IF(I10="Cancelada","Cancelada",IF(H10="","Sem prazo",IF(H10<TODAY(),"Atrasada","No prazo")))))
B11: 5 | D11: =IF(C11="","",IF(ISNUMBER(MATCH(C11&"",Diagnóstico!$B$9:$B$60,0)),INDEX(Diagnóstico!$C$9:$C$60,MATCH(C11&"",Diagnóstico!$B$9:$B$60,0)),"Requisito não encontrado")) | E11: =IF(C11="","",IF(ISNUMBER(MATCH(C11&"",Diagnóstico!$B$9:$B$60,0)),INDEX(Diagnóstico!$H$9:$H$60,MATCH(C11&"",Diagnóstico!$B$9:$B$60,0))&"","")) | K11: =IF(F11="","",IF(I11="Concluída","Concluída",IF(I11="Cancelada","Cancelada",IF(H11="","Sem prazo",IF(H11<TODAY(),"Atrasada","No prazo")))))
B12: 6 | D12: =IF(C12="","",IF(ISNUMBER(MATCH(C12&"",Diagnóstico!$B$9:$B$60,0)),INDEX(Diagnóstico!$C$9:$C$60,MATCH(C12&"",Diagnóstico!$B$9:$B$60,0)),"Requisito não encontrado")) | E12: =IF(C12="","",IF(ISNUMBER(MATCH(C12&"",Diagnóstico!$B$9:$B$60,0)),INDEX(Diagnóstico!$H$9:$H$60,MATCH(C12&"",Diagnóstico!$B$9:$B$60,0))&"","")) | K12: =IF(F12="","",IF(I12="Concluída","Concluída",IF(I12="Cancelada","Cancelada",IF(H12="","Sem prazo",IF(H12<TODAY(),"Atrasada","No prazo")))))
B13: 7 | D13: =IF(C13="","",IF(ISNUMBER(MATCH(C13&"",Diagnóstico!$B$9:$B$60,0)),INDEX(Diagnóstico!$C$9:$C$60,MATCH(C13&"",Diagnóstico!$B$9:$B$60,0)),"Requisito não encontrado")) | E13: =IF(C13="","",IF(ISNUMBER(MATCH(C13&"",Diagnóstico!$B$9:$B$60,0)),INDEX(Diagnóstico!$H$9:$H$60,MATCH(C13&"",Diagnóstico!$B$9:$B$60,0))&"","")) | K13: =IF(F13="","",IF(I13="Concluída","Concluída",IF(I13="Cancelada","Cancelada",IF(H13="","Sem prazo",IF(H13<TODAY(),"Atrasada","No prazo")))))
B14: 8 | D14: =IF(C14="","",IF(ISNUMBER(MATCH(C14&"",Diagnóstico!$B$9:$B$60,0)),INDEX(Diagnóstico!$C$9:$C$60,MATCH(C14&"",Diagnóstico!$B$9:$B$60,0)),"Requisito não encontrado")) | E14: =IF(C14="","",IF(ISNUMBER(MATCH(C14&"",Diagnóstico!$B$9:$B$60,0)),INDEX(Diagnóstico!$H$9:$H$60,MATCH(C14&"",Diagnóstico!$B$9:$B$60,0))&"","")) | K14: =IF(F14="","",IF(I14="Concluída","Concluída",IF(I14="Cancelada","Cancelada",IF(H14="","Sem prazo",IF(H14<TODAY(),"Atrasada","No prazo")))))
B15: 9 | D15: =IF(C15="","",IF(ISNUMBER(MATCH(C15&"",Diagnóstico!$B$9:$B$60,0)),INDEX(Diagnóstico!$C$9:$C$60,MATCH(C15&"",Diagnóstico!$B$9:$B$60,0)),"Requisito não encontrado")) | E15: =IF(C15="","",IF(ISNUMBER(MATCH(C15&"",Diagnóstico!$B$9:$B$60,0)),INDEX(Diagnóstico!$H$9:$H$60,MATCH(C15&"",Diagnóstico!$B$9:$B$60,0))&"","")) | K15: =IF(F15="","",IF(I15="Concluída","Concluída",IF(I15="Cancelada","Cancelada",IF(H15="","Sem prazo",IF(H15<TODAY(),"Atrasada","No prazo")))))
B16: 10 | D16: =IF(C16="","",IF(ISNUMBER(MATCH(C16&"",Diagnóstico!$B$9:$B$60,0)),INDEX(Diagnóstico!$C$9:$C$60,MATCH(C16&"",Diagnóstico!$B$9:$B$60,0)),"Requisito não encontrado")) | E16: =IF(C16="","",IF(ISNUMBER(MATCH(C16&"",Diagnóstico!$B$9:$B$60,0)),INDEX(Diagnóstico!$H$9:$H$60,MATCH(C16&"",Diagnóstico!$B$9:$B$60,0))&"","")) | K16: =IF(F16="","",IF(I16="Concluída","Concluída",IF(I16="Cancelada","Cancelada",IF(H16="","Sem prazo",IF(H16<TODAY(),"Atrasada","No prazo")))))
B17: 11 | D17: =IF(C17="","",IF(ISNUMBER(MATCH(C17&"",Diagnóstico!$B$9:$B$60,0)),INDEX(Diagnóstico!$C$9:$C$60,MATCH(C17&"",Diagnóstico!$B$9:$B$60,0)),"Requisito não encontrado")) | E17: =IF(C17="","",IF(ISNUMBER(MATCH(C17&"",Diagnóstico!$B$9:$B$60,0)),INDEX(Diagnóstico!$H$9:$H$60,MATCH(C17&"",Diagnóstico!$B$9:$B$60,0))&"","")) | K17: =IF(F17="","",IF(I17="Concluída","Concluída",IF(I17="Cancelada","Cancelada",IF(H17="","Sem prazo",IF(H17<TODAY(),"Atrasada","No prazo")))))
B18: 12 | D18: =IF(C18="","",IF(ISNUMBER(MATCH(C18&"",Diagnóstico!$B$9:$B$60,0)),INDEX(Diagnóstico!$C$9:$C$60,MATCH(C18&"",Diagnóstico!$B$9:$B$60,0)),"Requisito não encontrado")) | E18: =IF(C18="","",IF(ISNUMBER(MATCH(C18&"",Diagnóstico!$B$9:$B$60,0)),INDEX(Diagnóstico!$H$9:$H$60,MATCH(C18&"",Diagnóstico!$B$9:$B$60,0))&"","")) | K18: =IF(F18="","",IF(I18="Concluída","Concluída",IF(I18="Cancelada","Cancelada",IF(H18="","Sem prazo",IF(H18<TODAY(),"Atrasada","No prazo")))))
... B26: 20 | D26: =IF(C26="","",IF(ISNUMBER(MATCH(C26&"",Diagnóstico!$B$9:$B$60,0)),INDEX(Diagnóstico!$C$9:$C$60,MATCH(C26&"",Diagnóstico!$B$9:$B$60,0)),"Requisito não encontrado")) | E26: =IF(C26="","",IF(ISNUMBER(MATCH(C26&"",Diagnóstico!$B$9:$B$60,0)),INDEX(Diagnóstico!$H$9:$H$60,MATCH(C26&"",Diagnóstico!$B$9:$B$60,0))&"","")) | K26: =IF(F26="","",IF(I26="Concluída","Concluída",IF(I26="Cancelada","Cancelada",IF(H26="","Sem prazo",IF(H26<TODAY(),"Atrasada","No prazo")))))
B28: Resumo automático
B29: Ações registradas | E29: =COUNTA(F7:F26) -> 0
B30: Concluídas | E30: =COUNTIF(K7:K26,"Concluída") -> 0
B31: Atrasadas | E31: =COUNTIF(K7:K26,"Atrasada") -> 0
B32: Percentual concluído | E32: =IF(E29-COUNTIF(K7:K26,"Cancelada")<=0,0,E30/(E29-COUNTIF(K7:K26,"Cancelada"))) -> 0
B33: Lacunas do diagnóstico | E33: =SUMPRODUCT((Diagnóstico!$E$9:$E$60<>"Não")*((Diagnóstico!$F$9:$F$60="Atende em parte")+(Diagnóstico!$F$9:$F$60="Não atende"))) -> 0
B34: Lacunas sem ação no plano | E34: =SUMPRODUCT((Diagnóstico!$E$9:$E$60<>"Não")*((Diagnóstico!$F$9:$F$60="Atende em parte")+(Diagnóstico!$F$9:$F$60="Não atende"))*(COUNTIF($C$7:$C$26,Diagnóstico!$B$9:$B$60)=0)) -> 0
B35: Aviso | E35: =IF(E33=0,"Preencha a aba Diagnóstico",IF(E29=0,"Registre as ações",IF(SUMPRODUCT((F7:F26<>"")*(((C7:C26="")+(G7:G26="")+(H7:H26=""))>0))>0,"Há ação sem requisito, responsável ou prazo",IF(E34>0,"Há lacuna sem ação",IF(E31>0,"Há ação atrasada","OK"))))) -> Preencha a aba Diagnóstico

Sheet Documentos
B1: Informação documentada exigida pela norma
B2: Informe o documento ou o registro que atende a cada item, e onde ele fica.
B4: # | C4: Requisito | D4: Verbo | E4: O que precisa existir | F4: Documento ou registro da organização | G4: Onde fica, ou quem responde | H4: Situação
B5: Ex. | C5: 7.2 | D5: Reter | E5: Evidência de competência | F5: Lista de presença e ficha de treinamento | G5: Pasta de pessoal, com o gerente | H5: Existe
B6: 1 | C6: 4.3 | D6: Manter | E6: Escopo do sistema de gestão da qualidade
B7: 2 | C7: 4.4 | D7: Manter | E7: Informação para apoiar a operação dos processos, na extensão necessária
B8: 3 | C8: 4.4 | D8: Reter | E8: Evidência de que os processos são realizados conforme o planejado
B9: 4 | C9: 5.2 | D9: Manter | E9: Política da qualidade
B10: 5 | C10: 6.2 | D10: Manter | E10: Objetivos da qualidade
B11: 6 | C11: 7.1.5 | D11: Reter | E11: Evidência de que os recursos de monitoramento e medição são adequados
B12: 7 | C12: 7.1.5 | D12: Reter | E12: Base usada para calibrar ou verificar, quando não existe padrão de medição
B13: 8 | C13: 7.2 | D13: Reter | E13: Evidência de competência
B14: 9 | C14: 7.5 | D14: Manter | E14: Informação que a organização considera necessária para a eficácia do sistema
B15: 10 | C15: 8.1 | D15: Manter e reter | E15: Informação para ter confiança de que os processos foram realizados conforme o planejado e para demonstrar a conformidade
B16: 11 | C16: 8.2.3 | D16: Reter | E16: Resultados da análise crítica dos requisitos e novos requisitos de produtos e serviços
B17: 12 | C17: 8.3 | D17: Reter | E17: Planejamento, entradas, controles, saídas e mudanças de projeto e desenvolvimento
... B28: 23 | C28: 10.2 | D28: Reter | E28: Natureza das não conformidades, ações tomadas e resultados das ações corretivas
B30: Resumo automático
B31: Itens da lista | F31: =ROWS(H6:H28) -> 23
B32: Existem | F32: =COUNTIF(H6:H28,"Existe") -> 0
B33: Em elaboração | F33: =COUNTIF(H6:H28,"Em elaboração") -> 0
B34: Não existem | F34: =COUNTIF(H6:H28,"Não existe") -> 0
B35: Não aplicáveis | F35: =COUNTIF(H6:H28,"Não aplicável") -> 0
B36: Percentual existente | F36: =IF(F31-F35<=0,0,F32/(F31-F35)) -> 0
B37: Aviso | F37: =IF(COUNTA(H6:H28)=0,"Informe a situação de cada item",IF(COUNTBLANK(H6:H28)>0,"Há item sem situação",IF(SUMPRODUCT((H6:H28="Existe")*(F6:F28=""))>0,"Há item existente sem o nome do documento",IF(F34>0,"Há informação documentada exigida que não existe","OK")))) -> Informe a situação de cada item

Sheet Checklist
B1: Checklist de validação do sistema
B2: Escolha o status de cada item na lista suspensa (coluna em amarelo-claro).
B4: # | C4: Item de verificação | D4: Status | E4: Observações
B5: 1 | C5: O escopo está escrito, com os limites do sistema e as não aplicabilidades justificadas.
B6: 2 | C6: As questões internas e externas e as partes interessadas foram levantadas.
B7: 3 | C7: Os processos estão identificados, com entradas, saídas, responsáveis e indicadores.
B8: 4 | C8: A política e os objetivos da qualidade estão escritos e são conhecidos pela equipe.
B9: 5 | C9: Os riscos e as oportunidades têm ações definidas.
B10: 6 | C10: As competências necessárias estão definidas, e há evidência de que as pessoas as têm.
B11: 7 | C11: Os documentos e os registros exigidos existem e estão controlados.
B12: 8 | C12: Os requisitos do cliente são analisados antes do compromisso de fornecer.
B13: 9 | C13: Os fornecedores são avaliados com critérios definidos.
B14: 10 | C14: Os produtos e os serviços só são liberados depois das verificações planejadas.
B15: 11 | C15: A auditoria interna cobriu todos os requisitos aplicáveis.
B16: 12 | C16: A direção analisou criticamente o sistema, e as não conformidades têm ação corretiva.
B18: Resumo automático
B19: Itens atendidos (Sim) | D19: =COUNTIF(D5:D16,"Sim") -> 0
B20: Itens parciais | D20: =COUNTIF(D5:D16,"Parcial") -> 0
B21: Itens não atendidos | D21: =COUNTIF(D5:D16,"Não") -> 0
B22: Itens sem resposta | D22: =COUNTBLANK(D5:D16) -> 12
B23: Percentual atendido | D23: =D19/ROWS(D5:D16) -> 0
B24: Situação | D24: =IF(D19=ROWS(D5:D16),"Validado",IF(D22>0,"Em andamento","Com pendências")) -> Em andamento

Sheet Exemplo 1 - Pizzaria
B1: Diagnóstico de atendimento à ISO 9001:2015
B2: Exemplo preenchido, para consulta. Diagnóstico completo de uma organização pequena.
B4: Organização | D4: Pizzaria (loja com salão e delivery)
B5: Data | D5: 46297
B6: Responsável | D6: Gerente da loja, com apoio do atendente líder
B7: Escopo avaliado | D7: Produção e entrega de pizzas, no salão e por delivery.
B8: Critério | D8: ISO 9001:2015, seções 4 a 10.
B9: Método | D9: Entrevistas, observação de dois turnos e leitura dos registros de julho a setembro.
B11: Requisito | C11: Título | D11: Situação | E11: Evidência encontrada | G11: O que falta | I11: Pontos | J11: Seção
B12: Seção 4 · Contexto da organização
B13: 4.1 | C13: Entendendo a organização e seu contexto | D13: Atende em parte | E13: Matriz SWOT feita em 2026. | G13: Definir quando a análise será revista. | I13: =IF(D13="Atende",1,IF(D13="Atende em parte",0.5,0)) -> 0.5 | J13: 4
B14: 4.2 | C14: Entendendo as necessidades e expectativas de partes interessadas | D14: Atende em parte | E14: Clientes e vigilância sanitária considerados na SWOT. | G14: Incluir entregadores e fornecedores, com o que cada um espera. | I14: =IF(D14="Atende",1,IF(D14="Atende em parte",0.5,0)) -> 0.5 | J14: 4
B15: 4.3 | C15: Determinando o escopo do sistema de gestão da qualidade | D15: Não atende | E15: Não há escopo escrito. | G15: Escrever o escopo: produtos, loja, canais de venda e requisitos não aplicáveis. | I15: =IF(D15="Atende",1,IF(D15="Atende em parte",0.5,0)) -> 0 | J15: 4
B16: 4.4 | C16: Sistema de gestão da qualidade e seus processos | D16: Atende em parte | E16: SIPOC e indicadores do processo de delivery. | G16: Mapear compras, produção e atendimento no salão. | I16: =IF(D16="Atende",1,IF(D16="Atende em parte",0.5,0)) -> 0.5 | J16: 4
B17: Seção 5 · Liderança
B18: 5.1.1 | C18: Liderança e comprometimento: generalidades | D18: Atende | E18: O dono conduz a reunião semanal de indicadores e decide sobre recursos. | I18: =IF(D18="Atende",1,IF(D18="Atende em parte",0.5,0)) -> 1 | J18: 5
B19: 5.1.2 | C19: Foco no cliente | D19: Atende | E19: Reclamações e entregas no prazo são lidas toda semana pelo dono. | I19: =IF(D19="Atende",1,IF(D19="Atende em parte",0.5,0)) -> 1 | J19: 5
B20: 5.2 | C20: Política | D20: Não atende | E20: Não há política da qualidade. | G20: Escrever a política e apresentá-la à equipe. | I20: =IF(D20="Atende",1,IF(D20="Atende em parte",0.5,0)) -> 0 | J20: 5
B21: 5.3 | C21: Papéis, responsabilidades e autoridades organizacionais | D21: Atende | E21: Matriz RACI do delivery e escala com o responsável de cada turno. | I21: =IF(D21="Atende",1,IF(D21="Atende em parte",0.5,0)) -> 1 | J21: 5
B22: Seção 6 · Planejamento
B23: 6.1 | C23: Ações para abordar riscos e oportunidades | D23: Atende em parte | E23: Ameaças e oportunidades listadas na SWOT. | G23: Definir ações para os riscos priorizados e avaliar o resultado. | I23: =IF(D23="Atende",1,IF(D23="Atende em parte",0.5,0)) -> 0.5 | J23: 6
B24: 6.2 | C24: Objetivos da qualidade e planejamento para alcançá-los | D24: Atende em parte | E24: Objetivo de entregas em até 40 minutos, com meta de 95% e plano. | G24: Definir objetivos e planos para reclamações e desperdício. | I24: =IF(D24="Atende",1,IF(D24="Atende em parte",0.5,0)) -> 0.5 | J24: 6
B25: 6.3 | C25: Planejamento de mudanças | D25: Não atende | E25: O sistema de pedidos foi trocado sem teste e sem treinamento. | G25: Criar uma rotina simples para planejar mudanças. | I25: =IF(D25="Atende",1,IF(D25="Atende em parte",0.5,0)) -> 0 | J25: 6
B26: Seção 7 · Apoio
B27: 7.1.1 | C27: Recursos: generalidades e pessoas (7.1.1 e 7.1.2) | D27: Atende | E27: Escala padrão, com dois entregadores extras nas noites de pico. | I27: =IF(D27="Atende",1,IF(D27="Atende em parte",0.5,0)) -> 1 | J27: 7
B28: 7.1.3 | C28: Infraestrutura | D28: Atende | E28: Forno, motos e câmara fria com manutenção programada. | I28: =IF(D28="Atende",1,IF(D28="Atende em parte",0.5,0)) -> 1 | J28: 7
B29: 7.1.4 | C29: Ambiente para a operação dos processos | D29: Atende | E29: Rotina de limpeza e de controle de temperatura da cozinha. | I29: =IF(D29="Atende",1,IF(D29="Atende em parte",0.5,0)) -> 1 | J29: 7
B30: 7.1.5 | C30: Recursos de monitoramento e medição | D30: Atende em parte | E30: Balança verificada todo mês. | G30: Verificar o termômetro da câmara fria e registrar. | I30: =IF(D30="Atende",1,IF(D30="Atende em parte",0.5,0)) -> 0.5 | J30: 7
B31: 7.1.6 | C31: Conhecimento organizacional | D31: Atende em parte | E31: Receitas e instrução da expedição escritas. | G31: Registrar a regulagem do forno, conhecida só pelo pizzaiolo líder. | I31: =IF(D31="Atende",1,IF(D31="Atende em parte",0.5,0)) -> 0.5 | J31: 7
B32: 7.2 | C32: Competência | D32: Atende em parte | E32: Lista de presença do treinamento de julho. | G32: Definir e registrar o treinamento de quem entra depois. | I32: =IF(D32="Atende",1,IF(D32="Atende em parte",0.5,0)) -> 0.5 | J32: 7
B33: 7.3 | C33: Conscientização | D33: Atende em parte | E33: A equipe conhece a meta de entrega. | G33: Apresentar a política e os objetivos, quando existirem. | I33: =IF(D33="Atende",1,IF(D33="Atende em parte",0.5,0)) -> 0.5 | J33: 7
B34: 7.4 | C34: Comunicação | D34: Atende | E34: Reunião semanal, quadro de avisos e grupo de mensagens. | I34: =IF(D34="Atende",1,IF(D34="Atende em parte",0.5,0)) -> 1 | J34: 7
B35: 7.5 | C35: Informação documentada | D35: Atende em parte | E35: Instruções com número de revisão. | G35: Controlar também os roteiros e os formulários. | I35: =IF(D35="Atende",1,IF(D35="Atende em parte",0.5,0)) -> 0.5 | J35: 7
B36: Seção 8 · Operação
B37: 8.1 | C37: Planejamento e controle operacionais | D37: Atende | E37: Instrução IT-EXP-01, escala padrão e rotina de temperatura. | I37: =IF(D37="Atende",1,IF(D37="Atende em parte",0.5,0)) -> 1 | J37: 8
B38: 8.2.1 | C38: Comunicação com o cliente | D38: Atende | E38: Cardápio, site, aplicativo, telefone e canal de reclamações. | I38: =IF(D38="Atende",1,IF(D38="Atende em parte",0.5,0)) -> 1 | J38: 8
B39: 8.2.2 | C39: Determinação de requisitos relativos a produtos e serviços | D39: Atende | E39: Cardápio com ingredientes, alergênicos e prazo de entrega por região. | I39: =IF(D39="Atende",1,IF(D39="Atende em parte",0.5,0)) -> 1 | J39: 8
B40: 8.2.3 | C40: Análise crítica de requisitos relativos a produtos e serviços | D40: Atende em parte | E40: Pedido confirmado com o cliente no site e no aplicativo. | G40: Pedidos por telefone ficam sem o complemento do endereço (RNC 2026-05, em tratamento). | I40: =IF(D40="Atende",1,IF(D40="Atende em parte",0.5,0)) -> 0.5 | J40: 8
B41: 8.2.4 | C41: Mudanças nos requisitos para produtos e serviços | D41: Atende | E41: Alteração de pedido registrada no sistema e avisada à cozinha. | I41: =IF(D41="Atende",1,IF(D41="Atende em parte",0.5,0)) -> 1 | J41: 8
B42: 8.3 | C42: Projeto e desenvolvimento de produtos e serviços | D42: Atende em parte | E42: Sabores novos são testados com a equipe antes de entrar no cardápio. | G42: Registrar a receita aprovada e o resultado do teste. | I42: =IF(D42="Atende",1,IF(D42="Atende em parte",0.5,0)) -> 0.5 | J42: 8
...

Sheet Exemplo 2 - Compras
B1: Diagnóstico de atendimento à ISO 9001:2015
B2: Exemplo preenchido, para consulta. Requisitos da norma ligados a um processo.
B4: Organização | D4: Indústria de embalagens plásticas · processo de aquisição
B5: Data | D5: 46290
B6: Responsável | D6: Analista da Qualidade, com o gerente de Suprimentos
B7: Escopo avaliado | D7: Requisitos da norma ligados ao processo de adquirir materiais e serviços.
B8: Critério | D8: ISO 9001:2015, requisito 8.4 e requisitos relacionados.
B9: Método | D9: Relatório da auditoria 2026-07, de 22/09/2026, e entrevista com a gerência.
B11: Requisito | C11: Título | D11: Situação | E11: Evidência encontrada | G11: O que falta | I11: Pontos | J11: Seção
B12: Seção 4 · Contexto da organização
B13: 4.4 | C13: Sistema de gestão da qualidade e seus processos | D13: Atende | E13: SIPOC do processo de aquisição, com indicador de prazo de atendimento. | I13: =IF(D13="Atende",1,IF(D13="Atende em parte",0.5,0)) -> 1 | J13: 4
B14: Seção 5 · Liderança
B15: 5.3 | C15: Papéis, responsabilidades e autoridades organizacionais | D15: Atende | E15: Matriz RACI e alçadas de aprovação na política de compras. | I15: =IF(D15="Atende",1,IF(D15="Atende em parte",0.5,0)) -> 1 | J15: 5
B16: Seção 6 · Planejamento
B17: 6.1 | C17: Ações para abordar riscos e oportunidades | D17: Atende em parte | E17: Risco de falta de material crítico identificado. | G17: Definir ação para os itens de fornecedor único. | I17: =IF(D17="Atende",1,IF(D17="Atende em parte",0.5,0)) -> 0.5 | J17: 6
B18: Seção 7 · Apoio
B19: 7.2 | C19: Competência | D19: Atende | E19: Compradores com treinamento registrado no PR-SUP-01 rev. 5. | I19: =IF(D19="Atende",1,IF(D19="Atende em parte",0.5,0)) -> 1 | J19: 7
B20: 7.5 | C20: Informação documentada | D20: Atende | E20: PR-SUP-01 rev. 5 controlado e disponível no sistema. | I20: =IF(D20="Atende",1,IF(D20="Atende em parte",0.5,0)) -> 1 | J20: 7
B21: Seção 8 · Operação
B22: 8.4.1 | C22: Provedores externos: generalidades | D22: Atende em parte | E22: Critérios de homologação aplicados nas 5 homologações de 2026. | G22: 5 de 12 fornecedores críticos sem avaliação de desempenho em 2026 (auditoria 2026-07, constatação nº 2). | I22: =IF(D22="Atende",1,IF(D22="Atende em parte",0.5,0)) -> 0.5 | J22: 8
B23: 8.4.2 | C23: Provedores externos: tipo e extensão do controle | D23: Atende | E23: Itens conferidos antes da liberação, nos 10 recebimentos da amostra. | I23: =IF(D23="Atende",1,IF(D23="Atende em parte",0.5,0)) -> 1 | J23: 8
B24: 8.4.3 | C24: Provedores externos: informação | D24: Atende em parte | E24: 10 pedidos com especificação, quantidade, prazo e condição de aceitação. | G24: 4 de 10 requisições chegam a Suprimentos sem especificação técnica (RNC 2026-31). | I24: =IF(D24="Atende",1,IF(D24="Atende em parte",0.5,0)) -> 0.5 | J24: 8
B25: 8.5.3 | C25: Propriedade pertencente a clientes ou provedores externos | D25: Atende | E25: Paletes e embalagens retornáveis dos fornecedores com controle de saldo. | I25: =IF(D25="Atende",1,IF(D25="Atende em parte",0.5,0)) -> 1 | J25: 8
B26: 8.7 | C26: Controle de saídas não conformes | D26: Atende | E26: Item recebido com divergência é identificado, separado e devolvido. | I26: =IF(D26="Atende",1,IF(D26="Atende em parte",0.5,0)) -> 1 | J26: 8
B27: Seção 9 · Avaliação de desempenho
B28: 9.1.3 | C28: Análise e avaliação | D28: Atende em parte | E28: Prazo de atendimento analisado todo mês. | G28: Analisar também o desempenho dos fornecedores. | I28: =IF(D28="Atende",1,IF(D28="Atende em parte",0.5,0)) -> 0.5 | J28: 9
B29: 9.2 | C29: Auditoria interna | D29: Atende | E29: Auditoria 2026-07 realizada, com relatório distribuído. | I29: =IF(D29="Atende",1,IF(D29="Atende em parte",0.5,0)) -> 1 | J29: 9
B30: Seção 10 · Melhoria
B31: 10.2 | C31: Não conformidade e ação corretiva | D31: Atende em parte | E31: RNC 2026-31 aberto, com a correção feita. | G31: Concluir a análise de causa e as ações corretivas. | I31: =IF(D31="Atende",1,IF(D31="Atende em parte",0.5,0)) -> 0.5 | J31: 10
B33: Resultado por seção
B34: Seção | C34: Título | D34: Requisitos | E34: Avaliados | F34: Atende | G34: Atende em parte | H34: Não atende | I34: Atendimento
B35: 4 | C35: 4 · Contexto da organização | D35: =SUMPRODUCT(($J$12:$J$31=4)) -> 1 | E35: =SUMPRODUCT(($J$12:$J$31=4)*($D$12:$D$31<>"")) -> 1 | F35: =SUMPRODUCT(($J$12:$J$31=4)*($D$12:$D$31="Atende")) -> 1 | G35: =SUMPRODUCT(($J$12:$J$31=4)*($D$12:$D$31="Atende em parte")) -> 0 | H35: =SUMPRODUCT(($J$12:$J$31=4)*($D$12:$D$31="Não atende")) -> 0 | I35: =IF(E35=0,"",(F35+0.5*G35)/E35) -> 1
B36: 5 | C36: 5 · Liderança | D36: =SUMPRODUCT(($J$12:$J$31=5)) -> 1 | E36: =SUMPRODUCT(($J$12:$J$31=5)*($D$12:$D$31<>"")) -> 1 | F36: =SUMPRODUCT(($J$12:$J$31=5)*($D$12:$D$31="Atende")) -> 1 | G36: =SUMPRODUCT(($J$12:$J$31=5)*($D$12:$D$31="Atende em parte")) -> 0 | H36: =SUMPRODUCT(($J$12:$J$31=5)*($D$12:$D$31="Não atende")) -> 0 | I36: =IF(E36=0,"",(F36+0.5*G36)/E36) -> 1
B37: 6 | C37: 6 · Planejamento | D37: =SUMPRODUCT(($J$12:$J$31=6)) -> 1 | E37: =SUMPRODUCT(($J$12:$J$31=6)*($D$12:$D$31<>"")) -> 1 | F37: =SUMPRODUCT(($J$12:$J$31=6)*($D$12:$D$31="Atende")) -> 0 | G37: =SUMPRODUCT(($J$12:$J$31=6)*($D$12:$D$31="Atende em parte")) -> 1 | H37: =SUMPRODUCT(($J$12:$J$31=6)*($D$12:$D$31="Não atende")) -> 0 | I37: =IF(E37=0,"",(F37+0.5*G37)/E37) -> 0.5
B38: 7 | C38: 7 · Apoio | D38: =SUMPRODUCT(($J$12:$J$31=7)) -> 2 | E38: =SUMPRODUCT(($J$12:$J$31=7)*($D$12:$D$31<>"")) -> 2 | F38: =SUMPRODUCT(($J$12:$J$31=7)*($D$12:$D$31="Atende")) -> 2 | G38: =SUMPRODUCT(($J$12:$J$31=7)*($D$12:$D$31="Atende em parte")) -> 0 | H38: =SUMPRODUCT(($J$12:$J$31=7)*($D$12:$D$31="Não atende")) -> 0 | I38: =IF(E38=0,"",(F38+0.5*G38)/E38) -> 1
B39: 8 | C39: 8 · Operação | D39: =SUMPRODUCT(($J$12:$J$31=8)) -> 5 | E39: =SUMPRODUCT(($J$12:$J$31=8)*($D$12:$D$31<>"")) -> 5 | F39: =SUMPRODUCT(($J$12:$J$31=8)*($D$12:$D$31="Atende")) -> 3 | G39: =SUMPRODUCT(($J$12:$J$31=8)*($D$12:$D$31="Atende em parte")) -> 2 | H39: =SUMPRODUCT(($J$12:$J$31=8)*($D$12:$D$31="Não atende")) -> 0 | I39: =IF(E39=0,"",(F39+0.5*G39)/E39) -> 0.8
B40: 9 | C40: 9 · Avaliação de desempenho | D40: =SUMPRODUCT(($J$12:$J$31=9)) -> 2 | E40: =SUMPRODUCT(($J$12:$J$31=9)*($D$12:$D$31<>"")) -> 2 | F40: =SUMPRODUCT(($J$12:$J$31=9)*($D$12:$D$31="Atende")) -> 1 | G40: =SUMPRODUCT(($J$12:$J$31=9)*($D$12:$D$31="Atende em parte")) -> 1 | H40: =SUMPRODUCT(($J$12:$J$31=9)*($D$12:$D$31="Não atende")) -> 0 | I40: =IF(E40=0,"",(F40+0.5*G40)/E40) -> 0.75
B41: 10 | C41: 10 · Melhoria | D41: =SUMPRODUCT(($J$12:$J$31=10)) -> 1 | E41: =SUMPRODUCT(($J$12:$J$31=10)*($D$12:$D$31<>"")) -> 1 | F41: =SUMPRODUCT(($J$12:$J$31=10)*($D$12:$D$31="Atende")) -> 0 | G41: =SUMPRODUCT(($J$12:$J$31=10)*($D$12:$D$31="Atende em parte")) -> 1 | H41: =SUMPRODUCT(($J$12:$J$31=10)*($D$12:$D$31="Não atende")) -> 0 | I41: =IF(E41=0,"",(F41+0.5*G41)/E41) -> 0.5
B42: Total | D42: =SUM(D35:D41) -> 13 | E42: =SUM(E35:E41) -> 13 | F42: =SUM(F35:F41) -> 8 | G42: =SUM(G35:G41) -> 5 | H42: =SUM(H35:H41) -> 0 | I42: =IF(E42=0,"",(F42+0.5*G42)/E42) -> 0.80769231
B44: Resumo automático
...
