Workbook

Sheet Instruções
B1: Conhecimento organizacional e pós-entrega — Como usar esta planilha
B2: Modelo para mapear o conhecimento, registrar as lições aprendidas, definir o pós-entrega e acompanhar os atendimentos.
B4: Legenda: onde preencher
B5: Amarelo-claro | C5: Células de entrada. É aqui que você digita.
B6: Cinza | C6: Células calculadas ou fixas (pontos, situações, dias, prazos, conferências). Não altere.
B7: Cinza em itálico | C7: Linha de exemplo (marcada com “Ex.”). Mostra o formato esperado e não entra nas contagens.
B8: Listas suspensas | C8: Criticidade, forma, saída prevista, origem, produto, tipo de atendimento e checklist aceitam apenas as opções da lista.
B9: Comentários | C9: Células com triângulo vermelho no canto trazem uma dica de preenchimento. Passe o mouse sobre elas.
B11: As regras de cálculo
B12: Pontos de exposição | C12: Forma: só na cabeça 2, escrito 1, escrito e treinado 0. Pessoas que sabem fazer sozinhas: uma ou nenhuma 2, duas 1, três ou mais 0. Saída prevista: mais 1.
B13: Crítico | C13: Criticidade alta com 3 pontos ou mais.
B14: Em risco | C14: Criticidade alta ou média com 2 pontos ou mais, quando não é crítico.
B15: Sob controle | C15: Os demais, inclusive todo conhecimento de criticidade baixa.
B16: Lição pendente | C16: Sem data de incorporação. Vira aviso quando passa de 60 dias da data do caso.
B17: Prazo do atendimento | C17: O prazo de resposta do produto, na aba Pós-entrega.
B18: Dias do atendimento | C18: Da abertura à resolução. Se ainda está aberto, da abertura à data da leitura.
B19: Causa | C19: Obrigatória quando o atendimento está resolvido e é reclamação, garantia, devolução.
B21: Ordem recomendada de preenchimento
B22: Passo 1 | C22: Aba Conhecimento: informe a data da leitura.
B23: Passo 2 | C23: Aba Conhecimento: liste o que cada processo precisa saber, com criticidade, forma, onde está, quem sabe e saída prevista. Para o que estiver crítico ou em risco, a ação e o prazo.
B24: Passo 3 | C24: Aba Lições: registre os casos que ensinaram alguma coisa, com o destino e o responsável.
B25: Passo 4 | C25: Aba Pós-entrega: a política de cada produto, com o mínimo da lei ou do contrato, o prazo aceito, o que se faz e o prazo de resposta.
B26: Passo 5 | C26: Aba Atendimentos: as reclamações, garantias, devoluções, assistências e orientações do período.
B27: Passo 6 | C27: Aba Painel: leia os avisos. Depois, valide na aba Checklist.
B29: Abas da planilha
B30: Conhecimento | C30: A data da leitura e até 40 conhecimentos. Calcula os pontos, a situação e a conferência.
B31: Lições | C31: Até 60 lições aprendidas. Calcula a situação, os dias pendentes e a conferência.
B32: Pós-entrega | C32: Até 20 produtos ou serviços, com a política de cada um. Calcula a conferência.
B33: Atendimentos | C33: Até 80 atendimentos. Calcula o prazo, os dias, a situação e a conferência.
B34: Painel | C34: Os números das quatro abas, o gráfico do conhecimento e o aviso.
B35: Checklist | C35: Doze verificações do conhecimento e do pós-entrega, com percentual de conclusão.
B36: Exemplo 1 - Pizzaria | C36: A loja, lida em 31/05/2027.
B37: Exemplo 2 - Indústria | C37: A fábrica, lida em 30/09/2027.
B39: Regras e premissas do modelo
B40: Pessoas que sabem | C40: Conte quem faz sozinho, com o resultado certo. Quem só leu o documento não conta.
B41: Mínimo para reclamar | C41: O prazo da lei, para o consumidor, ou o do contrato, entre empresas. Confira a legislação e os contratos vigentes.
B42: Prazos em dias | C42: Todos os prazos são em dias corridos.
B43: Exemplos | C43: Os dados das abas de exemplo são ilustrativos, criados para este material.

Sheet Conhecimento
B1: Mapa do conhecimento
B2: Um conhecimento por linha: quão exposto ele está, e o que se faz para protegê-lo.
B4: Data da leitura | F4: Usada para saber que ações venceram e há quanto tempo cada lição e cada atendimento estão abertos.
B6: # | C6: Código | D6: Conhecimento | E6: Processo | F6: Criticidade | G6: Forma | H6: Onde está | I6: Pessoas que sabem | J6: Saída prevista? | K6: Ação de transferência | L6: Prazo | M6: Pontos | N6: Situação | O6: Conferência
C7: K-01 | D7: O que é preciso saber | F7: Lista | G7: Lista | H7: Documento | I7: Fazem sozinhas | J7: Lista | K7: Se crítico ou em risco | L7: Data | M7: Calculado | N7: Calculada | O7: Calculada
B8: 1 | M8: =IF(OR(G8="",I8=""),"",IF(G8="Só na cabeça",2,IF(G8="Escrito",1,0))+IF(I8<=1,2,IF(I8=2,1,0))+IF(J8="Sim",1,0)) | N8: =IF(OR(M8="",F8=""),"",IF(AND(F8="Alta",M8>=3),"Crítico",IF(AND(OR(F8="Alta",F8="Média"),M8>=2),"Em risco","Sob controle"))) | O8: =IF(C8="","",IF(F8="","Falta a criticidade",IF(G8="","Falta a forma",IF(I8="","Falta quantas pessoas sabem",IF(OR(N8="Crítico",N8="Em risco"),IF(K8="","Falta a ação de transferência",IF(L8="","Falta o prazo da ação",IF(AND(ISNUMBER($E$4),L8<$E$4),"Prazo da ação vencido",IF(AND(G8<>"Só na cabeça",H8=""),"Falta onde está escrito","OK")))),IF(AND(G8<>"Só na cabeça",H8=""),"Falta onde está escrito","OK"))))))
B9: 2 | M9: =IF(OR(G9="",I9=""),"",IF(G9="Só na cabeça",2,IF(G9="Escrito",1,0))+IF(I9<=1,2,IF(I9=2,1,0))+IF(J9="Sim",1,0)) | N9: =IF(OR(M9="",F9=""),"",IF(AND(F9="Alta",M9>=3),"Crítico",IF(AND(OR(F9="Alta",F9="Média"),M9>=2),"Em risco","Sob controle"))) | O9: =IF(C9="","",IF(F9="","Falta a criticidade",IF(G9="","Falta a forma",IF(I9="","Falta quantas pessoas sabem",IF(OR(N9="Crítico",N9="Em risco"),IF(K9="","Falta a ação de transferência",IF(L9="","Falta o prazo da ação",IF(AND(ISNUMBER($E$4),L9<$E$4),"Prazo da ação vencido",IF(AND(G9<>"Só na cabeça",H9=""),"Falta onde está escrito","OK")))),IF(AND(G9<>"Só na cabeça",H9=""),"Falta onde está escrito","OK"))))))
B10: 3 | M10: =IF(OR(G10="",I10=""),"",IF(G10="Só na cabeça",2,IF(G10="Escrito",1,0))+IF(I10<=1,2,IF(I10=2,1,0))+IF(J10="Sim",1,0)) | N10: =IF(OR(M10="",F10=""),"",IF(AND(F10="Alta",M10>=3),"Crítico",IF(AND(OR(F10="Alta",F10="Média"),M10>=2),"Em risco","Sob controle"))) | O10: =IF(C10="","",IF(F10="","Falta a criticidade",IF(G10="","Falta a forma",IF(I10="","Falta quantas pessoas sabem",IF(OR(N10="Crítico",N10="Em risco"),IF(K10="","Falta a ação de transferência",IF(L10="","Falta o prazo da ação",IF(AND(ISNUMBER($E$4),L10<$E$4),"Prazo da ação vencido",IF(AND(G10<>"Só na cabeça",H10=""),"Falta onde está escrito","OK")))),IF(AND(G10<>"Só na cabeça",H10=""),"Falta onde está escrito","OK"))))))
B11: 4 | M11: =IF(OR(G11="",I11=""),"",IF(G11="Só na cabeça",2,IF(G11="Escrito",1,0))+IF(I11<=1,2,IF(I11=2,1,0))+IF(J11="Sim",1,0)) | N11: =IF(OR(M11="",F11=""),"",IF(AND(F11="Alta",M11>=3),"Crítico",IF(AND(OR(F11="Alta",F11="Média"),M11>=2),"Em risco","Sob controle"))) | O11: =IF(C11="","",IF(F11="","Falta a criticidade",IF(G11="","Falta a forma",IF(I11="","Falta quantas pessoas sabem",IF(OR(N11="Crítico",N11="Em risco"),IF(K11="","Falta a ação de transferência",IF(L11="","Falta o prazo da ação",IF(AND(ISNUMBER($E$4),L11<$E$4),"Prazo da ação vencido",IF(AND(G11<>"Só na cabeça",H11=""),"Falta onde está escrito","OK")))),IF(AND(G11<>"Só na cabeça",H11=""),"Falta onde está escrito","OK"))))))
B12: 5 | M12: =IF(OR(G12="",I12=""),"",IF(G12="Só na cabeça",2,IF(G12="Escrito",1,0))+IF(I12<=1,2,IF(I12=2,1,0))+IF(J12="Sim",1,0)) | N12: =IF(OR(M12="",F12=""),"",IF(AND(F12="Alta",M12>=3),"Crítico",IF(AND(OR(F12="Alta",F12="Média"),M12>=2),"Em risco","Sob controle"))) | O12: =IF(C12="","",IF(F12="","Falta a criticidade",IF(G12="","Falta a forma",IF(I12="","Falta quantas pessoas sabem",IF(OR(N12="Crítico",N12="Em risco"),IF(K12="","Falta a ação de transferência",IF(L12="","Falta o prazo da ação",IF(AND(ISNUMBER($E$4),L12<$E$4),"Prazo da ação vencido",IF(AND(G12<>"Só na cabeça",H12=""),"Falta onde está escrito","OK")))),IF(AND(G12<>"Só na cabeça",H12=""),"Falta onde está escrito","OK"))))))
B13: 6 | M13: =IF(OR(G13="",I13=""),"",IF(G13="Só na cabeça",2,IF(G13="Escrito",1,0))+IF(I13<=1,2,IF(I13=2,1,0))+IF(J13="Sim",1,0)) | N13: =IF(OR(M13="",F13=""),"",IF(AND(F13="Alta",M13>=3),"Crítico",IF(AND(OR(F13="Alta",F13="Média"),M13>=2),"Em risco","Sob controle"))) | O13: =IF(C13="","",IF(F13="","Falta a criticidade",IF(G13="","Falta a forma",IF(I13="","Falta quantas pessoas sabem",IF(OR(N13="Crítico",N13="Em risco"),IF(K13="","Falta a ação de transferência",IF(L13="","Falta o prazo da ação",IF(AND(ISNUMBER($E$4),L13<$E$4),"Prazo da ação vencido",IF(AND(G13<>"Só na cabeça",H13=""),"Falta onde está escrito","OK")))),IF(AND(G13<>"Só na cabeça",H13=""),"Falta onde está escrito","OK"))))))
B14: 7 | M14: =IF(OR(G14="",I14=""),"",IF(G14="Só na cabeça",2,IF(G14="Escrito",1,0))+IF(I14<=1,2,IF(I14=2,1,0))+IF(J14="Sim",1,0)) | N14: =IF(OR(M14="",F14=""),"",IF(AND(F14="Alta",M14>=3),"Crítico",IF(AND(OR(F14="Alta",F14="Média"),M14>=2),"Em risco","Sob controle"))) | O14: =IF(C14="","",IF(F14="","Falta a criticidade",IF(G14="","Falta a forma",IF(I14="","Falta quantas pessoas sabem",IF(OR(N14="Crítico",N14="Em risco"),IF(K14="","Falta a ação de transferência",IF(L14="","Falta o prazo da ação",IF(AND(ISNUMBER($E$4),L14<$E$4),"Prazo da ação vencido",IF(AND(G14<>"Só na cabeça",H14=""),"Falta onde está escrito","OK")))),IF(AND(G14<>"Só na cabeça",H14=""),"Falta onde está escrito","OK"))))))
B15: 8 | M15: =IF(OR(G15="",I15=""),"",IF(G15="Só na cabeça",2,IF(G15="Escrito",1,0))+IF(I15<=1,2,IF(I15=2,1,0))+IF(J15="Sim",1,0)) | N15: =IF(OR(M15="",F15=""),"",IF(AND(F15="Alta",M15>=3),"Crítico",IF(AND(OR(F15="Alta",F15="Média"),M15>=2),"Em risco","Sob controle"))) | O15: =IF(C15="","",IF(F15="","Falta a criticidade",IF(G15="","Falta a forma",IF(I15="","Falta quantas pessoas sabem",IF(OR(N15="Crítico",N15="Em risco"),IF(K15="","Falta a ação de transferência",IF(L15="","Falta o prazo da ação",IF(AND(ISNUMBER($E$4),L15<$E$4),"Prazo da ação vencido",IF(AND(G15<>"Só na cabeça",H15=""),"Falta onde está escrito","OK")))),IF(AND(G15<>"Só na cabeça",H15=""),"Falta onde está escrito","OK"))))))
B16: 9 | M16: =IF(OR(G16="",I16=""),"",IF(G16="Só na cabeça",2,IF(G16="Escrito",1,0))+IF(I16<=1,2,IF(I16=2,1,0))+IF(J16="Sim",1,0)) | N16: =IF(OR(M16="",F16=""),"",IF(AND(F16="Alta",M16>=3),"Crítico",IF(AND(OR(F16="Alta",F16="Média"),M16>=2),"Em risco","Sob controle"))) | O16: =IF(C16="","",IF(F16="","Falta a criticidade",IF(G16="","Falta a forma",IF(I16="","Falta quantas pessoas sabem",IF(OR(N16="Crítico",N16="Em risco"),IF(K16="","Falta a ação de transferência",IF(L16="","Falta o prazo da ação",IF(AND(ISNUMBER($E$4),L16<$E$4),"Prazo da ação vencido",IF(AND(G16<>"Só na cabeça",H16=""),"Falta onde está escrito","OK")))),IF(AND(G16<>"Só na cabeça",H16=""),"Falta onde está escrito","OK"))))))
B17: 10 | M17: =IF(OR(G17="",I17=""),"",IF(G17="Só na cabeça",2,IF(G17="Escrito",1,0))+IF(I17<=1,2,IF(I17=2,1,0))+IF(J17="Sim",1,0)) | N17: =IF(OR(M17="",F17=""),"",IF(AND(F17="Alta",M17>=3),"Crítico",IF(AND(OR(F17="Alta",F17="Média"),M17>=2),"Em risco","Sob controle"))) | O17: =IF(C17="","",IF(F17="","Falta a criticidade",IF(G17="","Falta a forma",IF(I17="","Falta quantas pessoas sabem",IF(OR(N17="Crítico",N17="Em risco"),IF(K17="","Falta a ação de transferência",IF(L17="","Falta o prazo da ação",IF(AND(ISNUMBER($E$4),L17<$E$4),"Prazo da ação vencido",IF(AND(G17<>"Só na cabeça",H17=""),"Falta onde está escrito","OK")))),IF(AND(G17<>"Só na cabeça",H17=""),"Falta onde está escrito","OK"))))))
B18: 11 | M18: =IF(OR(G18="",I18=""),"",IF(G18="Só na cabeça",2,IF(G18="Escrito",1,0))+IF(I18<=1,2,IF(I18=2,1,0))+IF(J18="Sim",1,0)) | N18: =IF(OR(M18="",F18=""),"",IF(AND(F18="Alta",M18>=3),"Crítico",IF(AND(OR(F18="Alta",F18="Média"),M18>=2),"Em risco","Sob controle"))) | O18: =IF(C18="","",IF(F18="","Falta a criticidade",IF(G18="","Falta a forma",IF(I18="","Falta quantas pessoas sabem",IF(OR(N18="Crítico",N18="Em risco"),IF(K18="","Falta a ação de transferência",IF(L18="","Falta o prazo da ação",IF(AND(ISNUMBER($E$4),L18<$E$4),"Prazo da ação vencido",IF(AND(G18<>"Só na cabeça",H18=""),"Falta onde está escrito","OK")))),IF(AND(G18<>"Só na cabeça",H18=""),"Falta onde está escrito","OK"))))))
B19: 12 | M19: =IF(OR(G19="",I19=""),"",IF(G19="Só na cabeça",2,IF(G19="Escrito",1,0))+IF(I19<=1,2,IF(I19=2,1,0))+IF(J19="Sim",1,0)) | N19: =IF(OR(M19="",F19=""),"",IF(AND(F19="Alta",M19>=3),"Crítico",IF(AND(OR(F19="Alta",F19="Média"),M19>=2),"Em risco","Sob controle"))) | O19: =IF(C19="","",IF(F19="","Falta a criticidade",IF(G19="","Falta a forma",IF(I19="","Falta quantas pessoas sabem",IF(OR(N19="Crítico",N19="Em risco"),IF(K19="","Falta a ação de transferência",IF(L19="","Falta o prazo da ação",IF(AND(ISNUMBER($E$4),L19<$E$4),"Prazo da ação vencido",IF(AND(G19<>"Só na cabeça",H19=""),"Falta onde está escrito","OK")))),IF(AND(G19<>"Só na cabeça",H19=""),"Falta onde está escrito","OK"))))))
... B47: 40 | M47: =IF(OR(G47="",I47=""),"",IF(G47="Só na cabeça",2,IF(G47="Escrito",1,0))+IF(I47<=1,2,IF(I47=2,1,0))+IF(J47="Sim",1,0)) | N47: =IF(OR(M47="",F47=""),"",IF(AND(F47="Alta",M47>=3),"Crítico",IF(AND(OR(F47="Alta",F47="Média"),M47>=2),"Em risco","Sob controle"))) | O47: =IF(C47="","",IF(F47="","Falta a criticidade",IF(G47="","Falta a forma",IF(I47="","Falta quantas pessoas sabem",IF(OR(N47="Crítico",N47="Em risco"),IF(K47="","Falta a ação de transferência",IF(L47="","Falta o prazo da ação",IF(AND(ISNUMBER($E$4),L47<$E$4),"Prazo da ação vencido",IF(AND(G47<>"Só na cabeça",H47=""),"Falta onde está escrito","OK")))),IF(AND(G47<>"Só na cabeça",H47=""),"Falta onde está escrito","OK"))))))
B49: Resumo automático
B50: Conhecimentos mapeados | E50: =COUNTA(C8:C47) -> 0
B51: Por situação | E51: =COUNTIF(N8:N47,"Crítico")&" crítico"&", "&COUNTIF(N8:N47,"Em risco")&" em risco"&", "&COUNTIF(N8:N47,"Sob controle")&" sob controle" -> 0 crítico, 0 em risco, 0 sob controle
B52: Aviso | E52: =IF(E50=0,"Liste o conhecimento de cada processo",IF(E4="","Informe a data da leitura",IF(COUNTIF(O8:O47,"Falta a ação de transferência")>0,"Há conhecimento exposto sem ação de transferência",IF(COUNTIF(O8:O47,"Prazo da ação vencido")>0,"Há ação de transferência vencida",IF(SUMPRODUCT((O8:O47<>"")*(O8:O47<>"OK"))>0,"Há linha a completar: veja a coluna Conferência","OK"))))) -> Liste o conhecimento de cada processo

Sheet Lições
B1: Lições aprendidas
B2: Uma lição por linha: o caso, o que se aprendeu, para onde vai e quem leva.
B4: # | C4: Nº | D4: Data | E4: Origem | F4: O que aconteceu | G4: O que aprendemos | H4: Onde incorporar | I4: Responsável | J4: Conhecimento | K4: Incorporada em | L4: Situação | M4: Dias pendente | N4: Conferência
C5: L-01 | D5: Data do caso | E5: Lista | G5: A regra nova | H5: Documento ou treinamento | J5: Código, se houver | K5: Data | L5: Calculada | M5: Calculado | N5: Calculada
B6: Ex. | C6: L-01 | D6: 46451 | E6: Reclamação | F6: Pizza chegou fria | G6: Bolsa térmica fechada até a entrega | H6: Instrução IT-EXP-01 | I6: Gerente | J6: K-04 | K6: 46461 | L6: Incorporada | N6: OK
B7: 1 | L7: =IF(C7="","",IF(K7="","Pendente","Incorporada")) | M7: =IF(OR(C7="",K7<>"",D7=""),"",IF(ISNUMBER(Conhecimento!$E$4),Conhecimento!$E$4-D7,"")) | N7: =IF(C7="","",IF(D7="","Falta a data",IF(F7="","Falta o que aconteceu",IF(G7="","Falta o que aprendemos",IF(H7="","Falta onde incorporar",IF(AND(J7<>"",ISNA(MATCH(J7,Conhecimento!$C$8:$C$47,0))),"Conhecimento não cadastrado",IF(AND(L7="Pendente",N(M7)>60),"Pendente há mais de 60 dias","OK")))))))
B8: 2 | L8: =IF(C8="","",IF(K8="","Pendente","Incorporada")) | M8: =IF(OR(C8="",K8<>"",D8=""),"",IF(ISNUMBER(Conhecimento!$E$4),Conhecimento!$E$4-D8,"")) | N8: =IF(C8="","",IF(D8="","Falta a data",IF(F8="","Falta o que aconteceu",IF(G8="","Falta o que aprendemos",IF(H8="","Falta onde incorporar",IF(AND(J8<>"",ISNA(MATCH(J8,Conhecimento!$C$8:$C$47,0))),"Conhecimento não cadastrado",IF(AND(L8="Pendente",N(M8)>60),"Pendente há mais de 60 dias","OK")))))))
B9: 3 | L9: =IF(C9="","",IF(K9="","Pendente","Incorporada")) | M9: =IF(OR(C9="",K9<>"",D9=""),"",IF(ISNUMBER(Conhecimento!$E$4),Conhecimento!$E$4-D9,"")) | N9: =IF(C9="","",IF(D9="","Falta a data",IF(F9="","Falta o que aconteceu",IF(G9="","Falta o que aprendemos",IF(H9="","Falta onde incorporar",IF(AND(J9<>"",ISNA(MATCH(J9,Conhecimento!$C$8:$C$47,0))),"Conhecimento não cadastrado",IF(AND(L9="Pendente",N(M9)>60),"Pendente há mais de 60 dias","OK")))))))
B10: 4 | L10: =IF(C10="","",IF(K10="","Pendente","Incorporada")) | M10: =IF(OR(C10="",K10<>"",D10=""),"",IF(ISNUMBER(Conhecimento!$E$4),Conhecimento!$E$4-D10,"")) | N10: =IF(C10="","",IF(D10="","Falta a data",IF(F10="","Falta o que aconteceu",IF(G10="","Falta o que aprendemos",IF(H10="","Falta onde incorporar",IF(AND(J10<>"",ISNA(MATCH(J10,Conhecimento!$C$8:$C$47,0))),"Conhecimento não cadastrado",IF(AND(L10="Pendente",N(M10)>60),"Pendente há mais de 60 dias","OK")))))))
B11: 5 | L11: =IF(C11="","",IF(K11="","Pendente","Incorporada")) | M11: =IF(OR(C11="",K11<>"",D11=""),"",IF(ISNUMBER(Conhecimento!$E$4),Conhecimento!$E$4-D11,"")) | N11: =IF(C11="","",IF(D11="","Falta a data",IF(F11="","Falta o que aconteceu",IF(G11="","Falta o que aprendemos",IF(H11="","Falta onde incorporar",IF(AND(J11<>"",ISNA(MATCH(J11,Conhecimento!$C$8:$C$47,0))),"Conhecimento não cadastrado",IF(AND(L11="Pendente",N(M11)>60),"Pendente há mais de 60 dias","OK")))))))
B12: 6 | L12: =IF(C12="","",IF(K12="","Pendente","Incorporada")) | M12: =IF(OR(C12="",K12<>"",D12=""),"",IF(ISNUMBER(Conhecimento!$E$4),Conhecimento!$E$4-D12,"")) | N12: =IF(C12="","",IF(D12="","Falta a data",IF(F12="","Falta o que aconteceu",IF(G12="","Falta o que aprendemos",IF(H12="","Falta onde incorporar",IF(AND(J12<>"",ISNA(MATCH(J12,Conhecimento!$C$8:$C$47,0))),"Conhecimento não cadastrado",IF(AND(L12="Pendente",N(M12)>60),"Pendente há mais de 60 dias","OK")))))))
B13: 7 | L13: =IF(C13="","",IF(K13="","Pendente","Incorporada")) | M13: =IF(OR(C13="",K13<>"",D13=""),"",IF(ISNUMBER(Conhecimento!$E$4),Conhecimento!$E$4-D13,"")) | N13: =IF(C13="","",IF(D13="","Falta a data",IF(F13="","Falta o que aconteceu",IF(G13="","Falta o que aprendemos",IF(H13="","Falta onde incorporar",IF(AND(J13<>"",ISNA(MATCH(J13,Conhecimento!$C$8:$C$47,0))),"Conhecimento não cadastrado",IF(AND(L13="Pendente",N(M13)>60),"Pendente há mais de 60 dias","OK")))))))
B14: 8 | L14: =IF(C14="","",IF(K14="","Pendente","Incorporada")) | M14: =IF(OR(C14="",K14<>"",D14=""),"",IF(ISNUMBER(Conhecimento!$E$4),Conhecimento!$E$4-D14,"")) | N14: =IF(C14="","",IF(D14="","Falta a data",IF(F14="","Falta o que aconteceu",IF(G14="","Falta o que aprendemos",IF(H14="","Falta onde incorporar",IF(AND(J14<>"",ISNA(MATCH(J14,Conhecimento!$C$8:$C$47,0))),"Conhecimento não cadastrado",IF(AND(L14="Pendente",N(M14)>60),"Pendente há mais de 60 dias","OK")))))))
B15: 9 | L15: =IF(C15="","",IF(K15="","Pendente","Incorporada")) | M15: =IF(OR(C15="",K15<>"",D15=""),"",IF(ISNUMBER(Conhecimento!$E$4),Conhecimento!$E$4-D15,"")) | N15: =IF(C15="","",IF(D15="","Falta a data",IF(F15="","Falta o que aconteceu",IF(G15="","Falta o que aprendemos",IF(H15="","Falta onde incorporar",IF(AND(J15<>"",ISNA(MATCH(J15,Conhecimento!$C$8:$C$47,0))),"Conhecimento não cadastrado",IF(AND(L15="Pendente",N(M15)>60),"Pendente há mais de 60 dias","OK")))))))
B16: 10 | L16: =IF(C16="","",IF(K16="","Pendente","Incorporada")) | M16: =IF(OR(C16="",K16<>"",D16=""),"",IF(ISNUMBER(Conhecimento!$E$4),Conhecimento!$E$4-D16,"")) | N16: =IF(C16="","",IF(D16="","Falta a data",IF(F16="","Falta o que aconteceu",IF(G16="","Falta o que aprendemos",IF(H16="","Falta onde incorporar",IF(AND(J16<>"",ISNA(MATCH(J16,Conhecimento!$C$8:$C$47,0))),"Conhecimento não cadastrado",IF(AND(L16="Pendente",N(M16)>60),"Pendente há mais de 60 dias","OK")))))))
B17: 11 | L17: =IF(C17="","",IF(K17="","Pendente","Incorporada")) | M17: =IF(OR(C17="",K17<>"",D17=""),"",IF(ISNUMBER(Conhecimento!$E$4),Conhecimento!$E$4-D17,"")) | N17: =IF(C17="","",IF(D17="","Falta a data",IF(F17="","Falta o que aconteceu",IF(G17="","Falta o que aprendemos",IF(H17="","Falta onde incorporar",IF(AND(J17<>"",ISNA(MATCH(J17,Conhecimento!$C$8:$C$47,0))),"Conhecimento não cadastrado",IF(AND(L17="Pendente",N(M17)>60),"Pendente há mais de 60 dias","OK")))))))
B18: 12 | L18: =IF(C18="","",IF(K18="","Pendente","Incorporada")) | M18: =IF(OR(C18="",K18<>"",D18=""),"",IF(ISNUMBER(Conhecimento!$E$4),Conhecimento!$E$4-D18,"")) | N18: =IF(C18="","",IF(D18="","Falta a data",IF(F18="","Falta o que aconteceu",IF(G18="","Falta o que aprendemos",IF(H18="","Falta onde incorporar",IF(AND(J18<>"",ISNA(MATCH(J18,Conhecimento!$C$8:$C$47,0))),"Conhecimento não cadastrado",IF(AND(L18="Pendente",N(M18)>60),"Pendente há mais de 60 dias","OK")))))))
... B66: 60 | L66: =IF(C66="","",IF(K66="","Pendente","Incorporada")) | M66: =IF(OR(C66="",K66<>"",D66=""),"",IF(ISNUMBER(Conhecimento!$E$4),Conhecimento!$E$4-D66,"")) | N66: =IF(C66="","",IF(D66="","Falta a data",IF(F66="","Falta o que aconteceu",IF(G66="","Falta o que aprendemos",IF(H66="","Falta onde incorporar",IF(AND(J66<>"",ISNA(MATCH(J66,Conhecimento!$C$8:$C$47,0))),"Conhecimento não cadastrado",IF(AND(L66="Pendente",N(M66)>60),"Pendente há mais de 60 dias","OK")))))))
B68: Resumo automático
B69: Lições registradas | E69: =COUNTA(C7:C66) -> 0
B70: Por situação | E70: =COUNTIF(L7:L66,"Incorporada")&" incorporada"&", "&COUNTIF(L7:L66,"Pendente")&" pendente" -> 0 incorporada, 0 pendente
B71: Aviso | E71: =IF(E69=0,"Registre as lições aprendidas",IF(COUNTIF(N7:N66,"Pendente há mais de 60 dias")>0,"Há lição pendente há mais de 60 dias",IF(SUMPRODUCT((N7:N66<>"")*(N7:N66<>"OK"))>0,"Há lição a completar: veja a coluna Conferência","OK"))) -> Registre as lições aprendidas

Sheet Pós-entrega
B1: Política de pós-entrega
B2: Um produto ou serviço por linha: o que se faz depois da entrega, e com que prazos.
B4: # | C4: Produto ou serviço | D4: Vida útil | E4: Mínimo para reclamar (dias) | F4: Prazo aceito (dias) | G4: O que se faz depois da entrega | H4: Prazo de resposta (dias) | I4: O que se quer evitar no uso | J4: Conferência
D5: Validade, durabilidade | E5: Lei ou contrato | F5: O que a casa aceita | G5: Troca, laudo, visita, orientação | H5: Dias corridos | I5: Consequência indesejada | J5: Calculada
B6: Ex. | C6: Massa congelada para levar | D6: 60 dias no freezer | E6: 30 | F6: 30 | G6: Troca ou devolução do valor | H6: 2 | I6: Descongelar e congelar de novo | J6: OK
B7: 1 | J7: =IF(C7="","",IF(E7="","Falta o prazo mínimo para reclamar",IF(F7="","Falta o prazo aceito",IF(F7<E7,"Prazo aceito menor que o mínimo",IF(G7="","Falta o que se faz",IF(H7="","Falta o prazo de resposta","OK"))))))
B8: 2 | J8: =IF(C8="","",IF(E8="","Falta o prazo mínimo para reclamar",IF(F8="","Falta o prazo aceito",IF(F8<E8,"Prazo aceito menor que o mínimo",IF(G8="","Falta o que se faz",IF(H8="","Falta o prazo de resposta","OK"))))))
B9: 3 | J9: =IF(C9="","",IF(E9="","Falta o prazo mínimo para reclamar",IF(F9="","Falta o prazo aceito",IF(F9<E9,"Prazo aceito menor que o mínimo",IF(G9="","Falta o que se faz",IF(H9="","Falta o prazo de resposta","OK"))))))
B10: 4 | J10: =IF(C10="","",IF(E10="","Falta o prazo mínimo para reclamar",IF(F10="","Falta o prazo aceito",IF(F10<E10,"Prazo aceito menor que o mínimo",IF(G10="","Falta o que se faz",IF(H10="","Falta o prazo de resposta","OK"))))))
B11: 5 | J11: =IF(C11="","",IF(E11="","Falta o prazo mínimo para reclamar",IF(F11="","Falta o prazo aceito",IF(F11<E11,"Prazo aceito menor que o mínimo",IF(G11="","Falta o que se faz",IF(H11="","Falta o prazo de resposta","OK"))))))
B12: 6 | J12: =IF(C12="","",IF(E12="","Falta o prazo mínimo para reclamar",IF(F12="","Falta o prazo aceito",IF(F12<E12,"Prazo aceito menor que o mínimo",IF(G12="","Falta o que se faz",IF(H12="","Falta o prazo de resposta","OK"))))))
B13: 7 | J13: =IF(C13="","",IF(E13="","Falta o prazo mínimo para reclamar",IF(F13="","Falta o prazo aceito",IF(F13<E13,"Prazo aceito menor que o mínimo",IF(G13="","Falta o que se faz",IF(H13="","Falta o prazo de resposta","OK"))))))
B14: 8 | J14: =IF(C14="","",IF(E14="","Falta o prazo mínimo para reclamar",IF(F14="","Falta o prazo aceito",IF(F14<E14,"Prazo aceito menor que o mínimo",IF(G14="","Falta o que se faz",IF(H14="","Falta o prazo de resposta","OK"))))))
B15: 9 | J15: =IF(C15="","",IF(E15="","Falta o prazo mínimo para reclamar",IF(F15="","Falta o prazo aceito",IF(F15<E15,"Prazo aceito menor que o mínimo",IF(G15="","Falta o que se faz",IF(H15="","Falta o prazo de resposta","OK"))))))
B16: 10 | J16: =IF(C16="","",IF(E16="","Falta o prazo mínimo para reclamar",IF(F16="","Falta o prazo aceito",IF(F16<E16,"Prazo aceito menor que o mínimo",IF(G16="","Falta o que se faz",IF(H16="","Falta o prazo de resposta","OK"))))))
B17: 11 | J17: =IF(C17="","",IF(E17="","Falta o prazo mínimo para reclamar",IF(F17="","Falta o prazo aceito",IF(F17<E17,"Prazo aceito menor que o mínimo",IF(G17="","Falta o que se faz",IF(H17="","Falta o prazo de resposta","OK"))))))
B18: 12 | J18: =IF(C18="","",IF(E18="","Falta o prazo mínimo para reclamar",IF(F18="","Falta o prazo aceito",IF(F18<E18,"Prazo aceito menor que o mínimo",IF(G18="","Falta o que se faz",IF(H18="","Falta o prazo de resposta","OK"))))))
... B26: 20 | J26: =IF(C26="","",IF(E26="","Falta o prazo mínimo para reclamar",IF(F26="","Falta o prazo aceito",IF(F26<E26,"Prazo aceito menor que o mínimo",IF(G26="","Falta o que se faz",IF(H26="","Falta o prazo de resposta","OK"))))))
B28: Resumo automático
B29: Produtos com política | E29: =COUNTA(C7:C26) -> 0
B30: Aviso | E30: =IF(E29=0,"Escreva a política de cada produto",IF(COUNTIF(J7:J26,"Prazo aceito menor que o mínimo")>0,"Há prazo aceito menor que o mínimo da lei ou do contrato",IF(SUMPRODUCT((J7:J26<>"")*(J7:J26<>"OK"))>0,"Há política a completar: veja a coluna Conferência","OK"))) -> Escreva a política de cada produto

Sheet Atendimentos
B1: Atendimentos depois da entrega
B2: Um atendimento por linha. O prazo vem da política do produto, na aba Pós-entrega.
B4: # | C4: Nº | D4: Abertura | E4: Cliente | F4: Produto | G4: Tipo | H4: Relato | I4: Resolução | J4: Custo | K4: Causa | L4: Lição | M4: Prazo | N4: Dias | O4: Situação | P4: Conferência
C5: A-01 | D5: Data | F5: Lista | G5: Lista | H5: O que o cliente disse | I5: Data, se resolvido | J5: R$ | K5: Por que aconteceu | L5: Nº | M5: Calculado | N5: Calculado | O5: Calculada | P5: Calculada
B6: Ex. | C6: A-01 | D6: 46510 | E6: Cliente do bairro A | F6: Pizza entregue | G6: Reclamação | H6: Pizza fria | I6: 46510 | J6: 45 | K6: Entregador com 4 pedidos | L6: L-01 | M6: 1 | N6: 0 | O6: No prazo | P6: OK
B7: 1 | M7: =IF(F7="","",IFERROR(IF(INDEX('Pós-entrega'!$H$7:$H$26,MATCH(F7,'Pós-entrega'!$C$7:$C$26,0))="","",INDEX('Pós-entrega'!$H$7:$H$26,MATCH(F7,'Pós-entrega'!$C$7:$C$26,0))),"")) | N7: =IF(D7="","",IF(I7<>"",I7-D7,IF(ISNUMBER(Conhecimento!$E$4),Conhecimento!$E$4-D7,""))) | O7: =IF(OR(M7="",N7=""),"",IF(I7<>"",IF(N7<=M7,"No prazo","Fora do prazo"),IF(N7<=M7,"Aberto no prazo","Aberto e atrasado"))) | P7: =IF(AND(C7="",COUNTA(D7:L7)=0),"",IF(ISNA(MATCH(F7,'Pós-entrega'!$C$7:$C$26,0)),"Produto sem política",IF(D7="","Falta a data de abertura",IF(G7="","Falta o tipo",IF(AND(I7<>"",OR(G7="Reclamação",G7="Garantia",G7="Devolução"),K7=""),"Falta a causa",IF(AND(L7<>"",ISNA(MATCH(L7,Lições!$C$7:$C$66,0))),"Lição não encontrada","OK"))))))
B8: 2 | M8: =IF(F8="","",IFERROR(IF(INDEX('Pós-entrega'!$H$7:$H$26,MATCH(F8,'Pós-entrega'!$C$7:$C$26,0))="","",INDEX('Pós-entrega'!$H$7:$H$26,MATCH(F8,'Pós-entrega'!$C$7:$C$26,0))),"")) | N8: =IF(D8="","",IF(I8<>"",I8-D8,IF(ISNUMBER(Conhecimento!$E$4),Conhecimento!$E$4-D8,""))) | O8: =IF(OR(M8="",N8=""),"",IF(I8<>"",IF(N8<=M8,"No prazo","Fora do prazo"),IF(N8<=M8,"Aberto no prazo","Aberto e atrasado"))) | P8: =IF(AND(C8="",COUNTA(D8:L8)=0),"",IF(ISNA(MATCH(F8,'Pós-entrega'!$C$7:$C$26,0)),"Produto sem política",IF(D8="","Falta a data de abertura",IF(G8="","Falta o tipo",IF(AND(I8<>"",OR(G8="Reclamação",G8="Garantia",G8="Devolução"),K8=""),"Falta a causa",IF(AND(L8<>"",ISNA(MATCH(L8,Lições!$C$7:$C$66,0))),"Lição não encontrada","OK"))))))
B9: 3 | M9: =IF(F9="","",IFERROR(IF(INDEX('Pós-entrega'!$H$7:$H$26,MATCH(F9,'Pós-entrega'!$C$7:$C$26,0))="","",INDEX('Pós-entrega'!$H$7:$H$26,MATCH(F9,'Pós-entrega'!$C$7:$C$26,0))),"")) | N9: =IF(D9="","",IF(I9<>"",I9-D9,IF(ISNUMBER(Conhecimento!$E$4),Conhecimento!$E$4-D9,""))) | O9: =IF(OR(M9="",N9=""),"",IF(I9<>"",IF(N9<=M9,"No prazo","Fora do prazo"),IF(N9<=M9,"Aberto no prazo","Aberto e atrasado"))) | P9: =IF(AND(C9="",COUNTA(D9:L9)=0),"",IF(ISNA(MATCH(F9,'Pós-entrega'!$C$7:$C$26,0)),"Produto sem política",IF(D9="","Falta a data de abertura",IF(G9="","Falta o tipo",IF(AND(I9<>"",OR(G9="Reclamação",G9="Garantia",G9="Devolução"),K9=""),"Falta a causa",IF(AND(L9<>"",ISNA(MATCH(L9,Lições!$C$7:$C$66,0))),"Lição não encontrada","OK"))))))
B10: 4 | M10: =IF(F10="","",IFERROR(IF(INDEX('Pós-entrega'!$H$7:$H$26,MATCH(F10,'Pós-entrega'!$C$7:$C$26,0))="","",INDEX('Pós-entrega'!$H$7:$H$26,MATCH(F10,'Pós-entrega'!$C$7:$C$26,0))),"")) | N10: =IF(D10="","",IF(I10<>"",I10-D10,IF(ISNUMBER(Conhecimento!$E$4),Conhecimento!$E$4-D10,""))) | O10: =IF(OR(M10="",N10=""),"",IF(I10<>"",IF(N10<=M10,"No prazo","Fora do prazo"),IF(N10<=M10,"Aberto no prazo","Aberto e atrasado"))) | P10: =IF(AND(C10="",COUNTA(D10:L10)=0),"",IF(ISNA(MATCH(F10,'Pós-entrega'!$C$7:$C$26,0)),"Produto sem política",IF(D10="","Falta a data de abertura",IF(G10="","Falta o tipo",IF(AND(I10<>"",OR(G10="Reclamação",G10="Garantia",G10="Devolução"),K10=""),"Falta a causa",IF(AND(L10<>"",ISNA(MATCH(L10,Lições!$C$7:$C$66,0))),"Lição não encontrada","OK"))))))
B11: 5 | M11: =IF(F11="","",IFERROR(IF(INDEX('Pós-entrega'!$H$7:$H$26,MATCH(F11,'Pós-entrega'!$C$7:$C$26,0))="","",INDEX('Pós-entrega'!$H$7:$H$26,MATCH(F11,'Pós-entrega'!$C$7:$C$26,0))),"")) | N11: =IF(D11="","",IF(I11<>"",I11-D11,IF(ISNUMBER(Conhecimento!$E$4),Conhecimento!$E$4-D11,""))) | O11: =IF(OR(M11="",N11=""),"",IF(I11<>"",IF(N11<=M11,"No prazo","Fora do prazo"),IF(N11<=M11,"Aberto no prazo","Aberto e atrasado"))) | P11: =IF(AND(C11="",COUNTA(D11:L11)=0),"",IF(ISNA(MATCH(F11,'Pós-entrega'!$C$7:$C$26,0)),"Produto sem política",IF(D11="","Falta a data de abertura",IF(G11="","Falta o tipo",IF(AND(I11<>"",OR(G11="Reclamação",G11="Garantia",G11="Devolução"),K11=""),"Falta a causa",IF(AND(L11<>"",ISNA(MATCH(L11,Lições!$C$7:$C$66,0))),"Lição não encontrada","OK"))))))
B12: 6 | M12: =IF(F12="","",IFERROR(IF(INDEX('Pós-entrega'!$H$7:$H$26,MATCH(F12,'Pós-entrega'!$C$7:$C$26,0))="","",INDEX('Pós-entrega'!$H$7:$H$26,MATCH(F12,'Pós-entrega'!$C$7:$C$26,0))),"")) | N12: =IF(D12="","",IF(I12<>"",I12-D12,IF(ISNUMBER(Conhecimento!$E$4),Conhecimento!$E$4-D12,""))) | O12: =IF(OR(M12="",N12=""),"",IF(I12<>"",IF(N12<=M12,"No prazo","Fora do prazo"),IF(N12<=M12,"Aberto no prazo","Aberto e atrasado"))) | P12: =IF(AND(C12="",COUNTA(D12:L12)=0),"",IF(ISNA(MATCH(F12,'Pós-entrega'!$C$7:$C$26,0)),"Produto sem política",IF(D12="","Falta a data de abertura",IF(G12="","Falta o tipo",IF(AND(I12<>"",OR(G12="Reclamação",G12="Garantia",G12="Devolução"),K12=""),"Falta a causa",IF(AND(L12<>"",ISNA(MATCH(L12,Lições!$C$7:$C$66,0))),"Lição não encontrada","OK"))))))
B13: 7 | M13: =IF(F13="","",IFERROR(IF(INDEX('Pós-entrega'!$H$7:$H$26,MATCH(F13,'Pós-entrega'!$C$7:$C$26,0))="","",INDEX('Pós-entrega'!$H$7:$H$26,MATCH(F13,'Pós-entrega'!$C$7:$C$26,0))),"")) | N13: =IF(D13="","",IF(I13<>"",I13-D13,IF(ISNUMBER(Conhecimento!$E$4),Conhecimento!$E$4-D13,""))) | O13: =IF(OR(M13="",N13=""),"",IF(I13<>"",IF(N13<=M13,"No prazo","Fora do prazo"),IF(N13<=M13,"Aberto no prazo","Aberto e atrasado"))) | P13: =IF(AND(C13="",COUNTA(D13:L13)=0),"",IF(ISNA(MATCH(F13,'Pós-entrega'!$C$7:$C$26,0)),"Produto sem política",IF(D13="","Falta a data de abertura",IF(G13="","Falta o tipo",IF(AND(I13<>"",OR(G13="Reclamação",G13="Garantia",G13="Devolução"),K13=""),"Falta a causa",IF(AND(L13<>"",ISNA(MATCH(L13,Lições!$C$7:$C$66,0))),"Lição não encontrada","OK"))))))
B14: 8 | M14: =IF(F14="","",IFERROR(IF(INDEX('Pós-entrega'!$H$7:$H$26,MATCH(F14,'Pós-entrega'!$C$7:$C$26,0))="","",INDEX('Pós-entrega'!$H$7:$H$26,MATCH(F14,'Pós-entrega'!$C$7:$C$26,0))),"")) | N14: =IF(D14="","",IF(I14<>"",I14-D14,IF(ISNUMBER(Conhecimento!$E$4),Conhecimento!$E$4-D14,""))) | O14: =IF(OR(M14="",N14=""),"",IF(I14<>"",IF(N14<=M14,"No prazo","Fora do prazo"),IF(N14<=M14,"Aberto no prazo","Aberto e atrasado"))) | P14: =IF(AND(C14="",COUNTA(D14:L14)=0),"",IF(ISNA(MATCH(F14,'Pós-entrega'!$C$7:$C$26,0)),"Produto sem política",IF(D14="","Falta a data de abertura",IF(G14="","Falta o tipo",IF(AND(I14<>"",OR(G14="Reclamação",G14="Garantia",G14="Devolução"),K14=""),"Falta a causa",IF(AND(L14<>"",ISNA(MATCH(L14,Lições!$C$7:$C$66,0))),"Lição não encontrada","OK"))))))
B15: 9 | M15: =IF(F15="","",IFERROR(IF(INDEX('Pós-entrega'!$H$7:$H$26,MATCH(F15,'Pós-entrega'!$C$7:$C$26,0))="","",INDEX('Pós-entrega'!$H$7:$H$26,MATCH(F15,'Pós-entrega'!$C$7:$C$26,0))),"")) | N15: =IF(D15="","",IF(I15<>"",I15-D15,IF(ISNUMBER(Conhecimento!$E$4),Conhecimento!$E$4-D15,""))) | O15: =IF(OR(M15="",N15=""),"",IF(I15<>"",IF(N15<=M15,"No prazo","Fora do prazo"),IF(N15<=M15,"Aberto no prazo","Aberto e atrasado"))) | P15: =IF(AND(C15="",COUNTA(D15:L15)=0),"",IF(ISNA(MATCH(F15,'Pós-entrega'!$C$7:$C$26,0)),"Produto sem política",IF(D15="","Falta a data de abertura",IF(G15="","Falta o tipo",IF(AND(I15<>"",OR(G15="Reclamação",G15="Garantia",G15="Devolução"),K15=""),"Falta a causa",IF(AND(L15<>"",ISNA(MATCH(L15,Lições!$C$7:$C$66,0))),"Lição não encontrada","OK"))))))
B16: 10 | M16: =IF(F16="","",IFERROR(IF(INDEX('Pós-entrega'!$H$7:$H$26,MATCH(F16,'Pós-entrega'!$C$7:$C$26,0))="","",INDEX('Pós-entrega'!$H$7:$H$26,MATCH(F16,'Pós-entrega'!$C$7:$C$26,0))),"")) | N16: =IF(D16="","",IF(I16<>"",I16-D16,IF(ISNUMBER(Conhecimento!$E$4),Conhecimento!$E$4-D16,""))) | O16: =IF(OR(M16="",N16=""),"",IF(I16<>"",IF(N16<=M16,"No prazo","Fora do prazo"),IF(N16<=M16,"Aberto no prazo","Aberto e atrasado"))) | P16: =IF(AND(C16="",COUNTA(D16:L16)=0),"",IF(ISNA(MATCH(F16,'Pós-entrega'!$C$7:$C$26,0)),"Produto sem política",IF(D16="","Falta a data de abertura",IF(G16="","Falta o tipo",IF(AND(I16<>"",OR(G16="Reclamação",G16="Garantia",G16="Devolução"),K16=""),"Falta a causa",IF(AND(L16<>"",ISNA(MATCH(L16,Lições!$C$7:$C$66,0))),"Lição não encontrada","OK"))))))
B17: 11 | M17: =IF(F17="","",IFERROR(IF(INDEX('Pós-entrega'!$H$7:$H$26,MATCH(F17,'Pós-entrega'!$C$7:$C$26,0))="","",INDEX('Pós-entrega'!$H$7:$H$26,MATCH(F17,'Pós-entrega'!$C$7:$C$26,0))),"")) | N17: =IF(D17="","",IF(I17<>"",I17-D17,IF(ISNUMBER(Conhecimento!$E$4),Conhecimento!$E$4-D17,""))) | O17: =IF(OR(M17="",N17=""),"",IF(I17<>"",IF(N17<=M17,"No prazo","Fora do prazo"),IF(N17<=M17,"Aberto no prazo","Aberto e atrasado"))) | P17: =IF(AND(C17="",COUNTA(D17:L17)=0),"",IF(ISNA(MATCH(F17,'Pós-entrega'!$C$7:$C$26,0)),"Produto sem política",IF(D17="","Falta a data de abertura",IF(G17="","Falta o tipo",IF(AND(I17<>"",OR(G17="Reclamação",G17="Garantia",G17="Devolução"),K17=""),"Falta a causa",IF(AND(L17<>"",ISNA(MATCH(L17,Lições!$C$7:$C$66,0))),"Lição não encontrada","OK"))))))
B18: 12 | M18: =IF(F18="","",IFERROR(IF(INDEX('Pós-entrega'!$H$7:$H$26,MATCH(F18,'Pós-entrega'!$C$7:$C$26,0))="","",INDEX('Pós-entrega'!$H$7:$H$26,MATCH(F18,'Pós-entrega'!$C$7:$C$26,0))),"")) | N18: =IF(D18="","",IF(I18<>"",I18-D18,IF(ISNUMBER(Conhecimento!$E$4),Conhecimento!$E$4-D18,""))) | O18: =IF(OR(M18="",N18=""),"",IF(I18<>"",IF(N18<=M18,"No prazo","Fora do prazo"),IF(N18<=M18,"Aberto no prazo","Aberto e atrasado"))) | P18: =IF(AND(C18="",COUNTA(D18:L18)=0),"",IF(ISNA(MATCH(F18,'Pós-entrega'!$C$7:$C$26,0)),"Produto sem política",IF(D18="","Falta a data de abertura",IF(G18="","Falta o tipo",IF(AND(I18<>"",OR(G18="Reclamação",G18="Garantia",G18="Devolução"),K18=""),"Falta a causa",IF(AND(L18<>"",ISNA(MATCH(L18,Lições!$C$7:$C$66,0))),"Lição não encontrada","OK"))))))
... B86: 80 | M86: =IF(F86="","",IFERROR(IF(INDEX('Pós-entrega'!$H$7:$H$26,MATCH(F86,'Pós-entrega'!$C$7:$C$26,0))="","",INDEX('Pós-entrega'!$H$7:$H$26,MATCH(F86,'Pós-entrega'!$C$7:$C$26,0))),"")) | N86: =IF(D86="","",IF(I86<>"",I86-D86,IF(ISNUMBER(Conhecimento!$E$4),Conhecimento!$E$4-D86,""))) | O86: =IF(OR(M86="",N86=""),"",IF(I86<>"",IF(N86<=M86,"No prazo","Fora do prazo"),IF(N86<=M86,"Aberto no prazo","Aberto e atrasado"))) | P86: =IF(AND(C86="",COUNTA(D86:L86)=0),"",IF(ISNA(MATCH(F86,'Pós-entrega'!$C$7:$C$26,0)),"Produto sem política",IF(D86="","Falta a data de abertura",IF(G86="","Falta o tipo",IF(AND(I86<>"",OR(G86="Reclamação",G86="Garantia",G86="Devolução"),K86=""),"Falta a causa",IF(AND(L86<>"",ISNA(MATCH(L86,Lições!$C$7:$C$66,0))),"Lição não encontrada","OK"))))))
B88: Resumo automático
B89: Atendimentos | E89: =COUNTA(D7:D86)&" atendimentos, custo de R$ "&TEXT(SUM(J7:J86),"0") -> 0 atendimentos, custo de R$ 0
B90: Por situação | E90: =COUNTIF(O7:O86,"No prazo")&" no prazo"&", "&COUNTIF(O7:O86,"Fora do prazo")&" fora do prazo"&", "&COUNTIF(O7:O86,"Aberto no prazo")&" aberto no prazo"&", "&COUNTIF(O7:O86,"Aberto e atrasado")&" aberto e atrasado" -> 0 no prazo, 0 fora do prazo, 0 aberto no prazo, 0 aberto e atrasado
B91: Aviso | E91: =IF(COUNTA(D7:D86)=0,"Lance os atendimentos",IF(COUNTIF(O7:O86,"Aberto e atrasado")>0,"Há atendimento aberto e atrasado",IF(SUMPRODUCT((P7:P86<>"")*(P7:P86<>"OK"))>0,"Há atendimento a completar: veja a coluna Conferência",IF(COUNTIF(O7:O86,"Fora do prazo")>0,"Há atendimento resolvido fora do prazo: veja por quê","OK")))) -> Lance os atendimentos

Sheet Painel
B1: Painel do conhecimento e do pós-entrega
B2: Nada a preencher: tudo vem das outras abas.
B3: Data da leitura | C3: =IF(Conhecimento!$E$4="","",Conhecimento!$E$4)
B5: Indicador | C5: Resultado | D5: Como se lê
B6: CONHECIMENTO
B7: Conhecimentos mapeados | C7: =COUNTA(Conhecimento!C8:C47) -> 0 | D7: Da aba Conhecimento.
B8: Crítico | C8: =COUNTIF(Conhecimento!N8:N47,"Crítico") -> 0 | D8: Alta criticidade e muito exposto.
B9: Em risco | C9: =COUNTIF(Conhecimento!N8:N47,"Em risco") -> 0 | D9: Exposto, alta ou média criticidade.
B10: Sob controle | C10: =COUNTIF(Conhecimento!N8:N47,"Sob controle") -> 0 | D10: Protegido, ou de pouco efeito.
B11: Expostos sem ação de transferência | C11: =COUNTIF(Conhecimento!O8:O47,"Falta a ação de transferência") -> 0 | D11: Ninguém está transferindo.
B12: Ações de transferência vencidas | C12: =COUNTIF(Conhecimento!O8:O47,"Prazo da ação vencido") -> 0 | D12: O prazo passou.
B13: LIÇÕES APRENDIDAS
B14: Lições registradas | C14: =COUNTA(Lições!C7:C66) -> 0 | D14: Da aba Lições.
B15: Lições pendentes | C15: =COUNTIF(Lições!L7:L66,"Pendente") -> 0 | D15: Sem data de incorporação.
B16: Pendentes há mais de 60 dias | C16: =COUNTIF(Lições!N7:N66,"Pendente há mais de 60 dias") -> 0 | D16: Paradas: dar dono e prazo.
B17: PÓS-ENTREGA
B18: Produtos com política | C18: =COUNTA('Pós-entrega'!C7:C26) -> 0 | D18: Da aba Pós-entrega.
B19: Prazo aceito menor que o mínimo | C19: =COUNTIF('Pós-entrega'!J7:J26,"Prazo aceito menor que o mínimo") -> 0 | D19: Abaixo da lei ou do contrato.
B20: Atendimentos | C20: =COUNTA(Atendimentos!D7:D86) -> 0 | D20: Da aba Atendimentos.
B21: Abertos | C21: =COUNTIF(Atendimentos!O7:O86,"Aberto no prazo")+COUNTIF(Atendimentos!O7:O86,"Aberto e atrasado") -> 0 | D21: Ainda sem resolução.
B22: Fora do prazo, resolvidos ou não | C22: =COUNTIF(Atendimentos!O7:O86,"Fora do prazo")+COUNTIF(Atendimentos!O7:O86,"Aberto e atrasado") -> 0 | D22: Passaram do prazo de resposta.
B23: Resolvidos no prazo | C23: =IFERROR(COUNTIF(Atendimentos!O7:O86,"No prazo")/(COUNTIF(Atendimentos!O7:O86,"No prazo")+COUNTIF(Atendimentos!O7:O86,"Fora do prazo")),"") | D23: Entre os resolvidos.
B24: Custo dos atendimentos | C24: =SUM(Atendimentos!J7:J86) -> 0 | D24: Reposições, descontos, fretes, horas.
B25: Linhas a completar | C25: =SUMPRODUCT((Conhecimento!O8:O47<>"")*(Conhecimento!O8:O47<>"OK"))+SUMPRODUCT((Lições!N7:N66<>"")*(Lições!N7:N66<>"OK"))+SUMPRODUCT(('Pós-entrega'!J7:J26<>"")*('Pós-entrega'!J7:J26<>"OK"))+SUMPRODUCT((Atendimentos!P7:P86<>"")*(Atendimentos!P7:P86<>"OK")) -> 0 | D25: Conferências diferentes de OK nas quatro abas.
B27: Resumo automático
B28: Aviso | C28: =IF(C7+C18=0,"Preencha as abas Conhecimento e Pós-entrega",IF(C3="","Informe a data da leitura na aba Conhecimento",IF(COUNTIF(Atendimentos!O7:O86,"Aberto e atrasado")>0,"Há atendimento aberto e atrasado",IF(C19>0,"Há prazo aceito menor que o mínimo da lei ou do contrato",IF(C11>0,"Há conhecimento exposto sem ação de transferência",IF(C16>0,"Há lição pendente há mais de 60 dias",IF(C12>0,"Há ação de transferência vencida",IF(C25>0,"Há linha a completar: veja as conferências","OK")))))))) -> Preencha as abas Conhecimento e Pós-entrega
B30: Conhecimentos por situação
B31: Crítico | C31: =COUNTIF(Conhecimento!N8:N47,B31) -> 0
B32: Em risco | C32: =COUNTIF(Conhecimento!N8:N47,B32) -> 0
B33: Sob controle | C33: =COUNTIF(Conhecimento!N8:N47,B33) -> 0

Sheet Checklist
B1: Checklist do conhecimento e do pós-entrega
B2: Escolha o status de cada item na lista suspensa (coluna em amarelo-claro).
B4: # | C4: Item de verificação | D4: Status | E4: Observações
B5: 1 | C5: O conhecimento necessário para cada processo está mapeado, com a criticidade.
B6: 2 | C6: Para cada conhecimento, sabe-se quantas pessoas o dominam e onde está escrito.
B7: 3 | C7: O conhecimento crítico que só uma pessoa sabe tem ação de transferência com prazo.
B8: 4 | C8: Saídas previstas, como aposentadoria e mudança, entram no mapa com antecedência.
B9: 5 | C9: As lições aprendidas são registradas, com o que aconteceu e o que se aprendeu.
B10: 6 | C10: Cada lição tem destino: um documento, uma instrução ou um treinamento.
B11: 7 | C11: Lições pendentes são lidas todo mês, e nenhuma fica parada sem responsável.
B12: 8 | C12: O que a organização faz depois da entrega está definido para cada produto ou serviço.
B13: 9 | C13: Os prazos aceitos para reclamar respeitam a lei e os contratos.
B14: 10 | C14: As reclamações, garantias e assistências são registradas, com prazo de resposta.
B15: 11 | C15: Cada reclamação resolvida tem a causa registrada.
B16: 12 | C16: O que o pós-entrega ensina volta como lição aprendida.
B18: Resumo automático
B19: Itens atendidos (Sim) | D19: =COUNTIF(D5:D16,"Sim") -> 0
B20: Itens parciais | D20: =COUNTIF(D5:D16,"Parcial") -> 0
B21: Itens não atendidos | D21: =COUNTIF(D5:D16,"Não") -> 0
B22: Itens sem resposta | D22: =COUNTBLANK(D5:D16) -> 12
B23: Percentual atendido | D23: =D19/ROWS(D5:D16) -> 0
B24: Situação | D24: =IF(D19=ROWS(D5:D16),"Validado",IF(D22>0,"Em andamento","Com pendências")) -> Em andamento

Sheet Exemplo 1 - Pizzaria
B1: Conhecimento organizacional e pós-entrega
B2: Exemplo preenchido, para consulta. Use as abas de entrada para a sua organização.
B4: Organização | D4: Pizzaria (loja com salão e delivery)
B5: Responsável | D5: Gerente da loja
B6: Mudança prevista | D6: O pizzaiolo líder, há 12 anos na loja, muda de cidade em agosto de 2027.
B7: Origem | D7: Diagnóstico ISO de 2026: requisito 7.1.6 atendido em parte. As receitas estavam escritas, e a regulagem do forno só o pizzaiolo líder conhecia.
B8: Data da leitura | D8: 46538
B10: Mapa do conhecimento
B11: Código | C11: Conhecimento | D11: Processo | E11: Criticidade | F11: Forma | G11: Onde está | I11: Quem sabe | J11: Saída prevista | K11: Ação de transferência | L11: Prazo | M11: Pontos | N11: Situação | O11: Conferência
B12: K-01 | C12: Regulagem do forno e da chama do lastro | D12: Produção | E12: Alta | F12: Só na cabeça | I12: 1 | J12: Sim | K12: O pizzaiolo líder escreve a regulagem, grava um vídeo e acompanha os dois pizzaiolos no forno. | L12: 46568 | M12: =IF(OR(F12="",I12=""),"",IF(F12="Só na cabeça",2,IF(F12="Escrito",1,0))+IF(I12<=1,2,IF(I12=2,1,0))+IF(J12="Sim",1,0)) -> 5 | N12: =IF(OR(M12="",E12=""),"",IF(AND(E12="Alta",M12>=3),"Crítico",IF(AND(OR(E12="Alta",E12="Média"),M12>=2),"Em risco","Sob controle"))) -> Crítico | O12: =IF(B12="","",IF(E12="","Falta a criticidade",IF(F12="","Falta a forma",IF(I12="","Falta quantas pessoas sabem",IF(OR(N12="Crítico",N12="Em risco"),IF(K12="","Falta a ação de transferência",IF(L12="","Falta o prazo da ação",IF(AND(ISNUMBER($D$8),L12<$D$8),"Prazo da ação vencido",IF(AND(F12<>"Só na cabeça",G12=""),"Falta onde está escrito","OK")))),IF(AND(F12<>"Só na cabeça",G12=""),"Falta onde está escrito","OK")))))) -> OK
B13: K-02 | C13: Ponto da massa pela temperatura da cozinha | D13: Produção | E13: Alta | F13: Escrito | G13: Receita RC-01 | I13: 2 | J13: Não | M13: =IF(OR(F13="",I13=""),"",IF(F13="Só na cabeça",2,IF(F13="Escrito",1,0))+IF(I13<=1,2,IF(I13=2,1,0))+IF(J13="Sim",1,0)) -> 2 | N13: =IF(OR(M13="",E13=""),"",IF(AND(E13="Alta",M13>=3),"Crítico",IF(AND(OR(E13="Alta",E13="Média"),M13>=2),"Em risco","Sob controle"))) -> Em risco | O13: =IF(B13="","",IF(E13="","Falta a criticidade",IF(F13="","Falta a forma",IF(I13="","Falta quantas pessoas sabem",IF(OR(N13="Crítico",N13="Em risco"),IF(K13="","Falta a ação de transferência",IF(L13="","Falta o prazo da ação",IF(AND(ISNUMBER($D$8),L13<$D$8),"Prazo da ação vencido",IF(AND(F13<>"Só na cabeça",G13=""),"Falta onde está escrito","OK")))),IF(AND(F13<>"Só na cabeça",G13=""),"Falta onde está escrito","OK")))))) -> Falta a ação de transferência
B14: K-03 | C14: Receitas das pizzas | D14: Produção | E14: Alta | F14: Escrito e treinado | G14: Receitas RC-01 a RC-24 | I14: 4 | J14: Não | M14: =IF(OR(F14="",I14=""),"",IF(F14="Só na cabeça",2,IF(F14="Escrito",1,0))+IF(I14<=1,2,IF(I14=2,1,0))+IF(J14="Sim",1,0)) -> 0 | N14: =IF(OR(M14="",E14=""),"",IF(AND(E14="Alta",M14>=3),"Crítico",IF(AND(OR(E14="Alta",E14="Média"),M14>=2),"Em risco","Sob controle"))) -> Sob controle | O14: =IF(B14="","",IF(E14="","Falta a criticidade",IF(F14="","Falta a forma",IF(I14="","Falta quantas pessoas sabem",IF(OR(N14="Crítico",N14="Em risco"),IF(K14="","Falta a ação de transferência",IF(L14="","Falta o prazo da ação",IF(AND(ISNUMBER($D$8),L14<$D$8),"Prazo da ação vencido",IF(AND(F14<>"Só na cabeça",G14=""),"Falta onde está escrito","OK")))),IF(AND(F14<>"Só na cabeça",G14=""),"Falta onde está escrito","OK")))))) -> OK
B15: K-04 | C15: Montagem e conferência do pedido | D15: Expedição | E15: Alta | F15: Escrito e treinado | G15: Instrução IT-EXP-01 | I15: 3 | J15: Não | M15: =IF(OR(F15="",I15=""),"",IF(F15="Só na cabeça",2,IF(F15="Escrito",1,0))+IF(I15<=1,2,IF(I15=2,1,0))+IF(J15="Sim",1,0)) -> 0 | N15: =IF(OR(M15="",E15=""),"",IF(AND(E15="Alta",M15>=3),"Crítico",IF(AND(OR(E15="Alta",E15="Média"),M15>=2),"Em risco","Sob controle"))) -> Sob controle | O15: =IF(B15="","",IF(E15="","Falta a criticidade",IF(F15="","Falta a forma",IF(I15="","Falta quantas pessoas sabem",IF(OR(N15="Crítico",N15="Em risco"),IF(K15="","Falta a ação de transferência",IF(L15="","Falta o prazo da ação",IF(AND(ISNUMBER($D$8),L15<$D$8),"Prazo da ação vencido",IF(AND(F15<>"Só na cabeça",G15=""),"Falta onde está escrito","OK")))),IF(AND(F15<>"Só na cabeça",G15=""),"Falta onde está escrito","OK")))))) -> OK
B16: K-05 | C16: Uso do sistema de pedidos novo | D16: Atendimento | E16: Média | F16: Só na cabeça | I16: 2 | J16: Não | K16: O gerente escreve o passo a passo do sábado, com as telas. | M16: =IF(OR(F16="",I16=""),"",IF(F16="Só na cabeça",2,IF(F16="Escrito",1,0))+IF(I16<=1,2,IF(I16=2,1,0))+IF(J16="Sim",1,0)) -> 3 | N16: =IF(OR(M16="",E16=""),"",IF(AND(E16="Alta",M16>=3),"Crítico",IF(AND(OR(E16="Alta",E16="Média"),M16>=2),"Em risco","Sob controle"))) -> Em risco | O16: =IF(B16="","",IF(E16="","Falta a criticidade",IF(F16="","Falta a forma",IF(I16="","Falta quantas pessoas sabem",IF(OR(N16="Crítico",N16="Em risco"),IF(K16="","Falta a ação de transferência",IF(L16="","Falta o prazo da ação",IF(AND(ISNUMBER($D$8),L16<$D$8),"Prazo da ação vencido",IF(AND(F16<>"Só na cabeça",G16=""),"Falta onde está escrito","OK")))),IF(AND(F16<>"Só na cabeça",G16=""),"Falta onde está escrito","OK")))))) -> Falta o prazo da ação
B17: K-06 | C17: Contingência da câmara fria | D17: Estoque | E17: Alta | F17: Escrito | G17: Contingência CT-02, na porta da câmara | I17: 2 | J17: Não | K17: Treinar a equipe do domingo na contingência, com simulação. | L17: 46553 | M17: =IF(OR(F17="",I17=""),"",IF(F17="Só na cabeça",2,IF(F17="Escrito",1,0))+IF(I17<=1,2,IF(I17=2,1,0))+IF(J17="Sim",1,0)) -> 2 | N17: =IF(OR(M17="",E17=""),"",IF(AND(E17="Alta",M17>=3),"Crítico",IF(AND(OR(E17="Alta",E17="Média"),M17>=2),"Em risco","Sob controle"))) -> Em risco | O17: =IF(B17="","",IF(E17="","Falta a criticidade",IF(F17="","Falta a forma",IF(I17="","Falta quantas pessoas sabem",IF(OR(N17="Crítico",N17="Em risco"),IF(K17="","Falta a ação de transferência",IF(L17="","Falta o prazo da ação",IF(AND(ISNUMBER($D$8),L17<$D$8),"Prazo da ação vencido",IF(AND(F17<>"Só na cabeça",G17=""),"Falta onde está escrito","OK")))),IF(AND(F17<>"Só na cabeça",G17=""),"Falta onde está escrito","OK")))))) -> OK
B18: K-07 | C18: Rotas e atalhos do bairro | D18: Entrega | E18: Baixa | F18: Só na cabeça | I18: 3 | J18: Não | M18: =IF(OR(F18="",I18=""),"",IF(F18="Só na cabeça",2,IF(F18="Escrito",1,0))+IF(I18<=1,2,IF(I18=2,1,0))+IF(J18="Sim",1,0)) -> 2 | N18: =IF(OR(M18="",E18=""),"",IF(AND(E18="Alta",M18>=3),"Crítico",IF(AND(OR(E18="Alta",E18="Média"),M18>=2),"Em risco","Sob controle"))) -> Sob controle | O18: =IF(B18="","",IF(E18="","Falta a criticidade",IF(F18="","Falta a forma",IF(I18="","Falta quantas pessoas sabem",IF(OR(N18="Crítico",N18="Em risco"),IF(K18="","Falta a ação de transferência",IF(L18="","Falta o prazo da ação",IF(AND(ISNUMBER($D$8),L18<$D$8),"Prazo da ação vencido",IF(AND(F18<>"Só na cabeça",G18=""),"Falta onde está escrito","OK")))),IF(AND(F18<>"Só na cabeça",G18=""),"Falta onde está escrito","OK")))))) -> OK
B20: Lições aprendidas
B21: Nº | C21: O que aconteceu | D21: Data | E21: Origem | F21: O que aprendemos | I21: Conhec. | J21: Incorporada | K21: Onde incorporar | L21: Responsável | M21: Dias | N21: Situação | O21: Conferência
B22: L-01 | C22: Pizza chegou fria. | D22: 46451 | E22: Reclamação | F22: A bolsa térmica fica fechada até a entrega, e a pizza sai com 65 °C ou mais. | I22: K-04 | J22: 46461 | K22: Instrução IT-EXP-01 | L22: Gerente da loja | M22: =IF(OR(B22="",J22<>"",D22=""),"",IF(ISNUMBER($D$8),$D$8-D22,"")) | N22: =IF(B22="","",IF(J22="","Pendente","Incorporada")) -> Incorporada | O22: =IF(B22="","",IF(D22="","Falta a data",IF(C22="","Falta o que aconteceu",IF(F22="","Falta o que aprendemos",IF(K22="","Falta onde incorporar",IF(AND(I22<>"",ISNA(MATCH(I22,$B$12:$B$18,0))),"Conhecimento não cadastrado",IF(AND(N22="Pendente",N(M22)>60),"Pendente há mais de 60 dias","OK"))))))) -> OK
B23: L-02 | C23: Cliente pediu sem cebola e recebeu com cebola. | D23: 46468 | E23: Reclamação | F23: A observação do pedido precisa sair em destaque na etiqueta. | I23: K-05 | K23: Etiqueta do sistema de pedidos | M23: =IF(OR(B23="",J23<>"",D23=""),"",IF(ISNUMBER($D$8),$D$8-D23,"")) -> 70 | N23: =IF(B23="","",IF(J23="","Pendente","Incorporada")) -> Pendente | O23: =IF(B23="","",IF(D23="","Falta a data",IF(C23="","Falta o que aconteceu",IF(F23="","Falta o que aprendemos",IF(K23="","Falta onde incorporar",IF(AND(I23<>"",ISNA(MATCH(I23,$B$12:$B$18,0))),"Conhecimento não cadastrado",IF(AND(N23="Pendente",N(M23)>60),"Pendente há mais de 60 dias","OK"))))))) -> Pendente há mais de 60 dias
B24: L-03 | C24: Câmara fria parou, e a contingência foi improvisada. | D24: 46490 | E24: Quebra | F24: A contingência precisa estar escrita e na porta da câmara. | I24: K-06 | J24: 46497 | K24: Contingência CT-02 | L24: Gerente da loja | M24: =IF(OR(B24="",J24<>"",D24=""),"",IF(ISNUMBER($D$8),$D$8-D24,"")) | N24: =IF(B24="","",IF(J24="","Pendente","Incorporada")) -> Incorporada | O24: =IF(B24="","",IF(D24="","Falta a data",IF(C24="","Falta o que aconteceu",IF(F24="","Falta o que aprendemos",IF(K24="","Falta onde incorporar",IF(AND(I24<>"",ISNA(MATCH(I24,$B$12:$B$18,0))),"Conhecimento não cadastrado",IF(AND(N24="Pendente",N(M24)>60),"Pendente há mais de 60 dias","OK"))))))) -> OK
B25: L-04 | C25: Corrente da moto partiu na entrega. | D25: 46496 | E25: Quebra | F25: A revisão mensal precisa conferir a corrente. | J25: 46502 | K25: Roteiro de revisão das motos | L25: Gerente da loja | M25: =IF(OR(B25="",J25<>"",D25=""),"",IF(ISNUMBER($D$8),$D$8-D25,"")) | N25: =IF(B25="","",IF(J25="","Pendente","Incorporada")) -> Incorporada | O25: =IF(B25="","",IF(D25="","Falta a data",IF(C25="","Falta o que aconteceu",IF(F25="","Falta o que aprendemos",IF(K25="","Falta onde incorporar",IF(AND(I25<>"",ISNA(MATCH(I25,$B$12:$B$18,0))),"Conhecimento não cadastrado",IF(AND(N25="Pendente",N(M25)>60),"Pendente há mais de 60 dias","OK"))))))) -> OK
B26: L-05 | C26: Chama do forno apagando, e só o pizzaiolo líder sabia regular. | D26: 46503 | E26: Quebra | F26: A regulagem do forno precisa estar escrita. | I26: K-01 | K26: Instrução do forno IT-PRO-02 | L26: Pizzaiolo líder | M26: =IF(OR(B26="",J26<>"",D26=""),"",IF(ISNUMBER($D$8),$D$8-D26,"")) -> 35 | N26: =IF(B26="","",IF(J26="","Pendente","Incorporada")) -> Pendente | O26: =IF(B26="","",IF(D26="","Falta a data",IF(C26="","Falta o que aconteceu",IF(F26="","Falta o que aprendemos",IF(K26="","Falta onde incorporar",IF(AND(I26<>"",ISNA(MATCH(I26,$B$12:$B$18,0))),"Conhecimento não cadastrado",IF(AND(N26="Pendente",N(M26)>60),"Pendente há mais de 60 dias","OK"))))))) -> OK
B27: L-06 | C27: Clientes perguntam como reaquecer a pizza. | D27: 46517 | E27: Pós-entrega | K27: Embalagem | M27: =IF(OR(B27="",J27<>"",D27=""),"",IF(ISNUMBER($D$8),$D$8-D27,"")) -> 21 | N27: =IF(B27="","",IF(J27="","Pendente","Incorporada")) -> Pendente | O27: =IF(B27="","",IF(D27="","Falta a data",IF(C27="","Falta o que aconteceu",IF(F27="","Falta o que aprendemos",IF(K27="","Falta onde incorporar",IF(AND(I27<>"",ISNA(MATCH(I27,$B$12:$B$18,0))),"Conhecimento não cadastrado",IF(AND(N27="Pendente",N(M27)>60),"Pendente há mais de 60 dias","OK"))))))) -> Falta o que aprendemos
B29: Política de pós-entrega
B30: Produto ou serviço | D30: Vida útil | F30: Mínimo (dias) | G30: Aceito (dias) | H30: O que se faz | L30: Resposta (dias) | M30: O que se quer evitar | Q30: Conferência
B31: Pizza entregue | D31: Consumo no dia; até 3 dias na geladeira | F31: 30 | G31: 1 | H31: Reposição ou desconto, e orientação de reaquecimento. | L31: 1 | M31: Cliente comer a pizza depois de 3 dias. | Q31: =IF(B31="","",IF(F31="","Falta o prazo mínimo para reclamar",IF(G31="","Falta o prazo aceito",IF(G31<F31,"Prazo aceito menor que o mínimo",IF(H31="","Falta o que se faz",IF(L31="","Falta o prazo de resposta","OK")))))) -> Prazo aceito menor que o mínimo
B32: Pizza no salão | D32: Consumo no local | F32: 30 | G32: 30 | H32: Troca na hora. | L32: 0 | Q32: =IF(B32="","",IF(F32="","Falta o prazo mínimo para reclamar",IF(G32="","Falta o prazo aceito",IF(G32<F32,"Prazo aceito menor que o mínimo",IF(H32="","Falta o que se faz",IF(L32="","Falta o prazo de resposta","OK")))))) -> OK
B33: Massa congelada para levar | D33: 60 dias no freezer | F33: 30 | G33: 30 | H33: Troca ou devolução do valor, e orientação de armazenagem na embalagem. | L33: 2 | M33: Descongelar e congelar de novo. | Q33: =IF(B33="","",IF(F33="","Falta o prazo mínimo para reclamar",IF(G33="","Falta o prazo aceito",IF(G33<F33,"Prazo aceito menor que o mínimo",IF(H33="","Falta o que se faz",IF(L33="","Falta o prazo de resposta","OK")))))) -> OK
B35: Atendimentos depois da entrega
B36: Nº | C36: Relato | D36: Abertura | E36: Tipo | F36: Produto | H36: Cliente | I36: Resolução | J36: Custo | K36: Causa | L36: Lição | M36: Prazo | N36: Dias | O36: Situação | P36: Conferência
B37: A-01 | C37: Pizza fria. | D37: 46510 | E37: Reclamação | F37: Pizza entregue | H37: Cliente do bairro A | I37: 46510 | J37: 45 | K37: Entregador com 4 pedidos na mesma rota. | L37: L-01 | M37: =IF(F37="","",IFERROR(IF(INDEX($L$31:$L$33,MATCH(F37,$B$31:$B$33,0))="","",INDEX($L$31:$L$33,MATCH(F37,$B$31:$B$33,0))),"")) -> 1 | N37: =IF(D37="","",IF(I37<>"",I37-D37,IF(ISNUMBER($D$8),$D$8-D37,""))) -> 0 | O37: =IF(OR(M37="",N37=""),"",IF(I37<>"",IF(N37<=M37,"No prazo","Fora do prazo"),IF(N37<=M37,"Aberto no prazo","Aberto e atrasado"))) -> No prazo | P37: =IF(B37="","",IF(ISNA(MATCH(F37,$B$31:$B$33,0)),"Produto sem política",IF(D37="","Falta a data de abertura",IF(E37="","Falta o tipo",IF(AND(I37<>"",OR(E37="Reclamação",E37="Garantia",E37="Devolução"),K37=""),"Falta a causa",IF(AND(L37<>"",ISNA(MATCH(L37,$B$22:$B$27,0))),"Lição não encontrada","OK")))))) -> OK
B38: A-02 | C38: Sabor trocado: pediu sem cebola. | D38: 46514 | E38: Reclamação | F38: Pizza entregue | H38: Cliente do bairro B | I38: 46514 | J38: 60 | K38: Observação do pedido sem destaque na etiqueta. | L38: L-02 | M38: =IF(F38="","",IFERROR(IF(INDEX($L$31:$L$33,MATCH(F38,$B$31:$B$33,0))="","",INDEX($L$31:$L$33,MATCH(F38,$B$31:$B$33,0))),"")) -> 1 | N38: =IF(D38="","",IF(I38<>"",I38-D38,IF(ISNUMBER($D$8),$D$8-D38,""))) -> 0 | O38: =IF(OR(M38="",N38=""),"",IF(I38<>"",IF(N38<=M38,"No prazo","Fora do prazo"),IF(N38<=M38,"Aberto no prazo","Aberto e atrasado"))) -> No prazo | P38: =IF(B38="","",IF(ISNA(MATCH(F38,$B$31:$B$33,0)),"Produto sem política",IF(D38="","Falta a data de abertura",IF(E38="","Falta o tipo",IF(AND(I38<>"",OR(E38="Reclamação",E38="Garantia",E38="Devolução"),K38=""),"Falta a causa",IF(AND(L38<>"",ISNA(MATCH(L38,$B$22:$B$27,0))),"Lição não encontrada","OK")))))) -> OK
B39: A-03 | C39: Borda queimada. | D39: 46521 | E39: Reclamação | F39: Pizza entregue | H39: Cliente do bairro A | I39: 46523 | J39: 50 | K39: Chama irregular no forno. | L39: L-05 | M39: =IF(F39="","",IFERROR(IF(INDEX($L$31:$L$33,MATCH(F39,$B$31:$B$33,0))="","",INDEX($L$31:$L$33,MATCH(F39,$B$31:$B$33,0))),"")) -> 1 | N39: =IF(D39="","",IF(I39<>"",I39-D39,IF(ISNUMBER($D$8),$D$8-D39,""))) -> 2 | O39: =IF(OR(M39="",N39=""),"",IF(I39<>"",IF(N39<=M39,"No prazo","Fora do prazo"),IF(N39<=M39,"Aberto no prazo","Aberto e atrasado"))) -> Fora do prazo | P39: =IF(B39="","",IF(ISNA(MATCH(F39,$B$31:$B$33,0)),"Produto sem política",IF(D39="","Falta a data de abertura",IF(E39="","Falta o tipo",IF(AND(I39<>"",OR(E39="Reclamação",E39="Garantia",E39="Devolução"),K39=""),"Falta a causa",IF(AND(L39<>"",ISNA(MATCH(L39,$B$22:$B$27,0))),"Lição não encontrada","OK")))))) -> OK
B40: A-04 | C40: Como descongelar a massa. | D40: 46522 | E40: Orientação de uso | F40: Massa congelada para levar | H40: Cliente do balcão | I40: 46522 | J40: 0 | M40: =IF(F40="","",IFERROR(IF(INDEX($L$31:$L$33,MATCH(F40,$B$31:$B$33,0))="","",INDEX($L$31:$L$33,MATCH(F40,$B$31:$B$33,0))),"")) -> 2 | N40: =IF(D40="","",IF(I40<>"",I40-D40,IF(ISNUMBER($D$8),$D$8-D40,""))) -> 0 | O40: =IF(OR(M40="",N40=""),"",IF(I40<>"",IF(N40<=M40,"No prazo","Fora do prazo"),IF(N40<=M40,"Aberto no prazo","Aberto e atrasado"))) -> No prazo | P40: =IF(B40="","",IF(ISNA(MATCH(F40,$B$31:$B$33,0)),"Produto sem política",IF(D40="","Falta a data de abertura",IF(E40="","Falta o tipo",IF(AND(I40<>"",OR(E40="Reclamação",E40="Garantia",E40="Devolução"),K40=""),"Falta a causa",IF(AND(L40<>"",ISNA(MATCH(L40,$B$22:$B$27,0))),"Lição não encontrada","OK")))))) -> OK
B41: A-05 | C41: Atraso de uma hora. | D41: 46528 | E41: Reclamação | F41: Pizza entregue | H41: Cliente do bairro C | I41: 46529 | J41: 40 | M41: =IF(F41="","",IFERROR(IF(INDEX($L$31:$L$33,MATCH(F41,$B$31:$B$33,0))="","",INDEX($L$31:$L$33,MATCH(F41,$B$31:$B$33,0))),"")) -> 1 | N41: =IF(D41="","",IF(I41<>"",I41-D41,IF(ISNUMBER($D$8),$D$8-D41,""))) -> 1 | O41: =IF(OR(M41="",N41=""),"",IF(I41<>"",IF(N41<=M41,"No prazo","Fora do prazo"),IF(N41<=M41,"Aberto no prazo","Aberto e atrasado"))) -> No prazo | P41: =IF(B41="","",IF(ISNA(MATCH(F41,$B$31:$B$33,0)),"Produto sem política",IF(D41="","Falta a data de abertura",IF(E41="","Falta o tipo",IF(AND(I41<>"",OR(E41="Reclamação",E41="Garantia",E41="Devolução"),K41=""),"Falta a causa",IF(AND(L41<>"",ISNA(MATCH(L41,$B$22:$B$27,0))),"Lição não encontrada","OK")))))) -> Falta a causa
