Workbook

Sheet Instruções
B1: Processo de certificação — Como usar esta planilha
B2: Modelo para avaliar a prontidão, acompanhar o ciclo do certificado e tratar as constatações do organismo.
B4: Legenda: onde preencher
B5: Amarelo-claro | C5: Células de entrada. É aqui que você digita.
B6: Cinza | C6: Células calculadas ou fixas (critérios, limites, prazos, situações, conferências). Não altere.
B7: Cinza em itálico | C7: Linha de exemplo (marcada com “Ex.”). Mostra o formato esperado e não entra nas contagens.
B8: Listas suspensas | C8: Status, edição, auditoria, tipo de constatação e checklist aceitam apenas as opções da lista.
B9: Comentários | C9: Células com triângulo vermelho no canto trazem uma dica de preenchimento. Passe o mouse sobre elas.
B11: As regras de cálculo
B12: Prontidão | C12: Sim vale 1, Parcial 0,5, Não 0. Ainda não está pronta: há impeditivo da fase 1 diferente de Sim. Pronta para a fase 1: só faltam impeditivos da fase 2. Pronta para a fase 2: nenhum impeditivo pendente.
B13: Validade | C13: A data da decisão mais 36 meses, menos um dia.
B14: Limites do ciclo | C14: Fase 2: até 6 meses depois da fase 1. Manutenções: 12 e 24 meses depois da decisão. Recertificação: auditoria até 3 meses antes do vencimento. Transição: o fim da janela ou a validade, o que vier antes, só para a edição de 2015.
B15: Situação do evento | C15: No prazo ou Fora do prazo, se realizado. Se não: Atrasada depois do limite, Vence em 60 dias a 60 dias ou menos, Prevista antes disso.
B16: Prazos das constatações | C16: Plano em até 30 dias para as não conformidades. A maior fechada, com evidência aceita, em até 90 dias.
B17: Situação da constatação | C17: Fechada com evidência aceita. Plano atrasado sem plano depois do prazo. Vencida: risco ao certificado se a maior passou de 90 dias. Aguarda verificação para a menor com plano. Tratar antes da fase 2 para o ponto da fase 1 em aberto.
B19: Ordem recomendada de preenchimento
B20: Passo 1 | C20: Aba Prontidão: a data e o status de cada critério, com a evidência, ou a ação, o responsável e o prazo.
B21: Passo 2 | C21: Aba Ciclo: o organismo, a edição da norma, a data da decisão (real ou prevista), a data da leitura e o fim da transição.
B22: Passo 3 | C22: Aba Ciclo: as datas em que cada auditoria foi realizada.
B23: Passo 4 | C23: Aba Constatações: depois de cada auditoria, as constatações e as datas do plano, da ação e da evidência aceita.
B24: Passo 5 | C24: Aba Painel: leia os avisos. Depois, valide na aba Checklist.
B26: Abas da planilha
B27: Prontidão | C27: Os 14 critérios, com o momento e se são impeditivos. Calcula o percentual, os impeditivos e o resultado.
B28: Ciclo | C28: Os dados do certificado e os sete eventos. Calcula a validade, os limites e as situações.
B29: Constatações | C29: Até 40 constatações do organismo. Calcula os prazos, a situação e a conferência.
B30: Painel | C30: Os números das três abas, o gráfico das constatações e o aviso.
B31: Checklist | C31: Doze verificações da certificação, com percentual de conclusão.
B32: Exemplo 1 - Pizzaria | C32: Prontidão em 30/11/2027, certificação pela edição de 2026 em 2028.
B33: Exemplo 2 - Indústria | C33: Prontidão em 30/09/2027, certificação pela edição de 2015 em dezembro de 2027.
B35: Premissas do modelo
B36: Convenções | C36: Os prazos de 30 e 90 dias, os 6 meses entre as fases, os 3 meses da recertificação e os critérios de prontidão são uma convenção deste material. Vale o regulamento do seu organismo.
B37: Transição | C37: A ISO 9001:2026 foi publicada em 16/09/2026. O fim da transição vem preenchido com 30/09/2029, fixado pela Global ACI; desde 31/03/2028, certificados novos só pela edição de 2026. Confirme com o seu organismo.
B38: Exemplos | C38: Os dados das abas de exemplo são ilustrativos, criados para este material.

Sheet Prontidão
B1: Prontidão para a certificação
B2: Um critério por linha. Os impeditivos precisam estar em Sim antes da fase indicada.
B4: Data da avaliação
B6: # | C6: Critério | D6: Antes da | E6: Impeditivo | F6: Status | G6: Evidência | H6: Ação, se não está pronto | I6: Responsável | J6: Prazo | K6: Pontos | L6: Conferência
B7: 1 | C7: O escopo está definido, com a justificativa do que não se aplica. | D7: Fase 1 | E7: Sim | K7: =IF(F7="","",IF(F7="Sim",1,IF(F7="Parcial",0.5,0))) | L7: =IF(F7="","Falta o status",IF(AND(F7<>"Sim",H7=""),"Falta a ação",IF(AND(F7<>"Sim",J7=""),"Falta o prazo",IF(AND(F7="Sim",G7=""),"Falta a evidência","OK")))) -> Falta o status
B8: 2 | C8: A política e os objetivos da qualidade estão aprovados e comunicados. | D8: Fase 1 | E8: Sim | K8: =IF(F8="","",IF(F8="Sim",1,IF(F8="Parcial",0.5,0))) | L8: =IF(F8="","Falta o status",IF(AND(F8<>"Sim",H8=""),"Falta a ação",IF(AND(F8<>"Sim",J8=""),"Falta o prazo",IF(AND(F8="Sim",G8=""),"Falta a evidência","OK")))) -> Falta o status
B9: 3 | C9: Os processos estão determinados, com a sequência e a interação entre eles. | D9: Fase 1 | E9: Sim | K9: =IF(F9="","",IF(F9="Sim",1,IF(F9="Parcial",0.5,0))) | L9: =IF(F9="","Falta o status",IF(AND(F9<>"Sim",H9=""),"Falta a ação",IF(AND(F9<>"Sim",J9=""),"Falta o prazo",IF(AND(F9="Sim",G9=""),"Falta a evidência","OK")))) -> Falta o status
B10: 4 | C10: A informação documentada exigida existe e está sob controle. | D10: Fase 1 | E10: Sim | K10: =IF(F10="","",IF(F10="Sim",1,IF(F10="Parcial",0.5,0))) | L10: =IF(F10="","Falta o status",IF(AND(F10<>"Sim",H10=""),"Falta a ação",IF(AND(F10<>"Sim",J10=""),"Falta o prazo",IF(AND(F10="Sim",G10=""),"Falta a evidência","OK")))) -> Falta o status
B11: 5 | C11: O organismo de certificação está escolhido, acreditado para o escopo. | D11: Fase 1 | E11: — | K11: =IF(F11="","",IF(F11="Sim",1,IF(F11="Parcial",0.5,0))) | L11: =IF(F11="","Falta o status",IF(AND(F11<>"Sim",H11=""),"Falta a ação",IF(AND(F11<>"Sim",J11=""),"Falta o prazo",IF(AND(F11="Sim",G11=""),"Falta a evidência","OK")))) -> Falta o status
B12: 6 | C12: O sistema funciona há pelo menos três meses, com registros. | D12: Fase 2 | E12: Sim | K12: =IF(F12="","",IF(F12="Sim",1,IF(F12="Parcial",0.5,0))) | L12: =IF(F12="","Falta o status",IF(AND(F12<>"Sim",H12=""),"Falta a ação",IF(AND(F12<>"Sim",J12=""),"Falta o prazo",IF(AND(F12="Sim",G12=""),"Falta a evidência","OK")))) -> Falta o status
B13: 7 | C13: Há um ciclo completo de auditoria interna, cobrindo todos os processos. | D13: Fase 2 | E13: Sim | K13: =IF(F13="","",IF(F13="Sim",1,IF(F13="Parcial",0.5,0))) | L13: =IF(F13="","Falta o status",IF(AND(F13<>"Sim",H13=""),"Falta a ação",IF(AND(F13<>"Sim",J13=""),"Falta o prazo",IF(AND(F13="Sim",G13=""),"Falta a evidência","OK")))) -> Falta o status
B14: 8 | C14: Houve ao menos uma análise crítica pela direção, com todas as entradas. | D14: Fase 2 | E14: Sim | K14: =IF(F14="","",IF(F14="Sim",1,IF(F14="Parcial",0.5,0))) | L14: =IF(F14="","Falta o status",IF(AND(F14<>"Sim",H14=""),"Falta a ação",IF(AND(F14<>"Sim",J14=""),"Falta o prazo",IF(AND(F14="Sim",G14=""),"Falta a evidência","OK")))) -> Falta o status
B15: 9 | C15: As não conformidades da auditoria interna têm ação definida. | D15: Fase 2 | E15: Sim | K15: =IF(F15="","",IF(F15="Sim",1,IF(F15="Parcial",0.5,0))) | L15: =IF(F15="","Falta o status",IF(AND(F15<>"Sim",H15=""),"Falta a ação",IF(AND(F15<>"Sim",J15=""),"Falta o prazo",IF(AND(F15="Sim",G15=""),"Falta a evidência","OK")))) -> Falta o status
B16: 10 | C16: Os indicadores têm série de pelo menos três meses. | D16: Fase 2 | E16: — | K16: =IF(F16="","",IF(F16="Sim",1,IF(F16="Parcial",0.5,0))) | L16: =IF(F16="","Falta o status",IF(AND(F16<>"Sim",H16=""),"Falta a ação",IF(AND(F16<>"Sim",J16=""),"Falta o prazo",IF(AND(F16="Sim",G16=""),"Falta a evidência","OK")))) -> Falta o status
B17: 11 | C17: As pessoas sabem explicar a política e o próprio papel no sistema. | D17: Fase 2 | E17: — | K17: =IF(F17="","",IF(F17="Sim",1,IF(F17="Parcial",0.5,0))) | L17: =IF(F17="","Falta o status",IF(AND(F17<>"Sim",H17=""),"Falta a ação",IF(AND(F17<>"Sim",J17=""),"Falta o prazo",IF(AND(F17="Sim",G17=""),"Falta a evidência","OK")))) -> Falta o status
B18: 12 | C18: Os requisitos legais do produto estão identificados e atendidos. | D18: Fase 2 | E18: — | K18: =IF(F18="","",IF(F18="Sim",1,IF(F18="Parcial",0.5,0))) | L18: =IF(F18="","Falta o status",IF(AND(F18<>"Sim",H18=""),"Falta a ação",IF(AND(F18<>"Sim",J18=""),"Falta o prazo",IF(AND(F18="Sim",G18=""),"Falta a evidência","OK")))) -> Falta o status
... B20: 14 | C20: As reclamações e a satisfação do cliente são registradas e analisadas. | D20: Fase 2 | E20: — | K20: =IF(F20="","",IF(F20="Sim",1,IF(F20="Parcial",0.5,0))) | L20: =IF(F20="","Falta o status",IF(AND(F20<>"Sim",H20=""),"Falta a ação",IF(AND(F20<>"Sim",J20=""),"Falta o prazo",IF(AND(F20="Sim",G20=""),"Falta a evidência","OK")))) -> Falta o status
B22: Resumo automático
B23: Percentual atendido | E23: =IF(COUNTA(F7:F20)=0,"",SUM(K7:K20)/ROWS(K7:K20))
B24: Impeditivos antes da fase 1 | E24: =SUMPRODUCT((D7:D20="Fase 1")*(E7:E20="Sim")*(F7:F20<>"Sim")) -> 4
B25: Impeditivos antes da fase 2 | E25: =SUMPRODUCT((D7:D20="Fase 2")*(E7:E20="Sim")*(F7:F20<>"Sim")) -> 4
B26: Resultado | E26: =IF(COUNTA(F7:F20)=0,"",IF(SUMPRODUCT((D7:D20="Fase 1")*(E7:E20="Sim")*(F7:F20<>"Sim"))>0,"Ainda não está pronta",IF(SUMPRODUCT((D7:D20="Fase 2")*(E7:E20="Sim")*(F7:F20<>"Sim"))>0,"Pronta para a fase 1","Pronta para a fase 2")))
B27: Aviso | E27: =IF(COUNTA(F7:F20)=0,"Responda os critérios",IF(E24>0,"Há impeditivo pendente antes da fase 1",IF(E25>0,"Há impeditivo pendente antes da fase 2",IF(SUMPRODUCT((L7:L20<>"OK")*1)>0,"Há critério a completar: veja a coluna Conferência","OK")))) -> Responda os critérios

Sheet Ciclo
B1: Ciclo do certificado
B2: Os dados do certificado e os eventos do ciclo, com os limites calculados.
B4: Organismo | F4: O organismo de certificação, e a acreditação dele.
B5: Edição da norma | F5: A edição pela qual o certificado foi, ou será, emitido.
B6: Data da decisão de certificação | F6: A data real, ou a prevista, para simular o ciclo.
B7: Data da leitura | F7: Os eventos são comparados com esta data.
B8: Fim da transição | D8: 47391 | F8: Prazo para os certificados de 2015 migrarem. Confirme no comunicado da acreditação.
B9: Validade do certificado | D9: =IF(D6="","",EDATE(D6,36)-1)
B12: # | C12: Evento | D12: Limite | E12: Realizado em | F12: Situação | G12: Observação | H12: Limite pendente
B13: 1 | C13: Fase 1 | D13: ="" | F13: =IF(E13="","Prevista","Realizada") -> Prevista | H13: =IF(AND(D13<>"",E13=""),D13,"")
B14: 2 | C14: Fase 2 | D14: =IF(E13="","",EDATE(E13,6)) | F14: =IF(D14="","",IF(E14<>"",IF(E14<=D14,"No prazo","Fora do prazo"),IF(N($D$7)=0,"",IF($D$7>D14,"Atrasada",IF(D14-$D$7<=60,"Vence em 60 dias","Prevista"))))) | H14: =IF(AND(D14<>"",E14=""),D14,"")
B15: 3 | C15: Decisão de certificação | D15: ="" | E15: =IF($D$6="","",$D$6) | F15: =IF(E15="","Prevista","Realizada") -> Prevista | H15: =IF(AND(D15<>"",E15=""),D15,"")
B16: 4 | C16: 1ª manutenção | D16: =IF($D$6="","",EDATE($D$6,12)) | F16: =IF(D16="","",IF(E16<>"",IF(E16<=D16,"No prazo","Fora do prazo"),IF(N($D$7)=0,"",IF($D$7>D16,"Atrasada",IF(D16-$D$7<=60,"Vence em 60 dias","Prevista"))))) | H16: =IF(AND(D16<>"",E16=""),D16,"")
B17: 5 | C17: 2ª manutenção | D17: =IF($D$6="","",EDATE($D$6,24)) | F17: =IF(D17="","",IF(E17<>"",IF(E17<=D17,"No prazo","Fora do prazo"),IF(N($D$7)=0,"",IF($D$7>D17,"Atrasada",IF(D17-$D$7<=60,"Vence em 60 dias","Prevista"))))) | H17: =IF(AND(D17<>"",E17=""),D17,"")
B18: 6 | C18: Auditoria de recertificação | D18: =IF($D$6="","",EDATE($D$6,33)) | F18: =IF(D18="","",IF(E18<>"",IF(E18<=D18,"No prazo","Fora do prazo"),IF(N($D$7)=0,"",IF($D$7>D18,"Atrasada",IF(D18-$D$7<=60,"Vence em 60 dias","Prevista"))))) | H18: =IF(AND(D18<>"",E18=""),D18,"")
B19: 7 | C19: Transição para a edição de 2026 | D19: =IF(OR($D$6="",$D$5<>"ISO 9001:2015"),"",MIN($D$8,$D$9)) | F19: =IF($D$5<>"ISO 9001:2015","Não se aplica",IF(D19="","",IF(E19<>"",IF(E19<=D19,"No prazo","Fora do prazo"),IF(N($D$7)=0,"",IF($D$7>D19,"Atrasada",IF(D19-$D$7<=60,"Vence em 60 dias","Prevista")))))) -> Não se aplica | H19: =IF(AND(D19<>"",E19=""),D19,"")
B21: Resumo automático
B22: Validade | E22: =IF(D9="","",D9)
B23: Eventos | E23: =COUNTIF(F13:F19,"Realizada")&" realizada"&", "&COUNTIF(F13:F19,"No prazo")&" no prazo"&", "&COUNTIF(F13:F19,"Fora do prazo")&" fora do prazo"&", "&COUNTIF(F13:F19,"Vence em 60 dias")&" vence em 60 dias"&", "&COUNTIF(F13:F19,"Atrasada")&" atrasada"&", "&COUNTIF(F13:F19,"Prevista")&" prevista" -> 0 realizada, 0 no prazo, 0 fora do prazo, 0 vence em 60 dias, 0 atrasada, 2 prevista
B24: Aviso | E24: =IF(D6="","Informe a data da decisão, real ou prevista",IF(D7="","Informe a data da leitura",IF(COUNTIF(F13:F19,"Atrasada")>0,"Há evento atrasado: fale com o organismo",IF(COUNTIF(F13:F19,"Vence em 60 dias")>0,"Há evento que vence em 60 dias: confirme a data com o organismo","OK")))) -> Informe a data da decisão, real ou prevista

Sheet Constatações
B1: Constatações do organismo
B2: Uma constatação por linha, com as datas do plano, da ação e da evidência aceita.
B4: # | C4: Nº | D4: Auditoria | E4: Data | F4: Tipo | G4: Requisito | H4: Constatação | I4: Plano enviado | J4: Ação concluída | K4: Evidência aceita | L4: Prazo do plano | M4: Prazo para fechar | N4: Situação | O4: Conferência
D5: Lista | E5: Da auditoria | F5: Lista | G5: Ex.: 8.5.6 | H5: Como o organismo escreveu | I5: Data | J5: Data | K5: Data | L5: Calculado | M5: Calculado | N5: Calculada | O5: Calculada
B6: Ex. | C6: I-4 | D6: Fase 2 | E6: 46714 | F6: NC menor | G6: 7.2 | H6: Operador novo sem registro de treinamento | I6: 46726 | L6: 46744 | N6: Aguarda verificação | O6: OK
B7: 1 | L7: =IF(OR(E7="",AND(F7<>"NC maior",F7<>"NC menor")),"",E7+30) | M7: =IF(OR(E7="",F7<>"NC maior"),"",E7+90) | N7: =IF(OR(F7="",E7=""),"",IF(OR(F7="Oportunidade de melhoria",F7="Ponto de atenção da fase 1"),IF(K7<>"","Fechada",IF(F7="Ponto de atenção da fase 1","Tratar antes da fase 2","Para considerar")),IF(K7<>"","Fechada",IF(AND(I7="",N(Ciclo!$D$7)>L7),"Plano atrasado",IF(AND(F7="NC maior",N(Ciclo!$D$7)>M7),"Vencida: risco ao certificado",IF(AND(F7="NC menor",I7<>""),"Aguarda verificação","Aberta no prazo")))))) | O7: =IF(AND(C7="",COUNTA(D7:K7)=0),"",IF(E7="","Falta a data da auditoria",IF(F7="","Falta o tipo",IF(G7="","Falta o requisito",IF(H7="","Falta a descrição",IF(AND(I7<>"",I7<E7),"Plano antes da auditoria",IF(AND(F7="NC maior",K7<>"",J7=""),"Falta a conclusão da ação","OK")))))))
B8: 2 | L8: =IF(OR(E8="",AND(F8<>"NC maior",F8<>"NC menor")),"",E8+30) | M8: =IF(OR(E8="",F8<>"NC maior"),"",E8+90) | N8: =IF(OR(F8="",E8=""),"",IF(OR(F8="Oportunidade de melhoria",F8="Ponto de atenção da fase 1"),IF(K8<>"","Fechada",IF(F8="Ponto de atenção da fase 1","Tratar antes da fase 2","Para considerar")),IF(K8<>"","Fechada",IF(AND(I8="",N(Ciclo!$D$7)>L8),"Plano atrasado",IF(AND(F8="NC maior",N(Ciclo!$D$7)>M8),"Vencida: risco ao certificado",IF(AND(F8="NC menor",I8<>""),"Aguarda verificação","Aberta no prazo")))))) | O8: =IF(AND(C8="",COUNTA(D8:K8)=0),"",IF(E8="","Falta a data da auditoria",IF(F8="","Falta o tipo",IF(G8="","Falta o requisito",IF(H8="","Falta a descrição",IF(AND(I8<>"",I8<E8),"Plano antes da auditoria",IF(AND(F8="NC maior",K8<>"",J8=""),"Falta a conclusão da ação","OK")))))))
B9: 3 | L9: =IF(OR(E9="",AND(F9<>"NC maior",F9<>"NC menor")),"",E9+30) | M9: =IF(OR(E9="",F9<>"NC maior"),"",E9+90) | N9: =IF(OR(F9="",E9=""),"",IF(OR(F9="Oportunidade de melhoria",F9="Ponto de atenção da fase 1"),IF(K9<>"","Fechada",IF(F9="Ponto de atenção da fase 1","Tratar antes da fase 2","Para considerar")),IF(K9<>"","Fechada",IF(AND(I9="",N(Ciclo!$D$7)>L9),"Plano atrasado",IF(AND(F9="NC maior",N(Ciclo!$D$7)>M9),"Vencida: risco ao certificado",IF(AND(F9="NC menor",I9<>""),"Aguarda verificação","Aberta no prazo")))))) | O9: =IF(AND(C9="",COUNTA(D9:K9)=0),"",IF(E9="","Falta a data da auditoria",IF(F9="","Falta o tipo",IF(G9="","Falta o requisito",IF(H9="","Falta a descrição",IF(AND(I9<>"",I9<E9),"Plano antes da auditoria",IF(AND(F9="NC maior",K9<>"",J9=""),"Falta a conclusão da ação","OK")))))))
B10: 4 | L10: =IF(OR(E10="",AND(F10<>"NC maior",F10<>"NC menor")),"",E10+30) | M10: =IF(OR(E10="",F10<>"NC maior"),"",E10+90) | N10: =IF(OR(F10="",E10=""),"",IF(OR(F10="Oportunidade de melhoria",F10="Ponto de atenção da fase 1"),IF(K10<>"","Fechada",IF(F10="Ponto de atenção da fase 1","Tratar antes da fase 2","Para considerar")),IF(K10<>"","Fechada",IF(AND(I10="",N(Ciclo!$D$7)>L10),"Plano atrasado",IF(AND(F10="NC maior",N(Ciclo!$D$7)>M10),"Vencida: risco ao certificado",IF(AND(F10="NC menor",I10<>""),"Aguarda verificação","Aberta no prazo")))))) | O10: =IF(AND(C10="",COUNTA(D10:K10)=0),"",IF(E10="","Falta a data da auditoria",IF(F10="","Falta o tipo",IF(G10="","Falta o requisito",IF(H10="","Falta a descrição",IF(AND(I10<>"",I10<E10),"Plano antes da auditoria",IF(AND(F10="NC maior",K10<>"",J10=""),"Falta a conclusão da ação","OK")))))))
B11: 5 | L11: =IF(OR(E11="",AND(F11<>"NC maior",F11<>"NC menor")),"",E11+30) | M11: =IF(OR(E11="",F11<>"NC maior"),"",E11+90) | N11: =IF(OR(F11="",E11=""),"",IF(OR(F11="Oportunidade de melhoria",F11="Ponto de atenção da fase 1"),IF(K11<>"","Fechada",IF(F11="Ponto de atenção da fase 1","Tratar antes da fase 2","Para considerar")),IF(K11<>"","Fechada",IF(AND(I11="",N(Ciclo!$D$7)>L11),"Plano atrasado",IF(AND(F11="NC maior",N(Ciclo!$D$7)>M11),"Vencida: risco ao certificado",IF(AND(F11="NC menor",I11<>""),"Aguarda verificação","Aberta no prazo")))))) | O11: =IF(AND(C11="",COUNTA(D11:K11)=0),"",IF(E11="","Falta a data da auditoria",IF(F11="","Falta o tipo",IF(G11="","Falta o requisito",IF(H11="","Falta a descrição",IF(AND(I11<>"",I11<E11),"Plano antes da auditoria",IF(AND(F11="NC maior",K11<>"",J11=""),"Falta a conclusão da ação","OK")))))))
B12: 6 | L12: =IF(OR(E12="",AND(F12<>"NC maior",F12<>"NC menor")),"",E12+30) | M12: =IF(OR(E12="",F12<>"NC maior"),"",E12+90) | N12: =IF(OR(F12="",E12=""),"",IF(OR(F12="Oportunidade de melhoria",F12="Ponto de atenção da fase 1"),IF(K12<>"","Fechada",IF(F12="Ponto de atenção da fase 1","Tratar antes da fase 2","Para considerar")),IF(K12<>"","Fechada",IF(AND(I12="",N(Ciclo!$D$7)>L12),"Plano atrasado",IF(AND(F12="NC maior",N(Ciclo!$D$7)>M12),"Vencida: risco ao certificado",IF(AND(F12="NC menor",I12<>""),"Aguarda verificação","Aberta no prazo")))))) | O12: =IF(AND(C12="",COUNTA(D12:K12)=0),"",IF(E12="","Falta a data da auditoria",IF(F12="","Falta o tipo",IF(G12="","Falta o requisito",IF(H12="","Falta a descrição",IF(AND(I12<>"",I12<E12),"Plano antes da auditoria",IF(AND(F12="NC maior",K12<>"",J12=""),"Falta a conclusão da ação","OK")))))))
B13: 7 | L13: =IF(OR(E13="",AND(F13<>"NC maior",F13<>"NC menor")),"",E13+30) | M13: =IF(OR(E13="",F13<>"NC maior"),"",E13+90) | N13: =IF(OR(F13="",E13=""),"",IF(OR(F13="Oportunidade de melhoria",F13="Ponto de atenção da fase 1"),IF(K13<>"","Fechada",IF(F13="Ponto de atenção da fase 1","Tratar antes da fase 2","Para considerar")),IF(K13<>"","Fechada",IF(AND(I13="",N(Ciclo!$D$7)>L13),"Plano atrasado",IF(AND(F13="NC maior",N(Ciclo!$D$7)>M13),"Vencida: risco ao certificado",IF(AND(F13="NC menor",I13<>""),"Aguarda verificação","Aberta no prazo")))))) | O13: =IF(AND(C13="",COUNTA(D13:K13)=0),"",IF(E13="","Falta a data da auditoria",IF(F13="","Falta o tipo",IF(G13="","Falta o requisito",IF(H13="","Falta a descrição",IF(AND(I13<>"",I13<E13),"Plano antes da auditoria",IF(AND(F13="NC maior",K13<>"",J13=""),"Falta a conclusão da ação","OK")))))))
B14: 8 | L14: =IF(OR(E14="",AND(F14<>"NC maior",F14<>"NC menor")),"",E14+30) | M14: =IF(OR(E14="",F14<>"NC maior"),"",E14+90) | N14: =IF(OR(F14="",E14=""),"",IF(OR(F14="Oportunidade de melhoria",F14="Ponto de atenção da fase 1"),IF(K14<>"","Fechada",IF(F14="Ponto de atenção da fase 1","Tratar antes da fase 2","Para considerar")),IF(K14<>"","Fechada",IF(AND(I14="",N(Ciclo!$D$7)>L14),"Plano atrasado",IF(AND(F14="NC maior",N(Ciclo!$D$7)>M14),"Vencida: risco ao certificado",IF(AND(F14="NC menor",I14<>""),"Aguarda verificação","Aberta no prazo")))))) | O14: =IF(AND(C14="",COUNTA(D14:K14)=0),"",IF(E14="","Falta a data da auditoria",IF(F14="","Falta o tipo",IF(G14="","Falta o requisito",IF(H14="","Falta a descrição",IF(AND(I14<>"",I14<E14),"Plano antes da auditoria",IF(AND(F14="NC maior",K14<>"",J14=""),"Falta a conclusão da ação","OK")))))))
B15: 9 | L15: =IF(OR(E15="",AND(F15<>"NC maior",F15<>"NC menor")),"",E15+30) | M15: =IF(OR(E15="",F15<>"NC maior"),"",E15+90) | N15: =IF(OR(F15="",E15=""),"",IF(OR(F15="Oportunidade de melhoria",F15="Ponto de atenção da fase 1"),IF(K15<>"","Fechada",IF(F15="Ponto de atenção da fase 1","Tratar antes da fase 2","Para considerar")),IF(K15<>"","Fechada",IF(AND(I15="",N(Ciclo!$D$7)>L15),"Plano atrasado",IF(AND(F15="NC maior",N(Ciclo!$D$7)>M15),"Vencida: risco ao certificado",IF(AND(F15="NC menor",I15<>""),"Aguarda verificação","Aberta no prazo")))))) | O15: =IF(AND(C15="",COUNTA(D15:K15)=0),"",IF(E15="","Falta a data da auditoria",IF(F15="","Falta o tipo",IF(G15="","Falta o requisito",IF(H15="","Falta a descrição",IF(AND(I15<>"",I15<E15),"Plano antes da auditoria",IF(AND(F15="NC maior",K15<>"",J15=""),"Falta a conclusão da ação","OK")))))))
B16: 10 | L16: =IF(OR(E16="",AND(F16<>"NC maior",F16<>"NC menor")),"",E16+30) | M16: =IF(OR(E16="",F16<>"NC maior"),"",E16+90) | N16: =IF(OR(F16="",E16=""),"",IF(OR(F16="Oportunidade de melhoria",F16="Ponto de atenção da fase 1"),IF(K16<>"","Fechada",IF(F16="Ponto de atenção da fase 1","Tratar antes da fase 2","Para considerar")),IF(K16<>"","Fechada",IF(AND(I16="",N(Ciclo!$D$7)>L16),"Plano atrasado",IF(AND(F16="NC maior",N(Ciclo!$D$7)>M16),"Vencida: risco ao certificado",IF(AND(F16="NC menor",I16<>""),"Aguarda verificação","Aberta no prazo")))))) | O16: =IF(AND(C16="",COUNTA(D16:K16)=0),"",IF(E16="","Falta a data da auditoria",IF(F16="","Falta o tipo",IF(G16="","Falta o requisito",IF(H16="","Falta a descrição",IF(AND(I16<>"",I16<E16),"Plano antes da auditoria",IF(AND(F16="NC maior",K16<>"",J16=""),"Falta a conclusão da ação","OK")))))))
B17: 11 | L17: =IF(OR(E17="",AND(F17<>"NC maior",F17<>"NC menor")),"",E17+30) | M17: =IF(OR(E17="",F17<>"NC maior"),"",E17+90) | N17: =IF(OR(F17="",E17=""),"",IF(OR(F17="Oportunidade de melhoria",F17="Ponto de atenção da fase 1"),IF(K17<>"","Fechada",IF(F17="Ponto de atenção da fase 1","Tratar antes da fase 2","Para considerar")),IF(K17<>"","Fechada",IF(AND(I17="",N(Ciclo!$D$7)>L17),"Plano atrasado",IF(AND(F17="NC maior",N(Ciclo!$D$7)>M17),"Vencida: risco ao certificado",IF(AND(F17="NC menor",I17<>""),"Aguarda verificação","Aberta no prazo")))))) | O17: =IF(AND(C17="",COUNTA(D17:K17)=0),"",IF(E17="","Falta a data da auditoria",IF(F17="","Falta o tipo",IF(G17="","Falta o requisito",IF(H17="","Falta a descrição",IF(AND(I17<>"",I17<E17),"Plano antes da auditoria",IF(AND(F17="NC maior",K17<>"",J17=""),"Falta a conclusão da ação","OK")))))))
B18: 12 | L18: =IF(OR(E18="",AND(F18<>"NC maior",F18<>"NC menor")),"",E18+30) | M18: =IF(OR(E18="",F18<>"NC maior"),"",E18+90) | N18: =IF(OR(F18="",E18=""),"",IF(OR(F18="Oportunidade de melhoria",F18="Ponto de atenção da fase 1"),IF(K18<>"","Fechada",IF(F18="Ponto de atenção da fase 1","Tratar antes da fase 2","Para considerar")),IF(K18<>"","Fechada",IF(AND(I18="",N(Ciclo!$D$7)>L18),"Plano atrasado",IF(AND(F18="NC maior",N(Ciclo!$D$7)>M18),"Vencida: risco ao certificado",IF(AND(F18="NC menor",I18<>""),"Aguarda verificação","Aberta no prazo")))))) | O18: =IF(AND(C18="",COUNTA(D18:K18)=0),"",IF(E18="","Falta a data da auditoria",IF(F18="","Falta o tipo",IF(G18="","Falta o requisito",IF(H18="","Falta a descrição",IF(AND(I18<>"",I18<E18),"Plano antes da auditoria",IF(AND(F18="NC maior",K18<>"",J18=""),"Falta a conclusão da ação","OK")))))))
... B46: 40 | L46: =IF(OR(E46="",AND(F46<>"NC maior",F46<>"NC menor")),"",E46+30) | M46: =IF(OR(E46="",F46<>"NC maior"),"",E46+90) | N46: =IF(OR(F46="",E46=""),"",IF(OR(F46="Oportunidade de melhoria",F46="Ponto de atenção da fase 1"),IF(K46<>"","Fechada",IF(F46="Ponto de atenção da fase 1","Tratar antes da fase 2","Para considerar")),IF(K46<>"","Fechada",IF(AND(I46="",N(Ciclo!$D$7)>L46),"Plano atrasado",IF(AND(F46="NC maior",N(Ciclo!$D$7)>M46),"Vencida: risco ao certificado",IF(AND(F46="NC menor",I46<>""),"Aguarda verificação","Aberta no prazo")))))) | O46: =IF(AND(C46="",COUNTA(D46:K46)=0),"",IF(E46="","Falta a data da auditoria",IF(F46="","Falta o tipo",IF(G46="","Falta o requisito",IF(H46="","Falta a descrição",IF(AND(I46<>"",I46<E46),"Plano antes da auditoria",IF(AND(F46="NC maior",K46<>"",J46=""),"Falta a conclusão da ação","OK")))))))
B48: Resumo automático
B49: Constatações | E49: =COUNTA(F7:F46)&" constatações: "&COUNTIF(F7:F46,"NC maior")&" nc maior"&", "&COUNTIF(F7:F46,"NC menor")&" nc menor"&", "&COUNTIF(F7:F46,"Oportunidade de melhoria")&" oportunidade de melhoria"&", "&COUNTIF(F7:F46,"Ponto de atenção da fase 1")&" ponto de atenção da fase 1" -> 0 constatações: 0 nc maior, 0 nc menor, 0 oportunidade de melhoria, 0 ponto de atenção da fase 1
B50: Situação | E50: =COUNTIF(N7:N46,"Fechada")&" fechada"&", "&COUNTIF(N7:N46,"Aguarda verificação")&" aguarda verificação"&", "&COUNTIF(N7:N46,"Aberta no prazo")&" aberta no prazo"&", "&COUNTIF(N7:N46,"Plano atrasado")&" plano atrasado"&", "&COUNTIF(N7:N46,"Vencida: risco ao certificado")&" vencida: risco ao certificado" -> 0 fechada, 0 aguarda verificação, 0 aberta no prazo, 0 plano atrasado, 0 vencida: risco ao certificado
B51: Aviso | E51: =IF(COUNTA(F7:F46)=0,"Registre as constatações depois de cada auditoria",IF(COUNTIF(N7:N46,"Vencida: risco ao certificado")>0,"Há NC maior vencida: o certificado está em risco",IF(COUNTIF(N7:N46,"Plano atrasado")>0,"Há plano atrasado: envie ao organismo",IF(SUMPRODUCT((O7:O46<>"")*(O7:O46<>"OK"))>0,"Há constatação a completar: veja a coluna Conferência","OK")))) -> Registre as constatações depois de cada auditoria

Sheet Painel
B1: Painel da certificação
B2: Nada a preencher: tudo vem das outras abas.
B3: Organismo | C3: =IF(Ciclo!D4="","",Ciclo!D4)
B5: Indicador | C5: Resultado | D5: Como se lê
B6: PRONTIDÃO
B7: Data da avaliação | C7: =IF(Prontidão!D4="","",Prontidão!D4) | D7: Da aba Prontidão.
B8: Percentual atendido | C8: =IF(COUNTA(Prontidão!F7:F20)=0,"",SUM(Prontidão!K7:K20)/ROWS(Prontidão!K7:K20)) | D8: Sim vale 1, Parcial 0,5.
B9: Impeditivos antes da fase 1 | C9: =SUMPRODUCT((Prontidão!D7:D20="Fase 1")*(Prontidão!E7:E20="Sim")*(Prontidão!F7:F20<>"Sim")) -> 4 | D9: Precisam estar em Sim antes da fase 1.
B10: Impeditivos antes da fase 2 | C10: =SUMPRODUCT((Prontidão!D7:D20="Fase 2")*(Prontidão!E7:E20="Sim")*(Prontidão!F7:F20<>"Sim")) -> 4 | D10: Precisam estar em Sim antes da fase 2.
B11: Resultado | C11: =IF(COUNTA(Prontidão!F7:F20)=0,"",IF(SUMPRODUCT((Prontidão!D7:D20="Fase 1")*(Prontidão!E7:E20="Sim")*(Prontidão!F7:F20<>"Sim"))>0,"Ainda não está pronta",IF(SUMPRODUCT((Prontidão!D7:D20="Fase 2")*(Prontidão!E7:E20="Sim")*(Prontidão!F7:F20<>"Sim"))>0,"Pronta para a fase 1","Pronta para a fase 2"))) | D11: Pronta para a fase 2, para a fase 1, ou ainda não.
B12: CICLO
B13: Edição | C13: =IF(Ciclo!D5="","",Ciclo!D5) | D13: Do certificado.
B14: Validade | C14: =IF(Ciclo!D9="","",Ciclo!D9) | D14: Decisão mais três anos, menos um dia.
B15: Próximo limite | C15: =IF(MIN(Ciclo!H13:H19)=0,"",MIN(Ciclo!H13:H19)) | D15: O limite mais próximo de um evento ainda não feito.
B16: Próximo evento | C16: =IF(C15="","",IFERROR(INDEX(Ciclo!C13:C19,MATCH(C15,Ciclo!H13:H19,0)),"")) | D16: O evento desse limite.
B17: Eventos atrasados | C17: =COUNTIF(Ciclo!F13:F19,"Atrasada") -> 0 | D17: Falar com o organismo.
B18: Eventos que vencem em 60 dias | C18: =COUNTIF(Ciclo!F13:F19,"Vence em 60 dias") -> 0 | D18: Confirmar a data.
B19: CONSTATAÇÕES
B20: Constatações | C20: =COUNTA(Constatações!F7:F46) -> 0 | D20: Da aba Constatações.
B21: NC maiores | C21: =COUNTIF(Constatações!F7:F46,"NC maior") -> 0 | D21: Precisam fechar antes da decisão.
B22: NC maiores abertas | C22: =SUMPRODUCT((Constatações!F7:F46="NC maior")*(Constatações!N7:N46<>"Fechada")) -> 0 | D22: Sem evidência aceita.
B23: Planos atrasados | C23: =COUNTIF(Constatações!N7:N46,"Plano atrasado") -> 0 | D23: Enviar ao organismo.
B24: NC maiores vencidas | C24: =COUNTIF(Constatações!N7:N46,"Vencida: risco ao certificado") -> 0 | D24: Risco ao certificado.
B25: Aguardando verificação | C25: =COUNTIF(Constatações!N7:N46,"Aguarda verificação") -> 0 | D25: Menores a verificar na próxima auditoria.
B26: Linhas a completar | C26: =SUMPRODUCT((Prontidão!L7:L20<>"")*(Prontidão!L7:L20<>"OK"))+SUMPRODUCT((Constatações!O7:O46<>"")*(Constatações!O7:O46<>"OK")) -> 14 | D26: Conferências diferentes de OK.
B28: Resumo automático
B29: Aviso | C29: =IF(AND(COUNTA(Prontidão!F7:F20)=0,Ciclo!D6="",C20=0),"Preencha as abas Prontidão, Ciclo e Constatações",IF(C24>0,"Há NC maior vencida: o certificado está em risco",IF(C23>0,"Há plano atrasado: envie ao organismo",IF(C17>0,"Há evento do ciclo atrasado",IF(N(C9)+N(C10)>0,"Há impeditivo pendente na prontidão",IF(C18>0,"Há evento que vence em 60 dias",IF(C22>0,"Há NC maior aberta: feche antes da decisão",IF(C26>0,"Há linha a completar: veja as conferências","OK")))))))) -> Preencha as abas Prontidão, Ciclo e Constatações
B31: Constatações por tipo
B32: NC maior | C32: =COUNTIF(Constatações!F7:F46,B32) -> 0
B33: NC menor | C33: =COUNTIF(Constatações!F7:F46,B33) -> 0
B34: Oportunidade de melhoria | C34: =COUNTIF(Constatações!F7:F46,B34) -> 0
B35: Ponto de atenção da fase 1 | C35: =COUNTIF(Constatações!F7:F46,B35) -> 0

Sheet Checklist
B1: Checklist da certificação
B2: Escolha o status de cada item na lista suspensa (coluna em amarelo-claro).
B4: # | C4: Item de verificação | D4: Status | E4: Observações
B5: 1 | C5: O escopo da certificação está definido e é o mesmo do sistema.
B6: 2 | C6: O organismo escolhido é acreditado para o escopo, e o regulamento foi lido.
B7: 3 | C7: O sistema funciona há meses, com indicadores, auditoria interna completa e análise crítica.
B8: 4 | C8: As constatações da fase 1 foram tratadas antes da fase 2.
B9: 5 | C9: Quem será entrevistado sabe explicar o próprio trabalho e a política.
B10: 6 | C10: Os registros pedidos pela norma estão acessíveis no dia da auditoria.
B11: 7 | C11: Os planos de ação são enviados dentro do prazo do organismo.
B12: 8 | C12: As não conformidades maiores são fechadas, com evidência, antes da decisão.
B13: 9 | C13: As datas das manutenções e da recertificação estão no calendário do sistema.
B14: 10 | C14: O uso da marca de certificação segue as regras do organismo.
B15: 11 | C15: Mudanças importantes, como escopo, endereço ou porte, são comunicadas ao organismo.
B16: 12 | C16: A transição para a nova edição da norma está planejada antes do fim do prazo.
B18: Resumo automático
B19: Itens atendidos (Sim) | D19: =COUNTIF(D5:D16,"Sim") -> 0
B20: Itens parciais | D20: =COUNTIF(D5:D16,"Parcial") -> 0
B21: Itens não atendidos | D21: =COUNTIF(D5:D16,"Não") -> 0
B22: Itens sem resposta | D22: =COUNTBLANK(D5:D16) -> 12
B23: Percentual atendido | D23: =D19/ROWS(D5:D16) -> 0
B24: Situação | D24: =IF(D19=ROWS(D5:D16),"Validado",IF(D22>0,"Em andamento","Com pendências")) -> Em andamento

Sheet Exemplo 1 - Pizzaria
B1: Processo de certificação
B2: Exemplo preenchido, para consulta. Use as abas Prontidão, Ciclo e Constatações para a sua organização.
B4: Organização | D4: Pizzaria (loja com salão e delivery)
B5: Escopo | D5: Produção e venda de pizzas no salão, para retirada e por entrega, na loja do bairro.
B6: Organismo | D6: Organismo acreditado pela Cgcre, escolhido em dezembro de 2027
B7: Por que certificar | D7: Decisão da análise crítica de 14/06/2027: certificar para atender contratos de refeições de empresas.
B8: Data da avaliação de prontidão | D8: 46721
B9: Edição da norma | D9: ISO 9001:2026
B10: Data da decisão | D10: 46868
B11: Data da leitura do ciclo | D11: 46904
B12: Fim da transição | D12: 47391
B13: Validade do certificado | D13: =IF($D$10="","",EDATE($D$10,36)-1) -> 47962
B15: Prontidão
B16: # | C16: Critério | D16: Antes da | E16: Impeditivo | F16: Status | G16: Evidência | H16: Ação | I16: Responsável | J16: Prazo | K16: Pontos | L16: Conferência
B17: 1 | C17: O escopo está definido, com a justificativa do que não se aplica. | D17: Fase 1 | E17: Sim | F17: Sim | G17: Escopo de fevereiro de 2027, revisado em novembro | K17: =IF(F17="","",IF(F17="Sim",1,IF(F17="Parcial",0.5,0))) -> 1 | L17: =IF(F17="","Falta o status",IF(AND(F17<>"Sim",H17=""),"Falta a ação",IF(AND(F17<>"Sim",J17=""),"Falta o prazo",IF(AND(F17="Sim",G17=""),"Falta a evidência","OK")))) -> OK
B18: 2 | C18: A política e os objetivos da qualidade estão aprovados e comunicados. | D18: Fase 1 | E18: Sim | F18: Sim | G18: Política no salão; objetivos de 2027 no quadro da cozinha | K18: =IF(F18="","",IF(F18="Sim",1,IF(F18="Parcial",0.5,0))) -> 1 | L18: =IF(F18="","Falta o status",IF(AND(F18<>"Sim",H18=""),"Falta a ação",IF(AND(F18<>"Sim",J18=""),"Falta o prazo",IF(AND(F18="Sim",G18=""),"Falta a evidência","OK")))) -> OK
B19: 3 | C19: Os processos estão determinados, com a sequência e a interação entre eles. | D19: Fase 1 | E19: Sim | F19: Sim | G19: Mapa de processos e SIPOC dos quatro processos | K19: =IF(F19="","",IF(F19="Sim",1,IF(F19="Parcial",0.5,0))) -> 1 | L19: =IF(F19="","Falta o status",IF(AND(F19<>"Sim",H19=""),"Falta a ação",IF(AND(F19<>"Sim",J19=""),"Falta o prazo",IF(AND(F19="Sim",G19=""),"Falta a evidência","OK")))) -> OK
B20: 4 | C20: A informação documentada exigida existe e está sob controle. | D20: Fase 1 | E20: Sim | F20: Parcial | G20: Lista mestra em dia | H20: Recolher a instrução do salão na revisão 1, ainda em uso no balcão. | I20: Gerente da loja | J20: 46731 | K20: =IF(F20="","",IF(F20="Sim",1,IF(F20="Parcial",0.5,0))) -> 0.5 | L20: =IF(F20="","Falta o status",IF(AND(F20<>"Sim",H20=""),"Falta a ação",IF(AND(F20<>"Sim",J20=""),"Falta o prazo",IF(AND(F20="Sim",G20=""),"Falta a evidência","OK")))) -> OK
B21: 5 | C21: O organismo de certificação está escolhido, acreditado para o escopo. | D21: Fase 1 | E21: — | F21: Não | H21: Escolher entre as três propostas pedidas em outubro. | I21: Dono da loja | J21: 46736 | K21: =IF(F21="","",IF(F21="Sim",1,IF(F21="Parcial",0.5,0))) -> 0 | L21: =IF(F21="","Falta o status",IF(AND(F21<>"Sim",H21=""),"Falta a ação",IF(AND(F21<>"Sim",J21=""),"Falta o prazo",IF(AND(F21="Sim",G21=""),"Falta a evidência","OK")))) -> OK
B22: 6 | C22: O sistema funciona há pelo menos três meses, com registros. | D22: Fase 2 | E22: Sim | F22: Sim | G22: Registros desde janeiro de 2027 | K22: =IF(F22="","",IF(F22="Sim",1,IF(F22="Parcial",0.5,0))) -> 1 | L22: =IF(F22="","Falta o status",IF(AND(F22<>"Sim",H22=""),"Falta a ação",IF(AND(F22<>"Sim",J22=""),"Falta o prazo",IF(AND(F22="Sim",G22=""),"Falta a evidência","OK")))) -> OK
B23: 7 | C23: Há um ciclo completo de auditoria interna, cobrindo todos os processos. | D23: Fase 2 | E23: Sim | F23: Parcial | G23: Delivery, salão e recebimento auditados | H23: Auditar a produção e as compras em janeiro. | I23: Atendente do turno do almoço | J23: 46783 | K23: =IF(F23="","",IF(F23="Sim",1,IF(F23="Parcial",0.5,0))) -> 0.5 | L23: =IF(F23="","Falta o status",IF(AND(F23<>"Sim",H23=""),"Falta a ação",IF(AND(F23<>"Sim",J23=""),"Falta o prazo",IF(AND(F23="Sim",G23=""),"Falta a evidência","OK")))) -> OK
B24: 8 | C24: Houve ao menos uma análise crítica pela direção, com todas as entradas. | D24: Fase 2 | E24: Sim | F24: Sim | G24: Atas de 14/12/2026 e de 14/06/2027 | K24: =IF(F24="","",IF(F24="Sim",1,IF(F24="Parcial",0.5,0))) -> 1 | L24: =IF(F24="","Falta o status",IF(AND(F24<>"Sim",H24=""),"Falta a ação",IF(AND(F24<>"Sim",J24=""),"Falta o prazo",IF(AND(F24="Sim",G24=""),"Falta a evidência","OK")))) -> OK
B25: 9 | C25: As não conformidades da auditoria interna têm ação definida. | D25: Fase 2 | E25: Sim | F25: Sim | G25: Ações das auditorias de 2026 e de março de 2027 | K25: =IF(F25="","",IF(F25="Sim",1,IF(F25="Parcial",0.5,0))) -> 1 | L25: =IF(F25="","Falta o status",IF(AND(F25<>"Sim",H25=""),"Falta a ação",IF(AND(F25<>"Sim",J25=""),"Falta o prazo",IF(AND(F25="Sim",G25=""),"Falta a evidência","OK")))) -> OK
B26: 10 | C26: Os indicadores têm série de pelo menos três meses. | D26: Fase 2 | E26: — | F26: Sim | G26: Painel com 12 meses de entregas no prazo e de reclamações | K26: =IF(F26="","",IF(F26="Sim",1,IF(F26="Parcial",0.5,0))) -> 1 | L26: =IF(F26="","Falta o status",IF(AND(F26<>"Sim",H26=""),"Falta a ação",IF(AND(F26<>"Sim",J26=""),"Falta o prazo",IF(AND(F26="Sim",G26=""),"Falta a evidência","OK")))) -> OK
B27: 11 | C27: As pessoas sabem explicar a política e o próprio papel no sistema. | D27: Fase 2 | E27: — | F27: Parcial | G27: Perguntas de conscientização feitas a 6 pessoas | H27: Repetir a conversa da política com a equipe nova do salão. | I27: Gerente da loja | J27: 46767 | K27: =IF(F27="","",IF(F27="Sim",1,IF(F27="Parcial",0.5,0))) -> 0.5 | L27: =IF(F27="","Falta o status",IF(AND(F27<>"Sim",H27=""),"Falta a ação",IF(AND(F27<>"Sim",J27=""),"Falta o prazo",IF(AND(F27="Sim",G27=""),"Falta a evidência","OK")))) -> OK
B28: 12 | C28: Os requisitos legais do produto estão identificados e atendidos. | D28: Fase 2 | E28: — | F28: Sim | G28: Licença sanitária renovada; rotulagem de alergênicos | K28: =IF(F28="","",IF(F28="Sim",1,IF(F28="Parcial",0.5,0))) -> 1 | L28: =IF(F28="","Falta o status",IF(AND(F28<>"Sim",H28=""),"Falta a ação",IF(AND(F28<>"Sim",J28=""),"Falta o prazo",IF(AND(F28="Sim",G28=""),"Falta a evidência","OK")))) -> OK
B29: 13 | C29: A calibração e a manutenção dos itens críticos estão em dia. | D29: Fase 2 | E29: — | F29: Parcial | G29: Balança e termômetros em dia | H29: Fazer a revisão da câmara fria, atrasada desde outubro. | I29: Pizzaiolo líder | J29: 46731 | K29: =IF(F29="","",IF(F29="Sim",1,IF(F29="Parcial",0.5,0))) -> 0.5 | L29: =IF(F29="","Falta o status",IF(AND(F29<>"Sim",H29=""),"Falta a ação",IF(AND(F29<>"Sim",J29=""),"Falta o prazo",IF(AND(F29="Sim",G29=""),"Falta a evidência","OK")))) -> OK
B30: 14 | C30: As reclamações e a satisfação do cliente são registradas e analisadas. | D30: Fase 2 | E30: — | F30: Sim | G30: Registro de reclamações e pesquisa trimestral | K30: =IF(F30="","",IF(F30="Sim",1,IF(F30="Parcial",0.5,0))) -> 1 | L30: =IF(F30="","Falta o status",IF(AND(F30<>"Sim",H30=""),"Falta a ação",IF(AND(F30<>"Sim",J30=""),"Falta o prazo",IF(AND(F30="Sim",G30=""),"Falta a evidência","OK")))) -> OK
B31: Percentual atendido | D31: =IF(COUNTA(F17:F30)=0,"",SUM(K17:K30)/ROWS(K17:K30)) -> 0.78571429
B32: Impeditivos antes da fase 1 | D32: =SUMPRODUCT((D17:D30="Fase 1")*(E17:E30="Sim")*(F17:F30<>"Sim")) -> 1
B33: Impeditivos antes da fase 2 | D33: =SUMPRODUCT((D17:D30="Fase 2")*(E17:E30="Sim")*(F17:F30<>"Sim")) -> 1
B34: Resultado | D34: =IF(COUNTA(F17:F30)=0,"",IF(SUMPRODUCT((D17:D30="Fase 1")*(E17:E30="Sim")*(F17:F30<>"Sim"))>0,"Ainda não está pronta",IF(SUMPRODUCT((D17:D30="Fase 2")*(E17:E30="Sim")*(F17:F30<>"Sim"))>0,"Pronta para a fase 1","Pronta para a fase 2"))) -> Ainda não está pronta
B36: Ciclo do certificado
B37: # | C37: Evento | D37: Limite | E37: Realizado em | F37: Situação
B38: 1 | C38: Fase 1 | D38: ="" | E38: 46798 | F38: =IF(E38="","Prevista","Realizada") -> Realizada
B39: 2 | C39: Fase 2 | D39: =IF(E38="","",EDATE(E38,6)) -> 46980 | E39: 46833 | F39: =IF(D39="","",IF(E39<>"",IF(E39<=D39,"No prazo","Fora do prazo"),IF(N($D$11)=0,"",IF($D$11>D39,"Atrasada",IF(D39-$D$11<=60,"Vence em 60 dias","Prevista"))))) -> No prazo
B40: 3 | C40: Decisão de certificação | D40: ="" | E40: =IF($D$10="","",$D$10) -> 46868 | F40: =IF(E40="","Prevista","Realizada") -> Realizada
B41: 4 | C41: 1ª manutenção | D41: =IF($D$10="","",EDATE($D$10,12)) -> 47233 | F41: =IF(D41="","",IF(E41<>"",IF(E41<=D41,"No prazo","Fora do prazo"),IF(N($D$11)=0,"",IF($D$11>D41,"Atrasada",IF(D41-$D$11<=60,"Vence em 60 dias","Prevista"))))) -> Prevista
B42: 5 | C42: 2ª manutenção | D42: =IF($D$10="","",EDATE($D$10,24)) -> 47598 | F42: =IF(D42="","",IF(E42<>"",IF(E42<=D42,"No prazo","Fora do prazo"),IF(N($D$11)=0,"",IF($D$11>D42,"Atrasada",IF(D42-$D$11<=60,"Vence em 60 dias","Prevista"))))) -> Prevista
B43: 6 | C43: Auditoria de recertificação | D43: =IF($D$10="","",EDATE($D$10,33)) -> 47873 | F43: =IF(D43="","",IF(E43<>"",IF(E43<=D43,"No prazo","Fora do prazo"),IF(N($D$11)=0,"",IF($D$11>D43,"Atrasada",IF(D43-$D$11<=60,"Vence em 60 dias","Prevista"))))) -> Prevista
...

Sheet Exemplo 2 - Indústria
B1: Processo de certificação
B2: Exemplo preenchido, para consulta. Use as abas Prontidão, Ciclo e Constatações para a sua organização.
B4: Organização | D4: Indústria de embalagens plásticas
B5: Escopo | D5: Desenvolvimento e produção de filmes técnicos lisos e impressos para embalagem de alimentos.
B6: Organismo | D6: Organismo acreditado pela Cgcre, contratado em 23/04/2027 por R$ 38.000
B7: Por que certificar | D7: Objetivo O4: certificação até dezembro de 2027. Dois grandes clientes passam a exigir o certificado.
B8: Data da avaliação de prontidão | D8: 46660
B9: Edição da norma | D9: ISO 9001:2015
B10: Data da decisão | D10: 46738
B11: Data da leitura do ciclo | D11: 46767
B12: Fim da transição | D12: 47391
B13: Validade do certificado | D13: =IF($D$10="","",EDATE($D$10,36)-1) -> 47833
B15: Prontidão
B16: # | C16: Critério | D16: Antes da | E16: Impeditivo | F16: Status | G16: Evidência | H16: Ação | I16: Responsável | J16: Prazo | K16: Pontos | L16: Conferência
B17: 1 | C17: O escopo está definido, com a justificativa do que não se aplica. | D17: Fase 1 | E17: Sim | F17: Sim | G17: Escopo revisado em maio de 2027 | K17: =IF(F17="","",IF(F17="Sim",1,IF(F17="Parcial",0.5,0))) -> 1 | L17: =IF(F17="","Falta o status",IF(AND(F17<>"Sim",H17=""),"Falta a ação",IF(AND(F17<>"Sim",J17=""),"Falta o prazo",IF(AND(F17="Sim",G17=""),"Falta a evidência","OK")))) -> OK
B18: 2 | C18: A política e os objetivos da qualidade estão aprovados e comunicados. | D18: Fase 1 | E18: Sim | F18: Sim | G18: Política e objetivos de 2027, com o O4 | K18: =IF(F18="","",IF(F18="Sim",1,IF(F18="Parcial",0.5,0))) -> 1 | L18: =IF(F18="","Falta o status",IF(AND(F18<>"Sim",H18=""),"Falta a ação",IF(AND(F18<>"Sim",J18=""),"Falta o prazo",IF(AND(F18="Sim",G18=""),"Falta a evidência","OK")))) -> OK
B19: 3 | C19: Os processos estão determinados, com a sequência e a interação entre eles. | D19: Fase 1 | E19: Sim | F19: Sim | G19: Mapa dos nove processos, com tartarugas | K19: =IF(F19="","",IF(F19="Sim",1,IF(F19="Parcial",0.5,0))) -> 1 | L19: =IF(F19="","Falta o status",IF(AND(F19<>"Sim",H19=""),"Falta a ação",IF(AND(F19<>"Sim",J19=""),"Falta o prazo",IF(AND(F19="Sim",G19=""),"Falta a evidência","OK")))) -> OK
B20: 4 | C20: A informação documentada exigida existe e está sob controle. | D20: Fase 1 | E20: Sim | F20: Sim | G20: Lista mestra e tabela de retenção de março de 2027 | K20: =IF(F20="","",IF(F20="Sim",1,IF(F20="Parcial",0.5,0))) -> 1 | L20: =IF(F20="","Falta o status",IF(AND(F20<>"Sim",H20=""),"Falta a ação",IF(AND(F20<>"Sim",J20=""),"Falta o prazo",IF(AND(F20="Sim",G20=""),"Falta a evidência","OK")))) -> OK
B21: 5 | C21: O organismo de certificação está escolhido, acreditado para o escopo. | D21: Fase 1 | E21: — | F21: Sim | G21: Contrato de 23/04/2027 | K21: =IF(F21="","",IF(F21="Sim",1,IF(F21="Parcial",0.5,0))) -> 1 | L21: =IF(F21="","Falta o status",IF(AND(F21<>"Sim",H21=""),"Falta a ação",IF(AND(F21<>"Sim",J21=""),"Falta o prazo",IF(AND(F21="Sim",G21=""),"Falta a evidência","OK")))) -> OK
B22: 6 | C22: O sistema funciona há pelo menos três meses, com registros. | D22: Fase 2 | E22: Sim | F22: Sim | G22: Indicadores desde 2025 | K22: =IF(F22="","",IF(F22="Sim",1,IF(F22="Parcial",0.5,0))) -> 1 | L22: =IF(F22="","Falta o status",IF(AND(F22<>"Sim",H22=""),"Falta a ação",IF(AND(F22<>"Sim",J22=""),"Falta o prazo",IF(AND(F22="Sim",G22=""),"Falta a evidência","OK")))) -> OK
B23: 7 | C23: Há um ciclo completo de auditoria interna, cobrindo todos os processos. | D23: Fase 2 | E23: Sim | F23: Parcial | G23: Sete dos nove processos auditados | H23: Auditar a manutenção e a gestão de pessoas em outubro. | I23: Coordenador da Qualidade | J23: 46691 | K23: =IF(F23="","",IF(F23="Sim",1,IF(F23="Parcial",0.5,0))) -> 0.5 | L23: =IF(F23="","Falta o status",IF(AND(F23<>"Sim",H23=""),"Falta a ação",IF(AND(F23<>"Sim",J23=""),"Falta o prazo",IF(AND(F23="Sim",G23=""),"Falta a evidência","OK")))) -> OK
B24: 8 | C24: Houve ao menos uma análise crítica pela direção, com todas as entradas. | D24: Fase 2 | E24: Sim | F24: Sim | G24: Ata de 19/08/2027 | K24: =IF(F24="","",IF(F24="Sim",1,IF(F24="Parcial",0.5,0))) -> 1 | L24: =IF(F24="","Falta o status",IF(AND(F24<>"Sim",H24=""),"Falta a ação",IF(AND(F24<>"Sim",J24=""),"Falta o prazo",IF(AND(F24="Sim",G24=""),"Falta a evidência","OK")))) -> OK
B25: 9 | C25: As não conformidades da auditoria interna têm ação definida. | D25: Fase 2 | E25: Sim | F25: Sim | G25: Ações das auditorias de 2027 definidas | K25: =IF(F25="","",IF(F25="Sim",1,IF(F25="Parcial",0.5,0))) -> 1 | L25: =IF(F25="","Falta o status",IF(AND(F25<>"Sim",H25=""),"Falta a ação",IF(AND(F25<>"Sim",J25=""),"Falta o prazo",IF(AND(F25="Sim",G25=""),"Falta a evidência","OK")))) -> OK
B26: 10 | C26: Os indicadores têm série de pelo menos três meses. | D26: Fase 2 | E26: — | F26: Sim | G26: Painel de indicadores por processo | K26: =IF(F26="","",IF(F26="Sim",1,IF(F26="Parcial",0.5,0))) -> 1 | L26: =IF(F26="","Falta o status",IF(AND(F26<>"Sim",H26=""),"Falta a ação",IF(AND(F26<>"Sim",J26=""),"Falta o prazo",IF(AND(F26="Sim",G26=""),"Falta a evidência","OK")))) -> OK
B27: 11 | C27: As pessoas sabem explicar a política e o próprio papel no sistema. | D27: Fase 2 | E27: — | F27: Sim | G27: Entrevistas de conscientização em julho | K27: =IF(F27="","",IF(F27="Sim",1,IF(F27="Parcial",0.5,0))) -> 1 | L27: =IF(F27="","Falta o status",IF(AND(F27<>"Sim",H27=""),"Falta a ação",IF(AND(F27<>"Sim",J27=""),"Falta o prazo",IF(AND(F27="Sim",G27=""),"Falta a evidência","OK")))) -> OK
B28: 12 | C28: Os requisitos legais do produto estão identificados e atendidos. | D28: Fase 2 | E28: — | F28: Sim | G28: Laudos de migração do filme para alimentos | K28: =IF(F28="","",IF(F28="Sim",1,IF(F28="Parcial",0.5,0))) -> 1 | L28: =IF(F28="","Falta o status",IF(AND(F28<>"Sim",H28=""),"Falta a ação",IF(AND(F28<>"Sim",J28=""),"Falta o prazo",IF(AND(F28="Sim",G28=""),"Falta a evidência","OK")))) -> OK
B29: 13 | C29: A calibração e a manutenção dos itens críticos estão em dia. | D29: Fase 2 | E29: — | F29: Parcial | G29: Instrumentos em dia | H29: Concluir a preventiva atrasada da extrusora 3. | I29: Supervisor de manutenção | J29: 46675 | K29: =IF(F29="","",IF(F29="Sim",1,IF(F29="Parcial",0.5,0))) -> 0.5 | L29: =IF(F29="","Falta o status",IF(AND(F29<>"Sim",H29=""),"Falta a ação",IF(AND(F29<>"Sim",J29=""),"Falta o prazo",IF(AND(F29="Sim",G29=""),"Falta a evidência","OK")))) -> OK
B30: 14 | C30: As reclamações e a satisfação do cliente são registradas e analisadas. | D30: Fase 2 | E30: — | F30: Sim | G30: Pesquisa anual e registro de reclamações | K30: =IF(F30="","",IF(F30="Sim",1,IF(F30="Parcial",0.5,0))) -> 1 | L30: =IF(F30="","Falta o status",IF(AND(F30<>"Sim",H30=""),"Falta a ação",IF(AND(F30<>"Sim",J30=""),"Falta o prazo",IF(AND(F30="Sim",G30=""),"Falta a evidência","OK")))) -> OK
B31: Percentual atendido | D31: =IF(COUNTA(F17:F30)=0,"",SUM(K17:K30)/ROWS(K17:K30)) -> 0.92857143
B32: Impeditivos antes da fase 1 | D32: =SUMPRODUCT((D17:D30="Fase 1")*(E17:E30="Sim")*(F17:F30<>"Sim")) -> 0
B33: Impeditivos antes da fase 2 | D33: =SUMPRODUCT((D17:D30="Fase 2")*(E17:E30="Sim")*(F17:F30<>"Sim")) -> 1
B34: Resultado | D34: =IF(COUNTA(F17:F30)=0,"",IF(SUMPRODUCT((D17:D30="Fase 1")*(E17:E30="Sim")*(F17:F30<>"Sim"))>0,"Ainda não está pronta",IF(SUMPRODUCT((D17:D30="Fase 2")*(E17:E30="Sim")*(F17:F30<>"Sim"))>0,"Pronta para a fase 1","Pronta para a fase 2"))) -> Pronta para a fase 1
B36: Ciclo do certificado
B37: # | C37: Evento | D37: Limite | E37: Realizado em | F37: Situação
B38: 1 | C38: Fase 1 | D38: ="" | E38: 46680 | F38: =IF(E38="","Prevista","Realizada") -> Realizada
B39: 2 | C39: Fase 2 | D39: =IF(E38="","",EDATE(E38,6)) -> 46863 | E39: 46714 | F39: =IF(D39="","",IF(E39<>"",IF(E39<=D39,"No prazo","Fora do prazo"),IF(N($D$11)=0,"",IF($D$11>D39,"Atrasada",IF(D39-$D$11<=60,"Vence em 60 dias","Prevista"))))) -> No prazo
B40: 3 | C40: Decisão de certificação | D40: ="" | E40: =IF($D$10="","",$D$10) -> 46738 | F40: =IF(E40="","Prevista","Realizada") -> Realizada
B41: 4 | C41: 1ª manutenção | D41: =IF($D$10="","",EDATE($D$10,12)) -> 47104 | F41: =IF(D41="","",IF(E41<>"",IF(E41<=D41,"No prazo","Fora do prazo"),IF(N($D$11)=0,"",IF($D$11>D41,"Atrasada",IF(D41-$D$11<=60,"Vence em 60 dias","Prevista"))))) -> Prevista
B42: 5 | C42: 2ª manutenção | D42: =IF($D$10="","",EDATE($D$10,24)) -> 47469 | F42: =IF(D42="","",IF(E42<>"",IF(E42<=D42,"No prazo","Fora do prazo"),IF(N($D$11)=0,"",IF($D$11>D42,"Atrasada",IF(D42-$D$11<=60,"Vence em 60 dias","Prevista"))))) -> Prevista
B43: 6 | C43: Auditoria de recertificação | D43: =IF($D$10="","",EDATE($D$10,33)) -> 47743 | F43: =IF(D43="","",IF(E43<>"",IF(E43<=D43,"No prazo","Fora do prazo"),IF(N($D$11)=0,"",IF($D$11>D43,"Atrasada",IF(D43-$D$11<=60,"Vence em 60 dias","Prevista"))))) -> Prevista
...
