Workbook

Sheet Instruções
B1: Indicadores — Como usar esta planilha
B2: Modelo para definir os indicadores, registrar os resultados, ler a situação e registrar as decisões.
B4: Legenda: onde preencher
B5: Amarelo-claro | C5: Células de entrada. É aqui que você digita.
B6: Cinza | C6: Células calculadas ou fixas (rótulos, situações, avisos). Não altere.
B7: Cinza em itálico | C7: Linha de exemplo (marcada com “Ex.”). Mostra o formato esperado e não entra nas contagens.
B8: Listas suspensas | C8: Colunas de sentido, frequência e status aceitam apenas as opções da lista. Metas e resultados aceitam apenas números.
B9: Comentários | C9: Células com triângulo vermelho no canto trazem uma dica de preenchimento. Passe o mouse sobre elas.
B11: As três situações
B12: Na meta | C12: O último resultado atende à meta.
B13: Atenção | C13: O último resultado não atende à meta, mas está dentro do limite de atenção.
B14: Fora da meta | C14: O último resultado passou do limite de atenção.
B16: Ordem recomendada de preenchimento
B17: Passo 1 | C17: Aba Fichas: escreva cada indicador, com o objetivo, a fórmula, a unidade, o sentido, a meta e o limite de atenção.
B18: Passo 2 | C18: Aba Medições: escreva o nome dos períodos na linha amarela do cabeçalho.
B19: Passo 3 | C19: Aba Medições: registre o resultado de cada período, da esquerda para a direita, sem pular colunas.
B20: Passo 4 | C20: Aba Painel: leia a situação, a tendência e a ação sugerida de cada indicador.
B21: Passo 5 | C21: Aba Painel: informe o número do indicador que deve aparecer no gráfico.
B22: Passo 6 | C22: Aba Análise: registre a decisão de cada indicador fora da meta, com responsável e prazo.
B23: Passo 7 | C23: Aba Checklist: valide o conjunto de indicadores, pelo menos uma vez por ano.
B25: Abas da planilha
B26: Fichas | C26: Definição de até 12 indicadores, com conferência dos campos.
B27: Medições | C27: Resultados de cada indicador, em até 12 períodos, e contagem dos períodos seguidos fora da meta.
B28: Painel | C28: Leitura de cada indicador, resumo e gráfico do indicador escolhido.
B29: Análise | C29: Registro das decisões tomadas nas reuniões de indicadores.
B30: Checklist | C30: Doze verificações de qualidade dos indicadores, com percentual de conclusão.
B31: Exemplo 1 - Pizzaria | C31: Painel de quatro indicadores de uma organização pequena.
B32: Exemplo 2 - Compras | C32: Painel de quatro indicadores de um processo, com o registro da reunião de análise.
B34: Regras e premissas do modelo
B35: Situação | C35: É lida no último resultado registrado. A meta e o limite de atenção vêm da aba Fichas.
B36: Limite de atenção | C36: Separa o desvio pequeno do grande. Quando maior é melhor, o limite fica abaixo da meta. Quando menor é melhor, fica acima.
B37: Três períodos seguidos | C37: Quando os três últimos resultados não atendem à meta, a ação sugerida é abrir análise de causa, qualquer que seja a situação. A regra é uma convenção deste modelo.
B38: Tendência | C38: Compara a média dos três últimos períodos com a média dos três anteriores. Diferença de até 5% é considerada estável. Pede pelo menos seis medições.
B39: Um ano por arquivo | C39: O modelo guarda 12 períodos. Para o período seguinte, salve uma cópia do arquivo e limpe a aba Medições.
B40: Exemplos | C40: Os dados das abas de exemplo são ilustrativos, criados para este material.

Sheet Fichas
B1: Fichas dos indicadores
B2: Um indicador por linha. Duas pessoas, com a ficha na mão, precisam chegar ao mesmo número.
B4: Organização ou processo | G4: Responsável pelo painel
B5: Período | G5: Atualizado em
B7: # | C7: Indicador | D7: Objetivo | E7: Processo | F7: Fórmula | G7: Unidade | H7: Sentido | I7: Meta | J7: Limite de atenção | K7: Fonte dos dados | L7: Frequência | M7: Responsável | N7: Conferência
C8: Nome curto | D8: O que se quer alcançar | E8: Onde é medido | F8: O que se divide, e por quanto | G8: %, dias, itens | H8: Escolha na lista | I8: Número | J8: Número | K8: De onde vem o dado | L8: Escolha na lista | M8: Cargo ou nome | N8: Campos da linha
B9: Ex. | C9: Prazo de atendimento das requisições | D9: Fornecer os materiais no prazo | E9: Adquirir materiais e serviços | F9: Soma dos dias úteis entre a requisição e o pedido ÷ número de requisições | G9: dias úteis | H9: Menor é melhor | I9: 5 | J9: 6 | K9: Datas da requisição e do pedido, no sistema | L9: Mensal | M9: Comprador sênior | N9: Completa
B10: 1 | N10: =IF(C10="","",IF(D10="","Falta o objetivo",IF(F10="","Falta a fórmula",IF(OR(G10="",H10=""),"Falta a unidade ou o sentido",IF(I10="","Falta a meta",IF(J10="","Falta o limite de atenção",IF(OR(AND(H10="Maior é melhor",J10>=I10),AND(H10="Menor é melhor",J10<=I10)),"Limite incoerente com a meta",IF(OR(K10="",L10="",M10=""),"Falta fonte, frequência ou responsável","Completa"))))))))
B11: 2 | N11: =IF(C11="","",IF(D11="","Falta o objetivo",IF(F11="","Falta a fórmula",IF(OR(G11="",H11=""),"Falta a unidade ou o sentido",IF(I11="","Falta a meta",IF(J11="","Falta o limite de atenção",IF(OR(AND(H11="Maior é melhor",J11>=I11),AND(H11="Menor é melhor",J11<=I11)),"Limite incoerente com a meta",IF(OR(K11="",L11="",M11=""),"Falta fonte, frequência ou responsável","Completa"))))))))
B12: 3 | N12: =IF(C12="","",IF(D12="","Falta o objetivo",IF(F12="","Falta a fórmula",IF(OR(G12="",H12=""),"Falta a unidade ou o sentido",IF(I12="","Falta a meta",IF(J12="","Falta o limite de atenção",IF(OR(AND(H12="Maior é melhor",J12>=I12),AND(H12="Menor é melhor",J12<=I12)),"Limite incoerente com a meta",IF(OR(K12="",L12="",M12=""),"Falta fonte, frequência ou responsável","Completa"))))))))
B13: 4 | N13: =IF(C13="","",IF(D13="","Falta o objetivo",IF(F13="","Falta a fórmula",IF(OR(G13="",H13=""),"Falta a unidade ou o sentido",IF(I13="","Falta a meta",IF(J13="","Falta o limite de atenção",IF(OR(AND(H13="Maior é melhor",J13>=I13),AND(H13="Menor é melhor",J13<=I13)),"Limite incoerente com a meta",IF(OR(K13="",L13="",M13=""),"Falta fonte, frequência ou responsável","Completa"))))))))
B14: 5 | N14: =IF(C14="","",IF(D14="","Falta o objetivo",IF(F14="","Falta a fórmula",IF(OR(G14="",H14=""),"Falta a unidade ou o sentido",IF(I14="","Falta a meta",IF(J14="","Falta o limite de atenção",IF(OR(AND(H14="Maior é melhor",J14>=I14),AND(H14="Menor é melhor",J14<=I14)),"Limite incoerente com a meta",IF(OR(K14="",L14="",M14=""),"Falta fonte, frequência ou responsável","Completa"))))))))
B15: 6 | N15: =IF(C15="","",IF(D15="","Falta o objetivo",IF(F15="","Falta a fórmula",IF(OR(G15="",H15=""),"Falta a unidade ou o sentido",IF(I15="","Falta a meta",IF(J15="","Falta o limite de atenção",IF(OR(AND(H15="Maior é melhor",J15>=I15),AND(H15="Menor é melhor",J15<=I15)),"Limite incoerente com a meta",IF(OR(K15="",L15="",M15=""),"Falta fonte, frequência ou responsável","Completa"))))))))
B16: 7 | N16: =IF(C16="","",IF(D16="","Falta o objetivo",IF(F16="","Falta a fórmula",IF(OR(G16="",H16=""),"Falta a unidade ou o sentido",IF(I16="","Falta a meta",IF(J16="","Falta o limite de atenção",IF(OR(AND(H16="Maior é melhor",J16>=I16),AND(H16="Menor é melhor",J16<=I16)),"Limite incoerente com a meta",IF(OR(K16="",L16="",M16=""),"Falta fonte, frequência ou responsável","Completa"))))))))
B17: 8 | N17: =IF(C17="","",IF(D17="","Falta o objetivo",IF(F17="","Falta a fórmula",IF(OR(G17="",H17=""),"Falta a unidade ou o sentido",IF(I17="","Falta a meta",IF(J17="","Falta o limite de atenção",IF(OR(AND(H17="Maior é melhor",J17>=I17),AND(H17="Menor é melhor",J17<=I17)),"Limite incoerente com a meta",IF(OR(K17="",L17="",M17=""),"Falta fonte, frequência ou responsável","Completa"))))))))
B18: 9 | N18: =IF(C18="","",IF(D18="","Falta o objetivo",IF(F18="","Falta a fórmula",IF(OR(G18="",H18=""),"Falta a unidade ou o sentido",IF(I18="","Falta a meta",IF(J18="","Falta o limite de atenção",IF(OR(AND(H18="Maior é melhor",J18>=I18),AND(H18="Menor é melhor",J18<=I18)),"Limite incoerente com a meta",IF(OR(K18="",L18="",M18=""),"Falta fonte, frequência ou responsável","Completa"))))))))
B19: 10 | N19: =IF(C19="","",IF(D19="","Falta o objetivo",IF(F19="","Falta a fórmula",IF(OR(G19="",H19=""),"Falta a unidade ou o sentido",IF(I19="","Falta a meta",IF(J19="","Falta o limite de atenção",IF(OR(AND(H19="Maior é melhor",J19>=I19),AND(H19="Menor é melhor",J19<=I19)),"Limite incoerente com a meta",IF(OR(K19="",L19="",M19=""),"Falta fonte, frequência ou responsável","Completa"))))))))
B20: 11 | N20: =IF(C20="","",IF(D20="","Falta o objetivo",IF(F20="","Falta a fórmula",IF(OR(G20="",H20=""),"Falta a unidade ou o sentido",IF(I20="","Falta a meta",IF(J20="","Falta o limite de atenção",IF(OR(AND(H20="Maior é melhor",J20>=I20),AND(H20="Menor é melhor",J20<=I20)),"Limite incoerente com a meta",IF(OR(K20="",L20="",M20=""),"Falta fonte, frequência ou responsável","Completa"))))))))
B21: 12 | N21: =IF(C21="","",IF(D21="","Falta o objetivo",IF(F21="","Falta a fórmula",IF(OR(G21="",H21=""),"Falta a unidade ou o sentido",IF(I21="","Falta a meta",IF(J21="","Falta o limite de atenção",IF(OR(AND(H21="Maior é melhor",J21>=I21),AND(H21="Menor é melhor",J21<=I21)),"Limite incoerente com a meta",IF(OR(K21="",L21="",M21=""),"Falta fonte, frequência ou responsável","Completa"))))))))
B23: Resumo automático
B24: Indicadores cadastrados | E24: =COUNTA(C10:C21) -> 0
B25: Fichas completas | E25: =COUNTIF(N10:N21,"Completa") -> 0
B26: Aviso | E26: =IF(E24=0,"Cadastre os indicadores",IF(E25<E24,"Há ficha incompleta: veja a coluna Conferência",IF(E24>8,"São muitos indicadores: confira se todos levam a decisões","OK"))) -> Cadastre os indicadores

Sheet Medições
B1: Medições
B2: Registre os resultados da esquerda para a direita, sem pular colunas. Escreva o nome de cada período na linha amarela.
B5: # | C5: Indicador | D5: Unidade | E5: Períodos | Q5: Medições
C6: Vem da aba Fichas | D6: Vem da aba Fichas | Q6: Contagem
B7: 1 | C7: =IF(Fichas!C10="","",Fichas!C10) | D7: =IF(Fichas!G10="","",Fichas!G10) | Q7: =COUNT(E7:P7) -> 0
B8: 2 | C8: =IF(Fichas!C11="","",Fichas!C11) | D8: =IF(Fichas!G11="","",Fichas!G11) | Q8: =COUNT(E8:P8) -> 0
B9: 3 | C9: =IF(Fichas!C12="","",Fichas!C12) | D9: =IF(Fichas!G12="","",Fichas!G12) | Q9: =COUNT(E9:P9) -> 0
B10: 4 | C10: =IF(Fichas!C13="","",Fichas!C13) | D10: =IF(Fichas!G13="","",Fichas!G13) | Q10: =COUNT(E10:P10) -> 0
B11: 5 | C11: =IF(Fichas!C14="","",Fichas!C14) | D11: =IF(Fichas!G14="","",Fichas!G14) | Q11: =COUNT(E11:P11) -> 0
B12: 6 | C12: =IF(Fichas!C15="","",Fichas!C15) | D12: =IF(Fichas!G15="","",Fichas!G15) | Q12: =COUNT(E12:P12) -> 0
B13: 7 | C13: =IF(Fichas!C16="","",Fichas!C16) | D13: =IF(Fichas!G16="","",Fichas!G16) | Q13: =COUNT(E13:P13) -> 0
B14: 8 | C14: =IF(Fichas!C17="","",Fichas!C17) | D14: =IF(Fichas!G17="","",Fichas!G17) | Q14: =COUNT(E14:P14) -> 0
B15: 9 | C15: =IF(Fichas!C18="","",Fichas!C18) | D15: =IF(Fichas!G18="","",Fichas!G18) | Q15: =COUNT(E15:P15) -> 0
B16: 10 | C16: =IF(Fichas!C19="","",Fichas!C19) | D16: =IF(Fichas!G19="","",Fichas!G19) | Q16: =COUNT(E16:P16) -> 0
B17: 11 | C17: =IF(Fichas!C20="","",Fichas!C20) | D17: =IF(Fichas!G20="","",Fichas!G20) | Q17: =COUNT(E17:P17) -> 0
B18: 12 | C18: =IF(Fichas!C21="","",Fichas!C21) | D18: =IF(Fichas!G21="","",Fichas!G21) | Q18: =COUNT(E18:P18) -> 0
B20: Períodos seguidos fora da meta
B21: Contagem calculada a partir dos resultados e da meta de cada indicador. Volta a zero quando o resultado atende à meta.
B22: 1 | C22: =IF(Fichas!C10="","",Fichas!C10) | E22: =IF(OR(E7="",Fichas!$I10="",Fichas!$H10=""),"",IF(IF(Fichas!$H10="Maior é melhor",E7>=Fichas!$I10,E7<=Fichas!$I10),0,1)) | F22: =IF(OR(F7="",Fichas!$I10="",Fichas!$H10=""),"",IF(IF(Fichas!$H10="Maior é melhor",F7>=Fichas!$I10,F7<=Fichas!$I10),0,N(E22)+1)) | G22: =IF(OR(G7="",Fichas!$I10="",Fichas!$H10=""),"",IF(IF(Fichas!$H10="Maior é melhor",G7>=Fichas!$I10,G7<=Fichas!$I10),0,N(F22)+1)) | H22: =IF(OR(H7="",Fichas!$I10="",Fichas!$H10=""),"",IF(IF(Fichas!$H10="Maior é melhor",H7>=Fichas!$I10,H7<=Fichas!$I10),0,N(G22)+1)) | I22: =IF(OR(I7="",Fichas!$I10="",Fichas!$H10=""),"",IF(IF(Fichas!$H10="Maior é melhor",I7>=Fichas!$I10,I7<=Fichas!$I10),0,N(H22)+1)) | J22: =IF(OR(J7="",Fichas!$I10="",Fichas!$H10=""),"",IF(IF(Fichas!$H10="Maior é melhor",J7>=Fichas!$I10,J7<=Fichas!$I10),0,N(I22)+1)) | K22: =IF(OR(K7="",Fichas!$I10="",Fichas!$H10=""),"",IF(IF(Fichas!$H10="Maior é melhor",K7>=Fichas!$I10,K7<=Fichas!$I10),0,N(J22)+1)) | L22: =IF(OR(L7="",Fichas!$I10="",Fichas!$H10=""),"",IF(IF(Fichas!$H10="Maior é melhor",L7>=Fichas!$I10,L7<=Fichas!$I10),0,N(K22)+1)) | M22: =IF(OR(M7="",Fichas!$I10="",Fichas!$H10=""),"",IF(IF(Fichas!$H10="Maior é melhor",M7>=Fichas!$I10,M7<=Fichas!$I10),0,N(L22)+1)) | ... P22: =IF(OR(P7="",Fichas!$I10="",Fichas!$H10=""),"",IF(IF(Fichas!$H10="Maior é melhor",P7>=Fichas!$I10,P7<=Fichas!$I10),0,N(O22)+1)) | Q22: =IF(Q7=0,"",N(INDEX(E22:P22,Q7)))
B23: 2 | C23: =IF(Fichas!C11="","",Fichas!C11) | E23: =IF(OR(E8="",Fichas!$I11="",Fichas!$H11=""),"",IF(IF(Fichas!$H11="Maior é melhor",E8>=Fichas!$I11,E8<=Fichas!$I11),0,1)) | F23: =IF(OR(F8="",Fichas!$I11="",Fichas!$H11=""),"",IF(IF(Fichas!$H11="Maior é melhor",F8>=Fichas!$I11,F8<=Fichas!$I11),0,N(E23)+1)) | G23: =IF(OR(G8="",Fichas!$I11="",Fichas!$H11=""),"",IF(IF(Fichas!$H11="Maior é melhor",G8>=Fichas!$I11,G8<=Fichas!$I11),0,N(F23)+1)) | H23: =IF(OR(H8="",Fichas!$I11="",Fichas!$H11=""),"",IF(IF(Fichas!$H11="Maior é melhor",H8>=Fichas!$I11,H8<=Fichas!$I11),0,N(G23)+1)) | I23: =IF(OR(I8="",Fichas!$I11="",Fichas!$H11=""),"",IF(IF(Fichas!$H11="Maior é melhor",I8>=Fichas!$I11,I8<=Fichas!$I11),0,N(H23)+1)) | J23: =IF(OR(J8="",Fichas!$I11="",Fichas!$H11=""),"",IF(IF(Fichas!$H11="Maior é melhor",J8>=Fichas!$I11,J8<=Fichas!$I11),0,N(I23)+1)) | K23: =IF(OR(K8="",Fichas!$I11="",Fichas!$H11=""),"",IF(IF(Fichas!$H11="Maior é melhor",K8>=Fichas!$I11,K8<=Fichas!$I11),0,N(J23)+1)) | L23: =IF(OR(L8="",Fichas!$I11="",Fichas!$H11=""),"",IF(IF(Fichas!$H11="Maior é melhor",L8>=Fichas!$I11,L8<=Fichas!$I11),0,N(K23)+1)) | M23: =IF(OR(M8="",Fichas!$I11="",Fichas!$H11=""),"",IF(IF(Fichas!$H11="Maior é melhor",M8>=Fichas!$I11,M8<=Fichas!$I11),0,N(L23)+1)) | ... P23: =IF(OR(P8="",Fichas!$I11="",Fichas!$H11=""),"",IF(IF(Fichas!$H11="Maior é melhor",P8>=Fichas!$I11,P8<=Fichas!$I11),0,N(O23)+1)) | Q23: =IF(Q8=0,"",N(INDEX(E23:P23,Q8)))
B24: 3 | C24: =IF(Fichas!C12="","",Fichas!C12) | E24: =IF(OR(E9="",Fichas!$I12="",Fichas!$H12=""),"",IF(IF(Fichas!$H12="Maior é melhor",E9>=Fichas!$I12,E9<=Fichas!$I12),0,1)) | F24: =IF(OR(F9="",Fichas!$I12="",Fichas!$H12=""),"",IF(IF(Fichas!$H12="Maior é melhor",F9>=Fichas!$I12,F9<=Fichas!$I12),0,N(E24)+1)) | G24: =IF(OR(G9="",Fichas!$I12="",Fichas!$H12=""),"",IF(IF(Fichas!$H12="Maior é melhor",G9>=Fichas!$I12,G9<=Fichas!$I12),0,N(F24)+1)) | H24: =IF(OR(H9="",Fichas!$I12="",Fichas!$H12=""),"",IF(IF(Fichas!$H12="Maior é melhor",H9>=Fichas!$I12,H9<=Fichas!$I12),0,N(G24)+1)) | I24: =IF(OR(I9="",Fichas!$I12="",Fichas!$H12=""),"",IF(IF(Fichas!$H12="Maior é melhor",I9>=Fichas!$I12,I9<=Fichas!$I12),0,N(H24)+1)) | J24: =IF(OR(J9="",Fichas!$I12="",Fichas!$H12=""),"",IF(IF(Fichas!$H12="Maior é melhor",J9>=Fichas!$I12,J9<=Fichas!$I12),0,N(I24)+1)) | K24: =IF(OR(K9="",Fichas!$I12="",Fichas!$H12=""),"",IF(IF(Fichas!$H12="Maior é melhor",K9>=Fichas!$I12,K9<=Fichas!$I12),0,N(J24)+1)) | L24: =IF(OR(L9="",Fichas!$I12="",Fichas!$H12=""),"",IF(IF(Fichas!$H12="Maior é melhor",L9>=Fichas!$I12,L9<=Fichas!$I12),0,N(K24)+1)) | M24: =IF(OR(M9="",Fichas!$I12="",Fichas!$H12=""),"",IF(IF(Fichas!$H12="Maior é melhor",M9>=Fichas!$I12,M9<=Fichas!$I12),0,N(L24)+1)) | ... P24: =IF(OR(P9="",Fichas!$I12="",Fichas!$H12=""),"",IF(IF(Fichas!$H12="Maior é melhor",P9>=Fichas!$I12,P9<=Fichas!$I12),0,N(O24)+1)) | Q24: =IF(Q9=0,"",N(INDEX(E24:P24,Q9)))
B25: 4 | C25: =IF(Fichas!C13="","",Fichas!C13) | E25: =IF(OR(E10="",Fichas!$I13="",Fichas!$H13=""),"",IF(IF(Fichas!$H13="Maior é melhor",E10>=Fichas!$I13,E10<=Fichas!$I13),0,1)) | F25: =IF(OR(F10="",Fichas!$I13="",Fichas!$H13=""),"",IF(IF(Fichas!$H13="Maior é melhor",F10>=Fichas!$I13,F10<=Fichas!$I13),0,N(E25)+1)) | G25: =IF(OR(G10="",Fichas!$I13="",Fichas!$H13=""),"",IF(IF(Fichas!$H13="Maior é melhor",G10>=Fichas!$I13,G10<=Fichas!$I13),0,N(F25)+1)) | H25: =IF(OR(H10="",Fichas!$I13="",Fichas!$H13=""),"",IF(IF(Fichas!$H13="Maior é melhor",H10>=Fichas!$I13,H10<=Fichas!$I13),0,N(G25)+1)) | I25: =IF(OR(I10="",Fichas!$I13="",Fichas!$H13=""),"",IF(IF(Fichas!$H13="Maior é melhor",I10>=Fichas!$I13,I10<=Fichas!$I13),0,N(H25)+1)) | J25: =IF(OR(J10="",Fichas!$I13="",Fichas!$H13=""),"",IF(IF(Fichas!$H13="Maior é melhor",J10>=Fichas!$I13,J10<=Fichas!$I13),0,N(I25)+1)) | K25: =IF(OR(K10="",Fichas!$I13="",Fichas!$H13=""),"",IF(IF(Fichas!$H13="Maior é melhor",K10>=Fichas!$I13,K10<=Fichas!$I13),0,N(J25)+1)) | L25: =IF(OR(L10="",Fichas!$I13="",Fichas!$H13=""),"",IF(IF(Fichas!$H13="Maior é melhor",L10>=Fichas!$I13,L10<=Fichas!$I13),0,N(K25)+1)) | M25: =IF(OR(M10="",Fichas!$I13="",Fichas!$H13=""),"",IF(IF(Fichas!$H13="Maior é melhor",M10>=Fichas!$I13,M10<=Fichas!$I13),0,N(L25)+1)) | ... P25: =IF(OR(P10="",Fichas!$I13="",Fichas!$H13=""),"",IF(IF(Fichas!$H13="Maior é melhor",P10>=Fichas!$I13,P10<=Fichas!$I13),0,N(O25)+1)) | Q25: =IF(Q10=0,"",N(INDEX(E25:P25,Q10)))
B26: 5 | C26: =IF(Fichas!C14="","",Fichas!C14) | E26: =IF(OR(E11="",Fichas!$I14="",Fichas!$H14=""),"",IF(IF(Fichas!$H14="Maior é melhor",E11>=Fichas!$I14,E11<=Fichas!$I14),0,1)) | F26: =IF(OR(F11="",Fichas!$I14="",Fichas!$H14=""),"",IF(IF(Fichas!$H14="Maior é melhor",F11>=Fichas!$I14,F11<=Fichas!$I14),0,N(E26)+1)) | G26: =IF(OR(G11="",Fichas!$I14="",Fichas!$H14=""),"",IF(IF(Fichas!$H14="Maior é melhor",G11>=Fichas!$I14,G11<=Fichas!$I14),0,N(F26)+1)) | H26: =IF(OR(H11="",Fichas!$I14="",Fichas!$H14=""),"",IF(IF(Fichas!$H14="Maior é melhor",H11>=Fichas!$I14,H11<=Fichas!$I14),0,N(G26)+1)) | I26: =IF(OR(I11="",Fichas!$I14="",Fichas!$H14=""),"",IF(IF(Fichas!$H14="Maior é melhor",I11>=Fichas!$I14,I11<=Fichas!$I14),0,N(H26)+1)) | J26: =IF(OR(J11="",Fichas!$I14="",Fichas!$H14=""),"",IF(IF(Fichas!$H14="Maior é melhor",J11>=Fichas!$I14,J11<=Fichas!$I14),0,N(I26)+1)) | K26: =IF(OR(K11="",Fichas!$I14="",Fichas!$H14=""),"",IF(IF(Fichas!$H14="Maior é melhor",K11>=Fichas!$I14,K11<=Fichas!$I14),0,N(J26)+1)) | L26: =IF(OR(L11="",Fichas!$I14="",Fichas!$H14=""),"",IF(IF(Fichas!$H14="Maior é melhor",L11>=Fichas!$I14,L11<=Fichas!$I14),0,N(K26)+1)) | M26: =IF(OR(M11="",Fichas!$I14="",Fichas!$H14=""),"",IF(IF(Fichas!$H14="Maior é melhor",M11>=Fichas!$I14,M11<=Fichas!$I14),0,N(L26)+1)) | ... P26: =IF(OR(P11="",Fichas!$I14="",Fichas!$H14=""),"",IF(IF(Fichas!$H14="Maior é melhor",P11>=Fichas!$I14,P11<=Fichas!$I14),0,N(O26)+1)) | Q26: =IF(Q11=0,"",N(INDEX(E26:P26,Q11)))
B27: 6 | C27: =IF(Fichas!C15="","",Fichas!C15) | E27: =IF(OR(E12="",Fichas!$I15="",Fichas!$H15=""),"",IF(IF(Fichas!$H15="Maior é melhor",E12>=Fichas!$I15,E12<=Fichas!$I15),0,1)) | F27: =IF(OR(F12="",Fichas!$I15="",Fichas!$H15=""),"",IF(IF(Fichas!$H15="Maior é melhor",F12>=Fichas!$I15,F12<=Fichas!$I15),0,N(E27)+1)) | G27: =IF(OR(G12="",Fichas!$I15="",Fichas!$H15=""),"",IF(IF(Fichas!$H15="Maior é melhor",G12>=Fichas!$I15,G12<=Fichas!$I15),0,N(F27)+1)) | H27: =IF(OR(H12="",Fichas!$I15="",Fichas!$H15=""),"",IF(IF(Fichas!$H15="Maior é melhor",H12>=Fichas!$I15,H12<=Fichas!$I15),0,N(G27)+1)) | I27: =IF(OR(I12="",Fichas!$I15="",Fichas!$H15=""),"",IF(IF(Fichas!$H15="Maior é melhor",I12>=Fichas!$I15,I12<=Fichas!$I15),0,N(H27)+1)) | J27: =IF(OR(J12="",Fichas!$I15="",Fichas!$H15=""),"",IF(IF(Fichas!$H15="Maior é melhor",J12>=Fichas!$I15,J12<=Fichas!$I15),0,N(I27)+1)) | K27: =IF(OR(K12="",Fichas!$I15="",Fichas!$H15=""),"",IF(IF(Fichas!$H15="Maior é melhor",K12>=Fichas!$I15,K12<=Fichas!$I15),0,N(J27)+1)) | L27: =IF(OR(L12="",Fichas!$I15="",Fichas!$H15=""),"",IF(IF(Fichas!$H15="Maior é melhor",L12>=Fichas!$I15,L12<=Fichas!$I15),0,N(K27)+1)) | M27: =IF(OR(M12="",Fichas!$I15="",Fichas!$H15=""),"",IF(IF(Fichas!$H15="Maior é melhor",M12>=Fichas!$I15,M12<=Fichas!$I15),0,N(L27)+1)) | ... P27: =IF(OR(P12="",Fichas!$I15="",Fichas!$H15=""),"",IF(IF(Fichas!$H15="Maior é melhor",P12>=Fichas!$I15,P12<=Fichas!$I15),0,N(O27)+1)) | Q27: =IF(Q12=0,"",N(INDEX(E27:P27,Q12)))
B28: 7 | C28: =IF(Fichas!C16="","",Fichas!C16) | E28: =IF(OR(E13="",Fichas!$I16="",Fichas!$H16=""),"",IF(IF(Fichas!$H16="Maior é melhor",E13>=Fichas!$I16,E13<=Fichas!$I16),0,1)) | F28: =IF(OR(F13="",Fichas!$I16="",Fichas!$H16=""),"",IF(IF(Fichas!$H16="Maior é melhor",F13>=Fichas!$I16,F13<=Fichas!$I16),0,N(E28)+1)) | G28: =IF(OR(G13="",Fichas!$I16="",Fichas!$H16=""),"",IF(IF(Fichas!$H16="Maior é melhor",G13>=Fichas!$I16,G13<=Fichas!$I16),0,N(F28)+1)) | H28: =IF(OR(H13="",Fichas!$I16="",Fichas!$H16=""),"",IF(IF(Fichas!$H16="Maior é melhor",H13>=Fichas!$I16,H13<=Fichas!$I16),0,N(G28)+1)) | I28: =IF(OR(I13="",Fichas!$I16="",Fichas!$H16=""),"",IF(IF(Fichas!$H16="Maior é melhor",I13>=Fichas!$I16,I13<=Fichas!$I16),0,N(H28)+1)) | J28: =IF(OR(J13="",Fichas!$I16="",Fichas!$H16=""),"",IF(IF(Fichas!$H16="Maior é melhor",J13>=Fichas!$I16,J13<=Fichas!$I16),0,N(I28)+1)) | K28: =IF(OR(K13="",Fichas!$I16="",Fichas!$H16=""),"",IF(IF(Fichas!$H16="Maior é melhor",K13>=Fichas!$I16,K13<=Fichas!$I16),0,N(J28)+1)) | L28: =IF(OR(L13="",Fichas!$I16="",Fichas!$H16=""),"",IF(IF(Fichas!$H16="Maior é melhor",L13>=Fichas!$I16,L13<=Fichas!$I16),0,N(K28)+1)) | M28: =IF(OR(M13="",Fichas!$I16="",Fichas!$H16=""),"",IF(IF(Fichas!$H16="Maior é melhor",M13>=Fichas!$I16,M13<=Fichas!$I16),0,N(L28)+1)) | ... P28: =IF(OR(P13="",Fichas!$I16="",Fichas!$H16=""),"",IF(IF(Fichas!$H16="Maior é melhor",P13>=Fichas!$I16,P13<=Fichas!$I16),0,N(O28)+1)) | Q28: =IF(Q13=0,"",N(INDEX(E28:P28,Q13)))
B29: 8 | C29: =IF(Fichas!C17="","",Fichas!C17) | E29: =IF(OR(E14="",Fichas!$I17="",Fichas!$H17=""),"",IF(IF(Fichas!$H17="Maior é melhor",E14>=Fichas!$I17,E14<=Fichas!$I17),0,1)) | F29: =IF(OR(F14="",Fichas!$I17="",Fichas!$H17=""),"",IF(IF(Fichas!$H17="Maior é melhor",F14>=Fichas!$I17,F14<=Fichas!$I17),0,N(E29)+1)) | G29: =IF(OR(G14="",Fichas!$I17="",Fichas!$H17=""),"",IF(IF(Fichas!$H17="Maior é melhor",G14>=Fichas!$I17,G14<=Fichas!$I17),0,N(F29)+1)) | H29: =IF(OR(H14="",Fichas!$I17="",Fichas!$H17=""),"",IF(IF(Fichas!$H17="Maior é melhor",H14>=Fichas!$I17,H14<=Fichas!$I17),0,N(G29)+1)) | I29: =IF(OR(I14="",Fichas!$I17="",Fichas!$H17=""),"",IF(IF(Fichas!$H17="Maior é melhor",I14>=Fichas!$I17,I14<=Fichas!$I17),0,N(H29)+1)) | J29: =IF(OR(J14="",Fichas!$I17="",Fichas!$H17=""),"",IF(IF(Fichas!$H17="Maior é melhor",J14>=Fichas!$I17,J14<=Fichas!$I17),0,N(I29)+1)) | K29: =IF(OR(K14="",Fichas!$I17="",Fichas!$H17=""),"",IF(IF(Fichas!$H17="Maior é melhor",K14>=Fichas!$I17,K14<=Fichas!$I17),0,N(J29)+1)) | L29: =IF(OR(L14="",Fichas!$I17="",Fichas!$H17=""),"",IF(IF(Fichas!$H17="Maior é melhor",L14>=Fichas!$I17,L14<=Fichas!$I17),0,N(K29)+1)) | M29: =IF(OR(M14="",Fichas!$I17="",Fichas!$H17=""),"",IF(IF(Fichas!$H17="Maior é melhor",M14>=Fichas!$I17,M14<=Fichas!$I17),0,N(L29)+1)) | ... P29: =IF(OR(P14="",Fichas!$I17="",Fichas!$H17=""),"",IF(IF(Fichas!$H17="Maior é melhor",P14>=Fichas!$I17,P14<=Fichas!$I17),0,N(O29)+1)) | Q29: =IF(Q14=0,"",N(INDEX(E29:P29,Q14)))
B30: 9 | C30: =IF(Fichas!C18="","",Fichas!C18) | E30: =IF(OR(E15="",Fichas!$I18="",Fichas!$H18=""),"",IF(IF(Fichas!$H18="Maior é melhor",E15>=Fichas!$I18,E15<=Fichas!$I18),0,1)) | F30: =IF(OR(F15="",Fichas!$I18="",Fichas!$H18=""),"",IF(IF(Fichas!$H18="Maior é melhor",F15>=Fichas!$I18,F15<=Fichas!$I18),0,N(E30)+1)) | G30: =IF(OR(G15="",Fichas!$I18="",Fichas!$H18=""),"",IF(IF(Fichas!$H18="Maior é melhor",G15>=Fichas!$I18,G15<=Fichas!$I18),0,N(F30)+1)) | H30: =IF(OR(H15="",Fichas!$I18="",Fichas!$H18=""),"",IF(IF(Fichas!$H18="Maior é melhor",H15>=Fichas!$I18,H15<=Fichas!$I18),0,N(G30)+1)) | I30: =IF(OR(I15="",Fichas!$I18="",Fichas!$H18=""),"",IF(IF(Fichas!$H18="Maior é melhor",I15>=Fichas!$I18,I15<=Fichas!$I18),0,N(H30)+1)) | J30: =IF(OR(J15="",Fichas!$I18="",Fichas!$H18=""),"",IF(IF(Fichas!$H18="Maior é melhor",J15>=Fichas!$I18,J15<=Fichas!$I18),0,N(I30)+1)) | K30: =IF(OR(K15="",Fichas!$I18="",Fichas!$H18=""),"",IF(IF(Fichas!$H18="Maior é melhor",K15>=Fichas!$I18,K15<=Fichas!$I18),0,N(J30)+1)) | L30: =IF(OR(L15="",Fichas!$I18="",Fichas!$H18=""),"",IF(IF(Fichas!$H18="Maior é melhor",L15>=Fichas!$I18,L15<=Fichas!$I18),0,N(K30)+1)) | M30: =IF(OR(M15="",Fichas!$I18="",Fichas!$H18=""),"",IF(IF(Fichas!$H18="Maior é melhor",M15>=Fichas!$I18,M15<=Fichas!$I18),0,N(L30)+1)) | ... P30: =IF(OR(P15="",Fichas!$I18="",Fichas!$H18=""),"",IF(IF(Fichas!$H18="Maior é melhor",P15>=Fichas!$I18,P15<=Fichas!$I18),0,N(O30)+1)) | Q30: =IF(Q15=0,"",N(INDEX(E30:P30,Q15)))
B31: 10 | C31: =IF(Fichas!C19="","",Fichas!C19) | E31: =IF(OR(E16="",Fichas!$I19="",Fichas!$H19=""),"",IF(IF(Fichas!$H19="Maior é melhor",E16>=Fichas!$I19,E16<=Fichas!$I19),0,1)) | F31: =IF(OR(F16="",Fichas!$I19="",Fichas!$H19=""),"",IF(IF(Fichas!$H19="Maior é melhor",F16>=Fichas!$I19,F16<=Fichas!$I19),0,N(E31)+1)) | G31: =IF(OR(G16="",Fichas!$I19="",Fichas!$H19=""),"",IF(IF(Fichas!$H19="Maior é melhor",G16>=Fichas!$I19,G16<=Fichas!$I19),0,N(F31)+1)) | H31: =IF(OR(H16="",Fichas!$I19="",Fichas!$H19=""),"",IF(IF(Fichas!$H19="Maior é melhor",H16>=Fichas!$I19,H16<=Fichas!$I19),0,N(G31)+1)) | I31: =IF(OR(I16="",Fichas!$I19="",Fichas!$H19=""),"",IF(IF(Fichas!$H19="Maior é melhor",I16>=Fichas!$I19,I16<=Fichas!$I19),0,N(H31)+1)) | J31: =IF(OR(J16="",Fichas!$I19="",Fichas!$H19=""),"",IF(IF(Fichas!$H19="Maior é melhor",J16>=Fichas!$I19,J16<=Fichas!$I19),0,N(I31)+1)) | K31: =IF(OR(K16="",Fichas!$I19="",Fichas!$H19=""),"",IF(IF(Fichas!$H19="Maior é melhor",K16>=Fichas!$I19,K16<=Fichas!$I19),0,N(J31)+1)) | L31: =IF(OR(L16="",Fichas!$I19="",Fichas!$H19=""),"",IF(IF(Fichas!$H19="Maior é melhor",L16>=Fichas!$I19,L16<=Fichas!$I19),0,N(K31)+1)) | M31: =IF(OR(M16="",Fichas!$I19="",Fichas!$H19=""),"",IF(IF(Fichas!$H19="Maior é melhor",M16>=Fichas!$I19,M16<=Fichas!$I19),0,N(L31)+1)) | ... P31: =IF(OR(P16="",Fichas!$I19="",Fichas!$H19=""),"",IF(IF(Fichas!$H19="Maior é melhor",P16>=Fichas!$I19,P16<=Fichas!$I19),0,N(O31)+1)) | Q31: =IF(Q16=0,"",N(INDEX(E31:P31,Q16)))
B32: 11 | C32: =IF(Fichas!C20="","",Fichas!C20) | E32: =IF(OR(E17="",Fichas!$I20="",Fichas!$H20=""),"",IF(IF(Fichas!$H20="Maior é melhor",E17>=Fichas!$I20,E17<=Fichas!$I20),0,1)) | F32: =IF(OR(F17="",Fichas!$I20="",Fichas!$H20=""),"",IF(IF(Fichas!$H20="Maior é melhor",F17>=Fichas!$I20,F17<=Fichas!$I20),0,N(E32)+1)) | G32: =IF(OR(G17="",Fichas!$I20="",Fichas!$H20=""),"",IF(IF(Fichas!$H20="Maior é melhor",G17>=Fichas!$I20,G17<=Fichas!$I20),0,N(F32)+1)) | H32: =IF(OR(H17="",Fichas!$I20="",Fichas!$H20=""),"",IF(IF(Fichas!$H20="Maior é melhor",H17>=Fichas!$I20,H17<=Fichas!$I20),0,N(G32)+1)) | I32: =IF(OR(I17="",Fichas!$I20="",Fichas!$H20=""),"",IF(IF(Fichas!$H20="Maior é melhor",I17>=Fichas!$I20,I17<=Fichas!$I20),0,N(H32)+1)) | J32: =IF(OR(J17="",Fichas!$I20="",Fichas!$H20=""),"",IF(IF(Fichas!$H20="Maior é melhor",J17>=Fichas!$I20,J17<=Fichas!$I20),0,N(I32)+1)) | K32: =IF(OR(K17="",Fichas!$I20="",Fichas!$H20=""),"",IF(IF(Fichas!$H20="Maior é melhor",K17>=Fichas!$I20,K17<=Fichas!$I20),0,N(J32)+1)) | L32: =IF(OR(L17="",Fichas!$I20="",Fichas!$H20=""),"",IF(IF(Fichas!$H20="Maior é melhor",L17>=Fichas!$I20,L17<=Fichas!$I20),0,N(K32)+1)) | M32: =IF(OR(M17="",Fichas!$I20="",Fichas!$H20=""),"",IF(IF(Fichas!$H20="Maior é melhor",M17>=Fichas!$I20,M17<=Fichas!$I20),0,N(L32)+1)) | ... P32: =IF(OR(P17="",Fichas!$I20="",Fichas!$H20=""),"",IF(IF(Fichas!$H20="Maior é melhor",P17>=Fichas!$I20,P17<=Fichas!$I20),0,N(O32)+1)) | Q32: =IF(Q17=0,"",N(INDEX(E32:P32,Q17)))
B33: 12 | C33: =IF(Fichas!C21="","",Fichas!C21) | E33: =IF(OR(E18="",Fichas!$I21="",Fichas!$H21=""),"",IF(IF(Fichas!$H21="Maior é melhor",E18>=Fichas!$I21,E18<=Fichas!$I21),0,1)) | F33: =IF(OR(F18="",Fichas!$I21="",Fichas!$H21=""),"",IF(IF(Fichas!$H21="Maior é melhor",F18>=Fichas!$I21,F18<=Fichas!$I21),0,N(E33)+1)) | G33: =IF(OR(G18="",Fichas!$I21="",Fichas!$H21=""),"",IF(IF(Fichas!$H21="Maior é melhor",G18>=Fichas!$I21,G18<=Fichas!$I21),0,N(F33)+1)) | H33: =IF(OR(H18="",Fichas!$I21="",Fichas!$H21=""),"",IF(IF(Fichas!$H21="Maior é melhor",H18>=Fichas!$I21,H18<=Fichas!$I21),0,N(G33)+1)) | I33: =IF(OR(I18="",Fichas!$I21="",Fichas!$H21=""),"",IF(IF(Fichas!$H21="Maior é melhor",I18>=Fichas!$I21,I18<=Fichas!$I21),0,N(H33)+1)) | J33: =IF(OR(J18="",Fichas!$I21="",Fichas!$H21=""),"",IF(IF(Fichas!$H21="Maior é melhor",J18>=Fichas!$I21,J18<=Fichas!$I21),0,N(I33)+1)) | K33: =IF(OR(K18="",Fichas!$I21="",Fichas!$H21=""),"",IF(IF(Fichas!$H21="Maior é melhor",K18>=Fichas!$I21,K18<=Fichas!$I21),0,N(J33)+1)) | L33: =IF(OR(L18="",Fichas!$I21="",Fichas!$H21=""),"",IF(IF(Fichas!$H21="Maior é melhor",L18>=Fichas!$I21,L18<=Fichas!$I21),0,N(K33)+1)) | M33: =IF(OR(M18="",Fichas!$I21="",Fichas!$H21=""),"",IF(IF(Fichas!$H21="Maior é melhor",M18>=Fichas!$I21,M18<=Fichas!$I21),0,N(L33)+1)) | ... P33: =IF(OR(P18="",Fichas!$I21="",Fichas!$H21=""),"",IF(IF(Fichas!$H21="Maior é melhor",P18>=Fichas!$I21,P18<=Fichas!$I21),0,N(O33)+1)) | Q33: =IF(Q18=0,"",N(INDEX(E33:P33,Q18)))
B35: Resumo automático
B36: Indicadores com medição | D36: =COUNTIF(Q7:Q18,">0") -> 0
B37: Períodos com nome | D37: =COUNTA(E6:P6) -> 0
B38: Aviso | D38: =IF(D36=0,"Registre os resultados",IF(IF(Q7=0,0,COUNTBLANK(INDEX(E7:P7,1):INDEX(E7:P7,Q7)))+IF(Q8=0,0,COUNTBLANK(INDEX(E8:P8,1):INDEX(E8:P8,Q8)))+IF(Q9=0,0,COUNTBLANK(INDEX(E9:P9,1):INDEX(E9:P9,Q9)))+IF(Q10=0,0,COUNTBLANK(INDEX(E10:P10,1):INDEX(E10:P10,Q10)))+IF(Q11=0,0,COUNTBLANK(INDEX(E11:P11,1):INDEX(E11:P11,Q11)))+IF(Q12=0,0,COUNTBLANK(INDEX(E12:P12,1):INDEX(E12:P12,Q12)))+IF(Q13=0,0,COUNTBLANK(INDEX(E13:P13,1):INDEX(E13:P13,Q13)))+IF(Q14=0,0,COUNTBLANK(INDEX(E14:P14,1):INDEX(E14:P14,Q14)))+IF(Q15=0,0,COUNTBLANK(INDEX(E15:P15,1):INDEX(E15:P15,Q15)))+IF(Q16=0,0,COUNTBLANK(INDEX(E16:P16,1):INDEX(E16:P16,Q16)))+IF(Q17=0,0,COUNTBLANK(INDEX(E17:P17,1):INDEX(E17:P17,Q17)))+IF(Q18=0,0,COUNTBLANK(INDEX(E18:P18,1):INDEX(E18:P18,Q18)))>0,"Há coluna pulada: registre os resultados em sequência",IF(D37<MAX(Q7:Q18),"Há período sem nome",IF(SUMPRODUCT((Q7:Q18>0)*(Fichas!I10:I21=""))>0,"Há indicador medido sem meta","OK")))) -> Registre os resultados

Sheet Painel
B1: Painel de indicadores
B2: Leitura do último resultado de cada indicador. Calculado a partir das abas Fichas e Medições.
B4: Organização ou processo | D4: =IF(Fichas!D4="","",Fichas!D4) | I4: Atualizado em | L4: =IF(Fichas!K5="","",Fichas!K5)
B6: # | C6: Indicador | D6: Meta | E6: Limite de atenção | F6: Medições | G6: Último resultado | H6: Situação | I6: Média | J6: Seguidos fora da meta | K6: Média dos 3 anteriores | L6: Média dos 3 últimos | M6: Tendência | N6: Ação sugerida | O6: Sentido
B7: 1 | C7: =IF(Fichas!C10="","",Fichas!C10) | D7: =IF(Fichas!I10="","",Fichas!I10) | E7: =IF(Fichas!J10="","",Fichas!J10) | F7: =IF(C7="","",COUNT(Medições!$E$7:$P$7)) | G7: =IF(N(F7)=0,"",INDEX(Medições!$E$7:$P$7,F7)) | H7: =IF(OR(G7="",D7="",E7="",O7=""),"",IF(O7="Maior é melhor",IF(G7>=D7,"Na meta",IF(G7>=E7,"Atenção","Fora da meta")),IF(G7<=D7,"Na meta",IF(G7<=E7,"Atenção","Fora da meta")))) | I7: =IF(N(F7)=0,"",AVERAGE(Medições!$E$7:$P$7)) | J7: =IF(N(F7)=0,"",N(Medições!Q22)) | K7: =IF(N(F7)<6,"",AVERAGE(INDEX(Medições!$E$7:$P$7,F7-5):INDEX(Medições!$E$7:$P$7,F7-3))) | L7: =IF(N(F7)<6,"",AVERAGE(INDEX(Medições!$E$7:$P$7,F7-2):INDEX(Medições!$E$7:$P$7,F7))) | M7: =IF(N(F7)=0,"",IF(OR(F7="",F7<6),"Sem dados",IF(ABS(L7-K7)<=0.05*ABS(K7),"Estável",IF((L7>K7)=(O7="Maior é melhor"),"Melhorando","Piorando")))) | N7: =IF(H7="","",IF(N(J7)>=3,"Abrir análise de causa",IF(H7="Fora da meta","Analisar na reunião",IF(H7="Atenção","Acompanhar","Manter")))) | O7: =IF(Fichas!H10="","",Fichas!H10)
B8: 2 | C8: =IF(Fichas!C11="","",Fichas!C11) | D8: =IF(Fichas!I11="","",Fichas!I11) | E8: =IF(Fichas!J11="","",Fichas!J11) | F8: =IF(C8="","",COUNT(Medições!$E$8:$P$8)) | G8: =IF(N(F8)=0,"",INDEX(Medições!$E$8:$P$8,F8)) | H8: =IF(OR(G8="",D8="",E8="",O8=""),"",IF(O8="Maior é melhor",IF(G8>=D8,"Na meta",IF(G8>=E8,"Atenção","Fora da meta")),IF(G8<=D8,"Na meta",IF(G8<=E8,"Atenção","Fora da meta")))) | I8: =IF(N(F8)=0,"",AVERAGE(Medições!$E$8:$P$8)) | J8: =IF(N(F8)=0,"",N(Medições!Q23)) | K8: =IF(N(F8)<6,"",AVERAGE(INDEX(Medições!$E$8:$P$8,F8-5):INDEX(Medições!$E$8:$P$8,F8-3))) | L8: =IF(N(F8)<6,"",AVERAGE(INDEX(Medições!$E$8:$P$8,F8-2):INDEX(Medições!$E$8:$P$8,F8))) | M8: =IF(N(F8)=0,"",IF(OR(F8="",F8<6),"Sem dados",IF(ABS(L8-K8)<=0.05*ABS(K8),"Estável",IF((L8>K8)=(O8="Maior é melhor"),"Melhorando","Piorando")))) | N8: =IF(H8="","",IF(N(J8)>=3,"Abrir análise de causa",IF(H8="Fora da meta","Analisar na reunião",IF(H8="Atenção","Acompanhar","Manter")))) | O8: =IF(Fichas!H11="","",Fichas!H11)
B9: 3 | C9: =IF(Fichas!C12="","",Fichas!C12) | D9: =IF(Fichas!I12="","",Fichas!I12) | E9: =IF(Fichas!J12="","",Fichas!J12) | F9: =IF(C9="","",COUNT(Medições!$E$9:$P$9)) | G9: =IF(N(F9)=0,"",INDEX(Medições!$E$9:$P$9,F9)) | H9: =IF(OR(G9="",D9="",E9="",O9=""),"",IF(O9="Maior é melhor",IF(G9>=D9,"Na meta",IF(G9>=E9,"Atenção","Fora da meta")),IF(G9<=D9,"Na meta",IF(G9<=E9,"Atenção","Fora da meta")))) | I9: =IF(N(F9)=0,"",AVERAGE(Medições!$E$9:$P$9)) | J9: =IF(N(F9)=0,"",N(Medições!Q24)) | K9: =IF(N(F9)<6,"",AVERAGE(INDEX(Medições!$E$9:$P$9,F9-5):INDEX(Medições!$E$9:$P$9,F9-3))) | L9: =IF(N(F9)<6,"",AVERAGE(INDEX(Medições!$E$9:$P$9,F9-2):INDEX(Medições!$E$9:$P$9,F9))) | M9: =IF(N(F9)=0,"",IF(OR(F9="",F9<6),"Sem dados",IF(ABS(L9-K9)<=0.05*ABS(K9),"Estável",IF((L9>K9)=(O9="Maior é melhor"),"Melhorando","Piorando")))) | N9: =IF(H9="","",IF(N(J9)>=3,"Abrir análise de causa",IF(H9="Fora da meta","Analisar na reunião",IF(H9="Atenção","Acompanhar","Manter")))) | O9: =IF(Fichas!H12="","",Fichas!H12)
B10: 4 | C10: =IF(Fichas!C13="","",Fichas!C13) | D10: =IF(Fichas!I13="","",Fichas!I13) | E10: =IF(Fichas!J13="","",Fichas!J13) | F10: =IF(C10="","",COUNT(Medições!$E$10:$P$10)) | G10: =IF(N(F10)=0,"",INDEX(Medições!$E$10:$P$10,F10)) | H10: =IF(OR(G10="",D10="",E10="",O10=""),"",IF(O10="Maior é melhor",IF(G10>=D10,"Na meta",IF(G10>=E10,"Atenção","Fora da meta")),IF(G10<=D10,"Na meta",IF(G10<=E10,"Atenção","Fora da meta")))) | I10: =IF(N(F10)=0,"",AVERAGE(Medições!$E$10:$P$10)) | J10: =IF(N(F10)=0,"",N(Medições!Q25)) | K10: =IF(N(F10)<6,"",AVERAGE(INDEX(Medições!$E$10:$P$10,F10-5):INDEX(Medições!$E$10:$P$10,F10-3))) | L10: =IF(N(F10)<6,"",AVERAGE(INDEX(Medições!$E$10:$P$10,F10-2):INDEX(Medições!$E$10:$P$10,F10))) | M10: =IF(N(F10)=0,"",IF(OR(F10="",F10<6),"Sem dados",IF(ABS(L10-K10)<=0.05*ABS(K10),"Estável",IF((L10>K10)=(O10="Maior é melhor"),"Melhorando","Piorando")))) | N10: =IF(H10="","",IF(N(J10)>=3,"Abrir análise de causa",IF(H10="Fora da meta","Analisar na reunião",IF(H10="Atenção","Acompanhar","Manter")))) | O10: =IF(Fichas!H13="","",Fichas!H13)
B11: 5 | C11: =IF(Fichas!C14="","",Fichas!C14) | D11: =IF(Fichas!I14="","",Fichas!I14) | E11: =IF(Fichas!J14="","",Fichas!J14) | F11: =IF(C11="","",COUNT(Medições!$E$11:$P$11)) | G11: =IF(N(F11)=0,"",INDEX(Medições!$E$11:$P$11,F11)) | H11: =IF(OR(G11="",D11="",E11="",O11=""),"",IF(O11="Maior é melhor",IF(G11>=D11,"Na meta",IF(G11>=E11,"Atenção","Fora da meta")),IF(G11<=D11,"Na meta",IF(G11<=E11,"Atenção","Fora da meta")))) | I11: =IF(N(F11)=0,"",AVERAGE(Medições!$E$11:$P$11)) | J11: =IF(N(F11)=0,"",N(Medições!Q26)) | K11: =IF(N(F11)<6,"",AVERAGE(INDEX(Medições!$E$11:$P$11,F11-5):INDEX(Medições!$E$11:$P$11,F11-3))) | L11: =IF(N(F11)<6,"",AVERAGE(INDEX(Medições!$E$11:$P$11,F11-2):INDEX(Medições!$E$11:$P$11,F11))) | M11: =IF(N(F11)=0,"",IF(OR(F11="",F11<6),"Sem dados",IF(ABS(L11-K11)<=0.05*ABS(K11),"Estável",IF((L11>K11)=(O11="Maior é melhor"),"Melhorando","Piorando")))) | N11: =IF(H11="","",IF(N(J11)>=3,"Abrir análise de causa",IF(H11="Fora da meta","Analisar na reunião",IF(H11="Atenção","Acompanhar","Manter")))) | O11: =IF(Fichas!H14="","",Fichas!H14)
B12: 6 | C12: =IF(Fichas!C15="","",Fichas!C15) | D12: =IF(Fichas!I15="","",Fichas!I15) | E12: =IF(Fichas!J15="","",Fichas!J15) | F12: =IF(C12="","",COUNT(Medições!$E$12:$P$12)) | G12: =IF(N(F12)=0,"",INDEX(Medições!$E$12:$P$12,F12)) | H12: =IF(OR(G12="",D12="",E12="",O12=""),"",IF(O12="Maior é melhor",IF(G12>=D12,"Na meta",IF(G12>=E12,"Atenção","Fora da meta")),IF(G12<=D12,"Na meta",IF(G12<=E12,"Atenção","Fora da meta")))) | I12: =IF(N(F12)=0,"",AVERAGE(Medições!$E$12:$P$12)) | J12: =IF(N(F12)=0,"",N(Medições!Q27)) | K12: =IF(N(F12)<6,"",AVERAGE(INDEX(Medições!$E$12:$P$12,F12-5):INDEX(Medições!$E$12:$P$12,F12-3))) | L12: =IF(N(F12)<6,"",AVERAGE(INDEX(Medições!$E$12:$P$12,F12-2):INDEX(Medições!$E$12:$P$12,F12))) | M12: =IF(N(F12)=0,"",IF(OR(F12="",F12<6),"Sem dados",IF(ABS(L12-K12)<=0.05*ABS(K12),"Estável",IF((L12>K12)=(O12="Maior é melhor"),"Melhorando","Piorando")))) | N12: =IF(H12="","",IF(N(J12)>=3,"Abrir análise de causa",IF(H12="Fora da meta","Analisar na reunião",IF(H12="Atenção","Acompanhar","Manter")))) | O12: =IF(Fichas!H15="","",Fichas!H15)
B13: 7 | C13: =IF(Fichas!C16="","",Fichas!C16) | D13: =IF(Fichas!I16="","",Fichas!I16) | E13: =IF(Fichas!J16="","",Fichas!J16) | F13: =IF(C13="","",COUNT(Medições!$E$13:$P$13)) | G13: =IF(N(F13)=0,"",INDEX(Medições!$E$13:$P$13,F13)) | H13: =IF(OR(G13="",D13="",E13="",O13=""),"",IF(O13="Maior é melhor",IF(G13>=D13,"Na meta",IF(G13>=E13,"Atenção","Fora da meta")),IF(G13<=D13,"Na meta",IF(G13<=E13,"Atenção","Fora da meta")))) | I13: =IF(N(F13)=0,"",AVERAGE(Medições!$E$13:$P$13)) | J13: =IF(N(F13)=0,"",N(Medições!Q28)) | K13: =IF(N(F13)<6,"",AVERAGE(INDEX(Medições!$E$13:$P$13,F13-5):INDEX(Medições!$E$13:$P$13,F13-3))) | L13: =IF(N(F13)<6,"",AVERAGE(INDEX(Medições!$E$13:$P$13,F13-2):INDEX(Medições!$E$13:$P$13,F13))) | M13: =IF(N(F13)=0,"",IF(OR(F13="",F13<6),"Sem dados",IF(ABS(L13-K13)<=0.05*ABS(K13),"Estável",IF((L13>K13)=(O13="Maior é melhor"),"Melhorando","Piorando")))) | N13: =IF(H13="","",IF(N(J13)>=3,"Abrir análise de causa",IF(H13="Fora da meta","Analisar na reunião",IF(H13="Atenção","Acompanhar","Manter")))) | O13: =IF(Fichas!H16="","",Fichas!H16)
B14: 8 | C14: =IF(Fichas!C17="","",Fichas!C17) | D14: =IF(Fichas!I17="","",Fichas!I17) | E14: =IF(Fichas!J17="","",Fichas!J17) | F14: =IF(C14="","",COUNT(Medições!$E$14:$P$14)) | G14: =IF(N(F14)=0,"",INDEX(Medições!$E$14:$P$14,F14)) | H14: =IF(OR(G14="",D14="",E14="",O14=""),"",IF(O14="Maior é melhor",IF(G14>=D14,"Na meta",IF(G14>=E14,"Atenção","Fora da meta")),IF(G14<=D14,"Na meta",IF(G14<=E14,"Atenção","Fora da meta")))) | I14: =IF(N(F14)=0,"",AVERAGE(Medições!$E$14:$P$14)) | J14: =IF(N(F14)=0,"",N(Medições!Q29)) | K14: =IF(N(F14)<6,"",AVERAGE(INDEX(Medições!$E$14:$P$14,F14-5):INDEX(Medições!$E$14:$P$14,F14-3))) | L14: =IF(N(F14)<6,"",AVERAGE(INDEX(Medições!$E$14:$P$14,F14-2):INDEX(Medições!$E$14:$P$14,F14))) | M14: =IF(N(F14)=0,"",IF(OR(F14="",F14<6),"Sem dados",IF(ABS(L14-K14)<=0.05*ABS(K14),"Estável",IF((L14>K14)=(O14="Maior é melhor"),"Melhorando","Piorando")))) | N14: =IF(H14="","",IF(N(J14)>=3,"Abrir análise de causa",IF(H14="Fora da meta","Analisar na reunião",IF(H14="Atenção","Acompanhar","Manter")))) | O14: =IF(Fichas!H17="","",Fichas!H17)
B15: 9 | C15: =IF(Fichas!C18="","",Fichas!C18) | D15: =IF(Fichas!I18="","",Fichas!I18) | E15: =IF(Fichas!J18="","",Fichas!J18) | F15: =IF(C15="","",COUNT(Medições!$E$15:$P$15)) | G15: =IF(N(F15)=0,"",INDEX(Medições!$E$15:$P$15,F15)) | H15: =IF(OR(G15="",D15="",E15="",O15=""),"",IF(O15="Maior é melhor",IF(G15>=D15,"Na meta",IF(G15>=E15,"Atenção","Fora da meta")),IF(G15<=D15,"Na meta",IF(G15<=E15,"Atenção","Fora da meta")))) | I15: =IF(N(F15)=0,"",AVERAGE(Medições!$E$15:$P$15)) | J15: =IF(N(F15)=0,"",N(Medições!Q30)) | K15: =IF(N(F15)<6,"",AVERAGE(INDEX(Medições!$E$15:$P$15,F15-5):INDEX(Medições!$E$15:$P$15,F15-3))) | L15: =IF(N(F15)<6,"",AVERAGE(INDEX(Medições!$E$15:$P$15,F15-2):INDEX(Medições!$E$15:$P$15,F15))) | M15: =IF(N(F15)=0,"",IF(OR(F15="",F15<6),"Sem dados",IF(ABS(L15-K15)<=0.05*ABS(K15),"Estável",IF((L15>K15)=(O15="Maior é melhor"),"Melhorando","Piorando")))) | N15: =IF(H15="","",IF(N(J15)>=3,"Abrir análise de causa",IF(H15="Fora da meta","Analisar na reunião",IF(H15="Atenção","Acompanhar","Manter")))) | O15: =IF(Fichas!H18="","",Fichas!H18)
B16: 10 | C16: =IF(Fichas!C19="","",Fichas!C19) | D16: =IF(Fichas!I19="","",Fichas!I19) | E16: =IF(Fichas!J19="","",Fichas!J19) | F16: =IF(C16="","",COUNT(Medições!$E$16:$P$16)) | G16: =IF(N(F16)=0,"",INDEX(Medições!$E$16:$P$16,F16)) | H16: =IF(OR(G16="",D16="",E16="",O16=""),"",IF(O16="Maior é melhor",IF(G16>=D16,"Na meta",IF(G16>=E16,"Atenção","Fora da meta")),IF(G16<=D16,"Na meta",IF(G16<=E16,"Atenção","Fora da meta")))) | I16: =IF(N(F16)=0,"",AVERAGE(Medições!$E$16:$P$16)) | J16: =IF(N(F16)=0,"",N(Medições!Q31)) | K16: =IF(N(F16)<6,"",AVERAGE(INDEX(Medições!$E$16:$P$16,F16-5):INDEX(Medições!$E$16:$P$16,F16-3))) | L16: =IF(N(F16)<6,"",AVERAGE(INDEX(Medições!$E$16:$P$16,F16-2):INDEX(Medições!$E$16:$P$16,F16))) | M16: =IF(N(F16)=0,"",IF(OR(F16="",F16<6),"Sem dados",IF(ABS(L16-K16)<=0.05*ABS(K16),"Estável",IF((L16>K16)=(O16="Maior é melhor"),"Melhorando","Piorando")))) | N16: =IF(H16="","",IF(N(J16)>=3,"Abrir análise de causa",IF(H16="Fora da meta","Analisar na reunião",IF(H16="Atenção","Acompanhar","Manter")))) | O16: =IF(Fichas!H19="","",Fichas!H19)
B17: 11 | C17: =IF(Fichas!C20="","",Fichas!C20) | D17: =IF(Fichas!I20="","",Fichas!I20) | E17: =IF(Fichas!J20="","",Fichas!J20) | F17: =IF(C17="","",COUNT(Medições!$E$17:$P$17)) | G17: =IF(N(F17)=0,"",INDEX(Medições!$E$17:$P$17,F17)) | H17: =IF(OR(G17="",D17="",E17="",O17=""),"",IF(O17="Maior é melhor",IF(G17>=D17,"Na meta",IF(G17>=E17,"Atenção","Fora da meta")),IF(G17<=D17,"Na meta",IF(G17<=E17,"Atenção","Fora da meta")))) | I17: =IF(N(F17)=0,"",AVERAGE(Medições!$E$17:$P$17)) | J17: =IF(N(F17)=0,"",N(Medições!Q32)) | K17: =IF(N(F17)<6,"",AVERAGE(INDEX(Medições!$E$17:$P$17,F17-5):INDEX(Medições!$E$17:$P$17,F17-3))) | L17: =IF(N(F17)<6,"",AVERAGE(INDEX(Medições!$E$17:$P$17,F17-2):INDEX(Medições!$E$17:$P$17,F17))) | M17: =IF(N(F17)=0,"",IF(OR(F17="",F17<6),"Sem dados",IF(ABS(L17-K17)<=0.05*ABS(K17),"Estável",IF((L17>K17)=(O17="Maior é melhor"),"Melhorando","Piorando")))) | N17: =IF(H17="","",IF(N(J17)>=3,"Abrir análise de causa",IF(H17="Fora da meta","Analisar na reunião",IF(H17="Atenção","Acompanhar","Manter")))) | O17: =IF(Fichas!H20="","",Fichas!H20)
B18: 12 | C18: =IF(Fichas!C21="","",Fichas!C21) | D18: =IF(Fichas!I21="","",Fichas!I21) | E18: =IF(Fichas!J21="","",Fichas!J21) | F18: =IF(C18="","",COUNT(Medições!$E$18:$P$18)) | G18: =IF(N(F18)=0,"",INDEX(Medições!$E$18:$P$18,F18)) | H18: =IF(OR(G18="",D18="",E18="",O18=""),"",IF(O18="Maior é melhor",IF(G18>=D18,"Na meta",IF(G18>=E18,"Atenção","Fora da meta")),IF(G18<=D18,"Na meta",IF(G18<=E18,"Atenção","Fora da meta")))) | I18: =IF(N(F18)=0,"",AVERAGE(Medições!$E$18:$P$18)) | J18: =IF(N(F18)=0,"",N(Medições!Q33)) | K18: =IF(N(F18)<6,"",AVERAGE(INDEX(Medições!$E$18:$P$18,F18-5):INDEX(Medições!$E$18:$P$18,F18-3))) | L18: =IF(N(F18)<6,"",AVERAGE(INDEX(Medições!$E$18:$P$18,F18-2):INDEX(Medições!$E$18:$P$18,F18))) | M18: =IF(N(F18)=0,"",IF(OR(F18="",F18<6),"Sem dados",IF(ABS(L18-K18)<=0.05*ABS(K18),"Estável",IF((L18>K18)=(O18="Maior é melhor"),"Melhorando","Piorando")))) | N18: =IF(H18="","",IF(N(J18)>=3,"Abrir análise de causa",IF(H18="Fora da meta","Analisar na reunião",IF(H18="Atenção","Acompanhar","Manter")))) | O18: =IF(Fichas!H21="","",Fichas!H21)
B20: Resumo automático
B21: Indicadores com resultado | D21: =COUNTIF(F7:F18,">0") -> 0
B22: Na meta | D22: =COUNTIF(H7:H18,"Na meta") -> 0
B23: Atenção | D23: =COUNTIF(H7:H18,"Atenção") -> 0
B24: Fora da meta | D24: =COUNTIF(H7:H18,"Fora da meta") -> 0
B25: Com análise de causa sugerida | D25: =COUNTIF(N7:N18,"Abrir análise de causa") -> 0
B26: Aviso | D26: =IF(D21=0,"Registre os resultados na aba Medições",IF(Medições!D38<>"OK",Medições!D38,IF(D25>0,"Há indicador que pede análise de causa",IF(D24>0,"Há indicador fora da meta","OK")))) -> Registre os resultados na aba Medições
B28: Gráfico de um indicador
B29: Indicador do gráfico, de 1 a 12 | D29: 1 | E29: =IF(D29="","Informe o número do indicador",IF(INDEX(C7:C18,D29)="","Indicador sem cadastro",INDEX(C7:C18,D29))) -> Indicador sem cadastro
B30: Período | D30: =IF(Medições!E6="","",Medições!E6&"") | E30: =IF(Medições!F6="","",Medições!F6&"") | F30: =IF(Medições!G6="","",Medições!G6&"") | G30: =IF(Medições!H6="","",Medições!H6&"") | H30: =IF(Medições!I6="","",Medições!I6&"") | I30: =IF(Medições!J6="","",Medições!J6&"") | J30: =IF(Medições!K6="","",Medições!K6&"") | K30: =IF(Medições!L6="","",Medições!L6&"") | ... O30: =IF(Medições!P6="","",Medições!P6&"")
B31: Resultado | D31: =IF(N($D$29)=0,NA(),IF(INDEX(Medições!E7:E18,N($D$29))="",NA(),INDEX(Medições!E7:E18,N($D$29)))) -> #N/A | E31: =IF(N($D$29)=0,NA(),IF(INDEX(Medições!F7:F18,N($D$29))="",NA(),INDEX(Medições!F7:F18,N($D$29)))) -> #N/A | F31: =IF(N($D$29)=0,NA(),IF(INDEX(Medições!G7:G18,N($D$29))="",NA(),INDEX(Medições!G7:G18,N($D$29)))) -> #N/A | G31: =IF(N($D$29)=0,NA(),IF(INDEX(Medições!H7:H18,N($D$29))="",NA(),INDEX(Medições!H7:H18,N($D$29)))) -> #N/A | H31: =IF(N($D$29)=0,NA(),IF(INDEX(Medições!I7:I18,N($D$29))="",NA(),INDEX(Medições!I7:I18,N($D$29)))) -> #N/A | I31: =IF(N($D$29)=0,NA(),IF(INDEX(Medições!J7:J18,N($D$29))="",NA(),INDEX(Medições!J7:J18,N($D$29)))) -> #N/A | J31: =IF(N($D$29)=0,NA(),IF(INDEX(Medições!K7:K18,N($D$29))="",NA(),INDEX(Medições!K7:K18,N($D$29)))) -> #N/A | K31: =IF(N($D$29)=0,NA(),IF(INDEX(Medições!L7:L18,N($D$29))="",NA(),INDEX(Medições!L7:L18,N($D$29)))) -> #N/A | ... O31: =IF(N($D$29)=0,NA(),IF(INDEX(Medições!P7:P18,N($D$29))="",NA(),INDEX(Medições!P7:P18,N($D$29)))) -> #N/A
B32: Meta | D32: =IF(N($D$29)=0,NA(),IF(OR(INDEX(D$7:D$18,N($D$29))="",ISNA(D31)),NA(),INDEX(D$7:D$18,N($D$29)))) -> #N/A | E32: =IF(N($D$29)=0,NA(),IF(OR(INDEX(D$7:D$18,N($D$29))="",ISNA(E31)),NA(),INDEX(D$7:D$18,N($D$29)))) -> #N/A | F32: =IF(N($D$29)=0,NA(),IF(OR(INDEX(D$7:D$18,N($D$29))="",ISNA(F31)),NA(),INDEX(D$7:D$18,N($D$29)))) -> #N/A | G32: =IF(N($D$29)=0,NA(),IF(OR(INDEX(D$7:D$18,N($D$29))="",ISNA(G31)),NA(),INDEX(D$7:D$18,N($D$29)))) -> #N/A | H32: =IF(N($D$29)=0,NA(),IF(OR(INDEX(D$7:D$18,N($D$29))="",ISNA(H31)),NA(),INDEX(D$7:D$18,N($D$29)))) -> #N/A | I32: =IF(N($D$29)=0,NA(),IF(OR(INDEX(D$7:D$18,N($D$29))="",ISNA(I31)),NA(),INDEX(D$7:D$18,N($D$29)))) -> #N/A | J32: =IF(N($D$29)=0,NA(),IF(OR(INDEX(D$7:D$18,N($D$29))="",ISNA(J31)),NA(),INDEX(D$7:D$18,N($D$29)))) -> #N/A | K32: =IF(N($D$29)=0,NA(),IF(OR(INDEX(D$7:D$18,N($D$29))="",ISNA(K31)),NA(),INDEX(D$7:D$18,N($D$29)))) -> #N/A | L32: =IF(N($D$29)=0,NA(),IF(OR(INDEX(D$7:D$18,N($D$29))="",ISNA(L31)),NA(),INDEX(D$7:D$18,N($D$29)))) -> #N/A | M32: =IF(N($D$29)=0,NA(),IF(OR(INDEX(D$7:D$18,N($D$29))="",ISNA(M31)),NA(),INDEX(D$7:D$18,N($D$29)))) -> #N/A | N32: =IF(N($D$29)=0,NA(),IF(OR(INDEX(D$7:D$18,N($D$29))="",ISNA(N31)),NA(),INDEX(D$7:D$18,N($D$29)))) -> #N/A | O32: =IF(N($D$29)=0,NA(),IF(OR(INDEX(D$7:D$18,N($D$29))="",ISNA(O31)),NA(),INDEX(D$7:D$18,N($D$29)))) -> #N/A
B33: Limite de atenção | D33: =IF(N($D$29)=0,NA(),IF(OR(INDEX(E$7:E$18,N($D$29))="",ISNA(D31)),NA(),INDEX(E$7:E$18,N($D$29)))) -> #N/A | E33: =IF(N($D$29)=0,NA(),IF(OR(INDEX(E$7:E$18,N($D$29))="",ISNA(E31)),NA(),INDEX(E$7:E$18,N($D$29)))) -> #N/A | F33: =IF(N($D$29)=0,NA(),IF(OR(INDEX(E$7:E$18,N($D$29))="",ISNA(F31)),NA(),INDEX(E$7:E$18,N($D$29)))) -> #N/A | G33: =IF(N($D$29)=0,NA(),IF(OR(INDEX(E$7:E$18,N($D$29))="",ISNA(G31)),NA(),INDEX(E$7:E$18,N($D$29)))) -> #N/A | H33: =IF(N($D$29)=0,NA(),IF(OR(INDEX(E$7:E$18,N($D$29))="",ISNA(H31)),NA(),INDEX(E$7:E$18,N($D$29)))) -> #N/A | I33: =IF(N($D$29)=0,NA(),IF(OR(INDEX(E$7:E$18,N($D$29))="",ISNA(I31)),NA(),INDEX(E$7:E$18,N($D$29)))) -> #N/A | J33: =IF(N($D$29)=0,NA(),IF(OR(INDEX(E$7:E$18,N($D$29))="",ISNA(J31)),NA(),INDEX(E$7:E$18,N($D$29)))) -> #N/A | K33: =IF(N($D$29)=0,NA(),IF(OR(INDEX(E$7:E$18,N($D$29))="",ISNA(K31)),NA(),INDEX(E$7:E$18,N($D$29)))) -> #N/A | L33: =IF(N($D$29)=0,NA(),IF(OR(INDEX(E$7:E$18,N($D$29))="",ISNA(L31)),NA(),INDEX(E$7:E$18,N($D$29)))) -> #N/A | M33: =IF(N($D$29)=0,NA(),IF(OR(INDEX(E$7:E$18,N($D$29))="",ISNA(M31)),NA(),INDEX(E$7:E$18,N($D$29)))) -> #N/A | N33: =IF(N($D$29)=0,NA(),IF(OR(INDEX(E$7:E$18,N($D$29))="",ISNA(N31)),NA(),INDEX(E$7:E$18,N($D$29)))) -> #N/A | O33: =IF(N($D$29)=0,NA(),IF(OR(INDEX(E$7:E$18,N($D$29))="",ISNA(O31)),NA(),INDEX(E$7:E$18,N($D$29)))) -> #N/A

Sheet Análise
B1: Registro das reuniões de análise
B2: Uma linha por decisão. Todo indicador fora da meta tem decisão registrada, com responsável e prazo.
B4: # | C4: Data da reunião | D4: Indicador | E4: Nome do indicador | F4: O que os dados mostram | G4: Causa provável | H4: Decisão | I4: Responsável | J4: Prazo | K4: Status | L4: Situação
C5: Data | D5: Número, de 1 a 12 | E5: Calculado | F5: O fato, com números | G5: Hipótese, a confirmar | H5: Verbo no infinitivo | I5: Cargo ou nome | J5: Data | K5: Da decisão | L5: Calculada
B6: Ex. | C6: 46303 | D6: 1 | E6: Prazo de atendimento das requisições | F6: Cinco meses seguidos acima da meta, com pico de 6,2 dias em agosto. | G6: Requisições incompletas voltam ao requisitante e entram de novo na fila. | H6: Tratar junto com o RNC 2026-31. | I6: Gerente de Suprimentos | J6: 46318 | K6: Em andamento | L6: No prazo
B7: 1 | E7: =IF(D7="","",IF(INDEX(Painel!$C$7:$C$18,D7)="","Indicador sem cadastro",INDEX(Painel!$C$7:$C$18,D7))) | L7: =IF(H7="","",IF(K7="Concluída","Concluída",IF(J7="","Sem prazo",IF(J7<TODAY(),"Atrasada","No prazo"))))
B8: 2 | E8: =IF(D8="","",IF(INDEX(Painel!$C$7:$C$18,D8)="","Indicador sem cadastro",INDEX(Painel!$C$7:$C$18,D8))) | L8: =IF(H8="","",IF(K8="Concluída","Concluída",IF(J8="","Sem prazo",IF(J8<TODAY(),"Atrasada","No prazo"))))
B9: 3 | E9: =IF(D9="","",IF(INDEX(Painel!$C$7:$C$18,D9)="","Indicador sem cadastro",INDEX(Painel!$C$7:$C$18,D9))) | L9: =IF(H9="","",IF(K9="Concluída","Concluída",IF(J9="","Sem prazo",IF(J9<TODAY(),"Atrasada","No prazo"))))
B10: 4 | E10: =IF(D10="","",IF(INDEX(Painel!$C$7:$C$18,D10)="","Indicador sem cadastro",INDEX(Painel!$C$7:$C$18,D10))) | L10: =IF(H10="","",IF(K10="Concluída","Concluída",IF(J10="","Sem prazo",IF(J10<TODAY(),"Atrasada","No prazo"))))
B11: 5 | E11: =IF(D11="","",IF(INDEX(Painel!$C$7:$C$18,D11)="","Indicador sem cadastro",INDEX(Painel!$C$7:$C$18,D11))) | L11: =IF(H11="","",IF(K11="Concluída","Concluída",IF(J11="","Sem prazo",IF(J11<TODAY(),"Atrasada","No prazo"))))
B12: 6 | E12: =IF(D12="","",IF(INDEX(Painel!$C$7:$C$18,D12)="","Indicador sem cadastro",INDEX(Painel!$C$7:$C$18,D12))) | L12: =IF(H12="","",IF(K12="Concluída","Concluída",IF(J12="","Sem prazo",IF(J12<TODAY(),"Atrasada","No prazo"))))
B13: 7 | E13: =IF(D13="","",IF(INDEX(Painel!$C$7:$C$18,D13)="","Indicador sem cadastro",INDEX(Painel!$C$7:$C$18,D13))) | L13: =IF(H13="","",IF(K13="Concluída","Concluída",IF(J13="","Sem prazo",IF(J13<TODAY(),"Atrasada","No prazo"))))
B14: 8 | E14: =IF(D14="","",IF(INDEX(Painel!$C$7:$C$18,D14)="","Indicador sem cadastro",INDEX(Painel!$C$7:$C$18,D14))) | L14: =IF(H14="","",IF(K14="Concluída","Concluída",IF(J14="","Sem prazo",IF(J14<TODAY(),"Atrasada","No prazo"))))
B15: 9 | E15: =IF(D15="","",IF(INDEX(Painel!$C$7:$C$18,D15)="","Indicador sem cadastro",INDEX(Painel!$C$7:$C$18,D15))) | L15: =IF(H15="","",IF(K15="Concluída","Concluída",IF(J15="","Sem prazo",IF(J15<TODAY(),"Atrasada","No prazo"))))
B16: 10 | E16: =IF(D16="","",IF(INDEX(Painel!$C$7:$C$18,D16)="","Indicador sem cadastro",INDEX(Painel!$C$7:$C$18,D16))) | L16: =IF(H16="","",IF(K16="Concluída","Concluída",IF(J16="","Sem prazo",IF(J16<TODAY(),"Atrasada","No prazo"))))
B17: 11 | E17: =IF(D17="","",IF(INDEX(Painel!$C$7:$C$18,D17)="","Indicador sem cadastro",INDEX(Painel!$C$7:$C$18,D17))) | L17: =IF(H17="","",IF(K17="Concluída","Concluída",IF(J17="","Sem prazo",IF(J17<TODAY(),"Atrasada","No prazo"))))
B18: 12 | E18: =IF(D18="","",IF(INDEX(Painel!$C$7:$C$18,D18)="","Indicador sem cadastro",INDEX(Painel!$C$7:$C$18,D18))) | L18: =IF(H18="","",IF(K18="Concluída","Concluída",IF(J18="","Sem prazo",IF(J18<TODAY(),"Atrasada","No prazo"))))
... B21: 15 | E21: =IF(D21="","",IF(INDEX(Painel!$C$7:$C$18,D21)="","Indicador sem cadastro",INDEX(Painel!$C$7:$C$18,D21))) | L21: =IF(H21="","",IF(K21="Concluída","Concluída",IF(J21="","Sem prazo",IF(J21<TODAY(),"Atrasada","No prazo"))))
B23: Resumo automático
B24: Decisões registradas | F24: =COUNTA(H7:H21) -> 0
B25: Concluídas | F25: =COUNTIF(L7:L21,"Concluída") -> 0
B26: Atrasadas | F26: =COUNTIF(L7:L21,"Atrasada") -> 0
B27: Indicadores que pedem análise de causa | F27: =COUNTIF(Painel!$N$7:$N$18,"Abrir análise de causa") -> 0
B28: Desses, sem registro nesta aba | F28: =SUMPRODUCT((Painel!$N$7:$N$18="Abrir análise de causa")*(COUNTIF($D$7:$D$21,Painel!$B$7:$B$18)=0)) -> 0
B29: Aviso | F29: =IF(F28>0,"Há indicador que pede análise de causa sem decisão registrada",IF(SUMPRODUCT((H7:H21<>"")*(((D7:D21="")+(I7:I21="")+(J7:J21=""))>0))>0,"Há decisão sem indicador, responsável ou prazo",IF(F26>0,"Há decisão atrasada",IF(F24=0,"Sem decisões registradas","OK")))) -> Sem decisões registradas

Sheet Checklist
B1: Checklist de validação dos indicadores
B2: Escolha o status de cada item na lista suspensa (coluna em amarelo-claro).
B4: # | C4: Item de verificação | D4: Status | E4: Observações
B5: 1 | C5: Cada indicador está ligado a um objetivo ou a um processo.
B6: 2 | C6: A fórmula está escrita, com o que se divide, por quanto e em que unidade.
B7: 3 | C7: A fonte dos dados e o responsável pela coleta estão definidos.
B8: 4 | C8: A frequência de medição acompanha a velocidade do processo.
B9: 5 | C9: A meta tem valor, sentido e prazo.
B10: 6 | C10: A meta foi definida a partir do histórico ou de um requisito.
B11: 7 | C11: O limite de atenção está definido.
B12: 8 | C12: O conjunto de indicadores cabe em uma página.
B13: 9 | C13: Os resultados são apresentados em gráfico, com a meta.
B14: 10 | C14: Os resultados são analisados em reunião, com data marcada.
B15: 11 | C15: Cada indicador fora da meta tem decisão registrada, com responsável e prazo.
B16: 12 | C16: Os indicadores e as metas são revistos pelo menos uma vez por ano.
B18: Resumo automático
B19: Itens atendidos (Sim) | D19: =COUNTIF(D5:D16,"Sim") -> 0
B20: Itens parciais | D20: =COUNTIF(D5:D16,"Parcial") -> 0
B21: Itens não atendidos | D21: =COUNTIF(D5:D16,"Não") -> 0
B22: Itens sem resposta | D22: =COUNTBLANK(D5:D16) -> 12
B23: Percentual atendido | D23: =D19/ROWS(D5:D16) -> 0
B24: Situação | D24: =IF(D19=ROWS(D5:D16),"Validado",IF(D22>0,"Em andamento","Com pendências")) -> Em andamento

Sheet Exemplo 1 - Pizzaria
B1: Painel de indicadores
B2: Exemplo preenchido, para consulta. Use as abas Fichas, Medições, Painel e Análise para os seus indicadores.
B4: Organização | D4: Pizzaria (loja com salão e delivery)
B5: Período | D5: Outubro de 2025 a setembro de 2026
B6: Responsável | D6: Gerente da loja
B7: Reunião de análise | D7: Toda segunda-feira, com fechamento mensal
B8: Situação em | D8: 46301
B10: Fichas dos indicadores
B11: Nº | C11: Indicador | D11: Objetivo | H11: Fórmula | M11: Unidade | O11: Meta | P11: Limite | Q11: Sentido | R11: Responsável
B12: P1 | C12: Entregas em até 40 minutos | D12: Entregar o pedido no prazo prometido | H12: Pedidos entregues em até 40 minutos ÷ pedidos entregues × 100 | M12: % | O12: 95 | P12: 90 | Q12: Maior é melhor | R12: Líder da expedição
B13: P2 | C13: Reclamações por 100 pedidos | D13: Reduzir as reclamações dos clientes | H13: Reclamações registradas ÷ pedidos entregues × 100 | M13: por 100 pedidos | O13: 2 | P13: 3 | Q13: Menor é melhor | R13: Atendente líder
B14: P3 | C14: Pedidos refeitos por erro | D14: Entregar o pedido certo na primeira vez | H14: Pedidos refeitos ÷ pedidos produzidos × 100 | M14: % | O14: 1.5 | P14: 2.5 | Q14: Menor é melhor | R14: Pizzaiolo líder
B15: P4 | C15: Desperdício de insumos | D15: Reduzir o custo sem mexer na receita | H15: Custo dos insumos descartados ÷ custo dos insumos comprados × 100 | M15: % | O15: 4 | P15: 5 | Q15: Menor é melhor | R15: Gerente da loja
B17: Medições
B18: Nº | C18: Indicador | D18: Out/25 | E18: Nov/25 | F18: Dez/25 | G18: Jan/26 | H18: Fev/26 | I18: Mar/26 | J18: Abr/26 | K18: Mai/26 | L18: Jun/26 | M18: Jul/26 | N18: Ago/26 | O18: Set/26 | P18: Média | Q18: Seguidos fora
B19: P1 | C19: Entregas em até 40 minutos | D19: 81 | E19: 83 | F19: 80 | G19: 82 | H19: 82 | I19: 83 | J19: 82 | K19: 84 | L19: 88 | M19: 94 | N19: 96 | O19: 95 | P19: =AVERAGE(D19:O19) -> 85.833333 | Q19: =O25 -> 0
B20: P2 | C20: Reclamações por 100 pedidos | D20: 3.4 | E20: 3.1 | F20: 3.8 | G20: 3.2 | H20: 3 | I20: 3.1 | J20: 2.9 | K20: 2.6 | L20: 2.2 | M20: 1.8 | N20: 1.6 | O20: 1.9 | P20: =AVERAGE(D20:O20) -> 2.7166667 | Q20: =O26 -> 0
B21: P3 | C21: Pedidos refeitos por erro | D21: 2.1 | E21: 1.9 | F21: 2.4 | G21: 1.8 | H21: 1.7 | I21: 1.6 | J21: 1.4 | K21: 1.5 | L21: 1.3 | M21: 1.6 | N21: 1.8 | O21: 2 | P21: =AVERAGE(D21:O21) -> 1.7583333 | Q21: =O27 -> 3
B22: P4 | C22: Desperdício de insumos | D22: 4.8 | E22: 4.6 | F22: 5.2 | G22: 4.5 | H22: 4.3 | I22: 4.4 | J22: 4.1 | K22: 4.2 | L22: 3.9 | M22: 4 | N22: 3.8 | O22: 3.9 | P22: =AVERAGE(D22:O22) -> 4.3083333 | Q22: =O28 -> 0
B24: Períodos seguidos fora da meta
B25: P1 | C25: Entregas em até 40 minutos | D25: =IF(IF($Q12="Maior é melhor",D19>=$O12,D19<=$O12),0,1) -> 1 | E25: =IF(IF($Q12="Maior é melhor",E19>=$O12,E19<=$O12),0,N(D25)+1) -> 2 | F25: =IF(IF($Q12="Maior é melhor",F19>=$O12,F19<=$O12),0,N(E25)+1) -> 3 | G25: =IF(IF($Q12="Maior é melhor",G19>=$O12,G19<=$O12),0,N(F25)+1) -> 4 | H25: =IF(IF($Q12="Maior é melhor",H19>=$O12,H19<=$O12),0,N(G25)+1) -> 5 | I25: =IF(IF($Q12="Maior é melhor",I19>=$O12,I19<=$O12),0,N(H25)+1) -> 6 | J25: =IF(IF($Q12="Maior é melhor",J19>=$O12,J19<=$O12),0,N(I25)+1) -> 7 | K25: =IF(IF($Q12="Maior é melhor",K19>=$O12,K19<=$O12),0,N(J25)+1) -> 8 | L25: =IF(IF($Q12="Maior é melhor",L19>=$O12,L19<=$O12),0,N(K25)+1) -> 9 | ... O25: =IF(IF($Q12="Maior é melhor",O19>=$O12,O19<=$O12),0,N(N25)+1) -> 0
B26: P2 | C26: Reclamações por 100 pedidos | D26: =IF(IF($Q13="Maior é melhor",D20>=$O13,D20<=$O13),0,1) -> 1 | E26: =IF(IF($Q13="Maior é melhor",E20>=$O13,E20<=$O13),0,N(D26)+1) -> 2 | F26: =IF(IF($Q13="Maior é melhor",F20>=$O13,F20<=$O13),0,N(E26)+1) -> 3 | G26: =IF(IF($Q13="Maior é melhor",G20>=$O13,G20<=$O13),0,N(F26)+1) -> 4 | H26: =IF(IF($Q13="Maior é melhor",H20>=$O13,H20<=$O13),0,N(G26)+1) -> 5 | I26: =IF(IF($Q13="Maior é melhor",I20>=$O13,I20<=$O13),0,N(H26)+1) -> 6 | J26: =IF(IF($Q13="Maior é melhor",J20>=$O13,J20<=$O13),0,N(I26)+1) -> 7 | K26: =IF(IF($Q13="Maior é melhor",K20>=$O13,K20<=$O13),0,N(J26)+1) -> 8 | L26: =IF(IF($Q13="Maior é melhor",L20>=$O13,L20<=$O13),0,N(K26)+1) -> 9 | ... O26: =IF(IF($Q13="Maior é melhor",O20>=$O13,O20<=$O13),0,N(N26)+1) -> 0
B27: P3 | C27: Pedidos refeitos por erro | D27: =IF(IF($Q14="Maior é melhor",D21>=$O14,D21<=$O14),0,1) -> 1 | E27: =IF(IF($Q14="Maior é melhor",E21>=$O14,E21<=$O14),0,N(D27)+1) -> 2 | F27: =IF(IF($Q14="Maior é melhor",F21>=$O14,F21<=$O14),0,N(E27)+1) -> 3 | G27: =IF(IF($Q14="Maior é melhor",G21>=$O14,G21<=$O14),0,N(F27)+1) -> 4 | H27: =IF(IF($Q14="Maior é melhor",H21>=$O14,H21<=$O14),0,N(G27)+1) -> 5 | I27: =IF(IF($Q14="Maior é melhor",I21>=$O14,I21<=$O14),0,N(H27)+1) -> 6 | J27: =IF(IF($Q14="Maior é melhor",J21>=$O14,J21<=$O14),0,N(I27)+1) -> 0 | K27: =IF(IF($Q14="Maior é melhor",K21>=$O14,K21<=$O14),0,N(J27)+1) -> 0 | L27: =IF(IF($Q14="Maior é melhor",L21>=$O14,L21<=$O14),0,N(K27)+1) -> 0 | ... O27: =IF(IF($Q14="Maior é melhor",O21>=$O14,O21<=$O14),0,N(N27)+1) -> 3
B28: P4 | C28: Desperdício de insumos | D28: =IF(IF($Q15="Maior é melhor",D22>=$O15,D22<=$O15),0,1) -> 1 | E28: =IF(IF($Q15="Maior é melhor",E22>=$O15,E22<=$O15),0,N(D28)+1) -> 2 | F28: =IF(IF($Q15="Maior é melhor",F22>=$O15,F22<=$O15),0,N(E28)+1) -> 3 | G28: =IF(IF($Q15="Maior é melhor",G22>=$O15,G22<=$O15),0,N(F28)+1) -> 4 | H28: =IF(IF($Q15="Maior é melhor",H22>=$O15,H22<=$O15),0,N(G28)+1) -> 5 | I28: =IF(IF($Q15="Maior é melhor",I22>=$O15,I22<=$O15),0,N(H28)+1) -> 6 | J28: =IF(IF($Q15="Maior é melhor",J22>=$O15,J22<=$O15),0,N(I28)+1) -> 7 | K28: =IF(IF($Q15="Maior é melhor",K22>=$O15,K22<=$O15),0,N(J28)+1) -> 8 | L28: =IF(IF($Q15="Maior é melhor",L22>=$O15,L22<=$O15),0,N(K28)+1) -> 0 | ... O28: =IF(IF($Q15="Maior é melhor",O22>=$O15,O22<=$O15),0,N(N28)+1) -> 0
B30: Painel
