Workbook

Sheet Instruções
B1: Projeto e desenvolvimento — Como usar esta planilha
B2: Modelo para planejar o projeto, ligar as entradas às saídas e às verificações, registrar os controles e as mudanças, e decidir a liberação.
B4: Legenda: onde preencher
B5: Amarelo-claro | C5: Células de entrada. É aqui que você digita.
B6: Cinza | C6: Células calculadas ou fixas (rótulos, conferências, contagens, avisos). Não altere.
B7: Cinza em itálico | C7: Linha de exemplo (marcada com “Ex.”). Mostra o formato esperado e não entra nas contagens.
B8: Listas suspensas | C8: Tipo da etapa, resultado, tipo da entrada, resultado da verificação e checklist aceitam apenas as opções da lista.
B9: Comentários | C9: Células com triângulo vermelho no canto trazem uma dica de preenchimento. Passe o mouse sobre elas.
B11: As regras de cálculo
B12: Atrasada | C12: Etapa sem data de conclusão, com o prazo anterior à data da leitura, informada na aba Plano.
B13: Falta a ação | C13: Etapa com o resultado “Aprovado com ressalvas” ou “Reprovado”, sem a ação registrada.
B14: Liberado sem validação aprovada | C14: Etapa de “Liberação para produção” concluída sem nenhuma etapa de “Validação” aprovada, com ou sem ressalvas.
B15: Verificação pendente | C15: Entrada com tudo preenchido, sem o resultado da verificação.
B16: Não atende | C16: Com a ação escrita na coluna Evidência ou ação, a conferência mostra a ação em curso. Sem ela, pede a ação.
B17: Pode liberar? | C17: Sim quando há validação aprovada, todas as entradas atendem, nenhuma mudança está a rever e nenhuma etapa está atrasada ou a rever.
B19: Ordem recomendada de preenchimento
B20: Passo 1 | C20: Aba Plano: escreva o projeto, o objetivo, o cliente ou o usuário, o responsável, as datas e a data da leitura.
B21: Passo 2 | C21: Aba Plano: liste as etapas, com tipo, responsável, participantes e prazo. Inclua análises críticas, verificações e validações.
B22: Passo 3 | C22: Aba Entradas: escreva as entradas pelos sete tipos, com a fonte, a saída que atende e como verificar.
B23: Passo 4 | C23: Abas Plano e Entradas: conforme o projeto anda, lance as conclusões, os resultados, as ações e as evidências.
B24: Passo 5 | C24: Aba Mudanças: registre toda alteração em entrada ou saída já aprovada, com a análise, o que foi verificado de novo e quem autorizou.
B25: Passo 6 | C25: Aba Painel: leia as pendências e a resposta à pergunta “pode liberar?”. Depois, valide na aba Checklist.
B27: Abas da planilha
B28: Plano | C28: O projeto e até 20 etapas. Calcula a conferência de cada etapa e se o plano tem os três controles.
B29: Entradas | C29: Até 30 entradas, ligadas às saídas e às verificações. Calcula a conferência de cada entrada.
B30: Mudanças | C30: Até 20 mudanças de projeto. Calcula a conferência de cada uma.
B31: Painel | C31: Os indicadores, os controles, as entradas por tipo, o gráfico e a decisão de liberar.
B32: Checklist | C32: Doze verificações do processo de projeto, com percentual de conclusão.
B33: Exemplo 1 - Pizzaria | C33: A pizza vegana do cardápio de inverno, lida em 31/05/2027.
B34: Exemplo 2 - Indústria | C34: O filme para vegetais congelados, lido em 30/08/2027.
B36: Regras e premissas do modelo
B37: Tamanho do controle | C37: Um projeto pequeno pode ter cinco etapas e seis entradas. O que não pode faltar é ao menos uma verificação, uma validação e uma análise crítica.
B38: Resultado da etapa | C38: Use “Aprovado”, “Aprovado com ressalvas” ou “Reprovado” para todas as etapas concluídas, inclusive as de desenvolvimento.
B39: Entrada nova | C39: A entrada que aparece durante o projeto, por exemplo na validação, entra na lista com a fonte que a revelou.
B40: Exemplos | C40: Os dados das abas de exemplo são ilustrativos, criados para este material.

Sheet Plano
B1: Plano do projeto
B2: O projeto no alto. Abaixo, as etapas, com os três controles: análise crítica, verificação e validação.
B4: Organização
B5: Projeto
B6: Objetivo
B7: Cliente ou usuário
B8: Responsável e aprovação
B9: Início | E9: Liberação prevista
B10: Data da leitura | E10: Usada para saber o que está atrasado. Atualize a cada leitura.
B12: # | C12: Etapa | D12: Tipo | E12: Responsável | F12: Participantes | G12: Prazo | H12: Concluída em | I12: Resultado | J12: Ações e ressalvas | K12: Registro | L12: Conferência
C13: O que será feito | D13: Lista | E13: Uma função | F13: Áreas, cliente | G13: Data | H13: Data | I13: Lista | J13: Obrigatórias com ressalva ou reprovação | K13: Ata, relatório | L13: Calculada
B14: 1 | L14: =IF(C14="",IF(COUNTA(D14:K14)>0,"Falta a etapa",""),IF(D14="","Falta o tipo",IF(E14="","Falta o responsável",IF(G14="","Falta o prazo",IF(AND(H14<>"",I14=""),"Falta o resultado",IF(AND(I14<>"",H14=""),"Falta a data de conclusão",IF(AND(OR(I14="Aprovado com ressalvas",I14="Reprovado"),J14=""),"Falta a ação",IF(AND(D14="Liberação para produção",H14<>"",COUNTIFS($D$14:$D$33,"Validação",$I$14:$I$33,"Aprovado")+COUNTIFS($D$14:$D$33,"Validação",$I$14:$I$33,"Aprovado com ressalvas")=0),"Liberado sem validação aprovada",IF(AND(H14="",ISNUMBER($D$10),G14<$D$10),"Atrasada","OK")))))))))
B15: 2 | L15: =IF(C15="",IF(COUNTA(D15:K15)>0,"Falta a etapa",""),IF(D15="","Falta o tipo",IF(E15="","Falta o responsável",IF(G15="","Falta o prazo",IF(AND(H15<>"",I15=""),"Falta o resultado",IF(AND(I15<>"",H15=""),"Falta a data de conclusão",IF(AND(OR(I15="Aprovado com ressalvas",I15="Reprovado"),J15=""),"Falta a ação",IF(AND(D15="Liberação para produção",H15<>"",COUNTIFS($D$14:$D$33,"Validação",$I$14:$I$33,"Aprovado")+COUNTIFS($D$14:$D$33,"Validação",$I$14:$I$33,"Aprovado com ressalvas")=0),"Liberado sem validação aprovada",IF(AND(H15="",ISNUMBER($D$10),G15<$D$10),"Atrasada","OK")))))))))
B16: 3 | L16: =IF(C16="",IF(COUNTA(D16:K16)>0,"Falta a etapa",""),IF(D16="","Falta o tipo",IF(E16="","Falta o responsável",IF(G16="","Falta o prazo",IF(AND(H16<>"",I16=""),"Falta o resultado",IF(AND(I16<>"",H16=""),"Falta a data de conclusão",IF(AND(OR(I16="Aprovado com ressalvas",I16="Reprovado"),J16=""),"Falta a ação",IF(AND(D16="Liberação para produção",H16<>"",COUNTIFS($D$14:$D$33,"Validação",$I$14:$I$33,"Aprovado")+COUNTIFS($D$14:$D$33,"Validação",$I$14:$I$33,"Aprovado com ressalvas")=0),"Liberado sem validação aprovada",IF(AND(H16="",ISNUMBER($D$10),G16<$D$10),"Atrasada","OK")))))))))
B17: 4 | L17: =IF(C17="",IF(COUNTA(D17:K17)>0,"Falta a etapa",""),IF(D17="","Falta o tipo",IF(E17="","Falta o responsável",IF(G17="","Falta o prazo",IF(AND(H17<>"",I17=""),"Falta o resultado",IF(AND(I17<>"",H17=""),"Falta a data de conclusão",IF(AND(OR(I17="Aprovado com ressalvas",I17="Reprovado"),J17=""),"Falta a ação",IF(AND(D17="Liberação para produção",H17<>"",COUNTIFS($D$14:$D$33,"Validação",$I$14:$I$33,"Aprovado")+COUNTIFS($D$14:$D$33,"Validação",$I$14:$I$33,"Aprovado com ressalvas")=0),"Liberado sem validação aprovada",IF(AND(H17="",ISNUMBER($D$10),G17<$D$10),"Atrasada","OK")))))))))
B18: 5 | L18: =IF(C18="",IF(COUNTA(D18:K18)>0,"Falta a etapa",""),IF(D18="","Falta o tipo",IF(E18="","Falta o responsável",IF(G18="","Falta o prazo",IF(AND(H18<>"",I18=""),"Falta o resultado",IF(AND(I18<>"",H18=""),"Falta a data de conclusão",IF(AND(OR(I18="Aprovado com ressalvas",I18="Reprovado"),J18=""),"Falta a ação",IF(AND(D18="Liberação para produção",H18<>"",COUNTIFS($D$14:$D$33,"Validação",$I$14:$I$33,"Aprovado")+COUNTIFS($D$14:$D$33,"Validação",$I$14:$I$33,"Aprovado com ressalvas")=0),"Liberado sem validação aprovada",IF(AND(H18="",ISNUMBER($D$10),G18<$D$10),"Atrasada","OK")))))))))
B19: 6 | L19: =IF(C19="",IF(COUNTA(D19:K19)>0,"Falta a etapa",""),IF(D19="","Falta o tipo",IF(E19="","Falta o responsável",IF(G19="","Falta o prazo",IF(AND(H19<>"",I19=""),"Falta o resultado",IF(AND(I19<>"",H19=""),"Falta a data de conclusão",IF(AND(OR(I19="Aprovado com ressalvas",I19="Reprovado"),J19=""),"Falta a ação",IF(AND(D19="Liberação para produção",H19<>"",COUNTIFS($D$14:$D$33,"Validação",$I$14:$I$33,"Aprovado")+COUNTIFS($D$14:$D$33,"Validação",$I$14:$I$33,"Aprovado com ressalvas")=0),"Liberado sem validação aprovada",IF(AND(H19="",ISNUMBER($D$10),G19<$D$10),"Atrasada","OK")))))))))
B20: 7 | L20: =IF(C20="",IF(COUNTA(D20:K20)>0,"Falta a etapa",""),IF(D20="","Falta o tipo",IF(E20="","Falta o responsável",IF(G20="","Falta o prazo",IF(AND(H20<>"",I20=""),"Falta o resultado",IF(AND(I20<>"",H20=""),"Falta a data de conclusão",IF(AND(OR(I20="Aprovado com ressalvas",I20="Reprovado"),J20=""),"Falta a ação",IF(AND(D20="Liberação para produção",H20<>"",COUNTIFS($D$14:$D$33,"Validação",$I$14:$I$33,"Aprovado")+COUNTIFS($D$14:$D$33,"Validação",$I$14:$I$33,"Aprovado com ressalvas")=0),"Liberado sem validação aprovada",IF(AND(H20="",ISNUMBER($D$10),G20<$D$10),"Atrasada","OK")))))))))
B21: 8 | L21: =IF(C21="",IF(COUNTA(D21:K21)>0,"Falta a etapa",""),IF(D21="","Falta o tipo",IF(E21="","Falta o responsável",IF(G21="","Falta o prazo",IF(AND(H21<>"",I21=""),"Falta o resultado",IF(AND(I21<>"",H21=""),"Falta a data de conclusão",IF(AND(OR(I21="Aprovado com ressalvas",I21="Reprovado"),J21=""),"Falta a ação",IF(AND(D21="Liberação para produção",H21<>"",COUNTIFS($D$14:$D$33,"Validação",$I$14:$I$33,"Aprovado")+COUNTIFS($D$14:$D$33,"Validação",$I$14:$I$33,"Aprovado com ressalvas")=0),"Liberado sem validação aprovada",IF(AND(H21="",ISNUMBER($D$10),G21<$D$10),"Atrasada","OK")))))))))
B22: 9 | L22: =IF(C22="",IF(COUNTA(D22:K22)>0,"Falta a etapa",""),IF(D22="","Falta o tipo",IF(E22="","Falta o responsável",IF(G22="","Falta o prazo",IF(AND(H22<>"",I22=""),"Falta o resultado",IF(AND(I22<>"",H22=""),"Falta a data de conclusão",IF(AND(OR(I22="Aprovado com ressalvas",I22="Reprovado"),J22=""),"Falta a ação",IF(AND(D22="Liberação para produção",H22<>"",COUNTIFS($D$14:$D$33,"Validação",$I$14:$I$33,"Aprovado")+COUNTIFS($D$14:$D$33,"Validação",$I$14:$I$33,"Aprovado com ressalvas")=0),"Liberado sem validação aprovada",IF(AND(H22="",ISNUMBER($D$10),G22<$D$10),"Atrasada","OK")))))))))
B23: 10 | L23: =IF(C23="",IF(COUNTA(D23:K23)>0,"Falta a etapa",""),IF(D23="","Falta o tipo",IF(E23="","Falta o responsável",IF(G23="","Falta o prazo",IF(AND(H23<>"",I23=""),"Falta o resultado",IF(AND(I23<>"",H23=""),"Falta a data de conclusão",IF(AND(OR(I23="Aprovado com ressalvas",I23="Reprovado"),J23=""),"Falta a ação",IF(AND(D23="Liberação para produção",H23<>"",COUNTIFS($D$14:$D$33,"Validação",$I$14:$I$33,"Aprovado")+COUNTIFS($D$14:$D$33,"Validação",$I$14:$I$33,"Aprovado com ressalvas")=0),"Liberado sem validação aprovada",IF(AND(H23="",ISNUMBER($D$10),G23<$D$10),"Atrasada","OK")))))))))
B24: 11 | L24: =IF(C24="",IF(COUNTA(D24:K24)>0,"Falta a etapa",""),IF(D24="","Falta o tipo",IF(E24="","Falta o responsável",IF(G24="","Falta o prazo",IF(AND(H24<>"",I24=""),"Falta o resultado",IF(AND(I24<>"",H24=""),"Falta a data de conclusão",IF(AND(OR(I24="Aprovado com ressalvas",I24="Reprovado"),J24=""),"Falta a ação",IF(AND(D24="Liberação para produção",H24<>"",COUNTIFS($D$14:$D$33,"Validação",$I$14:$I$33,"Aprovado")+COUNTIFS($D$14:$D$33,"Validação",$I$14:$I$33,"Aprovado com ressalvas")=0),"Liberado sem validação aprovada",IF(AND(H24="",ISNUMBER($D$10),G24<$D$10),"Atrasada","OK")))))))))
B25: 12 | L25: =IF(C25="",IF(COUNTA(D25:K25)>0,"Falta a etapa",""),IF(D25="","Falta o tipo",IF(E25="","Falta o responsável",IF(G25="","Falta o prazo",IF(AND(H25<>"",I25=""),"Falta o resultado",IF(AND(I25<>"",H25=""),"Falta a data de conclusão",IF(AND(OR(I25="Aprovado com ressalvas",I25="Reprovado"),J25=""),"Falta a ação",IF(AND(D25="Liberação para produção",H25<>"",COUNTIFS($D$14:$D$33,"Validação",$I$14:$I$33,"Aprovado")+COUNTIFS($D$14:$D$33,"Validação",$I$14:$I$33,"Aprovado com ressalvas")=0),"Liberado sem validação aprovada",IF(AND(H25="",ISNUMBER($D$10),G25<$D$10),"Atrasada","OK")))))))))
... B33: 20 | L33: =IF(C33="",IF(COUNTA(D33:K33)>0,"Falta a etapa",""),IF(D33="","Falta o tipo",IF(E33="","Falta o responsável",IF(G33="","Falta o prazo",IF(AND(H33<>"",I33=""),"Falta o resultado",IF(AND(I33<>"",H33=""),"Falta a data de conclusão",IF(AND(OR(I33="Aprovado com ressalvas",I33="Reprovado"),J33=""),"Falta a ação",IF(AND(D33="Liberação para produção",H33<>"",COUNTIFS($D$14:$D$33,"Validação",$I$14:$I$33,"Aprovado")+COUNTIFS($D$14:$D$33,"Validação",$I$14:$I$33,"Aprovado com ressalvas")=0),"Liberado sem validação aprovada",IF(AND(H33="",ISNUMBER($D$10),G33<$D$10),"Atrasada","OK")))))))))
B35: Resumo automático
B36: Etapas no plano | D36: =COUNTA(C14:C33) -> 0
B37: Controles no plano | D37: =IF(D36=0,"",COUNTIF($D$14:$D$33,"Análise crítica")&" análises críticas, "&COUNTIF($D$14:$D$33,"Verificação")&" verificações, "&COUNTIF($D$14:$D$33,"Validação")&" validações")
B38: Concluídas e atrasadas | D38: =IF(D36=0,"",COUNTA(H14:H33)&" concluídas, "&COUNTIF(L14:L33,"Atrasada")&" atrasadas")
B39: Aviso | D39: =IF(D5="","Escreva o projeto",IF(D36=0,"Escreva as etapas",IF(COUNTIF(L14:L33,"Liberado sem validação aprovada")>0,"Há liberação sem validação aprovada",IF(COUNTIF($D$14:$D$33,"Validação")=0,"O plano não tem validação",IF(COUNTIF($D$14:$D$33,"Verificação")=0,"O plano não tem verificação",IF(COUNTIF($D$14:$D$33,"Análise crítica")=0,"O plano não tem análise crítica",IF(COUNTIF(L14:L33,"Atrasada")>0,"Há etapa atrasada",IF(SUMPRODUCT((L14:L33<>"")*(L14:L33<>"OK"))>0,"Há etapa a rever: veja a coluna Conferência","OK")))))))) -> Escreva o projeto

Sheet Entradas
B1: Entradas, saídas e verificação
B2: Uma linha por entrada. Cada entrada aponta a saída que a atende e como se verifica: é a matriz de rastreabilidade do projeto.
B4: # | C4: Código | D4: Entrada | E4: Tipo | F4: Fonte | G4: Saída que atende | H4: Como verificar | I4: Resultado | J4: Evidência ou ação | K4: Conferência
C5: E1, E2 | D5: Com número e condição | E5: Lista | F5: De onde veio | G5: Onde o projeto atende | H5: Método e critério | I5: Lista | J5: O resultado, ou o que será feito | K5: Calculada
B6: Ex. | C6: E3 | D6: Queda de dardo de pelo menos 300 g a -18 °C. | E6: Funcional ou de desempenho | F6: Uso pretendido: freezer do cliente | G6: Resina para baixa temperatura | H6: Ensaio de queda de dardo a -18 °C | I6: Atende | J6: 420 g, em 16/07. | K6: OK
B7: 1 | K7: =IF(D7="",IF(COUNTA(C7,E7:J7)>0,"Falta a entrada",""),IF(E7="","Falta o tipo",IF(F7="","Falta a fonte",IF(G7="","Falta a saída que atende",IF(H7="","Falta como verificar",IF(I7="Não atende",IF(J7="","Não atende, sem ação","Não atende: ação em curso"),IF(I7="","Verificação pendente","OK")))))))
B8: 2 | K8: =IF(D8="",IF(COUNTA(C8,E8:J8)>0,"Falta a entrada",""),IF(E8="","Falta o tipo",IF(F8="","Falta a fonte",IF(G8="","Falta a saída que atende",IF(H8="","Falta como verificar",IF(I8="Não atende",IF(J8="","Não atende, sem ação","Não atende: ação em curso"),IF(I8="","Verificação pendente","OK")))))))
B9: 3 | K9: =IF(D9="",IF(COUNTA(C9,E9:J9)>0,"Falta a entrada",""),IF(E9="","Falta o tipo",IF(F9="","Falta a fonte",IF(G9="","Falta a saída que atende",IF(H9="","Falta como verificar",IF(I9="Não atende",IF(J9="","Não atende, sem ação","Não atende: ação em curso"),IF(I9="","Verificação pendente","OK")))))))
B10: 4 | K10: =IF(D10="",IF(COUNTA(C10,E10:J10)>0,"Falta a entrada",""),IF(E10="","Falta o tipo",IF(F10="","Falta a fonte",IF(G10="","Falta a saída que atende",IF(H10="","Falta como verificar",IF(I10="Não atende",IF(J10="","Não atende, sem ação","Não atende: ação em curso"),IF(I10="","Verificação pendente","OK")))))))
B11: 5 | K11: =IF(D11="",IF(COUNTA(C11,E11:J11)>0,"Falta a entrada",""),IF(E11="","Falta o tipo",IF(F11="","Falta a fonte",IF(G11="","Falta a saída que atende",IF(H11="","Falta como verificar",IF(I11="Não atende",IF(J11="","Não atende, sem ação","Não atende: ação em curso"),IF(I11="","Verificação pendente","OK")))))))
B12: 6 | K12: =IF(D12="",IF(COUNTA(C12,E12:J12)>0,"Falta a entrada",""),IF(E12="","Falta o tipo",IF(F12="","Falta a fonte",IF(G12="","Falta a saída que atende",IF(H12="","Falta como verificar",IF(I12="Não atende",IF(J12="","Não atende, sem ação","Não atende: ação em curso"),IF(I12="","Verificação pendente","OK")))))))
B13: 7 | K13: =IF(D13="",IF(COUNTA(C13,E13:J13)>0,"Falta a entrada",""),IF(E13="","Falta o tipo",IF(F13="","Falta a fonte",IF(G13="","Falta a saída que atende",IF(H13="","Falta como verificar",IF(I13="Não atende",IF(J13="","Não atende, sem ação","Não atende: ação em curso"),IF(I13="","Verificação pendente","OK")))))))
B14: 8 | K14: =IF(D14="",IF(COUNTA(C14,E14:J14)>0,"Falta a entrada",""),IF(E14="","Falta o tipo",IF(F14="","Falta a fonte",IF(G14="","Falta a saída que atende",IF(H14="","Falta como verificar",IF(I14="Não atende",IF(J14="","Não atende, sem ação","Não atende: ação em curso"),IF(I14="","Verificação pendente","OK")))))))
B15: 9 | K15: =IF(D15="",IF(COUNTA(C15,E15:J15)>0,"Falta a entrada",""),IF(E15="","Falta o tipo",IF(F15="","Falta a fonte",IF(G15="","Falta a saída que atende",IF(H15="","Falta como verificar",IF(I15="Não atende",IF(J15="","Não atende, sem ação","Não atende: ação em curso"),IF(I15="","Verificação pendente","OK")))))))
B16: 10 | K16: =IF(D16="",IF(COUNTA(C16,E16:J16)>0,"Falta a entrada",""),IF(E16="","Falta o tipo",IF(F16="","Falta a fonte",IF(G16="","Falta a saída que atende",IF(H16="","Falta como verificar",IF(I16="Não atende",IF(J16="","Não atende, sem ação","Não atende: ação em curso"),IF(I16="","Verificação pendente","OK")))))))
B17: 11 | K17: =IF(D17="",IF(COUNTA(C17,E17:J17)>0,"Falta a entrada",""),IF(E17="","Falta o tipo",IF(F17="","Falta a fonte",IF(G17="","Falta a saída que atende",IF(H17="","Falta como verificar",IF(I17="Não atende",IF(J17="","Não atende, sem ação","Não atende: ação em curso"),IF(I17="","Verificação pendente","OK")))))))
B18: 12 | K18: =IF(D18="",IF(COUNTA(C18,E18:J18)>0,"Falta a entrada",""),IF(E18="","Falta o tipo",IF(F18="","Falta a fonte",IF(G18="","Falta a saída que atende",IF(H18="","Falta como verificar",IF(I18="Não atende",IF(J18="","Não atende, sem ação","Não atende: ação em curso"),IF(I18="","Verificação pendente","OK")))))))
... B36: 30 | K36: =IF(D36="",IF(COUNTA(C36,E36:J36)>0,"Falta a entrada",""),IF(E36="","Falta o tipo",IF(F36="","Falta a fonte",IF(G36="","Falta a saída que atende",IF(H36="","Falta como verificar",IF(I36="Não atende",IF(J36="","Não atende, sem ação","Não atende: ação em curso"),IF(I36="","Verificação pendente","OK")))))))
B38: Resumo automático
B39: Entradas escritas | D39: =COUNTA(D7:D36) -> 0
B40: Por resultado | D40: =IF(D39=0,"",COUNTIF(I7:I36,"Atende")&" atendem, "&COUNTIF(I7:I36,"Não atende")&" não atendem, "&COUNTIF(K7:K36,"Verificação pendente")&" pendentes")
B41: Tipos usados | D41: =SUMPRODUCT((COUNTIF(E7:E36,{"Cliente","Funcional ou de desempenho","Legal ou regulamentar","Norma ou código","Projeto anterior","Falha potencial","Da organização"})>0)*1)&" de 7" -> 0 de 7
B42: Aviso | D42: =IF(D39=0,"Escreva as entradas",IF(COUNTIF(K7:K36,"Não atende, sem ação")>0,"Há entrada que não atende, sem ação",IF(SUMPRODUCT((K7:K36<>"")*(K7:K36<>"OK")*(K7:K36<>"Verificação pendente")*(K7:K36<>"Não atende: ação em curso"))>0,"Há entrada a completar: veja a coluna Conferência",IF(COUNTIF(K7:K36,"Verificação pendente")+COUNTIF(K7:K36,"Não atende: ação em curso")>0,"Há entrada pendente ou que não atende: não libere ainda","OK")))) -> Escreva as entradas

Sheet Mudanças
B1: Mudanças de projeto
B2: Toda alteração em uma entrada ou em uma saída já aprovada. A mudança diz o que precisa ser verificado ou validado de novo.
B4: # | C4: Data | D4: O que mudou | E4: Motivo | F4: Análise do impacto | G4: O que foi verificado ou validado de novo | H4: Quem autorizou | I4: Conferência
C5: Data | D5: De quê, para quê | E5: Por que mudar | F5: Efeito nas entradas, nas saídas e no uso | G5: O ensaio, o teste, a validação | H5: Quem tem autoridade | I5: Calculada
B6: Ex. | C6: 46576 | D6: Resina do fornecedor B no lugar do A. | E6: Prazo de entrega. | F6: Fichas técnicas comparadas. | G6: Queda de dardo no lote de teste: 420 g. | H6: Gerente de engenharia | I6: OK
B7: 1 | I7: =IF(D7="",IF(COUNTA(C7,E7:H7)>0,"Falta o que mudou",""),IF(F7="","Falta a análise",IF(H7="","Falta quem autorizou",IF(G7="","Falta o que foi verificado de novo","OK"))))
B8: 2 | I8: =IF(D8="",IF(COUNTA(C8,E8:H8)>0,"Falta o que mudou",""),IF(F8="","Falta a análise",IF(H8="","Falta quem autorizou",IF(G8="","Falta o que foi verificado de novo","OK"))))
B9: 3 | I9: =IF(D9="",IF(COUNTA(C9,E9:H9)>0,"Falta o que mudou",""),IF(F9="","Falta a análise",IF(H9="","Falta quem autorizou",IF(G9="","Falta o que foi verificado de novo","OK"))))
B10: 4 | I10: =IF(D10="",IF(COUNTA(C10,E10:H10)>0,"Falta o que mudou",""),IF(F10="","Falta a análise",IF(H10="","Falta quem autorizou",IF(G10="","Falta o que foi verificado de novo","OK"))))
B11: 5 | I11: =IF(D11="",IF(COUNTA(C11,E11:H11)>0,"Falta o que mudou",""),IF(F11="","Falta a análise",IF(H11="","Falta quem autorizou",IF(G11="","Falta o que foi verificado de novo","OK"))))
B12: 6 | I12: =IF(D12="",IF(COUNTA(C12,E12:H12)>0,"Falta o que mudou",""),IF(F12="","Falta a análise",IF(H12="","Falta quem autorizou",IF(G12="","Falta o que foi verificado de novo","OK"))))
B13: 7 | I13: =IF(D13="",IF(COUNTA(C13,E13:H13)>0,"Falta o que mudou",""),IF(F13="","Falta a análise",IF(H13="","Falta quem autorizou",IF(G13="","Falta o que foi verificado de novo","OK"))))
B14: 8 | I14: =IF(D14="",IF(COUNTA(C14,E14:H14)>0,"Falta o que mudou",""),IF(F14="","Falta a análise",IF(H14="","Falta quem autorizou",IF(G14="","Falta o que foi verificado de novo","OK"))))
B15: 9 | I15: =IF(D15="",IF(COUNTA(C15,E15:H15)>0,"Falta o que mudou",""),IF(F15="","Falta a análise",IF(H15="","Falta quem autorizou",IF(G15="","Falta o que foi verificado de novo","OK"))))
B16: 10 | I16: =IF(D16="",IF(COUNTA(C16,E16:H16)>0,"Falta o que mudou",""),IF(F16="","Falta a análise",IF(H16="","Falta quem autorizou",IF(G16="","Falta o que foi verificado de novo","OK"))))
B17: 11 | I17: =IF(D17="",IF(COUNTA(C17,E17:H17)>0,"Falta o que mudou",""),IF(F17="","Falta a análise",IF(H17="","Falta quem autorizou",IF(G17="","Falta o que foi verificado de novo","OK"))))
B18: 12 | I18: =IF(D18="",IF(COUNTA(C18,E18:H18)>0,"Falta o que mudou",""),IF(F18="","Falta a análise",IF(H18="","Falta quem autorizou",IF(G18="","Falta o que foi verificado de novo","OK"))))
... B26: 20 | I26: =IF(D26="",IF(COUNTA(C26,E26:H26)>0,"Falta o que mudou",""),IF(F26="","Falta a análise",IF(H26="","Falta quem autorizou",IF(G26="","Falta o que foi verificado de novo","OK"))))
B28: Resumo automático
B29: Mudanças registradas | D29: =COUNTA(D7:D26) -> 0
B30: Mudanças a rever | D30: =SUMPRODUCT((I7:I26<>"")*(I7:I26<>"OK")) -> 0
B31: Aviso | D31: =IF(D29=0,"Nenhuma mudança registrada: confirme se o projeto não mudou",IF(D30>0,"Há mudança a rever: veja a coluna Conferência","OK")) -> Nenhuma mudança registrada: confirme se o projeto não mudou

Sheet Painel
B1: Painel do projeto
B2: Nada a preencher: tudo vem das outras abas.
B3: Projeto | C3: =IF(Plano!D5="","",Plano!D5)
B5: Indicador | C5: Resultado | D5: Como se lê
B6: Etapas no plano | C6: =COUNTA(Plano!C14:C33) -> 0 | D6: Da aba Plano.
B7: Etapas concluídas | C7: =COUNTA(Plano!H14:H33) -> 0 | D7: Com data de conclusão.
B8: Etapas atrasadas | C8: =COUNTIF(Plano!L14:L33,"Atrasada") -> 0 | D8: Sem conclusão, com o prazo vencido na data da leitura.
B9: Etapas a rever | C9: =SUMPRODUCT((Plano!L14:L33<>"")*(Plano!L14:L33<>"OK")*(Plano!L14:L33<>"Atrasada")) -> 0 | D9: Sem responsável, sem prazo, sem resultado, sem ação.
B10: Validações aprovadas | C10: =COUNTIFS(Plano!D14:D33,"Validação",Plano!I14:I33,"Aprovado")+COUNTIFS(Plano!D14:D33,"Validação",Plano!I14:I33,"Aprovado com ressalvas") -> 0 | D10: Com ou sem ressalvas. Sem nenhuma, o projeto não pode ser liberado.
B11: Entradas escritas | C11: =COUNTA(Entradas!D7:D36) -> 0 | D11: Da aba Entradas.
B12: Entradas que atendem | C12: =COUNTIF(Entradas!I7:I36,"Atende") -> 0 | D12: Verificadas e conformes.
B13: Entradas que não atendem | C13: =COUNTIF(Entradas!I7:I36,"Não atende") -> 0 | D13: Com ou sem ação em curso.
B14: Entradas pendentes | C14: =COUNTIF(Entradas!K7:K36,"Verificação pendente") -> 0 | D14: Sem resultado de verificação.
B15: Mudanças registradas | C15: =COUNTA(Mudanças!D7:D26) -> 0 | D15: Da aba Mudanças.
B16: Mudanças a rever | C16: =SUMPRODUCT((Mudanças!I7:I26<>"")*(Mudanças!I7:I26<>"OK")) -> 0 | D16: Sem análise, sem autorização ou sem nova verificação.
B17: Pode liberar? | C17: =IF(C6=0,"",IF(AND(C10>0,C11>0,C13+C14=0,C16=0,C8+C9=0),"Sim","Ainda não")) | D17: =IF(C17="Ainda não",IF(C10=0,"Falta uma validação aprovada.",IF(C13+C14>0,"Há entrada que não atende ou sem verificação.",IF(C16>0,"Há mudança sem análise, autorização ou nova verificação.","Há etapa atrasada ou a rever."))),IF(C17="Sim","As três perguntas do módulo 7 têm resposta sim.",""))
B19: Os três controles
B20: Controle | C20: No plano | D20: Concluídos | E20: Aprovados | F20: Reprovados | G20: Pergunta
B21: Análise crítica | C21: =COUNTIF(Plano!D14:D33,B21) -> 0 | D21: =COUNTIFS(Plano!D14:D33,B21,Plano!H14:H33,"<>") -> 0 | E21: =COUNTIFS(Plano!D14:D33,B21,Plano!I14:I33,"Aprovado")+COUNTIFS(Plano!D14:D33,B21,Plano!I14:I33,"Aprovado com ressalvas") -> 0 | F21: =COUNTIFS(Plano!D14:D33,B21,Plano!I14:I33,"Reprovado") -> 0 | G21: O projeto segue, muda ou para?
B22: Verificação | C22: =COUNTIF(Plano!D14:D33,B22) -> 0 | D22: =COUNTIFS(Plano!D14:D33,B22,Plano!H14:H33,"<>") -> 0 | E22: =COUNTIFS(Plano!D14:D33,B22,Plano!I14:I33,"Aprovado")+COUNTIFS(Plano!D14:D33,B22,Plano!I14:I33,"Aprovado com ressalvas") -> 0 | F22: =COUNTIFS(Plano!D14:D33,B22,Plano!I14:I33,"Reprovado") -> 0 | G22: As saídas atendem às entradas?
B23: Validação | C23: =COUNTIF(Plano!D14:D33,B23) -> 0 | D23: =COUNTIFS(Plano!D14:D33,B23,Plano!H14:H33,"<>") -> 0 | E23: =COUNTIFS(Plano!D14:D33,B23,Plano!I14:I33,"Aprovado")+COUNTIFS(Plano!D14:D33,B23,Plano!I14:I33,"Aprovado com ressalvas") -> 0 | F23: =COUNTIFS(Plano!D14:D33,B23,Plano!I14:I33,"Reprovado") -> 0 | G23: O produto serve para o uso pretendido?
B25: Entradas por tipo
B26: Tipo | C26: Entradas | D26: Atendem | E26: Não atendem | F26: Pendentes | G26: Leitura
B27: Cliente | C27: =COUNTIF(Entradas!E7:E36,B27) -> 0 | D27: =COUNTIFS(Entradas!E7:E36,B27,Entradas!I7:I36,"Atende") -> 0 | E27: =COUNTIFS(Entradas!E7:E36,B27,Entradas!I7:I36,"Não atende") -> 0 | F27: =COUNTIFS(Entradas!E7:E36,B27,Entradas!K7:K36,"Verificação pendente") -> 0 | G27: =IF(C27=0,"Nenhuma entrada deste tipo: confirme se é isso mesmo",IF(E27+F27>0,"Há o que verificar ou resolver","")) -> Nenhuma entrada deste tipo: confirme se é isso mesmo
B28: Funcional ou de desempenho | C28: =COUNTIF(Entradas!E7:E36,B28) -> 0 | D28: =COUNTIFS(Entradas!E7:E36,B28,Entradas!I7:I36,"Atende") -> 0 | E28: =COUNTIFS(Entradas!E7:E36,B28,Entradas!I7:I36,"Não atende") -> 0 | F28: =COUNTIFS(Entradas!E7:E36,B28,Entradas!K7:K36,"Verificação pendente") -> 0 | G28: =IF(C28=0,"Nenhuma entrada deste tipo: confirme se é isso mesmo",IF(E28+F28>0,"Há o que verificar ou resolver","")) -> Nenhuma entrada deste tipo: confirme se é isso mesmo
B29: Legal ou regulamentar | C29: =COUNTIF(Entradas!E7:E36,B29) -> 0 | D29: =COUNTIFS(Entradas!E7:E36,B29,Entradas!I7:I36,"Atende") -> 0 | E29: =COUNTIFS(Entradas!E7:E36,B29,Entradas!I7:I36,"Não atende") -> 0 | F29: =COUNTIFS(Entradas!E7:E36,B29,Entradas!K7:K36,"Verificação pendente") -> 0 | G29: =IF(C29=0,"Nenhuma entrada deste tipo: confirme se é isso mesmo",IF(E29+F29>0,"Há o que verificar ou resolver","")) -> Nenhuma entrada deste tipo: confirme se é isso mesmo
B30: Norma ou código | C30: =COUNTIF(Entradas!E7:E36,B30) -> 0 | D30: =COUNTIFS(Entradas!E7:E36,B30,Entradas!I7:I36,"Atende") -> 0 | E30: =COUNTIFS(Entradas!E7:E36,B30,Entradas!I7:I36,"Não atende") -> 0 | F30: =COUNTIFS(Entradas!E7:E36,B30,Entradas!K7:K36,"Verificação pendente") -> 0 | G30: =IF(C30=0,"Nenhuma entrada deste tipo: confirme se é isso mesmo",IF(E30+F30>0,"Há o que verificar ou resolver","")) -> Nenhuma entrada deste tipo: confirme se é isso mesmo
B31: Projeto anterior | C31: =COUNTIF(Entradas!E7:E36,B31) -> 0 | D31: =COUNTIFS(Entradas!E7:E36,B31,Entradas!I7:I36,"Atende") -> 0 | E31: =COUNTIFS(Entradas!E7:E36,B31,Entradas!I7:I36,"Não atende") -> 0 | F31: =COUNTIFS(Entradas!E7:E36,B31,Entradas!K7:K36,"Verificação pendente") -> 0 | G31: =IF(C31=0,"Nenhuma entrada deste tipo: confirme se é isso mesmo",IF(E31+F31>0,"Há o que verificar ou resolver","")) -> Nenhuma entrada deste tipo: confirme se é isso mesmo
B32: Falha potencial | C32: =COUNTIF(Entradas!E7:E36,B32) -> 0 | D32: =COUNTIFS(Entradas!E7:E36,B32,Entradas!I7:I36,"Atende") -> 0 | E32: =COUNTIFS(Entradas!E7:E36,B32,Entradas!I7:I36,"Não atende") -> 0 | F32: =COUNTIFS(Entradas!E7:E36,B32,Entradas!K7:K36,"Verificação pendente") -> 0 | G32: =IF(C32=0,"Nenhuma entrada deste tipo: confirme se é isso mesmo",IF(E32+F32>0,"Há o que verificar ou resolver","")) -> Nenhuma entrada deste tipo: confirme se é isso mesmo
B33: Da organização | C33: =COUNTIF(Entradas!E7:E36,B33) -> 0 | D33: =COUNTIFS(Entradas!E7:E36,B33,Entradas!I7:I36,"Atende") -> 0 | E33: =COUNTIFS(Entradas!E7:E36,B33,Entradas!I7:I36,"Não atende") -> 0 | F33: =COUNTIFS(Entradas!E7:E36,B33,Entradas!K7:K36,"Verificação pendente") -> 0 | G33: =IF(C33=0,"Nenhuma entrada deste tipo: confirme se é isso mesmo",IF(E33+F33>0,"Há o que verificar ou resolver","")) -> Nenhuma entrada deste tipo: confirme se é isso mesmo
B35: Resumo automático
B36: Aviso | C36: =IF(C6=0,"Escreva o plano na aba Plano",IF(COUNTIF(Plano!L14:L33,"Liberado sem validação aprovada")>0,"Há liberação sem validação aprovada",IF(C23=0,"O plano não tem validação",IF(C8>0,"Há etapa atrasada",IF(C16>0,"Há mudança a rever",IF(C13+C14>0,"Há entrada que não atende ou pendente",IF(C9>0,"Há etapa a rever","OK"))))))) -> Escreva o plano na aba Plano

Sheet Checklist
B1: Checklist do projeto e desenvolvimento
B2: Escolha o status de cada item na lista suspensa (coluna em amarelo-claro).
B4: # | C4: Item de verificação | D4: Status | E4: Observações
B5: 1 | C5: Está decidido se a organização faz projeto e desenvolvimento, e a não aplicabilidade, se houver, está justificada.
B6: 2 | C6: Cada projeto tem um plano: etapas, responsáveis, prazos, análises críticas, verificações e validações.
B7: 3 | C7: O cliente e os usuários participam quando o projeto depende deles.
B8: 4 | C8: As entradas estão escritas: cliente, desempenho, requisitos legais, normas, projetos anteriores, falhas potenciais e a organização.
B9: 5 | C9: Cada entrada é clara, completa e não conflita com as outras.
B10: 6 | C10: Cada entrada tem a saída que a atende e o modo de verificar.
B11: 7 | C11: As saídas incluem os critérios de aceitação e o que é essencial para o uso seguro.
B12: 8 | C12: A verificação confere as saídas contra as entradas, com registro.
B13: 9 | C13: A validação confere o produto no uso pretendido, antes da liberação.
B14: 10 | C14: As análises críticas registram os problemas encontrados e as ações.
B15: 11 | C15: Toda mudança no projeto é analisada, autorizada e verificada de novo, com registro.
B16: 12 | C16: O projeto só é liberado para a produção com a validação aprovada e as entradas verificadas.
B18: Resumo automático
B19: Itens atendidos (Sim) | D19: =COUNTIF(D5:D16,"Sim") -> 0
B20: Itens parciais | D20: =COUNTIF(D5:D16,"Parcial") -> 0
B21: Itens não atendidos | D21: =COUNTIF(D5:D16,"Não") -> 0
B22: Itens sem resposta | D22: =COUNTBLANK(D5:D16) -> 12
B23: Percentual atendido | D23: =D19/ROWS(D5:D16) -> 0
B24: Situação | D24: =IF(D19=ROWS(D5:D16),"Validado",IF(D22>0,"Em andamento","Com pendências")) -> Em andamento

Sheet Exemplo 1 - Pizzaria
B1: Projeto e desenvolvimento
B2: Exemplo preenchido, para consulta. Use as abas Plano, Entradas e Mudanças para o seu projeto.
B4: Organização | D4: Pizzaria (loja com salão e delivery)
B5: Projeto | D5: P-03 · Pizza vegana do cardápio de inverno
B6: Cliente ou usuário | D6: Clientes do salão e do aplicativo
B7: Objetivo | D7: Uma pizza sem ingrediente de origem animal, com o sabor e o tempo de forno das outras, no cardápio de 01/06/2027.
B8: Responsável e aprovação | D8: Pizzaiolo líder. Aprovação: gerente da loja e dono.
B9: Período | D9: De 05/04/2027 a 01/06/2027.
B10: Origem | D10: Requisito 8.3 atendido em parte no diagnóstico de 2026: sabores novos eram testados com a equipe, sem registro da receita aprovada nem do teste.
B11: Data da leitura | D11: 46538
B13: Plano do projeto
B14: # | C14: Etapa | E14: Tipo | F14: Responsável | G14: Participantes | H14: Prazo | I14: Concluída | J14: Resultado | K14: Ações e ressalvas | L14: Registro | M14: Conferência
B15: 1 | C15: Plano e entradas aprovados | E15: Planejamento | F15: Gerente da loja | G15: Pizzaiolo líder e dono | H15: 46482 | I15: 46482 | J15: Aprovado | L15: Ata de 05/04 | M15: =IF(C15="",IF(1>0,"Falta a etapa",""),IF(E15="","Falta o tipo",IF(F15="","Falta o responsável",IF(H15="","Falta o prazo",IF(AND(I15<>"",J15=""),"Falta o resultado",IF(AND(J15<>"",I15=""),"Falta a data de conclusão",IF(AND(OR(J15="Aprovado com ressalvas",J15="Reprovado"),K15=""),"Falta a ação",IF(AND(E15="Liberação para produção",I15<>"",COUNTIFS($E$15:$E$21,"Validação",$J$15:$J$21,"Aprovado")+COUNTIFS($E$15:$E$21,"Validação",$J$15:$J$21,"Aprovado com ressalvas")=0),"Liberado sem validação aprovada",IF(AND(I15="",ISNUMBER($D$11),H15<$D$11),"Atrasada","OK"))))))))) -> OK
B16: 2 | C16: Receita e ficha técnica, primeira versão | E16: Desenvolvimento | F16: Pizzaiolo líder | G16: Segundo pizzaiolo | H16: 46500 | I16: 46499 | J16: Aprovado | L16: Ficha técnica P-03 rev. 1 | M16: =IF(C16="",IF(1>0,"Falta a etapa",""),IF(E16="","Falta o tipo",IF(F16="","Falta o responsável",IF(H16="","Falta o prazo",IF(AND(I16<>"",J16=""),"Falta o resultado",IF(AND(J16<>"",I16=""),"Falta a data de conclusão",IF(AND(OR(J16="Aprovado com ressalvas",J16="Reprovado"),K16=""),"Falta a ação",IF(AND(E16="Liberação para produção",I16<>"",COUNTIFS($E$15:$E$21,"Validação",$J$15:$J$21,"Aprovado")+COUNTIFS($E$15:$E$21,"Validação",$J$15:$J$21,"Aprovado com ressalvas")=0),"Liberado sem validação aprovada",IF(AND(I16="",ISNUMBER($D$11),H16<$D$11),"Atrasada","OK"))))))))) -> OK
B17: 3 | C17: Ficha técnica, custo e teste de forno contra as entradas | E17: Verificação | F17: Pizzaiolo líder | G17: Gerente da loja | H17: 46507 | I17: 46510 | J17: Aprovado com ressalvas | K17: Custo de 34% (E6): rever o recheio. | L17: Planilha de verificação P-03 | M17: =IF(C17="",IF(1>0,"Falta a etapa",""),IF(E17="","Falta o tipo",IF(F17="","Falta o responsável",IF(H17="","Falta o prazo",IF(AND(I17<>"",J17=""),"Falta o resultado",IF(AND(J17<>"",I17=""),"Falta a data de conclusão",IF(AND(OR(J17="Aprovado com ressalvas",J17="Reprovado"),K17=""),"Falta a ação",IF(AND(E17="Liberação para produção",I17<>"",COUNTIFS($E$15:$E$21,"Validação",$J$15:$J$21,"Aprovado")+COUNTIFS($E$15:$E$21,"Validação",$J$15:$J$21,"Aprovado com ressalvas")=0),"Liberado sem validação aprovada",IF(AND(I17="",ISNUMBER($D$11),H17<$D$11),"Atrasada","OK"))))))))) -> OK
B18: 4 | C18: Análise crítica antes da degustação | E18: Análise crítica | F18: Gerente da loja | G18: Dono e pizzaiolo líder | H18: 46514 | I18: 46514 | J18: Aprovado com ressalvas | K18: Seguir para a degustação. Resolver o custo até 25/05. | L18: Ata de 07/05 | M18: =IF(C18="",IF(1>0,"Falta a etapa",""),IF(E18="","Falta o tipo",IF(F18="","Falta o responsável",IF(H18="","Falta o prazo",IF(AND(I18<>"",J18=""),"Falta o resultado",IF(AND(J18<>"",I18=""),"Falta a data de conclusão",IF(AND(OR(J18="Aprovado com ressalvas",J18="Reprovado"),K18=""),"Falta a ação",IF(AND(E18="Liberação para produção",I18<>"",COUNTIFS($E$15:$E$21,"Validação",$J$15:$J$21,"Aprovado")+COUNTIFS($E$15:$E$21,"Validação",$J$15:$J$21,"Aprovado com ressalvas")=0),"Liberado sem validação aprovada",IF(AND(I18="",ISNUMBER($D$11),H18<$D$11),"Atrasada","OK"))))))))) -> OK
B19: 5 | C19: Degustação com 20 clientes no salão | E19: Validação | F19: Gerente da loja | G19: 20 clientes, por convite | H19: 46528 | I19: 46527 | J19: Aprovado | L19: Fichas da degustação: nota média 4,3; 17 de 20 pediriam de novo | M19: =IF(C19="",IF(1>0,"Falta a etapa",""),IF(E19="","Falta o tipo",IF(F19="","Falta o responsável",IF(H19="","Falta o prazo",IF(AND(I19<>"",J19=""),"Falta o resultado",IF(AND(J19<>"",I19=""),"Falta a data de conclusão",IF(AND(OR(J19="Aprovado com ressalvas",J19="Reprovado"),K19=""),"Falta a ação",IF(AND(E19="Liberação para produção",I19<>"",COUNTIFS($E$15:$E$21,"Validação",$J$15:$J$21,"Aprovado")+COUNTIFS($E$15:$E$21,"Validação",$J$15:$J$21,"Aprovado com ressalvas")=0),"Liberado sem validação aprovada",IF(AND(I19="",ISNUMBER($D$11),H19<$D$11),"Atrasada","OK"))))))))) -> OK
B20: 6 | C20: Custo recalculado, com o recheio novo | E20: Verificação | F20: Pizzaiolo líder | G20: Gerente da loja | H20: 46532 | M20: =IF(C20="",IF(1>0,"Falta a etapa",""),IF(E20="","Falta o tipo",IF(F20="","Falta o responsável",IF(H20="","Falta o prazo",IF(AND(I20<>"",J20=""),"Falta o resultado",IF(AND(J20<>"",I20=""),"Falta a data de conclusão",IF(AND(OR(J20="Aprovado com ressalvas",J20="Reprovado"),K20=""),"Falta a ação",IF(AND(E20="Liberação para produção",I20<>"",COUNTIFS($E$15:$E$21,"Validação",$J$15:$J$21,"Aprovado")+COUNTIFS($E$15:$E$21,"Validação",$J$15:$J$21,"Aprovado com ressalvas")=0),"Liberado sem validação aprovada",IF(AND(I20="",ISNUMBER($D$11),H20<$D$11),"Atrasada","OK"))))))))) -> Atrasada
B21: 7 | C21: Inclusão no cardápio de inverno, com treinamento da equipe | E21: Liberação para produção | F21: Gerente da loja | G21: Toda a equipe | H21: 46539 | M21: =IF(C21="",IF(1>0,"Falta a etapa",""),IF(E21="","Falta o tipo",IF(F21="","Falta o responsável",IF(H21="","Falta o prazo",IF(AND(I21<>"",J21=""),"Falta o resultado",IF(AND(J21<>"",I21=""),"Falta a data de conclusão",IF(AND(OR(J21="Aprovado com ressalvas",J21="Reprovado"),K21=""),"Falta a ação",IF(AND(E21="Liberação para produção",I21<>"",COUNTIFS($E$15:$E$21,"Validação",$J$15:$J$21,"Aprovado")+COUNTIFS($E$15:$E$21,"Validação",$J$15:$J$21,"Aprovado com ressalvas")=0),"Liberado sem validação aprovada",IF(AND(I21="",ISNUMBER($D$11),H21<$D$11),"Atrasada","OK"))))))))) -> OK
B23: Entradas, saídas e verificação
B24: # | C24: Entrada | E24: Tipo | F24: Fonte | G24: Saída que atende | H24: Como verificar | I24: Resultado | J24: Evidência ou ação | M24: Conferência
B25: E1 | C25: Nenhum ingrediente de origem animal, inclusive na massa e no molho. | E25: Cliente | F25: Pedidos e comentários no aplicativo | G25: Ficha técnica P-03, com todos os ingredientes | H25: Conferência da ficha técnica e dos rótulos dos insumos | I25: Atende | J25: Rótulos conferidos em 20/04. Vale para a receita verificada até 03/05: com o queijo da marca B (12/05) e o tofu defumado (18/05), a ficha técnica e os rótulos precisam ser conferidos de novo. | M25: =IF(C25="",IF(1>0,"Falta a entrada",""),IF(E25="","Falta o tipo",IF(F25="","Falta a fonte",IF(G25="","Falta a saída que atende",IF(H25="","Falta como verificar",IF(I25="Não atende",IF(J25="","Não atende, sem ação","Não atende: ação em curso"),IF(I25="","Verificação pendente","OK"))))))) -> OK
B26: E2 | C26: Alergênicos informados no cardápio e no aplicativo. | E26: Legal ou regulamentar | F26: Requisito legal de rotulagem de alergênicos | G26: Texto do cardápio e do aplicativo | H26: Conferência do texto contra a ficha técnica | I26: Atende | J26: Texto conferido em 03/05. Vale para a receita verificada até 03/05: com o queijo da marca B (12/05) e o tofu defumado (18/05), o texto de alergênicos precisa ser conferido de novo. | M26: =IF(C26="",IF(1>0,"Falta a entrada",""),IF(E26="","Falta o tipo",IF(F26="","Falta a fonte",IF(G26="","Falta a saída que atende",IF(H26="","Falta como verificar",IF(I26="Não atende",IF(J26="","Não atende, sem ação","Não atende: ação em curso"),IF(I26="","Verificação pendente","OK"))))))) -> OK
B27: E3 | C27: Aviso de que a cozinha é compartilhada com produtos de origem animal. | E27: Falha potencial | F27: Oferta: o que a loja não garante | G27: Texto do cardápio | H27: Conferência do texto | I27: Atende | J27: Texto conferido em 03/05. | M27: =IF(C27="",IF(1>0,"Falta a entrada",""),IF(E27="","Falta o tipo",IF(F27="","Falta a fonte",IF(G27="","Falta a saída que atende",IF(H27="","Falta como verificar",IF(I27="Não atende",IF(J27="","Não atende, sem ação","Não atende: ação em curso"),IF(I27="","Verificação pendente","OK"))))))) -> OK
B28: E4 | C28: Tempo de forno de até 7 minutos, como o das outras pizzas. | E28: Funcional ou de desempenho | F28: Capacidade do forno no pico | G28: Instrução de montagem e de forno | H28: Teste no forno, com 10 pizzas | I28: Atende | J28: 7 minutos a 300 °C, em 22/04. | M28: =IF(C28="",IF(1>0,"Falta a entrada",""),IF(E28="","Falta o tipo",IF(F28="","Falta a fonte",IF(G28="","Falta a saída que atende",IF(H28="","Falta como verificar",IF(I28="Não atende",IF(J28="","Não atende, sem ação","Não atende: ação em curso"),IF(I28="","Verificação pendente","OK"))))))) -> OK
B29: E5 | C29: Nota de pelo menos 4,0, de 1 a 5, na degustação da equipe. | E29: Funcional ou de desempenho | F29: Padrão do cardápio | G29: Receita final | H29: Degustação com 8 pessoas da equipe | I29: Atende | J29: Nota média de 4,4, em 22/04. | M29: =IF(C29="",IF(1>0,"Falta a entrada",""),IF(E29="","Falta o tipo",IF(F29="","Falta a fonte",IF(G29="","Falta a saída que atende",IF(H29="","Falta como verificar",IF(I29="Não atende",IF(J29="","Não atende, sem ação","Não atende: ação em curso"),IF(I29="","Verificação pendente","OK"))))))) -> OK
B30: E6 | C30: Custo de insumos de até 30% do preço de venda. | E30: Da organização | F30: Ficha técnica e custo por pizza (objetivo O6) | G30: Ficha técnica, com o custo | H30: Cálculo do custo | I30: Não atende | J30: Custo de 34%. Recheio trocado em 18/05; custo a recalcular. | M30: =IF(C30="",IF(1>0,"Falta a entrada",""),IF(E30="","Falta o tipo",IF(F30="","Falta a fonte",IF(G30="","Falta a saída que atende",IF(H30="","Falta como verificar",IF(I30="Não atende",IF(J30="","Não atende, sem ação","Não atende: ação em curso"),IF(I30="","Verificação pendente","OK"))))))) -> Não atende: ação em curso
B31: E7 | C31: Queijo vegetal que derreta sem queimar a 300 °C. | E31: Projeto anterior | F31: Teste com outra marca, no projeto P-01 de 2026 | G31: Marca do queijo vegetal na ficha técnica | H31: Teste no forno | I31: Atende | J31: Marca A aprovada em 22/04. | M31: =IF(C31="",IF(1>0,"Falta a entrada",""),IF(E31="","Falta o tipo",IF(F31="","Falta a fonte",IF(G31="","Falta a saída que atende",IF(H31="","Falta como verificar",IF(I31="Não atende",IF(J31="","Não atende, sem ação","Não atende: ação em curso"),IF(I31="","Verificação pendente","OK"))))))) -> OK
B32: E8 | C32: Fornecedor do queijo vegetal homologado. | E32: Da organização | F32: Avaliação de fornecedores | G32: Fornecedor na lista de homologados | H32: Homologação | M32: =IF(C32="",IF(1>0,"Falta a entrada",""),IF(E32="","Falta o tipo",IF(F32="","Falta a fonte",IF(G32="","Falta a saída que atende",IF(H32="","Falta como verificar",IF(I32="Não atende",IF(J32="","Não atende, sem ação","Não atende: ação em curso"),IF(I32="","Verificação pendente","OK"))))))) -> Verificação pendente
B34: Mudanças de projeto
B35: Data | C35: O que mudou | E35: Motivo | G35: Análise do impacto | I35: O que foi verificado de novo | L35: Quem autorizou | M35: Conferência
B36: 46519 | C36: Queijo vegetal da marca B no lugar da marca A. | E36: Falta no fornecedor. | L36: Pizzaiolo líder | M36: =IF(C36="",IF(1>0,"Falta o que mudou",""),IF(G36="","Falta a análise",IF(L36="","Falta quem autorizou",IF(I36="","Falta o que foi verificado de novo","OK")))) -> Falta a análise
B37: 46525 | C37: Recheio de tofu defumado no lugar da castanha de caju. | E37: Custo de 34% na verificação. | G37: Custo estimado em 29%, a confirmar. | L37: Gerente da loja | M37: =IF(C37="",IF(1>0,"Falta o que mudou",""),IF(G37="","Falta a análise",IF(L37="","Falta quem autorizou",IF(I37="","Falta o que foi verificado de novo","OK")))) -> Falta o que foi verificado de novo
B39: Resumo automático
B40: Etapas: concluídas, atrasadas | F40: =COUNTA(I15:I21)&" de "&COUNTA(C15:C21)&" concluídas, "&COUNTIF(M15:M21,"Atrasada")&" atrasadas" -> 5 de 7 concluídas, 1 atrasadas
B41: Validações aprovadas | F41: =COUNTIFS($E$15:$E$21,"Validação",$J$15:$J$21,"Aprovado")+COUNTIFS($E$15:$E$21,"Validação",$J$15:$J$21,"Aprovado com ressalvas") -> 1
B42: Entradas: atendem, não atendem, pendentes | F42: =COUNTIF(I25:I32,"Atende")&" atendem, "&COUNTIF(I25:I32,"Não atende")&" não atendem, "&COUNTIF(M25:M32,"Verificação pendente")&" pendentes" -> 6 atendem, 1 não atendem, 1 pendentes
B43: Mudanças a rever | F43: =SUMPRODUCT((M36:M37<>"OK")*1) -> 2
B44: Pode liberar? | F44: =IF(AND(COUNTIFS($E$15:$E$21,"Validação",$J$15:$J$21,"Aprovado")+COUNTIFS($E$15:$E$21,"Validação",$J$15:$J$21,"Aprovado com ressalvas")>0,(COUNTIF(I25:I32,"Não atende")+COUNTIF(M25:M32,"Verificação pendente"))=0,SUMPRODUCT((M36:M37<>"OK")*1)=0,SUMPRODUCT((M15:M21<>"OK")*1)=0),"Sim","Ainda não") -> Ainda não

Sheet Exemplo 2 - Indústria
B1: Projeto e desenvolvimento
B2: Exemplo preenchido, para consulta. Use as abas Plano, Entradas e Mudanças para o seu projeto.
B4: Organização | D4: Indústria de embalagens plásticas
B5: Projeto | D5: D-07 · Filme para vegetais congelados
B6: Cliente ou usuário | D6: Cliente C, alimentos congelados (proposta PR-118)
B7: Objetivo | D7: Filme liso de 50 µm que resista ao freezer e ao transporte congelado, para produção regular a partir de outubro de 2027.
B8: Responsável e aprovação | D8: Gerente de engenharia. Aprovação: diretor geral.
B9: Período | D9: De 07/06/2027 a 24/09/2027.
B10: Origem | D10: Pedido PR-118, aceito com alteração em 07/06: lote de teste antes do pedido firme.
B11: Data da leitura | D11: 46629
B13: Plano do projeto
B14: # | C14: Etapa | E14: Tipo | F14: Responsável | G14: Participantes | H14: Prazo | I14: Concluída | J14: Resultado | K14: Ações e ressalvas | L14: Registro | M14: Conferência
B15: 1 | C15: Plano do projeto e entradas, com o cliente | E15: Planejamento | F15: Gerente de engenharia | G15: Comercial, Qualidade e cliente C | H15: 46549 | I15: 46549 | J15: Aprovado | L15: Ata de 11/06 | M15: =IF(C15="",IF(1>0,"Falta a etapa",""),IF(E15="","Falta o tipo",IF(F15="","Falta o responsável",IF(H15="","Falta o prazo",IF(AND(I15<>"",J15=""),"Falta o resultado",IF(AND(J15<>"",I15=""),"Falta a data de conclusão",IF(AND(OR(J15="Aprovado com ressalvas",J15="Reprovado"),K15=""),"Falta a ação",IF(AND(E15="Liberação para produção",I15<>"",COUNTIFS($E$15:$E$23,"Validação",$J$15:$J$23,"Aprovado")+COUNTIFS($E$15:$E$23,"Validação",$J$15:$J$23,"Aprovado com ressalvas")=0),"Liberado sem validação aprovada",IF(AND(I15="",ISNUMBER($D$11),H15<$D$11),"Atrasada","OK"))))))))) -> OK
B16: 2 | C16: Especificação ES-D07 e receita RX-D07 | E16: Desenvolvimento | F16: Gerente de engenharia | G16: Produção | H16: 46563 | I16: 46562 | J16: Aprovado | L16: ES-D07 rev. 1 e RX-D07 rev. 1 | M16: =IF(C16="",IF(1>0,"Falta a etapa",""),IF(E16="","Falta o tipo",IF(F16="","Falta o responsável",IF(H16="","Falta o prazo",IF(AND(I16<>"",J16=""),"Falta o resultado",IF(AND(J16<>"",I16=""),"Falta a data de conclusão",IF(AND(OR(J16="Aprovado com ressalvas",J16="Reprovado"),K16=""),"Falta a ação",IF(AND(E16="Liberação para produção",I16<>"",COUNTIFS($E$15:$E$23,"Validação",$J$15:$J$23,"Aprovado")+COUNTIFS($E$15:$E$23,"Validação",$J$15:$J$23,"Aprovado com ressalvas")=0),"Liberado sem validação aprovada",IF(AND(I16="",ISNUMBER($D$11),H16<$D$11),"Atrasada","OK"))))))))) -> OK
B17: 3 | C17: Análise crítica antes do lote de teste | E17: Análise crítica | F17: Gerente de engenharia | G17: Qualidade, Produção e Comercial | H17: 46566 | I17: 46566 | J17: Aprovado | L17: Ata de 28/06 | M17: =IF(C17="",IF(1>0,"Falta a etapa",""),IF(E17="","Falta o tipo",IF(F17="","Falta o responsável",IF(H17="","Falta o prazo",IF(AND(I17<>"",J17=""),"Falta o resultado",IF(AND(J17<>"",I17=""),"Falta a data de conclusão",IF(AND(OR(J17="Aprovado com ressalvas",J17="Reprovado"),K17=""),"Falta a ação",IF(AND(E17="Liberação para produção",I17<>"",COUNTIFS($E$15:$E$23,"Validação",$J$15:$J$23,"Aprovado")+COUNTIFS($E$15:$E$23,"Validação",$J$15:$J$23,"Aprovado com ressalvas")=0),"Liberado sem validação aprovada",IF(AND(I17="",ISNUMBER($D$11),H17<$D$11),"Atrasada","OK"))))))))) -> OK
B18: 4 | C18: Lote de teste de 500 kg: ensaios contra as entradas | E18: Verificação | F18: Laboratório | G18: Engenharia | H18: 46584 | I18: 46584 | J18: Aprovado com ressalvas | K18: Velocidade de 38 m/min (E8): ajustar no lote 2. | L18: Relatório de ensaios RE-D07-1 | M18: =IF(C18="",IF(1>0,"Falta a etapa",""),IF(E18="","Falta o tipo",IF(F18="","Falta o responsável",IF(H18="","Falta o prazo",IF(AND(I18<>"",J18=""),"Falta o resultado",IF(AND(J18<>"",I18=""),"Falta a data de conclusão",IF(AND(OR(J18="Aprovado com ressalvas",J18="Reprovado"),K18=""),"Falta a ação",IF(AND(E18="Liberação para produção",I18<>"",COUNTIFS($E$15:$E$23,"Validação",$J$15:$J$23,"Aprovado")+COUNTIFS($E$15:$E$23,"Validação",$J$15:$J$23,"Aprovado com ressalvas")=0),"Liberado sem validação aprovada",IF(AND(I18="",ISNUMBER($D$11),H18<$D$11),"Atrasada","OK"))))))))) -> OK
B19: 5 | C19: Embalagem, congelamento e transporte no cliente C, por três semanas | E19: Validação | F19: Gerente de engenharia | G19: Cliente C | H19: 46605 | I19: 46608 | J19: Reprovado | K19: Furos em 4% dos pacotes no transporte. Nova entrada E9: camada interna de 20 µm. | L19: Relatório do cliente C, de 09/08 | M19: =IF(C19="",IF(1>0,"Falta a etapa",""),IF(E19="","Falta o tipo",IF(F19="","Falta o responsável",IF(H19="","Falta o prazo",IF(AND(I19<>"",J19=""),"Falta o resultado",IF(AND(J19<>"",I19=""),"Falta a data de conclusão",IF(AND(OR(J19="Aprovado com ressalvas",J19="Reprovado"),K19=""),"Falta a ação",IF(AND(E19="Liberação para produção",I19<>"",COUNTIFS($E$15:$E$23,"Validação",$J$15:$J$23,"Aprovado")+COUNTIFS($E$15:$E$23,"Validação",$J$15:$J$23,"Aprovado com ressalvas")=0),"Liberado sem validação aprovada",IF(AND(I19="",ISNUMBER($D$11),H19<$D$11),"Atrasada","OK"))))))))) -> OK
B20: 6 | C20: Análise crítica depois da validação | E20: Análise crítica | F20: Gerente de engenharia | G20: Diretor geral, Qualidade e Comercial | H20: 46612 | I20: 46611 | J20: Aprovado | L20: Ata de 12/08 | M20: =IF(C20="",IF(1>0,"Falta a etapa",""),IF(E20="","Falta o tipo",IF(F20="","Falta o responsável",IF(H20="","Falta o prazo",IF(AND(I20<>"",J20=""),"Falta o resultado",IF(AND(J20<>"",I20=""),"Falta a data de conclusão",IF(AND(OR(J20="Aprovado com ressalvas",J20="Reprovado"),K20=""),"Falta a ação",IF(AND(E20="Liberação para produção",I20<>"",COUNTIFS($E$15:$E$23,"Validação",$J$15:$J$23,"Aprovado")+COUNTIFS($E$15:$E$23,"Validação",$J$15:$J$23,"Aprovado com ressalvas")=0),"Liberado sem validação aprovada",IF(AND(I20="",ISNUMBER($D$11),H20<$D$11),"Atrasada","OK"))))))))) -> OK
B21: 7 | C21: Lote 2: ensaios, com perfuração e velocidade | E21: Verificação | F21: Laboratório | G21: Engenharia | H21: 46626 | M21: =IF(C21="",IF(1>0,"Falta a etapa",""),IF(E21="","Falta o tipo",IF(F21="","Falta o responsável",IF(H21="","Falta o prazo",IF(AND(I21<>"",J21=""),"Falta o resultado",IF(AND(J21<>"",I21=""),"Falta a data de conclusão",IF(AND(OR(J21="Aprovado com ressalvas",J21="Reprovado"),K21=""),"Falta a ação",IF(AND(E21="Liberação para produção",I21<>"",COUNTIFS($E$15:$E$23,"Validação",$J$15:$J$23,"Aprovado")+COUNTIFS($E$15:$E$23,"Validação",$J$15:$J$23,"Aprovado com ressalvas")=0),"Liberado sem validação aprovada",IF(AND(I21="",ISNUMBER($D$11),H21<$D$11),"Atrasada","OK"))))))))) -> Atrasada
B22: 8 | C22: Segunda validação no cliente C | E22: Validação | F22: Gerente de engenharia | G22: Cliente C | H22: 46647 | M22: =IF(C22="",IF(1>0,"Falta a etapa",""),IF(E22="","Falta o tipo",IF(F22="","Falta o responsável",IF(H22="","Falta o prazo",IF(AND(I22<>"",J22=""),"Falta o resultado",IF(AND(J22<>"",I22=""),"Falta a data de conclusão",IF(AND(OR(J22="Aprovado com ressalvas",J22="Reprovado"),K22=""),"Falta a ação",IF(AND(E22="Liberação para produção",I22<>"",COUNTIFS($E$15:$E$23,"Validação",$J$15:$J$23,"Aprovado")+COUNTIFS($E$15:$E$23,"Validação",$J$15:$J$23,"Aprovado com ressalvas")=0),"Liberado sem validação aprovada",IF(AND(I22="",ISNUMBER($D$11),H22<$D$11),"Atrasada","OK"))))))))) -> OK
B23: 9 | C23: Liberação para produção regular, com o plano de controle | E23: Liberação para produção | F23: Gerente de engenharia | G23: Produção e Qualidade | H23: 46654 | M23: =IF(C23="",IF(1>0,"Falta a etapa",""),IF(E23="","Falta o tipo",IF(F23="","Falta o responsável",IF(H23="","Falta o prazo",IF(AND(I23<>"",J23=""),"Falta o resultado",IF(AND(J23<>"",I23=""),"Falta a data de conclusão",IF(AND(OR(J23="Aprovado com ressalvas",J23="Reprovado"),K23=""),"Falta a ação",IF(AND(E23="Liberação para produção",I23<>"",COUNTIFS($E$15:$E$23,"Validação",$J$15:$J$23,"Aprovado")+COUNTIFS($E$15:$E$23,"Validação",$J$15:$J$23,"Aprovado com ressalvas")=0),"Liberado sem validação aprovada",IF(AND(I23="",ISNUMBER($D$11),H23<$D$11),"Atrasada","OK"))))))))) -> OK
B25: Entradas, saídas e verificação
B26: # | C26: Entrada | E26: Tipo | F26: Fonte | G26: Saída que atende | H26: Como verificar | I26: Resultado | J26: Evidência ou ação | M26: Conferência
B27: E1 | C27: Espessura de 50 µm, com tolerância de ±2 µm. | E27: Cliente | F27: Proposta PR-118 | G27: Especificação ES-D07 | H27: Micrômetro, cinco pontos, lote de teste | I27: Atende | J27: Média de 50,3 µm, em 16/07. | M27: =IF(C27="",IF(1>0,"Falta a entrada",""),IF(E27="","Falta o tipo",IF(F27="","Falta a fonte",IF(G27="","Falta a saída que atende",IF(H27="","Falta como verificar",IF(I27="Não atende",IF(J27="","Não atende, sem ação","Não atende: ação em curso"),IF(I27="","Verificação pendente","OK"))))))) -> OK
B28: E2 | C28: Largura de 600 mm e bobina de até 600 mm de diâmetro. | E28: Cliente | F28: Visita à embaladora do cliente | G28: Especificação ES-D07 | H28: Medição no lote de teste | I28: Atende | J28: 600 mm e 580 mm de diâmetro. | M28: =IF(C28="",IF(1>0,"Falta a entrada",""),IF(E28="","Falta o tipo",IF(F28="","Falta a fonte",IF(G28="","Falta a saída que atende",IF(H28="","Falta como verificar",IF(I28="Não atende",IF(J28="","Não atende, sem ação","Não atende: ação em curso"),IF(I28="","Verificação pendente","OK"))))))) -> OK
B29: E3 | C29: Queda de dardo de pelo menos 300 g a -18 °C. | E29: Funcional ou de desempenho | F29: Uso pretendido: freezer do cliente | G29: Resina para baixa temperatura e receita RX-D07 | H29: Ensaio de queda de dardo a -18 °C | I29: Atende | J29: 420 g, em 16/07. | M29: =IF(C29="",IF(1>0,"Falta a entrada",""),IF(E29="","Falta o tipo",IF(F29="","Falta a fonte",IF(G29="","Falta a saída que atende",IF(H29="","Falta como verificar",IF(I29="Não atende",IF(J29="","Não atende, sem ação","Não atende: ação em curso"),IF(I29="","Verificação pendente","OK"))))))) -> OK
B30: E4 | C30: Declaração de conformidade para contato com alimentos. | E30: Legal ou regulamentar | F30: Legislação de embalagens para alimentos | G30: Declaração DC-D07, com as resinas e o aditivo | H30: Laudo de migração de laboratório externo | I30: Atende | J30: Laudo de 18/07. | M30: =IF(C30="",IF(1>0,"Falta a entrada",""),IF(E30="","Falta o tipo",IF(F30="","Falta a fonte",IF(G30="","Falta a saída que atende",IF(H30="","Falta como verificar",IF(I30="Não atende",IF(J30="","Não atende, sem ação","Não atende: ação em curso"),IF(I30="","Verificação pendente","OK"))))))) -> OK
B31: E5 | C31: Método de ensaio de queda de dardo da norma técnica. | E31: Norma ou código | F31: Ficha técnica do cliente | G31: Instrução de ensaio IE-12 | H31: Conferência da instrução com a norma | I31: Atende | J31: Instrução revista em 02/07. | M31: =IF(C31="",IF(1>0,"Falta a entrada",""),IF(E31="","Falta o tipo",IF(F31="","Falta a fonte",IF(G31="","Falta a saída que atende",IF(H31="","Falta como verificar",IF(I31="Não atende",IF(J31="","Não atende, sem ação","Não atende: ação em curso"),IF(I31="","Verificação pendente","OK"))))))) -> OK
B32: E6 | C32: Perfil de extrusão do filme de 40 µm como ponto de partida. | E32: Projeto anterior | F32: Receita RX-40 da extrusora 3 | G32: Receita RX-D07 | H32: Lote de teste de 500 kg | I32: Atende | J32: Lote de teste de 15/07. | M32: =IF(C32="",IF(1>0,"Falta a entrada",""),IF(E32="","Falta o tipo",IF(F32="","Falta a fonte",IF(G32="","Falta a saída que atende",IF(H32="","Falta como verificar",IF(I32="Não atende",IF(J32="","Não atende, sem ação","Não atende: ação em curso"),IF(I32="","Verificação pendente","OK"))))))) -> OK
B33: E7 | C33: Selagem sem falhas na embaladora do cliente, a 120 °C. | E33: Cliente | F33: Visita à embaladora do cliente | G33: Faixa de selagem na especificação ES-D07 | H33: Ensaio de selagem no laboratório | I33: Atende | J33: Selagem conforme de 110 a 135 °C. | M33: =IF(C33="",IF(1>0,"Falta a entrada",""),IF(E33="","Falta o tipo",IF(F33="","Falta a fonte",IF(G33="","Falta a saída que atende",IF(H33="","Falta como verificar",IF(I33="Não atende",IF(J33="","Não atende, sem ação","Não atende: ação em curso"),IF(I33="","Verificação pendente","OK"))))))) -> OK
B34: E8 | C34: Velocidade de pelo menos 40 m/min na extrusora 3. | E34: Da organização | F34: Custo-alvo da proposta | G34: Receita RX-D07 | H34: Lote de teste | I34: Não atende | J34: 38 m/min. Ajustar o resfriamento no lote 2. | M34: =IF(C34="",IF(1>0,"Falta a entrada",""),IF(E34="","Falta o tipo",IF(F34="","Falta a fonte",IF(G34="","Falta a saída que atende",IF(H34="","Falta como verificar",IF(I34="Não atende",IF(J34="","Não atende, sem ação","Não atende: ação em curso"),IF(I34="","Verificação pendente","OK"))))))) -> Não atende: ação em curso
B35: E9 | C35: Resistência à perfuração pelas pontas dos vegetais congelados. | E35: Falha potencial | F35: Validação de 09/08: furos no transporte | G35: Camada interna de 20 µm (ES-D07 rev. 2) | H35: Ensaio de perfuração no lote 2 | M35: =IF(C35="",IF(1>0,"Falta a entrada",""),IF(E35="","Falta o tipo",IF(F35="","Falta a fonte",IF(G35="","Falta a saída que atende",IF(H35="","Falta como verificar",IF(I35="Não atende",IF(J35="","Não atende, sem ação","Não atende: ação em curso"),IF(I35="","Verificação pendente","OK"))))))) -> Verificação pendente
B37: Mudanças de projeto
B38: Data | C38: O que mudou | E38: Motivo | G38: Análise do impacto | I38: O que foi verificado de novo | L38: Quem autorizou | M38: Conferência
B39: 46576 | C39: Resina para baixa temperatura do fornecedor B no lugar do fornecedor A. | E39: Prazo de entrega do fornecedor A. | G39: Fichas técnicas comparadas. Laudo de migração estendido à resina B. | I39: Queda de dardo no lote de teste, com a resina B: 420 g, em 16/07, conforme. | L39: Gerente de engenharia | M39: =IF(C39="",IF(1>0,"Falta o que mudou",""),IF(G39="","Falta a análise",IF(L39="","Falta quem autorizou",IF(I39="","Falta o que foi verificado de novo","OK")))) -> OK
B40: 46611 | C40: Camada interna de 15 para 20 µm. | E40: Validação de 09/08: furos no transporte. | G40: Efeito na selagem, no custo e na espessura total avaliado. | I40: Planejado no lote 2: perfuração, selagem e espessura. | L40: Gerente de engenharia | M40: =IF(C40="",IF(1>0,"Falta o que mudou",""),IF(G40="","Falta a análise",IF(L40="","Falta quem autorizou",IF(I40="","Falta o que foi verificado de novo","OK")))) -> OK
B41: 46621 | C41: Espessura total de 50 para 52 µm, para compensar a camada interna. | E41: Pedido da Produção. | L41: Líder do turno | M41: =IF(C41="",IF(1>0,"Falta o que mudou",""),IF(G41="","Falta a análise",IF(L41="","Falta quem autorizou",IF(I41="","Falta o que foi verificado de novo","OK")))) -> Falta a análise
B43: Resumo automático
B44: Etapas: concluídas, atrasadas | F44: =COUNTA(I15:I23)&" de "&COUNTA(C15:C23)&" concluídas, "&COUNTIF(M15:M23,"Atrasada")&" atrasadas" -> 6 de 9 concluídas, 1 atrasadas
B45: Validações aprovadas | F45: =COUNTIFS($E$15:$E$23,"Validação",$J$15:$J$23,"Aprovado")+COUNTIFS($E$15:$E$23,"Validação",$J$15:$J$23,"Aprovado com ressalvas") -> 0
...
