Workbook

Sheet Instruções
B1: RACI — Como usar esta planilha
B2: Modelo para definir quem executa, quem responde, quem é consultado e quem é informado em cada atividade.
B4: Legenda: onde preencher
B5: Amarelo-claro | C5: Células de entrada. É aqui que você digita.
B6: Cinza | C6: Células calculadas ou fixas (rótulos, contagens, avisos). Não altere.
B7: Cinza em itálico | C7: Linha de exemplo (marcada com “Ex.”). Mostra o formato esperado e não entra nas contagens.
B8: Listas suspensas | C8: As células da matriz aceitam apenas R, A, A/R, C ou I. Deixe em branco quando o papel não participa da atividade.
B9: Comentários | C9: Células com triângulo vermelho no canto trazem uma dica de preenchimento. Passe o mouse sobre elas.
B11: As quatro letras
B12: R | C12: Responsável: executa a atividade ou coordena a execução. Pelo menos um por atividade.
B13: A | C13: Aprovador: responde pelo resultado e tem autoridade para decidir. Um, e só um, por atividade.
B14: C | C14: Consultado: é ouvido antes da decisão ou da execução. Conversa de mão dupla.
B15: I | C15: Informado: recebe a notícia do que foi decidido ou feito. Aviso de mão única.
B16: A/R | C16: O mesmo papel executa e responde pelo resultado. Conta como A e como R nas conferências.
B18: Ordem recomendada de preenchimento
B19: Passo 1 | C19: Aba RACI: preencha o cabeçalho, com o processo e o escopo: onde começa e onde termina.
B20: Passo 2 | C20: Aba RACI: liste as atividades, com verbo no infinitivo e objeto, todas no mesmo nível de detalhe.
B21: Passo 3 | C21: Aba RACI: escreva os papéis na linha de cabeçalho da matriz. Use cargos ou funções, e não nomes.
B22: Passo 4 | C22: Aba RACI: marque o A de cada atividade. Um por linha.
B23: Passo 5 | C23: Aba RACI: marque os R. Use A/R quando o mesmo papel executa e responde.
B24: Passo 6 | C24: Aba RACI: marque os C e os I. Na dúvida entre os dois, escolha I.
B25: Passo 7 | C25: Aba RACI: confira os avisos de cada linha e de cada coluna. Aba Análise: veja a carga por papel.
B26: Passo 8 | C26: Aba Comunicação: registre quem ocupa cada papel, quem substitui e como a matriz foi comunicada.
B27: Passo 9 | C27: Aba Checklist: valide a matriz com quem ocupa os papéis.
B29: Abas da planilha
B30: RACI | C30: Modelo principal. Cabeçalho, matriz com até 15 atividades e 8 papéis, conferências e resumo automático.
B31: Análise | C31: Carga de cada papel, com contagem de R, A, C e I, participação, leitura da coluna e gráfico.
B32: Comunicação | C32: Quem ocupa cada papel, quem substitui, e como e quando a matriz foi comunicada e entendida.
B33: Checklist | C33: Doze verificações de qualidade da matriz, com percentual de conclusão.
B34: Exemplo 1 - Pizzaria | C34: Matriz preenchida de um processo operacional, com cinco papéis.
B35: Exemplo 2 - Compras | C35: Matriz preenchida de um processo que atravessa seis áreas, com avisos de gargalo e de sobrecarga.
B37: Regras e premissas do modelo
B38: Conferência da linha | C38: Cada atividade deve ter um único A e pelo menos um R. O aviso também aparece quando há mais de três consultados ou quando todos os papéis participam da atividade.
B39: Conferência da coluna | C39: Com cinco atividades ou mais, o aviso aparece quando um papel tem A ou R em mais de 60% delas. O limite é uma referência do modelo: a decisão sobre redistribuir é do grupo.
B40: Papéis, não pessoas | C40: As colunas da matriz trazem cargos ou funções. A relação entre o papel e as pessoas que o ocupam fica na aba Comunicação.
B41: Célula em branco | C41: Deixar a célula em branco é uma resposta válida: o papel não participa da atividade.
B42: Capacidade | C42: A planilha comporta 15 atividades e 8 papéis. Se faltar espaço, divida o processo em duas matrizes.
B43: Exemplos | C43: Os dados das abas de exemplo são ilustrativos, criados para este material.

Sheet RACI
B1: RACI — Matriz de responsabilidades
B2: Preencha as células em amarelo-claro. As células cinza são calculadas automaticamente.
B4: Processo ou projeto | H4: Dono do processo
B5: Área / unidade | H5: Data
B6: Elaborado por | H6: Versão
B7: Escopo
B8: Origem das atividades | H8: Participantes
B9: Fora do escopo
B11: Atividades | E11: Papéis | M11: Conferência da linha
B12: # | C12: Atividade | M12: A | N12: R | O12: Aviso da linha
C13: Verbo no infinitivo + objeto | E13: Cargo ou função na linha de cima. Nas células: R, A, A/R, C ou I | M13: Deve ser 1 | N13: 1 ou mais | O13: Calculado
B14: Ex. | C14: Cotar com fornecedores | E14: C | F14: A/R | M14: 1 | N14: 1 | O14: OK
B15: 1 | M15: =IF(C15="","",COUNTIF(E15:L15,"A")+COUNTIF(E15:L15,"A/R")) | N15: =IF(C15="","",COUNTIF(E15:L15,"R")+COUNTIF(E15:L15,"A/R")) | O15: =IF(C15="","",IF(COUNTA(E15:L15)=0,"Distribua os papéis",IF(M15=0,"Falta o A",IF(M15>1,"Mais de um A",IF(N15=0,"Falta o R",IF(COUNTIF(E15:L15,"C")>3,"Muitos consultados",IF(COUNTA(E15:L15)=COUNTA($E$12:$L$12),"Todos participam: confira","OK")))))))
B16: 2 | M16: =IF(C16="","",COUNTIF(E16:L16,"A")+COUNTIF(E16:L16,"A/R")) | N16: =IF(C16="","",COUNTIF(E16:L16,"R")+COUNTIF(E16:L16,"A/R")) | O16: =IF(C16="","",IF(COUNTA(E16:L16)=0,"Distribua os papéis",IF(M16=0,"Falta o A",IF(M16>1,"Mais de um A",IF(N16=0,"Falta o R",IF(COUNTIF(E16:L16,"C")>3,"Muitos consultados",IF(COUNTA(E16:L16)=COUNTA($E$12:$L$12),"Todos participam: confira","OK")))))))
B17: 3 | M17: =IF(C17="","",COUNTIF(E17:L17,"A")+COUNTIF(E17:L17,"A/R")) | N17: =IF(C17="","",COUNTIF(E17:L17,"R")+COUNTIF(E17:L17,"A/R")) | O17: =IF(C17="","",IF(COUNTA(E17:L17)=0,"Distribua os papéis",IF(M17=0,"Falta o A",IF(M17>1,"Mais de um A",IF(N17=0,"Falta o R",IF(COUNTIF(E17:L17,"C")>3,"Muitos consultados",IF(COUNTA(E17:L17)=COUNTA($E$12:$L$12),"Todos participam: confira","OK")))))))
B18: 4 | M18: =IF(C18="","",COUNTIF(E18:L18,"A")+COUNTIF(E18:L18,"A/R")) | N18: =IF(C18="","",COUNTIF(E18:L18,"R")+COUNTIF(E18:L18,"A/R")) | O18: =IF(C18="","",IF(COUNTA(E18:L18)=0,"Distribua os papéis",IF(M18=0,"Falta o A",IF(M18>1,"Mais de um A",IF(N18=0,"Falta o R",IF(COUNTIF(E18:L18,"C")>3,"Muitos consultados",IF(COUNTA(E18:L18)=COUNTA($E$12:$L$12),"Todos participam: confira","OK")))))))
B19: 5 | M19: =IF(C19="","",COUNTIF(E19:L19,"A")+COUNTIF(E19:L19,"A/R")) | N19: =IF(C19="","",COUNTIF(E19:L19,"R")+COUNTIF(E19:L19,"A/R")) | O19: =IF(C19="","",IF(COUNTA(E19:L19)=0,"Distribua os papéis",IF(M19=0,"Falta o A",IF(M19>1,"Mais de um A",IF(N19=0,"Falta o R",IF(COUNTIF(E19:L19,"C")>3,"Muitos consultados",IF(COUNTA(E19:L19)=COUNTA($E$12:$L$12),"Todos participam: confira","OK")))))))
B20: 6 | M20: =IF(C20="","",COUNTIF(E20:L20,"A")+COUNTIF(E20:L20,"A/R")) | N20: =IF(C20="","",COUNTIF(E20:L20,"R")+COUNTIF(E20:L20,"A/R")) | O20: =IF(C20="","",IF(COUNTA(E20:L20)=0,"Distribua os papéis",IF(M20=0,"Falta o A",IF(M20>1,"Mais de um A",IF(N20=0,"Falta o R",IF(COUNTIF(E20:L20,"C")>3,"Muitos consultados",IF(COUNTA(E20:L20)=COUNTA($E$12:$L$12),"Todos participam: confira","OK")))))))
B21: 7 | M21: =IF(C21="","",COUNTIF(E21:L21,"A")+COUNTIF(E21:L21,"A/R")) | N21: =IF(C21="","",COUNTIF(E21:L21,"R")+COUNTIF(E21:L21,"A/R")) | O21: =IF(C21="","",IF(COUNTA(E21:L21)=0,"Distribua os papéis",IF(M21=0,"Falta o A",IF(M21>1,"Mais de um A",IF(N21=0,"Falta o R",IF(COUNTIF(E21:L21,"C")>3,"Muitos consultados",IF(COUNTA(E21:L21)=COUNTA($E$12:$L$12),"Todos participam: confira","OK")))))))
B22: 8 | M22: =IF(C22="","",COUNTIF(E22:L22,"A")+COUNTIF(E22:L22,"A/R")) | N22: =IF(C22="","",COUNTIF(E22:L22,"R")+COUNTIF(E22:L22,"A/R")) | O22: =IF(C22="","",IF(COUNTA(E22:L22)=0,"Distribua os papéis",IF(M22=0,"Falta o A",IF(M22>1,"Mais de um A",IF(N22=0,"Falta o R",IF(COUNTIF(E22:L22,"C")>3,"Muitos consultados",IF(COUNTA(E22:L22)=COUNTA($E$12:$L$12),"Todos participam: confira","OK")))))))
B23: 9 | M23: =IF(C23="","",COUNTIF(E23:L23,"A")+COUNTIF(E23:L23,"A/R")) | N23: =IF(C23="","",COUNTIF(E23:L23,"R")+COUNTIF(E23:L23,"A/R")) | O23: =IF(C23="","",IF(COUNTA(E23:L23)=0,"Distribua os papéis",IF(M23=0,"Falta o A",IF(M23>1,"Mais de um A",IF(N23=0,"Falta o R",IF(COUNTIF(E23:L23,"C")>3,"Muitos consultados",IF(COUNTA(E23:L23)=COUNTA($E$12:$L$12),"Todos participam: confira","OK")))))))
B24: 10 | M24: =IF(C24="","",COUNTIF(E24:L24,"A")+COUNTIF(E24:L24,"A/R")) | N24: =IF(C24="","",COUNTIF(E24:L24,"R")+COUNTIF(E24:L24,"A/R")) | O24: =IF(C24="","",IF(COUNTA(E24:L24)=0,"Distribua os papéis",IF(M24=0,"Falta o A",IF(M24>1,"Mais de um A",IF(N24=0,"Falta o R",IF(COUNTIF(E24:L24,"C")>3,"Muitos consultados",IF(COUNTA(E24:L24)=COUNTA($E$12:$L$12),"Todos participam: confira","OK")))))))
B25: 11 | M25: =IF(C25="","",COUNTIF(E25:L25,"A")+COUNTIF(E25:L25,"A/R")) | N25: =IF(C25="","",COUNTIF(E25:L25,"R")+COUNTIF(E25:L25,"A/R")) | O25: =IF(C25="","",IF(COUNTA(E25:L25)=0,"Distribua os papéis",IF(M25=0,"Falta o A",IF(M25>1,"Mais de um A",IF(N25=0,"Falta o R",IF(COUNTIF(E25:L25,"C")>3,"Muitos consultados",IF(COUNTA(E25:L25)=COUNTA($E$12:$L$12),"Todos participam: confira","OK")))))))
B26: 12 | M26: =IF(C26="","",COUNTIF(E26:L26,"A")+COUNTIF(E26:L26,"A/R")) | N26: =IF(C26="","",COUNTIF(E26:L26,"R")+COUNTIF(E26:L26,"A/R")) | O26: =IF(C26="","",IF(COUNTA(E26:L26)=0,"Distribua os papéis",IF(M26=0,"Falta o A",IF(M26>1,"Mais de um A",IF(N26=0,"Falta o R",IF(COUNTIF(E26:L26,"C")>3,"Muitos consultados",IF(COUNTA(E26:L26)=COUNTA($E$12:$L$12),"Todos participam: confira","OK")))))))
... B29: 15 | M29: =IF(C29="","",COUNTIF(E29:L29,"A")+COUNTIF(E29:L29,"A/R")) | N29: =IF(C29="","",COUNTIF(E29:L29,"R")+COUNTIF(E29:L29,"A/R")) | O29: =IF(C29="","",IF(COUNTA(E29:L29)=0,"Distribua os papéis",IF(M29=0,"Falta o A",IF(M29>1,"Mais de um A",IF(N29=0,"Falta o R",IF(COUNTIF(E29:L29,"C")>3,"Muitos consultados",IF(COUNTA(E29:L29)=COUNTA($E$12:$L$12),"Todos participam: confira","OK")))))))
B31: Conferência da coluna: carga por papel
B32: R | C32: Atividades em que executa (R) | E32: =IF(AND(E$12="",COUNTA(E15:E29)=0),"",COUNTIF(E15:E29,"R")+COUNTIF(E15:E29,"A/R")) | F32: =IF(AND(F$12="",COUNTA(F15:F29)=0),"",COUNTIF(F15:F29,"R")+COUNTIF(F15:F29,"A/R")) | G32: =IF(AND(G$12="",COUNTA(G15:G29)=0),"",COUNTIF(G15:G29,"R")+COUNTIF(G15:G29,"A/R")) | H32: =IF(AND(H$12="",COUNTA(H15:H29)=0),"",COUNTIF(H15:H29,"R")+COUNTIF(H15:H29,"A/R")) | I32: =IF(AND(I$12="",COUNTA(I15:I29)=0),"",COUNTIF(I15:I29,"R")+COUNTIF(I15:I29,"A/R")) | J32: =IF(AND(J$12="",COUNTA(J15:J29)=0),"",COUNTIF(J15:J29,"R")+COUNTIF(J15:J29,"A/R")) | K32: =IF(AND(K$12="",COUNTA(K15:K29)=0),"",COUNTIF(K15:K29,"R")+COUNTIF(K15:K29,"A/R")) | L32: =IF(AND(L$12="",COUNTA(L15:L29)=0),"",COUNTIF(L15:L29,"R")+COUNTIF(L15:L29,"A/R"))
B33: A | C33: Atividades em que responde (A) | E33: =IF(AND(E$12="",COUNTA(E15:E29)=0),"",COUNTIF(E15:E29,"A")+COUNTIF(E15:E29,"A/R")) | F33: =IF(AND(F$12="",COUNTA(F15:F29)=0),"",COUNTIF(F15:F29,"A")+COUNTIF(F15:F29,"A/R")) | G33: =IF(AND(G$12="",COUNTA(G15:G29)=0),"",COUNTIF(G15:G29,"A")+COUNTIF(G15:G29,"A/R")) | H33: =IF(AND(H$12="",COUNTA(H15:H29)=0),"",COUNTIF(H15:H29,"A")+COUNTIF(H15:H29,"A/R")) | I33: =IF(AND(I$12="",COUNTA(I15:I29)=0),"",COUNTIF(I15:I29,"A")+COUNTIF(I15:I29,"A/R")) | J33: =IF(AND(J$12="",COUNTA(J15:J29)=0),"",COUNTIF(J15:J29,"A")+COUNTIF(J15:J29,"A/R")) | K33: =IF(AND(K$12="",COUNTA(K15:K29)=0),"",COUNTIF(K15:K29,"A")+COUNTIF(K15:K29,"A/R")) | L33: =IF(AND(L$12="",COUNTA(L15:L29)=0),"",COUNTIF(L15:L29,"A")+COUNTIF(L15:L29,"A/R"))
B34: C | C34: Atividades em que é consultado (C) | E34: =IF(AND(E$12="",COUNTA(E15:E29)=0),"",COUNTIF(E15:E29,"C")) | F34: =IF(AND(F$12="",COUNTA(F15:F29)=0),"",COUNTIF(F15:F29,"C")) | G34: =IF(AND(G$12="",COUNTA(G15:G29)=0),"",COUNTIF(G15:G29,"C")) | H34: =IF(AND(H$12="",COUNTA(H15:H29)=0),"",COUNTIF(H15:H29,"C")) | I34: =IF(AND(I$12="",COUNTA(I15:I29)=0),"",COUNTIF(I15:I29,"C")) | J34: =IF(AND(J$12="",COUNTA(J15:J29)=0),"",COUNTIF(J15:J29,"C")) | K34: =IF(AND(K$12="",COUNTA(K15:K29)=0),"",COUNTIF(K15:K29,"C")) | L34: =IF(AND(L$12="",COUNTA(L15:L29)=0),"",COUNTIF(L15:L29,"C"))
B35: I | C35: Atividades em que é informado (I) | E35: =IF(AND(E$12="",COUNTA(E15:E29)=0),"",COUNTIF(E15:E29,"I")) | F35: =IF(AND(F$12="",COUNTA(F15:F29)=0),"",COUNTIF(F15:F29,"I")) | G35: =IF(AND(G$12="",COUNTA(G15:G29)=0),"",COUNTIF(G15:G29,"I")) | H35: =IF(AND(H$12="",COUNTA(H15:H29)=0),"",COUNTIF(H15:H29,"I")) | I35: =IF(AND(I$12="",COUNTA(I15:I29)=0),"",COUNTIF(I15:I29,"I")) | J35: =IF(AND(J$12="",COUNTA(J15:J29)=0),"",COUNTIF(J15:J29,"I")) | K35: =IF(AND(K$12="",COUNTA(K15:K29)=0),"",COUNTIF(K15:K29,"I")) | L35: =IF(AND(L$12="",COUNTA(L15:L29)=0),"",COUNTIF(L15:L29,"I"))
B36: Total de participações | E36: =IF(AND(E$12="",COUNTA(E15:E29)=0),"",COUNTA(E15:E29)) | F36: =IF(AND(F$12="",COUNTA(F15:F29)=0),"",COUNTA(F15:F29)) | G36: =IF(AND(G$12="",COUNTA(G15:G29)=0),"",COUNTA(G15:G29)) | H36: =IF(AND(H$12="",COUNTA(H15:H29)=0),"",COUNTA(H15:H29)) | I36: =IF(AND(I$12="",COUNTA(I15:I29)=0),"",COUNTA(I15:I29)) | J36: =IF(AND(J$12="",COUNTA(J15:J29)=0),"",COUNTA(J15:J29)) | K36: =IF(AND(K$12="",COUNTA(K15:K29)=0),"",COUNTA(K15:K29)) | L36: =IF(AND(L$12="",COUNTA(L15:L29)=0),"",COUNTA(L15:L29))
B37: Aviso da coluna | E37: =IF(E$12="",IF(COUNTA(E15:E29)>0,"Papel sem nome",""),IF(E36=0,"Sem participação",IF(AND($H$40>=5,E33/$H$40>0.6),"Muitos A: possível gargalo",IF(AND($H$40>=5,E32/$H$40>0.6),"Muitos R: possível sobrecarga",IF(E32+E33=0,IF(E34=0,"Só informado","Só consultado ou informado"),"OK"))))) | F37: =IF(F$12="",IF(COUNTA(F15:F29)>0,"Papel sem nome",""),IF(F36=0,"Sem participação",IF(AND($H$40>=5,F33/$H$40>0.6),"Muitos A: possível gargalo",IF(AND($H$40>=5,F32/$H$40>0.6),"Muitos R: possível sobrecarga",IF(F32+F33=0,IF(F34=0,"Só informado","Só consultado ou informado"),"OK"))))) | G37: =IF(G$12="",IF(COUNTA(G15:G29)>0,"Papel sem nome",""),IF(G36=0,"Sem participação",IF(AND($H$40>=5,G33/$H$40>0.6),"Muitos A: possível gargalo",IF(AND($H$40>=5,G32/$H$40>0.6),"Muitos R: possível sobrecarga",IF(G32+G33=0,IF(G34=0,"Só informado","Só consultado ou informado"),"OK"))))) | H37: =IF(H$12="",IF(COUNTA(H15:H29)>0,"Papel sem nome",""),IF(H36=0,"Sem participação",IF(AND($H$40>=5,H33/$H$40>0.6),"Muitos A: possível gargalo",IF(AND($H$40>=5,H32/$H$40>0.6),"Muitos R: possível sobrecarga",IF(H32+H33=0,IF(H34=0,"Só informado","Só consultado ou informado"),"OK"))))) | I37: =IF(I$12="",IF(COUNTA(I15:I29)>0,"Papel sem nome",""),IF(I36=0,"Sem participação",IF(AND($H$40>=5,I33/$H$40>0.6),"Muitos A: possível gargalo",IF(AND($H$40>=5,I32/$H$40>0.6),"Muitos R: possível sobrecarga",IF(I32+I33=0,IF(I34=0,"Só informado","Só consultado ou informado"),"OK"))))) | J37: =IF(J$12="",IF(COUNTA(J15:J29)>0,"Papel sem nome",""),IF(J36=0,"Sem participação",IF(AND($H$40>=5,J33/$H$40>0.6),"Muitos A: possível gargalo",IF(AND($H$40>=5,J32/$H$40>0.6),"Muitos R: possível sobrecarga",IF(J32+J33=0,IF(J34=0,"Só informado","Só consultado ou informado"),"OK"))))) | K37: =IF(K$12="",IF(COUNTA(K15:K29)>0,"Papel sem nome",""),IF(K36=0,"Sem participação",IF(AND($H$40>=5,K33/$H$40>0.6),"Muitos A: possível gargalo",IF(AND($H$40>=5,K32/$H$40>0.6),"Muitos R: possível sobrecarga",IF(K32+K33=0,IF(K34=0,"Só informado","Só consultado ou informado"),"OK"))))) | L37: =IF(L$12="",IF(COUNTA(L15:L29)>0,"Papel sem nome",""),IF(L36=0,"Sem participação",IF(AND($H$40>=5,L33/$H$40>0.6),"Muitos A: possível gargalo",IF(AND($H$40>=5,L32/$H$40>0.6),"Muitos R: possível sobrecarga",IF(L32+L33=0,IF(L34=0,"Só informado","Só consultado ou informado"),"OK")))))
B39: Resumo automático
B40: Atividades listadas | H40: =COUNTA(C15:C29) -> 0
B41: Papéis definidos | H41: =COUNTA(E12:L12) -> 0
B42: Atividades sem aviso | H42: =COUNTIF(O15:O29,"OK") -> 0
B43: Atividades sem A ou com mais de um A | H43: =COUNTIF(O15:O29,"Falta o A")+COUNTIF(O15:O29,"Mais de um A") -> 0
B44: Atividades sem R | H44: =COUNTIF(O15:O29,"Falta o R") -> 0
B45: Papéis com aviso | H45: =SUMPRODUCT((E37:L37<>"")*(E37:L37<>"OK")) -> 0
B46: Situação da matriz | H46: =IF(H40=0,"Liste as atividades",IF(H41=0,"Defina os papéis",IF(H42<H40,"Há atividade com aviso: veja a conferência da linha","Linhas conferidas"))) -> Liste as atividades
...

Sheet Análise
B1: Análise — carga por papel
B2: Esta aba é calculada a partir da aba RACI. Não há nada para digitar aqui.
B4: Participação de cada papel
B5: # | C5: Papel | D5: R | E5: A | F5: C | G5: I | H5: Total | I5: Atividades de que participa | J5: Leitura da coluna
B6: 1 | C6: =IF(RACI!E12="","",RACI!E12) | D6: =IF(C6="","",RACI!E32) | E6: =IF(C6="","",RACI!E33) | F6: =IF(C6="","",RACI!E34) | G6: =IF(C6="","",RACI!E35) | H6: =IF(C6="","",RACI!E36) | I6: =IF(OR(C6="",RACI!$H$40=0),"",H6/RACI!$H$40) | J6: =IF(C6="","",RACI!E37)
B7: 2 | C7: =IF(RACI!F12="","",RACI!F12) | D7: =IF(C7="","",RACI!F32) | E7: =IF(C7="","",RACI!F33) | F7: =IF(C7="","",RACI!F34) | G7: =IF(C7="","",RACI!F35) | H7: =IF(C7="","",RACI!F36) | I7: =IF(OR(C7="",RACI!$H$40=0),"",H7/RACI!$H$40) | J7: =IF(C7="","",RACI!F37)
B8: 3 | C8: =IF(RACI!G12="","",RACI!G12) | D8: =IF(C8="","",RACI!G32) | E8: =IF(C8="","",RACI!G33) | F8: =IF(C8="","",RACI!G34) | G8: =IF(C8="","",RACI!G35) | H8: =IF(C8="","",RACI!G36) | I8: =IF(OR(C8="",RACI!$H$40=0),"",H8/RACI!$H$40) | J8: =IF(C8="","",RACI!G37)
B9: 4 | C9: =IF(RACI!H12="","",RACI!H12) | D9: =IF(C9="","",RACI!H32) | E9: =IF(C9="","",RACI!H33) | F9: =IF(C9="","",RACI!H34) | G9: =IF(C9="","",RACI!H35) | H9: =IF(C9="","",RACI!H36) | I9: =IF(OR(C9="",RACI!$H$40=0),"",H9/RACI!$H$40) | J9: =IF(C9="","",RACI!H37)
B10: 5 | C10: =IF(RACI!I12="","",RACI!I12) | D10: =IF(C10="","",RACI!I32) | E10: =IF(C10="","",RACI!I33) | F10: =IF(C10="","",RACI!I34) | G10: =IF(C10="","",RACI!I35) | H10: =IF(C10="","",RACI!I36) | I10: =IF(OR(C10="",RACI!$H$40=0),"",H10/RACI!$H$40) | J10: =IF(C10="","",RACI!I37)
B11: 6 | C11: =IF(RACI!J12="","",RACI!J12) | D11: =IF(C11="","",RACI!J32) | E11: =IF(C11="","",RACI!J33) | F11: =IF(C11="","",RACI!J34) | G11: =IF(C11="","",RACI!J35) | H11: =IF(C11="","",RACI!J36) | I11: =IF(OR(C11="",RACI!$H$40=0),"",H11/RACI!$H$40) | J11: =IF(C11="","",RACI!J37)
B12: 7 | C12: =IF(RACI!K12="","",RACI!K12) | D12: =IF(C12="","",RACI!K32) | E12: =IF(C12="","",RACI!K33) | F12: =IF(C12="","",RACI!K34) | G12: =IF(C12="","",RACI!K35) | H12: =IF(C12="","",RACI!K36) | I12: =IF(OR(C12="",RACI!$H$40=0),"",H12/RACI!$H$40) | J12: =IF(C12="","",RACI!K37)
B13: 8 | C13: =IF(RACI!L12="","",RACI!L12) | D13: =IF(C13="","",RACI!L32) | E13: =IF(C13="","",RACI!L33) | F13: =IF(C13="","",RACI!L34) | G13: =IF(C13="","",RACI!L35) | H13: =IF(C13="","",RACI!L36) | I13: =IF(OR(C13="",RACI!$H$40=0),"",H13/RACI!$H$40) | J13: =IF(C13="","",RACI!L37)
B15: Resumo automático
B16: Atividades na matriz | D16: =RACI!$H$40 -> 0
B17: Papéis na matriz | D17: =RACI!$H$41 -> 0
B18: Papel com mais R | D18: =IF(MAX(D6:D13)=0,"",INDEX(C6:C13,MATCH(MAX(D6:D13),D6:D13,0)))
B19: Papel com mais A | D19: =IF(MAX(E6:E13)=0,"",INDEX(C6:C13,MATCH(MAX(E6:E13),E6:E13,0)))
B20: Letras por atividade, em média | D20: =IF(RACI!$H$40=0,0,SUM(H6:H13)/RACI!$H$40) -> 0
B21: Papéis com aviso | D21: =RACI!$H$45 -> 0
B23: Gráfico: letras por papel

Sheet Comunicação
B1: Comunicação dos papéis
B2: Os papéis vêm da aba RACI. Registre quem ocupa cada um, quem substitui e como a matriz foi comunicada.
B4: # | C4: Papel | D4: Quem ocupa | E4: Substituto | F4: Forma de comunicação | G4: Data | H4: Entendido? | I4: Observações
B5: Ex. | C5: Comprador | D5: Três compradores da equipe de Suprimentos | E5: Comprador sênior | F5: Reunião da área, com a matriz projetada | G5: 46325 | H5: Sim | I5: Matriz afixada no quadro da área
B6: 1 | C6: =IF(RACI!E12="","",RACI!E12)
B7: 2 | C7: =IF(RACI!F12="","",RACI!F12)
B8: 3 | C8: =IF(RACI!G12="","",RACI!G12)
B9: 4 | C9: =IF(RACI!H12="","",RACI!H12)
B10: 5 | C10: =IF(RACI!I12="","",RACI!I12)
B11: 6 | C11: =IF(RACI!J12="","",RACI!J12)
B12: 7 | C12: =IF(RACI!K12="","",RACI!K12)
B13: 8 | C13: =IF(RACI!L12="","",RACI!L12)
B15: Resumo automático
B16: Papéis na matriz | F16: =SUMPRODUCT(--(C6:C13<>"")) -> 0
B17: Papéis com ocupante registrado | F17: =SUMPRODUCT((C6:C13<>"")*(D6:D13<>"")) -> 0
B18: Papéis com substituto | F18: =SUMPRODUCT((C6:C13<>"")*(E6:E13<>"")) -> 0
B19: Papéis comunicados | F19: =SUMPRODUCT((C6:C13<>"")*(G6:G13<>"")) -> 0
B20: Papéis que entenderam (Sim) | F20: =COUNTIF(H6:H13,"Sim") -> 0
B21: Situação | F21: =IF(F16=0,"Defina os papéis na aba RACI",IF(F19<F16,"Há papel sem comunicação registrada",IF(F20<F16,"Há papel sem entendimento confirmado","Matriz comunicada e entendida"))) -> Defina os papéis na aba RACI

Sheet Checklist
B1: Checklist de validação da Matriz RACI
B2: Escolha o status de cada item na lista suspensa (coluna em amarelo-claro).
B4: # | C4: Item de verificação | D4: Status | E4: Observações
B5: 1 | C5: O escopo da matriz está definido: um processo ou um projeto, com início e fim.
B6: 2 | C6: As atividades estão escritas com verbo no infinitivo e objeto.
B7: 3 | C7: As atividades têm o mesmo nível de detalhe.
B8: 4 | C8: As colunas trazem papéis ou cargos, e não nomes de pessoas.
B9: 5 | C9: Cada atividade tem um único A.
B10: 6 | C10: Cada atividade tem pelo menos um R.
B11: 7 | C11: Os consultados de cada atividade são só os necessários.
B12: 8 | C12: Nenhum papel concentra R ou A a ponto de virar sobrecarga ou gargalo.
B13: 9 | C13: Quem tem o A tem autoridade para decidir sobre a atividade.
B14: 10 | C14: A matriz foi construída com a participação de quem ocupa os papéis.
B15: 11 | C15: A matriz foi comunicada, e as pessoas entendem o próprio papel.
B16: 12 | C16: A data da próxima revisão está marcada.
B18: Resumo automático
B19: Itens atendidos (Sim) | D19: =COUNTIF(D5:D16,"Sim") -> 0
B20: Itens parciais | D20: =COUNTIF(D5:D16,"Parcial") -> 0
B21: Itens não atendidos | D21: =COUNTIF(D5:D16,"Não") -> 0
B22: Itens sem resposta | D22: =COUNTBLANK(D5:D16) -> 12
B23: Percentual atendido | D23: =D19/ROWS(D5:D16) -> 0
B24: Situação | D24: =IF(D19=ROWS(D5:D16),"Validado",IF(D22>0,"Em andamento","Com pendências")) -> Em andamento

Sheet Exemplo 1 - Pizzaria
B1: RACI — Matriz de responsabilidades
B2: Exemplo preenchido, para consulta. Use a aba RACI para a sua matriz.
B4: Processo ou projeto | D4: Atender pedido de delivery | H4: Dono do processo | J4: Gerente da loja
B5: Área / unidade | D5: Pizzaria (loja) | H5: Data | J5: 46294
B6: Elaborado por | D6: Equipe da loja | H6: Versão | J6: 1.0
B7: Escopo | D7: Do pedido confirmado pelo cliente até o pagamento recebido, mais a rotina de escala e de acompanhamento.
B8: Origem das atividades | D8: Macroetapas do SIPOC do processo | H8: Participantes | J8: Gerente, atendente, pizzaiolo, líder da expedição e um entregador
B9: Fora do escopo | D9: Compra de ingredientes e atendimento no salão.
B11: Atividades | E11: Papéis | M11: Conferência da linha
B12: # | C12: Atividade | E12: Gerente da loja | F12: Atendente | G12: Pizzaiolo | H12: Líder da expedição | I12: Entregador | M12: A | N12: R | O12: Aviso da linha
C13: Verbo no infinitivo + objeto | E13: Cargo ou função na linha de cima. Nas células: R, A, A/R, C ou I | M13: Deve ser 1 | N13: 1 ou mais | O13: Calculado
B14: Leia na horizontal para conferir cada atividade: um A e pelo menos um R. Leia na vertical para conferir a carga de cada papel.
B15: 1 | C15: Registrar o pedido | F15: A/R | G15: I | H15: I | M15: =IF(C15="","",COUNTIF(E15:L15,"A")+COUNTIF(E15:L15,"A/R")) -> 1 | N15: =IF(C15="","",COUNTIF(E15:L15,"R")+COUNTIF(E15:L15,"A/R")) -> 1 | O15: =IF(C15="","",IF(COUNTA(E15:L15)=0,"Distribua os papéis",IF(M15=0,"Falta o A",IF(M15>1,"Mais de um A",IF(N15=0,"Falta o R",IF(COUNTIF(E15:L15,"C")>3,"Muitos consultados",IF(COUNTA(E15:L15)=COUNTA($E$12:$L$12),"Todos participam: confira","OK"))))))) -> OK
B16: 2 | C16: Montar e assar a pizza | F16: C | G16: A/R | H16: I | M16: =IF(C16="","",COUNTIF(E16:L16,"A")+COUNTIF(E16:L16,"A/R")) -> 1 | N16: =IF(C16="","",COUNTIF(E16:L16,"R")+COUNTIF(E16:L16,"A/R")) -> 1 | O16: =IF(C16="","",IF(COUNTA(E16:L16)=0,"Distribua os papéis",IF(M16=0,"Falta o A",IF(M16>1,"Mais de um A",IF(N16=0,"Falta o R",IF(COUNTIF(E16:L16,"C")>3,"Muitos consultados",IF(COUNTA(E16:L16)=COUNTA($E$12:$L$12),"Todos participam: confira","OK"))))))) -> OK
B17: 3 | C17: Embalar e conferir o pedido | G17: C | H17: A/R | M17: =IF(C17="","",COUNTIF(E17:L17,"A")+COUNTIF(E17:L17,"A/R")) -> 1 | N17: =IF(C17="","",COUNTIF(E17:L17,"R")+COUNTIF(E17:L17,"A/R")) -> 1 | O17: =IF(C17="","",IF(COUNTA(E17:L17)=0,"Distribua os papéis",IF(M17=0,"Falta o A",IF(M17>1,"Mais de um A",IF(N17=0,"Falta o R",IF(COUNTIF(E17:L17,"C")>3,"Muitos consultados",IF(COUNTA(E17:L17)=COUNTA($E$12:$L$12),"Todos participam: confira","OK"))))))) -> OK
B18: 4 | C18: Agrupar os pedidos por bairro e despachar | E18: I | H18: A/R | I18: I | M18: =IF(C18="","",COUNTIF(E18:L18,"A")+COUNTIF(E18:L18,"A/R")) -> 1 | N18: =IF(C18="","",COUNTIF(E18:L18,"R")+COUNTIF(E18:L18,"A/R")) -> 1 | O18: =IF(C18="","",IF(COUNTA(E18:L18)=0,"Distribua os papéis",IF(M18=0,"Falta o A",IF(M18>1,"Mais de um A",IF(N18=0,"Falta o R",IF(COUNTIF(E18:L18,"C")>3,"Muitos consultados",IF(COUNTA(E18:L18)=COUNTA($E$12:$L$12),"Todos participam: confira","OK"))))))) -> OK
B19: 5 | C19: Entregar ao cliente | F19: I | H19: A | I19: R | M19: =IF(C19="","",COUNTIF(E19:L19,"A")+COUNTIF(E19:L19,"A/R")) -> 1 | N19: =IF(C19="","",COUNTIF(E19:L19,"R")+COUNTIF(E19:L19,"A/R")) -> 1 | O19: =IF(C19="","",IF(COUNTA(E19:L19)=0,"Distribua os papéis",IF(M19=0,"Falta o A",IF(M19>1,"Mais de um A",IF(N19=0,"Falta o R",IF(COUNTIF(E19:L19,"C")>3,"Muitos consultados",IF(COUNTA(E19:L19)=COUNTA($E$12:$L$12),"Todos participam: confira","OK"))))))) -> OK
B20: 6 | C20: Confirmar o pagamento | E20: I | F20: A | I20: R | M20: =IF(C20="","",COUNTIF(E20:L20,"A")+COUNTIF(E20:L20,"A/R")) -> 1 | N20: =IF(C20="","",COUNTIF(E20:L20,"R")+COUNTIF(E20:L20,"A/R")) -> 1 | O20: =IF(C20="","",IF(COUNTA(E20:L20)=0,"Distribua os papéis",IF(M20=0,"Falta o A",IF(M20>1,"Mais de um A",IF(N20=0,"Falta o R",IF(COUNTIF(E20:L20,"C")>3,"Muitos consultados",IF(COUNTA(E20:L20)=COUNTA($E$12:$L$12),"Todos participam: confira","OK"))))))) -> OK
B21: 7 | C21: Tratar a reclamação do cliente | E21: A | F21: R | G21: C | H21: C | M21: =IF(C21="","",COUNTIF(E21:L21,"A")+COUNTIF(E21:L21,"A/R")) -> 1 | N21: =IF(C21="","",COUNTIF(E21:L21,"R")+COUNTIF(E21:L21,"A/R")) -> 1 | O21: =IF(C21="","",IF(COUNTA(E21:L21)=0,"Distribua os papéis",IF(M21=0,"Falta o A",IF(M21>1,"Mais de um A",IF(N21=0,"Falta o R",IF(COUNTIF(E21:L21,"C")>3,"Muitos consultados",IF(COUNTA(E21:L21)=COUNTA($E$12:$L$12),"Todos participam: confira","OK"))))))) -> OK
B22: 8 | C22: Definir a escala de entregadores | E22: A/R | H22: C | I22: I | M22: =IF(C22="","",COUNTIF(E22:L22,"A")+COUNTIF(E22:L22,"A/R")) -> 1 | N22: =IF(C22="","",COUNTIF(E22:L22,"R")+COUNTIF(E22:L22,"A/R")) -> 1 | O22: =IF(C22="","",IF(COUNTA(E22:L22)=0,"Distribua os papéis",IF(M22=0,"Falta o A",IF(M22>1,"Mais de um A",IF(N22=0,"Falta o R",IF(COUNTIF(E22:L22,"C")>3,"Muitos consultados",IF(COUNTA(E22:L22)=COUNTA($E$12:$L$12),"Todos participam: confira","OK"))))))) -> OK
B23: 9 | C23: Acompanhar o indicador de entregas no prazo | E23: A | G23: I | H23: R | I23: I | M23: =IF(C23="","",COUNTIF(E23:L23,"A")+COUNTIF(E23:L23,"A/R")) -> 1 | N23: =IF(C23="","",COUNTIF(E23:L23,"R")+COUNTIF(E23:L23,"A/R")) -> 1 | O23: =IF(C23="","",IF(COUNTA(E23:L23)=0,"Distribua os papéis",IF(M23=0,"Falta o A",IF(M23>1,"Mais de um A",IF(N23=0,"Falta o R",IF(COUNTIF(E23:L23,"C")>3,"Muitos consultados",IF(COUNTA(E23:L23)=COUNTA($E$12:$L$12),"Todos participam: confira","OK"))))))) -> OK
B24: 10 | M24: =IF(C24="","",COUNTIF(E24:L24,"A")+COUNTIF(E24:L24,"A/R")) | N24: =IF(C24="","",COUNTIF(E24:L24,"R")+COUNTIF(E24:L24,"A/R")) | O24: =IF(C24="","",IF(COUNTA(E24:L24)=0,"Distribua os papéis",IF(M24=0,"Falta o A",IF(M24>1,"Mais de um A",IF(N24=0,"Falta o R",IF(COUNTIF(E24:L24,"C")>3,"Muitos consultados",IF(COUNTA(E24:L24)=COUNTA($E$12:$L$12),"Todos participam: confira","OK")))))))
B25: 11 | M25: =IF(C25="","",COUNTIF(E25:L25,"A")+COUNTIF(E25:L25,"A/R")) | N25: =IF(C25="","",COUNTIF(E25:L25,"R")+COUNTIF(E25:L25,"A/R")) | O25: =IF(C25="","",IF(COUNTA(E25:L25)=0,"Distribua os papéis",IF(M25=0,"Falta o A",IF(M25>1,"Mais de um A",IF(N25=0,"Falta o R",IF(COUNTIF(E25:L25,"C")>3,"Muitos consultados",IF(COUNTA(E25:L25)=COUNTA($E$12:$L$12),"Todos participam: confira","OK")))))))
B26: 12 | M26: =IF(C26="","",COUNTIF(E26:L26,"A")+COUNTIF(E26:L26,"A/R")) | N26: =IF(C26="","",COUNTIF(E26:L26,"R")+COUNTIF(E26:L26,"A/R")) | O26: =IF(C26="","",IF(COUNTA(E26:L26)=0,"Distribua os papéis",IF(M26=0,"Falta o A",IF(M26>1,"Mais de um A",IF(N26=0,"Falta o R",IF(COUNTIF(E26:L26,"C")>3,"Muitos consultados",IF(COUNTA(E26:L26)=COUNTA($E$12:$L$12),"Todos participam: confira","OK")))))))
B27: 13 | M27: =IF(C27="","",COUNTIF(E27:L27,"A")+COUNTIF(E27:L27,"A/R")) | N27: =IF(C27="","",COUNTIF(E27:L27,"R")+COUNTIF(E27:L27,"A/R")) | O27: =IF(C27="","",IF(COUNTA(E27:L27)=0,"Distribua os papéis",IF(M27=0,"Falta o A",IF(M27>1,"Mais de um A",IF(N27=0,"Falta o R",IF(COUNTIF(E27:L27,"C")>3,"Muitos consultados",IF(COUNTA(E27:L27)=COUNTA($E$12:$L$12),"Todos participam: confira","OK")))))))
B28: 14 | M28: =IF(C28="","",COUNTIF(E28:L28,"A")+COUNTIF(E28:L28,"A/R")) | N28: =IF(C28="","",COUNTIF(E28:L28,"R")+COUNTIF(E28:L28,"A/R")) | O28: =IF(C28="","",IF(COUNTA(E28:L28)=0,"Distribua os papéis",IF(M28=0,"Falta o A",IF(M28>1,"Mais de um A",IF(N28=0,"Falta o R",IF(COUNTIF(E28:L28,"C")>3,"Muitos consultados",IF(COUNTA(E28:L28)=COUNTA($E$12:$L$12),"Todos participam: confira","OK")))))))
B29: 15 | M29: =IF(C29="","",COUNTIF(E29:L29,"A")+COUNTIF(E29:L29,"A/R")) | N29: =IF(C29="","",COUNTIF(E29:L29,"R")+COUNTIF(E29:L29,"A/R")) | O29: =IF(C29="","",IF(COUNTA(E29:L29)=0,"Distribua os papéis",IF(M29=0,"Falta o A",IF(M29>1,"Mais de um A",IF(N29=0,"Falta o R",IF(COUNTIF(E29:L29,"C")>3,"Muitos consultados",IF(COUNTA(E29:L29)=COUNTA($E$12:$L$12),"Todos participam: confira","OK")))))))
B31: Conferência da coluna: carga por papel
B32: R | C32: Atividades em que executa (R) | E32: =IF(AND(E$12="",COUNTA(E15:E29)=0),"",COUNTIF(E15:E29,"R")+COUNTIF(E15:E29,"A/R")) -> 1 | F32: =IF(AND(F$12="",COUNTA(F15:F29)=0),"",COUNTIF(F15:F29,"R")+COUNTIF(F15:F29,"A/R")) -> 2 | G32: =IF(AND(G$12="",COUNTA(G15:G29)=0),"",COUNTIF(G15:G29,"R")+COUNTIF(G15:G29,"A/R")) -> 1 | H32: =IF(AND(H$12="",COUNTA(H15:H29)=0),"",COUNTIF(H15:H29,"R")+COUNTIF(H15:H29,"A/R")) -> 3 | I32: =IF(AND(I$12="",COUNTA(I15:I29)=0),"",COUNTIF(I15:I29,"R")+COUNTIF(I15:I29,"A/R")) -> 2 | J32: =IF(AND(J$12="",COUNTA(J15:J29)=0),"",COUNTIF(J15:J29,"R")+COUNTIF(J15:J29,"A/R")) | K32: =IF(AND(K$12="",COUNTA(K15:K29)=0),"",COUNTIF(K15:K29,"R")+COUNTIF(K15:K29,"A/R")) | L32: =IF(AND(L$12="",COUNTA(L15:L29)=0),"",COUNTIF(L15:L29,"R")+COUNTIF(L15:L29,"A/R"))
B33: A | C33: Atividades em que responde (A) | E33: =IF(AND(E$12="",COUNTA(E15:E29)=0),"",COUNTIF(E15:E29,"A")+COUNTIF(E15:E29,"A/R")) -> 3 | F33: =IF(AND(F$12="",COUNTA(F15:F29)=0),"",COUNTIF(F15:F29,"A")+COUNTIF(F15:F29,"A/R")) -> 2 | G33: =IF(AND(G$12="",COUNTA(G15:G29)=0),"",COUNTIF(G15:G29,"A")+COUNTIF(G15:G29,"A/R")) -> 1 | H33: =IF(AND(H$12="",COUNTA(H15:H29)=0),"",COUNTIF(H15:H29,"A")+COUNTIF(H15:H29,"A/R")) -> 3 | I33: =IF(AND(I$12="",COUNTA(I15:I29)=0),"",COUNTIF(I15:I29,"A")+COUNTIF(I15:I29,"A/R")) -> 0 | J33: =IF(AND(J$12="",COUNTA(J15:J29)=0),"",COUNTIF(J15:J29,"A")+COUNTIF(J15:J29,"A/R")) | K33: =IF(AND(K$12="",COUNTA(K15:K29)=0),"",COUNTIF(K15:K29,"A")+COUNTIF(K15:K29,"A/R")) | L33: =IF(AND(L$12="",COUNTA(L15:L29)=0),"",COUNTIF(L15:L29,"A")+COUNTIF(L15:L29,"A/R"))
B34: C | C34: Atividades em que é consultado (C) | E34: =IF(AND(E$12="",COUNTA(E15:E29)=0),"",COUNTIF(E15:E29,"C")) -> 0 | F34: =IF(AND(F$12="",COUNTA(F15:F29)=0),"",COUNTIF(F15:F29,"C")) -> 1 | G34: =IF(AND(G$12="",COUNTA(G15:G29)=0),"",COUNTIF(G15:G29,"C")) -> 2 | H34: =IF(AND(H$12="",COUNTA(H15:H29)=0),"",COUNTIF(H15:H29,"C")) -> 2 | I34: =IF(AND(I$12="",COUNTA(I15:I29)=0),"",COUNTIF(I15:I29,"C")) -> 0 | J34: =IF(AND(J$12="",COUNTA(J15:J29)=0),"",COUNTIF(J15:J29,"C")) | K34: =IF(AND(K$12="",COUNTA(K15:K29)=0),"",COUNTIF(K15:K29,"C")) | L34: =IF(AND(L$12="",COUNTA(L15:L29)=0),"",COUNTIF(L15:L29,"C"))
B35: I | C35: Atividades em que é informado (I) | E35: =IF(AND(E$12="",COUNTA(E15:E29)=0),"",COUNTIF(E15:E29,"I")) -> 2 | F35: =IF(AND(F$12="",COUNTA(F15:F29)=0),"",COUNTIF(F15:F29,"I")) -> 1 | G35: =IF(AND(G$12="",COUNTA(G15:G29)=0),"",COUNTIF(G15:G29,"I")) -> 2 | H35: =IF(AND(H$12="",COUNTA(H15:H29)=0),"",COUNTIF(H15:H29,"I")) -> 2 | I35: =IF(AND(I$12="",COUNTA(I15:I29)=0),"",COUNTIF(I15:I29,"I")) -> 3 | J35: =IF(AND(J$12="",COUNTA(J15:J29)=0),"",COUNTIF(J15:J29,"I")) | K35: =IF(AND(K$12="",COUNTA(K15:K29)=0),"",COUNTIF(K15:K29,"I")) | L35: =IF(AND(L$12="",COUNTA(L15:L29)=0),"",COUNTIF(L15:L29,"I"))
B36: Total de participações | E36: =IF(AND(E$12="",COUNTA(E15:E29)=0),"",COUNTA(E15:E29)) -> 5 | F36: =IF(AND(F$12="",COUNTA(F15:F29)=0),"",COUNTA(F15:F29)) -> 5 | G36: =IF(AND(G$12="",COUNTA(G15:G29)=0),"",COUNTA(G15:G29)) -> 5 | H36: =IF(AND(H$12="",COUNTA(H15:H29)=0),"",COUNTA(H15:H29)) -> 8 | I36: =IF(AND(I$12="",COUNTA(I15:I29)=0),"",COUNTA(I15:I29)) -> 5 | J36: =IF(AND(J$12="",COUNTA(J15:J29)=0),"",COUNTA(J15:J29)) | K36: =IF(AND(K$12="",COUNTA(K15:K29)=0),"",COUNTA(K15:K29)) | L36: =IF(AND(L$12="",COUNTA(L15:L29)=0),"",COUNTA(L15:L29))
B37: Aviso da coluna | E37: =IF(E$12="",IF(COUNTA(E15:E29)>0,"Papel sem nome",""),IF(E36=0,"Sem participação",IF(AND($H$40>=5,E33/$H$40>0.6),"Muitos A: possível gargalo",IF(AND($H$40>=5,E32/$H$40>0.6),"Muitos R: possível sobrecarga",IF(E32+E33=0,IF(E34=0,"Só informado","Só consultado ou informado"),"OK"))))) -> OK | F37: =IF(F$12="",IF(COUNTA(F15:F29)>0,"Papel sem nome",""),IF(F36=0,"Sem participação",IF(AND($H$40>=5,F33/$H$40>0.6),"Muitos A: possível gargalo",IF(AND($H$40>=5,F32/$H$40>0.6),"Muitos R: possível sobrecarga",IF(F32+F33=0,IF(F34=0,"Só informado","Só consultado ou informado"),"OK"))))) -> OK | G37: =IF(G$12="",IF(COUNTA(G15:G29)>0,"Papel sem nome",""),IF(G36=0,"Sem participação",IF(AND($H$40>=5,G33/$H$40>0.6),"Muitos A: possível gargalo",IF(AND($H$40>=5,G32/$H$40>0.6),"Muitos R: possível sobrecarga",IF(G32+G33=0,IF(G34=0,"Só informado","Só consultado ou informado"),"OK"))))) -> OK | H37: =IF(H$12="",IF(COUNTA(H15:H29)>0,"Papel sem nome",""),IF(H36=0,"Sem participação",IF(AND($H$40>=5,H33/$H$40>0.6),"Muitos A: possível gargalo",IF(AND($H$40>=5,H32/$H$40>0.6),"Muitos R: possível sobrecarga",IF(H32+H33=0,IF(H34=0,"Só informado","Só consultado ou informado"),"OK"))))) -> OK | I37: =IF(I$12="",IF(COUNTA(I15:I29)>0,"Papel sem nome",""),IF(I36=0,"Sem participação",IF(AND($H$40>=5,I33/$H$40>0.6),"Muitos A: possível gargalo",IF(AND($H$40>=5,I32/$H$40>0.6),"Muitos R: possível sobrecarga",IF(I32+I33=0,IF(I34=0,"Só informado","Só consultado ou informado"),"OK"))))) -> OK | J37: =IF(J$12="",IF(COUNTA(J15:J29)>0,"Papel sem nome",""),IF(J36=0,"Sem participação",IF(AND($H$40>=5,J33/$H$40>0.6),"Muitos A: possível gargalo",IF(AND($H$40>=5,J32/$H$40>0.6),"Muitos R: possível sobrecarga",IF(J32+J33=0,IF(J34=0,"Só informado","Só consultado ou informado"),"OK"))))) | K37: =IF(K$12="",IF(COUNTA(K15:K29)>0,"Papel sem nome",""),IF(K36=0,"Sem participação",IF(AND($H$40>=5,K33/$H$40>0.6),"Muitos A: possível gargalo",IF(AND($H$40>=5,K32/$H$40>0.6),"Muitos R: possível sobrecarga",IF(K32+K33=0,IF(K34=0,"Só informado","Só consultado ou informado"),"OK"))))) | L37: =IF(L$12="",IF(COUNTA(L15:L29)>0,"Papel sem nome",""),IF(L36=0,"Sem participação",IF(AND($H$40>=5,L33/$H$40>0.6),"Muitos A: possível gargalo",IF(AND($H$40>=5,L32/$H$40>0.6),"Muitos R: possível sobrecarga",IF(L32+L33=0,IF(L34=0,"Só informado","Só consultado ou informado"),"OK")))))
B39: Resumo automático
B40: Atividades listadas | H40: =COUNTA(C15:C29) -> 9
B41: Papéis definidos | H41: =COUNTA(E12:L12) -> 5
B42: Atividades sem aviso | H42: =COUNTIF(O15:O29,"OK") -> 9
B43: Atividades sem A ou com mais de um A | H43: =COUNTIF(O15:O29,"Falta o A")+COUNTIF(O15:O29,"Mais de um A") -> 0
B44: Atividades sem R | H44: =COUNTIF(O15:O29,"Falta o R") -> 0
...

Sheet Exemplo 2 - Compras
B1: RACI — Matriz de responsabilidades
B2: Exemplo preenchido, para consulta. Use a aba RACI para a sua matriz.
B4: Processo ou projeto | D4: Adquirir materiais e serviços | H4: Dono do processo | J4: Gerente de Suprimentos
B5: Área / unidade | D5: Suprimentos | H5: Data | J5: 46294
B6: Elaborado por | D6: Equipe de compras | H6: Versão | J6: 1.0
B7: Escopo | D7: Da requisição de compra até a liberação da nota fiscal para pagamento, mais a avaliação do fornecedor.
B8: Origem das atividades | D8: Macroetapas do SIPOC do processo | H8: Participantes | J8: Gerente, compradores, dois requisitantes, Controladoria e Recebimento
B9: Fora do escopo | D9: Homologação de fornecedores, pagamento e gestão de estoque.
B11: Atividades | E11: Papéis | M11: Conferência da linha
B12: # | C12: Atividade | E12: Requisitante | F12: Comprador | G12: Gerente de Suprimentos | H12: Controladoria | I12: Jurídico | J12: Recebimento | M12: A | N12: R | O12: Aviso da linha
C13: Verbo no infinitivo + objeto | E13: Cargo ou função na linha de cima. Nas células: R, A, A/R, C ou I | M13: Deve ser 1 | N13: 1 ou mais | O13: Calculado
B14: Leia na horizontal para conferir cada atividade: um A e pelo menos um R. Leia na vertical para conferir a carga de cada papel.
B15: 1 | C15: Emitir a requisição de compra | E15: A/R | F15: I | H15: C | M15: =IF(C15="","",COUNTIF(E15:L15,"A")+COUNTIF(E15:L15,"A/R")) -> 1 | N15: =IF(C15="","",COUNTIF(E15:L15,"R")+COUNTIF(E15:L15,"A/R")) -> 1 | O15: =IF(C15="","",IF(COUNTA(E15:L15)=0,"Distribua os papéis",IF(M15=0,"Falta o A",IF(M15>1,"Mais de um A",IF(N15=0,"Falta o R",IF(COUNTIF(E15:L15,"C")>3,"Muitos consultados",IF(COUNTA(E15:L15)=COUNTA($E$12:$L$12),"Todos participam: confira","OK"))))))) -> OK
B16: 2 | C16: Analisar a requisição | E16: C | F16: R | G16: A | M16: =IF(C16="","",COUNTIF(E16:L16,"A")+COUNTIF(E16:L16,"A/R")) -> 1 | N16: =IF(C16="","",COUNTIF(E16:L16,"R")+COUNTIF(E16:L16,"A/R")) -> 1 | O16: =IF(C16="","",IF(COUNTA(E16:L16)=0,"Distribua os papéis",IF(M16=0,"Falta o A",IF(M16>1,"Mais de um A",IF(N16=0,"Falta o R",IF(COUNTIF(E16:L16,"C")>3,"Muitos consultados",IF(COUNTA(E16:L16)=COUNTA($E$12:$L$12),"Todos participam: confira","OK"))))))) -> OK
B17: 3 | C17: Cotar com fornecedores | E17: C | F17: A/R | M17: =IF(C17="","",COUNTIF(E17:L17,"A")+COUNTIF(E17:L17,"A/R")) -> 1 | N17: =IF(C17="","",COUNTIF(E17:L17,"R")+COUNTIF(E17:L17,"A/R")) -> 1 | O17: =IF(C17="","",IF(COUNTA(E17:L17)=0,"Distribua os papéis",IF(M17=0,"Falta o A",IF(M17>1,"Mais de um A",IF(N17=0,"Falta o R",IF(COUNTIF(E17:L17,"C")>3,"Muitos consultados",IF(COUNTA(E17:L17)=COUNTA($E$12:$L$12),"Todos participam: confira","OK"))))))) -> OK
B18: 4 | C18: Selecionar a proposta | E18: C | F18: R | G18: A | H18: I | M18: =IF(C18="","",COUNTIF(E18:L18,"A")+COUNTIF(E18:L18,"A/R")) -> 1 | N18: =IF(C18="","",COUNTIF(E18:L18,"R")+COUNTIF(E18:L18,"A/R")) -> 1 | O18: =IF(C18="","",IF(COUNTA(E18:L18)=0,"Distribua os papéis",IF(M18=0,"Falta o A",IF(M18>1,"Mais de um A",IF(N18=0,"Falta o R",IF(COUNTIF(E18:L18,"C")>3,"Muitos consultados",IF(COUNTA(E18:L18)=COUNTA($E$12:$L$12),"Todos participam: confira","OK"))))))) -> OK
B19: 5 | C19: Aprovar a compra, conforme a alçada | E19: I | F19: I | G19: A/R | H19: C | M19: =IF(C19="","",COUNTIF(E19:L19,"A")+COUNTIF(E19:L19,"A/R")) -> 1 | N19: =IF(C19="","",COUNTIF(E19:L19,"R")+COUNTIF(E19:L19,"A/R")) -> 1 | O19: =IF(C19="","",IF(COUNTA(E19:L19)=0,"Distribua os papéis",IF(M19=0,"Falta o A",IF(M19>1,"Mais de um A",IF(N19=0,"Falta o R",IF(COUNTIF(E19:L19,"C")>3,"Muitos consultados",IF(COUNTA(E19:L19)=COUNTA($E$12:$L$12),"Todos participam: confira","OK"))))))) -> OK
B20: 6 | C20: Emitir o pedido de compra ou o contrato | E20: I | F20: R | G20: A | I20: C | J20: I | M20: =IF(C20="","",COUNTIF(E20:L20,"A")+COUNTIF(E20:L20,"A/R")) -> 1 | N20: =IF(C20="","",COUNTIF(E20:L20,"R")+COUNTIF(E20:L20,"A/R")) -> 1 | O20: =IF(C20="","",IF(COUNTA(E20:L20)=0,"Distribua os papéis",IF(M20=0,"Falta o A",IF(M20>1,"Mais de um A",IF(N20=0,"Falta o R",IF(COUNTIF(E20:L20,"C")>3,"Muitos consultados",IF(COUNTA(E20:L20)=COUNTA($E$12:$L$12),"Todos participam: confira","OK"))))))) -> OK
B21: 7 | C21: Receber e conferir o item | E21: C | F21: I | J21: A/R | M21: =IF(C21="","",COUNTIF(E21:L21,"A")+COUNTIF(E21:L21,"A/R")) -> 1 | N21: =IF(C21="","",COUNTIF(E21:L21,"R")+COUNTIF(E21:L21,"A/R")) -> 1 | O21: =IF(C21="","",IF(COUNTA(E21:L21)=0,"Distribua os papéis",IF(M21=0,"Falta o A",IF(M21>1,"Mais de um A",IF(N21=0,"Falta o R",IF(COUNTIF(E21:L21,"C")>3,"Muitos consultados",IF(COUNTA(E21:L21)=COUNTA($E$12:$L$12),"Todos participam: confira","OK"))))))) -> OK
B22: 8 | C22: Liberar a nota fiscal para pagamento | F22: R | G22: A | H22: I | J22: C | M22: =IF(C22="","",COUNTIF(E22:L22,"A")+COUNTIF(E22:L22,"A/R")) -> 1 | N22: =IF(C22="","",COUNTIF(E22:L22,"R")+COUNTIF(E22:L22,"A/R")) -> 1 | O22: =IF(C22="","",IF(COUNTA(E22:L22)=0,"Distribua os papéis",IF(M22=0,"Falta o A",IF(M22>1,"Mais de um A",IF(N22=0,"Falta o R",IF(COUNTIF(E22:L22,"C")>3,"Muitos consultados",IF(COUNTA(E22:L22)=COUNTA($E$12:$L$12),"Todos participam: confira","OK"))))))) -> OK
B23: 9 | C23: Avaliar o desempenho do fornecedor | E23: C | F23: R | G23: A | J23: C | M23: =IF(C23="","",COUNTIF(E23:L23,"A")+COUNTIF(E23:L23,"A/R")) -> 1 | N23: =IF(C23="","",COUNTIF(E23:L23,"R")+COUNTIF(E23:L23,"A/R")) -> 1 | O23: =IF(C23="","",IF(COUNTA(E23:L23)=0,"Distribua os papéis",IF(M23=0,"Falta o A",IF(M23>1,"Mais de um A",IF(N23=0,"Falta o R",IF(COUNTIF(E23:L23,"C")>3,"Muitos consultados",IF(COUNTA(E23:L23)=COUNTA($E$12:$L$12),"Todos participam: confira","OK"))))))) -> OK
B24: 10 | M24: =IF(C24="","",COUNTIF(E24:L24,"A")+COUNTIF(E24:L24,"A/R")) | N24: =IF(C24="","",COUNTIF(E24:L24,"R")+COUNTIF(E24:L24,"A/R")) | O24: =IF(C24="","",IF(COUNTA(E24:L24)=0,"Distribua os papéis",IF(M24=0,"Falta o A",IF(M24>1,"Mais de um A",IF(N24=0,"Falta o R",IF(COUNTIF(E24:L24,"C")>3,"Muitos consultados",IF(COUNTA(E24:L24)=COUNTA($E$12:$L$12),"Todos participam: confira","OK")))))))
B25: 11 | M25: =IF(C25="","",COUNTIF(E25:L25,"A")+COUNTIF(E25:L25,"A/R")) | N25: =IF(C25="","",COUNTIF(E25:L25,"R")+COUNTIF(E25:L25,"A/R")) | O25: =IF(C25="","",IF(COUNTA(E25:L25)=0,"Distribua os papéis",IF(M25=0,"Falta o A",IF(M25>1,"Mais de um A",IF(N25=0,"Falta o R",IF(COUNTIF(E25:L25,"C")>3,"Muitos consultados",IF(COUNTA(E25:L25)=COUNTA($E$12:$L$12),"Todos participam: confira","OK")))))))
B26: 12 | M26: =IF(C26="","",COUNTIF(E26:L26,"A")+COUNTIF(E26:L26,"A/R")) | N26: =IF(C26="","",COUNTIF(E26:L26,"R")+COUNTIF(E26:L26,"A/R")) | O26: =IF(C26="","",IF(COUNTA(E26:L26)=0,"Distribua os papéis",IF(M26=0,"Falta o A",IF(M26>1,"Mais de um A",IF(N26=0,"Falta o R",IF(COUNTIF(E26:L26,"C")>3,"Muitos consultados",IF(COUNTA(E26:L26)=COUNTA($E$12:$L$12),"Todos participam: confira","OK")))))))
B27: 13 | M27: =IF(C27="","",COUNTIF(E27:L27,"A")+COUNTIF(E27:L27,"A/R")) | N27: =IF(C27="","",COUNTIF(E27:L27,"R")+COUNTIF(E27:L27,"A/R")) | O27: =IF(C27="","",IF(COUNTA(E27:L27)=0,"Distribua os papéis",IF(M27=0,"Falta o A",IF(M27>1,"Mais de um A",IF(N27=0,"Falta o R",IF(COUNTIF(E27:L27,"C")>3,"Muitos consultados",IF(COUNTA(E27:L27)=COUNTA($E$12:$L$12),"Todos participam: confira","OK")))))))
B28: 14 | M28: =IF(C28="","",COUNTIF(E28:L28,"A")+COUNTIF(E28:L28,"A/R")) | N28: =IF(C28="","",COUNTIF(E28:L28,"R")+COUNTIF(E28:L28,"A/R")) | O28: =IF(C28="","",IF(COUNTA(E28:L28)=0,"Distribua os papéis",IF(M28=0,"Falta o A",IF(M28>1,"Mais de um A",IF(N28=0,"Falta o R",IF(COUNTIF(E28:L28,"C")>3,"Muitos consultados",IF(COUNTA(E28:L28)=COUNTA($E$12:$L$12),"Todos participam: confira","OK")))))))
B29: 15 | M29: =IF(C29="","",COUNTIF(E29:L29,"A")+COUNTIF(E29:L29,"A/R")) | N29: =IF(C29="","",COUNTIF(E29:L29,"R")+COUNTIF(E29:L29,"A/R")) | O29: =IF(C29="","",IF(COUNTA(E29:L29)=0,"Distribua os papéis",IF(M29=0,"Falta o A",IF(M29>1,"Mais de um A",IF(N29=0,"Falta o R",IF(COUNTIF(E29:L29,"C")>3,"Muitos consultados",IF(COUNTA(E29:L29)=COUNTA($E$12:$L$12),"Todos participam: confira","OK")))))))
B31: Conferência da coluna: carga por papel
B32: R | C32: Atividades em que executa (R) | E32: =IF(AND(E$12="",COUNTA(E15:E29)=0),"",COUNTIF(E15:E29,"R")+COUNTIF(E15:E29,"A/R")) -> 1 | F32: =IF(AND(F$12="",COUNTA(F15:F29)=0),"",COUNTIF(F15:F29,"R")+COUNTIF(F15:F29,"A/R")) -> 6 | G32: =IF(AND(G$12="",COUNTA(G15:G29)=0),"",COUNTIF(G15:G29,"R")+COUNTIF(G15:G29,"A/R")) -> 1 | H32: =IF(AND(H$12="",COUNTA(H15:H29)=0),"",COUNTIF(H15:H29,"R")+COUNTIF(H15:H29,"A/R")) -> 0 | I32: =IF(AND(I$12="",COUNTA(I15:I29)=0),"",COUNTIF(I15:I29,"R")+COUNTIF(I15:I29,"A/R")) -> 0 | J32: =IF(AND(J$12="",COUNTA(J15:J29)=0),"",COUNTIF(J15:J29,"R")+COUNTIF(J15:J29,"A/R")) -> 1 | K32: =IF(AND(K$12="",COUNTA(K15:K29)=0),"",COUNTIF(K15:K29,"R")+COUNTIF(K15:K29,"A/R")) | L32: =IF(AND(L$12="",COUNTA(L15:L29)=0),"",COUNTIF(L15:L29,"R")+COUNTIF(L15:L29,"A/R"))
B33: A | C33: Atividades em que responde (A) | E33: =IF(AND(E$12="",COUNTA(E15:E29)=0),"",COUNTIF(E15:E29,"A")+COUNTIF(E15:E29,"A/R")) -> 1 | F33: =IF(AND(F$12="",COUNTA(F15:F29)=0),"",COUNTIF(F15:F29,"A")+COUNTIF(F15:F29,"A/R")) -> 1 | G33: =IF(AND(G$12="",COUNTA(G15:G29)=0),"",COUNTIF(G15:G29,"A")+COUNTIF(G15:G29,"A/R")) -> 6 | H33: =IF(AND(H$12="",COUNTA(H15:H29)=0),"",COUNTIF(H15:H29,"A")+COUNTIF(H15:H29,"A/R")) -> 0 | I33: =IF(AND(I$12="",COUNTA(I15:I29)=0),"",COUNTIF(I15:I29,"A")+COUNTIF(I15:I29,"A/R")) -> 0 | J33: =IF(AND(J$12="",COUNTA(J15:J29)=0),"",COUNTIF(J15:J29,"A")+COUNTIF(J15:J29,"A/R")) -> 1 | K33: =IF(AND(K$12="",COUNTA(K15:K29)=0),"",COUNTIF(K15:K29,"A")+COUNTIF(K15:K29,"A/R")) | L33: =IF(AND(L$12="",COUNTA(L15:L29)=0),"",COUNTIF(L15:L29,"A")+COUNTIF(L15:L29,"A/R"))
B34: C | C34: Atividades em que é consultado (C) | E34: =IF(AND(E$12="",COUNTA(E15:E29)=0),"",COUNTIF(E15:E29,"C")) -> 5 | F34: =IF(AND(F$12="",COUNTA(F15:F29)=0),"",COUNTIF(F15:F29,"C")) -> 0 | G34: =IF(AND(G$12="",COUNTA(G15:G29)=0),"",COUNTIF(G15:G29,"C")) -> 0 | H34: =IF(AND(H$12="",COUNTA(H15:H29)=0),"",COUNTIF(H15:H29,"C")) -> 2 | I34: =IF(AND(I$12="",COUNTA(I15:I29)=0),"",COUNTIF(I15:I29,"C")) -> 1 | J34: =IF(AND(J$12="",COUNTA(J15:J29)=0),"",COUNTIF(J15:J29,"C")) -> 2 | K34: =IF(AND(K$12="",COUNTA(K15:K29)=0),"",COUNTIF(K15:K29,"C")) | L34: =IF(AND(L$12="",COUNTA(L15:L29)=0),"",COUNTIF(L15:L29,"C"))
B35: I | C35: Atividades em que é informado (I) | E35: =IF(AND(E$12="",COUNTA(E15:E29)=0),"",COUNTIF(E15:E29,"I")) -> 2 | F35: =IF(AND(F$12="",COUNTA(F15:F29)=0),"",COUNTIF(F15:F29,"I")) -> 3 | G35: =IF(AND(G$12="",COUNTA(G15:G29)=0),"",COUNTIF(G15:G29,"I")) -> 0 | H35: =IF(AND(H$12="",COUNTA(H15:H29)=0),"",COUNTIF(H15:H29,"I")) -> 2 | I35: =IF(AND(I$12="",COUNTA(I15:I29)=0),"",COUNTIF(I15:I29,"I")) -> 0 | J35: =IF(AND(J$12="",COUNTA(J15:J29)=0),"",COUNTIF(J15:J29,"I")) -> 1 | K35: =IF(AND(K$12="",COUNTA(K15:K29)=0),"",COUNTIF(K15:K29,"I")) | L35: =IF(AND(L$12="",COUNTA(L15:L29)=0),"",COUNTIF(L15:L29,"I"))
B36: Total de participações | E36: =IF(AND(E$12="",COUNTA(E15:E29)=0),"",COUNTA(E15:E29)) -> 8 | F36: =IF(AND(F$12="",COUNTA(F15:F29)=0),"",COUNTA(F15:F29)) -> 9 | G36: =IF(AND(G$12="",COUNTA(G15:G29)=0),"",COUNTA(G15:G29)) -> 6 | H36: =IF(AND(H$12="",COUNTA(H15:H29)=0),"",COUNTA(H15:H29)) -> 4 | I36: =IF(AND(I$12="",COUNTA(I15:I29)=0),"",COUNTA(I15:I29)) -> 1 | J36: =IF(AND(J$12="",COUNTA(J15:J29)=0),"",COUNTA(J15:J29)) -> 4 | K36: =IF(AND(K$12="",COUNTA(K15:K29)=0),"",COUNTA(K15:K29)) | L36: =IF(AND(L$12="",COUNTA(L15:L29)=0),"",COUNTA(L15:L29))
B37: Aviso da coluna | E37: =IF(E$12="",IF(COUNTA(E15:E29)>0,"Papel sem nome",""),IF(E36=0,"Sem participação",IF(AND($H$40>=5,E33/$H$40>0.6),"Muitos A: possível gargalo",IF(AND($H$40>=5,E32/$H$40>0.6),"Muitos R: possível sobrecarga",IF(E32+E33=0,IF(E34=0,"Só informado","Só consultado ou informado"),"OK"))))) -> OK | F37: =IF(F$12="",IF(COUNTA(F15:F29)>0,"Papel sem nome",""),IF(F36=0,"Sem participação",IF(AND($H$40>=5,F33/$H$40>0.6),"Muitos A: possível gargalo",IF(AND($H$40>=5,F32/$H$40>0.6),"Muitos R: possível sobrecarga",IF(F32+F33=0,IF(F34=0,"Só informado","Só consultado ou informado"),"OK"))))) -> Muitos R: possível sobrecarga | G37: =IF(G$12="",IF(COUNTA(G15:G29)>0,"Papel sem nome",""),IF(G36=0,"Sem participação",IF(AND($H$40>=5,G33/$H$40>0.6),"Muitos A: possível gargalo",IF(AND($H$40>=5,G32/$H$40>0.6),"Muitos R: possível sobrecarga",IF(G32+G33=0,IF(G34=0,"Só informado","Só consultado ou informado"),"OK"))))) -> Muitos A: possível gargalo | H37: =IF(H$12="",IF(COUNTA(H15:H29)>0,"Papel sem nome",""),IF(H36=0,"Sem participação",IF(AND($H$40>=5,H33/$H$40>0.6),"Muitos A: possível gargalo",IF(AND($H$40>=5,H32/$H$40>0.6),"Muitos R: possível sobrecarga",IF(H32+H33=0,IF(H34=0,"Só informado","Só consultado ou informado"),"OK"))))) -> Só consultado ou informado | I37: =IF(I$12="",IF(COUNTA(I15:I29)>0,"Papel sem nome",""),IF(I36=0,"Sem participação",IF(AND($H$40>=5,I33/$H$40>0.6),"Muitos A: possível gargalo",IF(AND($H$40>=5,I32/$H$40>0.6),"Muitos R: possível sobrecarga",IF(I32+I33=0,IF(I34=0,"Só informado","Só consultado ou informado"),"OK"))))) -> Só consultado ou informado | J37: =IF(J$12="",IF(COUNTA(J15:J29)>0,"Papel sem nome",""),IF(J36=0,"Sem participação",IF(AND($H$40>=5,J33/$H$40>0.6),"Muitos A: possível gargalo",IF(AND($H$40>=5,J32/$H$40>0.6),"Muitos R: possível sobrecarga",IF(J32+J33=0,IF(J34=0,"Só informado","Só consultado ou informado"),"OK"))))) -> OK | K37: =IF(K$12="",IF(COUNTA(K15:K29)>0,"Papel sem nome",""),IF(K36=0,"Sem participação",IF(AND($H$40>=5,K33/$H$40>0.6),"Muitos A: possível gargalo",IF(AND($H$40>=5,K32/$H$40>0.6),"Muitos R: possível sobrecarga",IF(K32+K33=0,IF(K34=0,"Só informado","Só consultado ou informado"),"OK"))))) | L37: =IF(L$12="",IF(COUNTA(L15:L29)>0,"Papel sem nome",""),IF(L36=0,"Sem participação",IF(AND($H$40>=5,L33/$H$40>0.6),"Muitos A: possível gargalo",IF(AND($H$40>=5,L32/$H$40>0.6),"Muitos R: possível sobrecarga",IF(L32+L33=0,IF(L34=0,"Só informado","Só consultado ou informado"),"OK")))))
B39: Resumo automático
B40: Atividades listadas | H40: =COUNTA(C15:C29) -> 9
B41: Papéis definidos | H41: =COUNTA(E12:L12) -> 6
B42: Atividades sem aviso | H42: =COUNTIF(O15:O29,"OK") -> 9
B43: Atividades sem A ou com mais de um A | H43: =COUNTIF(O15:O29,"Falta o A")+COUNTIF(O15:O29,"Mais de um A") -> 0
B44: Atividades sem R | H44: =COUNTIF(O15:O29,"Falta o R") -> 0
...
