Workbook

Sheet Instruções
B1: Liberação e produto não conforme — Como usar esta planilha
B2: Modelo para registrar a liberação, controlar o produto não conforme, decidir a disposição e ler o custo.
B4: Legenda: onde preencher
B5: Amarelo-claro | C5: Células de entrada. É aqui que você digita.
B6: Cinza | C6: Células calculadas ou fixas (rótulos, leituras, situações, avisos). Não altere.
B7: Cinza em itálico | C7: Linha de exemplo (marcada com “Ex.”). Mostra o formato esperado e não entra nas contagens.
B8: Listas suspensas | C8: Decisão, onde foi visto, disposição, reverificação, aceite do cliente e checklist aceitam apenas as opções da lista.
B9: Comentários | C9: Células com triângulo vermelho no canto trazem uma dica de preenchimento. Passe o mouse sobre elas.
B11: As regras de cálculo
B12: Conforme | C12: Todas as verificações previstas foram feitas, e nenhum resultado ficou fora do critério.
B13: Com desvio | C13: Todas foram feitas, e algum resultado ficou fora do critério. Pede o número do registro de não conforme.
B14: Verificação pendente | C14: Foram feitas menos verificações do que as previstas. Só pode ser liberado com autorização: escolha a decisão “Liberado com autorização” e informe quem autorizou.
B15: Situação do registro | C15: Aberto: sem disposição. Em tratamento: com disposição, sem data de encerramento. Encerrado: com a data de encerramento.
B16: Repetições | C16: Quantos registros têm o mesmo texto na coluna Defeito. Use sempre o mesmo nome para o mesmo defeito.
B17: Defeito repetido | C17: O mesmo defeito aparece em 3 registros ou mais, e nenhum deles traz uma ação corretiva.
B18: Custo por ponto de detecção | C18: A soma do custo dos registros achados no recebimento, no processo, na inspeção final e depois da entrega, dividida pelo número de registros.
B20: Ordem recomendada de preenchimento
B21: Passo 1 | C21: Aba Autoridades: escreva quem libera, quem autoriza a liberação pendente e quem decide cada disposição, com os limites.
B22: Passo 2 | C22: Aba Liberação: registre cada lote ou pedido, com as verificações previstas e feitas, os resultados fora do critério, a decisão e quem liberou.
B23: Passo 3 | C23: Aba Produto não conforme: registre cada caso, com o defeito, onde foi visto, a segregação, a disposição e quem decidiu.
B24: Passo 4 | C24: Aba Produto não conforme: complete o aceite ou a comunicação ao cliente, a reverificação, o encerramento, o custo e a ação corretiva, quando houver.
B25: Passo 5 | C25: Aba Painel: leia os registros abertos, as liberações a rever, os defeitos repetidos e o custo por ponto de detecção.
B26: Passo 6 | C26: Aba Checklist: valide a rotina.
B28: Abas da planilha
B29: Autoridades | C29: Quem decide cada coisa: liberar, autorizar a liberação pendente e as seis disposições. Calcula a conferência de cada linha.
B30: Liberação | C30: Até 60 lotes ou pedidos. Calcula a leitura do lote e a conferência da decisão.
B31: Produto não conforme | C31: Até 60 registros. Calcula a situação, as repetições do defeito e a conferência.
B32: Painel | C32: Os indicadores, o custo por ponto de detecção e por disposição, o gráfico e o aviso.
B33: Checklist | C33: Doze verificações da rotina, com percentual de conclusão.
B34: Exemplo 1 - Pizzaria | C34: As noites de 15 a 21/03/2027, com sete liberações e oito registros.
B35: Exemplo 2 - Indústria | C35: Os lotes 136 a 143 da extrusora 3, com oito liberações e nove registros.
B37: Regras e premissas do modelo
B38: Verificações | C38: Conte as verificações planejadas para o lote, no plano de controle e na inspeção final, e quantas foram feitas antes da decisão.
B39: Lote com parte retida | C39: Quando só uma parte sai do critério, libere a parte boa e informe o número do registro de não conforme da parte separada.
B40: Custo | C40: Some o que o caso custou: material perdido, retrabalho, frete, desconto, reposição. Use zero quando o custo ficou com o fornecedor.
B41: Exemplos | C41: Os dados das abas de exemplo são ilustrativos, criados para este material.

Sheet Autoridades
B1: Quem decide
B2: Escreva a função, e não o nome da pessoa. Os limites dizem até onde cada função pode decidir sozinha.
B4: Organização e produto
B6: # | C6: Decisão | D6: O que é | E6: Quem decide | F6: Limite ou condição | G6: O cliente concorda? | H6: Onde se registra | I6: Conferência
B7: 1 | C7: Liberar o produto | D7: A função que confere as verificações e libera. | I7: =IF(E7="","Falta quem decide",IF(FALSE(),"",IF(H7="","Falta onde se registra","OK"))) -> Falta quem decide
B8: 2 | C8: Autorizar a liberação com verificação pendente | D8: Quem pode correr o risco, e quando o cliente precisa saber. | I8: =IF(E8="","Falta quem decide",IF(FALSE(),"",IF(H8="","Falta onde se registra","OK"))) -> Falta quem decide
B9: 3 | C9: Retrabalhar | D9: Corrigir o produto para que volte a atender ao requisito. | I9: =IF(E9="","Falta quem decide",IF(FALSE(),"",IF(H9="","Falta onde se registra","OK"))) -> Falta quem decide
B10: 4 | C10: Reclassificar | D10: Destinar o produto a outro uso, em que ele atende ao requisito. | I10: =IF(E10="","Falta quem decide",IF(FALSE(),"",IF(H10="","Falta onde se registra","OK"))) -> Falta quem decide
B11: 5 | C11: Aceitar sob concessão | D11: Entregar o produto como está, com a autorização de quem pode aceitar. | I11: =IF(E11="","Falta quem decide",IF(AND(C11="Aceitar sob concessão",G11<>"Sim"),"A concessão pede o aceite do cliente",IF(H11="","Falta onde se registra","OK"))) -> Falta quem decide
B12: 6 | C12: Refugar | D12: Descartar o produto, ou destruí-lo para reaproveitar o material. | I12: =IF(E12="","Falta quem decide",IF(FALSE(),"",IF(H12="","Falta onde se registra","OK"))) -> Falta quem decide
B13: 7 | C13: Devolver ao fornecedor | D13: Devolver o item recebido a quem o forneceu. | I13: =IF(E13="","Falta quem decide",IF(FALSE(),"",IF(H13="","Falta onde se registra","OK"))) -> Falta quem decide
B14: 8 | C14: Recolher ou substituir | D14: Buscar o produto que já está com o cliente, trocar ou reparar. | I14: =IF(E14="","Falta quem decide",IF(FALSE(),"",IF(H14="","Falta onde se registra","OK"))) -> Falta quem decide
B16: Resumo automático
B17: Decisões com responsável | E17: =COUNTA(E7:E14)&" de 8" -> 0 de 8
B18: Aviso | E18: =IF(D4="","Escreva a organização e o produto",IF(COUNTIF(I7:I14,"OK")<ROWS(I7:I14),"Há decisão a completar: veja a coluna Conferência","OK")) -> Escreva a organização e o produto

Sheet Liberação
B1: Registro de liberação
B2: Uma linha por lote, pedido ou fechamento. A decisão se apoia nas verificações previstas e feitas.
B4: # | C4: Data | D4: Lote ou pedido | E4: Produto e quantidade | F4: Verificações previstas | G4: Verificações feitas | H4: Resultados fora | I4: Leitura | J4: Decisão | K4: Quem liberou | L4: Quem autorizou | M4: Nº do registro de não conforme | N4: Observação | O4: Conferência
C5: Data | D5: A identificação | E5: O que e quanto | F5: Número | G5: Número | H5: Número | I5: Calculada | J5: Lista | K5: Uma função | L5: Só na liberação pendente | M5: Quando houver desvio | O5: Calculada
B6: Ex. | C6: 46527 | D6: Lote 139 | E6: 4 bobinas, 1.190 kg | F6: 12 | G6: 11 | H6: 0 | I6: Verificação pendente | J6: Liberado com autorização | K6: Analista da Qualidade | L6: Gerente industrial, com o aceite do cliente | N6: Ensaio de solda pendente. | O6: OK
B7: 1 | I7: =IF(D7="","",IF(OR(F7="",G7=""),"Falta o número de verificações",IF(G7>F7,"Feitas acima das previstas",IF(G7<F7,"Verificação pendente",IF(N(H7)>0,"Com desvio","Conforme"))))) | O7: =IF(D7="","",IF(J7="","Falta a decisão",IF(OR(LEFT(I7,5)="Falta",LEFT(I7,5)="Feita"),I7,IF(AND(G7<F7,J7="Liberado"),"Liberado com verificação pendente",IF(AND(J7="Liberado com autorização",L7=""),"Falta quem autorizou",IF(AND(N(H7)>0,M7=""),"Desvio sem registro de não conforme",IF(AND(J7="Retido",M7=""),"Retido sem registro de não conforme",IF(AND(J7<>"Retido",K7=""),"Falta quem liberou","OK"))))))))
B8: 2 | I8: =IF(D8="","",IF(OR(F8="",G8=""),"Falta o número de verificações",IF(G8>F8,"Feitas acima das previstas",IF(G8<F8,"Verificação pendente",IF(N(H8)>0,"Com desvio","Conforme"))))) | O8: =IF(D8="","",IF(J8="","Falta a decisão",IF(OR(LEFT(I8,5)="Falta",LEFT(I8,5)="Feita"),I8,IF(AND(G8<F8,J8="Liberado"),"Liberado com verificação pendente",IF(AND(J8="Liberado com autorização",L8=""),"Falta quem autorizou",IF(AND(N(H8)>0,M8=""),"Desvio sem registro de não conforme",IF(AND(J8="Retido",M8=""),"Retido sem registro de não conforme",IF(AND(J8<>"Retido",K8=""),"Falta quem liberou","OK"))))))))
B9: 3 | I9: =IF(D9="","",IF(OR(F9="",G9=""),"Falta o número de verificações",IF(G9>F9,"Feitas acima das previstas",IF(G9<F9,"Verificação pendente",IF(N(H9)>0,"Com desvio","Conforme"))))) | O9: =IF(D9="","",IF(J9="","Falta a decisão",IF(OR(LEFT(I9,5)="Falta",LEFT(I9,5)="Feita"),I9,IF(AND(G9<F9,J9="Liberado"),"Liberado com verificação pendente",IF(AND(J9="Liberado com autorização",L9=""),"Falta quem autorizou",IF(AND(N(H9)>0,M9=""),"Desvio sem registro de não conforme",IF(AND(J9="Retido",M9=""),"Retido sem registro de não conforme",IF(AND(J9<>"Retido",K9=""),"Falta quem liberou","OK"))))))))
B10: 4 | I10: =IF(D10="","",IF(OR(F10="",G10=""),"Falta o número de verificações",IF(G10>F10,"Feitas acima das previstas",IF(G10<F10,"Verificação pendente",IF(N(H10)>0,"Com desvio","Conforme"))))) | O10: =IF(D10="","",IF(J10="","Falta a decisão",IF(OR(LEFT(I10,5)="Falta",LEFT(I10,5)="Feita"),I10,IF(AND(G10<F10,J10="Liberado"),"Liberado com verificação pendente",IF(AND(J10="Liberado com autorização",L10=""),"Falta quem autorizou",IF(AND(N(H10)>0,M10=""),"Desvio sem registro de não conforme",IF(AND(J10="Retido",M10=""),"Retido sem registro de não conforme",IF(AND(J10<>"Retido",K10=""),"Falta quem liberou","OK"))))))))
B11: 5 | I11: =IF(D11="","",IF(OR(F11="",G11=""),"Falta o número de verificações",IF(G11>F11,"Feitas acima das previstas",IF(G11<F11,"Verificação pendente",IF(N(H11)>0,"Com desvio","Conforme"))))) | O11: =IF(D11="","",IF(J11="","Falta a decisão",IF(OR(LEFT(I11,5)="Falta",LEFT(I11,5)="Feita"),I11,IF(AND(G11<F11,J11="Liberado"),"Liberado com verificação pendente",IF(AND(J11="Liberado com autorização",L11=""),"Falta quem autorizou",IF(AND(N(H11)>0,M11=""),"Desvio sem registro de não conforme",IF(AND(J11="Retido",M11=""),"Retido sem registro de não conforme",IF(AND(J11<>"Retido",K11=""),"Falta quem liberou","OK"))))))))
B12: 6 | I12: =IF(D12="","",IF(OR(F12="",G12=""),"Falta o número de verificações",IF(G12>F12,"Feitas acima das previstas",IF(G12<F12,"Verificação pendente",IF(N(H12)>0,"Com desvio","Conforme"))))) | O12: =IF(D12="","",IF(J12="","Falta a decisão",IF(OR(LEFT(I12,5)="Falta",LEFT(I12,5)="Feita"),I12,IF(AND(G12<F12,J12="Liberado"),"Liberado com verificação pendente",IF(AND(J12="Liberado com autorização",L12=""),"Falta quem autorizou",IF(AND(N(H12)>0,M12=""),"Desvio sem registro de não conforme",IF(AND(J12="Retido",M12=""),"Retido sem registro de não conforme",IF(AND(J12<>"Retido",K12=""),"Falta quem liberou","OK"))))))))
B13: 7 | I13: =IF(D13="","",IF(OR(F13="",G13=""),"Falta o número de verificações",IF(G13>F13,"Feitas acima das previstas",IF(G13<F13,"Verificação pendente",IF(N(H13)>0,"Com desvio","Conforme"))))) | O13: =IF(D13="","",IF(J13="","Falta a decisão",IF(OR(LEFT(I13,5)="Falta",LEFT(I13,5)="Feita"),I13,IF(AND(G13<F13,J13="Liberado"),"Liberado com verificação pendente",IF(AND(J13="Liberado com autorização",L13=""),"Falta quem autorizou",IF(AND(N(H13)>0,M13=""),"Desvio sem registro de não conforme",IF(AND(J13="Retido",M13=""),"Retido sem registro de não conforme",IF(AND(J13<>"Retido",K13=""),"Falta quem liberou","OK"))))))))
B14: 8 | I14: =IF(D14="","",IF(OR(F14="",G14=""),"Falta o número de verificações",IF(G14>F14,"Feitas acima das previstas",IF(G14<F14,"Verificação pendente",IF(N(H14)>0,"Com desvio","Conforme"))))) | O14: =IF(D14="","",IF(J14="","Falta a decisão",IF(OR(LEFT(I14,5)="Falta",LEFT(I14,5)="Feita"),I14,IF(AND(G14<F14,J14="Liberado"),"Liberado com verificação pendente",IF(AND(J14="Liberado com autorização",L14=""),"Falta quem autorizou",IF(AND(N(H14)>0,M14=""),"Desvio sem registro de não conforme",IF(AND(J14="Retido",M14=""),"Retido sem registro de não conforme",IF(AND(J14<>"Retido",K14=""),"Falta quem liberou","OK"))))))))
B15: 9 | I15: =IF(D15="","",IF(OR(F15="",G15=""),"Falta o número de verificações",IF(G15>F15,"Feitas acima das previstas",IF(G15<F15,"Verificação pendente",IF(N(H15)>0,"Com desvio","Conforme"))))) | O15: =IF(D15="","",IF(J15="","Falta a decisão",IF(OR(LEFT(I15,5)="Falta",LEFT(I15,5)="Feita"),I15,IF(AND(G15<F15,J15="Liberado"),"Liberado com verificação pendente",IF(AND(J15="Liberado com autorização",L15=""),"Falta quem autorizou",IF(AND(N(H15)>0,M15=""),"Desvio sem registro de não conforme",IF(AND(J15="Retido",M15=""),"Retido sem registro de não conforme",IF(AND(J15<>"Retido",K15=""),"Falta quem liberou","OK"))))))))
B16: 10 | I16: =IF(D16="","",IF(OR(F16="",G16=""),"Falta o número de verificações",IF(G16>F16,"Feitas acima das previstas",IF(G16<F16,"Verificação pendente",IF(N(H16)>0,"Com desvio","Conforme"))))) | O16: =IF(D16="","",IF(J16="","Falta a decisão",IF(OR(LEFT(I16,5)="Falta",LEFT(I16,5)="Feita"),I16,IF(AND(G16<F16,J16="Liberado"),"Liberado com verificação pendente",IF(AND(J16="Liberado com autorização",L16=""),"Falta quem autorizou",IF(AND(N(H16)>0,M16=""),"Desvio sem registro de não conforme",IF(AND(J16="Retido",M16=""),"Retido sem registro de não conforme",IF(AND(J16<>"Retido",K16=""),"Falta quem liberou","OK"))))))))
B17: 11 | I17: =IF(D17="","",IF(OR(F17="",G17=""),"Falta o número de verificações",IF(G17>F17,"Feitas acima das previstas",IF(G17<F17,"Verificação pendente",IF(N(H17)>0,"Com desvio","Conforme"))))) | O17: =IF(D17="","",IF(J17="","Falta a decisão",IF(OR(LEFT(I17,5)="Falta",LEFT(I17,5)="Feita"),I17,IF(AND(G17<F17,J17="Liberado"),"Liberado com verificação pendente",IF(AND(J17="Liberado com autorização",L17=""),"Falta quem autorizou",IF(AND(N(H17)>0,M17=""),"Desvio sem registro de não conforme",IF(AND(J17="Retido",M17=""),"Retido sem registro de não conforme",IF(AND(J17<>"Retido",K17=""),"Falta quem liberou","OK"))))))))
B18: 12 | I18: =IF(D18="","",IF(OR(F18="",G18=""),"Falta o número de verificações",IF(G18>F18,"Feitas acima das previstas",IF(G18<F18,"Verificação pendente",IF(N(H18)>0,"Com desvio","Conforme"))))) | O18: =IF(D18="","",IF(J18="","Falta a decisão",IF(OR(LEFT(I18,5)="Falta",LEFT(I18,5)="Feita"),I18,IF(AND(G18<F18,J18="Liberado"),"Liberado com verificação pendente",IF(AND(J18="Liberado com autorização",L18=""),"Falta quem autorizou",IF(AND(N(H18)>0,M18=""),"Desvio sem registro de não conforme",IF(AND(J18="Retido",M18=""),"Retido sem registro de não conforme",IF(AND(J18<>"Retido",K18=""),"Falta quem liberou","OK"))))))))
... B66: 60 | I66: =IF(D66="","",IF(OR(F66="",G66=""),"Falta o número de verificações",IF(G66>F66,"Feitas acima das previstas",IF(G66<F66,"Verificação pendente",IF(N(H66)>0,"Com desvio","Conforme"))))) | O66: =IF(D66="","",IF(J66="","Falta a decisão",IF(OR(LEFT(I66,5)="Falta",LEFT(I66,5)="Feita"),I66,IF(AND(G66<F66,J66="Liberado"),"Liberado com verificação pendente",IF(AND(J66="Liberado com autorização",L66=""),"Falta quem autorizou",IF(AND(N(H66)>0,M66=""),"Desvio sem registro de não conforme",IF(AND(J66="Retido",M66=""),"Retido sem registro de não conforme",IF(AND(J66<>"Retido",K66=""),"Falta quem liberou","OK"))))))))
B68: Resumo automático
B69: Lotes registrados | E69: =COUNTA(D7:D66) -> 0
B70: Por decisão | E70: =IF(E69=0,"",COUNTIF(J7:J66,"Liberado")&" liberados, "&COUNTIF(J7:J66,"Liberado com autorização")&" com autorização, "&COUNTIF(J7:J66,"Retido")&" retidos")
B71: Liberações a rever | E71: =SUMPRODUCT((O7:O66<>"")*(O7:O66<>"OK")) -> 0
B72: Aviso | E72: =IF(E69=0,"Registre as liberações",IF(COUNTIF(O7:O66,"Liberado com verificação pendente")>0,"Há lote liberado com verificação pendente, sem autorização",IF(E71>0,"Há liberação a rever: veja a coluna Conferência","OK"))) -> Registre as liberações

Sheet Produto não conforme
B1: Registro de produto não conforme
B2: Uma linha por caso. O registro descreve o defeito, a segregação, a disposição, quem decidiu e o que foi feito com o cliente.
B4: # | C4: Nº do registro | D4: Data | E4: Lote ou pedido | F4: Defeito | G4: Descrição | H4: Quantidade | I4: Onde foi visto | J4: Identificação e segregação | K4: Disposição | L4: Quem decidiu | M4: Cliente: concessão ou comunicação | N4: Reverificação | O4: Encerrado em | P4: Custo | Q4: Ação corretiva | R4: Situação | S4: Repetições | T4: Conferência
C5: Código | D5: Data | E5: A identificação | F5: Nome curto, sempre igual | G5: O que foi visto, com o critério | H5: Com unidade | I5: Lista | J5: A marca e o lugar | K5: Lista | L5: Uma função | M5: Aceite ou aviso, com data | N5: Lista | O5: Data | P5: R$ | Q5: Quando houver | R5: Calculada | S5: Calculadas | T5: Calculada
B6: Ex. | C6: 2027-21 | D6: 46527 | E6: Lote 140 | F6: Espessura fora | G6: Espessura de 43,1 e 43,4 µm, com o critério de 38 a 42 µm. | H6: 600 kg | I6: Inspeção final | J6: Lote retido, etiqueta vermelha no palete. | K6: Aceitar sob concessão | L6: Coordenador da Qualidade | M6: Cliente B aceitou por e-mail de 21/05. | O6: 46528 | P6: 1350 | R6: Encerrado | S6: 1 | T6: OK
B7: 1 | R7: =IF(F7="","",IF(K7="","Aberto",IF(O7="","Em tratamento","Encerrado"))) | S7: =IF(F7="","",COUNTIF($F$7:$F$66,F7)) | T7: =IF(F7="",IF(COUNTA(C7:E7,G7:Q7)>0,"Falta o defeito",""),IF(D7="","Falta a data",IF(I7="","Falta onde foi visto",IF(K7="","Falta a disposição",IF(L7="","Falta quem decidiu",IF(AND(J7="",I7<>"Após a entrega"),"Falta a identificação e a segregação",IF(AND(K7="Aceitar sob concessão",M7=""),"Falta a concessão do cliente",IF(AND(I7="Após a entrega",M7=""),"Falta informar o cliente",IF(AND(K7="Retrabalhar",N7=""),"Falta a reverificação",IF(AND(N7="Não conforme",O7<>""),"Encerrado com reverificação não conforme",IF(AND(S7>=3,COUNTIFS($F$7:$F$66,F7,$Q$7:$Q$66,"?*")=0),"Defeito repetido: avaliar ação corretiva","OK")))))))))))
B8: 2 | R8: =IF(F8="","",IF(K8="","Aberto",IF(O8="","Em tratamento","Encerrado"))) | S8: =IF(F8="","",COUNTIF($F$7:$F$66,F8)) | T8: =IF(F8="",IF(COUNTA(C8:E8,G8:Q8)>0,"Falta o defeito",""),IF(D8="","Falta a data",IF(I8="","Falta onde foi visto",IF(K8="","Falta a disposição",IF(L8="","Falta quem decidiu",IF(AND(J8="",I8<>"Após a entrega"),"Falta a identificação e a segregação",IF(AND(K8="Aceitar sob concessão",M8=""),"Falta a concessão do cliente",IF(AND(I8="Após a entrega",M8=""),"Falta informar o cliente",IF(AND(K8="Retrabalhar",N8=""),"Falta a reverificação",IF(AND(N8="Não conforme",O8<>""),"Encerrado com reverificação não conforme",IF(AND(S8>=3,COUNTIFS($F$7:$F$66,F8,$Q$7:$Q$66,"?*")=0),"Defeito repetido: avaliar ação corretiva","OK")))))))))))
B9: 3 | R9: =IF(F9="","",IF(K9="","Aberto",IF(O9="","Em tratamento","Encerrado"))) | S9: =IF(F9="","",COUNTIF($F$7:$F$66,F9)) | T9: =IF(F9="",IF(COUNTA(C9:E9,G9:Q9)>0,"Falta o defeito",""),IF(D9="","Falta a data",IF(I9="","Falta onde foi visto",IF(K9="","Falta a disposição",IF(L9="","Falta quem decidiu",IF(AND(J9="",I9<>"Após a entrega"),"Falta a identificação e a segregação",IF(AND(K9="Aceitar sob concessão",M9=""),"Falta a concessão do cliente",IF(AND(I9="Após a entrega",M9=""),"Falta informar o cliente",IF(AND(K9="Retrabalhar",N9=""),"Falta a reverificação",IF(AND(N9="Não conforme",O9<>""),"Encerrado com reverificação não conforme",IF(AND(S9>=3,COUNTIFS($F$7:$F$66,F9,$Q$7:$Q$66,"?*")=0),"Defeito repetido: avaliar ação corretiva","OK")))))))))))
B10: 4 | R10: =IF(F10="","",IF(K10="","Aberto",IF(O10="","Em tratamento","Encerrado"))) | S10: =IF(F10="","",COUNTIF($F$7:$F$66,F10)) | T10: =IF(F10="",IF(COUNTA(C10:E10,G10:Q10)>0,"Falta o defeito",""),IF(D10="","Falta a data",IF(I10="","Falta onde foi visto",IF(K10="","Falta a disposição",IF(L10="","Falta quem decidiu",IF(AND(J10="",I10<>"Após a entrega"),"Falta a identificação e a segregação",IF(AND(K10="Aceitar sob concessão",M10=""),"Falta a concessão do cliente",IF(AND(I10="Após a entrega",M10=""),"Falta informar o cliente",IF(AND(K10="Retrabalhar",N10=""),"Falta a reverificação",IF(AND(N10="Não conforme",O10<>""),"Encerrado com reverificação não conforme",IF(AND(S10>=3,COUNTIFS($F$7:$F$66,F10,$Q$7:$Q$66,"?*")=0),"Defeito repetido: avaliar ação corretiva","OK")))))))))))
B11: 5 | R11: =IF(F11="","",IF(K11="","Aberto",IF(O11="","Em tratamento","Encerrado"))) | S11: =IF(F11="","",COUNTIF($F$7:$F$66,F11)) | T11: =IF(F11="",IF(COUNTA(C11:E11,G11:Q11)>0,"Falta o defeito",""),IF(D11="","Falta a data",IF(I11="","Falta onde foi visto",IF(K11="","Falta a disposição",IF(L11="","Falta quem decidiu",IF(AND(J11="",I11<>"Após a entrega"),"Falta a identificação e a segregação",IF(AND(K11="Aceitar sob concessão",M11=""),"Falta a concessão do cliente",IF(AND(I11="Após a entrega",M11=""),"Falta informar o cliente",IF(AND(K11="Retrabalhar",N11=""),"Falta a reverificação",IF(AND(N11="Não conforme",O11<>""),"Encerrado com reverificação não conforme",IF(AND(S11>=3,COUNTIFS($F$7:$F$66,F11,$Q$7:$Q$66,"?*")=0),"Defeito repetido: avaliar ação corretiva","OK")))))))))))
B12: 6 | R12: =IF(F12="","",IF(K12="","Aberto",IF(O12="","Em tratamento","Encerrado"))) | S12: =IF(F12="","",COUNTIF($F$7:$F$66,F12)) | T12: =IF(F12="",IF(COUNTA(C12:E12,G12:Q12)>0,"Falta o defeito",""),IF(D12="","Falta a data",IF(I12="","Falta onde foi visto",IF(K12="","Falta a disposição",IF(L12="","Falta quem decidiu",IF(AND(J12="",I12<>"Após a entrega"),"Falta a identificação e a segregação",IF(AND(K12="Aceitar sob concessão",M12=""),"Falta a concessão do cliente",IF(AND(I12="Após a entrega",M12=""),"Falta informar o cliente",IF(AND(K12="Retrabalhar",N12=""),"Falta a reverificação",IF(AND(N12="Não conforme",O12<>""),"Encerrado com reverificação não conforme",IF(AND(S12>=3,COUNTIFS($F$7:$F$66,F12,$Q$7:$Q$66,"?*")=0),"Defeito repetido: avaliar ação corretiva","OK")))))))))))
B13: 7 | R13: =IF(F13="","",IF(K13="","Aberto",IF(O13="","Em tratamento","Encerrado"))) | S13: =IF(F13="","",COUNTIF($F$7:$F$66,F13)) | T13: =IF(F13="",IF(COUNTA(C13:E13,G13:Q13)>0,"Falta o defeito",""),IF(D13="","Falta a data",IF(I13="","Falta onde foi visto",IF(K13="","Falta a disposição",IF(L13="","Falta quem decidiu",IF(AND(J13="",I13<>"Após a entrega"),"Falta a identificação e a segregação",IF(AND(K13="Aceitar sob concessão",M13=""),"Falta a concessão do cliente",IF(AND(I13="Após a entrega",M13=""),"Falta informar o cliente",IF(AND(K13="Retrabalhar",N13=""),"Falta a reverificação",IF(AND(N13="Não conforme",O13<>""),"Encerrado com reverificação não conforme",IF(AND(S13>=3,COUNTIFS($F$7:$F$66,F13,$Q$7:$Q$66,"?*")=0),"Defeito repetido: avaliar ação corretiva","OK")))))))))))
B14: 8 | R14: =IF(F14="","",IF(K14="","Aberto",IF(O14="","Em tratamento","Encerrado"))) | S14: =IF(F14="","",COUNTIF($F$7:$F$66,F14)) | T14: =IF(F14="",IF(COUNTA(C14:E14,G14:Q14)>0,"Falta o defeito",""),IF(D14="","Falta a data",IF(I14="","Falta onde foi visto",IF(K14="","Falta a disposição",IF(L14="","Falta quem decidiu",IF(AND(J14="",I14<>"Após a entrega"),"Falta a identificação e a segregação",IF(AND(K14="Aceitar sob concessão",M14=""),"Falta a concessão do cliente",IF(AND(I14="Após a entrega",M14=""),"Falta informar o cliente",IF(AND(K14="Retrabalhar",N14=""),"Falta a reverificação",IF(AND(N14="Não conforme",O14<>""),"Encerrado com reverificação não conforme",IF(AND(S14>=3,COUNTIFS($F$7:$F$66,F14,$Q$7:$Q$66,"?*")=0),"Defeito repetido: avaliar ação corretiva","OK")))))))))))
B15: 9 | R15: =IF(F15="","",IF(K15="","Aberto",IF(O15="","Em tratamento","Encerrado"))) | S15: =IF(F15="","",COUNTIF($F$7:$F$66,F15)) | T15: =IF(F15="",IF(COUNTA(C15:E15,G15:Q15)>0,"Falta o defeito",""),IF(D15="","Falta a data",IF(I15="","Falta onde foi visto",IF(K15="","Falta a disposição",IF(L15="","Falta quem decidiu",IF(AND(J15="",I15<>"Após a entrega"),"Falta a identificação e a segregação",IF(AND(K15="Aceitar sob concessão",M15=""),"Falta a concessão do cliente",IF(AND(I15="Após a entrega",M15=""),"Falta informar o cliente",IF(AND(K15="Retrabalhar",N15=""),"Falta a reverificação",IF(AND(N15="Não conforme",O15<>""),"Encerrado com reverificação não conforme",IF(AND(S15>=3,COUNTIFS($F$7:$F$66,F15,$Q$7:$Q$66,"?*")=0),"Defeito repetido: avaliar ação corretiva","OK")))))))))))
B16: 10 | R16: =IF(F16="","",IF(K16="","Aberto",IF(O16="","Em tratamento","Encerrado"))) | S16: =IF(F16="","",COUNTIF($F$7:$F$66,F16)) | T16: =IF(F16="",IF(COUNTA(C16:E16,G16:Q16)>0,"Falta o defeito",""),IF(D16="","Falta a data",IF(I16="","Falta onde foi visto",IF(K16="","Falta a disposição",IF(L16="","Falta quem decidiu",IF(AND(J16="",I16<>"Após a entrega"),"Falta a identificação e a segregação",IF(AND(K16="Aceitar sob concessão",M16=""),"Falta a concessão do cliente",IF(AND(I16="Após a entrega",M16=""),"Falta informar o cliente",IF(AND(K16="Retrabalhar",N16=""),"Falta a reverificação",IF(AND(N16="Não conforme",O16<>""),"Encerrado com reverificação não conforme",IF(AND(S16>=3,COUNTIFS($F$7:$F$66,F16,$Q$7:$Q$66,"?*")=0),"Defeito repetido: avaliar ação corretiva","OK")))))))))))
B17: 11 | R17: =IF(F17="","",IF(K17="","Aberto",IF(O17="","Em tratamento","Encerrado"))) | S17: =IF(F17="","",COUNTIF($F$7:$F$66,F17)) | T17: =IF(F17="",IF(COUNTA(C17:E17,G17:Q17)>0,"Falta o defeito",""),IF(D17="","Falta a data",IF(I17="","Falta onde foi visto",IF(K17="","Falta a disposição",IF(L17="","Falta quem decidiu",IF(AND(J17="",I17<>"Após a entrega"),"Falta a identificação e a segregação",IF(AND(K17="Aceitar sob concessão",M17=""),"Falta a concessão do cliente",IF(AND(I17="Após a entrega",M17=""),"Falta informar o cliente",IF(AND(K17="Retrabalhar",N17=""),"Falta a reverificação",IF(AND(N17="Não conforme",O17<>""),"Encerrado com reverificação não conforme",IF(AND(S17>=3,COUNTIFS($F$7:$F$66,F17,$Q$7:$Q$66,"?*")=0),"Defeito repetido: avaliar ação corretiva","OK")))))))))))
B18: 12 | R18: =IF(F18="","",IF(K18="","Aberto",IF(O18="","Em tratamento","Encerrado"))) | S18: =IF(F18="","",COUNTIF($F$7:$F$66,F18)) | T18: =IF(F18="",IF(COUNTA(C18:E18,G18:Q18)>0,"Falta o defeito",""),IF(D18="","Falta a data",IF(I18="","Falta onde foi visto",IF(K18="","Falta a disposição",IF(L18="","Falta quem decidiu",IF(AND(J18="",I18<>"Após a entrega"),"Falta a identificação e a segregação",IF(AND(K18="Aceitar sob concessão",M18=""),"Falta a concessão do cliente",IF(AND(I18="Após a entrega",M18=""),"Falta informar o cliente",IF(AND(K18="Retrabalhar",N18=""),"Falta a reverificação",IF(AND(N18="Não conforme",O18<>""),"Encerrado com reverificação não conforme",IF(AND(S18>=3,COUNTIFS($F$7:$F$66,F18,$Q$7:$Q$66,"?*")=0),"Defeito repetido: avaliar ação corretiva","OK")))))))))))
... B66: 60 | R66: =IF(F66="","",IF(K66="","Aberto",IF(O66="","Em tratamento","Encerrado"))) | S66: =IF(F66="","",COUNTIF($F$7:$F$66,F66)) | T66: =IF(F66="",IF(COUNTA(C66:E66,G66:Q66)>0,"Falta o defeito",""),IF(D66="","Falta a data",IF(I66="","Falta onde foi visto",IF(K66="","Falta a disposição",IF(L66="","Falta quem decidiu",IF(AND(J66="",I66<>"Após a entrega"),"Falta a identificação e a segregação",IF(AND(K66="Aceitar sob concessão",M66=""),"Falta a concessão do cliente",IF(AND(I66="Após a entrega",M66=""),"Falta informar o cliente",IF(AND(K66="Retrabalhar",N66=""),"Falta a reverificação",IF(AND(N66="Não conforme",O66<>""),"Encerrado com reverificação não conforme",IF(AND(S66>=3,COUNTIFS($F$7:$F$66,F66,$Q$7:$Q$66,"?*")=0),"Defeito repetido: avaliar ação corretiva","OK")))))))))))
B68: Resumo automático
B69: Registros | E69: =COUNTA(F7:F66) -> 0
B70: Por situação | E70: =IF(E69=0,"",COUNTIF(R7:R66,"Aberto")&" abertos, "&COUNTIF(R7:R66,"Em tratamento")&" em tratamento, "&COUNTIF(R7:R66,"Encerrado")&" encerrados")
B71: Custo | E71: =SUM(P7:P66) -> 0
B72: Aviso | E72: =IF(E69=0,"Registre os casos de produto não conforme",IF(COUNTIF(T7:T66,"Falta informar o cliente")>0,"Há defeito visto depois da entrega sem o cliente informado",IF(COUNTIF(R7:R66,"Aberto")>0,"Há registro sem disposição",IF(COUNTIF(T7:T66,"Defeito repetido: avaliar ação corretiva")>0,"Há defeito repetido sem ação corretiva",IF(SUMPRODUCT((T7:T66<>"")*(T7:T66<>"OK"))>0,"Há registro a completar: veja a coluna Conferência","OK"))))) -> Registre os casos de produto não conforme

Sheet Painel
B1: Painel da liberação e do produto não conforme
B2: Nada a preencher: tudo vem das outras abas.
B4: Indicador | C4: Resultado | D4: Como se lê
B5: Lotes registrados | C5: =COUNTA(Liberação!D7:D66) -> 0 | D5: Da aba Liberação.
B6: Liberados conformes | C6: =COUNTIFS(Liberação!J7:J66,"Liberado",Liberação!I7:I66,"Conforme") -> 0 | D6: Todas as verificações feitas, nenhuma fora do critério.
B7: Liberados com autorização | C7: =COUNTIF(Liberação!J7:J66,"Liberado com autorização") -> 0 | D7: Verificação pendente, com a aprovação de quem pode.
B8: Retidos | C8: =COUNTIF(Liberação!J7:J66,"Retido") -> 0 | D8: Esperam a disposição.
B9: Liberações a rever | C9: =SUMPRODUCT((Liberação!O7:O66<>"")*(Liberação!O7:O66<>"OK")) -> 0 | D9: Liberado com pendência, sem quem liberou, desvio sem registro.
B10: Registros de produto não conforme | C10: =COUNTA('Produto não conforme'!F7:F66) -> 0 | D10: Da aba Produto não conforme.
B11: Abertos, sem disposição | C11: =COUNTIF('Produto não conforme'!R7:R66,"Aberto") -> 0 | D11: Decidir na semana.
B12: Em tratamento | C12: =COUNTIF('Produto não conforme'!R7:R66,"Em tratamento") -> 0 | D12: Com disposição, sem encerramento.
B13: Achados depois da entrega | C13: =COUNTIF('Produto não conforme'!I7:I66,"Após a entrega") -> 0 | D13: Os mais caros: o cliente viu o defeito.
B14: Custo do período | C14: =SUM('Produto não conforme'!P7:P66) -> 0 | D14: A soma do custo dos registros.
B15: Registros a completar | C15: =SUMPRODUCT(('Produto não conforme'!T7:T66<>"")*('Produto não conforme'!T7:T66<>"OK")) -> 0 | D15: Veja a coluna Conferência da aba Produto não conforme.
B16: Defeitos repetidos sem ação | C16: =COUNTIF('Produto não conforme'!T7:T66,"Defeito repetido: avaliar ação corretiva") -> 0 | D16: Registros de um defeito com 3 casos ou mais, sem ação corretiva.
B18: Onde o defeito foi visto, e quanto custou
B19: Ponto de detecção | C19: Registros | D19: Custo | E19: Custo por registro | F19: Parte do custo | G19: Leitura
B20: Recebimento | C20: =COUNTIF('Produto não conforme'!I7:I66,B20) -> 0 | D20: =SUMIF('Produto não conforme'!I7:I66,B20,'Produto não conforme'!P7:P66) -> 0 | E20: =IF(C20=0,0,D20/C20) -> 0 | F20: =IF(SUM(D$20:D$23)=0,"",D20/SUM(D$20:D$23)) | G20: O defeito não entrou na operação.
B21: Processo | C21: =COUNTIF('Produto não conforme'!I7:I66,B21) -> 0 | D21: =SUMIF('Produto não conforme'!I7:I66,B21,'Produto não conforme'!P7:P66) -> 0 | E21: =IF(C21=0,0,D21/C21) -> 0 | F21: =IF(SUM(D$20:D$23)=0,"",D21/SUM(D$20:D$23)) | G21: Visto onde nasce: a correção é barata.
B22: Inspeção final | C22: =COUNTIF('Produto não conforme'!I7:I66,B22) -> 0 | D22: =SUMIF('Produto não conforme'!I7:I66,B22,'Produto não conforme'!P7:P66) -> 0 | E22: =IF(C22=0,0,D22/C22) -> 0 | F22: =IF(SUM(D$20:D$23)=0,"",D22/SUM(D$20:D$23)) | G22: O produto já está pronto: o custo cresce.
B23: Após a entrega | C23: =COUNTIF('Produto não conforme'!I7:I66,B23) -> 0 | D23: =SUMIF('Produto não conforme'!I7:I66,B23,'Produto não conforme'!P7:P66) -> 0 | E23: =IF(C23=0,0,D23/C23) -> 0 | F23: =IF(SUM(D$20:D$23)=0,"",D23/SUM(D$20:D$23)) | G23: O cliente viu: o mais caro.
B25: Por disposição
B26: Disposição | C26: Registros | D26: Custo | E26: Custo por registro | F26: Parte do custo | G26: Cuidado
B27: Retrabalhar | C27: =COUNTIF('Produto não conforme'!K7:K66,B27) -> 0 | D27: =SUMIF('Produto não conforme'!K7:K66,B27,'Produto não conforme'!P7:P66) -> 0 | E27: =IF(C27=0,"",D27/C27) | F27: =IF(SUM(D$27:D$32)=0,"",D27/SUM(D$27:D$32)) | G27: Verificar de novo depois da correção.
B28: Reclassificar | C28: =COUNTIF('Produto não conforme'!K7:K66,B28) -> 0 | D28: =SUMIF('Produto não conforme'!K7:K66,B28,'Produto não conforme'!P7:P66) -> 0 | E28: =IF(C28=0,"",D28/C28) | F28: =IF(SUM(D$27:D$32)=0,"",D28/SUM(D$27:D$32)) | G28: Identificar de novo, com a nova classe.
B29: Aceitar sob concessão | C29: =COUNTIF('Produto não conforme'!K7:K66,B29) -> 0 | D29: =SUMIF('Produto não conforme'!K7:K66,B29,'Produto não conforme'!P7:P66) -> 0 | E29: =IF(C29=0,"",D29/C29) | F29: =IF(SUM(D$27:D$32)=0,"",D29/SUM(D$27:D$32)) | G29: A autorização do cliente, por escrito, antes da entrega.
B30: Refugar | C30: =COUNTIF('Produto não conforme'!K7:K66,B30) -> 0 | D30: =SUMIF('Produto não conforme'!K7:K66,B30,'Produto não conforme'!P7:P66) -> 0 | E30: =IF(C30=0,"",D30/C30) | F30: =IF(SUM(D$27:D$32)=0,"",D30/SUM(D$27:D$32)) | G30: Garantir que o produto não volte ao fluxo.
B31: Devolver ao fornecedor | C31: =COUNTIF('Produto não conforme'!K7:K66,B31) -> 0 | D31: =SUMIF('Produto não conforme'!K7:K66,B31,'Produto não conforme'!P7:P66) -> 0 | E31: =IF(C31=0,"",D31/C31) | F31: =IF(SUM(D$27:D$32)=0,"",D31/SUM(D$27:D$32)) | G31: Registrar a ocorrência na avaliação do fornecedor.
B32: Recolher ou substituir | C32: =COUNTIF('Produto não conforme'!K7:K66,B32) -> 0 | D32: =SUMIF('Produto não conforme'!K7:K66,B32,'Produto não conforme'!P7:P66) -> 0 | E32: =IF(C32=0,"",D32/C32) | F32: =IF(SUM(D$27:D$32)=0,"",D32/SUM(D$27:D$32)) | G32: Informar o cliente, sem esperar a reclamação.
B34: Resumo automático
B35: Aviso | C35: =IF(AND(C5=0,C10=0),"Registre as liberações e os casos de produto não conforme",IF(COUNTIF('Produto não conforme'!T7:T66,"Falta informar o cliente")>0,"Há defeito visto depois da entrega sem o cliente informado",IF(COUNTIF(Liberação!O7:O66,"Liberado com verificação pendente")>0,"Há lote liberado com verificação pendente, sem autorização",IF(C11>0,"Há registro sem disposição",IF(C16>0,"Há defeito repetido sem ação corretiva",IF(C9+C15>0,"Há liberação ou registro a completar","OK")))))) -> Registre as liberações e os casos de produto não conforme

Sheet Checklist
B1: Checklist da liberação e do produto não conforme
B2: Escolha o status de cada item na lista suspensa (coluna em amarelo-claro).
B4: # | C4: Item de verificação | D4: Status | E4: Observações
B5: 1 | C5: Cada produto tem critérios de aceitação escritos e as verificações que precisam estar feitas antes da liberação.
B6: 2 | C6: Está definido quem tem autoridade para liberar, e o registro de liberação traz esse nome.
B7: 3 | C7: Nenhum produto sai com verificação pendente sem a autorização de quem pode autorizar e, quando aplicável, do cliente.
B8: 4 | C8: O produto não conforme é identificado assim que é encontrado.
B9: 5 | C9: O produto não conforme é separado do fluxo, para não ser usado nem entregue por engano.
B10: 6 | C10: Está definido quem pode decidir cada disposição: retrabalhar, reclassificar, conceder, refugar, devolver ou recolher.
B11: 7 | C11: O produto retrabalhado é verificado de novo antes de seguir.
B12: 8 | C12: A concessão tem a autorização do cliente registrada, antes da entrega.
B13: 9 | C13: O defeito encontrado depois da entrega é comunicado ao cliente, sem esperar a reclamação.
B14: 10 | C14: Cada registro descreve o defeito, a ação tomada, a concessão obtida e quem decidiu.
B15: 11 | C15: Os registros abertos são lidos toda semana, e nenhum fica sem disposição.
B16: 12 | C16: O defeito que se repete leva à análise de causa, no tratamento de não conformidades.
B18: Resumo automático
B19: Itens atendidos (Sim) | D19: =COUNTIF(D5:D16,"Sim") -> 0
B20: Itens parciais | D20: =COUNTIF(D5:D16,"Parcial") -> 0
B21: Itens não atendidos | D21: =COUNTIF(D5:D16,"Não") -> 0
B22: Itens sem resposta | D22: =COUNTBLANK(D5:D16) -> 12
B23: Percentual atendido | D23: =D19/ROWS(D5:D16) -> 0
B24: Situação | D24: =IF(D19=ROWS(D5:D16),"Validado",IF(D22>0,"Em andamento","Com pendências")) -> Em andamento

Sheet Exemplo 1 - Pizzaria
B1: Liberação e produto não conforme
B2: Exemplo preenchido, para consulta. Use as abas Autoridades, Liberação e Produto não conforme para a sua organização.
B4: Organização | E4: Pizzaria (loja com salão e delivery)
B5: Processo | E5: Produzir e embalar (P2) e Entregar o pedido (P3)
B6: Produto | E6: Pizza entregue em casa e servida no salão
B7: Quem libera | E7: Cada pedido: quem embala, com a rubrica na etiqueta. O fechamento da noite: líder da expedição.
B8: Quem decide a disposição | E8: Pizzaiolo líder e líder da expedição, no turno. Gerente da loja, para descarte de insumos, concessão e troca no cliente.
B9: Registros | E9: Noites de 15 a 21/03/2027, lidos em 22/03/2027.
B10: Origem | E10: Requisito 8.7 atendido em parte no diagnóstico de 2026: a pizza errada era refeita, sem registro.
B12: Liberações
B13: Data | C13: Lote | D13: Produto e quantidade | E13: Verificações previstas | F13: Feitas | G13: Fora | H13: Leitura | I13: Decisão | J13: Quem liberou | K13: Quem autorizou | M13: Registro | N13: Observação | Q13: Conferência
B14: 46461 | C14: Noite 15/03 | D14: 142 pedidos | E14: 8 | F14: 8 | G14: 0 | H14: =IF(C14="","",IF(OR(E14="",F14=""),"Falta o número de verificações",IF(F14>E14,"Feitas acima das previstas",IF(F14<E14,"Verificação pendente",IF(N(G14)>0,"Com desvio","Conforme"))))) -> Conforme | I14: Liberado | J14: Líder da expedição | Q14: =IF(C14="","",IF(I14="","Falta a decisão",IF(OR(LEFT(H14,5)="Falta",LEFT(H14,5)="Feita"),H14,IF(AND(F14<E14,I14="Liberado"),"Liberado com verificação pendente",IF(AND(I14="Liberado com autorização",K14=""),"Falta quem autorizou",IF(AND(N(G14)>0,M14=""),"Desvio sem registro de não conforme",IF(AND(I14="Retido",M14=""),"Retido sem registro de não conforme",IF(AND(I14<>"Retido",J14=""),"Falta quem liberou","OK")))))))) -> OK
B15: 46462 | C15: Noite 16/03 | D15: 118 pedidos | E15: 8 | F15: 8 | G15: 1 | H15: =IF(C15="","",IF(OR(E15="",F15=""),"Falta o número de verificações",IF(F15>E15,"Feitas acima das previstas",IF(F15<E15,"Verificação pendente",IF(N(G15)>0,"Com desvio","Conforme"))))) -> Com desvio | I15: Liberado | J15: Líder da expedição | M15: 2027-15 | Q15: =IF(C15="","",IF(I15="","Falta a decisão",IF(OR(LEFT(H15,5)="Falta",LEFT(H15,5)="Feita"),H15,IF(AND(F15<E15,I15="Liberado"),"Liberado com verificação pendente",IF(AND(I15="Liberado com autorização",K15=""),"Falta quem autorizou",IF(AND(N(G15)>0,M15=""),"Desvio sem registro de não conforme",IF(AND(I15="Retido",M15=""),"Retido sem registro de não conforme",IF(AND(I15<>"Retido",J15=""),"Falta quem liberou","OK")))))))) -> OK
B16: 46463 | C16: Noite 17/03 | D16: 125 pedidos | E16: 8 | F16: 8 | G16: 0 | H16: =IF(C16="","",IF(OR(E16="",F16=""),"Falta o número de verificações",IF(F16>E16,"Feitas acima das previstas",IF(F16<E16,"Verificação pendente",IF(N(G16)>0,"Com desvio","Conforme"))))) -> Conforme | I16: Liberado | J16: Líder da expedição | Q16: =IF(C16="","",IF(I16="","Falta a decisão",IF(OR(LEFT(H16,5)="Falta",LEFT(H16,5)="Feita"),H16,IF(AND(F16<E16,I16="Liberado"),"Liberado com verificação pendente",IF(AND(I16="Liberado com autorização",K16=""),"Falta quem autorizou",IF(AND(N(G16)>0,M16=""),"Desvio sem registro de não conforme",IF(AND(I16="Retido",M16=""),"Retido sem registro de não conforme",IF(AND(I16<>"Retido",J16=""),"Falta quem liberou","OK")))))))) -> OK
B17: 46464 | C17: Noite 18/03 | D17: 131 pedidos | E17: 8 | F17: 8 | G17: 1 | H17: =IF(C17="","",IF(OR(E17="",F17=""),"Falta o número de verificações",IF(F17>E17,"Feitas acima das previstas",IF(F17<E17,"Verificação pendente",IF(N(G17)>0,"Com desvio","Conforme"))))) -> Com desvio | I17: Liberado | J17: Líder da expedição | M17: 2027-17 | Q17: =IF(C17="","",IF(I17="","Falta a decisão",IF(OR(LEFT(H17,5)="Falta",LEFT(H17,5)="Feita"),H17,IF(AND(F17<E17,I17="Liberado"),"Liberado com verificação pendente",IF(AND(I17="Liberado com autorização",K17=""),"Falta quem autorizou",IF(AND(N(G17)>0,M17=""),"Desvio sem registro de não conforme",IF(AND(I17="Retido",M17=""),"Retido sem registro de não conforme",IF(AND(I17<>"Retido",J17=""),"Falta quem liberou","OK")))))))) -> OK
B18: 46465 | C18: Noite 19/03 | D18: 214 pedidos | E18: 8 | F18: 8 | G18: 2 | H18: =IF(C18="","",IF(OR(E18="",F18=""),"Falta o número de verificações",IF(F18>E18,"Feitas acima das previstas",IF(F18<E18,"Verificação pendente",IF(N(G18)>0,"Com desvio","Conforme"))))) -> Com desvio | I18: Liberado | J18: Líder da expedição | M18: 2027-18 e 2027-19 | Q18: =IF(C18="","",IF(I18="","Falta a decisão",IF(OR(LEFT(H18,5)="Falta",LEFT(H18,5)="Feita"),H18,IF(AND(F18<E18,I18="Liberado"),"Liberado com verificação pendente",IF(AND(I18="Liberado com autorização",K18=""),"Falta quem autorizou",IF(AND(N(G18)>0,M18=""),"Desvio sem registro de não conforme",IF(AND(I18="Retido",M18=""),"Retido sem registro de não conforme",IF(AND(I18<>"Retido",J18=""),"Falta quem liberou","OK")))))))) -> OK
B19: 46466 | C19: Noite 20/03 | D19: 236 pedidos | E19: 8 | F19: 7 | G19: 1 | H19: =IF(C19="","",IF(OR(E19="",F19=""),"Falta o número de verificações",IF(F19>E19,"Feitas acima das previstas",IF(F19<E19,"Verificação pendente",IF(N(G19)>0,"Com desvio","Conforme"))))) -> Verificação pendente | I19: Liberado | J19: Líder da expedição | M19: 2027-21 | N19: A temperatura na saída não foi medida na última hora do pico. | Q19: =IF(C19="","",IF(I19="","Falta a decisão",IF(OR(LEFT(H19,5)="Falta",LEFT(H19,5)="Feita"),H19,IF(AND(F19<E19,I19="Liberado"),"Liberado com verificação pendente",IF(AND(I19="Liberado com autorização",K19=""),"Falta quem autorizou",IF(AND(N(G19)>0,M19=""),"Desvio sem registro de não conforme",IF(AND(I19="Retido",M19=""),"Retido sem registro de não conforme",IF(AND(I19<>"Retido",J19=""),"Falta quem liberou","OK")))))))) -> Liberado com verificação pendente
B20: 46467 | C20: Noite 21/03 | D20: 160 pedidos | E20: 8 | F20: 8 | G20: 0 | H20: =IF(C20="","",IF(OR(E20="",F20=""),"Falta o número de verificações",IF(F20>E20,"Feitas acima das previstas",IF(F20<E20,"Verificação pendente",IF(N(G20)>0,"Com desvio","Conforme"))))) -> Conforme | I20: Liberado | J20: Líder da expedição | Q20: =IF(C20="","",IF(I20="","Falta a decisão",IF(OR(LEFT(H20,5)="Falta",LEFT(H20,5)="Feita"),H20,IF(AND(F20<E20,I20="Liberado"),"Liberado com verificação pendente",IF(AND(I20="Liberado com autorização",K20=""),"Falta quem autorizou",IF(AND(N(G20)>0,M20=""),"Desvio sem registro de não conforme",IF(AND(I20="Retido",M20=""),"Retido sem registro de não conforme",IF(AND(I20<>"Retido",J20=""),"Falta quem liberou","OK")))))))) -> OK
B22: Produto não conforme
B23: Nº | C23: Data | D23: Lote ou pedido | E23: Defeito | F23: Quantidade | G23: Onde foi visto | H23: Identificação e segregação | I23: Disposição | J23: Quem decidiu | K23: Cliente | L23: Reverificação | M23: Encerrado em | N23: Custo | O23: Ação corretiva | P23: Situação | Q23: Conferência
B24: 2027-14 | C24: 46461 | D24: Noite 13/03, pedido das 21h | E24: Pizza fria na saída | F24: 1 pizza | G24: Inspeção final | P24: =IF(E24="","",IF(I24="","Aberto",IF(M24="","Em tratamento","Encerrado"))) -> Aberto | Q24: =IF(E24="",IF(1>0,"Falta o defeito",""),IF(C24="","Falta a data",IF(G24="","Falta onde foi visto",IF(I24="","Falta a disposição",IF(J24="","Falta quem decidiu",IF(AND(H24="",G24<>"Após a entrega"),"Falta a identificação e a segregação",IF(AND(I24="Aceitar sob concessão",K24=""),"Falta a concessão do cliente",IF(AND(G24="Após a entrega",K24=""),"Falta informar o cliente",IF(AND(I24="Retrabalhar",L24=""),"Falta a reverificação",IF(AND(L24="Não conforme",M24<>""),"Encerrado com reverificação não conforme",IF(AND(COUNTIF($E$24:$E$31,E24)>=3,COUNTIFS($E$24:$E$31,E24,$O$24:$O$31,"?*")=0),"Defeito repetido: avaliar ação corretiva","OK"))))))))))) -> Falta a disposição
B25: 2027-15 | C25: 46462 | D25: Pedido 5127 | E25: Sabor trocado | F25: 1 pizza | G25: Inspeção final | H25: Retirada da bancada de saída. | I25: Refugar | J25: Pizzaiolo líder | M25: 46462 | N25: 28 | P25: =IF(E25="","",IF(I25="","Aberto",IF(M25="","Em tratamento","Encerrado"))) -> Encerrado | Q25: =IF(E25="",IF(1>0,"Falta o defeito",""),IF(C25="","Falta a data",IF(G25="","Falta onde foi visto",IF(I25="","Falta a disposição",IF(J25="","Falta quem decidiu",IF(AND(H25="",G25<>"Após a entrega"),"Falta a identificação e a segregação",IF(AND(I25="Aceitar sob concessão",K25=""),"Falta a concessão do cliente",IF(AND(G25="Após a entrega",K25=""),"Falta informar o cliente",IF(AND(I25="Retrabalhar",L25=""),"Falta a reverificação",IF(AND(L25="Não conforme",M25<>""),"Encerrado com reverificação não conforme",IF(AND(COUNTIF($E$24:$E$31,E25)>=3,COUNTIFS($E$24:$E$31,E25,$O$24:$O$31,"?*")=0),"Defeito repetido: avaliar ação corretiva","OK"))))))))))) -> OK
B26: 2027-16 | C26: 46463 | D26: Muçarela, nota de 17/03 | E26: Insumo fora de temperatura | F26: 12 kg | G26: Recebimento | H26: Não entrou na câmara. Ficou na área de recebimento, com etiqueta vermelha. | I26: Devolver ao fornecedor | J26: Gerente da loja | M26: 46463 | N26: 0 | P26: =IF(E26="","",IF(I26="","Aberto",IF(M26="","Em tratamento","Encerrado"))) -> Encerrado | Q26: =IF(E26="",IF(1>0,"Falta o defeito",""),IF(C26="","Falta a data",IF(G26="","Falta onde foi visto",IF(I26="","Falta a disposição",IF(J26="","Falta quem decidiu",IF(AND(H26="",G26<>"Após a entrega"),"Falta a identificação e a segregação",IF(AND(I26="Aceitar sob concessão",K26=""),"Falta a concessão do cliente",IF(AND(G26="Após a entrega",K26=""),"Falta informar o cliente",IF(AND(I26="Retrabalhar",L26=""),"Falta a reverificação",IF(AND(L26="Não conforme",M26<>""),"Encerrado com reverificação não conforme",IF(AND(COUNTIF($E$24:$E$31,E26)>=3,COUNTIFS($E$24:$E$31,E26,$O$24:$O$31,"?*")=0),"Defeito repetido: avaliar ação corretiva","OK"))))))))))) -> OK
B27: 2027-17 | C27: 46464 | D27: Massa 18/03 | E27: Peso da massa fora | F27: 40 bolas | G27: Processo | H27: Caixa do lote com etiqueta vermelha. | I27: Retrabalhar | J27: Pizzaiolo líder | L27: Conforme | M27: 46464 | N27: 0 | P27: =IF(E27="","",IF(I27="","Aberto",IF(M27="","Em tratamento","Encerrado"))) -> Encerrado | Q27: =IF(E27="",IF(1>0,"Falta o defeito",""),IF(C27="","Falta a data",IF(G27="","Falta onde foi visto",IF(I27="","Falta a disposição",IF(J27="","Falta quem decidiu",IF(AND(H27="",G27<>"Após a entrega"),"Falta a identificação e a segregação",IF(AND(I27="Aceitar sob concessão",K27=""),"Falta a concessão do cliente",IF(AND(G27="Após a entrega",K27=""),"Falta informar o cliente",IF(AND(I27="Retrabalhar",L27=""),"Falta a reverificação",IF(AND(L27="Não conforme",M27<>""),"Encerrado com reverificação não conforme",IF(AND(COUNTIF($E$24:$E$31,E27)>=3,COUNTIFS($E$24:$E$31,E27,$O$24:$O$31,"?*")=0),"Defeito repetido: avaliar ação corretiva","OK"))))))))))) -> OK
B28: 2027-18 | C28: 46465 | D28: Pedido 5342, mesa 7 | E28: Borda queimada | F28: 1 pizza | G28: Inspeção final | H28: Mostrada ao cliente antes de servir. | I28: Aceitar sob concessão | J28: Gerente da loja | K28: Cliente da mesa 7 aceitou, com desconto de 20%, em 19/03. | M28: 46465 | N28: 11 | P28: =IF(E28="","",IF(I28="","Aberto",IF(M28="","Em tratamento","Encerrado"))) -> Encerrado | Q28: =IF(E28="",IF(1>0,"Falta o defeito",""),IF(C28="","Falta a data",IF(G28="","Falta onde foi visto",IF(I28="","Falta a disposição",IF(J28="","Falta quem decidiu",IF(AND(H28="",G28<>"Após a entrega"),"Falta a identificação e a segregação",IF(AND(I28="Aceitar sob concessão",K28=""),"Falta a concessão do cliente",IF(AND(G28="Após a entrega",K28=""),"Falta informar o cliente",IF(AND(I28="Retrabalhar",L28=""),"Falta a reverificação",IF(AND(L28="Não conforme",M28<>""),"Encerrado com reverificação não conforme",IF(AND(COUNTIF($E$24:$E$31,E28)>=3,COUNTIFS($E$24:$E$31,E28,$O$24:$O$31,"?*")=0),"Defeito repetido: avaliar ação corretiva","OK"))))))))))) -> OK
B29: 2027-19 | C29: 46465 | D29: Pedido 5360 | E29: Pizza fria na saída | F29: 1 pizza | G29: Inspeção final | H29: Voltou da bancada de saída para o forno. | I29: Retrabalhar | J29: Líder da expedição | L29: Conforme | M29: 46465 | N29: 0 | P29: =IF(E29="","",IF(I29="","Aberto",IF(M29="","Em tratamento","Encerrado"))) -> Encerrado | Q29: =IF(E29="",IF(1>0,"Falta o defeito",""),IF(C29="","Falta a data",IF(G29="","Falta onde foi visto",IF(I29="","Falta a disposição",IF(J29="","Falta quem decidiu",IF(AND(H29="",G29<>"Após a entrega"),"Falta a identificação e a segregação",IF(AND(I29="Aceitar sob concessão",K29=""),"Falta a concessão do cliente",IF(AND(G29="Após a entrega",K29=""),"Falta informar o cliente",IF(AND(I29="Retrabalhar",L29=""),"Falta a reverificação",IF(AND(L29="Não conforme",M29<>""),"Encerrado com reverificação não conforme",IF(AND(COUNTIF($E$24:$E$31,E29)>=3,COUNTIFS($E$24:$E$31,E29,$O$24:$O$31,"?*")=0),"Defeito repetido: avaliar ação corretiva","OK"))))))))))) -> OK
B30: 2027-20 | C30: 46466 | D30: Pedido 5431 | E30: Sabor trocado | F30: 1 pizza | G30: Após a entrega | I30: Recolher ou substituir | J30: Gerente da loja | K30: Cliente atendido em 20/03: pizza nova entregue em 35 minutos. | M30: 46466 | N30: 46 | P30: =IF(E30="","",IF(I30="","Aberto",IF(M30="","Em tratamento","Encerrado"))) -> Encerrado | Q30: =IF(E30="",IF(1>0,"Falta o defeito",""),IF(C30="","Falta a data",IF(G30="","Falta onde foi visto",IF(I30="","Falta a disposição",IF(J30="","Falta quem decidiu",IF(AND(H30="",G30<>"Após a entrega"),"Falta a identificação e a segregação",IF(AND(I30="Aceitar sob concessão",K30=""),"Falta a concessão do cliente",IF(AND(G30="Após a entrega",K30=""),"Falta informar o cliente",IF(AND(I30="Retrabalhar",L30=""),"Falta a reverificação",IF(AND(L30="Não conforme",M30<>""),"Encerrado com reverificação não conforme",IF(AND(COUNTIF($E$24:$E$31,E30)>=3,COUNTIFS($E$24:$E$31,E30,$O$24:$O$31,"?*")=0),"Defeito repetido: avaliar ação corretiva","OK"))))))))))) -> OK
B31: 2027-21 | C31: 46466 | D31: Pedido 5440 | E31: Sabor trocado | F31: 1 pizza | G31: Inspeção final | H31: Retirada da bancada de saída. | I31: Refugar | J31: Pizzaiolo líder | M31: 46466 | N31: 28 | O31: RNC 2027-03 | P31: =IF(E31="","",IF(I31="","Aberto",IF(M31="","Em tratamento","Encerrado"))) -> Encerrado | Q31: =IF(E31="",IF(1>0,"Falta o defeito",""),IF(C31="","Falta a data",IF(G31="","Falta onde foi visto",IF(I31="","Falta a disposição",IF(J31="","Falta quem decidiu",IF(AND(H31="",G31<>"Após a entrega"),"Falta a identificação e a segregação",IF(AND(I31="Aceitar sob concessão",K31=""),"Falta a concessão do cliente",IF(AND(G31="Após a entrega",K31=""),"Falta informar o cliente",IF(AND(I31="Retrabalhar",L31=""),"Falta a reverificação",IF(AND(L31="Não conforme",M31<>""),"Encerrado com reverificação não conforme",IF(AND(COUNTIF($E$24:$E$31,E31)>=3,COUNTIFS($E$24:$E$31,E31,$O$24:$O$31,"?*")=0),"Defeito repetido: avaliar ação corretiva","OK"))))))))))) -> OK
B33: Onde o defeito foi visto, e quanto custou
B34: Ponto de detecção | E34: Registros | F34: Custo | H34: Custo por registro | I34: Parte do custo
B35: Recebimento | E35: =COUNTIF(G24:G31,B35) -> 1 | F35: =SUMIF(G24:G31,B35,N24:N31) -> 0 | H35: =IF(E35=0,"",F35/E35) -> 0 | I35: =IF(SUM(F$35:F$38)=0,"",F35/SUM(F$35:F$38)) -> 0
B36: Processo | E36: =COUNTIF(G24:G31,B36) -> 1 | F36: =SUMIF(G24:G31,B36,N24:N31) -> 0 | H36: =IF(E36=0,"",F36/E36) -> 0 | I36: =IF(SUM(F$35:F$38)=0,"",F36/SUM(F$35:F$38)) -> 0
B37: Inspeção final | E37: =COUNTIF(G24:G31,B37) -> 5 | F37: =SUMIF(G24:G31,B37,N24:N31) -> 67 | H37: =IF(E37=0,"",F37/E37) -> 13.4 | I37: =IF(SUM(F$35:F$38)=0,"",F37/SUM(F$35:F$38)) -> 0.59292035
B38: Após a entrega | E38: =COUNTIF(G24:G31,B38) -> 1 | F38: =SUMIF(G24:G31,B38,N24:N31) -> 46 | H38: =IF(E38=0,"",F38/E38) -> 46 | I38: =IF(SUM(F$35:F$38)=0,"",F38/SUM(F$35:F$38)) -> 0.40707965
B40: Resumo automático
B41: Liberações: registradas, a rever | G41: =COUNTA(C14:C20)&" registradas, "&SUMPRODUCT((Q14:Q20<>"OK")*1)&" a rever" -> 7 registradas, 1 a rever
B42: Registros: abertos, em tratamento, encerrados | G42: =COUNTIF(P24:P31,"Aberto")&" abertos, "&COUNTIF(P24:P31,"Em tratamento")&" em tratamento, "&COUNTIF(P24:P31,"Encerrado")&" encerrados" -> 1 abertos, 0 em tratamento, 7 encerrados
B43: Registros a completar | G43: =SUMPRODUCT((Q24:Q31<>"OK")*1) -> 1
B44: Custo do período | G44: =SUM(N24:N31) -> 113
B45: Custo achado depois da entrega | G45: =SUMIF(G24:G31,"Após a entrega",N24:N31) -> 46

Sheet Exemplo 2 - Indústria
B1: Liberação e produto não conforme
B2: Exemplo preenchido, para consulta. Use as abas Autoridades, Liberação e Produto não conforme para a sua organização.
B4: Organização | E4: Indústria de embalagens plásticas
B5: Processo | E5: Extrusão, na extrusora 3, e inspeção final
B6: Produto | E6: Filme de 40 µm para clientes do segmento de alimentos
B7: Quem libera | E7: Analista da Qualidade, com o laudo do lote. Liberação com verificação pendente: só com a autorização do gerente industrial e o aceite do cliente.
B8: Quem decide a disposição | E8: Coordenador da Qualidade. Retrabalho na linha: líder do turno. Devolução de insumo ao fornecedor: gerente de Suprimentos. Refugo acima de 500 kg e recolhimento no cliente: gerente industrial e gerente comercial.
B9: Registros | E9: Lotes 136 a 143, de 17 a 26/05/2027, lidos em 28/05/2027.
B10: Origem | E10: Reclamações do cliente A e o objetivo O1: reduzir o refugo para 2,0%.
B12: Liberações
B13: Data | C13: Lote | D13: Produto e quantidade | E13: Verificações previstas | F13: Feitas | G13: Fora | H13: Leitura | I13: Decisão | J13: Quem liberou | K13: Quem autorizou | M13: Registro | N13: Observação | Q13: Conferência
B14: 46524 | C14: Lote 136 | D14: 4 bobinas, 1.210 kg | E14: 12 | F14: 12 | G14: 0 | H14: =IF(C14="","",IF(OR(E14="",F14=""),"Falta o número de verificações",IF(F14>E14,"Feitas acima das previstas",IF(F14<E14,"Verificação pendente",IF(N(G14)>0,"Com desvio","Conforme"))))) -> Conforme | I14: Liberado | J14: Analista da Qualidade | Q14: =IF(C14="","",IF(I14="","Falta a decisão",IF(OR(LEFT(H14,5)="Falta",LEFT(H14,5)="Feita"),H14,IF(AND(F14<E14,I14="Liberado"),"Liberado com verificação pendente",IF(AND(I14="Liberado com autorização",K14=""),"Falta quem autorizou",IF(AND(N(G14)>0,M14=""),"Desvio sem registro de não conforme",IF(AND(I14="Retido",M14=""),"Retido sem registro de não conforme",IF(AND(I14<>"Retido",J14=""),"Falta quem liberou","OK")))))))) -> OK
B15: 46525 | C15: Lote 137 | D15: 4 bobinas, 1.180 kg | E15: 12 | F15: 12 | G15: 1 | H15: =IF(C15="","",IF(OR(E15="",F15=""),"Falta o número de verificações",IF(F15>E15,"Feitas acima das previstas",IF(F15<E15,"Verificação pendente",IF(N(G15)>0,"Com desvio","Conforme"))))) -> Com desvio | I15: Liberado | J15: Analista da Qualidade | M15: 2027-20 | N15: Bobina 3 segregada. As outras três foram liberadas. | Q15: =IF(C15="","",IF(I15="","Falta a decisão",IF(OR(LEFT(H15,5)="Falta",LEFT(H15,5)="Feita"),H15,IF(AND(F15<E15,I15="Liberado"),"Liberado com verificação pendente",IF(AND(I15="Liberado com autorização",K15=""),"Falta quem autorizou",IF(AND(N(G15)>0,M15=""),"Desvio sem registro de não conforme",IF(AND(I15="Retido",M15=""),"Retido sem registro de não conforme",IF(AND(I15<>"Retido",J15=""),"Falta quem liberou","OK")))))))) -> OK
B16: 46526 | C16: Lote 138 | D16: 4 bobinas, 1.225 kg | E16: 12 | F16: 12 | G16: 0 | H16: =IF(C16="","",IF(OR(E16="",F16=""),"Falta o número de verificações",IF(F16>E16,"Feitas acima das previstas",IF(F16<E16,"Verificação pendente",IF(N(G16)>0,"Com desvio","Conforme"))))) -> Conforme | I16: Liberado | J16: Analista da Qualidade | Q16: =IF(C16="","",IF(I16="","Falta a decisão",IF(OR(LEFT(H16,5)="Falta",LEFT(H16,5)="Feita"),H16,IF(AND(F16<E16,I16="Liberado"),"Liberado com verificação pendente",IF(AND(I16="Liberado com autorização",K16=""),"Falta quem autorizou",IF(AND(N(G16)>0,M16=""),"Desvio sem registro de não conforme",IF(AND(I16="Retido",M16=""),"Retido sem registro de não conforme",IF(AND(I16<>"Retido",J16=""),"Falta quem liberou","OK")))))))) -> OK
B17: 46527 | C17: Lote 139 | D17: 4 bobinas, 1.190 kg | E17: 12 | F17: 11 | G17: 0 | H17: =IF(C17="","",IF(OR(E17="",F17=""),"Falta o número de verificações",IF(F17>E17,"Feitas acima das previstas",IF(F17<E17,"Verificação pendente",IF(N(G17)>0,"Com desvio","Conforme"))))) -> Verificação pendente | I17: Liberado com autorização | J17: Analista da Qualidade | K17: Gerente industrial, com o aceite do cliente A por e-mail. | N17: Ensaio de solda pendente: dinamômetro em calibração. Feito em 21/05, conforme. | Q17: =IF(C17="","",IF(I17="","Falta a decisão",IF(OR(LEFT(H17,5)="Falta",LEFT(H17,5)="Feita"),H17,IF(AND(F17<E17,I17="Liberado"),"Liberado com verificação pendente",IF(AND(I17="Liberado com autorização",K17=""),"Falta quem autorizou",IF(AND(N(G17)>0,M17=""),"Desvio sem registro de não conforme",IF(AND(I17="Retido",M17=""),"Retido sem registro de não conforme",IF(AND(I17<>"Retido",J17=""),"Falta quem liberou","OK")))))))) -> OK
B18: 46527 | C18: Lote 140 | D18: 2 bobinas, 600 kg | E18: 12 | F18: 12 | G18: 2 | H18: =IF(C18="","",IF(OR(E18="",F18=""),"Falta o número de verificações",IF(F18>E18,"Feitas acima das previstas",IF(F18<E18,"Verificação pendente",IF(N(G18)>0,"Com desvio","Conforme"))))) -> Com desvio | I18: Retido | J18: Analista da Qualidade | M18: 2027-21 | N18: Espessura acima do critério nas duas bobinas. Retido em 20/05; liberado em 21/05, com a concessão do cliente B. | Q18: =IF(C18="","",IF(I18="","Falta a decisão",IF(OR(LEFT(H18,5)="Falta",LEFT(H18,5)="Feita"),H18,IF(AND(F18<E18,I18="Liberado"),"Liberado com verificação pendente",IF(AND(I18="Liberado com autorização",K18=""),"Falta quem autorizou",IF(AND(N(G18)>0,M18=""),"Desvio sem registro de não conforme",IF(AND(I18="Retido",M18=""),"Retido sem registro de não conforme",IF(AND(I18<>"Retido",J18=""),"Falta quem liberou","OK")))))))) -> OK
B19: 46528 | C19: Lote 141 | D19: 4 bobinas, 1.205 kg | E19: 12 | F19: 12 | G19: 0 | H19: =IF(C19="","",IF(OR(E19="",F19=""),"Falta o número de verificações",IF(F19>E19,"Feitas acima das previstas",IF(F19<E19,"Verificação pendente",IF(N(G19)>0,"Com desvio","Conforme"))))) -> Conforme | I19: Liberado | J19: Analista da Qualidade | Q19: =IF(C19="","",IF(I19="","Falta a decisão",IF(OR(LEFT(H19,5)="Falta",LEFT(H19,5)="Feita"),H19,IF(AND(F19<E19,I19="Liberado"),"Liberado com verificação pendente",IF(AND(I19="Liberado com autorização",K19=""),"Falta quem autorizou",IF(AND(N(G19)>0,M19=""),"Desvio sem registro de não conforme",IF(AND(I19="Retido",M19=""),"Retido sem registro de não conforme",IF(AND(I19<>"Retido",J19=""),"Falta quem liberou","OK")))))))) -> OK
B20: 46531 | C20: Lote 142 | D20: 4 bobinas, 1.215 kg | E20: 12 | F20: 11 | G20: 0 | H20: =IF(C20="","",IF(OR(E20="",F20=""),"Falta o número de verificações",IF(F20>E20,"Feitas acima das previstas",IF(F20<E20,"Verificação pendente",IF(N(G20)>0,"Com desvio","Conforme"))))) -> Verificação pendente | I20: Liberado | J20: Analista da Qualidade | N20: Ensaio de solda na fila do laboratório. Lote embarcado no mesmo dia. | Q20: =IF(C20="","",IF(I20="","Falta a decisão",IF(OR(LEFT(H20,5)="Falta",LEFT(H20,5)="Feita"),H20,IF(AND(F20<E20,I20="Liberado"),"Liberado com verificação pendente",IF(AND(I20="Liberado com autorização",K20=""),"Falta quem autorizou",IF(AND(N(G20)>0,M20=""),"Desvio sem registro de não conforme",IF(AND(I20="Retido",M20=""),"Retido sem registro de não conforme",IF(AND(I20<>"Retido",J20=""),"Falta quem liberou","OK")))))))) -> Liberado com verificação pendente
B21: 46533 | C21: Lote 143 | D21: 4 bobinas, 1.200 kg | E21: 12 | F21: 12 | G21: 1 | H21: =IF(C21="","",IF(OR(E21="",F21=""),"Falta o número de verificações",IF(F21>E21,"Feitas acima das previstas",IF(F21<E21,"Verificação pendente",IF(N(G21)>0,"Com desvio","Conforme"))))) -> Com desvio | I21: Liberado | J21: Analista da Qualidade | M21: 2027-24 | N21: Bobina 1 segregada para refilar. | Q21: =IF(C21="","",IF(I21="","Falta a decisão",IF(OR(LEFT(H21,5)="Falta",LEFT(H21,5)="Feita"),H21,IF(AND(F21<E21,I21="Liberado"),"Liberado com verificação pendente",IF(AND(I21="Liberado com autorização",K21=""),"Falta quem autorizou",IF(AND(N(G21)>0,M21=""),"Desvio sem registro de não conforme",IF(AND(I21="Retido",M21=""),"Retido sem registro de não conforme",IF(AND(I21<>"Retido",J21=""),"Falta quem liberou","OK")))))))) -> OK
B23: Produto não conforme
