Workbook

Sheet Instruções
B1: Não conformidade e ação corretiva — Como usar esta planilha
B2: Modelo para registrar a não conformidade, planejar as ações e verificar a eficácia.
B4: Legenda: onde preencher
B5: Amarelo-claro | C5: Células de entrada. É aqui que você digita.
B6: Cinza | C6: Células calculadas ou fixas (rótulos, contagens, avisos). Não altere.
B7: Cinza em itálico | C7: Linha de exemplo (marcada com “Ex.”). Mostra o formato esperado e não entra nas contagens.
B8: Listas suspensas | C8: Colunas de origem, etapa, tipo, status e momento aceitam apenas as opções da lista. Datas e números são conferidos na digitação.
B9: Comentários | C9: Células com triângulo vermelho no canto trazem uma dica de preenchimento. Passe o mouse sobre elas.
B11: Os três conceitos
B12: Não conformidade | C12: O não atendimento de um requisito. É descrita com requisito, evidência e declaração.
B13: Correção | C13: Ação para eliminar a não conformidade encontrada. Trata o efeito: o que já saiu errado.
B14: Ação corretiva | C14: Ação para eliminar a causa da não conformidade e evitar que ela se repita. Depende da análise da causa.
B16: Ordem recomendada de preenchimento
B17: Passo 1 | C17: Aba Controle: inclua a não conformidade na lista, com a origem, o processo e o responsável.
B18: Passo 2 | C18: Aba Registro: descreva a não conformidade e registre a correção e o que foi feito pelo cliente afetado.
B19: Passo 3 | C19: Aba Registro: verifique a abrangência e registre a decisão sobre a ação corretiva.
B20: Passo 4 | C20: Aba Registro: preencha os porquês, com a forma de confirmação de cada resposta, e a causa raiz.
B21: Passo 5 | C21: Aba Plano de ação: escreva as correções e uma ação corretiva para cada causa confirmada.
B22: Passo 6 | C22: Aba Eficácia: defina o indicador, a meta e o critério antes de implantar as ações. Depois, registre as medições.
B23: Passo 7 | C23: Aba Checklist: valide o tratamento. Abas Registro e Controle: registre o encerramento.
B25: Abas da planilha
B26: Controle | C26: Lista de todas as não conformidades, com situação, tempo de encerramento e gráfico por origem.
B27: Registro | C27: Formulário de uma não conformidade: descrição, correção, abrangência, decisão, causa e encerramento.
B28: Plano de ação | C28: Correções e ações corretivas, com causa tratada, responsável, prazo, status e evidência.
B29: Eficácia | C29: Indicador, meta, critério e medições, com a conclusão sobre a eficácia e o gráfico.
B30: Checklist | C30: Doze verificações de qualidade do tratamento, com percentual de conclusão.
B31: Exemplo 1 - Pizzaria | C31: Tratamento de uma não conformidade de auditoria, com padrões da própria organização.
B32: Exemplo 2 - Compras | C32: Tratamento de uma não conformidade de auditoria, com procedimento interno e indicador mensal.
B34: Regras e premissas do modelo
B35: Um registro por vez | C35: As abas Registro, Plano de ação e Eficácia servem a uma não conformidade. Para a seguinte, salve uma cópia do arquivo ou duplique as três abas. A aba Controle reúne todas.
B36: Situação | C36: Uma não conformidade ou uma ação é considerada atrasada quando o prazo é anterior à data de hoje e ela ainda não foi concluída.
B37: Eficácia | C37: A ação é considerada eficaz quando os últimos períodos medidos depois das ações ficam dentro da meta, na quantidade definida no critério, e a não conformidade não voltou.
B38: Medições | C38: Preencha as medições em sequência, sem pular linhas. O modelo lê a última linha preenchida para concluir.
B39: Conferência | C39: As conferências apontam campos vazios. Elas não avaliam a qualidade do texto: uma causa mal definida passa pela conferência.
B40: Exemplos | C40: Os dados das abas de exemplo são ilustrativos, criados para este material.

Sheet Controle
B1: Controle de não conformidades
B2: Uma linha por não conformidade. Preencha as células em amarelo-claro.
B4: Organização ou unidade | G4: Responsável pelo controle
B5: Período | G5: Atualizado em
B7: Nº | C7: Aberta em | D7: Origem | E7: Processo | F7: Descrição resumida | G7: Ação corretiva? | H7: Responsável | I7: Prazo | J7: Etapa atual | K7: Encerrada em | L7: Reincidente? | M7: Dias em aberto | N7: Situação
C8: Data | D8: De onde veio | E8: Onde ocorreu | F8: A declaração, em uma frase | G8: Sim ou Não | H8: Do tratamento | I8: Das ações | J8: Do tratamento | K8: Data | L8: Já tinha sido tratada? | M8: Calculado | N8: Calculada
B9: Ex. | C9: 46287 | D9: Auditoria interna | E9: Requisição de compra | F9: Requisições de compra são aceitas sem a especificação técnica exigida pelo procedimento. | G9: Sim | H9: Gerente de Suprimentos | I9: 46318 | J9: Ação em implantação | L9: Não | M9: 7 | N9: No prazo
B10: 1 | M10: =IF(C10="","",IF(K10<>"",K10-C10,TODAY()-C10)) | N10: =IF(C10="","",IF(OR(J10="Encerrada",K10<>""),IF(K10="","Falta a data",IF(J10="Encerrada","Encerrada","Confira a etapa")),IF(I10="","Sem prazo",IF(I10<TODAY(),"Atrasada","No prazo"))))
B11: 2 | M11: =IF(C11="","",IF(K11<>"",K11-C11,TODAY()-C11)) | N11: =IF(C11="","",IF(OR(J11="Encerrada",K11<>""),IF(K11="","Falta a data",IF(J11="Encerrada","Encerrada","Confira a etapa")),IF(I11="","Sem prazo",IF(I11<TODAY(),"Atrasada","No prazo"))))
B12: 3 | M12: =IF(C12="","",IF(K12<>"",K12-C12,TODAY()-C12)) | N12: =IF(C12="","",IF(OR(J12="Encerrada",K12<>""),IF(K12="","Falta a data",IF(J12="Encerrada","Encerrada","Confira a etapa")),IF(I12="","Sem prazo",IF(I12<TODAY(),"Atrasada","No prazo"))))
B13: 4 | M13: =IF(C13="","",IF(K13<>"",K13-C13,TODAY()-C13)) | N13: =IF(C13="","",IF(OR(J13="Encerrada",K13<>""),IF(K13="","Falta a data",IF(J13="Encerrada","Encerrada","Confira a etapa")),IF(I13="","Sem prazo",IF(I13<TODAY(),"Atrasada","No prazo"))))
B14: 5 | M14: =IF(C14="","",IF(K14<>"",K14-C14,TODAY()-C14)) | N14: =IF(C14="","",IF(OR(J14="Encerrada",K14<>""),IF(K14="","Falta a data",IF(J14="Encerrada","Encerrada","Confira a etapa")),IF(I14="","Sem prazo",IF(I14<TODAY(),"Atrasada","No prazo"))))
B15: 6 | M15: =IF(C15="","",IF(K15<>"",K15-C15,TODAY()-C15)) | N15: =IF(C15="","",IF(OR(J15="Encerrada",K15<>""),IF(K15="","Falta a data",IF(J15="Encerrada","Encerrada","Confira a etapa")),IF(I15="","Sem prazo",IF(I15<TODAY(),"Atrasada","No prazo"))))
B16: 7 | M16: =IF(C16="","",IF(K16<>"",K16-C16,TODAY()-C16)) | N16: =IF(C16="","",IF(OR(J16="Encerrada",K16<>""),IF(K16="","Falta a data",IF(J16="Encerrada","Encerrada","Confira a etapa")),IF(I16="","Sem prazo",IF(I16<TODAY(),"Atrasada","No prazo"))))
B17: 8 | M17: =IF(C17="","",IF(K17<>"",K17-C17,TODAY()-C17)) | N17: =IF(C17="","",IF(OR(J17="Encerrada",K17<>""),IF(K17="","Falta a data",IF(J17="Encerrada","Encerrada","Confira a etapa")),IF(I17="","Sem prazo",IF(I17<TODAY(),"Atrasada","No prazo"))))
B18: 9 | M18: =IF(C18="","",IF(K18<>"",K18-C18,TODAY()-C18)) | N18: =IF(C18="","",IF(OR(J18="Encerrada",K18<>""),IF(K18="","Falta a data",IF(J18="Encerrada","Encerrada","Confira a etapa")),IF(I18="","Sem prazo",IF(I18<TODAY(),"Atrasada","No prazo"))))
B19: 10 | M19: =IF(C19="","",IF(K19<>"",K19-C19,TODAY()-C19)) | N19: =IF(C19="","",IF(OR(J19="Encerrada",K19<>""),IF(K19="","Falta a data",IF(J19="Encerrada","Encerrada","Confira a etapa")),IF(I19="","Sem prazo",IF(I19<TODAY(),"Atrasada","No prazo"))))
B20: 11 | M20: =IF(C20="","",IF(K20<>"",K20-C20,TODAY()-C20)) | N20: =IF(C20="","",IF(OR(J20="Encerrada",K20<>""),IF(K20="","Falta a data",IF(J20="Encerrada","Encerrada","Confira a etapa")),IF(I20="","Sem prazo",IF(I20<TODAY(),"Atrasada","No prazo"))))
B21: 12 | M21: =IF(C21="","",IF(K21<>"",K21-C21,TODAY()-C21)) | N21: =IF(C21="","",IF(OR(J21="Encerrada",K21<>""),IF(K21="","Falta a data",IF(J21="Encerrada","Encerrada","Confira a etapa")),IF(I21="","Sem prazo",IF(I21<TODAY(),"Atrasada","No prazo"))))
... B29: 20 | M29: =IF(C29="","",IF(K29<>"",K29-C29,TODAY()-C29)) | N29: =IF(C29="","",IF(OR(J29="Encerrada",K29<>""),IF(K29="","Falta a data",IF(J29="Encerrada","Encerrada","Confira a etapa")),IF(I29="","Sem prazo",IF(I29<TODAY(),"Atrasada","No prazo"))))
B31: Resumo automático
B32: Não conformidades registradas | G32: =COUNT(C10:C29) -> 0 | J32: Origem | M32: Registros
B33: Encerradas | G33: =COUNTIF(N10:N29,"Encerrada") -> 0 | J33: Auditoria interna | M33: =COUNTIF(D10:D29,"Auditoria interna") -> 0
B34: Em aberto | G34: =G32-G33 -> 0 | J34: Auditoria externa | M34: =COUNTIF(D10:D29,"Auditoria externa") -> 0
B35: Atrasadas | G35: =COUNTIF(N10:N29,"Atrasada") -> 0 | J35: Reclamação de cliente | M35: =COUNTIF(D10:D29,"Reclamação de cliente") -> 0
B36: Tempo médio de encerramento, em dias | G36: =IF(G33=0,"",AVERAGEIF(N10:N29,"Encerrada",M10:M29)) | J36: Produto ou serviço não conforme | M36: =COUNTIF(D10:D29,"Produto ou serviço não conforme") -> 0
B37: Com ação corretiva | G37: =COUNTIF(G10:G29,"Sim") -> 0 | J37: Fornecedor | M37: =COUNTIF(D10:D29,"Fornecedor") -> 0
B38: Reincidentes | G38: =COUNTIF(L10:L29,"Sim") -> 0 | J38: Indicador fora da meta | M38: =COUNTIF(D10:D29,"Indicador fora da meta") -> 0
B39: Aviso | G39: =IF(G32=0,"Registre as não conformidades",IF(COUNTIF(N10:N29,"Falta a data")>0,"Há registro encerrado sem data",IF(COUNTIF(N10:N29,"Confira a etapa")>0,"Há registro com data de encerramento e etapa em aberto",IF(SUMPRODUCT((C10:C29<>"")*(H10:H29=""))>0,"Há registro sem responsável",IF(G35>0,"Há não conformidade atrasada","OK"))))) -> Registre as não conformidades | J39: Outra | M39: =COUNTIF(D10:D29,"Outra") -> 0

Sheet Registro
B1: Registro de não conformidade
B2: Um registro por não conformidade. Preencha os blocos na ordem.
B4: Registro nº | E4: Data de abertura
B5: Origem | E5: Processo
B6: Registrado por | E6: Responsável
B8: 1. Descrição da não conformidade
B9: Requisito
B10: Evidência
B11: Declaração
B13: 2. Correção e consequências
B14: # | C14: O que foi feito para corrigir e conter | E14: Responsável | F14: Data | G14: Status
B15: 1
B16: 2
B17: 3
B18: 4
B19: Consequências tratadas
B21: 3. Abrangência e decisão
B22: A falha existe em outro lugar? | E22: Ação corretiva necessária?
B23: O que foi verificado
B24: Justificativa da decisão
B26: 4. Análise da causa
B27: # | C27: Pergunta | D27: Resposta | F27: Como foi confirmada
B28: 1
B29: 2 | C29: Por quê?
B30: 3 | C30: Por quê?
B31: 4 | C31: Por quê?
B32: 5 | C32: Por quê?
B33: Causa raiz
B35: 5. Encerramento
B36: Mudanças no sistema de gestão
B37: Riscos atualizados? | E37: Data de encerramento
B38: Aprovado por | E38: Eficácia (aba Eficácia) | F38: =IF(LEFT(Eficácia!E29,6)="Eficaz","Eficaz",IF(LEFT(Eficácia!E29,3)="Não","Não eficaz","Não comprovada")) -> Não comprovada
B40: Conferência automática
B41: 1. Descrição | D41: =IF(COUNTA(D9:D11)=3,"Completa","Falta "&IF(D9="","o requisito",IF(D10="","a evidência","a declaração"))) -> Falta o requisito
B42: 2. Correção | D42: =IF(COUNTA(C15:C18)=0,"Registre a correção",IF(SUMPRODUCT((C15:C18<>"")*(((E15:E18="")+(F15:F18=""))>0))>0,"Há correção sem responsável ou sem data",IF(COUNTIF(G15:G18,"Pendente")>0,"Há correção pendente","Completa"))) -> Registre a correção
B43: 3. Abrangência e decisão | D43: =IF(D22="","Informe se a falha existe em outro lugar",IF(D22="Não verificado","Verifique a abrangência",IF(F22="","Registre a decisão",IF(D24="","Justifique a decisão","Completa")))) -> Informe se a falha existe em outro lugar
B44: 4. Análise da causa | D44: =IF(F22="Não","Não se aplica",IF(COUNTA(D28:D32)<2,"Responda a pelo menos dois porquês",IF(COUNTA(F28:F32)<COUNTA(D28:D32),"Há resposta sem confirmação",IF(D33="","Escreva a causa raiz","Completa")))) -> Responda a pelo menos dois porquês
B45: 5. Encerramento | D45: =IF(F37="","Em aberto",IF(AND(F22="Sim",F38<>"Eficaz"),"Encerrado sem eficácia comprovada","Encerrado")) -> Em aberto
B46: Situação do registro | D46: =IF(COUNTA(D9:D11,C15:C18,D22,F22)=0,"Registro em branco",IF(SUMPRODUCT((D41:D44<>"Completa")*(D41:D44<>"Não se aplica"))>0,"Há blocos incompletos",IF(F22="Não","Registro completo: só correção","Pronto para o plano de ação"))) -> Registro em branco

Sheet Plano de ação
B1: Plano de ação
B2: Registre as correções e as ações corretivas. Cada ação corretiva trata uma causa confirmada.
B4: Registro nº | D4: =IF(Registro!D4="","",Registro!D4) | E4: Não conformidade | F4: =IF(Registro!D11="","",Registro!D11)
B6: # | C6: Tipo | D6: O que será feito | E6: Causa tratada | F6: Responsável | G6: Prazo | H6: Status | I6: Concluída em | J6: Evidência de implantação | K6: Conferência | L6: Situação
C7: Efeito ou causa | D7: Verbo no infinitivo e resultado esperado | E7: Só para ação corretiva | F7: Cargo ou nome | G7: Data | H7: Da ação | I7: Data | J7: Documento, registro ou teste | K7: Campos da linha | L7: Calculada
B8: Ex. | C8: Ação corretiva | D8: Tornar obrigatório o campo de especificação, com bloqueio do envio da requisição incompleta. | E8: O campo de especificação é opcional. | F8: Analista de sistemas | G8: 46311 | H8: Concluída | I8: 46309 | J8: Chamado 4471 encerrado. Teste com 5 requisições. | K8: Completa | L8: Concluída
B9: 1 | K9: =IF(C9="","",IF(D9="","Falta a ação",IF(AND(C9="Ação corretiva",E9=""),"Falta a causa tratada",IF(OR(F9="",G9=""),"Falta responsável ou prazo",IF(AND(H9="Concluída",J9=""),"Falta a evidência","Completa"))))) | L9: =IF(C9="","",IF(H9="Concluída","Concluída",IF(H9="Cancelada","Cancelada",IF(G9="","Sem prazo",IF(G9<TODAY(),"Atrasada","No prazo")))))
B10: 2 | K10: =IF(C10="","",IF(D10="","Falta a ação",IF(AND(C10="Ação corretiva",E10=""),"Falta a causa tratada",IF(OR(F10="",G10=""),"Falta responsável ou prazo",IF(AND(H10="Concluída",J10=""),"Falta a evidência","Completa"))))) | L10: =IF(C10="","",IF(H10="Concluída","Concluída",IF(H10="Cancelada","Cancelada",IF(G10="","Sem prazo",IF(G10<TODAY(),"Atrasada","No prazo")))))
B11: 3 | K11: =IF(C11="","",IF(D11="","Falta a ação",IF(AND(C11="Ação corretiva",E11=""),"Falta a causa tratada",IF(OR(F11="",G11=""),"Falta responsável ou prazo",IF(AND(H11="Concluída",J11=""),"Falta a evidência","Completa"))))) | L11: =IF(C11="","",IF(H11="Concluída","Concluída",IF(H11="Cancelada","Cancelada",IF(G11="","Sem prazo",IF(G11<TODAY(),"Atrasada","No prazo")))))
B12: 4 | K12: =IF(C12="","",IF(D12="","Falta a ação",IF(AND(C12="Ação corretiva",E12=""),"Falta a causa tratada",IF(OR(F12="",G12=""),"Falta responsável ou prazo",IF(AND(H12="Concluída",J12=""),"Falta a evidência","Completa"))))) | L12: =IF(C12="","",IF(H12="Concluída","Concluída",IF(H12="Cancelada","Cancelada",IF(G12="","Sem prazo",IF(G12<TODAY(),"Atrasada","No prazo")))))
B13: 5 | K13: =IF(C13="","",IF(D13="","Falta a ação",IF(AND(C13="Ação corretiva",E13=""),"Falta a causa tratada",IF(OR(F13="",G13=""),"Falta responsável ou prazo",IF(AND(H13="Concluída",J13=""),"Falta a evidência","Completa"))))) | L13: =IF(C13="","",IF(H13="Concluída","Concluída",IF(H13="Cancelada","Cancelada",IF(G13="","Sem prazo",IF(G13<TODAY(),"Atrasada","No prazo")))))
B14: 6 | K14: =IF(C14="","",IF(D14="","Falta a ação",IF(AND(C14="Ação corretiva",E14=""),"Falta a causa tratada",IF(OR(F14="",G14=""),"Falta responsável ou prazo",IF(AND(H14="Concluída",J14=""),"Falta a evidência","Completa"))))) | L14: =IF(C14="","",IF(H14="Concluída","Concluída",IF(H14="Cancelada","Cancelada",IF(G14="","Sem prazo",IF(G14<TODAY(),"Atrasada","No prazo")))))
B15: 7 | K15: =IF(C15="","",IF(D15="","Falta a ação",IF(AND(C15="Ação corretiva",E15=""),"Falta a causa tratada",IF(OR(F15="",G15=""),"Falta responsável ou prazo",IF(AND(H15="Concluída",J15=""),"Falta a evidência","Completa"))))) | L15: =IF(C15="","",IF(H15="Concluída","Concluída",IF(H15="Cancelada","Cancelada",IF(G15="","Sem prazo",IF(G15<TODAY(),"Atrasada","No prazo")))))
B16: 8 | K16: =IF(C16="","",IF(D16="","Falta a ação",IF(AND(C16="Ação corretiva",E16=""),"Falta a causa tratada",IF(OR(F16="",G16=""),"Falta responsável ou prazo",IF(AND(H16="Concluída",J16=""),"Falta a evidência","Completa"))))) | L16: =IF(C16="","",IF(H16="Concluída","Concluída",IF(H16="Cancelada","Cancelada",IF(G16="","Sem prazo",IF(G16<TODAY(),"Atrasada","No prazo")))))
B17: 9 | K17: =IF(C17="","",IF(D17="","Falta a ação",IF(AND(C17="Ação corretiva",E17=""),"Falta a causa tratada",IF(OR(F17="",G17=""),"Falta responsável ou prazo",IF(AND(H17="Concluída",J17=""),"Falta a evidência","Completa"))))) | L17: =IF(C17="","",IF(H17="Concluída","Concluída",IF(H17="Cancelada","Cancelada",IF(G17="","Sem prazo",IF(G17<TODAY(),"Atrasada","No prazo")))))
B18: 10 | K18: =IF(C18="","",IF(D18="","Falta a ação",IF(AND(C18="Ação corretiva",E18=""),"Falta a causa tratada",IF(OR(F18="",G18=""),"Falta responsável ou prazo",IF(AND(H18="Concluída",J18=""),"Falta a evidência","Completa"))))) | L18: =IF(C18="","",IF(H18="Concluída","Concluída",IF(H18="Cancelada","Cancelada",IF(G18="","Sem prazo",IF(G18<TODAY(),"Atrasada","No prazo")))))
B19: 11 | K19: =IF(C19="","",IF(D19="","Falta a ação",IF(AND(C19="Ação corretiva",E19=""),"Falta a causa tratada",IF(OR(F19="",G19=""),"Falta responsável ou prazo",IF(AND(H19="Concluída",J19=""),"Falta a evidência","Completa"))))) | L19: =IF(C19="","",IF(H19="Concluída","Concluída",IF(H19="Cancelada","Cancelada",IF(G19="","Sem prazo",IF(G19<TODAY(),"Atrasada","No prazo")))))
B20: 12 | K20: =IF(C20="","",IF(D20="","Falta a ação",IF(AND(C20="Ação corretiva",E20=""),"Falta a causa tratada",IF(OR(F20="",G20=""),"Falta responsável ou prazo",IF(AND(H20="Concluída",J20=""),"Falta a evidência","Completa"))))) | L20: =IF(C20="","",IF(H20="Concluída","Concluída",IF(H20="Cancelada","Cancelada",IF(G20="","Sem prazo",IF(G20<TODAY(),"Atrasada","No prazo")))))
B22: Resumo automático
B23: Ações registradas | E23: =COUNTA(C9:C20) -> 0
B24: Correções | E24: =COUNTIF(C9:C20,"Correção") -> 0
B25: Ações corretivas | E25: =COUNTIF(C9:C20,"Ação corretiva") -> 0
B26: Concluídas | E26: =COUNTIF(L9:L20,"Concluída") -> 0
B27: Atrasadas | E27: =COUNTIF(L9:L20,"Atrasada") -> 0
B28: Percentual concluído | E28: =IF(E23-COUNTIF(L9:L20,"Cancelada")<=0,0,E26/(E23-COUNTIF(L9:L20,"Cancelada"))) -> 0
B29: Aviso | E29: =IF(E23=0,"Registre as ações",IF(AND(Registro!F22="Sim",E25=0),"A decisão pede ação corretiva, e nenhuma foi registrada",IF(COUNTIF(K9:K20,"Falta*")>0,"Há ação incompleta: veja a coluna Conferência",IF(E27>0,"Há ação atrasada","OK")))) -> Registre as ações

Sheet Eficácia
B1: Verificação da eficácia
B2: Defina o indicador, a meta e o critério antes de implantar as ações. Depois, registre as medições.
B4: Indicador | J4: Unidade
B5: Método de medição | J5: Verificado por
B6: Sentido | F6: Meta | J6: Data da verificação
B7: Critério: períodos seguidos na meta | F7: A falha voltou? | J7: Registro nº | L7: =IF(Registro!D4="","",Registro!D4)
B9: # | C9: Período | D9: Momento | E9: Valor | F9: Meta | G9: Dentro da meta? | H9: Seguidos na meta
B10: Ex. | C10: Nov/2026 | D10: Depois | E10: 4 | F10: 5 | G10: Sim | H10: 1
B11: 1 | F11: =IF(OR(E11="",$G$6=""),"",$G$6) | G11: =IF(OR(E11="",$G$6=""),"",IF($D$6="Maior é melhor",IF(E11>=$G$6,"Sim","Não"),IF(E11<=$G$6,"Sim","Não"))) | H11: =IF(OR(E11="",D11<>"Depois"),"",IF(G11="Sim",1,0))
B12: 2 | F12: =IF(OR(E12="",$G$6=""),"",$G$6) | G12: =IF(OR(E12="",$G$6=""),"",IF($D$6="Maior é melhor",IF(E12>=$G$6,"Sim","Não"),IF(E12<=$G$6,"Sim","Não"))) | H12: =IF(OR(E12="",D12<>"Depois"),"",IF(G12="Sim",N(H11)+1,0))
B13: 3 | F13: =IF(OR(E13="",$G$6=""),"",$G$6) | G13: =IF(OR(E13="",$G$6=""),"",IF($D$6="Maior é melhor",IF(E13>=$G$6,"Sim","Não"),IF(E13<=$G$6,"Sim","Não"))) | H13: =IF(OR(E13="",D13<>"Depois"),"",IF(G13="Sim",N(H12)+1,0))
B14: 4 | F14: =IF(OR(E14="",$G$6=""),"",$G$6) | G14: =IF(OR(E14="",$G$6=""),"",IF($D$6="Maior é melhor",IF(E14>=$G$6,"Sim","Não"),IF(E14<=$G$6,"Sim","Não"))) | H14: =IF(OR(E14="",D14<>"Depois"),"",IF(G14="Sim",N(H13)+1,0))
B15: 5 | F15: =IF(OR(E15="",$G$6=""),"",$G$6) | G15: =IF(OR(E15="",$G$6=""),"",IF($D$6="Maior é melhor",IF(E15>=$G$6,"Sim","Não"),IF(E15<=$G$6,"Sim","Não"))) | H15: =IF(OR(E15="",D15<>"Depois"),"",IF(G15="Sim",N(H14)+1,0))
B16: 6 | F16: =IF(OR(E16="",$G$6=""),"",$G$6) | G16: =IF(OR(E16="",$G$6=""),"",IF($D$6="Maior é melhor",IF(E16>=$G$6,"Sim","Não"),IF(E16<=$G$6,"Sim","Não"))) | H16: =IF(OR(E16="",D16<>"Depois"),"",IF(G16="Sim",N(H15)+1,0))
B17: 7 | F17: =IF(OR(E17="",$G$6=""),"",$G$6) | G17: =IF(OR(E17="",$G$6=""),"",IF($D$6="Maior é melhor",IF(E17>=$G$6,"Sim","Não"),IF(E17<=$G$6,"Sim","Não"))) | H17: =IF(OR(E17="",D17<>"Depois"),"",IF(G17="Sim",N(H16)+1,0))
B18: 8 | F18: =IF(OR(E18="",$G$6=""),"",$G$6) | G18: =IF(OR(E18="",$G$6=""),"",IF($D$6="Maior é melhor",IF(E18>=$G$6,"Sim","Não"),IF(E18<=$G$6,"Sim","Não"))) | H18: =IF(OR(E18="",D18<>"Depois"),"",IF(G18="Sim",N(H17)+1,0))
B19: 9 | F19: =IF(OR(E19="",$G$6=""),"",$G$6) | G19: =IF(OR(E19="",$G$6=""),"",IF($D$6="Maior é melhor",IF(E19>=$G$6,"Sim","Não"),IF(E19<=$G$6,"Sim","Não"))) | H19: =IF(OR(E19="",D19<>"Depois"),"",IF(G19="Sim",N(H18)+1,0))
B20: 10 | F20: =IF(OR(E20="",$G$6=""),"",$G$6) | G20: =IF(OR(E20="",$G$6=""),"",IF($D$6="Maior é melhor",IF(E20>=$G$6,"Sim","Não"),IF(E20<=$G$6,"Sim","Não"))) | H20: =IF(OR(E20="",D20<>"Depois"),"",IF(G20="Sim",N(H19)+1,0))
B21: 11 | F21: =IF(OR(E21="",$G$6=""),"",$G$6) | G21: =IF(OR(E21="",$G$6=""),"",IF($D$6="Maior é melhor",IF(E21>=$G$6,"Sim","Não"),IF(E21<=$G$6,"Sim","Não"))) | H21: =IF(OR(E21="",D21<>"Depois"),"",IF(G21="Sim",N(H20)+1,0))
B22: 12 | F22: =IF(OR(E22="",$G$6=""),"",$G$6) | G22: =IF(OR(E22="",$G$6=""),"",IF($D$6="Maior é melhor",IF(E22>=$G$6,"Sim","Não"),IF(E22<=$G$6,"Sim","Não"))) | H22: =IF(OR(E22="",D22<>"Depois"),"",IF(G22="Sim",N(H21)+1,0))
B24: Resumo automático
B25: Medições antes das ações | E25: =SUMPRODUCT((D11:D22="Antes")*(E11:E22<>"")) -> 0
B26: Média antes | E26: =IF(E25=0,"",AVERAGEIF(D11:D22,"Antes",E11:E22))
B27: Medições depois das ações | E27: =SUMPRODUCT((D11:D22="Depois")*(E11:E22<>"")) -> 0
B28: Média depois | E28: =IF(E27=0,"",AVERAGEIF(D11:D22,"Depois",E11:E22))
B29: Conclusão | E29: =IF(E27=0,"Sem medição depois das ações",IF($G$7="Sim","Não eficaz: a falha voltou. Refaça a análise da causa",IF(OR($G$6="",$D$7=""),"Informe a meta e o critério",IF(N(INDEX(H11:H22,MAX(1,COUNT(E11:E22))))>=$D$7,"Eficaz: encerre e padronize",IF(AND(E27>=$D$7,INDEX(G11:G22,MAX(1,COUNT(E11:E22)))="Não"),IF(AND(E25>0,IF($D$6="Maior é melhor",E28>E26,E28<E26)),"Parcial: melhorou, mas não atingiu a meta. Complete as ações","Não eficaz: meta não atingida. Refaça a análise da causa"),IF($D$7-N(INDEX(H11:H22,MAX(1,COUNT(E11:E22))))=1,"Em observação: falta 1 período seguido na meta","Em observação: faltam "&($D$7-N(INDEX(H11:H22,MAX(1,COUNT(E11:E22)))))&" períodos seguidos na meta")))))) -> Sem medição depois das ações
B30: Aviso | E30: =IF(COUNT(E11:E22)=0,"Registre as medições",IF(COUNTBLANK(INDEX(E11:E22,1):INDEX(E11:E22,COUNT(E11:E22)))>0,"Preencha as medições em sequência, sem pular linhas",IF(SUMPRODUCT((E11:E22<>"")*(D11:D22=""))>0,"Há medição sem o momento",IF(OR($G$6="",$D$7="",$D$6=""),"Informe o sentido, a meta e o critério",IF($G$7="","Informe se a falha voltou","OK"))))) -> Registre as medições

Sheet Checklist
B1: Checklist de validação do tratamento
B2: Escolha o status de cada item na lista suspensa (coluna em amarelo-claro).
B4: # | C4: Item de verificação | D4: Status | E4: Observações
B5: 1 | C5: A não conformidade está descrita com requisito, evidência e declaração.
B6: 2 | C6: A correção foi feita e registrada, com data e responsável.
B7: 3 | C7: As consequências para o cliente foram tratadas.
B8: 4 | C8: A abrangência foi verificada em outros produtos, locais e períodos.
B9: 5 | C9: A decisão sobre a ação corretiva está registrada e justificada.
B10: 6 | C10: A causa foi analisada com quem executa o processo.
B11: 7 | C11: Cada causa foi confirmada com um fato ou um dado.
B12: 8 | C12: Cada ação corretiva trata uma causa confirmada.
B13: 9 | C13: Cada ação tem responsável, prazo e evidência de implantação.
B14: 10 | C14: O indicador, a meta e o período de observação foram definidos antes da implantação.
B15: 11 | C15: A eficácia foi verificada, de preferência por quem não executou as ações.
B16: 12 | C16: Os riscos, os procedimentos e os treinamentos foram atualizados.
B18: Resumo automático
B19: Itens atendidos (Sim) | D19: =COUNTIF(D5:D16,"Sim") -> 0
B20: Itens parciais | D20: =COUNTIF(D5:D16,"Parcial") -> 0
B21: Itens não atendidos | D21: =COUNTIF(D5:D16,"Não") -> 0
B22: Itens sem resposta | D22: =COUNTBLANK(D5:D16) -> 12
B23: Percentual atendido | D23: =D19/ROWS(D5:D16) -> 0
B24: Situação | D24: =IF(D19=ROWS(D5:D16),"Validado",IF(D22>0,"Em andamento","Com pendências")) -> Em andamento

Sheet Exemplo 1 - Pizzaria
B1: Não conformidade e ação corretiva — do registro ao encerramento
B2: Exemplo preenchido, para consulta. Use as abas Registro, Plano de ação e Eficácia para o seu tratamento.
B4: Registro nº | D4: RNC 2026-05
B5: Aberto em | D5: 46290
B6: Origem | D6: Auditoria interna. Auditoria 2026-03, constatação nº 1
B7: Processo | D7: Registro do pedido
B8: Registrado por | D8: Atendente do turno da tarde, auditor líder
B9: Responsável | D9: Atendente líder
B11: 1. Descrição da não conformidade
B12: Requisito | D12: IT-EXP-01 rev. 2, item 2: todo pedido deve ser registrado com o complemento do endereço.
B13: Evidência | D13: Em 10 pedidos recebidos por telefone em 19/09, 6 foram registrados sem complemento.
B14: Declaração | D14: Pedidos recebidos por telefone são registrados sem o complemento do endereço exigido pela instrução.
B16: 2 e 3. Abrangência, consequências e decisão
B17: Abrangência | D17: Site e aplicativo: o campo é obrigatório, e os 20 pedidos da amostra estavam completos. WhatsApp: 3 de 8 pedidos sem complemento, em 26/09. O canal entrou no tratamento.
B18: Consequências | D18: Em setembro, 9 entregas atrasaram por endereço incompleto, com 2 reclamações. Os 2 clientes receberam contato e um cupom de desconto.
B19: Decisão | D19: Ação corretiva necessária. A falha se repete em mais da metade dos pedidos por telefone e atrasa a entrega ao cliente.
B21: 4. Análise da causa
B22: # | C22: Pergunta | E22: Resposta | G22: Como foi confirmada
B23: 1 | C23: Por que os pedidos por telefone ficam sem complemento? | E23: O atendente não pergunta o complemento, e a tela aceita o pedido sem ele. | G23: Observação de 12 atendimentos em 26/09: a pergunta foi feita em 4. Teste na tela do sistema.
B24: 2 | C24: Por que o atendente não pergunta? | E24: O roteiro de atendimento por telefone não traz essa pergunta. | G24: Leitura do roteiro afixado no balcão, de março de 2026.
B25: 3 | C25: Por que o roteiro não traz a pergunta? | E25: O roteiro foi escrito antes da revisão 2 da instrução, de setembro de 2026, e não foi atualizado. | G25: Comparação das datas dos dois documentos.
B26: 4 | C26: Por que o roteiro não foi atualizado? | E26: Quando uma instrução muda, ninguém confere os roteiros, as telas e os formulários ligados a ela. | G26: Entrevista com o gerente: a revisão 2 alterou só a instrução.
B27: Causa raiz | D27: A mudança de uma instrução não leva à revisão dos roteiros, das telas e dos formulários ligados a ela.
B29: 5. Plano de ação
B30: # | C30: Tipo | D30: O que foi feito | E30: Causa tratada | F30: Responsável | G30: Concluída em | H30: Evidência de implantação
B31: 1 | C31: Correção | D31: Ligar para os clientes dos pedidos da noite que estavam sem complemento e completar o endereço antes da saída. | E31: Trata o efeito. | F31: Atendente líder | G31: 46290 | H31: 5 pedidos completados antes da saída.
B32: 2 | C32: Correção | D32: Conferir o endereço de todo pedido por telefone e por WhatsApp antes da saída, até a ação corretiva entrar em vigor. | E32: Trata o efeito. | F32: Líder da expedição | G32: 46291 | H32: Conferência anotada na etiqueta, de 26/09 a 11/10.
B33: 3 | C33: Ação corretiva | D33: Tornar obrigatório o campo de complemento na tela de pedidos por telefone e por WhatsApp, com a opção “casa, sem complemento”. | E33: A tela aceita o pedido sem complemento. | F33: Gerente da loja | G33: 46302 | H33: Tela alterada pelo fornecedor do sistema. Teste com 5 pedidos.
B34: 4 | C34: Ação corretiva | D34: Revisar o roteiro de atendimento, com a pergunta do complemento, e treinar os atendentes dos dois turnos. | E34: O roteiro não traz a pergunta. | F34: Atendente líder | G34: 46303 | H34: Roteiro rev. 2 afixado. Lista de presença com 7 atendentes.
B35: 5 | C35: Ação corretiva | D35: Incluir na rotina de revisão de instruções a conferência dos roteiros, das telas e dos formulários ligados. | E35: A mudança de instrução não leva à revisão dos documentos ligados. | F35: Gerente da loja | G35: 46309 | H35: Rotina de documentos rev. 3, item 4.
B37: 6. Verificação da eficácia
B38: Indicador | D38: Pedidos por telefone e por WhatsApp registrados sem complemento, em percentual.
B39: Método de medição | D39: Amostra de 30 pedidos por semana, escolhida pelo gerente.
B40: Verificado por | D40: Gerente da loja, em 09/11/2026.
B41: Observação | D41: Entregas atrasadas por endereço incompleto: 9 em setembro, nenhuma de 12/10 a 08/11.
B42: Sentido | D42: Menor é melhor | E42: Meta | F42: 5 | G42: Critério | H42: 4
B44: # | C44: Período | D44: Momento | E44: Valor | F44: Meta | G44: Na meta? | H44: Períodos seguidos na meta
B45: 1 | C45: Auditoria, 19/09 | D45: Antes | E45: 60 | F45: =$F$42 -> 5 | G45: =IF($D$42="Maior é melhor",IF(E45>=$F$42,"Sim","Não"),IF(E45<=$F$42,"Sim","Não")) -> Não | H45: =IF(D45<>"Depois","",IF(G45="Sim",1,0))
B46: 2 | C46: Semana de 21/09 | D46: Antes | E46: 57 | F46: =$F$42 -> 5 | G46: =IF($D$42="Maior é melhor",IF(E46>=$F$42,"Sim","Não"),IF(E46<=$F$42,"Sim","Não")) -> Não | H46: =IF(D46<>"Depois","",IF(G46="Sim",N(H45)+1,0))
B47: 3 | C47: Semana de 28/09 | D47: Antes | E47: 53 | F47: =$F$42 -> 5 | G47: =IF($D$42="Maior é melhor",IF(E47>=$F$42,"Sim","Não"),IF(E47<=$F$42,"Sim","Não")) -> Não | H47: =IF(D47<>"Depois","",IF(G47="Sim",N(H46)+1,0))
...

Sheet Exemplo 2 - Compras
B1: Não conformidade e ação corretiva — do registro ao encerramento
B2: Exemplo preenchido, para consulta. Use as abas Registro, Plano de ação e Eficácia para o seu tratamento.
B4: Registro nº | D4: RNC 2026-31
B5: Aberto em | D5: 46287
B6: Origem | D6: Auditoria interna. Auditoria 2026-07, constatação nº 1
B7: Processo | D7: Requisição de compra
B8: Registrado por | D8: Analista da Qualidade, auditor líder
B9: Responsável | D9: Gerente de Suprimentos
B11: 1. Descrição da não conformidade
B12: Requisito | D12: PR-SUP-01 rev. 5, item 4.2: toda requisição deve conter a especificação técnica do item.
B13: Evidência | D13: Requisições RC-0412, RC-0433, RC-0457 e RC-0461 sem especificação técnica, em amostra de 10.
B14: Declaração | D14: Requisições de compra são aceitas sem a especificação técnica exigida pelo procedimento.
B16: 2 e 3. Abrangência, consequências e decisão
B17: Abrangência | D17: Levantamento das 312 requisições de janeiro a agosto: 97 sem especificação técnica, ou 31%. Delas, 58 são da Manutenção, e 71 pedem itens sem cadastro.
B18: Consequências | D18: No período, 7 itens foram devolvidos a fornecedores por serem diferentes do necessário, com atraso médio de 9 dias por devolução.
B19: Decisão | D19: Ação corretiva necessária. A falha atinge quase um terço das requisições e já causou compra de item errado.
B21: 4. Análise da causa
B22: # | C22: Pergunta | E22: Resposta | G22: Como foi confirmada
B23: 1 | C23: Por que as requisições chegam sem especificação técnica? | E23: O campo de especificação do sistema é opcional e de texto livre. | G23: Teste no sistema: a requisição é enviada com o campo vazio.
B24: 2 | C24: Por que o requisitante deixa o campo vazio? | E24: Para itens sem cadastro, ele não sabe o que informar. | G24: 71 das 97 requisições sem especificação pedem itens sem cadastro.
B25: 3 | C25: Por que os itens não têm cadastro com especificação? | E25: Não existe rotina para cadastrar o item antes da primeira compra. | G25: Leitura do PR-SUP-01 e entrevista com 3 requisitantes.
B26: 4 | C26: Por que o comprador aceita a requisição incompleta? | E26: Devolver a requisição atrasa a compra, e o comprador é medido só pelo prazo de atendimento. | G26: Entrevista com os 4 compradores e leitura do indicador da área.
B27: Causa raiz | D27: O processo permite requisitar sem especificação: o campo é opcional, os itens novos não têm cadastro e o indicador do comprador considera só o prazo.
B29: 5. Plano de ação
B30: # | C30: Tipo | D30: O que foi feito | E30: Causa tratada | F30: Responsável | G30: Concluída em | H30: Evidência de implantação
B31: 1 | C31: Correção | D31: Completar a especificação das requisições RC-0412, RC-0433, RC-0457 e RC-0461 com as áreas requisitantes. | E31: Trata o efeito. | F31: Comprador sênior | G31: 46290 | H31: 4 requisições completadas no sistema.
B32: 2 | C32: Correção | D32: Conferir os itens já recebidos dessas requisições contra a necessidade da área. | E32: Trata o efeito. | F32: Líder do Recebimento | G32: 46291 | H32: 3 itens conformes. Rolamento da RC-0457 diferente do necessário: devolvido ao fornecedor.
B33: 3 | C33: Correção | D33: Devolver ao requisitante toda requisição sem especificação, a partir de 23/09. | E33: Trata o efeito. | F33: Compradores | G33: 46288 | H33: Comunicado da gerência, de 23/09.
B34: 4 | C34: Ação corretiva | D34: Tornar obrigatório o campo de especificação, com bloqueio do envio da requisição incompleta. | E34: O campo de especificação é opcional. | F34: Analista de sistemas | G34: 46309 | H34: Chamado 4471 encerrado. Teste com 5 requisições.
B35: 5 | C35: Ação corretiva | D35: Revisar o PR-SUP-01: cadastro do item antes da primeira compra, devolução da requisição incompleta em 1 dia útil e prazo do comprador contado a partir da requisição completa. | E35: Não há rotina de cadastro, e o indicador considera só o prazo. | F35: Gerente de Suprimentos | G35: 46311 | H35: PR-SUP-01 rev. 6 publicado.
B36: 6 | C36: Ação corretiva | D36: Cadastrar a especificação padrão dos 120 itens de manutenção mais comprados. | E36: Itens sem cadastro não têm especificação. | F36: Supervisor de manutenção | G36: 46318 | H36: 120 itens cadastrados, com conferência do comprador sênior.
B37: 7 | C37: Ação corretiva | D37: Treinar os requisitantes das 6 áreas na revisão 6 do procedimento. | E37: O requisitante não sabe o que informar. | F37: Comprador sênior | G37: 46317 | H37: Listas de presença: 31 requisitantes.
B39: 6. Verificação da eficácia
B40: Indicador | D40: Requisições com especificação ausente ou insuficiente, em percentual.
B41: Método de medição | D41: Todas as requisições do mês, na conferência do comprador.
B42: Verificado por | D42: Analista da Qualidade, em 05/02/2027.
B43: Observação | D43: Devoluções a fornecedor por item diferente do necessário: 7 de janeiro a agosto, nenhuma de novembro a janeiro.
B44: Sentido | D44: Menor é melhor | E44: Meta | F44: 5 | G44: Critério | H44: 3
B46: # | C46: Período | D46: Momento | E46: Valor | F46: Meta | G46: Na meta? | H46: Períodos seguidos na meta
B47: 1 | C47: Abr/2026 | D47: Antes | E47: 29 | F47: =$F$44 -> 5 | G47: =IF($D$44="Maior é melhor",IF(E47>=$F$44,"Sim","Não"),IF(E47<=$F$44,"Sim","Não")) -> Não | H47: =IF(D47<>"Depois","",IF(G47="Sim",1,0))
...
