Workbook

Sheet Instruções
B1: Histograma e CEP — Como usar esta planilha
B2: Modelo para o gráfico de média e amplitude, o histograma e a capacidade de uma característica.
B4: Legenda: onde preencher
B5: Amarelo-claro | C5: Células de entrada. É aqui que você digita.
B6: Cinza | C6: Células calculadas ou fixas (médias, amplitudes, fases, sinais, limites, capacidade). Não altere.
B7: Vermelho na medição | C7: A medição está fora da especificação.
B8: Comentários | C8: Células com triângulo vermelho no canto trazem uma dica de preenchimento. Passe o mouse sobre elas.
B10: As regras de cálculo
B11: Média e amplitude | C11: Só com as 5 medições do subgrupo preenchidas.
B12: Fase | C12: Excluído quando marcado para excluir. Base para os primeiros subgrupos, até o número informado. Acompanhamento para os seguintes.
B13: Limites | C13: Calculados só com os subgrupos da base: LC ± 0,577 × R̄ para a média; 2,114 × R̄ para a amplitude; σ = R̄ ÷ 2,326.
B14: Sinais | C14: Na ordem: média fora dos limites; amplitude fora do limite; sete médias seguidas do mesmo lado da linha central; seis médias seguidas subindo ou descendo.
B15: Capacidade | C15: Cp = (LSE − LIE) ÷ 6σ. Cpk = menor distância da LC a um limite ÷ 3σ. Capaz: 1,33 ou mais; No limite: de 1,00 a 1,33; abaixo: não capaz.
B16: Histograma | C16: 12 classes de largura igual a um oitavo da tolerância, a partir de dois oitavos abaixo do LIE. Cada valor entra na classe em que é maior ou igual ao início.
B18: Ordem recomendada de preenchimento
B19: Passo 1 | C19: Aba Dados: a característica, a unidade, o LIE, o LSE e quantos subgrupos formam a base.
B20: Passo 2 | C20: Aba Dados: cada subgrupo com a data, a identificação e as cinco medições.
B21: Passo 3 | C21: Aba Dados: marque Sim em Excluir da base para os subgrupos com causa conhecida, e escreva o motivo.
B22: Passo 4 | C22: Abas Gráficos e Histograma: leia os pontos, os limites e a forma.
B23: Passo 5 | C23: Aba Painel: leia a capacidade e o aviso. Depois, valide na aba Checklist.
B25: Abas da planilha
B26: Dados | C26: Até 30 subgrupos de 5 medições, com os limites calculados no alto.
B27: Gráficos | C27: O gráfico das médias e o das amplitudes, com a linha central e os limites.
B28: Histograma | C28: As classes, as contagens e o gráfico das medições individuais.
B29: Painel | C29: Os números dos subgrupos, dos sinais e da capacidade, com o aviso.
B30: Checklist | C30: Doze verificações do gráfico, com percentual de conclusão.
B31: Exemplo 1 - Pizzaria | C31: O peso da bola de massa: em controle, mas não capaz.
B32: Exemplo 2 - Indústria | C32: A espessura do filme: capaz na base, com sinais no acompanhamento.
B34: Premissas do modelo
B35: Gráfico | C35: Média e amplitude (X̄-R), com subgrupos de 5 e as constantes de Shewhart para esse tamanho. Outro tamanho de subgrupo pede outras constantes.
B36: Regras e classes | C36: As regras de sinal, a classificação da capacidade e as classes do histograma são uma convenção deste material, próxima das usuais.
B37: Exemplos | C37: Os dados das abas de exemplo são ilustrativos, criados para este material.

Sheet Dados
B1: Dados do gráfico de controle
B2: Um subgrupo por linha: as cinco medições feitas juntas, nas mesmas condições.
B4: Característica medida | K4: Subgrupos na base | L4: =COUNTIF($N$13:$N$42,"Base") -> 0 | N4: Da aba: os subgrupos marcados como Base.
B5: Unidade | K5: Linha central da média (LC) | L5: =IF($L$4=0,"",AVERAGEIF($N$13:$N$42,"Base",$L$13:$L$42)) | N5: Média das médias da base.
B6: Especificação: mínimo (LIE) | K6: Limite superior de controle (LSC) | L6: =IF($L$5="","",$L$5+0.577*$L$8) | N6: LC + 0,577 × R̄.
B7: Especificação: máximo (LSE) | K7: Limite inferior de controle (LIC) | L7: =IF($L$5="","",$L$5-0.577*$L$8) | N7: LC − 0,577 × R̄.
B8: Subgrupos da base | K8: Amplitude média (R̄) | L8: =IF($L$4=0,"",AVERAGEIF($N$13:$N$42,"Base",$M$13:$M$42)) | N8: Média das amplitudes da base.
B9: Tamanho do subgrupo | E9: 5 | K9: Limite da amplitude (LSC de R) | L9: =IF($L$8="","",2.114*$L$8) | N9: 2,114 × R̄. O inferior é zero.
K10: Desvio estimado (σ = R̄ ÷ d2) | L10: =IF($L$8="","",$L$8/2.326) | N10: R̄ ÷ 2,326. Usado na capacidade.
B12: # | C12: Data | D12: Identificação | E12: Medição 1 | F12: Medição 2 | G12: Medição 3 | H12: Medição 4 | I12: Medição 5 | J12: Excluir da base | K12: Motivo da exclusão | L12: Média | M12: Amplitude | N12: Fase | O12: Fora da espec. | P12: Sinal | Q12: Conferência
B13: 1 | L13: =IF(COUNT(E13:I13)=5,AVERAGE(E13:I13),"") | M13: =IF(COUNT(E13:I13)=5,MAX(E13:I13)-MIN(E13:I13),"") | N13: =IF(L13="","",IF(J13="Sim","Excluído",IF(OR($E$8="",B13<=$E$8),"Base","Acompanhamento"))) | O13: =IF(OR(COUNT(E13:I13)=0,$E$6="",$E$7=""),"",COUNTIF(E13:I13,"<"&$E$6)+COUNTIF(E13:I13,">"&$E$7)) | P13: =IF(OR(L13="",$L$5=""),"",IF(OR(L13>$L$6,L13<$L$7),"Média fora dos limites",IF(M13>$L$9,"Amplitude fora do limite",IF(FALSE(),"7 do mesmo lado",IF(FALSE(),"6 subindo ou descendo",""))))) | Q13: =IF(COUNT(E13:I13)+LEN(C13)+LEN(D13)+LEN(J13)=0,"",IF(AND(COUNT(E13:I13)>0,COUNT(E13:I13)<5),"Faltam medições",IF(AND(COUNT(E13:I13)>0,C13=""),"Falta a data",IF(AND(J13="Sim",K13=""),"Falta o motivo",IF(COUNT(E13:I13)=0,"Faltam medições","OK")))))
B14: 2 | L14: =IF(COUNT(E14:I14)=5,AVERAGE(E14:I14),"") | M14: =IF(COUNT(E14:I14)=5,MAX(E14:I14)-MIN(E14:I14),"") | N14: =IF(L14="","",IF(J14="Sim","Excluído",IF(OR($E$8="",B14<=$E$8),"Base","Acompanhamento"))) | O14: =IF(OR(COUNT(E14:I14)=0,$E$6="",$E$7=""),"",COUNTIF(E14:I14,"<"&$E$6)+COUNTIF(E14:I14,">"&$E$7)) | P14: =IF(OR(L14="",$L$5=""),"",IF(OR(L14>$L$6,L14<$L$7),"Média fora dos limites",IF(M14>$L$9,"Amplitude fora do limite",IF(FALSE(),"7 do mesmo lado",IF(FALSE(),"6 subindo ou descendo",""))))) | Q14: =IF(COUNT(E14:I14)+LEN(C14)+LEN(D14)+LEN(J14)=0,"",IF(AND(COUNT(E14:I14)>0,COUNT(E14:I14)<5),"Faltam medições",IF(AND(COUNT(E14:I14)>0,C14=""),"Falta a data",IF(AND(J14="Sim",K14=""),"Falta o motivo",IF(COUNT(E14:I14)=0,"Faltam medições","OK")))))
B15: 3 | L15: =IF(COUNT(E15:I15)=5,AVERAGE(E15:I15),"") | M15: =IF(COUNT(E15:I15)=5,MAX(E15:I15)-MIN(E15:I15),"") | N15: =IF(L15="","",IF(J15="Sim","Excluído",IF(OR($E$8="",B15<=$E$8),"Base","Acompanhamento"))) | O15: =IF(OR(COUNT(E15:I15)=0,$E$6="",$E$7=""),"",COUNTIF(E15:I15,"<"&$E$6)+COUNTIF(E15:I15,">"&$E$7)) | P15: =IF(OR(L15="",$L$5=""),"",IF(OR(L15>$L$6,L15<$L$7),"Média fora dos limites",IF(M15>$L$9,"Amplitude fora do limite",IF(FALSE(),"7 do mesmo lado",IF(FALSE(),"6 subindo ou descendo",""))))) | Q15: =IF(COUNT(E15:I15)+LEN(C15)+LEN(D15)+LEN(J15)=0,"",IF(AND(COUNT(E15:I15)>0,COUNT(E15:I15)<5),"Faltam medições",IF(AND(COUNT(E15:I15)>0,C15=""),"Falta a data",IF(AND(J15="Sim",K15=""),"Falta o motivo",IF(COUNT(E15:I15)=0,"Faltam medições","OK")))))
B16: 4 | L16: =IF(COUNT(E16:I16)=5,AVERAGE(E16:I16),"") | M16: =IF(COUNT(E16:I16)=5,MAX(E16:I16)-MIN(E16:I16),"") | N16: =IF(L16="","",IF(J16="Sim","Excluído",IF(OR($E$8="",B16<=$E$8),"Base","Acompanhamento"))) | O16: =IF(OR(COUNT(E16:I16)=0,$E$6="",$E$7=""),"",COUNTIF(E16:I16,"<"&$E$6)+COUNTIF(E16:I16,">"&$E$7)) | P16: =IF(OR(L16="",$L$5=""),"",IF(OR(L16>$L$6,L16<$L$7),"Média fora dos limites",IF(M16>$L$9,"Amplitude fora do limite",IF(FALSE(),"7 do mesmo lado",IF(FALSE(),"6 subindo ou descendo",""))))) | Q16: =IF(COUNT(E16:I16)+LEN(C16)+LEN(D16)+LEN(J16)=0,"",IF(AND(COUNT(E16:I16)>0,COUNT(E16:I16)<5),"Faltam medições",IF(AND(COUNT(E16:I16)>0,C16=""),"Falta a data",IF(AND(J16="Sim",K16=""),"Falta o motivo",IF(COUNT(E16:I16)=0,"Faltam medições","OK")))))
B17: 5 | L17: =IF(COUNT(E17:I17)=5,AVERAGE(E17:I17),"") | M17: =IF(COUNT(E17:I17)=5,MAX(E17:I17)-MIN(E17:I17),"") | N17: =IF(L17="","",IF(J17="Sim","Excluído",IF(OR($E$8="",B17<=$E$8),"Base","Acompanhamento"))) | O17: =IF(OR(COUNT(E17:I17)=0,$E$6="",$E$7=""),"",COUNTIF(E17:I17,"<"&$E$6)+COUNTIF(E17:I17,">"&$E$7)) | P17: =IF(OR(L17="",$L$5=""),"",IF(OR(L17>$L$6,L17<$L$7),"Média fora dos limites",IF(M17>$L$9,"Amplitude fora do limite",IF(FALSE(),"7 do mesmo lado",IF(FALSE(),"6 subindo ou descendo",""))))) | Q17: =IF(COUNT(E17:I17)+LEN(C17)+LEN(D17)+LEN(J17)=0,"",IF(AND(COUNT(E17:I17)>0,COUNT(E17:I17)<5),"Faltam medições",IF(AND(COUNT(E17:I17)>0,C17=""),"Falta a data",IF(AND(J17="Sim",K17=""),"Falta o motivo",IF(COUNT(E17:I17)=0,"Faltam medições","OK")))))
B18: 6 | L18: =IF(COUNT(E18:I18)=5,AVERAGE(E18:I18),"") | M18: =IF(COUNT(E18:I18)=5,MAX(E18:I18)-MIN(E18:I18),"") | N18: =IF(L18="","",IF(J18="Sim","Excluído",IF(OR($E$8="",B18<=$E$8),"Base","Acompanhamento"))) | O18: =IF(OR(COUNT(E18:I18)=0,$E$6="",$E$7=""),"",COUNTIF(E18:I18,"<"&$E$6)+COUNTIF(E18:I18,">"&$E$7)) | P18: =IF(OR(L18="",$L$5=""),"",IF(OR(L18>$L$6,L18<$L$7),"Média fora dos limites",IF(M18>$L$9,"Amplitude fora do limite",IF(FALSE(),"7 do mesmo lado",IF(AND(COUNT(L13:L18)=6,OR(AND(L18>L17,L17>L16,L16>L15,L15>L14,L14>L13),AND(L18<L17,L17<L16,L16<L15,L15<L14,L14<L13))),"6 subindo ou descendo",""))))) | Q18: =IF(COUNT(E18:I18)+LEN(C18)+LEN(D18)+LEN(J18)=0,"",IF(AND(COUNT(E18:I18)>0,COUNT(E18:I18)<5),"Faltam medições",IF(AND(COUNT(E18:I18)>0,C18=""),"Falta a data",IF(AND(J18="Sim",K18=""),"Falta o motivo",IF(COUNT(E18:I18)=0,"Faltam medições","OK")))))
B19: 7 | L19: =IF(COUNT(E19:I19)=5,AVERAGE(E19:I19),"") | M19: =IF(COUNT(E19:I19)=5,MAX(E19:I19)-MIN(E19:I19),"") | N19: =IF(L19="","",IF(J19="Sim","Excluído",IF(OR($E$8="",B19<=$E$8),"Base","Acompanhamento"))) | O19: =IF(OR(COUNT(E19:I19)=0,$E$6="",$E$7=""),"",COUNTIF(E19:I19,"<"&$E$6)+COUNTIF(E19:I19,">"&$E$7)) | P19: =IF(OR(L19="",$L$5=""),"",IF(OR(L19>$L$6,L19<$L$7),"Média fora dos limites",IF(M19>$L$9,"Amplitude fora do limite",IF(OR(COUNTIF(L13:L19,">"&$L$5)=7,COUNTIF(L13:L19,"<"&$L$5)=7),"7 do mesmo lado",IF(AND(COUNT(L14:L19)=6,OR(AND(L19>L18,L18>L17,L17>L16,L16>L15,L15>L14),AND(L19<L18,L18<L17,L17<L16,L16<L15,L15<L14))),"6 subindo ou descendo",""))))) | Q19: =IF(COUNT(E19:I19)+LEN(C19)+LEN(D19)+LEN(J19)=0,"",IF(AND(COUNT(E19:I19)>0,COUNT(E19:I19)<5),"Faltam medições",IF(AND(COUNT(E19:I19)>0,C19=""),"Falta a data",IF(AND(J19="Sim",K19=""),"Falta o motivo",IF(COUNT(E19:I19)=0,"Faltam medições","OK")))))
B20: 8 | L20: =IF(COUNT(E20:I20)=5,AVERAGE(E20:I20),"") | M20: =IF(COUNT(E20:I20)=5,MAX(E20:I20)-MIN(E20:I20),"") | N20: =IF(L20="","",IF(J20="Sim","Excluído",IF(OR($E$8="",B20<=$E$8),"Base","Acompanhamento"))) | O20: =IF(OR(COUNT(E20:I20)=0,$E$6="",$E$7=""),"",COUNTIF(E20:I20,"<"&$E$6)+COUNTIF(E20:I20,">"&$E$7)) | P20: =IF(OR(L20="",$L$5=""),"",IF(OR(L20>$L$6,L20<$L$7),"Média fora dos limites",IF(M20>$L$9,"Amplitude fora do limite",IF(OR(COUNTIF(L14:L20,">"&$L$5)=7,COUNTIF(L14:L20,"<"&$L$5)=7),"7 do mesmo lado",IF(AND(COUNT(L15:L20)=6,OR(AND(L20>L19,L19>L18,L18>L17,L17>L16,L16>L15),AND(L20<L19,L19<L18,L18<L17,L17<L16,L16<L15))),"6 subindo ou descendo",""))))) | Q20: =IF(COUNT(E20:I20)+LEN(C20)+LEN(D20)+LEN(J20)=0,"",IF(AND(COUNT(E20:I20)>0,COUNT(E20:I20)<5),"Faltam medições",IF(AND(COUNT(E20:I20)>0,C20=""),"Falta a data",IF(AND(J20="Sim",K20=""),"Falta o motivo",IF(COUNT(E20:I20)=0,"Faltam medições","OK")))))
B21: 9 | L21: =IF(COUNT(E21:I21)=5,AVERAGE(E21:I21),"") | M21: =IF(COUNT(E21:I21)=5,MAX(E21:I21)-MIN(E21:I21),"") | N21: =IF(L21="","",IF(J21="Sim","Excluído",IF(OR($E$8="",B21<=$E$8),"Base","Acompanhamento"))) | O21: =IF(OR(COUNT(E21:I21)=0,$E$6="",$E$7=""),"",COUNTIF(E21:I21,"<"&$E$6)+COUNTIF(E21:I21,">"&$E$7)) | P21: =IF(OR(L21="",$L$5=""),"",IF(OR(L21>$L$6,L21<$L$7),"Média fora dos limites",IF(M21>$L$9,"Amplitude fora do limite",IF(OR(COUNTIF(L15:L21,">"&$L$5)=7,COUNTIF(L15:L21,"<"&$L$5)=7),"7 do mesmo lado",IF(AND(COUNT(L16:L21)=6,OR(AND(L21>L20,L20>L19,L19>L18,L18>L17,L17>L16),AND(L21<L20,L20<L19,L19<L18,L18<L17,L17<L16))),"6 subindo ou descendo",""))))) | Q21: =IF(COUNT(E21:I21)+LEN(C21)+LEN(D21)+LEN(J21)=0,"",IF(AND(COUNT(E21:I21)>0,COUNT(E21:I21)<5),"Faltam medições",IF(AND(COUNT(E21:I21)>0,C21=""),"Falta a data",IF(AND(J21="Sim",K21=""),"Falta o motivo",IF(COUNT(E21:I21)=0,"Faltam medições","OK")))))
B22: 10 | L22: =IF(COUNT(E22:I22)=5,AVERAGE(E22:I22),"") | M22: =IF(COUNT(E22:I22)=5,MAX(E22:I22)-MIN(E22:I22),"") | N22: =IF(L22="","",IF(J22="Sim","Excluído",IF(OR($E$8="",B22<=$E$8),"Base","Acompanhamento"))) | O22: =IF(OR(COUNT(E22:I22)=0,$E$6="",$E$7=""),"",COUNTIF(E22:I22,"<"&$E$6)+COUNTIF(E22:I22,">"&$E$7)) | P22: =IF(OR(L22="",$L$5=""),"",IF(OR(L22>$L$6,L22<$L$7),"Média fora dos limites",IF(M22>$L$9,"Amplitude fora do limite",IF(OR(COUNTIF(L16:L22,">"&$L$5)=7,COUNTIF(L16:L22,"<"&$L$5)=7),"7 do mesmo lado",IF(AND(COUNT(L17:L22)=6,OR(AND(L22>L21,L21>L20,L20>L19,L19>L18,L18>L17),AND(L22<L21,L21<L20,L20<L19,L19<L18,L18<L17))),"6 subindo ou descendo",""))))) | Q22: =IF(COUNT(E22:I22)+LEN(C22)+LEN(D22)+LEN(J22)=0,"",IF(AND(COUNT(E22:I22)>0,COUNT(E22:I22)<5),"Faltam medições",IF(AND(COUNT(E22:I22)>0,C22=""),"Falta a data",IF(AND(J22="Sim",K22=""),"Falta o motivo",IF(COUNT(E22:I22)=0,"Faltam medições","OK")))))
B23: 11 | L23: =IF(COUNT(E23:I23)=5,AVERAGE(E23:I23),"") | M23: =IF(COUNT(E23:I23)=5,MAX(E23:I23)-MIN(E23:I23),"") | N23: =IF(L23="","",IF(J23="Sim","Excluído",IF(OR($E$8="",B23<=$E$8),"Base","Acompanhamento"))) | O23: =IF(OR(COUNT(E23:I23)=0,$E$6="",$E$7=""),"",COUNTIF(E23:I23,"<"&$E$6)+COUNTIF(E23:I23,">"&$E$7)) | P23: =IF(OR(L23="",$L$5=""),"",IF(OR(L23>$L$6,L23<$L$7),"Média fora dos limites",IF(M23>$L$9,"Amplitude fora do limite",IF(OR(COUNTIF(L17:L23,">"&$L$5)=7,COUNTIF(L17:L23,"<"&$L$5)=7),"7 do mesmo lado",IF(AND(COUNT(L18:L23)=6,OR(AND(L23>L22,L22>L21,L21>L20,L20>L19,L19>L18),AND(L23<L22,L22<L21,L21<L20,L20<L19,L19<L18))),"6 subindo ou descendo",""))))) | Q23: =IF(COUNT(E23:I23)+LEN(C23)+LEN(D23)+LEN(J23)=0,"",IF(AND(COUNT(E23:I23)>0,COUNT(E23:I23)<5),"Faltam medições",IF(AND(COUNT(E23:I23)>0,C23=""),"Falta a data",IF(AND(J23="Sim",K23=""),"Falta o motivo",IF(COUNT(E23:I23)=0,"Faltam medições","OK")))))
B24: 12 | L24: =IF(COUNT(E24:I24)=5,AVERAGE(E24:I24),"") | M24: =IF(COUNT(E24:I24)=5,MAX(E24:I24)-MIN(E24:I24),"") | N24: =IF(L24="","",IF(J24="Sim","Excluído",IF(OR($E$8="",B24<=$E$8),"Base","Acompanhamento"))) | O24: =IF(OR(COUNT(E24:I24)=0,$E$6="",$E$7=""),"",COUNTIF(E24:I24,"<"&$E$6)+COUNTIF(E24:I24,">"&$E$7)) | P24: =IF(OR(L24="",$L$5=""),"",IF(OR(L24>$L$6,L24<$L$7),"Média fora dos limites",IF(M24>$L$9,"Amplitude fora do limite",IF(OR(COUNTIF(L18:L24,">"&$L$5)=7,COUNTIF(L18:L24,"<"&$L$5)=7),"7 do mesmo lado",IF(AND(COUNT(L19:L24)=6,OR(AND(L24>L23,L23>L22,L22>L21,L21>L20,L20>L19),AND(L24<L23,L23<L22,L22<L21,L21<L20,L20<L19))),"6 subindo ou descendo",""))))) | Q24: =IF(COUNT(E24:I24)+LEN(C24)+LEN(D24)+LEN(J24)=0,"",IF(AND(COUNT(E24:I24)>0,COUNT(E24:I24)<5),"Faltam medições",IF(AND(COUNT(E24:I24)>0,C24=""),"Falta a data",IF(AND(J24="Sim",K24=""),"Falta o motivo",IF(COUNT(E24:I24)=0,"Faltam medições","OK")))))
B25: 13 | L25: =IF(COUNT(E25:I25)=5,AVERAGE(E25:I25),"") | M25: =IF(COUNT(E25:I25)=5,MAX(E25:I25)-MIN(E25:I25),"") | N25: =IF(L25="","",IF(J25="Sim","Excluído",IF(OR($E$8="",B25<=$E$8),"Base","Acompanhamento"))) | O25: =IF(OR(COUNT(E25:I25)=0,$E$6="",$E$7=""),"",COUNTIF(E25:I25,"<"&$E$6)+COUNTIF(E25:I25,">"&$E$7)) | P25: =IF(OR(L25="",$L$5=""),"",IF(OR(L25>$L$6,L25<$L$7),"Média fora dos limites",IF(M25>$L$9,"Amplitude fora do limite",IF(OR(COUNTIF(L19:L25,">"&$L$5)=7,COUNTIF(L19:L25,"<"&$L$5)=7),"7 do mesmo lado",IF(AND(COUNT(L20:L25)=6,OR(AND(L25>L24,L24>L23,L23>L22,L22>L21,L21>L20),AND(L25<L24,L24<L23,L23<L22,L22<L21,L21<L20))),"6 subindo ou descendo",""))))) | Q25: =IF(COUNT(E25:I25)+LEN(C25)+LEN(D25)+LEN(J25)=0,"",IF(AND(COUNT(E25:I25)>0,COUNT(E25:I25)<5),"Faltam medições",IF(AND(COUNT(E25:I25)>0,C25=""),"Falta a data",IF(AND(J25="Sim",K25=""),"Falta o motivo",IF(COUNT(E25:I25)=0,"Faltam medições","OK")))))
B26: 14 | L26: =IF(COUNT(E26:I26)=5,AVERAGE(E26:I26),"") | M26: =IF(COUNT(E26:I26)=5,MAX(E26:I26)-MIN(E26:I26),"") | N26: =IF(L26="","",IF(J26="Sim","Excluído",IF(OR($E$8="",B26<=$E$8),"Base","Acompanhamento"))) | O26: =IF(OR(COUNT(E26:I26)=0,$E$6="",$E$7=""),"",COUNTIF(E26:I26,"<"&$E$6)+COUNTIF(E26:I26,">"&$E$7)) | P26: =IF(OR(L26="",$L$5=""),"",IF(OR(L26>$L$6,L26<$L$7),"Média fora dos limites",IF(M26>$L$9,"Amplitude fora do limite",IF(OR(COUNTIF(L20:L26,">"&$L$5)=7,COUNTIF(L20:L26,"<"&$L$5)=7),"7 do mesmo lado",IF(AND(COUNT(L21:L26)=6,OR(AND(L26>L25,L25>L24,L24>L23,L23>L22,L22>L21),AND(L26<L25,L25<L24,L24<L23,L23<L22,L22<L21))),"6 subindo ou descendo",""))))) | Q26: =IF(COUNT(E26:I26)+LEN(C26)+LEN(D26)+LEN(J26)=0,"",IF(AND(COUNT(E26:I26)>0,COUNT(E26:I26)<5),"Faltam medições",IF(AND(COUNT(E26:I26)>0,C26=""),"Falta a data",IF(AND(J26="Sim",K26=""),"Falta o motivo",IF(COUNT(E26:I26)=0,"Faltam medições","OK")))))
B27: 15 | L27: =IF(COUNT(E27:I27)=5,AVERAGE(E27:I27),"") | M27: =IF(COUNT(E27:I27)=5,MAX(E27:I27)-MIN(E27:I27),"") | N27: =IF(L27="","",IF(J27="Sim","Excluído",IF(OR($E$8="",B27<=$E$8),"Base","Acompanhamento"))) | O27: =IF(OR(COUNT(E27:I27)=0,$E$6="",$E$7=""),"",COUNTIF(E27:I27,"<"&$E$6)+COUNTIF(E27:I27,">"&$E$7)) | P27: =IF(OR(L27="",$L$5=""),"",IF(OR(L27>$L$6,L27<$L$7),"Média fora dos limites",IF(M27>$L$9,"Amplitude fora do limite",IF(OR(COUNTIF(L21:L27,">"&$L$5)=7,COUNTIF(L21:L27,"<"&$L$5)=7),"7 do mesmo lado",IF(AND(COUNT(L22:L27)=6,OR(AND(L27>L26,L26>L25,L25>L24,L24>L23,L23>L22),AND(L27<L26,L26<L25,L25<L24,L24<L23,L23<L22))),"6 subindo ou descendo",""))))) | Q27: =IF(COUNT(E27:I27)+LEN(C27)+LEN(D27)+LEN(J27)=0,"",IF(AND(COUNT(E27:I27)>0,COUNT(E27:I27)<5),"Faltam medições",IF(AND(COUNT(E27:I27)>0,C27=""),"Falta a data",IF(AND(J27="Sim",K27=""),"Falta o motivo",IF(COUNT(E27:I27)=0,"Faltam medições","OK")))))
B28: 16 | L28: =IF(COUNT(E28:I28)=5,AVERAGE(E28:I28),"") | M28: =IF(COUNT(E28:I28)=5,MAX(E28:I28)-MIN(E28:I28),"") | N28: =IF(L28="","",IF(J28="Sim","Excluído",IF(OR($E$8="",B28<=$E$8),"Base","Acompanhamento"))) | O28: =IF(OR(COUNT(E28:I28)=0,$E$6="",$E$7=""),"",COUNTIF(E28:I28,"<"&$E$6)+COUNTIF(E28:I28,">"&$E$7)) | P28: =IF(OR(L28="",$L$5=""),"",IF(OR(L28>$L$6,L28<$L$7),"Média fora dos limites",IF(M28>$L$9,"Amplitude fora do limite",IF(OR(COUNTIF(L22:L28,">"&$L$5)=7,COUNTIF(L22:L28,"<"&$L$5)=7),"7 do mesmo lado",IF(AND(COUNT(L23:L28)=6,OR(AND(L28>L27,L27>L26,L26>L25,L25>L24,L24>L23),AND(L28<L27,L27<L26,L26<L25,L25<L24,L24<L23))),"6 subindo ou descendo",""))))) | Q28: =IF(COUNT(E28:I28)+LEN(C28)+LEN(D28)+LEN(J28)=0,"",IF(AND(COUNT(E28:I28)>0,COUNT(E28:I28)<5),"Faltam medições",IF(AND(COUNT(E28:I28)>0,C28=""),"Falta a data",IF(AND(J28="Sim",K28=""),"Falta o motivo",IF(COUNT(E28:I28)=0,"Faltam medições","OK")))))
B29: 17 | L29: =IF(COUNT(E29:I29)=5,AVERAGE(E29:I29),"") | M29: =IF(COUNT(E29:I29)=5,MAX(E29:I29)-MIN(E29:I29),"") | N29: =IF(L29="","",IF(J29="Sim","Excluído",IF(OR($E$8="",B29<=$E$8),"Base","Acompanhamento"))) | O29: =IF(OR(COUNT(E29:I29)=0,$E$6="",$E$7=""),"",COUNTIF(E29:I29,"<"&$E$6)+COUNTIF(E29:I29,">"&$E$7)) | P29: =IF(OR(L29="",$L$5=""),"",IF(OR(L29>$L$6,L29<$L$7),"Média fora dos limites",IF(M29>$L$9,"Amplitude fora do limite",IF(OR(COUNTIF(L23:L29,">"&$L$5)=7,COUNTIF(L23:L29,"<"&$L$5)=7),"7 do mesmo lado",IF(AND(COUNT(L24:L29)=6,OR(AND(L29>L28,L28>L27,L27>L26,L26>L25,L25>L24),AND(L29<L28,L28<L27,L27<L26,L26<L25,L25<L24))),"6 subindo ou descendo",""))))) | Q29: =IF(COUNT(E29:I29)+LEN(C29)+LEN(D29)+LEN(J29)=0,"",IF(AND(COUNT(E29:I29)>0,COUNT(E29:I29)<5),"Faltam medições",IF(AND(COUNT(E29:I29)>0,C29=""),"Falta a data",IF(AND(J29="Sim",K29=""),"Falta o motivo",IF(COUNT(E29:I29)=0,"Faltam medições","OK")))))
B30: 18 | L30: =IF(COUNT(E30:I30)=5,AVERAGE(E30:I30),"") | M30: =IF(COUNT(E30:I30)=5,MAX(E30:I30)-MIN(E30:I30),"") | N30: =IF(L30="","",IF(J30="Sim","Excluído",IF(OR($E$8="",B30<=$E$8),"Base","Acompanhamento"))) | O30: =IF(OR(COUNT(E30:I30)=0,$E$6="",$E$7=""),"",COUNTIF(E30:I30,"<"&$E$6)+COUNTIF(E30:I30,">"&$E$7)) | P30: =IF(OR(L30="",$L$5=""),"",IF(OR(L30>$L$6,L30<$L$7),"Média fora dos limites",IF(M30>$L$9,"Amplitude fora do limite",IF(OR(COUNTIF(L24:L30,">"&$L$5)=7,COUNTIF(L24:L30,"<"&$L$5)=7),"7 do mesmo lado",IF(AND(COUNT(L25:L30)=6,OR(AND(L30>L29,L29>L28,L28>L27,L27>L26,L26>L25),AND(L30<L29,L29<L28,L28<L27,L27<L26,L26<L25))),"6 subindo ou descendo",""))))) | Q30: =IF(COUNT(E30:I30)+LEN(C30)+LEN(D30)+LEN(J30)=0,"",IF(AND(COUNT(E30:I30)>0,COUNT(E30:I30)<5),"Faltam medições",IF(AND(COUNT(E30:I30)>0,C30=""),"Falta a data",IF(AND(J30="Sim",K30=""),"Falta o motivo",IF(COUNT(E30:I30)=0,"Faltam medições","OK")))))
... B42: 30 | L42: =IF(COUNT(E42:I42)=5,AVERAGE(E42:I42),"") | M42: =IF(COUNT(E42:I42)=5,MAX(E42:I42)-MIN(E42:I42),"") | N42: =IF(L42="","",IF(J42="Sim","Excluído",IF(OR($E$8="",B42<=$E$8),"Base","Acompanhamento"))) | O42: =IF(OR(COUNT(E42:I42)=0,$E$6="",$E$7=""),"",COUNTIF(E42:I42,"<"&$E$6)+COUNTIF(E42:I42,">"&$E$7)) | P42: =IF(OR(L42="",$L$5=""),"",IF(OR(L42>$L$6,L42<$L$7),"Média fora dos limites",IF(M42>$L$9,"Amplitude fora do limite",IF(OR(COUNTIF(L36:L42,">"&$L$5)=7,COUNTIF(L36:L42,"<"&$L$5)=7),"7 do mesmo lado",IF(AND(COUNT(L37:L42)=6,OR(AND(L42>L41,L41>L40,L40>L39,L39>L38,L38>L37),AND(L42<L41,L41<L40,L40<L39,L39<L38,L38<L37))),"6 subindo ou descendo",""))))) | Q42: =IF(COUNT(E42:I42)+LEN(C42)+LEN(D42)+LEN(J42)=0,"",IF(AND(COUNT(E42:I42)>0,COUNT(E42:I42)<5),"Faltam medições",IF(AND(COUNT(E42:I42)>0,C42=""),"Falta a data",IF(AND(J42="Sim",K42=""),"Falta o motivo",IF(COUNT(E42:I42)=0,"Faltam medições","OK")))))
B44: Resumo automático
B45: Fases | E45: =COUNTIF(N13:N42,"Base")&" base"&", "&COUNTIF(N13:N42,"Excluído")&" excluído"&", "&COUNTIF(N13:N42,"Acompanhamento")&" acompanhamento" -> 0 base, 0 excluído, 0 acompanhamento
B46: Sinais | E46: =COUNTIF(P13:P42,"Média fora dos limites")&" média fora dos limites"&", "&COUNTIF(P13:P42,"Amplitude fora do limite")&" amplitude fora do limite"&", "&COUNTIF(P13:P42,"7 do mesmo lado")&" 7 do mesmo lado"&", "&COUNTIF(P13:P42,"6 subindo ou descendo")&" 6 subindo ou descendo" -> 0 média fora dos limites, 0 amplitude fora do limite, 0 7 do mesmo lado, 0 6 subindo ou descendo

Sheet Gráficos
B1: Gráficos de controle
B2: Nada a preencher: os pontos e os limites vêm da aba Dados.
B3: Linhas sem subgrupo mostram #N/D, para o gráfico não desenhar um ponto em zero.
B4: # | C4: Média | D4: LSC | E4: LC | F4: LIC | G4: Amplitude | H4: LSC de R | I4: R̄
B5: 1 | C5: =IF(OR(Dados!L13="",Dados!L13=""),NA(),Dados!L13) -> #N/A | D5: =IF(OR(Dados!L13="",Dados!$L$6=""),NA(),Dados!$L$6) -> #N/A | E5: =IF(OR(Dados!L13="",Dados!$L$5=""),NA(),Dados!$L$5) -> #N/A | F5: =IF(OR(Dados!L13="",Dados!$L$7=""),NA(),Dados!$L$7) -> #N/A | G5: =IF(OR(Dados!L13="",Dados!M13=""),NA(),Dados!M13) -> #N/A | H5: =IF(OR(Dados!L13="",Dados!$L$9=""),NA(),Dados!$L$9) -> #N/A | I5: =IF(OR(Dados!L13="",Dados!$L$8=""),NA(),Dados!$L$8) -> #N/A
B6: 2 | C6: =IF(OR(Dados!L14="",Dados!L14=""),NA(),Dados!L14) -> #N/A | D6: =IF(OR(Dados!L14="",Dados!$L$6=""),NA(),Dados!$L$6) -> #N/A | E6: =IF(OR(Dados!L14="",Dados!$L$5=""),NA(),Dados!$L$5) -> #N/A | F6: =IF(OR(Dados!L14="",Dados!$L$7=""),NA(),Dados!$L$7) -> #N/A | G6: =IF(OR(Dados!L14="",Dados!M14=""),NA(),Dados!M14) -> #N/A | H6: =IF(OR(Dados!L14="",Dados!$L$9=""),NA(),Dados!$L$9) -> #N/A | I6: =IF(OR(Dados!L14="",Dados!$L$8=""),NA(),Dados!$L$8) -> #N/A
B7: 3 | C7: =IF(OR(Dados!L15="",Dados!L15=""),NA(),Dados!L15) -> #N/A | D7: =IF(OR(Dados!L15="",Dados!$L$6=""),NA(),Dados!$L$6) -> #N/A | E7: =IF(OR(Dados!L15="",Dados!$L$5=""),NA(),Dados!$L$5) -> #N/A | F7: =IF(OR(Dados!L15="",Dados!$L$7=""),NA(),Dados!$L$7) -> #N/A | G7: =IF(OR(Dados!L15="",Dados!M15=""),NA(),Dados!M15) -> #N/A | H7: =IF(OR(Dados!L15="",Dados!$L$9=""),NA(),Dados!$L$9) -> #N/A | I7: =IF(OR(Dados!L15="",Dados!$L$8=""),NA(),Dados!$L$8) -> #N/A
B8: 4 | C8: =IF(OR(Dados!L16="",Dados!L16=""),NA(),Dados!L16) -> #N/A | D8: =IF(OR(Dados!L16="",Dados!$L$6=""),NA(),Dados!$L$6) -> #N/A | E8: =IF(OR(Dados!L16="",Dados!$L$5=""),NA(),Dados!$L$5) -> #N/A | F8: =IF(OR(Dados!L16="",Dados!$L$7=""),NA(),Dados!$L$7) -> #N/A | G8: =IF(OR(Dados!L16="",Dados!M16=""),NA(),Dados!M16) -> #N/A | H8: =IF(OR(Dados!L16="",Dados!$L$9=""),NA(),Dados!$L$9) -> #N/A | I8: =IF(OR(Dados!L16="",Dados!$L$8=""),NA(),Dados!$L$8) -> #N/A
B9: 5 | C9: =IF(OR(Dados!L17="",Dados!L17=""),NA(),Dados!L17) -> #N/A | D9: =IF(OR(Dados!L17="",Dados!$L$6=""),NA(),Dados!$L$6) -> #N/A | E9: =IF(OR(Dados!L17="",Dados!$L$5=""),NA(),Dados!$L$5) -> #N/A | F9: =IF(OR(Dados!L17="",Dados!$L$7=""),NA(),Dados!$L$7) -> #N/A | G9: =IF(OR(Dados!L17="",Dados!M17=""),NA(),Dados!M17) -> #N/A | H9: =IF(OR(Dados!L17="",Dados!$L$9=""),NA(),Dados!$L$9) -> #N/A | I9: =IF(OR(Dados!L17="",Dados!$L$8=""),NA(),Dados!$L$8) -> #N/A
B10: 6 | C10: =IF(OR(Dados!L18="",Dados!L18=""),NA(),Dados!L18) -> #N/A | D10: =IF(OR(Dados!L18="",Dados!$L$6=""),NA(),Dados!$L$6) -> #N/A | E10: =IF(OR(Dados!L18="",Dados!$L$5=""),NA(),Dados!$L$5) -> #N/A | F10: =IF(OR(Dados!L18="",Dados!$L$7=""),NA(),Dados!$L$7) -> #N/A | G10: =IF(OR(Dados!L18="",Dados!M18=""),NA(),Dados!M18) -> #N/A | H10: =IF(OR(Dados!L18="",Dados!$L$9=""),NA(),Dados!$L$9) -> #N/A | I10: =IF(OR(Dados!L18="",Dados!$L$8=""),NA(),Dados!$L$8) -> #N/A
B11: 7 | C11: =IF(OR(Dados!L19="",Dados!L19=""),NA(),Dados!L19) -> #N/A | D11: =IF(OR(Dados!L19="",Dados!$L$6=""),NA(),Dados!$L$6) -> #N/A | E11: =IF(OR(Dados!L19="",Dados!$L$5=""),NA(),Dados!$L$5) -> #N/A | F11: =IF(OR(Dados!L19="",Dados!$L$7=""),NA(),Dados!$L$7) -> #N/A | G11: =IF(OR(Dados!L19="",Dados!M19=""),NA(),Dados!M19) -> #N/A | H11: =IF(OR(Dados!L19="",Dados!$L$9=""),NA(),Dados!$L$9) -> #N/A | I11: =IF(OR(Dados!L19="",Dados!$L$8=""),NA(),Dados!$L$8) -> #N/A
B12: 8 | C12: =IF(OR(Dados!L20="",Dados!L20=""),NA(),Dados!L20) -> #N/A | D12: =IF(OR(Dados!L20="",Dados!$L$6=""),NA(),Dados!$L$6) -> #N/A | E12: =IF(OR(Dados!L20="",Dados!$L$5=""),NA(),Dados!$L$5) -> #N/A | F12: =IF(OR(Dados!L20="",Dados!$L$7=""),NA(),Dados!$L$7) -> #N/A | G12: =IF(OR(Dados!L20="",Dados!M20=""),NA(),Dados!M20) -> #N/A | H12: =IF(OR(Dados!L20="",Dados!$L$9=""),NA(),Dados!$L$9) -> #N/A | I12: =IF(OR(Dados!L20="",Dados!$L$8=""),NA(),Dados!$L$8) -> #N/A
B13: 9 | C13: =IF(OR(Dados!L21="",Dados!L21=""),NA(),Dados!L21) -> #N/A | D13: =IF(OR(Dados!L21="",Dados!$L$6=""),NA(),Dados!$L$6) -> #N/A | E13: =IF(OR(Dados!L21="",Dados!$L$5=""),NA(),Dados!$L$5) -> #N/A | F13: =IF(OR(Dados!L21="",Dados!$L$7=""),NA(),Dados!$L$7) -> #N/A | G13: =IF(OR(Dados!L21="",Dados!M21=""),NA(),Dados!M21) -> #N/A | H13: =IF(OR(Dados!L21="",Dados!$L$9=""),NA(),Dados!$L$9) -> #N/A | I13: =IF(OR(Dados!L21="",Dados!$L$8=""),NA(),Dados!$L$8) -> #N/A
B14: 10 | C14: =IF(OR(Dados!L22="",Dados!L22=""),NA(),Dados!L22) -> #N/A | D14: =IF(OR(Dados!L22="",Dados!$L$6=""),NA(),Dados!$L$6) -> #N/A | E14: =IF(OR(Dados!L22="",Dados!$L$5=""),NA(),Dados!$L$5) -> #N/A | F14: =IF(OR(Dados!L22="",Dados!$L$7=""),NA(),Dados!$L$7) -> #N/A | G14: =IF(OR(Dados!L22="",Dados!M22=""),NA(),Dados!M22) -> #N/A | H14: =IF(OR(Dados!L22="",Dados!$L$9=""),NA(),Dados!$L$9) -> #N/A | I14: =IF(OR(Dados!L22="",Dados!$L$8=""),NA(),Dados!$L$8) -> #N/A
B15: 11 | C15: =IF(OR(Dados!L23="",Dados!L23=""),NA(),Dados!L23) -> #N/A | D15: =IF(OR(Dados!L23="",Dados!$L$6=""),NA(),Dados!$L$6) -> #N/A | E15: =IF(OR(Dados!L23="",Dados!$L$5=""),NA(),Dados!$L$5) -> #N/A | F15: =IF(OR(Dados!L23="",Dados!$L$7=""),NA(),Dados!$L$7) -> #N/A | G15: =IF(OR(Dados!L23="",Dados!M23=""),NA(),Dados!M23) -> #N/A | H15: =IF(OR(Dados!L23="",Dados!$L$9=""),NA(),Dados!$L$9) -> #N/A | I15: =IF(OR(Dados!L23="",Dados!$L$8=""),NA(),Dados!$L$8) -> #N/A
B16: 12 | C16: =IF(OR(Dados!L24="",Dados!L24=""),NA(),Dados!L24) -> #N/A | D16: =IF(OR(Dados!L24="",Dados!$L$6=""),NA(),Dados!$L$6) -> #N/A | E16: =IF(OR(Dados!L24="",Dados!$L$5=""),NA(),Dados!$L$5) -> #N/A | F16: =IF(OR(Dados!L24="",Dados!$L$7=""),NA(),Dados!$L$7) -> #N/A | G16: =IF(OR(Dados!L24="",Dados!M24=""),NA(),Dados!M24) -> #N/A | H16: =IF(OR(Dados!L24="",Dados!$L$9=""),NA(),Dados!$L$9) -> #N/A | I16: =IF(OR(Dados!L24="",Dados!$L$8=""),NA(),Dados!$L$8) -> #N/A
... B34: 30 | C34: =IF(OR(Dados!L42="",Dados!L42=""),NA(),Dados!L42) -> #N/A | D34: =IF(OR(Dados!L42="",Dados!$L$6=""),NA(),Dados!$L$6) -> #N/A | E34: =IF(OR(Dados!L42="",Dados!$L$5=""),NA(),Dados!$L$5) -> #N/A | F34: =IF(OR(Dados!L42="",Dados!$L$7=""),NA(),Dados!$L$7) -> #N/A | G34: =IF(OR(Dados!L42="",Dados!M42=""),NA(),Dados!M42) -> #N/A | H34: =IF(OR(Dados!L42="",Dados!$L$9=""),NA(),Dados!$L$9) -> #N/A | I34: =IF(OR(Dados!L42="",Dados!$L$8=""),NA(),Dados!$L$8) -> #N/A

Sheet Histograma
B1: Histograma das medições
B2: Nada a preencher: as classes vêm da especificação, e as medições, da aba Dados.
B4: Largura da classe | D4: =IF(OR(Dados!$E$6="",Dados!$E$7=""),"",(Dados!$E$7-Dados!$E$6)/8)
B5: Início da primeira classe | D5: =IF(D4="","",Dados!$E$6-2*D4)
B7: # | C7: De | D7: Até (exclusive) | E7: Medições
B8: 1 | C8: =IF($D$4="","",Dados!$E$6-2*$D$4+0*$D$4) | D8: =IF($D$4="","",Dados!$E$6-2*$D$4+1*$D$4) | E8: =IF(C8="","",COUNTIFS(Dados!$E$13:$I$42,">="&C8,Dados!$E$13:$I$42,"<"&D8))
B9: 2 | C9: =IF($D$4="","",Dados!$E$6-2*$D$4+1*$D$4) | D9: =IF($D$4="","",Dados!$E$6-2*$D$4+2*$D$4) | E9: =IF(C9="","",COUNTIFS(Dados!$E$13:$I$42,">="&C9,Dados!$E$13:$I$42,"<"&D9))
B10: 3 | C10: =IF($D$4="","",Dados!$E$6-2*$D$4+2*$D$4) | D10: =IF($D$4="","",Dados!$E$6-2*$D$4+3*$D$4) | E10: =IF(C10="","",COUNTIFS(Dados!$E$13:$I$42,">="&C10,Dados!$E$13:$I$42,"<"&D10))
B11: 4 | C11: =IF($D$4="","",Dados!$E$6-2*$D$4+3*$D$4) | D11: =IF($D$4="","",Dados!$E$6-2*$D$4+4*$D$4) | E11: =IF(C11="","",COUNTIFS(Dados!$E$13:$I$42,">="&C11,Dados!$E$13:$I$42,"<"&D11))
B12: 5 | C12: =IF($D$4="","",Dados!$E$6-2*$D$4+4*$D$4) | D12: =IF($D$4="","",Dados!$E$6-2*$D$4+5*$D$4) | E12: =IF(C12="","",COUNTIFS(Dados!$E$13:$I$42,">="&C12,Dados!$E$13:$I$42,"<"&D12))
B13: 6 | C13: =IF($D$4="","",Dados!$E$6-2*$D$4+5*$D$4) | D13: =IF($D$4="","",Dados!$E$6-2*$D$4+6*$D$4) | E13: =IF(C13="","",COUNTIFS(Dados!$E$13:$I$42,">="&C13,Dados!$E$13:$I$42,"<"&D13))
B14: 7 | C14: =IF($D$4="","",Dados!$E$6-2*$D$4+6*$D$4) | D14: =IF($D$4="","",Dados!$E$6-2*$D$4+7*$D$4) | E14: =IF(C14="","",COUNTIFS(Dados!$E$13:$I$42,">="&C14,Dados!$E$13:$I$42,"<"&D14))
B15: 8 | C15: =IF($D$4="","",Dados!$E$6-2*$D$4+7*$D$4) | D15: =IF($D$4="","",Dados!$E$6-2*$D$4+8*$D$4) | E15: =IF(C15="","",COUNTIFS(Dados!$E$13:$I$42,">="&C15,Dados!$E$13:$I$42,"<"&D15))
B16: 9 | C16: =IF($D$4="","",Dados!$E$6-2*$D$4+8*$D$4) | D16: =IF($D$4="","",Dados!$E$6-2*$D$4+9*$D$4) | E16: =IF(C16="","",COUNTIFS(Dados!$E$13:$I$42,">="&C16,Dados!$E$13:$I$42,"<"&D16))
B17: 10 | C17: =IF($D$4="","",Dados!$E$6-2*$D$4+9*$D$4) | D17: =IF($D$4="","",Dados!$E$6-2*$D$4+10*$D$4) | E17: =IF(C17="","",COUNTIFS(Dados!$E$13:$I$42,">="&C17,Dados!$E$13:$I$42,"<"&D17))
B18: 11 | C18: =IF($D$4="","",Dados!$E$6-2*$D$4+10*$D$4) | D18: =IF($D$4="","",Dados!$E$6-2*$D$4+11*$D$4) | E18: =IF(C18="","",COUNTIFS(Dados!$E$13:$I$42,">="&C18,Dados!$E$13:$I$42,"<"&D18))
B19: 12 | C19: =IF($D$4="","",Dados!$E$6-2*$D$4+11*$D$4) | D19: =IF($D$4="","",Dados!$E$6-2*$D$4+12*$D$4) | E19: =IF(C19="","",COUNTIFS(Dados!$E$13:$I$42,">="&C19,Dados!$E$13:$I$42,"<"&D19))
B20: Abaixo da primeira classe | E20: =IF($D$4="","",COUNTIF(Dados!$E$13:$I$42,"<"&C8))
B21: Acima da última classe | E21: =IF($D$4="","",COUNTIF(Dados!$E$13:$I$42,">="&D19)) | G21: Classes em vermelho na tabela ficam fora da especificação, inteira ou em parte.
B23: Resumo das medições
B24: Medições | E24: =COUNT(Dados!$E$13:$I$42) -> 0
B25: Média geral | E25: =IF(COUNT(Dados!$E$13:$I$42)=0,"",AVERAGE(Dados!$E$13:$I$42))
B26: Menor | E26: =IF(COUNT(Dados!$E$13:$I$42)=0,"",MIN(Dados!$E$13:$I$42))
B27: Maior | E27: =IF(COUNT(Dados!$E$13:$I$42)=0,"",MAX(Dados!$E$13:$I$42))
B28: Fora da especificação | E28: =IF(OR(COUNT(Dados!$E$13:$I$42)=0,Dados!$E$6="",Dados!$E$7=""),"",COUNTIF(Dados!$E$13:$I$42,"<"&Dados!$E$6)+COUNTIF(Dados!$E$13:$I$42,">"&Dados!$E$7))

Sheet Painel
B1: Painel do processo
B2: Nada a preencher: tudo vem das outras abas.
B3: Característica | C3: =IF(Dados!E4="","",Dados!E4&IF(Dados!E5="",""," ("&Dados!E5&")"))
B5: Indicador | C5: Resultado | D5: Como se lê
B6: SUBGRUPOS
B7: Subgrupos completos | C7: =COUNT(Dados!$L$13:$L$42) -> 0 | D7: Com as cinco medições.
B8: Na base | C8: =COUNTIF(Dados!$N$13:$N$42,"Base") -> 0 | D8: Usados nos limites.
B9: Excluídos | C9: =COUNTIF(Dados!$N$13:$N$42,"Excluído") -> 0 | D9: Com causa conhecida.
B10: Em acompanhamento | C10: =COUNTIF(Dados!$N$13:$N$42,"Acompanhamento") -> 0 | D10: Lidos contra os limites fixos.
B11: Linhas a completar | C11: =SUMPRODUCT((Dados!$Q$13:$Q$42<>"")*(Dados!$Q$13:$Q$42<>"OK")) -> 0 | D11: Conferências diferentes de OK.
B12: SINAIS
B13: Média fora dos limites | C13: =COUNTIF(Dados!$P$13:$P$42,"Média fora dos limites") -> 0 | D13: Média acima do LSC ou abaixo do LIC.
B14: Amplitude fora do limite | C14: =COUNTIF(Dados!$P$13:$P$42,"Amplitude fora do limite") -> 0 | D14: Amplitude acima do limite.
B15: 7 do mesmo lado | C15: =COUNTIF(Dados!$P$13:$P$42,"7 do mesmo lado") -> 0 | D15: Sequência do mesmo lado da linha central.
B16: 6 subindo ou descendo | C16: =COUNTIF(Dados!$P$13:$P$42,"6 subindo ou descendo") -> 0 | D16: Tendência: desgaste ou aquecimento.
B17: Sinais na base | C17: =SUMPRODUCT((Dados!$N$13:$N$42="Base")*(LEN(Dados!$P$13:$P$42)>0)) -> 0 | D17: Com sinal na base, a capacidade não vale.
B18: Sinais no acompanhamento | C18: =SUMPRODUCT((Dados!$N$13:$N$42="Acompanhamento")*(LEN(Dados!$P$13:$P$42)>0)) -> 0 | D18: Cada um pede causa e ação.
B19: Primeiro sinal no acompanhamento | C19: =IFERROR(INDEX(Dados!$C$13:$C$42,MATCH(1,INDEX((Dados!$N$13:$N$42="Acompanhamento")*(LEN(Dados!$P$13:$P$42)>0),0),0)),"") | D19: A data do primeiro aviso.
B20: CAPACIDADE
B21: Medições | C21: =COUNT(Dados!$E$13:$I$42) -> 0 | D21: Valores individuais.
B22: Medições fora da especificação | C22: =SUM(Dados!$O$13:$O$42) -> 0 | D22: Cada uma é uma unidade fora.
B23: Cp | C23: =IF(OR(Dados!$L$10="",Dados!$E$6="",Dados!$E$7=""),"",IF(Dados!$L$10=0,"",(Dados!$E$7-Dados!$E$6)/(6*Dados!$L$10))) | D23: Tolerância ÷ seis desvios.
B24: Cpk | C24: =IF(OR(Dados!$L$10="",Dados!$E$6="",Dados!$E$7=""),"",IF(Dados!$L$10=0,"",MIN(Dados!$E$7-Dados!$L$5,Dados!$L$5-Dados!$E$6)/(3*Dados!$L$10))) | D24: 1,33 ou mais: capaz. De 1,00 a 1,33: no limite.
B25: Situação da capacidade | C25: =IF(C24="","",IF(C17>0,"Base com sinal: trate antes",IF(C24>=1.33,"Capaz",IF(C24>=1,"No limite","Não capaz")))) | D25: Só vale com a base sem sinal.
B27: Resumo automático
B28: Aviso | C28: =IF(C7=0,"Lance os subgrupos na aba Dados",IF(C8<20,"Base com menos de 20 subgrupos: limites provisórios",IF(C11>0,"Há linha a completar: veja a coluna Conferência",IF(C17>0,"Há sinal na base: procure a causa e exclua o subgrupo",IF(C18>0,"Há sinal no acompanhamento: procure a causa e anote a ação",IF(C25="Não capaz","Processo em controle, mas não capaz: mude o processo",IF(C25="No limite","Capacidade no limite: acompanhe de perto","OK"))))))) -> Lance os subgrupos na aba Dados

Sheet Checklist
B1: Checklist do CEP
B2: Escolha o status de cada item na lista suspensa (coluna em amarelo-claro).
B4: # | C4: Item de verificação | D4: Status | E4: Observações
B5: 1 | C5: A característica medida pesa para o cliente e tem critério escrito.
B6: 2 | C6: O instrumento tem resolução de no máximo um décimo da tolerância e está calibrado ou verificado.
B7: 3 | C7: Cada subgrupo tem cinco medições feitas nas mesmas condições.
B8: 4 | C8: A base tem pelo menos 20 subgrupos.
B9: 5 | C9: Os subgrupos com causa conhecida foram excluídos da base, com o motivo escrito.
B10: 6 | C10: Os limites de controle vêm dos dados, e não da especificação.
B11: 7 | C11: Os limites ficam fixos durante o acompanhamento, e só são recalculados depois de uma mudança no processo.
B12: 8 | C12: Cada subgrupo novo é lançado e lido no mesmo turno.
B13: 9 | C13: Todo sinal tem causa procurada e ação registrada.
B14: 10 | C14: A capacidade só é calculada com a base em controle.
B15: 11 | C15: O histograma é lido junto com a especificação: centro, largura e forma.
B16: 12 | C16: A decisão sobre capacidade baixa foi levada à direção ou ao dono do processo.
B18: Resumo automático
B19: Itens atendidos (Sim) | D19: =COUNTIF(D5:D16,"Sim") -> 0
B20: Itens parciais | D20: =COUNTIF(D5:D16,"Parcial") -> 0
B21: Itens não atendidos | D21: =COUNTIF(D5:D16,"Não") -> 0
B22: Itens sem resposta | D22: =COUNTBLANK(D5:D16) -> 12
B23: Percentual atendido | D23: =D19/ROWS(D5:D16) -> 0
B24: Situação | D24: =IF(D19=ROWS(D5:D16),"Validado",IF(D22>0,"Em andamento","Com pendências")) -> Em andamento

Sheet Exemplo 1 - Pizzaria
B1: Histograma e CEP
B2: Exemplo preenchido, para consulta. Use a aba Dados para a sua característica.
B4: Organização | E4: Pizzaria (loja com salão e delivery)
B5: Processo | E5: Preparar a massa
B6: Medição | E6: Balança da bancada BAL-01, de 1 g, verificada em 01/03/2027
B7: Subgrupo | E7: As cinco bolas de cada lote de massa, pesadas uma a uma. Um lote por dia, de 22/03 a 15/04/2027.
B8: Origem | E8: Registro de produto não conforme 2027-17: bolas com 365 g em média em 18/03. O plano registrava só a média de cinco bolas.
B10: Característica medida | E10: Peso da bola de massa da pizza grande | K10: Subgrupos na base | L10: =COUNTIF($N$19:$N$43,"Base") -> 25 | N10: Da aba: os subgrupos marcados como Base.
B11: Unidade | E11: g | K11: Linha central da média (LC) | L11: =IF($L$10=0,"",AVERAGEIF($N$19:$N$43,"Base",$L$19:$L$43)) -> 400.304 | N11: Média das médias da base.
B12: Especificação: mínimo (LIE) | E12: 380 | K12: Limite superior de controle (LSC) | L12: =IF($L$11="","",$L$11+0.577*$L$14) -> 411.08236 | N12: LC + 0,577 × R̄.
B13: Especificação: máximo (LSE) | E13: 420 | K13: Limite inferior de controle (LIC) | L13: =IF($L$11="","",$L$11-0.577*$L$14) -> 389.52564 | N13: LC − 0,577 × R̄.
B14: Subgrupos da base | E14: 25 | K14: Amplitude média (R̄) | L14: =IF($L$10=0,"",AVERAGEIF($N$19:$N$43,"Base",$M$19:$M$43)) -> 18.68 | N14: Média das amplitudes da base.
B15: Tamanho do subgrupo | E15: 5 | K15: Limite da amplitude (LSC de R) | L15: =IF($L$14="","",2.114*$L$14) -> 39.48952 | N15: 2,114 × R̄. O inferior é zero.
K16: Desvio estimado (σ = R̄ ÷ d2) | L16: =IF($L$14="","",$L$14/2.326) -> 8.0309544 | N16: R̄ ÷ 2,326. Usado na capacidade.
B18: # | C18: Data | D18: Identificação | E18: Medição 1 | F18: Medição 2 | G18: Medição 3 | H18: Medição 4 | I18: Medição 5 | J18: Excluir da base | K18: Motivo da exclusão | L18: Média | M18: Amplitude | N18: Fase | O18: Fora da espec. | P18: Sinal | Q18: Conferência | S18: LSC | T18: LC | U18: LIC | V18: LSC de R | W18: R̄
B19: 1 | C19: 46468 | D19: Massa 22/03 | E19: 390 | F19: 399 | G19: 411 | H19: 386 | I19: 407 | L19: =IF(COUNT(E19:I19)=5,AVERAGE(E19:I19),"") -> 398.6 | M19: =IF(COUNT(E19:I19)=5,MAX(E19:I19)-MIN(E19:I19),"") -> 25 | N19: =IF(L19="","",IF(J19="Sim","Excluído",IF(OR($E$14="",B19<=$E$14),"Base","Acompanhamento"))) -> Base | O19: =IF(OR(COUNT(E19:I19)=0,$E$12="",$E$13=""),"",COUNTIF(E19:I19,"<"&$E$12)+COUNTIF(E19:I19,">"&$E$13)) -> 0 | P19: =IF(OR(L19="",$L$11=""),"",IF(OR(L19>$L$12,L19<$L$13),"Média fora dos limites",IF(M19>$L$15,"Amplitude fora do limite",IF(FALSE(),"7 do mesmo lado",IF(FALSE(),"6 subindo ou descendo",""))))) | Q19: =IF(COUNT(E19:I19)+LEN(C19)+LEN(D19)+LEN(J19)=0,"",IF(AND(COUNT(E19:I19)>0,COUNT(E19:I19)<5),"Faltam medições",IF(AND(COUNT(E19:I19)>0,C19=""),"Falta a data",IF(AND(J19="Sim",K19=""),"Falta o motivo",IF(COUNT(E19:I19)=0,"Faltam medições","OK"))))) -> OK | S19: =$L$12 -> 411.08236 | T19: =$L$11 -> 400.304 | U19: =$L$13 -> 389.52564 | V19: =$L$15 -> 39.48952 | W19: =$L$14 -> 18.68
B20: 2 | C20: 46469 | D20: Massa 23/03 | E20: 395 | F20: 409 | G20: 398 | H20: 400 | I20: 404 | L20: =IF(COUNT(E20:I20)=5,AVERAGE(E20:I20),"") -> 401.2 | M20: =IF(COUNT(E20:I20)=5,MAX(E20:I20)-MIN(E20:I20),"") -> 14 | N20: =IF(L20="","",IF(J20="Sim","Excluído",IF(OR($E$14="",B20<=$E$14),"Base","Acompanhamento"))) -> Base | O20: =IF(OR(COUNT(E20:I20)=0,$E$12="",$E$13=""),"",COUNTIF(E20:I20,"<"&$E$12)+COUNTIF(E20:I20,">"&$E$13)) -> 0 | P20: =IF(OR(L20="",$L$11=""),"",IF(OR(L20>$L$12,L20<$L$13),"Média fora dos limites",IF(M20>$L$15,"Amplitude fora do limite",IF(FALSE(),"7 do mesmo lado",IF(FALSE(),"6 subindo ou descendo",""))))) | Q20: =IF(COUNT(E20:I20)+LEN(C20)+LEN(D20)+LEN(J20)=0,"",IF(AND(COUNT(E20:I20)>0,COUNT(E20:I20)<5),"Faltam medições",IF(AND(COUNT(E20:I20)>0,C20=""),"Falta a data",IF(AND(J20="Sim",K20=""),"Falta o motivo",IF(COUNT(E20:I20)=0,"Faltam medições","OK"))))) -> OK | S20: =$L$12 -> 411.08236 | T20: =$L$11 -> 400.304 | U20: =$L$13 -> 389.52564 | V20: =$L$15 -> 39.48952 | W20: =$L$14 -> 18.68
B21: 3 | C21: 46470 | D21: Massa 24/03 | E21: 396 | F21: 400 | G21: 399 | H21: 412 | I21: 403 | L21: =IF(COUNT(E21:I21)=5,AVERAGE(E21:I21),"") -> 402 | M21: =IF(COUNT(E21:I21)=5,MAX(E21:I21)-MIN(E21:I21),"") -> 16 | N21: =IF(L21="","",IF(J21="Sim","Excluído",IF(OR($E$14="",B21<=$E$14),"Base","Acompanhamento"))) -> Base | O21: =IF(OR(COUNT(E21:I21)=0,$E$12="",$E$13=""),"",COUNTIF(E21:I21,"<"&$E$12)+COUNTIF(E21:I21,">"&$E$13)) -> 0 | P21: =IF(OR(L21="",$L$11=""),"",IF(OR(L21>$L$12,L21<$L$13),"Média fora dos limites",IF(M21>$L$15,"Amplitude fora do limite",IF(FALSE(),"7 do mesmo lado",IF(FALSE(),"6 subindo ou descendo",""))))) | Q21: =IF(COUNT(E21:I21)+LEN(C21)+LEN(D21)+LEN(J21)=0,"",IF(AND(COUNT(E21:I21)>0,COUNT(E21:I21)<5),"Faltam medições",IF(AND(COUNT(E21:I21)>0,C21=""),"Falta a data",IF(AND(J21="Sim",K21=""),"Falta o motivo",IF(COUNT(E21:I21)=0,"Faltam medições","OK"))))) -> OK | S21: =$L$12 -> 411.08236 | T21: =$L$11 -> 400.304 | U21: =$L$13 -> 389.52564 | V21: =$L$15 -> 39.48952 | W21: =$L$14 -> 18.68
B22: 4 | C22: 46471 | D22: Massa 25/03 | E22: 387 | F22: 403 | G22: 402 | H22: 400 | I22: 411 | L22: =IF(COUNT(E22:I22)=5,AVERAGE(E22:I22),"") -> 400.6 | M22: =IF(COUNT(E22:I22)=5,MAX(E22:I22)-MIN(E22:I22),"") -> 24 | N22: =IF(L22="","",IF(J22="Sim","Excluído",IF(OR($E$14="",B22<=$E$14),"Base","Acompanhamento"))) -> Base | O22: =IF(OR(COUNT(E22:I22)=0,$E$12="",$E$13=""),"",COUNTIF(E22:I22,"<"&$E$12)+COUNTIF(E22:I22,">"&$E$13)) -> 0 | P22: =IF(OR(L22="",$L$11=""),"",IF(OR(L22>$L$12,L22<$L$13),"Média fora dos limites",IF(M22>$L$15,"Amplitude fora do limite",IF(FALSE(),"7 do mesmo lado",IF(FALSE(),"6 subindo ou descendo",""))))) | Q22: =IF(COUNT(E22:I22)+LEN(C22)+LEN(D22)+LEN(J22)=0,"",IF(AND(COUNT(E22:I22)>0,COUNT(E22:I22)<5),"Faltam medições",IF(AND(COUNT(E22:I22)>0,C22=""),"Falta a data",IF(AND(J22="Sim",K22=""),"Falta o motivo",IF(COUNT(E22:I22)=0,"Faltam medições","OK"))))) -> OK | S22: =$L$12 -> 411.08236 | T22: =$L$11 -> 400.304 | U22: =$L$13 -> 389.52564 | V22: =$L$15 -> 39.48952 | W22: =$L$14 -> 18.68
B23: 5 | C23: 46472 | D23: Massa 26/03 | E23: 409 | F23: 388 | G23: 411 | H23: 396 | I23: 396 | L23: =IF(COUNT(E23:I23)=5,AVERAGE(E23:I23),"") -> 400 | M23: =IF(COUNT(E23:I23)=5,MAX(E23:I23)-MIN(E23:I23),"") -> 23 | N23: =IF(L23="","",IF(J23="Sim","Excluído",IF(OR($E$14="",B23<=$E$14),"Base","Acompanhamento"))) -> Base | O23: =IF(OR(COUNT(E23:I23)=0,$E$12="",$E$13=""),"",COUNTIF(E23:I23,"<"&$E$12)+COUNTIF(E23:I23,">"&$E$13)) -> 0 | P23: =IF(OR(L23="",$L$11=""),"",IF(OR(L23>$L$12,L23<$L$13),"Média fora dos limites",IF(M23>$L$15,"Amplitude fora do limite",IF(FALSE(),"7 do mesmo lado",IF(FALSE(),"6 subindo ou descendo",""))))) | Q23: =IF(COUNT(E23:I23)+LEN(C23)+LEN(D23)+LEN(J23)=0,"",IF(AND(COUNT(E23:I23)>0,COUNT(E23:I23)<5),"Faltam medições",IF(AND(COUNT(E23:I23)>0,C23=""),"Falta a data",IF(AND(J23="Sim",K23=""),"Falta o motivo",IF(COUNT(E23:I23)=0,"Faltam medições","OK"))))) -> OK | S23: =$L$12 -> 411.08236 | T23: =$L$11 -> 400.304 | U23: =$L$13 -> 389.52564 | V23: =$L$15 -> 39.48952 | W23: =$L$14 -> 18.68
B24: 6 | C24: 46473 | D24: Massa 27/03 | E24: 396 | F24: 399 | G24: 406 | H24: 390 | I24: 398 | L24: =IF(COUNT(E24:I24)=5,AVERAGE(E24:I24),"") -> 397.8 | M24: =IF(COUNT(E24:I24)=5,MAX(E24:I24)-MIN(E24:I24),"") -> 16 | N24: =IF(L24="","",IF(J24="Sim","Excluído",IF(OR($E$14="",B24<=$E$14),"Base","Acompanhamento"))) -> Base | O24: =IF(OR(COUNT(E24:I24)=0,$E$12="",$E$13=""),"",COUNTIF(E24:I24,"<"&$E$12)+COUNTIF(E24:I24,">"&$E$13)) -> 0 | P24: =IF(OR(L24="",$L$11=""),"",IF(OR(L24>$L$12,L24<$L$13),"Média fora dos limites",IF(M24>$L$15,"Amplitude fora do limite",IF(FALSE(),"7 do mesmo lado",IF(AND(COUNT(L19:L24)=6,OR(AND(L24>L23,L23>L22,L22>L21,L21>L20,L20>L19),AND(L24<L23,L23<L22,L22<L21,L21<L20,L20<L19))),"6 subindo ou descendo",""))))) | Q24: =IF(COUNT(E24:I24)+LEN(C24)+LEN(D24)+LEN(J24)=0,"",IF(AND(COUNT(E24:I24)>0,COUNT(E24:I24)<5),"Faltam medições",IF(AND(COUNT(E24:I24)>0,C24=""),"Falta a data",IF(AND(J24="Sim",K24=""),"Falta o motivo",IF(COUNT(E24:I24)=0,"Faltam medições","OK"))))) -> OK | S24: =$L$12 -> 411.08236 | T24: =$L$11 -> 400.304 | U24: =$L$13 -> 389.52564 | V24: =$L$15 -> 39.48952 | W24: =$L$14 -> 18.68
B25: 7 | C25: 46474 | D25: Massa 28/03 | E25: 393 | F25: 397 | G25: 395 | H25: 404 | I25: 405 | L25: =IF(COUNT(E25:I25)=5,AVERAGE(E25:I25),"") -> 398.8 | M25: =IF(COUNT(E25:I25)=5,MAX(E25:I25)-MIN(E25:I25),"") -> 12 | N25: =IF(L25="","",IF(J25="Sim","Excluído",IF(OR($E$14="",B25<=$E$14),"Base","Acompanhamento"))) -> Base | O25: =IF(OR(COUNT(E25:I25)=0,$E$12="",$E$13=""),"",COUNTIF(E25:I25,"<"&$E$12)+COUNTIF(E25:I25,">"&$E$13)) -> 0 | P25: =IF(OR(L25="",$L$11=""),"",IF(OR(L25>$L$12,L25<$L$13),"Média fora dos limites",IF(M25>$L$15,"Amplitude fora do limite",IF(OR(COUNTIF(L19:L25,">"&$L$11)=7,COUNTIF(L19:L25,"<"&$L$11)=7),"7 do mesmo lado",IF(AND(COUNT(L20:L25)=6,OR(AND(L25>L24,L24>L23,L23>L22,L22>L21,L21>L20),AND(L25<L24,L24<L23,L23<L22,L22<L21,L21<L20))),"6 subindo ou descendo",""))))) | Q25: =IF(COUNT(E25:I25)+LEN(C25)+LEN(D25)+LEN(J25)=0,"",IF(AND(COUNT(E25:I25)>0,COUNT(E25:I25)<5),"Faltam medições",IF(AND(COUNT(E25:I25)>0,C25=""),"Falta a data",IF(AND(J25="Sim",K25=""),"Falta o motivo",IF(COUNT(E25:I25)=0,"Faltam medições","OK"))))) -> OK | S25: =$L$12 -> 411.08236 | T25: =$L$11 -> 400.304 | U25: =$L$13 -> 389.52564 | V25: =$L$15 -> 39.48952 | W25: =$L$14 -> 18.68
B26: 8 | C26: 46475 | D26: Massa 29/03 | E26: 391 | F26: 401 | G26: 386 | H26: 400 | I26: 405 | L26: =IF(COUNT(E26:I26)=5,AVERAGE(E26:I26),"") -> 396.6 | M26: =IF(COUNT(E26:I26)=5,MAX(E26:I26)-MIN(E26:I26),"") -> 19 | N26: =IF(L26="","",IF(J26="Sim","Excluído",IF(OR($E$14="",B26<=$E$14),"Base","Acompanhamento"))) -> Base | O26: =IF(OR(COUNT(E26:I26)=0,$E$12="",$E$13=""),"",COUNTIF(E26:I26,"<"&$E$12)+COUNTIF(E26:I26,">"&$E$13)) -> 0 | P26: =IF(OR(L26="",$L$11=""),"",IF(OR(L26>$L$12,L26<$L$13),"Média fora dos limites",IF(M26>$L$15,"Amplitude fora do limite",IF(OR(COUNTIF(L20:L26,">"&$L$11)=7,COUNTIF(L20:L26,"<"&$L$11)=7),"7 do mesmo lado",IF(AND(COUNT(L21:L26)=6,OR(AND(L26>L25,L25>L24,L24>L23,L23>L22,L22>L21),AND(L26<L25,L25<L24,L24<L23,L23<L22,L22<L21))),"6 subindo ou descendo",""))))) | Q26: =IF(COUNT(E26:I26)+LEN(C26)+LEN(D26)+LEN(J26)=0,"",IF(AND(COUNT(E26:I26)>0,COUNT(E26:I26)<5),"Faltam medições",IF(AND(COUNT(E26:I26)>0,C26=""),"Falta a data",IF(AND(J26="Sim",K26=""),"Falta o motivo",IF(COUNT(E26:I26)=0,"Faltam medições","OK"))))) -> OK | S26: =$L$12 -> 411.08236 | T26: =$L$11 -> 400.304 | U26: =$L$13 -> 389.52564 | V26: =$L$15 -> 39.48952 | W26: =$L$14 -> 18.68
B27: 9 | C27: 46476 | D27: Massa 30/03 | E27: 397 | F27: 419 | G27: 403 | H27: 393 | I27: 402 | L27: =IF(COUNT(E27:I27)=5,AVERAGE(E27:I27),"") -> 402.8 | M27: =IF(COUNT(E27:I27)=5,MAX(E27:I27)-MIN(E27:I27),"") -> 26 | N27: =IF(L27="","",IF(J27="Sim","Excluído",IF(OR($E$14="",B27<=$E$14),"Base","Acompanhamento"))) -> Base | O27: =IF(OR(COUNT(E27:I27)=0,$E$12="",$E$13=""),"",COUNTIF(E27:I27,"<"&$E$12)+COUNTIF(E27:I27,">"&$E$13)) -> 0 | P27: =IF(OR(L27="",$L$11=""),"",IF(OR(L27>$L$12,L27<$L$13),"Média fora dos limites",IF(M27>$L$15,"Amplitude fora do limite",IF(OR(COUNTIF(L21:L27,">"&$L$11)=7,COUNTIF(L21:L27,"<"&$L$11)=7),"7 do mesmo lado",IF(AND(COUNT(L22:L27)=6,OR(AND(L27>L26,L26>L25,L25>L24,L24>L23,L23>L22),AND(L27<L26,L26<L25,L25<L24,L24<L23,L23<L22))),"6 subindo ou descendo",""))))) | Q27: =IF(COUNT(E27:I27)+LEN(C27)+LEN(D27)+LEN(J27)=0,"",IF(AND(COUNT(E27:I27)>0,COUNT(E27:I27)<5),"Faltam medições",IF(AND(COUNT(E27:I27)>0,C27=""),"Falta a data",IF(AND(J27="Sim",K27=""),"Falta o motivo",IF(COUNT(E27:I27)=0,"Faltam medições","OK"))))) -> OK | S27: =$L$12 -> 411.08236 | T27: =$L$11 -> 400.304 | U27: =$L$13 -> 389.52564 | V27: =$L$15 -> 39.48952 | W27: =$L$14 -> 18.68
B28: 10 | C28: 46477 | D28: Massa 31/03 | E28: 393 | F28: 403 | G28: 398 | H28: 399 | I28: 378 | L28: =IF(COUNT(E28:I28)=5,AVERAGE(E28:I28),"") -> 394.2 | M28: =IF(COUNT(E28:I28)=5,MAX(E28:I28)-MIN(E28:I28),"") -> 25 | N28: =IF(L28="","",IF(J28="Sim","Excluído",IF(OR($E$14="",B28<=$E$14),"Base","Acompanhamento"))) -> Base | O28: =IF(OR(COUNT(E28:I28)=0,$E$12="",$E$13=""),"",COUNTIF(E28:I28,"<"&$E$12)+COUNTIF(E28:I28,">"&$E$13)) -> 1 | P28: =IF(OR(L28="",$L$11=""),"",IF(OR(L28>$L$12,L28<$L$13),"Média fora dos limites",IF(M28>$L$15,"Amplitude fora do limite",IF(OR(COUNTIF(L22:L28,">"&$L$11)=7,COUNTIF(L22:L28,"<"&$L$11)=7),"7 do mesmo lado",IF(AND(COUNT(L23:L28)=6,OR(AND(L28>L27,L27>L26,L26>L25,L25>L24,L24>L23),AND(L28<L27,L27<L26,L26<L25,L25<L24,L24<L23))),"6 subindo ou descendo",""))))) | Q28: =IF(COUNT(E28:I28)+LEN(C28)+LEN(D28)+LEN(J28)=0,"",IF(AND(COUNT(E28:I28)>0,COUNT(E28:I28)<5),"Faltam medições",IF(AND(COUNT(E28:I28)>0,C28=""),"Falta a data",IF(AND(J28="Sim",K28=""),"Falta o motivo",IF(COUNT(E28:I28)=0,"Faltam medições","OK"))))) -> OK | S28: =$L$12 -> 411.08236 | T28: =$L$11 -> 400.304 | U28: =$L$13 -> 389.52564 | V28: =$L$15 -> 39.48952 | W28: =$L$14 -> 18.68
B29: 11 | C29: 46478 | D29: Massa 01/04 | E29: 393 | F29: 405 | G29: 405 | H29: 406 | I29: 402 | L29: =IF(COUNT(E29:I29)=5,AVERAGE(E29:I29),"") -> 402.2 | M29: =IF(COUNT(E29:I29)=5,MAX(E29:I29)-MIN(E29:I29),"") -> 13 | N29: =IF(L29="","",IF(J29="Sim","Excluído",IF(OR($E$14="",B29<=$E$14),"Base","Acompanhamento"))) -> Base | O29: =IF(OR(COUNT(E29:I29)=0,$E$12="",$E$13=""),"",COUNTIF(E29:I29,"<"&$E$12)+COUNTIF(E29:I29,">"&$E$13)) -> 0 | P29: =IF(OR(L29="",$L$11=""),"",IF(OR(L29>$L$12,L29<$L$13),"Média fora dos limites",IF(M29>$L$15,"Amplitude fora do limite",IF(OR(COUNTIF(L23:L29,">"&$L$11)=7,COUNTIF(L23:L29,"<"&$L$11)=7),"7 do mesmo lado",IF(AND(COUNT(L24:L29)=6,OR(AND(L29>L28,L28>L27,L27>L26,L26>L25,L25>L24),AND(L29<L28,L28<L27,L27<L26,L26<L25,L25<L24))),"6 subindo ou descendo",""))))) | Q29: =IF(COUNT(E29:I29)+LEN(C29)+LEN(D29)+LEN(J29)=0,"",IF(AND(COUNT(E29:I29)>0,COUNT(E29:I29)<5),"Faltam medições",IF(AND(COUNT(E29:I29)>0,C29=""),"Falta a data",IF(AND(J29="Sim",K29=""),"Falta o motivo",IF(COUNT(E29:I29)=0,"Faltam medições","OK"))))) -> OK | S29: =$L$12 -> 411.08236 | T29: =$L$11 -> 400.304 | U29: =$L$13 -> 389.52564 | V29: =$L$15 -> 39.48952 | W29: =$L$14 -> 18.68
B30: 12 | C30: 46479 | D30: Massa 02/04 | E30: 408 | F30: 407 | G30: 404 | H30: 409 | I30: 407 | L30: =IF(COUNT(E30:I30)=5,AVERAGE(E30:I30),"") -> 407 | M30: =IF(COUNT(E30:I30)=5,MAX(E30:I30)-MIN(E30:I30),"") -> 5 | N30: =IF(L30="","",IF(J30="Sim","Excluído",IF(OR($E$14="",B30<=$E$14),"Base","Acompanhamento"))) -> Base | O30: =IF(OR(COUNT(E30:I30)=0,$E$12="",$E$13=""),"",COUNTIF(E30:I30,"<"&$E$12)+COUNTIF(E30:I30,">"&$E$13)) -> 0 | P30: =IF(OR(L30="",$L$11=""),"",IF(OR(L30>$L$12,L30<$L$13),"Média fora dos limites",IF(M30>$L$15,"Amplitude fora do limite",IF(OR(COUNTIF(L24:L30,">"&$L$11)=7,COUNTIF(L24:L30,"<"&$L$11)=7),"7 do mesmo lado",IF(AND(COUNT(L25:L30)=6,OR(AND(L30>L29,L29>L28,L28>L27,L27>L26,L26>L25),AND(L30<L29,L29<L28,L28<L27,L27<L26,L26<L25))),"6 subindo ou descendo",""))))) | Q30: =IF(COUNT(E30:I30)+LEN(C30)+LEN(D30)+LEN(J30)=0,"",IF(AND(COUNT(E30:I30)>0,COUNT(E30:I30)<5),"Faltam medições",IF(AND(COUNT(E30:I30)>0,C30=""),"Falta a data",IF(AND(J30="Sim",K30=""),"Falta o motivo",IF(COUNT(E30:I30)=0,"Faltam medições","OK"))))) -> OK | S30: =$L$12 -> 411.08236 | T30: =$L$11 -> 400.304 | U30: =$L$13 -> 389.52564 | V30: =$L$15 -> 39.48952 | W30: =$L$14 -> 18.68
B31: 13 | C31: 46480 | D31: Massa 03/04 | E31: 396 | F31: 404 | G31: 407 | H31: 398 | I31: 384 | L31: =IF(COUNT(E31:I31)=5,AVERAGE(E31:I31),"") -> 397.8 | M31: =IF(COUNT(E31:I31)=5,MAX(E31:I31)-MIN(E31:I31),"") -> 23 | N31: =IF(L31="","",IF(J31="Sim","Excluído",IF(OR($E$14="",B31<=$E$14),"Base","Acompanhamento"))) -> Base | O31: =IF(OR(COUNT(E31:I31)=0,$E$12="",$E$13=""),"",COUNTIF(E31:I31,"<"&$E$12)+COUNTIF(E31:I31,">"&$E$13)) -> 0 | P31: =IF(OR(L31="",$L$11=""),"",IF(OR(L31>$L$12,L31<$L$13),"Média fora dos limites",IF(M31>$L$15,"Amplitude fora do limite",IF(OR(COUNTIF(L25:L31,">"&$L$11)=7,COUNTIF(L25:L31,"<"&$L$11)=7),"7 do mesmo lado",IF(AND(COUNT(L26:L31)=6,OR(AND(L31>L30,L30>L29,L29>L28,L28>L27,L27>L26),AND(L31<L30,L30<L29,L29<L28,L28<L27,L27<L26))),"6 subindo ou descendo",""))))) | Q31: =IF(COUNT(E31:I31)+LEN(C31)+LEN(D31)+LEN(J31)=0,"",IF(AND(COUNT(E31:I31)>0,COUNT(E31:I31)<5),"Faltam medições",IF(AND(COUNT(E31:I31)>0,C31=""),"Falta a data",IF(AND(J31="Sim",K31=""),"Falta o motivo",IF(COUNT(E31:I31)=0,"Faltam medições","OK"))))) -> OK | S31: =$L$12 -> 411.08236 | T31: =$L$11 -> 400.304 | U31: =$L$13 -> 389.52564 | V31: =$L$15 -> 39.48952 | W31: =$L$14 -> 18.68
B32: 14 | C32: 46481 | D32: Massa 04/04 | E32: 397 | F32: 402 | G32: 379 | H32: 388 | I32: 390 | L32: =IF(COUNT(E32:I32)=5,AVERAGE(E32:I32),"") -> 391.2 | M32: =IF(COUNT(E32:I32)=5,MAX(E32:I32)-MIN(E32:I32),"") -> 23 | N32: =IF(L32="","",IF(J32="Sim","Excluído",IF(OR($E$14="",B32<=$E$14),"Base","Acompanhamento"))) -> Base | O32: =IF(OR(COUNT(E32:I32)=0,$E$12="",$E$13=""),"",COUNTIF(E32:I32,"<"&$E$12)+COUNTIF(E32:I32,">"&$E$13)) -> 1 | P32: =IF(OR(L32="",$L$11=""),"",IF(OR(L32>$L$12,L32<$L$13),"Média fora dos limites",IF(M32>$L$15,"Amplitude fora do limite",IF(OR(COUNTIF(L26:L32,">"&$L$11)=7,COUNTIF(L26:L32,"<"&$L$11)=7),"7 do mesmo lado",IF(AND(COUNT(L27:L32)=6,OR(AND(L32>L31,L31>L30,L30>L29,L29>L28,L28>L27),AND(L32<L31,L31<L30,L30<L29,L29<L28,L28<L27))),"6 subindo ou descendo",""))))) | Q32: =IF(COUNT(E32:I32)+LEN(C32)+LEN(D32)+LEN(J32)=0,"",IF(AND(COUNT(E32:I32)>0,COUNT(E32:I32)<5),"Faltam medições",IF(AND(COUNT(E32:I32)>0,C32=""),"Falta a data",IF(AND(J32="Sim",K32=""),"Falta o motivo",IF(COUNT(E32:I32)=0,"Faltam medições","OK"))))) -> OK | S32: =$L$12 -> 411.08236 | T32: =$L$11 -> 400.304 | U32: =$L$13 -> 389.52564 | V32: =$L$15 -> 39.48952 | W32: =$L$14 -> 18.68
B33: 15 | C33: 46482 | D33: Massa 05/04 | E33: 413 | F33: 406 | G33: 397 | H33: 407 | I33: 402 | L33: =IF(COUNT(E33:I33)=5,AVERAGE(E33:I33),"") -> 405 | M33: =IF(COUNT(E33:I33)=5,MAX(E33:I33)-MIN(E33:I33),"") -> 16 | N33: =IF(L33="","",IF(J33="Sim","Excluído",IF(OR($E$14="",B33<=$E$14),"Base","Acompanhamento"))) -> Base | O33: =IF(OR(COUNT(E33:I33)=0,$E$12="",$E$13=""),"",COUNTIF(E33:I33,"<"&$E$12)+COUNTIF(E33:I33,">"&$E$13)) -> 0 | P33: =IF(OR(L33="",$L$11=""),"",IF(OR(L33>$L$12,L33<$L$13),"Média fora dos limites",IF(M33>$L$15,"Amplitude fora do limite",IF(OR(COUNTIF(L27:L33,">"&$L$11)=7,COUNTIF(L27:L33,"<"&$L$11)=7),"7 do mesmo lado",IF(AND(COUNT(L28:L33)=6,OR(AND(L33>L32,L32>L31,L31>L30,L30>L29,L29>L28),AND(L33<L32,L32<L31,L31<L30,L30<L29,L29<L28))),"6 subindo ou descendo",""))))) | Q33: =IF(COUNT(E33:I33)+LEN(C33)+LEN(D33)+LEN(J33)=0,"",IF(AND(COUNT(E33:I33)>0,COUNT(E33:I33)<5),"Faltam medições",IF(AND(COUNT(E33:I33)>0,C33=""),"Falta a data",IF(AND(J33="Sim",K33=""),"Falta o motivo",IF(COUNT(E33:I33)=0,"Faltam medições","OK"))))) -> OK | S33: =$L$12 -> 411.08236 | T33: =$L$11 -> 400.304 | U33: =$L$13 -> 389.52564 | V33: =$L$15 -> 39.48952 | W33: =$L$14 -> 18.68
B34: 16 | C34: 46483 | D34: Massa 06/04 | E34: 387 | F34: 396 | G34: 407 | H34: 397 | I34: 419 | L34: =IF(COUNT(E34:I34)=5,AVERAGE(E34:I34),"") -> 401.2 | M34: =IF(COUNT(E34:I34)=5,MAX(E34:I34)-MIN(E34:I34),"") -> 32 | N34: =IF(L34="","",IF(J34="Sim","Excluído",IF(OR($E$14="",B34<=$E$14),"Base","Acompanhamento"))) -> Base | O34: =IF(OR(COUNT(E34:I34)=0,$E$12="",$E$13=""),"",COUNTIF(E34:I34,"<"&$E$12)+COUNTIF(E34:I34,">"&$E$13)) -> 0 | P34: =IF(OR(L34="",$L$11=""),"",IF(OR(L34>$L$12,L34<$L$13),"Média fora dos limites",IF(M34>$L$15,"Amplitude fora do limite",IF(OR(COUNTIF(L28:L34,">"&$L$11)=7,COUNTIF(L28:L34,"<"&$L$11)=7),"7 do mesmo lado",IF(AND(COUNT(L29:L34)=6,OR(AND(L34>L33,L33>L32,L32>L31,L31>L30,L30>L29),AND(L34<L33,L33<L32,L32<L31,L31<L30,L30<L29))),"6 subindo ou descendo",""))))) | Q34: =IF(COUNT(E34:I34)+LEN(C34)+LEN(D34)+LEN(J34)=0,"",IF(AND(COUNT(E34:I34)>0,COUNT(E34:I34)<5),"Faltam medições",IF(AND(COUNT(E34:I34)>0,C34=""),"Falta a data",IF(AND(J34="Sim",K34=""),"Falta o motivo",IF(COUNT(E34:I34)=0,"Faltam medições","OK"))))) -> OK | S34: =$L$12 -> 411.08236 | T34: =$L$11 -> 400.304 | U34: =$L$13 -> 389.52564 | V34: =$L$15 -> 39.48952 | W34: =$L$14 -> 18.68
B35: 17 | C35: 46484 | D35: Massa 07/04 | E35: 396 | F35: 397 | G35: 398 | H35: 400 | I35: 400 | L35: =IF(COUNT(E35:I35)=5,AVERAGE(E35:I35),"") -> 398.2 | M35: =IF(COUNT(E35:I35)=5,MAX(E35:I35)-MIN(E35:I35),"") -> 4 | N35: =IF(L35="","",IF(J35="Sim","Excluído",IF(OR($E$14="",B35<=$E$14),"Base","Acompanhamento"))) -> Base | O35: =IF(OR(COUNT(E35:I35)=0,$E$12="",$E$13=""),"",COUNTIF(E35:I35,"<"&$E$12)+COUNTIF(E35:I35,">"&$E$13)) -> 0 | P35: =IF(OR(L35="",$L$11=""),"",IF(OR(L35>$L$12,L35<$L$13),"Média fora dos limites",IF(M35>$L$15,"Amplitude fora do limite",IF(OR(COUNTIF(L29:L35,">"&$L$11)=7,COUNTIF(L29:L35,"<"&$L$11)=7),"7 do mesmo lado",IF(AND(COUNT(L30:L35)=6,OR(AND(L35>L34,L34>L33,L33>L32,L32>L31,L31>L30),AND(L35<L34,L34<L33,L33<L32,L32<L31,L31<L30))),"6 subindo ou descendo",""))))) | Q35: =IF(COUNT(E35:I35)+LEN(C35)+LEN(D35)+LEN(J35)=0,"",IF(AND(COUNT(E35:I35)>0,COUNT(E35:I35)<5),"Faltam medições",IF(AND(COUNT(E35:I35)>0,C35=""),"Falta a data",IF(AND(J35="Sim",K35=""),"Falta o motivo",IF(COUNT(E35:I35)=0,"Faltam medições","OK"))))) -> OK | S35: =$L$12 -> 411.08236 | T35: =$L$11 -> 400.304 | U35: =$L$13 -> 389.52564 | V35: =$L$15 -> 39.48952 | W35: =$L$14 -> 18.68
B36: 18 | C36: 46485 | D36: Massa 08/04 | E36: 411 | F36: 417 | G36: 398 | H36: 387 | I36: 397 | L36: =IF(COUNT(E36:I36)=5,AVERAGE(E36:I36),"") -> 402 | M36: =IF(COUNT(E36:I36)=5,MAX(E36:I36)-MIN(E36:I36),"") -> 30 | N36: =IF(L36="","",IF(J36="Sim","Excluído",IF(OR($E$14="",B36<=$E$14),"Base","Acompanhamento"))) -> Base | O36: =IF(OR(COUNT(E36:I36)=0,$E$12="",$E$13=""),"",COUNTIF(E36:I36,"<"&$E$12)+COUNTIF(E36:I36,">"&$E$13)) -> 0 | P36: =IF(OR(L36="",$L$11=""),"",IF(OR(L36>$L$12,L36<$L$13),"Média fora dos limites",IF(M36>$L$15,"Amplitude fora do limite",IF(OR(COUNTIF(L30:L36,">"&$L$11)=7,COUNTIF(L30:L36,"<"&$L$11)=7),"7 do mesmo lado",IF(AND(COUNT(L31:L36)=6,OR(AND(L36>L35,L35>L34,L34>L33,L33>L32,L32>L31),AND(L36<L35,L35<L34,L34<L33,L33<L32,L32<L31))),"6 subindo ou descendo",""))))) | Q36: =IF(COUNT(E36:I36)+LEN(C36)+LEN(D36)+LEN(J36)=0,"",IF(AND(COUNT(E36:I36)>0,COUNT(E36:I36)<5),"Faltam medições",IF(AND(COUNT(E36:I36)>0,C36=""),"Falta a data",IF(AND(J36="Sim",K36=""),"Falta o motivo",IF(COUNT(E36:I36)=0,"Faltam medições","OK"))))) -> OK | S36: =$L$12 -> 411.08236 | T36: =$L$11 -> 400.304 | U36: =$L$13 -> 389.52564 | V36: =$L$15 -> 39.48952 | W36: =$L$14 -> 18.68
... B43: 25 | C43: 46492 | D43: Massa 15/04 | E43: 416 | F43: 399 | G43: 395 | H43: 402 | I43: 416 | L43: =IF(COUNT(E43:I43)=5,AVERAGE(E43:I43),"") -> 405.6 | M43: =IF(COUNT(E43:I43)=5,MAX(E43:I43)-MIN(E43:I43),"") -> 21 | N43: =IF(L43="","",IF(J43="Sim","Excluído",IF(OR($E$14="",B43<=$E$14),"Base","Acompanhamento"))) -> Base | O43: =IF(OR(COUNT(E43:I43)=0,$E$12="",$E$13=""),"",COUNTIF(E43:I43,"<"&$E$12)+COUNTIF(E43:I43,">"&$E$13)) -> 0 | P43: =IF(OR(L43="",$L$11=""),"",IF(OR(L43>$L$12,L43<$L$13),"Média fora dos limites",IF(M43>$L$15,"Amplitude fora do limite",IF(OR(COUNTIF(L37:L43,">"&$L$11)=7,COUNTIF(L37:L43,"<"&$L$11)=7),"7 do mesmo lado",IF(AND(COUNT(L38:L43)=6,OR(AND(L43>L42,L42>L41,L41>L40,L40>L39,L39>L38),AND(L43<L42,L42<L41,L41<L40,L40<L39,L39<L38))),"6 subindo ou descendo",""))))) | Q43: =IF(COUNT(E43:I43)+LEN(C43)+LEN(D43)+LEN(J43)=0,"",IF(AND(COUNT(E43:I43)>0,COUNT(E43:I43)<5),"Faltam medições",IF(AND(COUNT(E43:I43)>0,C43=""),"Falta a data",IF(AND(J43="Sim",K43=""),"Falta o motivo",IF(COUNT(E43:I43)=0,"Faltam medições","OK"))))) -> OK | S43: =$L$12 -> 411.08236 | T43: =$L$11 -> 400.304 | U43: =$L$13 -> 389.52564 | V43: =$L$15 -> 39.48952 | W43: =$L$14 -> 18.68
B45: Gráficos de controle
B61: Resumo automático
B62: Indicador | E62: Resultado | G62: Como se lê
B63: SUBGRUPOS
