Workbook

Sheet Instruções
B1: Partes interessadas — Como usar esta planilha
B2: Modelo para listar as partes interessadas, avaliar a influência e o interesse, registrar os requisitos e acompanhar o atendimento.
B4: Legenda: onde preencher
B5: Amarelo-claro | C5: Células de entrada. É aqui que você digita.
B6: Cinza | C6: Células calculadas ou fixas (rótulos, estratégias, conferências, contagens, avisos). Não altere.
B7: Cinza em itálico | C7: Linha de exemplo (marcada com “Ex.”). Mostra o formato esperado e não entra nas contagens.
B8: Listas suspensas | C8: Grupo, requisito legal, parte, tipo, adotado, situação e status aceitam apenas as opções da lista. As notas aceitam números de 1 a 5.
B9: Comentários | C9: Células com triângulo vermelho no canto trazem uma dica de preenchimento. Passe o mouse sobre elas.
B11: As regras de cálculo
B12: Notas | C12: Influência: o quanto a parte pode ajudar ou parar a operação. Interesse: o quanto ela acompanha e cobra. De 1 a 5. Nota 4 ou 5 conta como alta.
B13: Estratégia | C13: Influência alta e interesse alto: gerir de perto. Influência alta e interesse baixo: manter satisfeito. Influência baixa e interesse alto: manter informado. As duas baixas: monitorar.
B14: Pertinente | C14: É pertinente ao sistema a parte que fica fora do quadrante de monitorar, e a que tem requisito legal. Toda parte pertinente pede pelo menos um requisito.
B15: Tipo do requisito | C15: Legal: vem de lei, regulamento ou licença. Contratual: vem de contrato, pedido ou promessa. Expectativa: a organização decide se adota.
B16: Atendimento | C16: Pontos dos requisitos adotados: 1 para atende, 0,5 para atende em parte, 0 para não atende. Atendimento = pontos ÷ requisitos adotados.
B17: Ações | C17: Todo requisito adotado que não atende por completo pede ação, responsável e prazo. A ação vencida é a que tem prazo anterior à data da análise.
B19: Ordem recomendada de preenchimento
B20: Passo 1 | C20: Aba Partes: liste as partes, grupo por grupo, e escreva por que cada uma importa. Dê as notas e marque as que têm requisito legal.
B21: Passo 2 | C21: Aba Partes: para cada parte pertinente, escreva o canal de relacionamento e quem cuida dele.
B22: Passo 3 | C22: Aba Requisitos: escreva o que cada parte pertinente espera, com o tipo. Decida se cada expectativa é adotada.
B23: Passo 4 | C23: Aba Requisitos: ligue cada requisito adotado a um processo e a uma forma de monitorar. Avalie a situação e defina as ações.
B24: Passo 5 | C24: Abas Matriz e Painel: leia quem está em cada quadrante e que parte é atendida pior.
B25: Passo 6 | C25: Aba Checklist: valide a análise.
B27: Abas da planilha
B28: Partes | C28: Até 12 partes interessadas, com grupo, motivo, notas, canal e quem cuida. Calcula a estratégia e a pertinência.
B29: Requisitos | C29: Até 40 requisitos, com tipo, decisão, processo, monitoramento, situação e ação. Confere cada linha.
B30: Matriz | C30: A grade de influência e interesse, com a contagem de partes, e as partes de cada estratégia.
B31: Painel | C31: Os indicadores gerais, os requisitos e o atendimento de cada parte, e o gráfico.
B32: Checklist | C32: Doze verificações de qualidade da análise, com percentual de conclusão.
B33: Exemplo 1 - Pizzaria | C33: As onze partes e os dezesseis requisitos da loja.
B34: Exemplo 2 - Indústria | C34: As doze partes e os dezesseis requisitos da fábrica.
B36: Regras e premissas do modelo
B37: Nome da parte | C37: Na aba Requisitos, a parte é escolhida na lista da aba Partes. Se o nome mudar na aba Partes, escolha de novo na aba Requisitos.
B38: Partes parecidas | C38: O modelo aceita 12 partes. Agrupe as que esperam a mesma coisa: “clientes de alimentos”, e não um cliente por linha.
B39: Expectativa recusada | C39: Registre também a expectativa que não foi adotada, com o motivo na coluna “Como atende, ou por que não adota”.
B40: Exemplos | C40: Os dados das abas de exemplo são ilustrativos, criados para este material.

Sheet Partes
B1: Partes interessadas
B2: Liste quem afeta a organização e quem é afetado por ela. A estratégia e a pertinência saem das notas.
B4: Organização
B5: Data e responsáveis pela análise
B6: Escopo: o que a análise cobre
B8: # | C8: Parte interessada | D8: Grupo | E8: Por que importa | F8: Influência | G8: Interesse | H8: Requisito legal? | I8: Estratégia | J8: Pertinente | K8: Relacionamento: canal e frequência | L8: Quem cuida | M8: Conferência | O8: Chave: não altere
C9: Nome concreto | D9: Escolha na lista | E9: Como afeta, ou como é afetada | F9: 1 a 5 | G9: 1 a 5 | H9: Sim ou Não | I9: Calculada | J9: Calculada | K9: Para as partes pertinentes | L9: Função | M9: Calculada
B10: Ex. | C10: Vigilância sanitária | D10: Regulador | E10: Licencia e fiscaliza. Pode interditar a loja. | F10: 5 | G10: 2 | H10: Sim | I10: Manter satisfeito | J10: Sim | K10: Renovação anual da licença e visitas de fiscalização. | L10: Gerente da loja | M10: OK
B11: 1 | I11: =IF(OR(F11="",G11=""),"",IF(F11>=4,IF(G11>=4,"Gerir de perto","Manter satisfeito"),IF(G11>=4,"Manter informado","Monitorar"))) | J11: =IF(I11="","",IF(OR(I11<>"Monitorar",H11="Sim"),"Sim","Não")) | M11: =IF(C11="","",IF(COUNTIF(C$11:C$22,C11)>1,"Parte repetida",IF(OR(F11="",G11=""),"Faltam as notas",IF(E11="","Falta o motivo",IF(J11<>"Sim","OK",IF(K11="","Falta o canal de relacionamento",IF(COUNTIF(Requisitos!C$7:C$46,C11)=0,"Parte pertinente sem requisito","OK"))))))) | O11: =IF(OR(C11="",I11=""),"",I11&"|"&COUNTIFS(I$11:I11,I11,C$11:C11,"<>"))
B12: 2 | I12: =IF(OR(F12="",G12=""),"",IF(F12>=4,IF(G12>=4,"Gerir de perto","Manter satisfeito"),IF(G12>=4,"Manter informado","Monitorar"))) | J12: =IF(I12="","",IF(OR(I12<>"Monitorar",H12="Sim"),"Sim","Não")) | M12: =IF(C12="","",IF(COUNTIF(C$11:C$22,C12)>1,"Parte repetida",IF(OR(F12="",G12=""),"Faltam as notas",IF(E12="","Falta o motivo",IF(J12<>"Sim","OK",IF(K12="","Falta o canal de relacionamento",IF(COUNTIF(Requisitos!C$7:C$46,C12)=0,"Parte pertinente sem requisito","OK"))))))) | O12: =IF(OR(C12="",I12=""),"",I12&"|"&COUNTIFS(I$11:I12,I12,C$11:C12,"<>"))
B13: 3 | I13: =IF(OR(F13="",G13=""),"",IF(F13>=4,IF(G13>=4,"Gerir de perto","Manter satisfeito"),IF(G13>=4,"Manter informado","Monitorar"))) | J13: =IF(I13="","",IF(OR(I13<>"Monitorar",H13="Sim"),"Sim","Não")) | M13: =IF(C13="","",IF(COUNTIF(C$11:C$22,C13)>1,"Parte repetida",IF(OR(F13="",G13=""),"Faltam as notas",IF(E13="","Falta o motivo",IF(J13<>"Sim","OK",IF(K13="","Falta o canal de relacionamento",IF(COUNTIF(Requisitos!C$7:C$46,C13)=0,"Parte pertinente sem requisito","OK"))))))) | O13: =IF(OR(C13="",I13=""),"",I13&"|"&COUNTIFS(I$11:I13,I13,C$11:C13,"<>"))
B14: 4 | I14: =IF(OR(F14="",G14=""),"",IF(F14>=4,IF(G14>=4,"Gerir de perto","Manter satisfeito"),IF(G14>=4,"Manter informado","Monitorar"))) | J14: =IF(I14="","",IF(OR(I14<>"Monitorar",H14="Sim"),"Sim","Não")) | M14: =IF(C14="","",IF(COUNTIF(C$11:C$22,C14)>1,"Parte repetida",IF(OR(F14="",G14=""),"Faltam as notas",IF(E14="","Falta o motivo",IF(J14<>"Sim","OK",IF(K14="","Falta o canal de relacionamento",IF(COUNTIF(Requisitos!C$7:C$46,C14)=0,"Parte pertinente sem requisito","OK"))))))) | O14: =IF(OR(C14="",I14=""),"",I14&"|"&COUNTIFS(I$11:I14,I14,C$11:C14,"<>"))
B15: 5 | I15: =IF(OR(F15="",G15=""),"",IF(F15>=4,IF(G15>=4,"Gerir de perto","Manter satisfeito"),IF(G15>=4,"Manter informado","Monitorar"))) | J15: =IF(I15="","",IF(OR(I15<>"Monitorar",H15="Sim"),"Sim","Não")) | M15: =IF(C15="","",IF(COUNTIF(C$11:C$22,C15)>1,"Parte repetida",IF(OR(F15="",G15=""),"Faltam as notas",IF(E15="","Falta o motivo",IF(J15<>"Sim","OK",IF(K15="","Falta o canal de relacionamento",IF(COUNTIF(Requisitos!C$7:C$46,C15)=0,"Parte pertinente sem requisito","OK"))))))) | O15: =IF(OR(C15="",I15=""),"",I15&"|"&COUNTIFS(I$11:I15,I15,C$11:C15,"<>"))
B16: 6 | I16: =IF(OR(F16="",G16=""),"",IF(F16>=4,IF(G16>=4,"Gerir de perto","Manter satisfeito"),IF(G16>=4,"Manter informado","Monitorar"))) | J16: =IF(I16="","",IF(OR(I16<>"Monitorar",H16="Sim"),"Sim","Não")) | M16: =IF(C16="","",IF(COUNTIF(C$11:C$22,C16)>1,"Parte repetida",IF(OR(F16="",G16=""),"Faltam as notas",IF(E16="","Falta o motivo",IF(J16<>"Sim","OK",IF(K16="","Falta o canal de relacionamento",IF(COUNTIF(Requisitos!C$7:C$46,C16)=0,"Parte pertinente sem requisito","OK"))))))) | O16: =IF(OR(C16="",I16=""),"",I16&"|"&COUNTIFS(I$11:I16,I16,C$11:C16,"<>"))
B17: 7 | I17: =IF(OR(F17="",G17=""),"",IF(F17>=4,IF(G17>=4,"Gerir de perto","Manter satisfeito"),IF(G17>=4,"Manter informado","Monitorar"))) | J17: =IF(I17="","",IF(OR(I17<>"Monitorar",H17="Sim"),"Sim","Não")) | M17: =IF(C17="","",IF(COUNTIF(C$11:C$22,C17)>1,"Parte repetida",IF(OR(F17="",G17=""),"Faltam as notas",IF(E17="","Falta o motivo",IF(J17<>"Sim","OK",IF(K17="","Falta o canal de relacionamento",IF(COUNTIF(Requisitos!C$7:C$46,C17)=0,"Parte pertinente sem requisito","OK"))))))) | O17: =IF(OR(C17="",I17=""),"",I17&"|"&COUNTIFS(I$11:I17,I17,C$11:C17,"<>"))
B18: 8 | I18: =IF(OR(F18="",G18=""),"",IF(F18>=4,IF(G18>=4,"Gerir de perto","Manter satisfeito"),IF(G18>=4,"Manter informado","Monitorar"))) | J18: =IF(I18="","",IF(OR(I18<>"Monitorar",H18="Sim"),"Sim","Não")) | M18: =IF(C18="","",IF(COUNTIF(C$11:C$22,C18)>1,"Parte repetida",IF(OR(F18="",G18=""),"Faltam as notas",IF(E18="","Falta o motivo",IF(J18<>"Sim","OK",IF(K18="","Falta o canal de relacionamento",IF(COUNTIF(Requisitos!C$7:C$46,C18)=0,"Parte pertinente sem requisito","OK"))))))) | O18: =IF(OR(C18="",I18=""),"",I18&"|"&COUNTIFS(I$11:I18,I18,C$11:C18,"<>"))
B19: 9 | I19: =IF(OR(F19="",G19=""),"",IF(F19>=4,IF(G19>=4,"Gerir de perto","Manter satisfeito"),IF(G19>=4,"Manter informado","Monitorar"))) | J19: =IF(I19="","",IF(OR(I19<>"Monitorar",H19="Sim"),"Sim","Não")) | M19: =IF(C19="","",IF(COUNTIF(C$11:C$22,C19)>1,"Parte repetida",IF(OR(F19="",G19=""),"Faltam as notas",IF(E19="","Falta o motivo",IF(J19<>"Sim","OK",IF(K19="","Falta o canal de relacionamento",IF(COUNTIF(Requisitos!C$7:C$46,C19)=0,"Parte pertinente sem requisito","OK"))))))) | O19: =IF(OR(C19="",I19=""),"",I19&"|"&COUNTIFS(I$11:I19,I19,C$11:C19,"<>"))
B20: 10 | I20: =IF(OR(F20="",G20=""),"",IF(F20>=4,IF(G20>=4,"Gerir de perto","Manter satisfeito"),IF(G20>=4,"Manter informado","Monitorar"))) | J20: =IF(I20="","",IF(OR(I20<>"Monitorar",H20="Sim"),"Sim","Não")) | M20: =IF(C20="","",IF(COUNTIF(C$11:C$22,C20)>1,"Parte repetida",IF(OR(F20="",G20=""),"Faltam as notas",IF(E20="","Falta o motivo",IF(J20<>"Sim","OK",IF(K20="","Falta o canal de relacionamento",IF(COUNTIF(Requisitos!C$7:C$46,C20)=0,"Parte pertinente sem requisito","OK"))))))) | O20: =IF(OR(C20="",I20=""),"",I20&"|"&COUNTIFS(I$11:I20,I20,C$11:C20,"<>"))
B21: 11 | I21: =IF(OR(F21="",G21=""),"",IF(F21>=4,IF(G21>=4,"Gerir de perto","Manter satisfeito"),IF(G21>=4,"Manter informado","Monitorar"))) | J21: =IF(I21="","",IF(OR(I21<>"Monitorar",H21="Sim"),"Sim","Não")) | M21: =IF(C21="","",IF(COUNTIF(C$11:C$22,C21)>1,"Parte repetida",IF(OR(F21="",G21=""),"Faltam as notas",IF(E21="","Falta o motivo",IF(J21<>"Sim","OK",IF(K21="","Falta o canal de relacionamento",IF(COUNTIF(Requisitos!C$7:C$46,C21)=0,"Parte pertinente sem requisito","OK"))))))) | O21: =IF(OR(C21="",I21=""),"",I21&"|"&COUNTIFS(I$11:I21,I21,C$11:C21,"<>"))
B22: 12 | I22: =IF(OR(F22="",G22=""),"",IF(F22>=4,IF(G22>=4,"Gerir de perto","Manter satisfeito"),IF(G22>=4,"Manter informado","Monitorar"))) | J22: =IF(I22="","",IF(OR(I22<>"Monitorar",H22="Sim"),"Sim","Não")) | M22: =IF(C22="","",IF(COUNTIF(C$11:C$22,C22)>1,"Parte repetida",IF(OR(F22="",G22=""),"Faltam as notas",IF(E22="","Falta o motivo",IF(J22<>"Sim","OK",IF(K22="","Falta o canal de relacionamento",IF(COUNTIF(Requisitos!C$7:C$46,C22)=0,"Parte pertinente sem requisito","OK"))))))) | O22: =IF(OR(C22="",I22=""),"",I22&"|"&COUNTIFS(I$11:I22,I22,C$11:C22,"<>"))
B24: Resumo automático
B25: Partes listadas | E25: =COUNTA(C11:C22) -> 0
B26: Partes pertinentes ao sistema | E26: =COUNTIF(J11:J22,"Sim") -> 0
B27: Por estratégia | E27: =IF(E25=0,"",COUNTIF(I11:I22,"Gerir de perto")&" gerir de perto"&", "&COUNTIF(I11:I22,"Manter satisfeito")&" manter satisfeito"&", "&COUNTIF(I11:I22,"Manter informado")&" manter informado"&", "&COUNTIF(I11:I22,"Monitorar")&" monitorar")
B28: Aviso | E28: =IF(E25=0,"Liste as partes interessadas",IF(COUNTIF(M11:M22,"OK")<E25,"Há parte a rever: veja a coluna Conferência",IF(E25<5,"Poucas partes: percorra os seis grupos","OK"))) -> Liste as partes interessadas

Sheet Requisitos
B1: Requisitos das partes interessadas
B2: Uma linha por necessidade ou expectativa. O que é legal ou contratual entra sempre. A expectativa entra por decisão.
B4: # | C4: Parte interessada | D4: O que espera | E4: Tipo | F4: Adotado? | G4: Como atende, ou por que não adota | H4: Como se monitora | I4: Situação | J4: Ação | K4: Responsável | L4: Prazo | M4: Conferência
C5: Da lista da aba Partes | D5: Com verbo e critério | E5: Escolha na lista | F5: Sim ou Não | G5: Processo ou documento, ou a justificativa | H5: Fonte e frequência | I5: Escolha na lista | J5: Se não atende por completo | K5: Função | L5: Data | M5: Calculada
B6: Ex. | C6: Vigilância sanitária | D6: Manter a licença sanitária válida. | E6: Legal | F6: Sim | G6: Renovação protocolada em 09/10/2026. | H6: Controle de vencimentos das licenças, todo mês. | I6: Atende em parte | J6: Acompanhar o protocolo até a emissão da licença. | K6: Gerente da loja | L6: 46339 | M6: OK
B7: 1 | M7: =IF(D7="","",IF(C7="","Falta a parte",IF(E7="","Falta o tipo",IF(F7="","Decida se é adotado",IF(AND(E7<>"Expectativa",F7="Não"),"Legal ou contratual não pode ser recusado",IF(F7="Não",IF(G7="","Falta a justificativa","Não adotado"),IF(G7="","Falta como atende",IF(H7="","Falta o monitoramento",IF(I7="","Falta a situação",IF(I7="Atende","OK",IF(J7="","Falta a ação",IF(OR(K7="",L7=""),"Ação sem responsável ou prazo","OK"))))))))))))
B8: 2 | M8: =IF(D8="","",IF(C8="","Falta a parte",IF(E8="","Falta o tipo",IF(F8="","Decida se é adotado",IF(AND(E8<>"Expectativa",F8="Não"),"Legal ou contratual não pode ser recusado",IF(F8="Não",IF(G8="","Falta a justificativa","Não adotado"),IF(G8="","Falta como atende",IF(H8="","Falta o monitoramento",IF(I8="","Falta a situação",IF(I8="Atende","OK",IF(J8="","Falta a ação",IF(OR(K8="",L8=""),"Ação sem responsável ou prazo","OK"))))))))))))
B9: 3 | M9: =IF(D9="","",IF(C9="","Falta a parte",IF(E9="","Falta o tipo",IF(F9="","Decida se é adotado",IF(AND(E9<>"Expectativa",F9="Não"),"Legal ou contratual não pode ser recusado",IF(F9="Não",IF(G9="","Falta a justificativa","Não adotado"),IF(G9="","Falta como atende",IF(H9="","Falta o monitoramento",IF(I9="","Falta a situação",IF(I9="Atende","OK",IF(J9="","Falta a ação",IF(OR(K9="",L9=""),"Ação sem responsável ou prazo","OK"))))))))))))
B10: 4 | M10: =IF(D10="","",IF(C10="","Falta a parte",IF(E10="","Falta o tipo",IF(F10="","Decida se é adotado",IF(AND(E10<>"Expectativa",F10="Não"),"Legal ou contratual não pode ser recusado",IF(F10="Não",IF(G10="","Falta a justificativa","Não adotado"),IF(G10="","Falta como atende",IF(H10="","Falta o monitoramento",IF(I10="","Falta a situação",IF(I10="Atende","OK",IF(J10="","Falta a ação",IF(OR(K10="",L10=""),"Ação sem responsável ou prazo","OK"))))))))))))
B11: 5 | M11: =IF(D11="","",IF(C11="","Falta a parte",IF(E11="","Falta o tipo",IF(F11="","Decida se é adotado",IF(AND(E11<>"Expectativa",F11="Não"),"Legal ou contratual não pode ser recusado",IF(F11="Não",IF(G11="","Falta a justificativa","Não adotado"),IF(G11="","Falta como atende",IF(H11="","Falta o monitoramento",IF(I11="","Falta a situação",IF(I11="Atende","OK",IF(J11="","Falta a ação",IF(OR(K11="",L11=""),"Ação sem responsável ou prazo","OK"))))))))))))
B12: 6 | M12: =IF(D12="","",IF(C12="","Falta a parte",IF(E12="","Falta o tipo",IF(F12="","Decida se é adotado",IF(AND(E12<>"Expectativa",F12="Não"),"Legal ou contratual não pode ser recusado",IF(F12="Não",IF(G12="","Falta a justificativa","Não adotado"),IF(G12="","Falta como atende",IF(H12="","Falta o monitoramento",IF(I12="","Falta a situação",IF(I12="Atende","OK",IF(J12="","Falta a ação",IF(OR(K12="",L12=""),"Ação sem responsável ou prazo","OK"))))))))))))
B13: 7 | M13: =IF(D13="","",IF(C13="","Falta a parte",IF(E13="","Falta o tipo",IF(F13="","Decida se é adotado",IF(AND(E13<>"Expectativa",F13="Não"),"Legal ou contratual não pode ser recusado",IF(F13="Não",IF(G13="","Falta a justificativa","Não adotado"),IF(G13="","Falta como atende",IF(H13="","Falta o monitoramento",IF(I13="","Falta a situação",IF(I13="Atende","OK",IF(J13="","Falta a ação",IF(OR(K13="",L13=""),"Ação sem responsável ou prazo","OK"))))))))))))
B14: 8 | M14: =IF(D14="","",IF(C14="","Falta a parte",IF(E14="","Falta o tipo",IF(F14="","Decida se é adotado",IF(AND(E14<>"Expectativa",F14="Não"),"Legal ou contratual não pode ser recusado",IF(F14="Não",IF(G14="","Falta a justificativa","Não adotado"),IF(G14="","Falta como atende",IF(H14="","Falta o monitoramento",IF(I14="","Falta a situação",IF(I14="Atende","OK",IF(J14="","Falta a ação",IF(OR(K14="",L14=""),"Ação sem responsável ou prazo","OK"))))))))))))
B15: 9 | M15: =IF(D15="","",IF(C15="","Falta a parte",IF(E15="","Falta o tipo",IF(F15="","Decida se é adotado",IF(AND(E15<>"Expectativa",F15="Não"),"Legal ou contratual não pode ser recusado",IF(F15="Não",IF(G15="","Falta a justificativa","Não adotado"),IF(G15="","Falta como atende",IF(H15="","Falta o monitoramento",IF(I15="","Falta a situação",IF(I15="Atende","OK",IF(J15="","Falta a ação",IF(OR(K15="",L15=""),"Ação sem responsável ou prazo","OK"))))))))))))
B16: 10 | M16: =IF(D16="","",IF(C16="","Falta a parte",IF(E16="","Falta o tipo",IF(F16="","Decida se é adotado",IF(AND(E16<>"Expectativa",F16="Não"),"Legal ou contratual não pode ser recusado",IF(F16="Não",IF(G16="","Falta a justificativa","Não adotado"),IF(G16="","Falta como atende",IF(H16="","Falta o monitoramento",IF(I16="","Falta a situação",IF(I16="Atende","OK",IF(J16="","Falta a ação",IF(OR(K16="",L16=""),"Ação sem responsável ou prazo","OK"))))))))))))
B17: 11 | M17: =IF(D17="","",IF(C17="","Falta a parte",IF(E17="","Falta o tipo",IF(F17="","Decida se é adotado",IF(AND(E17<>"Expectativa",F17="Não"),"Legal ou contratual não pode ser recusado",IF(F17="Não",IF(G17="","Falta a justificativa","Não adotado"),IF(G17="","Falta como atende",IF(H17="","Falta o monitoramento",IF(I17="","Falta a situação",IF(I17="Atende","OK",IF(J17="","Falta a ação",IF(OR(K17="",L17=""),"Ação sem responsável ou prazo","OK"))))))))))))
B18: 12 | M18: =IF(D18="","",IF(C18="","Falta a parte",IF(E18="","Falta o tipo",IF(F18="","Decida se é adotado",IF(AND(E18<>"Expectativa",F18="Não"),"Legal ou contratual não pode ser recusado",IF(F18="Não",IF(G18="","Falta a justificativa","Não adotado"),IF(G18="","Falta como atende",IF(H18="","Falta o monitoramento",IF(I18="","Falta a situação",IF(I18="Atende","OK",IF(J18="","Falta a ação",IF(OR(K18="",L18=""),"Ação sem responsável ou prazo","OK"))))))))))))
... B46: 40 | M46: =IF(D46="","",IF(C46="","Falta a parte",IF(E46="","Falta o tipo",IF(F46="","Decida se é adotado",IF(AND(E46<>"Expectativa",F46="Não"),"Legal ou contratual não pode ser recusado",IF(F46="Não",IF(G46="","Falta a justificativa","Não adotado"),IF(G46="","Falta como atende",IF(H46="","Falta o monitoramento",IF(I46="","Falta a situação",IF(I46="Atende","OK",IF(J46="","Falta a ação",IF(OR(K46="",L46=""),"Ação sem responsável ou prazo","OK"))))))))))))
B48: Resumo automático
B49: Requisitos levantados | E49: =COUNTA(D7:D46) -> 0
B50: Requisitos adotados | E50: =COUNTIF(F7:F46,"Sim") -> 0
B51: Expectativas não adotadas | E51: =COUNTIF(F7:F46,"Não") -> 0
B52: Atendimento dos requisitos adotados | E52: =IF(COUNTIF(F7:F46,"Sim")=0,"",(COUNTIFS(F7:F46,"Sim",I7:I46,"Atende")+0.5*COUNTIFS(F7:F46,"Sim",I7:I46,"Atende em parte"))/COUNTIF(F7:F46,"Sim"))
B53: Ações abertas | E53: =COUNTIFS(F7:F46,"Sim",I7:I46,"Atende em parte")+COUNTIFS(F7:F46,"Sim",I7:I46,"Não atende") -> 0
B54: Aviso | E54: =IF(E49=0,"Registre os requisitos",IF(COUNTIF(M7:M46,"OK")+COUNTIF(M7:M46,"Não adotado")<E49,"Há requisito a rever: veja a coluna Conferência",IF(COUNTIFS(E7:E46,"Legal",I7:I46,"Não atende")>0,"Há requisito legal não atendido",IF(COUNTIF(Partes!M11:M22,"Parte pertinente sem requisito")>0,"Há parte pertinente sem requisito: veja a aba Partes","OK")))) -> Registre os requisitos

Sheet Matriz
B1: Matriz de influência e interesse
B2: Quantas partes há em cada célula. A cor mostra a estratégia. Tudo vem da aba Partes.
D4: INTERESSE →
B5: INFLUÊNCIA ↓ | D5: 1 | E5: 2 | F5: 3 | G5: 4 | H5: 5
B6: Alta | C6: 5 | D6: =IF(COUNTIFS(Partes!$F$11:$F$22,5,Partes!$G$11:$G$22,1)=0,"",COUNTIFS(Partes!$F$11:$F$22,5,Partes!$G$11:$G$22,1)) | E6: =IF(COUNTIFS(Partes!$F$11:$F$22,5,Partes!$G$11:$G$22,2)=0,"",COUNTIFS(Partes!$F$11:$F$22,5,Partes!$G$11:$G$22,2)) | F6: =IF(COUNTIFS(Partes!$F$11:$F$22,5,Partes!$G$11:$G$22,3)=0,"",COUNTIFS(Partes!$F$11:$F$22,5,Partes!$G$11:$G$22,3)) | G6: =IF(COUNTIFS(Partes!$F$11:$F$22,5,Partes!$G$11:$G$22,4)=0,"",COUNTIFS(Partes!$F$11:$F$22,5,Partes!$G$11:$G$22,4)) | H6: =IF(COUNTIFS(Partes!$F$11:$F$22,5,Partes!$G$11:$G$22,5)=0,"",COUNTIFS(Partes!$F$11:$F$22,5,Partes!$G$11:$G$22,5))
B7: Alta | C7: 4 | D7: =IF(COUNTIFS(Partes!$F$11:$F$22,4,Partes!$G$11:$G$22,1)=0,"",COUNTIFS(Partes!$F$11:$F$22,4,Partes!$G$11:$G$22,1)) | E7: =IF(COUNTIFS(Partes!$F$11:$F$22,4,Partes!$G$11:$G$22,2)=0,"",COUNTIFS(Partes!$F$11:$F$22,4,Partes!$G$11:$G$22,2)) | F7: =IF(COUNTIFS(Partes!$F$11:$F$22,4,Partes!$G$11:$G$22,3)=0,"",COUNTIFS(Partes!$F$11:$F$22,4,Partes!$G$11:$G$22,3)) | G7: =IF(COUNTIFS(Partes!$F$11:$F$22,4,Partes!$G$11:$G$22,4)=0,"",COUNTIFS(Partes!$F$11:$F$22,4,Partes!$G$11:$G$22,4)) | H7: =IF(COUNTIFS(Partes!$F$11:$F$22,4,Partes!$G$11:$G$22,5)=0,"",COUNTIFS(Partes!$F$11:$F$22,4,Partes!$G$11:$G$22,5))
B8: Baixa | C8: 3 | D8: =IF(COUNTIFS(Partes!$F$11:$F$22,3,Partes!$G$11:$G$22,1)=0,"",COUNTIFS(Partes!$F$11:$F$22,3,Partes!$G$11:$G$22,1)) | E8: =IF(COUNTIFS(Partes!$F$11:$F$22,3,Partes!$G$11:$G$22,2)=0,"",COUNTIFS(Partes!$F$11:$F$22,3,Partes!$G$11:$G$22,2)) | F8: =IF(COUNTIFS(Partes!$F$11:$F$22,3,Partes!$G$11:$G$22,3)=0,"",COUNTIFS(Partes!$F$11:$F$22,3,Partes!$G$11:$G$22,3)) | G8: =IF(COUNTIFS(Partes!$F$11:$F$22,3,Partes!$G$11:$G$22,4)=0,"",COUNTIFS(Partes!$F$11:$F$22,3,Partes!$G$11:$G$22,4)) | H8: =IF(COUNTIFS(Partes!$F$11:$F$22,3,Partes!$G$11:$G$22,5)=0,"",COUNTIFS(Partes!$F$11:$F$22,3,Partes!$G$11:$G$22,5))
B9: Baixa | C9: 2 | D9: =IF(COUNTIFS(Partes!$F$11:$F$22,2,Partes!$G$11:$G$22,1)=0,"",COUNTIFS(Partes!$F$11:$F$22,2,Partes!$G$11:$G$22,1)) | E9: =IF(COUNTIFS(Partes!$F$11:$F$22,2,Partes!$G$11:$G$22,2)=0,"",COUNTIFS(Partes!$F$11:$F$22,2,Partes!$G$11:$G$22,2)) | F9: =IF(COUNTIFS(Partes!$F$11:$F$22,2,Partes!$G$11:$G$22,3)=0,"",COUNTIFS(Partes!$F$11:$F$22,2,Partes!$G$11:$G$22,3)) | G9: =IF(COUNTIFS(Partes!$F$11:$F$22,2,Partes!$G$11:$G$22,4)=0,"",COUNTIFS(Partes!$F$11:$F$22,2,Partes!$G$11:$G$22,4)) | H9: =IF(COUNTIFS(Partes!$F$11:$F$22,2,Partes!$G$11:$G$22,5)=0,"",COUNTIFS(Partes!$F$11:$F$22,2,Partes!$G$11:$G$22,5))
B10: Baixa | C10: 1 | D10: =IF(COUNTIFS(Partes!$F$11:$F$22,1,Partes!$G$11:$G$22,1)=0,"",COUNTIFS(Partes!$F$11:$F$22,1,Partes!$G$11:$G$22,1)) | E10: =IF(COUNTIFS(Partes!$F$11:$F$22,1,Partes!$G$11:$G$22,2)=0,"",COUNTIFS(Partes!$F$11:$F$22,1,Partes!$G$11:$G$22,2)) | F10: =IF(COUNTIFS(Partes!$F$11:$F$22,1,Partes!$G$11:$G$22,3)=0,"",COUNTIFS(Partes!$F$11:$F$22,1,Partes!$G$11:$G$22,3)) | G10: =IF(COUNTIFS(Partes!$F$11:$F$22,1,Partes!$G$11:$G$22,4)=0,"",COUNTIFS(Partes!$F$11:$F$22,1,Partes!$G$11:$G$22,4)) | H10: =IF(COUNTIFS(Partes!$F$11:$F$22,1,Partes!$G$11:$G$22,5)=0,"",COUNTIFS(Partes!$F$11:$F$22,1,Partes!$G$11:$G$22,5))
D11: Baixo | E11: Baixo | F11: Baixo | G11: Alto | H11: Alto
B13: As partes de cada estratégia
B14: Estratégia | D14: Partes | E14: Quem são
B15: Gerir de perto | D15: =COUNTIF(Partes!$I$11:$I$22,"Gerir de perto") -> 0 | E15: =IFERROR(INDEX(Partes!$C$11:$C$22,MATCH("Gerir de perto|1",Partes!$O$11:$O$22,0)),"")&IFERROR("; "&INDEX(Partes!$C$11:$C$22,MATCH("Gerir de perto|2",Partes!$O$11:$O$22,0)),"")&IFERROR("; "&INDEX(Partes!$C$11:$C$22,MATCH("Gerir de perto|3",Partes!$O$11:$O$22,0)),"")&IFERROR("; "&INDEX(Partes!$C$11:$C$22,MATCH("Gerir de perto|4",Partes!$O$11:$O$22,0)),"")&IFERROR("; "&INDEX(Partes!$C$11:$C$22,MATCH("Gerir de perto|5",Partes!$O$11:$O$22,0)),"")&IFERROR("; "&INDEX(Partes!$C$11:$C$22,MATCH("Gerir de perto|6",Partes!$O$11:$O$22,0)),"")&IFERROR("; "&INDEX(Partes!$C$11:$C$22,MATCH("Gerir de perto|7",Partes!$O$11:$O$22,0)),"")&IFERROR("; "&INDEX(Partes!$C$11:$C$22,MATCH("Gerir de perto|8",Partes!$O$11:$O$22,0)),"")&IFERROR("; "&INDEX(Partes!$C$11:$C$22,MATCH("Gerir de perto|9",Partes!$O$11:$O$22,0)),"")&IFERROR("; "&INDEX(Partes!$C$11:$C$22,MATCH("Gerir de perto|10",Partes!$O$11:$O$22,0)),"")&IFERROR("; "&INDEX(Partes!$C$11:$C$22,MATCH("Gerir de perto|11",Partes!$O$11:$O$22,0)),"")&IFERROR("; "&INDEX(Partes!$C$11:$C$22,MATCH("Gerir de perto|12",Partes!$O$11:$O$22,0)),"")
B16: Manter satisfeito | D16: =COUNTIF(Partes!$I$11:$I$22,"Manter satisfeito") -> 0 | E16: =IFERROR(INDEX(Partes!$C$11:$C$22,MATCH("Manter satisfeito|1",Partes!$O$11:$O$22,0)),"")&IFERROR("; "&INDEX(Partes!$C$11:$C$22,MATCH("Manter satisfeito|2",Partes!$O$11:$O$22,0)),"")&IFERROR("; "&INDEX(Partes!$C$11:$C$22,MATCH("Manter satisfeito|3",Partes!$O$11:$O$22,0)),"")&IFERROR("; "&INDEX(Partes!$C$11:$C$22,MATCH("Manter satisfeito|4",Partes!$O$11:$O$22,0)),"")&IFERROR("; "&INDEX(Partes!$C$11:$C$22,MATCH("Manter satisfeito|5",Partes!$O$11:$O$22,0)),"")&IFERROR("; "&INDEX(Partes!$C$11:$C$22,MATCH("Manter satisfeito|6",Partes!$O$11:$O$22,0)),"")&IFERROR("; "&INDEX(Partes!$C$11:$C$22,MATCH("Manter satisfeito|7",Partes!$O$11:$O$22,0)),"")&IFERROR("; "&INDEX(Partes!$C$11:$C$22,MATCH("Manter satisfeito|8",Partes!$O$11:$O$22,0)),"")&IFERROR("; "&INDEX(Partes!$C$11:$C$22,MATCH("Manter satisfeito|9",Partes!$O$11:$O$22,0)),"")&IFERROR("; "&INDEX(Partes!$C$11:$C$22,MATCH("Manter satisfeito|10",Partes!$O$11:$O$22,0)),"")&IFERROR("; "&INDEX(Partes!$C$11:$C$22,MATCH("Manter satisfeito|11",Partes!$O$11:$O$22,0)),"")&IFERROR("; "&INDEX(Partes!$C$11:$C$22,MATCH("Manter satisfeito|12",Partes!$O$11:$O$22,0)),"")
B17: Manter informado | D17: =COUNTIF(Partes!$I$11:$I$22,"Manter informado") -> 0 | E17: =IFERROR(INDEX(Partes!$C$11:$C$22,MATCH("Manter informado|1",Partes!$O$11:$O$22,0)),"")&IFERROR("; "&INDEX(Partes!$C$11:$C$22,MATCH("Manter informado|2",Partes!$O$11:$O$22,0)),"")&IFERROR("; "&INDEX(Partes!$C$11:$C$22,MATCH("Manter informado|3",Partes!$O$11:$O$22,0)),"")&IFERROR("; "&INDEX(Partes!$C$11:$C$22,MATCH("Manter informado|4",Partes!$O$11:$O$22,0)),"")&IFERROR("; "&INDEX(Partes!$C$11:$C$22,MATCH("Manter informado|5",Partes!$O$11:$O$22,0)),"")&IFERROR("; "&INDEX(Partes!$C$11:$C$22,MATCH("Manter informado|6",Partes!$O$11:$O$22,0)),"")&IFERROR("; "&INDEX(Partes!$C$11:$C$22,MATCH("Manter informado|7",Partes!$O$11:$O$22,0)),"")&IFERROR("; "&INDEX(Partes!$C$11:$C$22,MATCH("Manter informado|8",Partes!$O$11:$O$22,0)),"")&IFERROR("; "&INDEX(Partes!$C$11:$C$22,MATCH("Manter informado|9",Partes!$O$11:$O$22,0)),"")&IFERROR("; "&INDEX(Partes!$C$11:$C$22,MATCH("Manter informado|10",Partes!$O$11:$O$22,0)),"")&IFERROR("; "&INDEX(Partes!$C$11:$C$22,MATCH("Manter informado|11",Partes!$O$11:$O$22,0)),"")&IFERROR("; "&INDEX(Partes!$C$11:$C$22,MATCH("Manter informado|12",Partes!$O$11:$O$22,0)),"")
B18: Monitorar | D18: =COUNTIF(Partes!$I$11:$I$22,"Monitorar") -> 0 | E18: =IFERROR(INDEX(Partes!$C$11:$C$22,MATCH("Monitorar|1",Partes!$O$11:$O$22,0)),"")&IFERROR("; "&INDEX(Partes!$C$11:$C$22,MATCH("Monitorar|2",Partes!$O$11:$O$22,0)),"")&IFERROR("; "&INDEX(Partes!$C$11:$C$22,MATCH("Monitorar|3",Partes!$O$11:$O$22,0)),"")&IFERROR("; "&INDEX(Partes!$C$11:$C$22,MATCH("Monitorar|4",Partes!$O$11:$O$22,0)),"")&IFERROR("; "&INDEX(Partes!$C$11:$C$22,MATCH("Monitorar|5",Partes!$O$11:$O$22,0)),"")&IFERROR("; "&INDEX(Partes!$C$11:$C$22,MATCH("Monitorar|6",Partes!$O$11:$O$22,0)),"")&IFERROR("; "&INDEX(Partes!$C$11:$C$22,MATCH("Monitorar|7",Partes!$O$11:$O$22,0)),"")&IFERROR("; "&INDEX(Partes!$C$11:$C$22,MATCH("Monitorar|8",Partes!$O$11:$O$22,0)),"")&IFERROR("; "&INDEX(Partes!$C$11:$C$22,MATCH("Monitorar|9",Partes!$O$11:$O$22,0)),"")&IFERROR("; "&INDEX(Partes!$C$11:$C$22,MATCH("Monitorar|10",Partes!$O$11:$O$22,0)),"")&IFERROR("; "&INDEX(Partes!$C$11:$C$22,MATCH("Monitorar|11",Partes!$O$11:$O$22,0)),"")&IFERROR("; "&INDEX(Partes!$C$11:$C$22,MATCH("Monitorar|12",Partes!$O$11:$O$22,0)),"")
B20: O que fazer em cada estratégia
B21: Gerir de perto | D21: Influência alta e interesse alto. Reunir, combinar os requisitos e acompanhar de perto.
B22: Manter satisfeito | D22: Influência alta e interesse baixo. Cumprir o que exige, sem surpresas. Contato pontual.
B23: Manter informado | D23: Influência baixa e interesse alto. Contar o que muda e ouvir. Pode virar aliada ou reclamante.
B24: Monitorar | D24: Influência baixa e interesse baixo. Listar e rever uma vez por ano. Sem requisito no sistema.
B26: Aviso | D26: =IF(COUNT(Partes!F11:F22)=0,"Dê as notas na aba Partes",IF(D15>COUNTA(Partes!C11:C22)/2,"Mais da metade das partes em gerir de perto: reveja as notas",IF(D18=0,"Nenhuma parte só monitorada: a lista pode estar incompleta","OK"))) -> Dê as notas na aba Partes

Sheet Painel
B1: Painel das partes interessadas
B2: Os indicadores gerais e o atendimento de cada parte. Informe só a data da análise.
B4: Data da análise | E4: Usada para contar as ações vencidas.
B6: Indicador | D6: Resultado | E6: Como se lê
B7: Partes listadas | D7: =COUNTA(Partes!C11:C22) -> 0 | E7: Todas as partes da aba Partes.
B8: Partes pertinentes ao sistema | D8: =COUNTIF(Partes!J11:J22,"Sim") -> 0 | E8: Fora do quadrante de monitorar, ou com requisito legal.
B9: Partes pertinentes sem requisito | D9: =COUNTIF(Partes!M11:M22,"Parte pertinente sem requisito") -> 0 | E9: Deve ser zero: toda parte pertinente pede um requisito.
B10: Requisitos adotados | D10: =COUNTIF(Requisitos!F7:F46,"Sim") -> 0 | E10: Legais, contratuais e expectativas adotadas.
B11: Atendimento geral | D11: =IF(Requisitos!E52="","",Requisitos!E52) | E11: Atende vale 1, atende em parte vale 0,5.
B12: Requisitos legais atendidos por completo | D12: =IF(COUNTIFS(Requisitos!E7:E46,"Legal",Requisitos!F7:F46,"Sim")=0,"",COUNTIFS(Requisitos!E7:E46,"Legal",Requisitos!F7:F46,"Sim",Requisitos!I7:I46,"Atende")&" de "&COUNTIFS(Requisitos!E7:E46,"Legal",Requisitos!F7:F46,"Sim")) | E12: O legal em parte tem prazo correndo: acompanhe de perto.
B13: Ações abertas | D13: =Requisitos!E53 -> 0 | E13: Requisitos adotados que não atendem por completo.
B14: Ações vencidas | D14: =IF(D4="","",SUMPRODUCT((Requisitos!F7:F46="Sim")*((Requisitos!I7:I46="Atende em parte")+(Requisitos!I7:I46="Não atende"))*ISNUMBER(Requisitos!L7:L46)*(Requisitos!L7:L46<D4))) | E14: Prazo anterior à data da análise.
B16: Requisitos e atendimento por parte
B17: # | C17: Parte interessada | D17: Estratégia | E17: Pertinente | F17: Requisitos adotados | G17: Atende | H17: Em parte | I17: Não atende | J17: Atendimento | K17: Leitura
B18: 1 | C18: =IF(Partes!C11="","",Partes!C11) | D18: =IF(C18="","",Partes!I11) | E18: =IF(C18="","",Partes!J11) | F18: =IF(C18="","",COUNTIFS(Requisitos!$C$7:$C$46,C18,Requisitos!$F$7:$F$46,"Sim")) | G18: =IF(C18="","",COUNTIFS(Requisitos!$C$7:$C$46,C18,Requisitos!$F$7:$F$46,"Sim",Requisitos!$I$7:$I$46,"Atende")) | H18: =IF(C18="","",COUNTIFS(Requisitos!$C$7:$C$46,C18,Requisitos!$F$7:$F$46,"Sim",Requisitos!$I$7:$I$46,"Atende em parte")) | I18: =IF(C18="","",COUNTIFS(Requisitos!$C$7:$C$46,C18,Requisitos!$F$7:$F$46,"Sim",Requisitos!$I$7:$I$46,"Não atende")) | J18: =IF(OR(C18="",N(F18)=0),"",(G18+0.5*H18)/F18) | K18: =IF(C18="","",IF(E18<>"Sim","Só monitorada",IF(F18=0,"Sem requisito",IF(G18+H18+I18<F18,"Falta avaliar a situação",IF(I18>0,"Há requisito não atendido",IF(H18>0,"Há pendência","Atendida"))))))
B19: 2 | C19: =IF(Partes!C12="","",Partes!C12) | D19: =IF(C19="","",Partes!I12) | E19: =IF(C19="","",Partes!J12) | F19: =IF(C19="","",COUNTIFS(Requisitos!$C$7:$C$46,C19,Requisitos!$F$7:$F$46,"Sim")) | G19: =IF(C19="","",COUNTIFS(Requisitos!$C$7:$C$46,C19,Requisitos!$F$7:$F$46,"Sim",Requisitos!$I$7:$I$46,"Atende")) | H19: =IF(C19="","",COUNTIFS(Requisitos!$C$7:$C$46,C19,Requisitos!$F$7:$F$46,"Sim",Requisitos!$I$7:$I$46,"Atende em parte")) | I19: =IF(C19="","",COUNTIFS(Requisitos!$C$7:$C$46,C19,Requisitos!$F$7:$F$46,"Sim",Requisitos!$I$7:$I$46,"Não atende")) | J19: =IF(OR(C19="",N(F19)=0),"",(G19+0.5*H19)/F19) | K19: =IF(C19="","",IF(E19<>"Sim","Só monitorada",IF(F19=0,"Sem requisito",IF(G19+H19+I19<F19,"Falta avaliar a situação",IF(I19>0,"Há requisito não atendido",IF(H19>0,"Há pendência","Atendida"))))))
B20: 3 | C20: =IF(Partes!C13="","",Partes!C13) | D20: =IF(C20="","",Partes!I13) | E20: =IF(C20="","",Partes!J13) | F20: =IF(C20="","",COUNTIFS(Requisitos!$C$7:$C$46,C20,Requisitos!$F$7:$F$46,"Sim")) | G20: =IF(C20="","",COUNTIFS(Requisitos!$C$7:$C$46,C20,Requisitos!$F$7:$F$46,"Sim",Requisitos!$I$7:$I$46,"Atende")) | H20: =IF(C20="","",COUNTIFS(Requisitos!$C$7:$C$46,C20,Requisitos!$F$7:$F$46,"Sim",Requisitos!$I$7:$I$46,"Atende em parte")) | I20: =IF(C20="","",COUNTIFS(Requisitos!$C$7:$C$46,C20,Requisitos!$F$7:$F$46,"Sim",Requisitos!$I$7:$I$46,"Não atende")) | J20: =IF(OR(C20="",N(F20)=0),"",(G20+0.5*H20)/F20) | K20: =IF(C20="","",IF(E20<>"Sim","Só monitorada",IF(F20=0,"Sem requisito",IF(G20+H20+I20<F20,"Falta avaliar a situação",IF(I20>0,"Há requisito não atendido",IF(H20>0,"Há pendência","Atendida"))))))
B21: 4 | C21: =IF(Partes!C14="","",Partes!C14) | D21: =IF(C21="","",Partes!I14) | E21: =IF(C21="","",Partes!J14) | F21: =IF(C21="","",COUNTIFS(Requisitos!$C$7:$C$46,C21,Requisitos!$F$7:$F$46,"Sim")) | G21: =IF(C21="","",COUNTIFS(Requisitos!$C$7:$C$46,C21,Requisitos!$F$7:$F$46,"Sim",Requisitos!$I$7:$I$46,"Atende")) | H21: =IF(C21="","",COUNTIFS(Requisitos!$C$7:$C$46,C21,Requisitos!$F$7:$F$46,"Sim",Requisitos!$I$7:$I$46,"Atende em parte")) | I21: =IF(C21="","",COUNTIFS(Requisitos!$C$7:$C$46,C21,Requisitos!$F$7:$F$46,"Sim",Requisitos!$I$7:$I$46,"Não atende")) | J21: =IF(OR(C21="",N(F21)=0),"",(G21+0.5*H21)/F21) | K21: =IF(C21="","",IF(E21<>"Sim","Só monitorada",IF(F21=0,"Sem requisito",IF(G21+H21+I21<F21,"Falta avaliar a situação",IF(I21>0,"Há requisito não atendido",IF(H21>0,"Há pendência","Atendida"))))))
B22: 5 | C22: =IF(Partes!C15="","",Partes!C15) | D22: =IF(C22="","",Partes!I15) | E22: =IF(C22="","",Partes!J15) | F22: =IF(C22="","",COUNTIFS(Requisitos!$C$7:$C$46,C22,Requisitos!$F$7:$F$46,"Sim")) | G22: =IF(C22="","",COUNTIFS(Requisitos!$C$7:$C$46,C22,Requisitos!$F$7:$F$46,"Sim",Requisitos!$I$7:$I$46,"Atende")) | H22: =IF(C22="","",COUNTIFS(Requisitos!$C$7:$C$46,C22,Requisitos!$F$7:$F$46,"Sim",Requisitos!$I$7:$I$46,"Atende em parte")) | I22: =IF(C22="","",COUNTIFS(Requisitos!$C$7:$C$46,C22,Requisitos!$F$7:$F$46,"Sim",Requisitos!$I$7:$I$46,"Não atende")) | J22: =IF(OR(C22="",N(F22)=0),"",(G22+0.5*H22)/F22) | K22: =IF(C22="","",IF(E22<>"Sim","Só monitorada",IF(F22=0,"Sem requisito",IF(G22+H22+I22<F22,"Falta avaliar a situação",IF(I22>0,"Há requisito não atendido",IF(H22>0,"Há pendência","Atendida"))))))
B23: 6 | C23: =IF(Partes!C16="","",Partes!C16) | D23: =IF(C23="","",Partes!I16) | E23: =IF(C23="","",Partes!J16) | F23: =IF(C23="","",COUNTIFS(Requisitos!$C$7:$C$46,C23,Requisitos!$F$7:$F$46,"Sim")) | G23: =IF(C23="","",COUNTIFS(Requisitos!$C$7:$C$46,C23,Requisitos!$F$7:$F$46,"Sim",Requisitos!$I$7:$I$46,"Atende")) | H23: =IF(C23="","",COUNTIFS(Requisitos!$C$7:$C$46,C23,Requisitos!$F$7:$F$46,"Sim",Requisitos!$I$7:$I$46,"Atende em parte")) | I23: =IF(C23="","",COUNTIFS(Requisitos!$C$7:$C$46,C23,Requisitos!$F$7:$F$46,"Sim",Requisitos!$I$7:$I$46,"Não atende")) | J23: =IF(OR(C23="",N(F23)=0),"",(G23+0.5*H23)/F23) | K23: =IF(C23="","",IF(E23<>"Sim","Só monitorada",IF(F23=0,"Sem requisito",IF(G23+H23+I23<F23,"Falta avaliar a situação",IF(I23>0,"Há requisito não atendido",IF(H23>0,"Há pendência","Atendida"))))))
B24: 7 | C24: =IF(Partes!C17="","",Partes!C17) | D24: =IF(C24="","",Partes!I17) | E24: =IF(C24="","",Partes!J17) | F24: =IF(C24="","",COUNTIFS(Requisitos!$C$7:$C$46,C24,Requisitos!$F$7:$F$46,"Sim")) | G24: =IF(C24="","",COUNTIFS(Requisitos!$C$7:$C$46,C24,Requisitos!$F$7:$F$46,"Sim",Requisitos!$I$7:$I$46,"Atende")) | H24: =IF(C24="","",COUNTIFS(Requisitos!$C$7:$C$46,C24,Requisitos!$F$7:$F$46,"Sim",Requisitos!$I$7:$I$46,"Atende em parte")) | I24: =IF(C24="","",COUNTIFS(Requisitos!$C$7:$C$46,C24,Requisitos!$F$7:$F$46,"Sim",Requisitos!$I$7:$I$46,"Não atende")) | J24: =IF(OR(C24="",N(F24)=0),"",(G24+0.5*H24)/F24) | K24: =IF(C24="","",IF(E24<>"Sim","Só monitorada",IF(F24=0,"Sem requisito",IF(G24+H24+I24<F24,"Falta avaliar a situação",IF(I24>0,"Há requisito não atendido",IF(H24>0,"Há pendência","Atendida"))))))
B25: 8 | C25: =IF(Partes!C18="","",Partes!C18) | D25: =IF(C25="","",Partes!I18) | E25: =IF(C25="","",Partes!J18) | F25: =IF(C25="","",COUNTIFS(Requisitos!$C$7:$C$46,C25,Requisitos!$F$7:$F$46,"Sim")) | G25: =IF(C25="","",COUNTIFS(Requisitos!$C$7:$C$46,C25,Requisitos!$F$7:$F$46,"Sim",Requisitos!$I$7:$I$46,"Atende")) | H25: =IF(C25="","",COUNTIFS(Requisitos!$C$7:$C$46,C25,Requisitos!$F$7:$F$46,"Sim",Requisitos!$I$7:$I$46,"Atende em parte")) | I25: =IF(C25="","",COUNTIFS(Requisitos!$C$7:$C$46,C25,Requisitos!$F$7:$F$46,"Sim",Requisitos!$I$7:$I$46,"Não atende")) | J25: =IF(OR(C25="",N(F25)=0),"",(G25+0.5*H25)/F25) | K25: =IF(C25="","",IF(E25<>"Sim","Só monitorada",IF(F25=0,"Sem requisito",IF(G25+H25+I25<F25,"Falta avaliar a situação",IF(I25>0,"Há requisito não atendido",IF(H25>0,"Há pendência","Atendida"))))))
B26: 9 | C26: =IF(Partes!C19="","",Partes!C19) | D26: =IF(C26="","",Partes!I19) | E26: =IF(C26="","",Partes!J19) | F26: =IF(C26="","",COUNTIFS(Requisitos!$C$7:$C$46,C26,Requisitos!$F$7:$F$46,"Sim")) | G26: =IF(C26="","",COUNTIFS(Requisitos!$C$7:$C$46,C26,Requisitos!$F$7:$F$46,"Sim",Requisitos!$I$7:$I$46,"Atende")) | H26: =IF(C26="","",COUNTIFS(Requisitos!$C$7:$C$46,C26,Requisitos!$F$7:$F$46,"Sim",Requisitos!$I$7:$I$46,"Atende em parte")) | I26: =IF(C26="","",COUNTIFS(Requisitos!$C$7:$C$46,C26,Requisitos!$F$7:$F$46,"Sim",Requisitos!$I$7:$I$46,"Não atende")) | J26: =IF(OR(C26="",N(F26)=0),"",(G26+0.5*H26)/F26) | K26: =IF(C26="","",IF(E26<>"Sim","Só monitorada",IF(F26=0,"Sem requisito",IF(G26+H26+I26<F26,"Falta avaliar a situação",IF(I26>0,"Há requisito não atendido",IF(H26>0,"Há pendência","Atendida"))))))
B27: 10 | C27: =IF(Partes!C20="","",Partes!C20) | D27: =IF(C27="","",Partes!I20) | E27: =IF(C27="","",Partes!J20) | F27: =IF(C27="","",COUNTIFS(Requisitos!$C$7:$C$46,C27,Requisitos!$F$7:$F$46,"Sim")) | G27: =IF(C27="","",COUNTIFS(Requisitos!$C$7:$C$46,C27,Requisitos!$F$7:$F$46,"Sim",Requisitos!$I$7:$I$46,"Atende")) | H27: =IF(C27="","",COUNTIFS(Requisitos!$C$7:$C$46,C27,Requisitos!$F$7:$F$46,"Sim",Requisitos!$I$7:$I$46,"Atende em parte")) | I27: =IF(C27="","",COUNTIFS(Requisitos!$C$7:$C$46,C27,Requisitos!$F$7:$F$46,"Sim",Requisitos!$I$7:$I$46,"Não atende")) | J27: =IF(OR(C27="",N(F27)=0),"",(G27+0.5*H27)/F27) | K27: =IF(C27="","",IF(E27<>"Sim","Só monitorada",IF(F27=0,"Sem requisito",IF(G27+H27+I27<F27,"Falta avaliar a situação",IF(I27>0,"Há requisito não atendido",IF(H27>0,"Há pendência","Atendida"))))))
B28: 11 | C28: =IF(Partes!C21="","",Partes!C21) | D28: =IF(C28="","",Partes!I21) | E28: =IF(C28="","",Partes!J21) | F28: =IF(C28="","",COUNTIFS(Requisitos!$C$7:$C$46,C28,Requisitos!$F$7:$F$46,"Sim")) | G28: =IF(C28="","",COUNTIFS(Requisitos!$C$7:$C$46,C28,Requisitos!$F$7:$F$46,"Sim",Requisitos!$I$7:$I$46,"Atende")) | H28: =IF(C28="","",COUNTIFS(Requisitos!$C$7:$C$46,C28,Requisitos!$F$7:$F$46,"Sim",Requisitos!$I$7:$I$46,"Atende em parte")) | I28: =IF(C28="","",COUNTIFS(Requisitos!$C$7:$C$46,C28,Requisitos!$F$7:$F$46,"Sim",Requisitos!$I$7:$I$46,"Não atende")) | J28: =IF(OR(C28="",N(F28)=0),"",(G28+0.5*H28)/F28) | K28: =IF(C28="","",IF(E28<>"Sim","Só monitorada",IF(F28=0,"Sem requisito",IF(G28+H28+I28<F28,"Falta avaliar a situação",IF(I28>0,"Há requisito não atendido",IF(H28>0,"Há pendência","Atendida"))))))
B29: 12 | C29: =IF(Partes!C22="","",Partes!C22) | D29: =IF(C29="","",Partes!I22) | E29: =IF(C29="","",Partes!J22) | F29: =IF(C29="","",COUNTIFS(Requisitos!$C$7:$C$46,C29,Requisitos!$F$7:$F$46,"Sim")) | G29: =IF(C29="","",COUNTIFS(Requisitos!$C$7:$C$46,C29,Requisitos!$F$7:$F$46,"Sim",Requisitos!$I$7:$I$46,"Atende")) | H29: =IF(C29="","",COUNTIFS(Requisitos!$C$7:$C$46,C29,Requisitos!$F$7:$F$46,"Sim",Requisitos!$I$7:$I$46,"Atende em parte")) | I29: =IF(C29="","",COUNTIFS(Requisitos!$C$7:$C$46,C29,Requisitos!$F$7:$F$46,"Sim",Requisitos!$I$7:$I$46,"Não atende")) | J29: =IF(OR(C29="",N(F29)=0),"",(G29+0.5*H29)/F29) | K29: =IF(C29="","",IF(E29<>"Sim","Só monitorada",IF(F29=0,"Sem requisito",IF(G29+H29+I29<F29,"Falta avaliar a situação",IF(I29>0,"Há requisito não atendido",IF(H29>0,"Há pendência","Atendida"))))))
B31: Resumo automático
B32: Parte com o menor atendimento | D32: =IF(COUNT(J18:J29)=0,"",INDEX(C18:C29,MATCH(MIN(J18:J29),J18:J29,0))&" · "&TEXT(MIN(J18:J29),"0%"))
B33: Aviso | D33: =IF(D7=0,"Liste as partes na aba Partes",IF(D10=0,"Registre os requisitos na aba Requisitos",IF(D9>0,"Há parte pertinente sem requisito",IF(D4="","Informe a data da análise",IF(D14>0,"Há ação vencida: veja a aba Requisitos",IF(COUNTIF(K18:K29,"Há requisito não atendido")>0,"Há requisito não atendido: leve à direção","OK")))))) -> Liste as partes na aba Partes

Sheet Checklist
B1: Checklist das partes interessadas
B2: Escolha o status de cada item na lista suspensa (coluna em amarelo-claro).
B4: # | C4: Item de verificação | D4: Status | E4: Observações
B5: 1 | C5: A lista cobre os grupos: clientes, colaboradores, fornecedores e parceiros, reguladores, proprietários e sociedade.
B6: 2 | C6: Cada parte tem nota de influência e de interesse, dada pela equipe, com o motivo escrito.
B7: 3 | C7: As partes pertinentes ao sistema estão separadas das que são só monitoradas.
B8: 4 | C8: Cada parte pertinente tem pelo menos um requisito escrito, com verbo e critério.
B9: 5 | C9: Os requisitos legais e contratuais estão identificados e foram todos adotados.
B10: 6 | C10: Cada expectativa tem decisão registrada: adotada, ou não adotada, com a justificativa.
B11: 7 | C11: Cada requisito adotado está ligado a um processo ou a um documento que o atende.
B12: 8 | C12: Cada requisito adotado tem uma forma de monitoramento, com fonte e frequência.
B13: 9 | C13: A situação de cada requisito está avaliada, e o que não atende tem ação, responsável e prazo.
B14: 10 | C14: Cada parte pertinente tem um canal de relacionamento e alguém que cuida dele.
B15: 11 | C15: A lista alimentou a Matriz SWOT, a Matriz de riscos e o escopo do sistema.
B16: 12 | C16: A lista tem data de revisão, e o resultado vai à análise crítica pela direção.
B18: Resumo automático
B19: Itens atendidos (Sim) | D19: =COUNTIF(D5:D16,"Sim") -> 0
B20: Itens parciais | D20: =COUNTIF(D5:D16,"Parcial") -> 0
B21: Itens não atendidos | D21: =COUNTIF(D5:D16,"Não") -> 0
B22: Itens sem resposta | D22: =COUNTBLANK(D5:D16) -> 12
B23: Percentual atendido | D23: =D19/ROWS(D5:D16) -> 0
B24: Situação | D24: =IF(D19=ROWS(D5:D16),"Validado",IF(D22>0,"Em andamento","Com pendências")) -> Em andamento

Sheet Exemplo 1 - Pizzaria
B1: Partes interessadas
B2: Exemplo preenchido, para consulta. Use as abas Partes e Requisitos para a sua organização.
B4: Organização | D4: Pizzaria (loja com salão e delivery)
B5: Data e responsáveis | D5: 23/10/2026. Gerente da loja, com os três líderes.
B6: Escopo | D6: A loja inteira: salão, produção e delivery.
B7: Origem | D7: Diagnóstico da ISO 9001 de 02/10/2026, requisito 4.2: incluir entregadores e fornecedores, com o que cada um espera.
B8: Revisão | D8: Uma vez por ano, em outubro, e sempre que uma parte mudar de posição.
B10: Partes interessadas
B11: # | C11: Parte interessada | D11: Por que importa | E11: Influência | F11: Interesse | G11: Relacionamento: canal e frequência | H11: Quem cuida | I11: Estratégia | J11: Grupo | K11: Requisito legal? | L11: Pertinente
B12: 1 | C12: Clientes | D12: Compram, avaliam no aplicativo e decidem se voltam. | E12: 5 | F12: 5 | G12: Pedidos, reclamações e avaliações do aplicativo, todos os dias. | H12: Atendente líder | I12: =IF(E12>=4,IF(F12>=4,"Gerir de perto","Manter satisfeito"),IF(F12>=4,"Manter informado","Monitorar")) -> Gerir de perto | J12: Cliente | K12: Não | L12: =IF(OR(I12<>"Monitorar",K12="Sim"),"Sim","Não") -> Sim
B13: 2 | C13: Sócios | D13: Definem o investimento e esperam resultado. | E13: 5 | F13: 5 | G13: Reunião mensal de resultados. | H13: Gerente da loja | I13: =IF(E13>=4,IF(F13>=4,"Gerir de perto","Manter satisfeito"),IF(F13>=4,"Manter informado","Monitorar")) -> Gerir de perto | J13: Proprietário ou investidor | K13: Não | L13: =IF(OR(I13<>"Monitorar",K13="Sim"),"Sim","Não") -> Sim
B14: 3 | C14: Equipe da loja | D14: Produz, atende e embala. Sem ela não há pedido certo. | E14: 4 | F14: 5 | G14: Reunião semanal e quadro de avisos. | H14: Gerente da loja | I14: =IF(E14>=4,IF(F14>=4,"Gerir de perto","Manter satisfeito"),IF(F14>=4,"Manter informado","Monitorar")) -> Gerir de perto | J14: Colaborador | K14: Sim | L14: =IF(OR(I14<>"Monitorar",K14="Sim"),"Sim","Não") -> Sim
B15: 4 | C15: Entregadores | D15: Levam o pedido ao cliente. São a loja na porta de quem comprou. | E15: 4 | F15: 5 | G15: Conversa no início do turno e grupo de mensagens. | H15: Líder da expedição | I15: =IF(E15>=4,IF(F15>=4,"Gerir de perto","Manter satisfeito"),IF(F15>=4,"Manter informado","Monitorar")) -> Gerir de perto | J15: Fornecedor ou parceiro | K15: Não | L15: =IF(OR(I15<>"Monitorar",K15="Sim"),"Sim","Não") -> Sim
B16: 5 | C16: Vigilância sanitária | D16: Licencia e fiscaliza. Pode interditar a loja. | E16: 5 | F16: 2 | G16: Renovação anual da licença e visitas de fiscalização. | H16: Gerente da loja | I16: =IF(E16>=4,IF(F16>=4,"Gerir de perto","Manter satisfeito"),IF(F16>=4,"Manter informado","Monitorar")) -> Manter satisfeito | J16: Regulador | K16: Sim | L16: =IF(OR(I16<>"Monitorar",K16="Sim"),"Sim","Não") -> Sim
B17: 6 | C17: Prefeitura e Corpo de Bombeiros | D17: Emitem o alvará e o auto de vistoria. | E17: 5 | F17: 1 | G17: Renovações, nas datas de vencimento. | H17: Gerente da loja | I17: =IF(E17>=4,IF(F17>=4,"Gerir de perto","Manter satisfeito"),IF(F17>=4,"Manter informado","Monitorar")) -> Manter satisfeito | J17: Regulador | K17: Sim | L17: =IF(OR(I17<>"Monitorar",K17="Sim"),"Sim","Não") -> Sim
B18: 7 | C18: Aplicativo de delivery | D18: Traz mais da metade dos pedidos e define a taxa e as regras. | E18: 5 | F18: 2 | G18: Painel do parceiro, toda semana. | H18: Gerente da loja | I18: =IF(E18>=4,IF(F18>=4,"Gerir de perto","Manter satisfeito"),IF(F18>=4,"Manter informado","Monitorar")) -> Manter satisfeito | J18: Fornecedor ou parceiro | K18: Não | L18: =IF(OR(I18<>"Monitorar",K18="Sim"),"Sim","Não") -> Sim
B19: 8 | C19: Fornecedores de insumos | D19: Entregam queijo, farinha e embalagens. A falta para a produção. | E19: 4 | F19: 3 | G19: Pedido semanal e avaliação a cada semestre. | H19: Pizzaiolo líder | I19: =IF(E19>=4,IF(F19>=4,"Gerir de perto","Manter satisfeito"),IF(F19>=4,"Manter informado","Monitorar")) -> Manter satisfeito | J19: Fornecedor ou parceiro | K19: Não | L19: =IF(OR(I19<>"Monitorar",K19="Sim"),"Sim","Não") -> Sim
B20: 9 | C20: Vizinhos da loja | D20: Convivem com o movimento, o ruído e as motos. | E20: 2 | F20: 4 | G20: Conversa direta e telefone da gerência na porta. | H20: Gerente da loja | I20: =IF(E20>=4,IF(F20>=4,"Gerir de perto","Manter satisfeito"),IF(F20>=4,"Manter informado","Monitorar")) -> Manter informado | J20: Sociedade | K20: Não | L20: =IF(OR(I20<>"Monitorar",K20="Sim"),"Sim","Não") -> Sim
B21: 10 | C21: Portarias dos condomínios atendidos | D21: Recebem o entregador e definem como o pedido sobe. | E21: 3 | F21: 2 | G21: — | H21: — | I21: =IF(E21>=4,IF(F21>=4,"Gerir de perto","Manter satisfeito"),IF(F21>=4,"Manter informado","Monitorar")) -> Monitorar | J21: Sociedade | K21: Não | L21: =IF(OR(I21<>"Monitorar",K21="Sim"),"Sim","Não") -> Não
B22: 11 | C22: Concorrentes do bairro | D22: Disputam o mesmo cliente. Não têm requisito sobre a loja. | E22: 2 | F22: 2 | G22: — | H22: — | I22: =IF(E22>=4,IF(F22>=4,"Gerir de perto","Manter satisfeito"),IF(F22>=4,"Manter informado","Monitorar")) -> Monitorar | J22: Outro | K22: Não | L22: =IF(OR(I22<>"Monitorar",K22="Sim"),"Sim","Não") -> Não
B24: Requisitos
B25: # | C25: Parte interessada | D25: O que espera | E25: Tipo | F25: Adotado? | G25: Como atende, ou por que não adota | H25: Como se monitora | I25: Situação | J25: Ação | K25: Responsável | L25: Prazo
B26: 1 | C26: Clientes | D26: Receber o pedido em até 40 minutos. | E26: Contratual | F26: Sim | G26: Processo de delivery, com escala reforçada no pico e agrupamento por zona. | H26: Entregas em até 40 minutos, todo mês. | I26: Atende | J26: — | K26: — | L26: —
B27: 2 | C27: Clientes | D27: Receber a pizza quente e o pedido certo, na primeira vez. | E27: Expectativa | F27: Sim | G27: Conferência do pedido antes de embalar, com etiqueta rubricada. | H27: Pedidos refeitos por erro, todo mês. | I27: Atende em parte | J27: Analisar a alta dos pedidos refeitos desde a troca do sistema de pedidos. | K27: Pizzaiolo líder | L27: 46346
B28: 3 | C28: Clientes | D28: Ter um canal para reclamar e receber resposta. | E28: Expectativa | F28: Sim | G28: Registro de reclamações do site, do aplicativo e do telefone. | H28: Reclamações por 100 pedidos, todo mês. | I28: Atende em parte | J28: Medir a satisfação, e não só a reclamação: propor a pesquisa na análise crítica. | K28: Atendente líder | L28: 46370
B29: 4 | C29: Sócios | D29: Recuperar a margem do delivery, que caiu com a taxa do aplicativo. | E29: Expectativa | F29: Sim | G29: Ciclo PDCA da margem do delivery, aberto em 09/10/2026. | H29: Margem do delivery, todo mês, na reunião de resultados. | I29: Não atende | J29: Concluir o ciclo PDCA e levar o resultado aos sócios. | K29: Gerente da loja | L29: 46416
B30: 5 | C30: Equipe da loja | D30: Salário em dia, registro e condições seguras de trabalho. | E30: Legal | F30: Sim | G30: Folha de pagamento e rotina de segurança da cozinha. | H30: Conferência da folha, todo mês, e inspeção de segurança, a cada trimestre. | I30: Atende | J30: — | K30: — | L30: —
B31: 6 | C31: Equipe da loja | D31: Saber o que se espera da função e ser treinada para ela. | E31: Expectativa | F31: Sim | G31: Instruções de trabalho nos postos e treinamento na admissão. | H31: Registros de treinamento, a cada admissão. | I31: Atende em parte | J31: Montar a matriz de competências da loja. | K31: Gerente da loja | L31: 46430
B32: 7 | C32: Entregadores | D32: Receber por entrega, no dia combinado. | E32: Contratual | F32: Sim | G32: Fechamento semanal das entregas. | H32: Conferência do fechamento, toda segunda-feira. | I32: Atende | J32: — | K32: — | L32: —
B33: 8 | C33: Entregadores | D33: Sair com o pedido pronto, a rota agrupada e o endereço completo. | E33: Expectativa | F33: Sim | G33: Instrução da expedição e campo de complemento obrigatório. | H33: Atrasos por motivo, na folha de verificação. | I33: Atende | J33: — | K33: — | L33: —
B34: 9 | C34: Entregadores | D34: Conhecer a escala com antecedência. | E34: Expectativa | F34: Sim | G34: Escala avisada na véspera, pelo grupo de mensagens. | H34: Saídas de entregadores, a cada trimestre. | I34: Atende em parte | J34: Publicar a escala da semana toda sexta-feira. | K34: Líder da expedição | L34: 46332
B35: 10 | C35: Vigilância sanitária | D35: Manter a licença sanitária válida. | E35: Legal | F35: Sim | G35: Renovação protocolada em 09/10/2026. | H35: Controle de vencimentos das licenças, todo mês. | I35: Atende em parte | J35: Acompanhar o protocolo até a emissão da licença. | K35: Gerente da loja | L35: 46339
B36: 11 | C36: Vigilância sanitária | D36: Cumprir as boas práticas de manipulação: temperatura, higiene e controle de pragas. | E36: Legal | F36: Sim | G36: Manual de boas práticas e registro de temperatura, duas vezes por turno. | H36: Registros de temperatura, conferidos toda semana. | I36: Atende | J36: — | K36: — | L36: —
B37: 12 | C37: Prefeitura e Corpo de Bombeiros | D37: Manter o alvará de funcionamento e o auto de vistoria válidos. | E37: Legal | F37: Sim | G37: Documentos afixados na loja, com vencimento em 2027. | H37: Controle de vencimentos das licenças, todo mês. | I37: Atende | J37: — | K37: — | L37: —
B38: 13 | C38: Aplicativo de delivery | D38: Aceitar o pedido em até 3 minutos e manter a nota mínima da loja. | E38: Contratual | F38: Sim | G38: Tela de pedidos no balcão, com alerta sonoro. | H38: Painel do parceiro, toda semana. | I38: Atende | J38: — | K38: — | L38: —
B39: 14 | C39: Fornecedores de insumos | D39: Receber o pedido da semana até quarta-feira e o pagamento no prazo. | E39: Contratual | F39: Sim | G39: Rotina de compras do pizzaiolo líder. | H39: Pedidos fora do dia e pagamentos em atraso, todo mês. | I39: Atende | J39: — | K39: — | L39: —
B40: 15 | C40: Vizinhos da loja | D40: Motos desligadas na espera e fora da calçada. | E40: Expectativa | F40: Sim | G40: Área de espera marcada no recuo da loja. | H40: Reclamações de vizinhos, registradas pela gerência. | I40: Atende | J40: — | K40: — | L40: —
B41: 16 | C41: Vizinhos da loja | D41: Encerrar as entregas às 22h. | E41: Expectativa | F41: Não | G41: O alvará permite funcionar até a meia-noite, e um terço dos pedidos de sexta e de sábado entra depois das 22h. A loja adotou o requisito do ruído. | H41: — | I41: — | J41: — | K41: — | L41: —
B43: Resumo automático
B44: Partes listadas e pertinentes | E44: =COUNTA(C12:C22)&" listadas, "&COUNTIF(L12:L22,"Sim")&" pertinentes" -> 11 listadas, 9 pertinentes
...

Sheet Exemplo 2 - Indústria
B1: Partes interessadas
B2: Exemplo preenchido, para consulta. Use as abas Partes e Requisitos para a sua organização.
B4: Organização | D4: Indústria de embalagens plásticas
B5: Data e responsáveis | D5: 20/01/2027. Coordenador da Qualidade, com os gerentes e a direção.
B6: Escopo | D6: A fábrica inteira: extrusão, impressão, corte e expedição.
B7: Origem | D7: Revisão anual, em preparação para a análise crítica de 18/02/2027.
B8: Revisão | D8: Uma vez por ano, em janeiro, antes da análise crítica.
B10: Partes interessadas
B11: # | C11: Parte interessada | D11: Por que importa | E11: Influência | F11: Interesse | G11: Relacionamento: canal e frequência | H11: Quem cuida | I11: Estratégia | J11: Grupo | K11: Requisito legal? | L11: Pertinente
B12: 1 | C12: Clientes de alimentos | D12: Compram a maior parte do volume e respondem pela embalagem perante o consumidor. | E12: 5 | F12: 5 | G12: Visitas do comercial, pesquisa anual e reclamações. | H12: Gerente comercial | I12: =IF(E12>=4,IF(F12>=4,"Gerir de perto","Manter satisfeito"),IF(F12>=4,"Manter informado","Monitorar")) -> Gerir de perto | J12: Cliente | K12: Não | L12: =IF(OR(I12<>"Monitorar",K12="Sim"),"Sim","Não") -> Sim
B13: 2 | C13: Clientes de cosméticos e industriais | D13: Exigem impressão no padrão e pedem embalagem com material reciclado. | E13: 4 | F13: 4 | G13: Visitas do comercial, pesquisa anual e reclamações. | H13: Gerente comercial | I13: =IF(E13>=4,IF(F13>=4,"Gerir de perto","Manter satisfeito"),IF(F13>=4,"Manter informado","Monitorar")) -> Gerir de perto | J13: Cliente | K13: Não | L13: =IF(OR(I13<>"Monitorar",K13="Sim"),"Sim","Não") -> Sim
B14: 3 | C14: Direção e acionistas | D14: Aprovam os recursos e definem a estratégia. | E14: 5 | F14: 5 | G14: Análise crítica a cada semestre e reunião mensal de resultados. | H14: Coordenador da Qualidade | I14: =IF(E14>=4,IF(F14>=4,"Gerir de perto","Manter satisfeito"),IF(F14>=4,"Manter informado","Monitorar")) -> Gerir de perto | J14: Proprietário ou investidor | K14: Não | L14: =IF(OR(I14<>"Monitorar",K14="Sim"),"Sim","Não") -> Sim
B15: 4 | C15: Colaboradores | D15: Operam as extrusoras e a impressão. A segurança deles é obrigação legal. | E15: 4 | F15: 5 | G15: Reunião de turno, mural e pesquisa de clima anual. | H15: RH | I15: =IF(E15>=4,IF(F15>=4,"Gerir de perto","Manter satisfeito"),IF(F15>=4,"Manter informado","Monitorar")) -> Gerir de perto | J15: Colaborador | K15: Sim | L15: =IF(OR(I15<>"Monitorar",K15="Sim"),"Sim","Não") -> Sim
B16: 5 | C16: Autoridade sanitária | D16: Regula os materiais que entram em contato com alimentos. | E16: 5 | F16: 2 | G16: Acompanhamento das normas, a cada trimestre. | H16: Coordenador da Qualidade | I16: =IF(E16>=4,IF(F16>=4,"Gerir de perto","Manter satisfeito"),IF(F16>=4,"Manter informado","Monitorar")) -> Manter satisfeito | J16: Regulador | K16: Sim | L16: =IF(OR(I16<>"Monitorar",K16="Sim"),"Sim","Não") -> Sim
B17: 6 | C17: Órgão ambiental | D17: Emite a licença de operação e fiscaliza os resíduos. | E17: 5 | F17: 2 | G17: Renovação da licença e relatórios anuais. | H17: Gerente industrial | I17: =IF(E17>=4,IF(F17>=4,"Gerir de perto","Manter satisfeito"),IF(F17>=4,"Manter informado","Monitorar")) -> Manter satisfeito | J17: Regulador | K17: Sim | L17: =IF(OR(I17<>"Monitorar",K17="Sim"),"Sim","Não") -> Sim
B18: 7 | C18: Fornecedores de resina | D18: A resina de polietileno tem fornecedor único. | E18: 5 | F18: 3 | G18: Previsão trimestral e avaliação a cada semestre. | H18: Gerente de Suprimentos | I18: =IF(E18>=4,IF(F18>=4,"Gerir de perto","Manter satisfeito"),IF(F18>=4,"Manter informado","Monitorar")) -> Manter satisfeito | J18: Fornecedor ou parceiro | K18: Não | L18: =IF(OR(I18<>"Monitorar",K18="Sim"),"Sim","Não") -> Sim
B19: 8 | C19: Organismo de certificação | D19: Fará a auditoria de certificação, que dois grandes clientes passaram a exigir. | E19: 4 | F19: 3 | G19: Contratação prevista para 2027 e contato do Coordenador da Qualidade. | H19: Coordenador da Qualidade | I19: =IF(E19>=4,IF(F19>=4,"Gerir de perto","Manter satisfeito"),IF(F19>=4,"Manter informado","Monitorar")) -> Manter satisfeito | J19: Fornecedor ou parceiro | K19: Não | L19: =IF(OR(I19<>"Monitorar",K19="Sim"),"Sim","Não") -> Sim
B20: 9 | C20: Transportadoras | D20: Levam o produto ao cliente. O atraso delas é atraso da fábrica. | E20: 3 | F20: 4 | G20: Agendamento diário e reunião a cada semestre. | H20: Líder da expedição | I20: =IF(E20>=4,IF(F20>=4,"Gerir de perto","Manter satisfeito"),IF(F20>=4,"Manter informado","Monitorar")) -> Manter informado | J20: Fornecedor ou parceiro | K20: Não | L20: =IF(OR(I20<>"Monitorar",K20="Sim"),"Sim","Não") -> Sim
B21: 10 | C21: Comunidade vizinha | D21: Convive com o tráfego de caminhões e com o ruído do turno da noite. | E21: 2 | F21: 4 | G21: Telefone da portaria e reunião anual com a associação do bairro. | H21: Gerente industrial | I21: =IF(E21>=4,IF(F21>=4,"Gerir de perto","Manter satisfeito"),IF(F21>=4,"Manter informado","Monitorar")) -> Manter informado | J21: Sociedade | K21: Não | L21: =IF(OR(I21<>"Monitorar",K21="Sim"),"Sim","Não") -> Sim
B22: 11 | C22: Sindicato da categoria | D22: Negocia o acordo coletivo uma vez por ano. | E22: 3 | F22: 3 | G22: — | H22: — | I22: =IF(E22>=4,IF(F22>=4,"Gerir de perto","Manter satisfeito"),IF(F22>=4,"Manter informado","Monitorar")) -> Monitorar | J22: Sociedade | K22: Não | L22: =IF(OR(I22<>"Monitorar",K22="Sim"),"Sim","Não") -> Não
B23: 12 | C23: Bancos e seguradora | D23: Financiam e seguram o patrimônio. Não têm requisito sobre o produto. | E23: 2 | F23: 2 | G23: — | H23: — | I23: =IF(E23>=4,IF(F23>=4,"Gerir de perto","Manter satisfeito"),IF(F23>=4,"Manter informado","Monitorar")) -> Monitorar | J23: Outro | K23: Não | L23: =IF(OR(I23<>"Monitorar",K23="Sim"),"Sim","Não") -> Não
B25: Requisitos
B26: # | C26: Parte interessada | D26: O que espera | E26: Tipo | F26: Adotado? | G26: Como atende, ou por que não adota | H26: Como se monitora | I26: Situação | J26: Ação | K26: Responsável | L26: Prazo
