Workbook

Sheet Instruções
B1: PDCA — Como usar esta planilha
B2: Modelo para conduzir um ciclo de melhoria: Planejar, Executar, Verificar e Agir.
B4: Legenda: onde preencher
B5: Amarelo-claro | C5: Células de entrada. É aqui que você digita.
B6: Cinza | C6: Células calculadas ou fixas (rótulos, contagens, avisos). Não altere.
B7: Cinza em itálico | C7: Linha de exemplo (marcada com “Ex.”). Mostra o formato esperado e não entra nas contagens.
B8: Listas suspensas | C8: Colunas de status, tipo, momento e sentido aceitam apenas as opções da lista.
B9: Comentários | C9: Células com triângulo vermelho no canto trazem uma dica de preenchimento. Passe o mouse sobre elas.
B11: As quatro fases
B12: P | C12: Planejar: identificar o problema, observar, analisar as causas e montar o plano de ação.
B13: D | C13: Executar: treinar as pessoas, executar o plano e registrar os desvios.
B14: C | C14: Verificar: medir o resultado, comparar com a meta e avaliar efeitos colaterais.
B15: A | C15: Agir: padronizar o que funcionou, registrar as lições e definir o próximo ciclo.
B17: Ordem recomendada de preenchimento
B18: Passo 1 | C18: Aba PDCA: preencha o cabeçalho, com o tema, o dono, a descrição do problema, o indicador, a situação inicial e a meta.
B19: Passo 2 | C19: Aba PDCA, etapas 1 a 3: registre o problema, o que foi observado e as causas confirmadas com dados.
B20: Passo 3 | C20: Aba Plano de ação: detalhe as ações no formato 5W2H. Depois, conclua a etapa 4 na aba PDCA.
B21: Passo 4 | C21: Aba Verificação: registre as medições de antes das ações.
B22: Passo 5 | C22: Aba Plano de ação: atualize o status durante a execução. Registre os desvios na etapa 5 da aba PDCA.
B23: Passo 6 | C23: Aba Verificação: registre as medições de depois das ações e leia o resultado do ciclo.
B24: Passo 7 | C24: Aba Padronização: registre padrões, treinamentos, pendências e lições aprendidas.
B25: Passo 8 | C25: Aba PDCA, etapas 7 e 8: registre o que virou padrão e qual é o próximo ciclo.
B26: Passo 9 | C26: Aba Checklist: valide o ciclo com a equipe e com o dono do problema.
B28: Abas da planilha
B29: PDCA | C29: Modelo principal. Cabeçalho do ciclo, registro das oito etapas e resumo automático.
B30: Plano de ação | C30: Ações no formato 5W2H, com situação calculada a partir do prazo e do status.
B31: Verificação | C31: Medições do indicador, comparação com a meta e gráfico de tendência.
B32: Checklist | C32: Doze verificações de qualidade do ciclo, com percentual de conclusão.
B33: Padronização | C33: Registro de padrões, treinamentos, pendências e lições aprendidas.
B34: Exemplo 1 - Pizzaria | C34: Ciclo preenchido em que a meta foi atingida: reduzir os atrasos nas entregas.
B35: Exemplo 2 - Compras | C35: Ciclo preenchido em que a meta não foi atingida: reduzir o prazo de compra.
B37: Regras e premissas do modelo
B38: Etapas | C38: O ciclo tem oito etapas fixas, as mesmas do MASP. O aviso de sequência aparece quando uma etapa está concluída e a anterior não. O PDCA permite voltar etapas, mas não pular.
B39: Indicador e meta | C39: Digite a situação inicial, a meta e as medições só com números, na unidade do indicador: 82 para 82%. O sentido do indicador define a comparação com a meta.
B40: Resultado do ciclo | C40: A aba Verificação compara a média das medições marcadas como “Depois” com a meta. As medições marcadas como “Durante” aparecem no gráfico, mas não entram nas médias.
B41: Ação atrasada | C41: Uma ação é considerada atrasada quando o prazo é anterior à data de hoje e o status não é Concluída nem Cancelada.
B42: Capacidade | C42: A planilha comporta 15 ações, 16 medições e 15 itens de padronização. Se faltar espaço, o ciclo provavelmente está grande demais: divida o problema.
B43: Exemplos | C43: Os dados das abas de exemplo são ilustrativos, criados para este material.

Sheet PDCA
B1: PDCA — Registro do ciclo de melhoria
B2: Preencha as células em amarelo-claro. As células cinza são calculadas automaticamente.
B4: Tema do ciclo | G4: Dono do problema
B5: Área / unidade | G5: Data de início
B6: Elaborado por | G6: Versão
B7: Descrição do problema
B8: Indicador | G8: Unidade de medida
B9: Situação inicial (valor) | G9: Meta (valor)
B10: Sentido do indicador | G10: Prazo da meta
B11: Fora do escopo
B13: # | C13: Fase | D13: Etapa | E13: Pergunta-guia | F13: Registro: o que foi feito ou decidido | G13: Ferramenta ou evidência | H13: Responsável | I13: Conclusão | J13: Status
B14: Ex. | C14: P | D14: Identificar o problema | E14: Qual é o problema, quanto ele pesa e qual é a meta? | F14: 18% das entregas chegam depois de 40 minutos. Meta: passar de 82% para 95% em 12 semanas. | G14: Relatório do aplicativo de delivery | H14: Gerente da loja | I14: 46325 | J14: Concluída
B15: 1 | C15: P Planejar | D15: Identificar o problema | E15: Qual é o problema, quanto ele pesa e qual é a meta?
B16: 2 | D16: Observar | E16: Onde, quando e com quem o problema acontece?
B17: 3 | D17: Analisar as causas | E17: Por que acontece? Qual é a causa raiz, confirmada com dados?
B18: 4 | D18: Planejar a ação | E18: O que será feito, por quem e até quando?
B19: 5 | C19: D Executar | D19: Executar | E19: O plano foi executado como previsto? O que foi diferente?
B20: 6 | C20: C Verificar | D20: Verificar | E20: A meta foi atingida? Houve efeito colateral?
B21: 7 | C21: A Agir | D21: Padronizar | E21: O que vira padrão e quem precisa ser treinado?
B22: 8 | D22: Concluir | E22: O que aprendemos e qual é o próximo ciclo?
B24: Resumo automático
B25: Etapas concluídas | F25: =COUNTIF(J15:J22,"Concluída") -> 0
B26: Fase atual do ciclo | F26: =IF(COUNTIF(J15:J18,"Concluída")<4,"P — Planejar",IF(J19<>"Concluída","D — Executar",IF(J20<>"Concluída","C — Verificar",IF(COUNTIF(J21:J22,"Concluída")<2,"A — Agir","Ciclo concluído")))) -> P — Planejar
B27: Aviso: sequência das etapas | F27: =IF(SUMPRODUCT((J16:J22="Concluída")*(J15:J21<>"Concluída"))>0,"Há etapa concluída antes da anterior","OK") -> OK
B28: Aviso: registro das etapas | F28: =IF(SUMPRODUCT((J15:J22="Concluída")*(F15:F22=""))>0,"Há etapa concluída sem registro","OK") -> OK
B29: Aviso: meta | F29: =IF(OR(D9="",H9=""),"Informe a situação inicial e a meta",IF(D10="","Informe o sentido do indicador",IF(OR(AND(D10="Menor é melhor",H9>=D9),AND(D10="Maior é melhor",H9<=D9)),"A meta não melhora a situação inicial","OK"))) -> Informe a situação inicial e a meta
B30: Diferença entre a meta e a situação inicial | F30: =IF(OR(D9="",H9=""),"",H9-D9)
B31: Campos do cabeçalho preenchidos | F31: =COUNTA(D4,H4,D5,H5,D6,H6,D7,D8,H8,D9,H9,D10,H10,D11) -> 0

Sheet Plano de ação
B1: Plano de ação (5W2H)
B2: Uma linha por ação. Cada ação ataca uma causa confirmada e tem um único responsável.
B4: # | C4: O quê (ação) | D4: Por quê (causa atacada) | E4: Quem | F4: Onde | G4: Quando (prazo) | H4: Como | I4: Quanto custa | J4: Status | K4: Situação
B5: Ex. | C5: Reforçar a escala de entregadores às sextas e sábados, das 19h às 22h | D5: A escala não acompanha o pico de pedidos | E5: Gerente da loja | F5: Loja | G5: 46325 | H5: Contratar dois entregadores parceiros para o horário de pico | I5: 600 | J5: Em andamento | K5: No prazo
B6: 1 | K6: =IF(C6="","",IF(OR(J6="Concluída",J6="Cancelada"),J6,IF(G6="","Sem prazo",IF(G6<TODAY(),"Atrasada","No prazo"))))
B7: 2 | K7: =IF(C7="","",IF(OR(J7="Concluída",J7="Cancelada"),J7,IF(G7="","Sem prazo",IF(G7<TODAY(),"Atrasada","No prazo"))))
B8: 3 | K8: =IF(C8="","",IF(OR(J8="Concluída",J8="Cancelada"),J8,IF(G8="","Sem prazo",IF(G8<TODAY(),"Atrasada","No prazo"))))
B9: 4 | K9: =IF(C9="","",IF(OR(J9="Concluída",J9="Cancelada"),J9,IF(G9="","Sem prazo",IF(G9<TODAY(),"Atrasada","No prazo"))))
B10: 5 | K10: =IF(C10="","",IF(OR(J10="Concluída",J10="Cancelada"),J10,IF(G10="","Sem prazo",IF(G10<TODAY(),"Atrasada","No prazo"))))
B11: 6 | K11: =IF(C11="","",IF(OR(J11="Concluída",J11="Cancelada"),J11,IF(G11="","Sem prazo",IF(G11<TODAY(),"Atrasada","No prazo"))))
B12: 7 | K12: =IF(C12="","",IF(OR(J12="Concluída",J12="Cancelada"),J12,IF(G12="","Sem prazo",IF(G12<TODAY(),"Atrasada","No prazo"))))
B13: 8 | K13: =IF(C13="","",IF(OR(J13="Concluída",J13="Cancelada"),J13,IF(G13="","Sem prazo",IF(G13<TODAY(),"Atrasada","No prazo"))))
B14: 9 | K14: =IF(C14="","",IF(OR(J14="Concluída",J14="Cancelada"),J14,IF(G14="","Sem prazo",IF(G14<TODAY(),"Atrasada","No prazo"))))
B15: 10 | K15: =IF(C15="","",IF(OR(J15="Concluída",J15="Cancelada"),J15,IF(G15="","Sem prazo",IF(G15<TODAY(),"Atrasada","No prazo"))))
B16: 11 | K16: =IF(C16="","",IF(OR(J16="Concluída",J16="Cancelada"),J16,IF(G16="","Sem prazo",IF(G16<TODAY(),"Atrasada","No prazo"))))
B17: 12 | K17: =IF(C17="","",IF(OR(J17="Concluída",J17="Cancelada"),J17,IF(G17="","Sem prazo",IF(G17<TODAY(),"Atrasada","No prazo"))))
... B20: 15 | K20: =IF(C20="","",IF(OR(J20="Concluída",J20="Cancelada"),J20,IF(G20="","Sem prazo",IF(G20<TODAY(),"Atrasada","No prazo"))))
B22: Resumo automático
B23: Ações registradas | H23: =COUNTA(C6:C20) -> 0
B24: Concluídas | H24: =COUNTIF(J6:J20,"Concluída") -> 0
B25: Em andamento | H25: =COUNTIF(J6:J20,"Em andamento") -> 0
B26: Não iniciadas | H26: =COUNTIF(J6:J20,"Não iniciada") -> 0
B27: Atrasadas | H27: =COUNTIF(K6:K20,"Atrasada") -> 0
B28: Ações sem responsável ou sem prazo | H28: =SUMPRODUCT((C6:C20<>"")*((E6:E20="")+(G6:G20="")>0)) -> 0
B29: Percentual concluído | H29: =IF(H23=0,0,H24/H23) -> 0
B30: Custo total previsto | H30: =SUM(I6:I20) -> 0

Sheet Verificação
B1: Verificação — medições do indicador
B2: As células cinza do cabeçalho vêm da aba PDCA. Preencha as colunas em amarelo-claro.
B4: Indicador e meta
B5: Indicador | D5: =IF(PDCA!D8="","",PDCA!D8) | G5: Unidade | H5: =IF(PDCA!H8="","",PDCA!H8)
B6: Situação inicial | D6: =IF(PDCA!D9="","",PDCA!D9) | G6: Meta | H6: =IF(PDCA!H9="","",PDCA!H9)
B7: Sentido | D7: =IF(PDCA!D10="","",PDCA!D10) | G7: Prazo da meta | H7: =IF(PDCA!H10="","",PDCA!H10)
B9: # | C9: Período | D9: Momento | E9: Valor medido | F9: Observações | G9: Meta | H9: Atingiu a meta?
B10: Ex. | C10: Semana 1 | D10: Antes | E10: 81 | F10: Semana com feriado na sexta-feira | G10: 95 | H10: Não
B11: 1 | G11: =IF(OR($H$6="",E11=""),NA(),$H$6) -> #N/A | H11: =IF(OR(E11="",$H$6=""),"",IF($D$7="Menor é melhor",IF(E11<=$H$6,"Sim","Não"),IF(E11>=$H$6,"Sim","Não")))
B12: 2 | G12: =IF(OR($H$6="",E12=""),NA(),$H$6) -> #N/A | H12: =IF(OR(E12="",$H$6=""),"",IF($D$7="Menor é melhor",IF(E12<=$H$6,"Sim","Não"),IF(E12>=$H$6,"Sim","Não")))
B13: 3 | G13: =IF(OR($H$6="",E13=""),NA(),$H$6) -> #N/A | H13: =IF(OR(E13="",$H$6=""),"",IF($D$7="Menor é melhor",IF(E13<=$H$6,"Sim","Não"),IF(E13>=$H$6,"Sim","Não")))
B14: 4 | G14: =IF(OR($H$6="",E14=""),NA(),$H$6) -> #N/A | H14: =IF(OR(E14="",$H$6=""),"",IF($D$7="Menor é melhor",IF(E14<=$H$6,"Sim","Não"),IF(E14>=$H$6,"Sim","Não")))
B15: 5 | G15: =IF(OR($H$6="",E15=""),NA(),$H$6) -> #N/A | H15: =IF(OR(E15="",$H$6=""),"",IF($D$7="Menor é melhor",IF(E15<=$H$6,"Sim","Não"),IF(E15>=$H$6,"Sim","Não")))
B16: 6 | G16: =IF(OR($H$6="",E16=""),NA(),$H$6) -> #N/A | H16: =IF(OR(E16="",$H$6=""),"",IF($D$7="Menor é melhor",IF(E16<=$H$6,"Sim","Não"),IF(E16>=$H$6,"Sim","Não")))
B17: 7 | G17: =IF(OR($H$6="",E17=""),NA(),$H$6) -> #N/A | H17: =IF(OR(E17="",$H$6=""),"",IF($D$7="Menor é melhor",IF(E17<=$H$6,"Sim","Não"),IF(E17>=$H$6,"Sim","Não")))
B18: 8 | G18: =IF(OR($H$6="",E18=""),NA(),$H$6) -> #N/A | H18: =IF(OR(E18="",$H$6=""),"",IF($D$7="Menor é melhor",IF(E18<=$H$6,"Sim","Não"),IF(E18>=$H$6,"Sim","Não")))
B19: 9 | G19: =IF(OR($H$6="",E19=""),NA(),$H$6) -> #N/A | H19: =IF(OR(E19="",$H$6=""),"",IF($D$7="Menor é melhor",IF(E19<=$H$6,"Sim","Não"),IF(E19>=$H$6,"Sim","Não")))
B20: 10 | G20: =IF(OR($H$6="",E20=""),NA(),$H$6) -> #N/A | H20: =IF(OR(E20="",$H$6=""),"",IF($D$7="Menor é melhor",IF(E20<=$H$6,"Sim","Não"),IF(E20>=$H$6,"Sim","Não")))
B21: 11 | G21: =IF(OR($H$6="",E21=""),NA(),$H$6) -> #N/A | H21: =IF(OR(E21="",$H$6=""),"",IF($D$7="Menor é melhor",IF(E21<=$H$6,"Sim","Não"),IF(E21>=$H$6,"Sim","Não")))
B22: 12 | G22: =IF(OR($H$6="",E22=""),NA(),$H$6) -> #N/A | H22: =IF(OR(E22="",$H$6=""),"",IF($D$7="Menor é melhor",IF(E22<=$H$6,"Sim","Não"),IF(E22>=$H$6,"Sim","Não")))
... B26: 16 | G26: =IF(OR($H$6="",E26=""),NA(),$H$6) -> #N/A | H26: =IF(OR(E26="",$H$6=""),"",IF($D$7="Menor é melhor",IF(E26<=$H$6,"Sim","Não"),IF(E26>=$H$6,"Sim","Não")))
B28: Resumo automático
B29: Medições registradas | F29: =COUNT(E11:E26) -> 0
B30: Média antes das ações | F30: =IFERROR(AVERAGEIF(D11:D26,"Antes",E11:E26),"Sem dados") -> Sem dados
B31: Média depois das ações | F31: =IFERROR(AVERAGEIF(D11:D26,"Depois",E11:E26),"Sem dados") -> Sem dados
B32: Variação (depois menos antes) | F32: =IF(AND(ISNUMBER(F30),ISNUMBER(F31)),F31-F30,"Sem dados") -> Sem dados
B33: Medições de depois que atingiram a meta | F33: =COUNTIFS(D11:D26,"Depois",H11:H26,"Sim") -> 0
B34: Resultado do ciclo | F34: =IF(OR(NOT(ISNUMBER(F31)),$H$6=""),"Sem dados para concluir",IF(OR(AND($D$7="Menor é melhor",F31<=$H$6),AND($D$7<>"Menor é melhor",F31>=$H$6)),"Meta atingida: padronize","Meta não atingida: volte à análise das causas")) -> Sem dados para concluir
B36: Gráfico: indicador ao longo do tempo

Sheet Checklist
B1: Checklist de validação do ciclo PDCA
B2: Escolha o status de cada item na lista suspensa (coluna em amarelo-claro).
B4: # | C4: Item de verificação | D4: Status | E4: Observações
B5: 1 | C5: O problema está descrito com fatos e dados, sem causa nem solução embutida.
B6: 2 | C6: Existe um indicador, e a situação inicial foi medida.
B7: 3 | C7: A meta tem objetivo, valor e prazo.
B8: 4 | C8: O problema foi observado no local e os dados foram estratificados.
B9: 5 | C9: A causa raiz foi identificada e confirmada com dados.
B10: 6 | C10: Cada ação do plano ataca uma causa confirmada e tem responsável e prazo.
B11: 7 | C11: As pessoas envolvidas foram treinadas, e os desvios da execução foram registrados.
B12: 8 | C12: O resultado foi medido com o mesmo indicador e o mesmo método da situação inicial.
B13: 9 | C13: O resultado foi comparado com a meta, e os efeitos colaterais foram avaliados.
B14: 10 | C14: O que funcionou virou padrão: documentos atualizados e pessoas treinadas.
B15: 11 | C15: As lições aprendidas e as pendências foram registradas.
B16: 12 | C16: O próximo ciclo foi definido.
B18: Resumo automático
B19: Itens atendidos (Sim) | D19: =COUNTIF(D5:D16,"Sim") -> 0
B20: Itens parciais | D20: =COUNTIF(D5:D16,"Parcial") -> 0
B21: Itens não atendidos | D21: =COUNTIF(D5:D16,"Não") -> 0
B22: Itens sem resposta | D22: =COUNTBLANK(D5:D16) -> 12
B23: Percentual atendido | D23: =D19/ROWS(D5:D16) -> 0
B24: Situação | D24: =IF(D19=ROWS(D5:D16),"Validado",IF(D22>0,"Em andamento","Com pendências")) -> Em andamento

Sheet Padronização
B1: Padronização e lições aprendidas
B2: Registre aqui o que vira padrão, quem precisa ser treinado, o que ficou pendente e o que se aprendeu.
B4: # | C4: Item | D4: Tipo | E4: Documento ou processo afetado | F4: Ação | G4: Responsável | H4: Prazo | I4: Status
B5: Ex. | C5: Nova escala de entregadores para sextas e sábados | D5: Padrão | E5: Instrução de trabalho da expedição | F5: Revisar a instrução e divulgar à equipe | G5: Gerente da loja | H5: 46325 | I5: Aberta
B6: 1
B7: 2
B8: 3
B9: 4
B10: 5
B11: 6
B12: 7
B13: 8
B14: 9
B15: 10
B16: 11
B17: 12
... B20: 15
B22: Resumo automático
B23: Itens registrados | G23: =COUNTA(C6:C20) -> 0
B24: Abertos | G24: =COUNTIF(I6:I20,"Aberta") -> 0
B25: Em andamento | G25: =COUNTIF(I6:I20,"Em andamento") -> 0
B26: Concluídos | G26: =COUNTIF(I6:I20,"Concluída") -> 0
B27: Padrões e treinamentos ainda não concluídos | G27: =COUNTIFS(D6:D20,"Padrão",I6:I20,"<>Concluída")+COUNTIFS(D6:D20,"Treinamento",I6:I20,"<>Concluída") -> 0
B28: Lições aprendidas registradas | G28: =COUNTIF(D6:D20,"Lição aprendida") -> 0

Sheet Exemplo 1 - Pizzaria
B1: PDCA — Registro do ciclo de melhoria
B2: Exemplo preenchido, para consulta. Use a aba PDCA para o seu ciclo.
B4: Tema do ciclo | D4: Reduzir os atrasos nas entregas de delivery | G4: Dono do problema | H4: Gerente da loja
B5: Área / unidade | D5: Pizzaria (loja) | G5: Data de início | H5: 46188
B6: Elaborado por | D6: Equipe da loja | G6: Versão | H6: 1.0
B7: Descrição do problema | D7: 18% das entregas de delivery chegam ao cliente depois de 40 minutos. Os atrasos geram reclamações e pedidos cancelados.
B8: Indicador | D8: % de entregas em até 40 minutos | G8: Unidade de medida | H8: %
B9: Situação inicial (valor) | D9: 82 | G9: Meta (valor) | H9: 95
B10: Sentido do indicador | D10: Maior é melhor | G10: Prazo da meta | H10: 46271
B11: Fora do escopo | D11: Atendimento no salão, compra de ingredientes e cardápio.
B13: # | C13: Fase | D13: Etapa | E13: Pergunta-guia | F13: Registro: o que foi feito ou decidido | G13: Ferramenta ou evidência | H13: Responsável | I13: Conclusão | J13: Status
B14: Leia de cima para baixo: cada etapa só começa quando a anterior está concluída. O registro resume o que foi feito; a evidência diz onde está a prova.
B15: 1 | C15: P Planejar | D15: Identificar o problema | E15: Qual é o problema, quanto ele pesa e qual é a meta? | F15: 18% das entregas chegam depois de 40 minutos. Meta: passar de 82% para 95% de entregas no prazo, em até 12 semanas. | G15: Relatório do aplicativo de delivery | H15: Gerente da loja | I15: 46199 | J15: Concluída
B16: 2 | D16: Observar | E16: Onde, quando e com quem o problema acontece? | F16: Os atrasos se concentram nas sextas e sábados, das 19h às 22h. Em 46% deles, a pizza pronta ficou esperando entregador. | G16: Estratificação por dia e horário; gráfico de Pareto | H16: Líder da expedição | I16: 46213 | J16: Concluída
B17: 3 | D17: Analisar as causas | E17: Por que acontece? Qual é a causa raiz, confirmada com dados? | F17: Causas confirmadas: a escala de entregadores é igual em todos os dias; os pedidos saem sem agrupamento por bairro; o formulário aceita endereço sem complemento. | G17: Diagrama de Ishikawa; 5 porquês | H17: Equipe da loja | I17: 46220 | J17: Concluída
B18: 4 | D18: Planejar a ação | E18: O que será feito, por quem e até quando? | F18: Três ações: reforçar a escala no pico, agrupar pedidos por bairro na expedição e tornar o complemento do endereço obrigatório. | G18: Plano de ação 5W2H | H18: Gerente da loja | I18: 46227 | J18: Concluída
B19: 5 | C19: D Executar | D19: Executar | E19: O plano foi executado como previsto? O que foi diferente? | F19: Ações implantadas nas semanas 7 e 8, com treinamento da expedição. Desvio: o agrupamento por bairro só começou na semana 8. | G19: Plano de ação com datas reais; lista de presença | H19: Líder da expedição | I19: 46241 | J19: Concluída
B20: 6 | C20: C Verificar | D20: Verificar | E20: A meta foi atingida? Houve efeito colateral? | F20: Média de 95,5% nas semanas 9 a 12. Meta atingida. Efeito colateral: o custo com entregadores subiu R$ 600 por mês. | G20: Gráfico de tendência, antes e depois | H20: Gerente da loja | I20: 46273 | J20: Concluída
B21: 7 | C21: A Agir | D21: Padronizar | E21: O que vira padrão e quem precisa ser treinado? | F21: A nova escala virou padrão, a instrução de trabalho da expedição foi atualizada e o campo obrigatório foi mantido. | G21: Instrução de trabalho revisada; registro de treinamento | H21: Gerente da loja | I21: 46280 | J21: Concluída
B22: 8 | D22: Concluir | E22: O que aprendemos e qual é o próximo ciclo? | F22: Lição: medir por faixa de horário, e não só pela média do dia. Próximo ciclo: a fila do forno, segundo item do Pareto. | G22: Registro de lições aprendidas | H22: Equipe da loja | I22: 46283 | J22: Concluída
B24: Resumo automático
B25: Etapas concluídas | F25: =COUNTIF(J15:J22,"Concluída") -> 8
B26: Fase atual do ciclo | F26: =IF(COUNTIF(J15:J18,"Concluída")<4,"P — Planejar",IF(J19<>"Concluída","D — Executar",IF(J20<>"Concluída","C — Verificar",IF(COUNTIF(J21:J22,"Concluída")<2,"A — Agir","Ciclo concluído")))) -> Ciclo concluído
B27: Aviso: sequência das etapas | F27: =IF(SUMPRODUCT((J16:J22="Concluída")*(J15:J21<>"Concluída"))>0,"Há etapa concluída antes da anterior","OK") -> OK
B28: Aviso: registro das etapas | F28: =IF(SUMPRODUCT((J15:J22="Concluída")*(F15:F22=""))>0,"Há etapa concluída sem registro","OK") -> OK
B29: Aviso: meta | F29: =IF(OR(D9="",H9=""),"Informe a situação inicial e a meta",IF(D10="","Informe o sentido do indicador",IF(OR(AND(D10="Menor é melhor",H9>=D9),AND(D10="Maior é melhor",H9<=D9)),"A meta não melhora a situação inicial","OK"))) -> OK
B30: Diferença entre a meta e a situação inicial | F30: =IF(OR(D9="",H9=""),"",H9-D9) -> 13
B31: Campos do cabeçalho preenchidos | F31: =COUNTA(D4,H4,D5,H5,D6,H6,D7,D8,H8,D9,H9,D10,H10,D11) -> 14
B33: Verificação: medições do indicador
B34: # | C34: Período | D34: Momento | E34: Valor medido | F34: Observações | G34: Meta | H34: Atingiu a meta?
B35: 1 | C35: Semana 1 | D35: Antes | E35: 81 | G35: =IF(OR($H$9="",E35=""),NA(),$H$9) -> 95 | H35: =IF(OR(E35="",$H$9=""),"",IF($D$10="Menor é melhor",IF(E35<=$H$9,"Sim","Não"),IF(E35>=$H$9,"Sim","Não"))) -> Não
B36: 2 | C36: Semana 2 | D36: Antes | E36: 83 | G36: =IF(OR($H$9="",E36=""),NA(),$H$9) -> 95 | H36: =IF(OR(E36="",$H$9=""),"",IF($D$10="Menor é melhor",IF(E36<=$H$9,"Sim","Não"),IF(E36>=$H$9,"Sim","Não"))) -> Não
B37: 3 | C37: Semana 3 | D37: Antes | E37: 80 | F37: Chuva forte no sábado | G37: =IF(OR($H$9="",E37=""),NA(),$H$9) -> 95 | H37: =IF(OR(E37="",$H$9=""),"",IF($D$10="Menor é melhor",IF(E37<=$H$9,"Sim","Não"),IF(E37>=$H$9,"Sim","Não"))) -> Não
B38: 4 | C38: Semana 4 | D38: Antes | E38: 84 | G38: =IF(OR($H$9="",E38=""),NA(),$H$9) -> 95 | H38: =IF(OR(E38="",$H$9=""),"",IF($D$10="Menor é melhor",IF(E38<=$H$9,"Sim","Não"),IF(E38>=$H$9,"Sim","Não"))) -> Não
B39: 5 | C39: Semana 5 | D39: Antes | E39: 82 | G39: =IF(OR($H$9="",E39=""),NA(),$H$9) -> 95 | H39: =IF(OR(E39="",$H$9=""),"",IF($D$10="Menor é melhor",IF(E39<=$H$9,"Sim","Não"),IF(E39>=$H$9,"Sim","Não"))) -> Não
B40: 6 | C40: Semana 6 | D40: Antes | E40: 82 | G40: =IF(OR($H$9="",E40=""),NA(),$H$9) -> 95 | H40: =IF(OR(E40="",$H$9=""),"",IF($D$10="Menor é melhor",IF(E40<=$H$9,"Sim","Não"),IF(E40>=$H$9,"Sim","Não"))) -> Não
B41: 7 | C41: Semana 7 | D41: Durante | E41: 86 | F41: Escala reforçada e campo obrigatório | G41: =IF(OR($H$9="",E41=""),NA(),$H$9) -> 95 | H41: =IF(OR(E41="",$H$9=""),"",IF($D$10="Menor é melhor",IF(E41<=$H$9,"Sim","Não"),IF(E41>=$H$9,"Sim","Não"))) -> Não
B42: 8 | C42: Semana 8 | D42: Durante | E42: 90 | F42: Início do agrupamento por bairro | G42: =IF(OR($H$9="",E42=""),NA(),$H$9) -> 95 | H42: =IF(OR(E42="",$H$9=""),"",IF($D$10="Menor é melhor",IF(E42<=$H$9,"Sim","Não"),IF(E42>=$H$9,"Sim","Não"))) -> Não
B43: 9 | C43: Semana 9 | D43: Depois | E43: 94 | G43: =IF(OR($H$9="",E43=""),NA(),$H$9) -> 95 | H43: =IF(OR(E43="",$H$9=""),"",IF($D$10="Menor é melhor",IF(E43<=$H$9,"Sim","Não"),IF(E43>=$H$9,"Sim","Não"))) -> Não
B44: 10 | C44: Semana 10 | D44: Depois | E44: 96 | G44: =IF(OR($H$9="",E44=""),NA(),$H$9) -> 95 | H44: =IF(OR(E44="",$H$9=""),"",IF($D$10="Menor é melhor",IF(E44<=$H$9,"Sim","Não"),IF(E44>=$H$9,"Sim","Não"))) -> Sim
...

Sheet Exemplo 2 - Compras
B1: PDCA — Registro do ciclo de melhoria
B2: Exemplo preenchido, para consulta. Use a aba PDCA para o seu ciclo.
B4: Tema do ciclo | D4: Reduzir o prazo de compra | G4: Dono do problema | H4: Gerente de Suprimentos
B5: Área / unidade | D5: Suprimentos | G5: Data de início | H5: 46174
B6: Elaborado por | D6: Equipe de compras | G6: Versão | H6: 1.0
B7: Descrição do problema | D7: O pedido de compra leva, em média, 12 dias úteis para ser emitido depois da requisição aprovada. As áreas recebem os itens depois da data de necessidade.
B8: Indicador | D8: Dias úteis entre a requisição aprovada e o pedido emitido | G8: Unidade de medida | H8: dias úteis
B9: Situação inicial (valor) | D9: 12 | G9: Meta (valor) | H9: 7
B10: Sentido do indicador | D10: Menor é melhor | G10: Prazo da meta | H10: 46265
B11: Fora do escopo | D11: Homologação de fornecedores, pagamento e gestão de estoque.
B13: # | C13: Fase | D13: Etapa | E13: Pergunta-guia | F13: Registro: o que foi feito ou decidido | G13: Ferramenta ou evidência | H13: Responsável | I13: Conclusão | J13: Status
B14: Leia de cima para baixo: cada etapa só começa quando a anterior está concluída. O registro resume o que foi feito; a evidência diz onde está a prova.
B15: 1 | C15: P Planejar | D15: Identificar o problema | E15: Qual é o problema, quanto ele pesa e qual é a meta? | F15: O pedido leva, em média, 12 dias úteis para ser emitido. Meta: reduzir para 7 dias úteis, em 3 meses. | G15: Relatório do sistema de compras | H15: Gerente de Suprimentos | I15: 46178 | J15: Concluída
B16: 2 | D16: Observar | E16: Onde, quando e com quem o problema acontece? | F16: 40% das requisições são devolvidas por especificação incompleta. Compras de baixo valor demoram tanto quanto as de alto valor. | G16: Estratificação por valor e por motivo de devolução | H16: Analista de compras | I16: 46192 | J16: Concluída
B17: 3 | D17: Analisar as causas | E17: Por que acontece? Qual é a causa raiz, confirmada com dados? | F17: Causas confirmadas: o formulário de requisição não tem campos obrigatórios; a política exige três cotações para qualquer valor. | G17: 5 porquês; mapa do processo | H17: Equipe de compras | I17: 46199 | J17: Concluída
B18: 4 | D18: Planejar a ação | E18: O que será feito, por quem e até quando? | F18: Novo formulário com campos obrigatórios e catálogo de itens. Uma cotação só para compras de até R$ 2.000, com aprovação da Diretoria. | G18: Plano de ação 5W2H; política de compras revisada | H18: Gerente de Suprimentos | I18: 46206 | J18: Concluída
B19: 5 | C19: D Executar | D19: Executar | E19: O plano foi executado como previsto? O que foi diferente? | F19: Piloto de 4 semanas em duas áreas requisitantes, com treinamento dos requisitantes e dos compradores. | G19: Registro do piloto | H19: Analista de compras | I19: 46234 | J19: Concluída
B20: 6 | C20: C Verificar | D20: Verificar | E20: A meta foi atingida? Houve efeito colateral? | F20: O prazo caiu para 8 dias úteis. Meta não atingida. As devoluções caíram de 40% para 12%. O tempo restante está na revisão de contratos. | G20: Comparação antes e depois; novo Pareto | H20: Gerente de Suprimentos | I20: 46262 | J20: Concluída
B21: 7 | C21: A Agir | D21: Padronizar | E21: O que vira padrão e quem precisa ser treinado? | F21: O formulário e a nova alçada foram estendidos a todas as áreas, porque funcionaram. O procedimento de compras foi revisado. | G21: Procedimento revisado; comunicado às áreas | H21: Gerente de Suprimentos | I21: 46276 | J21: Concluída
B22: 8 | D22: Concluir | E22: O que aprendemos e qual é o próximo ciclo? | F22: A meta de 7 dias foi mantida. Novo ciclo aberto, com foco na etapa de revisão de contratos. | G22: Registro de lições aprendidas; novo ciclo | H22: Equipe de compras | I22: 46283 | J22: Concluída
B24: Resumo automático
B25: Etapas concluídas | F25: =COUNTIF(J15:J22,"Concluída") -> 8
B26: Fase atual do ciclo | F26: =IF(COUNTIF(J15:J18,"Concluída")<4,"P — Planejar",IF(J19<>"Concluída","D — Executar",IF(J20<>"Concluída","C — Verificar",IF(COUNTIF(J21:J22,"Concluída")<2,"A — Agir","Ciclo concluído")))) -> Ciclo concluído
B27: Aviso: sequência das etapas | F27: =IF(SUMPRODUCT((J16:J22="Concluída")*(J15:J21<>"Concluída"))>0,"Há etapa concluída antes da anterior","OK") -> OK
B28: Aviso: registro das etapas | F28: =IF(SUMPRODUCT((J15:J22="Concluída")*(F15:F22=""))>0,"Há etapa concluída sem registro","OK") -> OK
B29: Aviso: meta | F29: =IF(OR(D9="",H9=""),"Informe a situação inicial e a meta",IF(D10="","Informe o sentido do indicador",IF(OR(AND(D10="Menor é melhor",H9>=D9),AND(D10="Maior é melhor",H9<=D9)),"A meta não melhora a situação inicial","OK"))) -> OK
B30: Diferença entre a meta e a situação inicial | F30: =IF(OR(D9="",H9=""),"",H9-D9) -> -5
B31: Campos do cabeçalho preenchidos | F31: =COUNTA(D4,H4,D5,H5,D6,H6,D7,D8,H8,D9,H9,D10,H10,D11) -> 14
B33: Verificação: medições do indicador
B34: # | C34: Período | D34: Momento | E34: Valor medido | F34: Observações | G34: Meta | H34: Atingiu a meta?
B35: 1 | C35: Semana 1 | D35: Antes | E35: 12.5 | G35: =IF(OR($H$9="",E35=""),NA(),$H$9) -> 7 | H35: =IF(OR(E35="",$H$9=""),"",IF($D$10="Menor é melhor",IF(E35<=$H$9,"Sim","Não"),IF(E35>=$H$9,"Sim","Não"))) -> Não
B36: 2 | C36: Semana 2 | D36: Antes | E36: 11.5 | G36: =IF(OR($H$9="",E36=""),NA(),$H$9) -> 7 | H36: =IF(OR(E36="",$H$9=""),"",IF($D$10="Menor é melhor",IF(E36<=$H$9,"Sim","Não"),IF(E36>=$H$9,"Sim","Não"))) -> Não
B37: 3 | C37: Semana 3 | D37: Antes | E37: 12 | G37: =IF(OR($H$9="",E37=""),NA(),$H$9) -> 7 | H37: =IF(OR(E37="",$H$9=""),"",IF($D$10="Menor é melhor",IF(E37<=$H$9,"Sim","Não"),IF(E37>=$H$9,"Sim","Não"))) -> Não
B38: 4 | C38: Semana 4 | D38: Antes | E38: 12 | G38: =IF(OR($H$9="",E38=""),NA(),$H$9) -> 7 | H38: =IF(OR(E38="",$H$9=""),"",IF($D$10="Menor é melhor",IF(E38<=$H$9,"Sim","Não"),IF(E38>=$H$9,"Sim","Não"))) -> Não
B39: 5 | C39: Semana 5 | D39: Antes | E39: 12 | G39: =IF(OR($H$9="",E39=""),NA(),$H$9) -> 7 | H39: =IF(OR(E39="",$H$9=""),"",IF($D$10="Menor é melhor",IF(E39<=$H$9,"Sim","Não"),IF(E39>=$H$9,"Sim","Não"))) -> Não
B40: 6 | C40: Semana 6 | D40: Durante | E40: 11 | F40: Início do piloto em duas áreas | G40: =IF(OR($H$9="",E40=""),NA(),$H$9) -> 7 | H40: =IF(OR(E40="",$H$9=""),"",IF($D$10="Menor é melhor",IF(E40<=$H$9,"Sim","Não"),IF(E40>=$H$9,"Sim","Não"))) -> Não
B41: 7 | C41: Semana 7 | D41: Durante | E41: 10 | G41: =IF(OR($H$9="",E41=""),NA(),$H$9) -> 7 | H41: =IF(OR(E41="",$H$9=""),"",IF($D$10="Menor é melhor",IF(E41<=$H$9,"Sim","Não"),IF(E41>=$H$9,"Sim","Não"))) -> Não
B42: 8 | C42: Semana 8 | D42: Durante | E42: 9 | G42: =IF(OR($H$9="",E42=""),NA(),$H$9) -> 7 | H42: =IF(OR(E42="",$H$9=""),"",IF($D$10="Menor é melhor",IF(E42<=$H$9,"Sim","Não"),IF(E42>=$H$9,"Sim","Não"))) -> Não
B43: 9 | C43: Semana 9 | D43: Durante | E43: 8.5 | G43: =IF(OR($H$9="",E43=""),NA(),$H$9) -> 7 | H43: =IF(OR(E43="",$H$9=""),"",IF($D$10="Menor é melhor",IF(E43<=$H$9,"Sim","Não"),IF(E43>=$H$9,"Sim","Não"))) -> Não
B44: 10 | C44: Semana 10 | D44: Depois | E44: 8 | G44: =IF(OR($H$9="",E44=""),NA(),$H$9) -> 7 | H44: =IF(OR(E44="",$H$9=""),"",IF($D$10="Menor é melhor",IF(E44<=$H$9,"Sim","Não"),IF(E44>=$H$9,"Sim","Não"))) -> Não
...
