Workbook

Sheet Instruções
B1: Requisitos do cliente e análise de pedidos — Como usar esta planilha
B2: Modelo para definir a oferta, analisar cada pedido antes de aceitar e controlar as mudanças nos pedidos aceitos.
B4: Legenda: onde preencher
B5: Amarelo-claro | C5: Células de entrada. É aqui que você digita.
B6: Cinza | C6: Células calculadas ou fixas (rótulos, leituras, conferências, avisos). Não altere.
B7: Cinza em itálico | C7: Linha de exemplo (marcada com “Ex.”). Mostra o formato esperado e não entra nas contagens.
B8: Listas suspensas | C8: Respostas às perguntas, decisão, capacidade confirmada, documentos atualizados e checklist aceitam apenas as opções da lista.
B9: Comentários | C9: Células com triângulo vermelho no canto trazem uma dica de preenchimento. Passe o mouse sobre elas.
B11: As sete perguntas da análise
B12: 1 · Especificação | C12: O produto e a especificação estão definidos, e a organização consegue cumpri-la?
B13: 2 · Capacidade e prazo | C13: A quantidade e o prazo cabem na capacidade, considerando o que já foi aceito?
B14: 3 · Entrega e pós-entrega | C14: O local, a forma de entrega e o que vem depois dela estão combinados?
B15: 4 · Uso pretendido | C15: Os requisitos que o cliente não declarou, mas que o uso exige, foram considerados?
B16: 5 · Requisitos legais | C16: Os requisitos legais e regulamentares do produto e do uso foram identificados?
B17: 6 · Diferenças | C17: As diferenças em relação à proposta, ao pedido anterior ou ao catálogo foram resolvidas?
B18: 7 · Preço e condições | C18: O preço, o pagamento e as demais condições estão confirmados?
B20: As regras de cálculo
B21: Pode aceitar | C21: As 7 perguntas foram respondidas, todas com “Sim” ou “Não se aplica”.
B22: Resolver antes de aceitar | C22: Alguma resposta é “Não”. O pedido pode ser aceito com alteração negociada, recusado ou ficar em análise.
B23: Análise incompleta | C23: Alguma pergunta ficou sem resposta.
B24: Aceito com pendência | C24: A decisão é “Aceito”, e alguma resposta é “Não”. É o aviso mais grave da planilha.
B25: Analisado depois de aceitar | C25: A data da análise é posterior à data da confirmação ao cliente.
B26: Mudança a rever | C26: Mudança sem análise, sem os documentos atualizados ou sem quem foi informado.
B28: Ordem recomendada de preenchimento
B29: Passo 1 | C29: Aba Oferta: escreva cada produto ou serviço oferecido, a especificação, os requisitos legais, o que não se garante, onde o cliente é informado e se a capacidade foi confirmada.
B30: Passo 2 | C30: Aba Pedidos: registre cada pedido, com o que o cliente pede e os requisitos não declarados e legais identificados.
B31: Passo 3 | C31: Aba Pedidos: responda às 7 perguntas, registre a decisão, o que foi negociado ou o motivo, quem analisou e as datas da análise e da confirmação.
B32: Passo 4 | C32: Aba Mudanças: registre cada alteração nos pedidos aceitos, com a análise, os documentos e quem foi informado.
B33: Passo 5 | C33: Aba Painel: leia os pedidos a rever, as respostas “não” por pergunta e as mudanças a rever.
B34: Passo 6 | C34: Aba Checklist: valide a rotina.
B36: Abas da planilha
B37: Oferta | C37: Até 12 itens oferecidos. Calcula a conferência de cada item.
B38: Pedidos | C38: Até 60 pedidos. Calcula a leitura da análise, as pendências e a conferência da decisão.
B39: Mudanças | C39: Até 30 mudanças nos pedidos aceitos. Calcula a conferência de cada uma.
B40: Painel | C40: Os indicadores, as respostas por pergunta, o gráfico e o aviso.
B41: Checklist | C41: Doze verificações da rotina, com percentual de conclusão.
B42: Exemplo 1 - Pizzaria | C42: As encomendas e os pedidos especiais de 22 a 28/03/2027.
B43: Exemplo 2 - Indústria | C43: Os pedidos e as propostas de 01 a 15/06/2027.
B45: Regras e premissas do modelo
B46: Análise simplificada | C46: Para o pedido igual ao anterior, ou pelo catálogo, as perguntas podem ser respondidas na tela de confirmação. Use “Não se aplica” quando a pergunta não couber.
...

Sheet Oferta
B1: A oferta
B2: O que a organização se dispõe a fornecer. É a base da análise: o pedido que cabe na oferta é mais simples de analisar.
B4: # | C4: Item | D4: O que se oferece | E4: Requisitos legais | F4: O que não se garante | G4: Onde o cliente é informado | H4: Capacidade confirmada? | I4: Conferência
C5: Produto ou serviço | D5: Especificação, prazos, limites | E5: Leis e regulamentos | F5: Escrito, para o cliente saber | G5: Catálogo, site, proposta | H5: Lista | I5: Calculada
B6: 1 | I6: =IF(C6="",IF(COUNTA(D6:H6)>0,"Falta o item",""),IF(D6="","Falta a especificação",IF(G6="","Falta onde o cliente é informado",IF(H6<>"Sim","Capacidade não confirmada","OK"))))
B7: 2 | I7: =IF(C7="",IF(COUNTA(D7:H7)>0,"Falta o item",""),IF(D7="","Falta a especificação",IF(G7="","Falta onde o cliente é informado",IF(H7<>"Sim","Capacidade não confirmada","OK"))))
B8: 3 | I8: =IF(C8="",IF(COUNTA(D8:H8)>0,"Falta o item",""),IF(D8="","Falta a especificação",IF(G8="","Falta onde o cliente é informado",IF(H8<>"Sim","Capacidade não confirmada","OK"))))
B9: 4 | I9: =IF(C9="",IF(COUNTA(D9:H9)>0,"Falta o item",""),IF(D9="","Falta a especificação",IF(G9="","Falta onde o cliente é informado",IF(H9<>"Sim","Capacidade não confirmada","OK"))))
B10: 5 | I10: =IF(C10="",IF(COUNTA(D10:H10)>0,"Falta o item",""),IF(D10="","Falta a especificação",IF(G10="","Falta onde o cliente é informado",IF(H10<>"Sim","Capacidade não confirmada","OK"))))
B11: 6 | I11: =IF(C11="",IF(COUNTA(D11:H11)>0,"Falta o item",""),IF(D11="","Falta a especificação",IF(G11="","Falta onde o cliente é informado",IF(H11<>"Sim","Capacidade não confirmada","OK"))))
B12: 7 | I12: =IF(C12="",IF(COUNTA(D12:H12)>0,"Falta o item",""),IF(D12="","Falta a especificação",IF(G12="","Falta onde o cliente é informado",IF(H12<>"Sim","Capacidade não confirmada","OK"))))
B13: 8 | I13: =IF(C13="",IF(COUNTA(D13:H13)>0,"Falta o item",""),IF(D13="","Falta a especificação",IF(G13="","Falta onde o cliente é informado",IF(H13<>"Sim","Capacidade não confirmada","OK"))))
B14: 9 | I14: =IF(C14="",IF(COUNTA(D14:H14)>0,"Falta o item",""),IF(D14="","Falta a especificação",IF(G14="","Falta onde o cliente é informado",IF(H14<>"Sim","Capacidade não confirmada","OK"))))
B15: 10 | I15: =IF(C15="",IF(COUNTA(D15:H15)>0,"Falta o item",""),IF(D15="","Falta a especificação",IF(G15="","Falta onde o cliente é informado",IF(H15<>"Sim","Capacidade não confirmada","OK"))))
B16: 11 | I16: =IF(C16="",IF(COUNTA(D16:H16)>0,"Falta o item",""),IF(D16="","Falta a especificação",IF(G16="","Falta onde o cliente é informado",IF(H16<>"Sim","Capacidade não confirmada","OK"))))
B17: 12 | I17: =IF(C17="",IF(COUNTA(D17:H17)>0,"Falta o item",""),IF(D17="","Falta a especificação",IF(G17="","Falta onde o cliente é informado",IF(H17<>"Sim","Capacidade não confirmada","OK"))))
B19: Resumo automático
B20: Itens na oferta | D20: =COUNTA(C6:C17) -> 0
B21: Aviso | D21: =IF(D20=0,"Escreva a oferta",IF(COUNTIF(I6:I17,"OK")<D20,"Há item a rever: veja a coluna Conferência","OK")) -> Escreva a oferta

Sheet Pedidos
B1: Análise crítica dos pedidos
B2: Uma linha por pedido. Responda às sete perguntas antes de confirmar ao cliente.
B4: # | C4: Nº do pedido | D4: Data | E4: Cliente | F4: Canal | G4: O que pede | H4: Requisitos não declarados e legais identificados | I4: Prazo pedido | J4: 1 · Especificação | K4: 2 · Capacidade e prazo | L4: 3 · Entrega e pós-entrega | M4: 4 · Uso pretendido | N4: 5 · Requisitos legais | O4: 6 · Diferenças | P4: 7 · Preço e condições | Q4: Leitura | R4: Pendências | S4: Decisão | T4: O que foi negociado, ou o motivo | U4: Quem analisou | V4: Data da análise | W4: Data da confirmação | X4: Conferência
C5: Código | D5: Recebido em | F5: Telefone, e-mail | G5: Os requisitos declarados | H5: O uso, a lei, as diferenças | I5: Data | J5: Lista | K5: Lista | L5: Lista | M5: Lista | N5: Lista | O5: Lista | P5: Lista | Q5: Calculada | R5: Calculadas | S5: Lista | T5: Com o aceite do cliente | U5: Uma função | V5: Data | W5: Data | X5: Calculada
B6: Ex. | C6: E-32 | D6: 46471 | E6: Comissão de formatura | F6: Telefone | G6: 50 pizzas para sábado 27/03 às 21h. | H6: Cerveja pedida para turma com menores. | I6: 46473 | J6: Sim | K6: Não | L6: Sim | M6: Sim | N6: Não | O6: Sim | P6: Sim | Q6: Resolver antes de aceitar | R6: 2 | S6: Aceito com alteração | T6: Entrega às 18h30, sem bebida alcoólica. | U6: Gerente da loja | V6: 46471 | W6: 46471 | X6: OK
B7: 1 | Q7: =IF(AND(C7="",E7="",G7=""),"",IF(COUNTA(J7:P7)<7,"Análise incompleta",IF(COUNTIF(J7:P7,"Não")>0,"Resolver antes de aceitar","Pode aceitar"))) | R7: =IF(AND(C7="",E7="",G7=""),"",COUNTIF(J7:P7,"Não")) | X7: =IF(AND(C7="",E7="",G7=""),"",IF(S7="","Falta a decisão",IF(U7="","Falta quem analisou",IF(S7="Em análise","OK",IF(COUNTA(J7:P7)<7,"Falta responder à análise",IF(V7="","Falta a data da análise",IF(AND(OR(S7="Aceito",S7="Aceito com alteração"),W7=""),"Falta a data da confirmação",IF(AND(OR(S7="Aceito",S7="Aceito com alteração"),V7>W7),"Analisado depois de aceitar",IF(AND(S7="Aceito",COUNTIF(J7:P7,"Não")>0),"Aceito com pendência na análise",IF(AND(S7="Aceito com alteração",T7=""),"Falta o que foi negociado",IF(AND(S7="Recusado",T7=""),"Falta o motivo da recusa","OK")))))))))))
B8: 2 | Q8: =IF(AND(C8="",E8="",G8=""),"",IF(COUNTA(J8:P8)<7,"Análise incompleta",IF(COUNTIF(J8:P8,"Não")>0,"Resolver antes de aceitar","Pode aceitar"))) | R8: =IF(AND(C8="",E8="",G8=""),"",COUNTIF(J8:P8,"Não")) | X8: =IF(AND(C8="",E8="",G8=""),"",IF(S8="","Falta a decisão",IF(U8="","Falta quem analisou",IF(S8="Em análise","OK",IF(COUNTA(J8:P8)<7,"Falta responder à análise",IF(V8="","Falta a data da análise",IF(AND(OR(S8="Aceito",S8="Aceito com alteração"),W8=""),"Falta a data da confirmação",IF(AND(OR(S8="Aceito",S8="Aceito com alteração"),V8>W8),"Analisado depois de aceitar",IF(AND(S8="Aceito",COUNTIF(J8:P8,"Não")>0),"Aceito com pendência na análise",IF(AND(S8="Aceito com alteração",T8=""),"Falta o que foi negociado",IF(AND(S8="Recusado",T8=""),"Falta o motivo da recusa","OK")))))))))))
B9: 3 | Q9: =IF(AND(C9="",E9="",G9=""),"",IF(COUNTA(J9:P9)<7,"Análise incompleta",IF(COUNTIF(J9:P9,"Não")>0,"Resolver antes de aceitar","Pode aceitar"))) | R9: =IF(AND(C9="",E9="",G9=""),"",COUNTIF(J9:P9,"Não")) | X9: =IF(AND(C9="",E9="",G9=""),"",IF(S9="","Falta a decisão",IF(U9="","Falta quem analisou",IF(S9="Em análise","OK",IF(COUNTA(J9:P9)<7,"Falta responder à análise",IF(V9="","Falta a data da análise",IF(AND(OR(S9="Aceito",S9="Aceito com alteração"),W9=""),"Falta a data da confirmação",IF(AND(OR(S9="Aceito",S9="Aceito com alteração"),V9>W9),"Analisado depois de aceitar",IF(AND(S9="Aceito",COUNTIF(J9:P9,"Não")>0),"Aceito com pendência na análise",IF(AND(S9="Aceito com alteração",T9=""),"Falta o que foi negociado",IF(AND(S9="Recusado",T9=""),"Falta o motivo da recusa","OK")))))))))))
B10: 4 | Q10: =IF(AND(C10="",E10="",G10=""),"",IF(COUNTA(J10:P10)<7,"Análise incompleta",IF(COUNTIF(J10:P10,"Não")>0,"Resolver antes de aceitar","Pode aceitar"))) | R10: =IF(AND(C10="",E10="",G10=""),"",COUNTIF(J10:P10,"Não")) | X10: =IF(AND(C10="",E10="",G10=""),"",IF(S10="","Falta a decisão",IF(U10="","Falta quem analisou",IF(S10="Em análise","OK",IF(COUNTA(J10:P10)<7,"Falta responder à análise",IF(V10="","Falta a data da análise",IF(AND(OR(S10="Aceito",S10="Aceito com alteração"),W10=""),"Falta a data da confirmação",IF(AND(OR(S10="Aceito",S10="Aceito com alteração"),V10>W10),"Analisado depois de aceitar",IF(AND(S10="Aceito",COUNTIF(J10:P10,"Não")>0),"Aceito com pendência na análise",IF(AND(S10="Aceito com alteração",T10=""),"Falta o que foi negociado",IF(AND(S10="Recusado",T10=""),"Falta o motivo da recusa","OK")))))))))))
B11: 5 | Q11: =IF(AND(C11="",E11="",G11=""),"",IF(COUNTA(J11:P11)<7,"Análise incompleta",IF(COUNTIF(J11:P11,"Não")>0,"Resolver antes de aceitar","Pode aceitar"))) | R11: =IF(AND(C11="",E11="",G11=""),"",COUNTIF(J11:P11,"Não")) | X11: =IF(AND(C11="",E11="",G11=""),"",IF(S11="","Falta a decisão",IF(U11="","Falta quem analisou",IF(S11="Em análise","OK",IF(COUNTA(J11:P11)<7,"Falta responder à análise",IF(V11="","Falta a data da análise",IF(AND(OR(S11="Aceito",S11="Aceito com alteração"),W11=""),"Falta a data da confirmação",IF(AND(OR(S11="Aceito",S11="Aceito com alteração"),V11>W11),"Analisado depois de aceitar",IF(AND(S11="Aceito",COUNTIF(J11:P11,"Não")>0),"Aceito com pendência na análise",IF(AND(S11="Aceito com alteração",T11=""),"Falta o que foi negociado",IF(AND(S11="Recusado",T11=""),"Falta o motivo da recusa","OK")))))))))))
B12: 6 | Q12: =IF(AND(C12="",E12="",G12=""),"",IF(COUNTA(J12:P12)<7,"Análise incompleta",IF(COUNTIF(J12:P12,"Não")>0,"Resolver antes de aceitar","Pode aceitar"))) | R12: =IF(AND(C12="",E12="",G12=""),"",COUNTIF(J12:P12,"Não")) | X12: =IF(AND(C12="",E12="",G12=""),"",IF(S12="","Falta a decisão",IF(U12="","Falta quem analisou",IF(S12="Em análise","OK",IF(COUNTA(J12:P12)<7,"Falta responder à análise",IF(V12="","Falta a data da análise",IF(AND(OR(S12="Aceito",S12="Aceito com alteração"),W12=""),"Falta a data da confirmação",IF(AND(OR(S12="Aceito",S12="Aceito com alteração"),V12>W12),"Analisado depois de aceitar",IF(AND(S12="Aceito",COUNTIF(J12:P12,"Não")>0),"Aceito com pendência na análise",IF(AND(S12="Aceito com alteração",T12=""),"Falta o que foi negociado",IF(AND(S12="Recusado",T12=""),"Falta o motivo da recusa","OK")))))))))))
B13: 7 | Q13: =IF(AND(C13="",E13="",G13=""),"",IF(COUNTA(J13:P13)<7,"Análise incompleta",IF(COUNTIF(J13:P13,"Não")>0,"Resolver antes de aceitar","Pode aceitar"))) | R13: =IF(AND(C13="",E13="",G13=""),"",COUNTIF(J13:P13,"Não")) | X13: =IF(AND(C13="",E13="",G13=""),"",IF(S13="","Falta a decisão",IF(U13="","Falta quem analisou",IF(S13="Em análise","OK",IF(COUNTA(J13:P13)<7,"Falta responder à análise",IF(V13="","Falta a data da análise",IF(AND(OR(S13="Aceito",S13="Aceito com alteração"),W13=""),"Falta a data da confirmação",IF(AND(OR(S13="Aceito",S13="Aceito com alteração"),V13>W13),"Analisado depois de aceitar",IF(AND(S13="Aceito",COUNTIF(J13:P13,"Não")>0),"Aceito com pendência na análise",IF(AND(S13="Aceito com alteração",T13=""),"Falta o que foi negociado",IF(AND(S13="Recusado",T13=""),"Falta o motivo da recusa","OK")))))))))))
B14: 8 | Q14: =IF(AND(C14="",E14="",G14=""),"",IF(COUNTA(J14:P14)<7,"Análise incompleta",IF(COUNTIF(J14:P14,"Não")>0,"Resolver antes de aceitar","Pode aceitar"))) | R14: =IF(AND(C14="",E14="",G14=""),"",COUNTIF(J14:P14,"Não")) | X14: =IF(AND(C14="",E14="",G14=""),"",IF(S14="","Falta a decisão",IF(U14="","Falta quem analisou",IF(S14="Em análise","OK",IF(COUNTA(J14:P14)<7,"Falta responder à análise",IF(V14="","Falta a data da análise",IF(AND(OR(S14="Aceito",S14="Aceito com alteração"),W14=""),"Falta a data da confirmação",IF(AND(OR(S14="Aceito",S14="Aceito com alteração"),V14>W14),"Analisado depois de aceitar",IF(AND(S14="Aceito",COUNTIF(J14:P14,"Não")>0),"Aceito com pendência na análise",IF(AND(S14="Aceito com alteração",T14=""),"Falta o que foi negociado",IF(AND(S14="Recusado",T14=""),"Falta o motivo da recusa","OK")))))))))))
B15: 9 | Q15: =IF(AND(C15="",E15="",G15=""),"",IF(COUNTA(J15:P15)<7,"Análise incompleta",IF(COUNTIF(J15:P15,"Não")>0,"Resolver antes de aceitar","Pode aceitar"))) | R15: =IF(AND(C15="",E15="",G15=""),"",COUNTIF(J15:P15,"Não")) | X15: =IF(AND(C15="",E15="",G15=""),"",IF(S15="","Falta a decisão",IF(U15="","Falta quem analisou",IF(S15="Em análise","OK",IF(COUNTA(J15:P15)<7,"Falta responder à análise",IF(V15="","Falta a data da análise",IF(AND(OR(S15="Aceito",S15="Aceito com alteração"),W15=""),"Falta a data da confirmação",IF(AND(OR(S15="Aceito",S15="Aceito com alteração"),V15>W15),"Analisado depois de aceitar",IF(AND(S15="Aceito",COUNTIF(J15:P15,"Não")>0),"Aceito com pendência na análise",IF(AND(S15="Aceito com alteração",T15=""),"Falta o que foi negociado",IF(AND(S15="Recusado",T15=""),"Falta o motivo da recusa","OK")))))))))))
B16: 10 | Q16: =IF(AND(C16="",E16="",G16=""),"",IF(COUNTA(J16:P16)<7,"Análise incompleta",IF(COUNTIF(J16:P16,"Não")>0,"Resolver antes de aceitar","Pode aceitar"))) | R16: =IF(AND(C16="",E16="",G16=""),"",COUNTIF(J16:P16,"Não")) | X16: =IF(AND(C16="",E16="",G16=""),"",IF(S16="","Falta a decisão",IF(U16="","Falta quem analisou",IF(S16="Em análise","OK",IF(COUNTA(J16:P16)<7,"Falta responder à análise",IF(V16="","Falta a data da análise",IF(AND(OR(S16="Aceito",S16="Aceito com alteração"),W16=""),"Falta a data da confirmação",IF(AND(OR(S16="Aceito",S16="Aceito com alteração"),V16>W16),"Analisado depois de aceitar",IF(AND(S16="Aceito",COUNTIF(J16:P16,"Não")>0),"Aceito com pendência na análise",IF(AND(S16="Aceito com alteração",T16=""),"Falta o que foi negociado",IF(AND(S16="Recusado",T16=""),"Falta o motivo da recusa","OK")))))))))))
B17: 11 | Q17: =IF(AND(C17="",E17="",G17=""),"",IF(COUNTA(J17:P17)<7,"Análise incompleta",IF(COUNTIF(J17:P17,"Não")>0,"Resolver antes de aceitar","Pode aceitar"))) | R17: =IF(AND(C17="",E17="",G17=""),"",COUNTIF(J17:P17,"Não")) | X17: =IF(AND(C17="",E17="",G17=""),"",IF(S17="","Falta a decisão",IF(U17="","Falta quem analisou",IF(S17="Em análise","OK",IF(COUNTA(J17:P17)<7,"Falta responder à análise",IF(V17="","Falta a data da análise",IF(AND(OR(S17="Aceito",S17="Aceito com alteração"),W17=""),"Falta a data da confirmação",IF(AND(OR(S17="Aceito",S17="Aceito com alteração"),V17>W17),"Analisado depois de aceitar",IF(AND(S17="Aceito",COUNTIF(J17:P17,"Não")>0),"Aceito com pendência na análise",IF(AND(S17="Aceito com alteração",T17=""),"Falta o que foi negociado",IF(AND(S17="Recusado",T17=""),"Falta o motivo da recusa","OK")))))))))))
B18: 12 | Q18: =IF(AND(C18="",E18="",G18=""),"",IF(COUNTA(J18:P18)<7,"Análise incompleta",IF(COUNTIF(J18:P18,"Não")>0,"Resolver antes de aceitar","Pode aceitar"))) | R18: =IF(AND(C18="",E18="",G18=""),"",COUNTIF(J18:P18,"Não")) | X18: =IF(AND(C18="",E18="",G18=""),"",IF(S18="","Falta a decisão",IF(U18="","Falta quem analisou",IF(S18="Em análise","OK",IF(COUNTA(J18:P18)<7,"Falta responder à análise",IF(V18="","Falta a data da análise",IF(AND(OR(S18="Aceito",S18="Aceito com alteração"),W18=""),"Falta a data da confirmação",IF(AND(OR(S18="Aceito",S18="Aceito com alteração"),V18>W18),"Analisado depois de aceitar",IF(AND(S18="Aceito",COUNTIF(J18:P18,"Não")>0),"Aceito com pendência na análise",IF(AND(S18="Aceito com alteração",T18=""),"Falta o que foi negociado",IF(AND(S18="Recusado",T18=""),"Falta o motivo da recusa","OK")))))))))))
... B66: 60 | Q66: =IF(AND(C66="",E66="",G66=""),"",IF(COUNTA(J66:P66)<7,"Análise incompleta",IF(COUNTIF(J66:P66,"Não")>0,"Resolver antes de aceitar","Pode aceitar"))) | R66: =IF(AND(C66="",E66="",G66=""),"",COUNTIF(J66:P66,"Não")) | X66: =IF(AND(C66="",E66="",G66=""),"",IF(S66="","Falta a decisão",IF(U66="","Falta quem analisou",IF(S66="Em análise","OK",IF(COUNTA(J66:P66)<7,"Falta responder à análise",IF(V66="","Falta a data da análise",IF(AND(OR(S66="Aceito",S66="Aceito com alteração"),W66=""),"Falta a data da confirmação",IF(AND(OR(S66="Aceito",S66="Aceito com alteração"),V66>W66),"Analisado depois de aceitar",IF(AND(S66="Aceito",COUNTIF(J66:P66,"Não")>0),"Aceito com pendência na análise",IF(AND(S66="Aceito com alteração",T66=""),"Falta o que foi negociado",IF(AND(S66="Recusado",T66=""),"Falta o motivo da recusa","OK")))))))))))
B68: Resumo automático
B69: Pedidos registrados | E69: =COUNTA(C7:C66) -> 0
B70: Por decisão | E70: =IF(E69=0,"",COUNTIF(S7:S66,"Aceito")&" aceitos"&", "&COUNTIF(S7:S66,"Aceito com alteração")&" aceitos com alteração"&", "&COUNTIF(S7:S66,"Recusado")&" recusados"&", "&COUNTIF(S7:S66,"Em análise")&" em análise")
B71: Pedidos a rever | E71: =SUMPRODUCT((X7:X66<>"")*(X7:X66<>"OK")) -> 0
B72: Aviso | E72: =IF(E69=0,"Registre os pedidos",IF(COUNTIF(X7:X66,"Aceito com pendência na análise")>0,"Há pedido aceito com pendência na análise",IF(COUNTIF(X7:X66,"Analisado depois de aceitar")>0,"Há pedido analisado depois de aceito",IF(E71>0,"Há pedido a rever: veja a coluna Conferência","OK")))) -> Registre os pedidos

Sheet Mudanças
B1: Mudanças nos pedidos aceitos
B2: Uma linha por alteração depois do aceite, venha do cliente ou da organização.
B4: # | C4: Data | D4: Pedido | E4: O que mudou | F4: Quem pediu | G4: Análise da mudança | H4: Documentos atualizados? | I4: Quem foi informado | J4: Conferência
C5: Data | D5: Nº da aba Pedidos | E5: De quê, para quê | G5: Capacidade, prazo, especificação | H5: Lista | I5: Quem produz, entrega, compra | J5: Calculada
B6: Ex. | C6: 46470 | D6: E-31 | E6: De 30 para 35 pizzas. | F6: Cliente, por telefone | G6: Capacidade conferida: a sexta às 19h comporta. | H6: Sim | I6: Pizzaiolo líder | J6: OK
B7: 1 | J7: =IF(E7="",IF(COUNTA(C7:D7,F7:I7)>0,"Falta o que mudou",""),IF(D7="","Falta o pedido",IF(COUNTIF(Pedidos!$C$7:$C$66,D7)=0,"Pedido não está na aba Pedidos",IF(G7="","Falta a análise",IF(H7<>"Sim","Documentos não atualizados",IF(I7="","Falta quem foi informado","OK"))))))
B8: 2 | J8: =IF(E8="",IF(COUNTA(C8:D8,F8:I8)>0,"Falta o que mudou",""),IF(D8="","Falta o pedido",IF(COUNTIF(Pedidos!$C$7:$C$66,D8)=0,"Pedido não está na aba Pedidos",IF(G8="","Falta a análise",IF(H8<>"Sim","Documentos não atualizados",IF(I8="","Falta quem foi informado","OK"))))))
B9: 3 | J9: =IF(E9="",IF(COUNTA(C9:D9,F9:I9)>0,"Falta o que mudou",""),IF(D9="","Falta o pedido",IF(COUNTIF(Pedidos!$C$7:$C$66,D9)=0,"Pedido não está na aba Pedidos",IF(G9="","Falta a análise",IF(H9<>"Sim","Documentos não atualizados",IF(I9="","Falta quem foi informado","OK"))))))
B10: 4 | J10: =IF(E10="",IF(COUNTA(C10:D10,F10:I10)>0,"Falta o que mudou",""),IF(D10="","Falta o pedido",IF(COUNTIF(Pedidos!$C$7:$C$66,D10)=0,"Pedido não está na aba Pedidos",IF(G10="","Falta a análise",IF(H10<>"Sim","Documentos não atualizados",IF(I10="","Falta quem foi informado","OK"))))))
B11: 5 | J11: =IF(E11="",IF(COUNTA(C11:D11,F11:I11)>0,"Falta o que mudou",""),IF(D11="","Falta o pedido",IF(COUNTIF(Pedidos!$C$7:$C$66,D11)=0,"Pedido não está na aba Pedidos",IF(G11="","Falta a análise",IF(H11<>"Sim","Documentos não atualizados",IF(I11="","Falta quem foi informado","OK"))))))
B12: 6 | J12: =IF(E12="",IF(COUNTA(C12:D12,F12:I12)>0,"Falta o que mudou",""),IF(D12="","Falta o pedido",IF(COUNTIF(Pedidos!$C$7:$C$66,D12)=0,"Pedido não está na aba Pedidos",IF(G12="","Falta a análise",IF(H12<>"Sim","Documentos não atualizados",IF(I12="","Falta quem foi informado","OK"))))))
B13: 7 | J13: =IF(E13="",IF(COUNTA(C13:D13,F13:I13)>0,"Falta o que mudou",""),IF(D13="","Falta o pedido",IF(COUNTIF(Pedidos!$C$7:$C$66,D13)=0,"Pedido não está na aba Pedidos",IF(G13="","Falta a análise",IF(H13<>"Sim","Documentos não atualizados",IF(I13="","Falta quem foi informado","OK"))))))
B14: 8 | J14: =IF(E14="",IF(COUNTA(C14:D14,F14:I14)>0,"Falta o que mudou",""),IF(D14="","Falta o pedido",IF(COUNTIF(Pedidos!$C$7:$C$66,D14)=0,"Pedido não está na aba Pedidos",IF(G14="","Falta a análise",IF(H14<>"Sim","Documentos não atualizados",IF(I14="","Falta quem foi informado","OK"))))))
B15: 9 | J15: =IF(E15="",IF(COUNTA(C15:D15,F15:I15)>0,"Falta o que mudou",""),IF(D15="","Falta o pedido",IF(COUNTIF(Pedidos!$C$7:$C$66,D15)=0,"Pedido não está na aba Pedidos",IF(G15="","Falta a análise",IF(H15<>"Sim","Documentos não atualizados",IF(I15="","Falta quem foi informado","OK"))))))
B16: 10 | J16: =IF(E16="",IF(COUNTA(C16:D16,F16:I16)>0,"Falta o que mudou",""),IF(D16="","Falta o pedido",IF(COUNTIF(Pedidos!$C$7:$C$66,D16)=0,"Pedido não está na aba Pedidos",IF(G16="","Falta a análise",IF(H16<>"Sim","Documentos não atualizados",IF(I16="","Falta quem foi informado","OK"))))))
B17: 11 | J17: =IF(E17="",IF(COUNTA(C17:D17,F17:I17)>0,"Falta o que mudou",""),IF(D17="","Falta o pedido",IF(COUNTIF(Pedidos!$C$7:$C$66,D17)=0,"Pedido não está na aba Pedidos",IF(G17="","Falta a análise",IF(H17<>"Sim","Documentos não atualizados",IF(I17="","Falta quem foi informado","OK"))))))
B18: 12 | J18: =IF(E18="",IF(COUNTA(C18:D18,F18:I18)>0,"Falta o que mudou",""),IF(D18="","Falta o pedido",IF(COUNTIF(Pedidos!$C$7:$C$66,D18)=0,"Pedido não está na aba Pedidos",IF(G18="","Falta a análise",IF(H18<>"Sim","Documentos não atualizados",IF(I18="","Falta quem foi informado","OK"))))))
... B36: 30 | J36: =IF(E36="",IF(COUNTA(C36:D36,F36:I36)>0,"Falta o que mudou",""),IF(D36="","Falta o pedido",IF(COUNTIF(Pedidos!$C$7:$C$66,D36)=0,"Pedido não está na aba Pedidos",IF(G36="","Falta a análise",IF(H36<>"Sim","Documentos não atualizados",IF(I36="","Falta quem foi informado","OK"))))))
B38: Resumo automático
B39: Mudanças registradas | E39: =COUNTA(E7:E36) -> 0
B40: Mudanças a rever | E40: =SUMPRODUCT((J7:J36<>"")*(J7:J36<>"OK")) -> 0
B41: Aviso | E41: =IF(E39=0,"Nenhuma mudança registrada: confirme se nenhum pedido mudou",IF(E40>0,"Há mudança a rever: veja a coluna Conferência","OK")) -> Nenhuma mudança registrada: confirme se nenhum pedido mudou

Sheet Painel
B1: Painel dos pedidos
B2: Nada a preencher: tudo vem das outras abas.
B4: Indicador | C4: Resultado | D4: Como se lê
B5: Itens na oferta | C5: =COUNTA(Oferta!C6:C17) -> 0 | D5: Da aba Oferta.
B6: Itens da oferta a rever | C6: =SUMPRODUCT((Oferta!I6:I17<>"")*(Oferta!I6:I17<>"OK")) -> 0 | D6: Sem especificação, sem onde informar, sem a capacidade confirmada.
B7: Pedidos registrados | C7: =COUNTA(Pedidos!C7:C66) -> 0 | D7: Da aba Pedidos.
B8: Aceito | C8: =COUNTIF(Pedidos!S7:S66,"Aceito") -> 0 | D8: Todas as respostas “sim” ou “não se aplica”.
B9: Aceito com alteração | C9: =COUNTIF(Pedidos!S7:S66,"Aceito com alteração") -> 0 | D9: Um “não” resolvido com o cliente.
B10: Recusado | C10: =COUNTIF(Pedidos!S7:S66,"Recusado") -> 0 | D10: Um “não” sem solução aceitável.
B11: Em análise | C11: =COUNTIF(Pedidos!S7:S66,"Em análise") -> 0 | D11: Falta informação para decidir.
B12: Pedidos em que a análise encontrou problema | C12: =COUNTIF(Pedidos!R7:R66,">0") -> 0 | D12: Ao menos uma resposta “não”.
B13: Pedidos a rever | C13: =SUMPRODUCT((Pedidos!X7:X66<>"")*(Pedidos!X7:X66<>"OK")) -> 0 | D13: Veja a coluna Conferência da aba Pedidos.
B14: Aceitos com pendência na análise | C14: =COUNTIF(Pedidos!X7:X66,"Aceito com pendência na análise") -> 0 | D14: O mais grave: o problema vai para a produção.
B15: Analisados depois de aceitar | C15: =COUNTIF(Pedidos!X7:X66,"Analisado depois de aceitar") -> 0 | D15: O compromisso veio antes da análise.
B16: Mudanças registradas | C16: =COUNTA(Mudanças!E7:E36) -> 0 | D16: Da aba Mudanças.
B17: Mudanças a rever | C17: =SUMPRODUCT((Mudanças!J7:J36<>"")*(Mudanças!J7:J36<>"OK")) -> 0 | D17: Sem análise, sem documentos ou sem quem foi informado.
B19: Respostas por pergunta
B20: Pergunta | C20: Sim | D20: Não | E20: Não se aplica | F20: Parte com “não” | G20: Sem resposta | H20: Leitura
B21: 1 · Especificação | C21: =COUNTIF(Pedidos!J7:J66,"Sim") -> 0 | D21: =COUNTIF(Pedidos!J7:J66,"Não") -> 0 | E21: =COUNTIF(Pedidos!J7:J66,"Não se aplica") -> 0 | F21: =IF(C21+D21=0,"",D21/(C21+D21)) | G21: =MAX(0,COUNTA(Pedidos!C7:C66)-C21-D21-E21) -> 0 | H21: =IF(D21=0,"",IF(D21=MAX(D$21:D$27),"A que mais encontra problema: rever a oferta",""))
B22: 2 · Capacidade e prazo | C22: =COUNTIF(Pedidos!K7:K66,"Sim") -> 0 | D22: =COUNTIF(Pedidos!K7:K66,"Não") -> 0 | E22: =COUNTIF(Pedidos!K7:K66,"Não se aplica") -> 0 | F22: =IF(C22+D22=0,"",D22/(C22+D22)) | G22: =MAX(0,COUNTA(Pedidos!C7:C66)-C22-D22-E22) -> 0 | H22: =IF(D22=0,"",IF(D22=MAX(D$21:D$27),"A que mais encontra problema: rever a oferta",""))
B23: 3 · Entrega e pós-entrega | C23: =COUNTIF(Pedidos!L7:L66,"Sim") -> 0 | D23: =COUNTIF(Pedidos!L7:L66,"Não") -> 0 | E23: =COUNTIF(Pedidos!L7:L66,"Não se aplica") -> 0 | F23: =IF(C23+D23=0,"",D23/(C23+D23)) | G23: =MAX(0,COUNTA(Pedidos!C7:C66)-C23-D23-E23) -> 0 | H23: =IF(D23=0,"",IF(D23=MAX(D$21:D$27),"A que mais encontra problema: rever a oferta",""))
B24: 4 · Uso pretendido | C24: =COUNTIF(Pedidos!M7:M66,"Sim") -> 0 | D24: =COUNTIF(Pedidos!M7:M66,"Não") -> 0 | E24: =COUNTIF(Pedidos!M7:M66,"Não se aplica") -> 0 | F24: =IF(C24+D24=0,"",D24/(C24+D24)) | G24: =MAX(0,COUNTA(Pedidos!C7:C66)-C24-D24-E24) -> 0 | H24: =IF(D24=0,"",IF(D24=MAX(D$21:D$27),"A que mais encontra problema: rever a oferta",""))
B25: 5 · Requisitos legais | C25: =COUNTIF(Pedidos!N7:N66,"Sim") -> 0 | D25: =COUNTIF(Pedidos!N7:N66,"Não") -> 0 | E25: =COUNTIF(Pedidos!N7:N66,"Não se aplica") -> 0 | F25: =IF(C25+D25=0,"",D25/(C25+D25)) | G25: =MAX(0,COUNTA(Pedidos!C7:C66)-C25-D25-E25) -> 0 | H25: =IF(D25=0,"",IF(D25=MAX(D$21:D$27),"A que mais encontra problema: rever a oferta",""))
B26: 6 · Diferenças | C26: =COUNTIF(Pedidos!O7:O66,"Sim") -> 0 | D26: =COUNTIF(Pedidos!O7:O66,"Não") -> 0 | E26: =COUNTIF(Pedidos!O7:O66,"Não se aplica") -> 0 | F26: =IF(C26+D26=0,"",D26/(C26+D26)) | G26: =MAX(0,COUNTA(Pedidos!C7:C66)-C26-D26-E26) -> 0 | H26: =IF(D26=0,"",IF(D26=MAX(D$21:D$27),"A que mais encontra problema: rever a oferta",""))
B27: 7 · Preço e condições | C27: =COUNTIF(Pedidos!P7:P66,"Sim") -> 0 | D27: =COUNTIF(Pedidos!P7:P66,"Não") -> 0 | E27: =COUNTIF(Pedidos!P7:P66,"Não se aplica") -> 0 | F27: =IF(C27+D27=0,"",D27/(C27+D27)) | G27: =MAX(0,COUNTA(Pedidos!C7:C66)-C27-D27-E27) -> 0 | H27: =IF(D27=0,"",IF(D27=MAX(D$21:D$27),"A que mais encontra problema: rever a oferta",""))
B29: Resumo automático
B30: Aviso | C30: =IF(C7=0,"Registre os pedidos na aba Pedidos",IF(C14>0,"Há pedido aceito com pendência na análise",IF(C15>0,"Há pedido analisado depois de aceito",IF(C17>0,"Há mudança sem análise, sem documentos ou sem aviso",IF(C6>0,"Há item da oferta a rever",IF(C13>0,"Há pedido a rever","OK")))))) -> Registre os pedidos na aba Pedidos

Sheet Checklist
B1: Checklist dos requisitos do cliente
B2: Escolha o status de cada item na lista suspensa (coluna em amarelo-claro).
B4: # | C4: Item de verificação | D4: Status | E4: Observações
B5: 1 | C5: Os canais de comunicação com o cliente estão definidos: informações, pedidos, mudanças e reclamações.
B6: 2 | C6: O que a organização oferece está definido, com a especificação de cada produto ou serviço.
B7: 3 | C7: Os requisitos legais aplicáveis ao que é oferecido estão identificados.
B8: 4 | C8: A organização confirmou que consegue cumprir o que oferece, inclusive a capacidade.
B9: 5 | C9: O que a organização não garante está informado ao cliente.
B10: 6 | C10: Todo pedido é analisado antes de a organização se comprometer a fornecer.
B11: 7 | C11: A análise considera os requisitos que o cliente não declarou, mas que o uso exige.
B12: 8 | C12: As diferenças entre o pedido e a proposta são resolvidas antes da confirmação.
B13: 9 | C13: O pedido verbal é confirmado com o cliente antes de ser aceito.
B14: 10 | C14: O resultado da análise fica registrado, com quem analisou e quando.
B15: 11 | C15: Quando o pedido muda, é analisado de novo, os documentos são atualizados e as pessoas são informadas.
B16: 12 | C16: O pedido aceito com alteração ou recusado tem o motivo registrado e comunicado ao cliente.
B18: Resumo automático
B19: Itens atendidos (Sim) | D19: =COUNTIF(D5:D16,"Sim") -> 0
B20: Itens parciais | D20: =COUNTIF(D5:D16,"Parcial") -> 0
B21: Itens não atendidos | D21: =COUNTIF(D5:D16,"Não") -> 0
B22: Itens sem resposta | D22: =COUNTBLANK(D5:D16) -> 12
B23: Percentual atendido | D23: =D19/ROWS(D5:D16) -> 0
B24: Situação | D24: =IF(D19=ROWS(D5:D16),"Validado",IF(D22>0,"Em andamento","Com pendências")) -> Em andamento

Sheet Exemplo 1 - Pizzaria
B1: Requisitos do cliente e análise de pedidos
B2: Exemplo preenchido, para consulta. Use as abas Oferta, Pedidos e Mudanças para a sua organização.
B4: Organização | E4: Pizzaria (loja com salão e delivery)
B5: Processo | E5: Registrar o pedido (P1)
B6: Quem analisa | E6: Pedido comum: atendente, na tela de confirmação. Encomenda de 20 pizzas ou mais: gerente da loja, antes de confirmar.
B7: Registros | E7: Encomendas e pedidos especiais de 22 a 28/03/2027, lidos em 29/03/2027.
B8: Origem | E8: Requisito 8.2.3 atendido em parte no diagnóstico de 2026: pedidos por telefone sem o complemento do endereço (RNC 2026-05).
B10: A oferta
B11: Item | D11: O que se oferece | F11: Requisitos legais | N11: O que não se garante | P11: Onde o cliente é informado | Q11: Capacidade confirmada? | T11: Conferência
B12: Pizza no delivery | D12: Sabores e tamanhos do cardápio, com os ingredientes. Entrega em até 40 minutos na área de entrega. | F12: Alergênicos informados no cardápio. | N12: Ausência de glúten e de traços de leite: a cozinha é compartilhada. Entrega fora da área. | P12: Cardápio, site e aplicativo. | Q12: Sim | T12: =IF(B12="",IF(1>0,"Falta o item",""),IF(D12="","Falta a especificação",IF(P12="","Falta onde o cliente é informado",IF(Q12<>"Sim","Capacidade não confirmada","OK")))) -> OK
B13: Retirada no balcão | D13: Os mesmos sabores e tamanhos, prontos em até 25 minutos. | F13: Alergênicos informados no cardápio. | N13: Reserva de horário exato. | P13: Cardápio e telefone. | Q13: Sim | T13: =IF(B13="",IF(1>0,"Falta o item",""),IF(D13="","Falta a especificação",IF(P13="","Falta onde o cliente é informado",IF(Q13<>"Sim","Capacidade não confirmada","OK")))) -> OK
B14: Encomenda para eventos | D14: A partir de 20 pizzas, com 48 horas de antecedência, de terça a domingo, das 18h às 23h. | F14: Alergênicos informados na confirmação. Bebida alcoólica só para maiores de 18 anos. | N14: Montagem no local do evento. | P14: Site e telefone. | Q14: Não | T14: =IF(B14="",IF(1>0,"Falta o item",""),IF(D14="","Falta a especificação",IF(P14="","Falta onde o cliente é informado",IF(Q14<>"Sim","Capacidade não confirmada","OK")))) -> Capacidade não confirmada
B16: Pedidos
B17: Nº | C17: Data | D17: Cliente | E17: O que pede | F17: Prazo | G17: 1 | H17: 2 | I17: 3 | J17: 4 | K17: 5 | L17: 6 | M17: 7 | N17: Leitura | O17: Decisão | P17: O que foi negociado, ou o motivo | Q17: Quem analisou | R17: Análise | S17: Confirmação | T17: Conferência
B18: E-31 | C18: 46468 | D18: Escritório de contabilidade · Telefone | E18: 30 pizzas grandes, sexta 26/03 às 19h, no 8º andar de um prédio comercial. Entrega com elevador de serviço, combinada com a portaria. | F18: 46472 | G18: Sim | H18: Sim | I18: Sim | J18: Sim | K18: Sim | L18: Sim | M18: Sim | N18: =IF(B18="","",IF(COUNTA(G18:M18)<7,"Análise incompleta",IF(COUNTIF(G18:M18,"Não")>0,"Resolver antes de aceitar","Pode aceitar"))) -> Pode aceitar | O18: Aceito | Q18: Gerente da loja | R18: 46468 | S18: 46468 | T18: =IF(B18="","",IF(O18="","Falta a decisão",IF(Q18="","Falta quem analisou",IF(O18="Em análise","OK",IF(COUNTA(G18:M18)<7,"Falta responder à análise",IF(R18="","Falta a data da análise",IF(AND(OR(O18="Aceito",O18="Aceito com alteração"),S18=""),"Falta a data da confirmação",IF(AND(OR(O18="Aceito",O18="Aceito com alteração"),R18>S18),"Analisado depois de aceitar",IF(AND(O18="Aceito",COUNTIF(G18:M18,"Não")>0),"Aceito com pendência na análise",IF(AND(O18="Aceito com alteração",P18=""),"Falta o que foi negociado",IF(AND(O18="Recusado",P18=""),"Falta o motivo da recusa","OK"))))))))))) -> OK
B19: T-1184 | C19: 46469 | D19: Cliente por telefone · Telefone | E19: Uma pizza grande meia calabresa, meia muçarela. | F19: 46469 | G19: Sim | H19: Sim | I19: Sim | J19: Sim | K19: Não se aplica | L19: Sim | M19: Sim | N19: =IF(B19="","",IF(COUNTA(G19:M19)<7,"Análise incompleta",IF(COUNTIF(G19:M19,"Não")>0,"Resolver antes de aceitar","Pode aceitar"))) -> Pode aceitar | O19: Aceito | P19: Complemento do endereço pedido e lido de volta antes de confirmar. | Q19: Atendente do turno | R19: 46469 | S19: 46469 | T19: =IF(B19="","",IF(O19="","Falta a decisão",IF(Q19="","Falta quem analisou",IF(O19="Em análise","OK",IF(COUNTA(G19:M19)<7,"Falta responder à análise",IF(R19="","Falta a data da análise",IF(AND(OR(O19="Aceito",O19="Aceito com alteração"),S19=""),"Falta a data da confirmação",IF(AND(OR(O19="Aceito",O19="Aceito com alteração"),R19>S19),"Analisado depois de aceitar",IF(AND(O19="Aceito",COUNTIF(G19:M19,"Não")>0),"Aceito com pendência na análise",IF(AND(O19="Aceito com alteração",P19=""),"Falta o que foi negociado",IF(AND(O19="Recusado",P19=""),"Falta o motivo da recusa","OK"))))))))))) -> OK
B20: A-772 | C20: 46470 | D20: Cliente pelo aplicativo · Aplicativo | E20: Pizza de muçarela “sem glúten”, para uma criança celíaca. Isenção total de glúten, inclusive de contaminação na cozinha. | F20: 46470 | G20: Sim | H20: Sim | I20: Sim | J20: Não | K20: Sim | L20: Sim | M20: Sim | N20: =IF(B20="","",IF(COUNTA(G20:M20)<7,"Análise incompleta",IF(COUNTIF(G20:M20,"Não")>0,"Resolver antes de aceitar","Pode aceitar"))) -> Resolver antes de aceitar | O20: Recusado | P20: A cozinha não garante a ausência de glúten. Cliente informado pelo telefone, com o motivo. | Q20: Gerente da loja | R20: 46470 | T20: =IF(B20="","",IF(O20="","Falta a decisão",IF(Q20="","Falta quem analisou",IF(O20="Em análise","OK",IF(COUNTA(G20:M20)<7,"Falta responder à análise",IF(R20="","Falta a data da análise",IF(AND(OR(O20="Aceito",O20="Aceito com alteração"),S20=""),"Falta a data da confirmação",IF(AND(OR(O20="Aceito",O20="Aceito com alteração"),R20>S20),"Analisado depois de aceitar",IF(AND(O20="Aceito",COUNTIF(G20:M20,"Não")>0),"Aceito com pendência na análise",IF(AND(O20="Aceito com alteração",P20=""),"Falta o que foi negociado",IF(AND(O20="Recusado",P20=""),"Falta o motivo da recusa","OK"))))))))))) -> OK
B21: E-32 | C21: 46471 | D21: Comissão de formatura · Telefone | E21: 50 pizzas grandes, sábado 27/03 às 21h, no salão de festas. Bebidas para a festa: o cliente pediu cerveja; a turma tem alunos menores de idade. | F21: 46473 | G21: Sim | H21: Não | I21: Sim | J21: Sim | K21: Não | L21: Sim | M21: Sim | N21: =IF(B21="","",IF(COUNTA(G21:M21)<7,"Análise incompleta",IF(COUNTIF(G21:M21,"Não")>0,"Resolver antes de aceitar","Pode aceitar"))) -> Resolver antes de aceitar | O21: Aceito com alteração | P21: Entrega às 18h30, em duas levas, antes do pico do sábado. Sem bebida alcoólica no pedido. | Q21: Gerente da loja | R21: 46471 | S21: 46471 | T21: =IF(B21="","",IF(O21="","Falta a decisão",IF(Q21="","Falta quem analisou",IF(O21="Em análise","OK",IF(COUNTA(G21:M21)<7,"Falta responder à análise",IF(R21="","Falta a data da análise",IF(AND(OR(O21="Aceito",O21="Aceito com alteração"),S21=""),"Falta a data da confirmação",IF(AND(OR(O21="Aceito",O21="Aceito com alteração"),R21>S21),"Analisado depois de aceitar",IF(AND(O21="Aceito",COUNTIF(G21:M21,"Não")>0),"Aceito com pendência na análise",IF(AND(O21="Aceito com alteração",P21=""),"Falta o que foi negociado",IF(AND(O21="Recusado",P21=""),"Falta o motivo da recusa","OK"))))))))))) -> OK
B22: E-33 | C22: 46471 | D22: Escola do bairro · Telefone | E22: 20 pizzas para segunda 29/03, às 11h. | F22: 46475 | G22: Sim | H22: Não | I22: Sim | J22: Sim | K22: Sim | L22: Sim | M22: Sim | N22: =IF(B22="","",IF(COUNTA(G22:M22)<7,"Análise incompleta",IF(COUNTIF(G22:M22,"Não")>0,"Resolver antes de aceitar","Pode aceitar"))) -> Resolver antes de aceitar | O22: Recusado | P22: A loja não atende encomendas para eventos às segundas, e o horário de encomenda começa às 18h. O cliente não aceitou outro dia. | Q22: Gerente da loja | R22: 46471 | T22: =IF(B22="","",IF(O22="","Falta a decisão",IF(Q22="","Falta quem analisou",IF(O22="Em análise","OK",IF(COUNTA(G22:M22)<7,"Falta responder à análise",IF(R22="","Falta a data da análise",IF(AND(OR(O22="Aceito",O22="Aceito com alteração"),S22=""),"Falta a data da confirmação",IF(AND(OR(O22="Aceito",O22="Aceito com alteração"),R22>S22),"Analisado depois de aceitar",IF(AND(O22="Aceito",COUNTIF(G22:M22,"Não")>0),"Aceito com pendência na análise",IF(AND(O22="Aceito com alteração",P22=""),"Falta o que foi negociado",IF(AND(O22="Recusado",P22=""),"Falta o motivo da recusa","OK"))))))))))) -> OK
B23: T-1201 | C23: 46472 | D23: Cliente por telefone · Telefone | E23: Duas pizzas grandes, para entrega em um bairro vizinho. | F23: 46472 | G23: Sim | H23: Sim | I23: Não | J23: Sim | K23: Não se aplica | L23: Sim | M23: Sim | N23: =IF(B23="","",IF(COUNTA(G23:M23)<7,"Análise incompleta",IF(COUNTIF(G23:M23,"Não")>0,"Resolver antes de aceitar","Pode aceitar"))) -> Resolver antes de aceitar | O23: Aceito com alteração | P23: O endereço fica fora da área de entrega. O cliente aceitou retirar no balcão. | Q23: Atendente do turno | R23: 46472 | S23: 46472 | T23: =IF(B23="","",IF(O23="","Falta a decisão",IF(Q23="","Falta quem analisou",IF(O23="Em análise","OK",IF(COUNTA(G23:M23)<7,"Falta responder à análise",IF(R23="","Falta a data da análise",IF(AND(OR(O23="Aceito",O23="Aceito com alteração"),S23=""),"Falta a data da confirmação",IF(AND(OR(O23="Aceito",O23="Aceito com alteração"),R23>S23),"Analisado depois de aceitar",IF(AND(O23="Aceito",COUNTIF(G23:M23,"Não")>0),"Aceito com pendência na análise",IF(AND(O23="Aceito com alteração",P23=""),"Falta o que foi negociado",IF(AND(O23="Recusado",P23=""),"Falta o motivo da recusa","OK"))))))))))) -> OK
B24: E-34 | C24: 46472 | D24: Empresa de eventos · Telefone | E24: 40 pizzas grandes, sábado 27/03 às 20h. | F24: 46473 | G24: Sim | H24: Não | I24: Sim | J24: Sim | K24: Sim | L24: Sim | M24: Sim | N24: =IF(B24="","",IF(COUNTA(G24:M24)<7,"Análise incompleta",IF(COUNTIF(G24:M24,"Não")>0,"Resolver antes de aceitar","Pode aceitar"))) -> Resolver antes de aceitar | O24: Aceito | Q24: Atendente do turno | R24: 46472 | S24: 46472 | T24: =IF(B24="","",IF(O24="","Falta a decisão",IF(Q24="","Falta quem analisou",IF(O24="Em análise","OK",IF(COUNTA(G24:M24)<7,"Falta responder à análise",IF(R24="","Falta a data da análise",IF(AND(OR(O24="Aceito",O24="Aceito com alteração"),S24=""),"Falta a data da confirmação",IF(AND(OR(O24="Aceito",O24="Aceito com alteração"),R24>S24),"Analisado depois de aceitar",IF(AND(O24="Aceito",COUNTIF(G24:M24,"Não")>0),"Aceito com pendência na análise",IF(AND(O24="Aceito com alteração",P24=""),"Falta o que foi negociado",IF(AND(O24="Recusado",P24=""),"Falta o motivo da recusa","OK"))))))))))) -> Aceito com pendência na análise
B25: E-35 | C25: 46472 | D25: Família do bairro · Telefone | E25: 25 pizzas grandes, domingo 28/03 às 20h, para um aniversário. | F25: 46474 | G25: Sim | H25: Sim | I25: Sim | J25: Sim | K25: Sim | L25: Sim | M25: Sim | N25: =IF(B25="","",IF(COUNTA(G25:M25)<7,"Análise incompleta",IF(COUNTIF(G25:M25,"Não")>0,"Resolver antes de aceitar","Pode aceitar"))) -> Pode aceitar | O25: Aceito | Q25: Gerente da loja | R25: 46473 | S25: 46472 | T25: =IF(B25="","",IF(O25="","Falta a decisão",IF(Q25="","Falta quem analisou",IF(O25="Em análise","OK",IF(COUNTA(G25:M25)<7,"Falta responder à análise",IF(R25="","Falta a data da análise",IF(AND(OR(O25="Aceito",O25="Aceito com alteração"),S25=""),"Falta a data da confirmação",IF(AND(OR(O25="Aceito",O25="Aceito com alteração"),R25>S25),"Analisado depois de aceitar",IF(AND(O25="Aceito",COUNTIF(G25:M25,"Não")>0),"Aceito com pendência na análise",IF(AND(O25="Aceito com alteração",P25=""),"Falta o que foi negociado",IF(AND(O25="Recusado",P25=""),"Falta o motivo da recusa","OK"))))))))))) -> Analisado depois de aceitar
B26: Perguntas: 1 especificação · 2 capacidade e prazo · 3 entrega e pós-entrega · 4 uso pretendido · 5 requisitos legais · 6 diferenças · 7 preço e condições.
B28: Mudanças nos pedidos aceitos
B29: Data | C29: Pedido | D29: O que mudou | F29: Análise da mudança | N29: Quem pediu | P29: Quem foi informado | Q29: Documentos atualizados? | T29: Conferência
B30: 46470 | C30: E-31 | D30: De 30 para 35 pizzas, com 5 sabores trocados. | F30: Capacidade conferida pelo gerente: a sexta às 19h comporta. | N30: Cliente, por telefone | P30: Pizzaiolo líder e líder da expedição | Q30: Sim | T30: =IF(D30="",IF(1>0,"Falta o que mudou",""),IF(C30="","Falta o pedido",IF(COUNTIF($B$18:$B$25,C30)=0,"Pedido não está na aba Pedidos",IF(F30="","Falta a análise",IF(Q30<>"Sim","Documentos não atualizados",IF(P30="","Falta quem foi informado","OK")))))) -> OK
B31: 46472 | C31: E-32 | D31: Mais 10 pizzas doces na segunda leva. | N31: Cliente, pelo aplicativo de mensagens | Q31: Não | T31: =IF(D31="",IF(1>0,"Falta o que mudou",""),IF(C31="","Falta o pedido",IF(COUNTIF($B$18:$B$25,C31)=0,"Pedido não está na aba Pedidos",IF(F31="","Falta a análise",IF(Q31<>"Sim","Documentos não atualizados",IF(P31="","Falta quem foi informado","OK")))))) -> Falta a análise
B33: Resumo automático
B34: Pedidos por decisão | F34: =COUNTIF(O18:O25,"Aceito")&" aceitos"&", "&COUNTIF(O18:O25,"Aceito com alteração")&" aceitos com alteração"&", "&COUNTIF(O18:O25,"Recusado")&" recusados"&", "&COUNTIF(O18:O25,"Em análise")&" em análise" -> 4 aceitos, 2 aceitos com alteração, 2 recusados, 0 em análise
B35: Pedidos em que a análise encontrou problema | F35: =SUMPRODUCT((((G18:G25="Não")+(H18:H25="Não")+(I18:I25="Não")+(J18:J25="Não")+(K18:K25="Não")+(L18:L25="Não")+(M18:M25="Não"))>0)*1) -> 5
B36: Pedidos a rever | F36: =SUMPRODUCT((T18:T25<>"OK")*1) -> 2
B37: Respostas “não” por pergunta | F37: ="1: "&COUNTIF(G18:G25,"Não")&" · "&"2: "&COUNTIF(H18:H25,"Não")&" · "&"3: "&COUNTIF(I18:I25,"Não")&" · "&"4: "&COUNTIF(J18:J25,"Não")&" · "&"5: "&COUNTIF(K18:K25,"Não")&" · "&"6: "&COUNTIF(L18:L25,"Não")&" · "&"7: "&COUNTIF(M18:M25,"Não") -> 1: 0 · 2: 3 · 3: 1 · 4: 1 · 5: 1 · 6: 0 · 7: 0
B38: Mudanças: registradas, a rever | F38: =COUNTA(D30:D31)&" registradas, "&SUMPRODUCT((T30:T31<>"OK")*1)&" a rever" -> 2 registradas, 1 a rever

Sheet Exemplo 2 - Indústria
B1: Requisitos do cliente e análise de pedidos
B2: Exemplo preenchido, para consulta. Use as abas Oferta, Pedidos e Mudanças para a sua organização.
B4: Organização | E4: Indústria de embalagens plásticas
B5: Processo | E5: Vender e programar
B6: Quem analisa | E6: Gerente comercial, com a Programação para capacidade e prazo, a Engenharia para itens novos e a Qualidade para requisitos legais.
B7: Registros | E7: Pedidos e propostas de 01 a 15/06/2027, lidos em 16/06/2027.
B8: Origem | E8: Reclamações do cliente A por espessura e a certificação ISO 9001 prevista para dezembro (objetivo O4).
B10: A oferta
B11: Item | D11: O que se oferece | F11: Requisitos legais | N11: O que não se garante | P11: Onde o cliente é informado | Q11: Capacidade confirmada? | T11: Conferência
B12: Filme liso | D12: Espessura de 30 a 80 µm, com tolerância de ±2 µm; largura de 300 a 1.200 mm; bobinas de até 800 mm de diâmetro. | F12: Declaração de conformidade para contato com alimentos, a cada lote. | N12: Tolerância de espessura menor que ±2 µm. | P12: Catálogo técnico e proposta. | Q12: Sim | T12: =IF(B12="",IF(1>0,"Falta o item",""),IF(D12="","Falta a especificação",IF(P12="","Falta onde o cliente é informado",IF(Q12<>"Sim","Capacidade não confirmada","OK")))) -> OK
B13: Filme impresso | D13: Até seis cores, com a arte aprovada pelo cliente e os cilindros do cliente. | F13: Tintas próprias para embalagem de alimentos. | N13: Cores fora da tabela de tintas homologadas. | P13: Catálogo técnico e proposta. | Q13: Sim | T13: =IF(B13="",IF(1>0,"Falta o item",""),IF(D13="","Falta a especificação",IF(P13="","Falta onde o cliente é informado",IF(Q13<>"Sim","Capacidade não confirmada","OK")))) -> OK
B14: Filme com resina reciclada | D14: Até 30% de resina reciclada, só na camada externa, por acordo de desenvolvimento. | F14: Resina reciclada não é usada na camada em contato com o alimento. | N14: Fornecimento regular antes da aprovação do lote piloto. | P14: Proposta de desenvolvimento. | Q14: Sim | T14: =IF(B14="",IF(1>0,"Falta o item",""),IF(D14="","Falta a especificação",IF(P14="","Falta onde o cliente é informado",IF(Q14<>"Sim","Capacidade não confirmada","OK")))) -> OK
B16: Pedidos
B17: Nº | C17: Data | D17: Cliente | E17: O que pede | F17: Prazo | G17: 1 | H17: 2 | I17: 3 | J17: 4 | K17: 5 | L17: 6 | M17: 7 | N17: Leitura | O17: Decisão | P17: O que foi negociado, ou o motivo | Q17: Quem analisou | R17: Análise | S17: Confirmação | T17: Conferência
B18: PV-2231 | C18: 46539 | D18: Cliente A · E-mail | E18: 12 t de filme liso de 40 µm, 600 mm, em 20 dias. Igual ao pedido de maio. | F18: 46559 | G18: Sim | H18: Sim | I18: Sim | J18: Sim | K18: Sim | L18: Sim | M18: Sim | N18: =IF(B18="","",IF(COUNTA(G18:M18)<7,"Análise incompleta",IF(COUNTIF(G18:M18,"Não")>0,"Resolver antes de aceitar","Pode aceitar"))) -> Pode aceitar | O18: Aceito | Q18: Gerente comercial | R18: 46539 | S18: 46539 | T18: =IF(B18="","",IF(O18="","Falta a decisão",IF(Q18="","Falta quem analisou",IF(O18="Em análise","OK",IF(COUNTA(G18:M18)<7,"Falta responder à análise",IF(R18="","Falta a data da análise",IF(AND(OR(O18="Aceito",O18="Aceito com alteração"),S18=""),"Falta a data da confirmação",IF(AND(OR(O18="Aceito",O18="Aceito com alteração"),R18>S18),"Analisado depois de aceitar",IF(AND(O18="Aceito",COUNTIF(G18:M18,"Não")>0),"Aceito com pendência na análise",IF(AND(O18="Aceito com alteração",P18=""),"Falta o que foi negociado",IF(AND(O18="Recusado",P18=""),"Falta o motivo da recusa","OK"))))))))))) -> OK
B19: PV-2232 | C19: 46540 | D19: Cliente B · E-mail | E19: 30 t de filme liso de 50 µm em 10 dias. | F19: 46550 | G19: Sim | H19: Não | I19: Sim | J19: Sim | K19: Sim | L19: Sim | M19: Sim | N19: =IF(B19="","",IF(COUNTA(G19:M19)<7,"Análise incompleta",IF(COUNTIF(G19:M19,"Não")>0,"Resolver antes de aceitar","Pode aceitar"))) -> Resolver antes de aceitar | O19: Aceito com alteração | P19: 15 t em 10 dias e 15 t em 25 dias, com o aceite do cliente por e-mail. | Q19: Gerente comercial | R19: 46540 | S19: 46541 | T19: =IF(B19="","",IF(O19="","Falta a decisão",IF(Q19="","Falta quem analisou",IF(O19="Em análise","OK",IF(COUNTA(G19:M19)<7,"Falta responder à análise",IF(R19="","Falta a data da análise",IF(AND(OR(O19="Aceito",O19="Aceito com alteração"),S19=""),"Falta a data da confirmação",IF(AND(OR(O19="Aceito",O19="Aceito com alteração"),R19>S19),"Analisado depois de aceitar",IF(AND(O19="Aceito",COUNTIF(G19:M19,"Não")>0),"Aceito com pendência na análise",IF(AND(O19="Aceito com alteração",P19=""),"Falta o que foi negociado",IF(AND(O19="Recusado",P19=""),"Falta o motivo da recusa","OK"))))))))))) -> OK
B20: PR-118 | C20: 46541 | D20: Cliente C, alimentos congelados · Visita | E20: Filme liso de 50 µm para embalar vegetais congelados. Resistência ao impacto a -18 °C, que o filme padrão não tem. Declaração de conformidade para contato com alimentos. | F20: 46583 | G20: Sim | H20: Sim | I20: Sim | J20: Não | K20: Sim | L20: Sim | M20: Sim | N20: =IF(B20="","",IF(COUNTA(G20:M20)<7,"Análise incompleta",IF(COUNTIF(G20:M20,"Não")>0,"Resolver antes de aceitar","Pode aceitar"))) -> Resolver antes de aceitar | O20: Aceito com alteração | P20: Lote de teste de 500 kg com a resina para baixa temperatura, ensaiado pelo cliente antes do pedido firme. | Q20: Gerente de engenharia | R20: 46542 | S20: 46545 | T20: =IF(B20="","",IF(O20="","Falta a decisão",IF(Q20="","Falta quem analisou",IF(O20="Em análise","OK",IF(COUNTA(G20:M20)<7,"Falta responder à análise",IF(R20="","Falta a data da análise",IF(AND(OR(O20="Aceito",O20="Aceito com alteração"),S20=""),"Falta a data da confirmação",IF(AND(OR(O20="Aceito",O20="Aceito com alteração"),R20>S20),"Analisado depois de aceitar",IF(AND(O20="Aceito",COUNTIF(G20:M20,"Não")>0),"Aceito com pendência na análise",IF(AND(O20="Aceito com alteração",P20=""),"Falta o que foi negociado",IF(AND(O20="Recusado",P20=""),"Falta o motivo da recusa","OK"))))))))))) -> OK
B21: PV-2236 | C21: 46545 | D21: Cliente A · E-mail | E21: Item novo: filme de 35 µm com tolerância de ±1 µm. | F21: 46568 | G21: Não | H21: Sim | I21: Sim | J21: Sim | K21: Sim | L21: Sim | M21: Sim | N21: =IF(B21="","",IF(COUNTA(G21:M21)<7,"Análise incompleta",IF(COUNTIF(G21:M21,"Não")>0,"Resolver antes de aceitar","Pode aceitar"))) -> Resolver antes de aceitar | O21: Aceito com alteração | P21: Tolerância de ±2 µm, a capacidade do processo, aceita pelo cliente por e-mail. | Q21: Gerente de engenharia | R21: 46546 | S21: 46547 | T21: =IF(B21="","",IF(O21="","Falta a decisão",IF(Q21="","Falta quem analisou",IF(O21="Em análise","OK",IF(COUNTA(G21:M21)<7,"Falta responder à análise",IF(R21="","Falta a data da análise",IF(AND(OR(O21="Aceito",O21="Aceito com alteração"),S21=""),"Falta a data da confirmação",IF(AND(OR(O21="Aceito",O21="Aceito com alteração"),R21>S21),"Analisado depois de aceitar",IF(AND(O21="Aceito",COUNTIF(G21:M21,"Não")>0),"Aceito com pendência na análise",IF(AND(O21="Aceito com alteração",P21=""),"Falta o que foi negociado",IF(AND(O21="Recusado",P21=""),"Falta o motivo da recusa","OK"))))))))))) -> OK
B22: PR-119 | C22: 46546 | D22: Cliente D · E-mail | E22: Filme com 50% de resina reciclada, para contato direto com queijos. | F22: 46569 | G22: Sim | H22: Sim | I22: Sim | J22: Sim | K22: Não | L22: Sim | M22: Sim | N22: =IF(B22="","",IF(COUNTA(G22:M22)<7,"Análise incompleta",IF(COUNTIF(G22:M22,"Não")>0,"Resolver antes de aceitar","Pode aceitar"))) -> Resolver antes de aceitar | O22: Recusado | P22: A resina reciclada não pode estar em contato com o alimento. Oferecido o filme com 30% na camada externa, em desenvolvimento. | Q22: Coordenador da Qualidade | R22: 46547 | T22: =IF(B22="","",IF(O22="","Falta a decisão",IF(Q22="","Falta quem analisou",IF(O22="Em análise","OK",IF(COUNTA(G22:M22)<7,"Falta responder à análise",IF(R22="","Falta a data da análise",IF(AND(OR(O22="Aceito",O22="Aceito com alteração"),S22=""),"Falta a data da confirmação",IF(AND(OR(O22="Aceito",O22="Aceito com alteração"),R22>S22),"Analisado depois de aceitar",IF(AND(O22="Aceito",COUNTIF(G22:M22,"Não")>0),"Aceito com pendência na análise",IF(AND(O22="Aceito com alteração",P22=""),"Falta o que foi negociado",IF(AND(O22="Recusado",P22=""),"Falta o motivo da recusa","OK"))))))))))) -> OK
B23: PV-2238 | C23: 46547 | D23: Cliente B · E-mail | E23: 10 t de filme liso de 50 µm, com 620 mm de largura. | F23: 46563 | G23: Sim | H23: Sim | I23: Sim | J23: Sim | K23: Sim | L23: Não | M23: Sim | N23: =IF(B23="","",IF(COUNTA(G23:M23)<7,"Análise incompleta",IF(COUNTIF(G23:M23,"Não")>0,"Resolver antes de aceitar","Pode aceitar"))) -> Resolver antes de aceitar | O23: Aceito | Q23: Gerente comercial | R23: 46547 | S23: 46547 | T23: =IF(B23="","",IF(O23="","Falta a decisão",IF(Q23="","Falta quem analisou",IF(O23="Em análise","OK",IF(COUNTA(G23:M23)<7,"Falta responder à análise",IF(R23="","Falta a data da análise",IF(AND(OR(O23="Aceito",O23="Aceito com alteração"),S23=""),"Falta a data da confirmação",IF(AND(OR(O23="Aceito",O23="Aceito com alteração"),R23>S23),"Analisado depois de aceitar",IF(AND(O23="Aceito",COUNTIF(G23:M23,"Não")>0),"Aceito com pendência na análise",IF(AND(O23="Aceito com alteração",P23=""),"Falta o que foi negociado",IF(AND(O23="Recusado",P23=""),"Falta o motivo da recusa","OK"))))))))))) -> Aceito com pendência na análise
B24: PR-120 | C24: 46548 | D24: Cliente E · Visita | E24: Filme impresso em quatro cores para embalagem de biscoitos. | F24: 46578 | G24: Não | H24: Sim | I24: Sim | J24: Sim | K24: Sim | L24: Sim | M24: Sim | N24: =IF(B24="","",IF(COUNTA(G24:M24)<7,"Análise incompleta",IF(COUNTIF(G24:M24,"Não")>0,"Resolver antes de aceitar","Pode aceitar"))) -> Resolver antes de aceitar | O24: Em análise | P24: Aguardando a arte aprovada pelo cliente. | Q24: Gerente comercial | R24: 46549 | T24: =IF(B24="","",IF(O24="","Falta a decisão",IF(Q24="","Falta quem analisou",IF(O24="Em análise","OK",IF(COUNTA(G24:M24)<7,"Falta responder à análise",IF(R24="","Falta a data da análise",IF(AND(OR(O24="Aceito",O24="Aceito com alteração"),S24=""),"Falta a data da confirmação",IF(AND(OR(O24="Aceito",O24="Aceito com alteração"),R24>S24),"Analisado depois de aceitar",IF(AND(O24="Aceito",COUNTIF(G24:M24,"Não")>0),"Aceito com pendência na análise",IF(AND(O24="Aceito com alteração",P24=""),"Falta o que foi negociado",IF(AND(O24="Recusado",P24=""),"Falta o motivo da recusa","OK"))))))))))) -> OK
B25: PV-2241 | C25: 46549 | D25: Cliente A · Telefone | E25: 8 t de filme liso de 40 µm, urgente, em 5 dias. | F25: 46554 | G25: Sim | H25: Sim | I25: Sim | J25: Sim | K25: Sim | L25: Sim | M25: Sim | N25: =IF(B25="","",IF(COUNTA(G25:M25)<7,"Análise incompleta",IF(COUNTIF(G25:M25,"Não")>0,"Resolver antes de aceitar","Pode aceitar"))) -> Pode aceitar | O25: Aceito | Q25: Programação da produção | R25: 46552 | S25: 46549 | T25: =IF(B25="","",IF(O25="","Falta a decisão",IF(Q25="","Falta quem analisou",IF(O25="Em análise","OK",IF(COUNTA(G25:M25)<7,"Falta responder à análise",IF(R25="","Falta a data da análise",IF(AND(OR(O25="Aceito",O25="Aceito com alteração"),S25=""),"Falta a data da confirmação",IF(AND(OR(O25="Aceito",O25="Aceito com alteração"),R25>S25),"Analisado depois de aceitar",IF(AND(O25="Aceito",COUNTIF(G25:M25,"Não")>0),"Aceito com pendência na análise",IF(AND(O25="Aceito com alteração",P25=""),"Falta o que foi negociado",IF(AND(O25="Recusado",P25=""),"Falta o motivo da recusa","OK"))))))))))) -> Analisado depois de aceitar
B26: Perguntas: 1 especificação · 2 capacidade e prazo · 3 entrega e pós-entrega · 4 uso pretendido · 5 requisitos legais · 6 diferenças · 7 preço e condições.
B28: Mudanças nos pedidos aceitos
B29: Data | C29: Pedido | D29: O que mudou | F29: Análise da mudança | N29: Quem pediu | P29: Quem foi informado | Q29: Documentos atualizados? | T29: Conferência
B30: 46542 | C30: PV-2232 | D30: Entrega no novo centro de distribuição do cliente. | F30: Frete recalculado e aceito pelo cliente. | N30: Comprador do cliente B | P30: Expedição | Q30: Sim | T30: =IF(D30="",IF(1>0,"Falta o que mudou",""),IF(C30="","Falta o pedido",IF(COUNTIF($B$18:$B$25,C30)=0,"Pedido não está na aba Pedidos",IF(F30="","Falta a análise",IF(Q30<>"Sim","Documentos não atualizados",IF(P30="","Falta quem foi informado","OK")))))) -> OK
B31: 46549 | C31: PV-2231 | D31: De 12 para 16 t. | F31: Programação conferiu a extrusora 3. Compras confirmou a resina. | N31: Comprador do cliente A | P31: Produção e Compras | Q31: Sim | T31: =IF(D31="",IF(1>0,"Falta o que mudou",""),IF(C31="","Falta o pedido",IF(COUNTIF($B$18:$B$25,C31)=0,"Pedido não está na aba Pedidos",IF(F31="","Falta a análise",IF(Q31<>"Sim","Documentos não atualizados",IF(P31="","Falta quem foi informado","OK")))))) -> OK
B32: 46550 | C32: PV-2238 | D32: Largura corrigida de 600 para 620 mm na ordem de produção. | F32: Conferida com o pedido do cliente. | N32: Programação da produção | Q32: Sim | T32: =IF(D32="",IF(1>0,"Falta o que mudou",""),IF(C32="","Falta o pedido",IF(COUNTIF($B$18:$B$25,C32)=0,"Pedido não está na aba Pedidos",IF(F32="","Falta a análise",IF(Q32<>"Sim","Documentos não atualizados",IF(P32="","Falta quem foi informado","OK")))))) -> Falta quem foi informado
B34: Resumo automático
B35: Pedidos por decisão | F35: =COUNTIF(O18:O25,"Aceito")&" aceitos"&", "&COUNTIF(O18:O25,"Aceito com alteração")&" aceitos com alteração"&", "&COUNTIF(O18:O25,"Recusado")&" recusados"&", "&COUNTIF(O18:O25,"Em análise")&" em análise" -> 3 aceitos, 3 aceitos com alteração, 1 recusados, 1 em análise
B36: Pedidos em que a análise encontrou problema | F36: =SUMPRODUCT((((G18:G25="Não")+(H18:H25="Não")+(I18:I25="Não")+(J18:J25="Não")+(K18:K25="Não")+(L18:L25="Não")+(M18:M25="Não"))>0)*1) -> 6
B37: Pedidos a rever | F37: =SUMPRODUCT((T18:T25<>"OK")*1) -> 2
B38: Respostas “não” por pergunta | F38: ="1: "&COUNTIF(G18:G25,"Não")&" · "&"2: "&COUNTIF(H18:H25,"Não")&" · "&"3: "&COUNTIF(I18:I25,"Não")&" · "&"4: "&COUNTIF(J18:J25,"Não")&" · "&"5: "&COUNTIF(K18:K25,"Não")&" · "&"6: "&COUNTIF(L18:L25,"Não")&" · "&"7: "&COUNTIF(M18:M25,"Não") -> 1: 2 · 2: 1 · 3: 0 · 4: 1 · 5: 1 · 6: 1 · 7: 0
B39: Mudanças: registradas, a rever | F39: =COUNTA(D30:D32)&" registradas, "&SUMPRODUCT((T30:T32<>"OK")*1)&" a rever" -> 3 registradas, 1 a rever
