Workbook

Sheet Instruções
B1: Recursos, infraestrutura e ambiente — Como usar esta planilha
B2: Modelo para dimensionar as pessoas no pico, controlar a manutenção da infraestrutura e acompanhar o ambiente dos processos.
B4: Legenda: onde preencher
B5: Amarelo-claro | C5: Células de entrada. É aqui que você digita.
B6: Cinza | C6: Células calculadas ou fixas (necessárias, próxima preventiva, quebras, disponibilidade, situações, conferências). Não altere.
B7: Cinza em itálico | C7: Linha de exemplo (marcada com “Ex.”). Mostra o formato esperado e não entra nas contagens.
B8: Listas suspensas | C8: Tipo, criticidade, código do item, tipo de manutenção, produto afetado, tipo de fator e checklist aceitam apenas as opções da lista.
B9: Comentários | C9: Células com triângulo vermelho no canto trazem uma dica de preenchimento. Passe o mouse sobre elas.
B11: As regras de cálculo
B12: Pessoas necessárias | C12: A demanda do pico dividida pela produtividade de uma pessoa, arredondada para cima.
B13: Folga | C13: As pessoas escaladas menos as necessárias. Negativa: falta gente. Zero: justo. Positiva: com folga.
B14: Próxima preventiva | C14: A última preventiva mais o intervalo, em meses.
B15: Em dia | C15: A próxima preventiva está a mais de 7 dias do fim do período.
B16: Vence em 7 dias | C16: A próxima preventiva está a 7 dias ou menos.
B17: Atrasada | C17: A data já passou, ou há intervalo e nenhuma preventiva registrada.
B18: Sem plano | C18: O item não tem intervalo de preventiva. Aceito só na criticidade baixa.
B19: Quebras e horas paradas | C19: Só as corretivas da aba Manutenções, com data dentro do período.
B20: Disponibilidade | C20: Horas programadas menos horas paradas, divididas pelas horas programadas. A preventiva é planejada e não entra na conta.
B21: Ambiente | C21: Fora quando a medição fica abaixo do mínimo ou acima do máximo. Sem medição quando não há medição.
B23: Ordem recomendada de preenchimento
B24: Passo 1 | C24: Aba Pessoas: cada função no período de maior movimento, com a demanda do pico, a produtividade, as escaladas e as qualificadas.
B25: Passo 2 | C25: Aba Infraestrutura: informe o início e o fim do período e a meta de disponibilidade.
B26: Passo 3 | C26: Aba Infraestrutura: cadastre os itens, com tipo, criticidade, preventiva, contingência e horas programadas no período.
B27: Passo 4 | C27: Aba Manutenções: lance as preventivas e as corretivas, com o tempo parado, a causa, a ação e o produto afetado.
B28: Passo 5 | C28: Aba Ambiente: os fatores que afetam o produto, com o limite, o controle e a última medição.
B29: Passo 6 | C29: Aba Painel: leia os avisos. Depois, valide na aba Checklist.
B31: Abas da planilha
B32: Pessoas | C32: Até 30 funções e períodos. Calcula as necessárias, a folga, a situação e a conferência.
B33: Infraestrutura | C33: Até 40 itens. Calcula a próxima preventiva, a situação, as quebras, as horas paradas, a disponibilidade e a conferência.
B34: Manutenções | C34: Até 80 registros de preventivas e corretivas. Traz o nome do item e calcula a conferência.
B35: Ambiente | C35: Até 30 fatores. Calcula a situação e a conferência.
B36: Painel | C36: Os números das quatro abas, o gráfico das preventivas e o aviso.
B37: Checklist | C37: Doze verificações dos recursos, da infraestrutura e do ambiente, com percentual de conclusão.
B38: Exemplo 1 - Pizzaria | C38: A loja em abril de 2027.
B39: Exemplo 2 - Indústria | C39: A fábrica em julho de 2027.
B41: Regras e premissas do modelo
B42: Demanda do pico | C42: A maior demanda numa hora ou num turno, medida no sistema. A média esconde o problema.
B43: Criticidade | C43: Alta: se parar, o produto ou a entrega param. Média: atrapalha, mas há como seguir. Baixa: há reserva, ou a falta não afeta o produto.
B44: Contingência | C44: Obrigatória para a criticidade alta: o que fazer quando o item parar, escrito antes.
B45: Horas programadas | C45: As horas em que o item deveria estar disponível no período. Deixe em branco para itens sem horário, como um sistema.
...

Sheet Pessoas
B1: Pessoas no pico
B2: Uma função por período por linha. As pessoas necessárias vêm da demanda do pico e da produtividade.
B4: # | C4: Função | D4: Período | E4: Unidade da demanda | F4: Demanda no pico | G4: Produtividade por pessoa | H4: Necessárias | I4: Escaladas | J4: Qualificadas | K4: Folga | L4: Situação | M4: Conferência
D5: Dia e horário | E5: pedidos por hora | F5: Número | G5: Na mesma unidade | H5: Calculada | I5: Número | J5: Das escaladas | K5: Calculada | L5: Calculada | M5: Calculada
B6: Ex. | C6: Entregador | D6: Sexta, 20h às 22h | E6: entregas por hora | F6: 29 | G6: 3 | H6: 10 | I6: 8 | J6: 8 | K6: -2 | L6: Falta gente | M6: Faltam 2 pessoas
B7: 1 | H7: =IF(OR(N(F7)=0,N(G7)=0),"",ROUNDUP(F7/G7,0)) | K7: =IF(OR(H7="",I7=""),"",I7-H7) | L7: =IF(K7="","",IF(K7<0,"Falta gente",IF(K7=0,"Justo","Com folga"))) | M7: =IF(C7="","",IF(N(F7)=0,"Falta a demanda",IF(N(G7)=0,"Falta a produtividade",IF(I7="","Falta o número escalado",IF(J7="","Falta o número de qualificados",IF(J7>I7,"Mais qualificados que escalados",IF(K7<0,IF(K7=-1,"Falta 1 pessoa","Faltam "&-K7&" pessoas"),IF(J7=0,"Sem pessoa qualificada na escala","OK"))))))))
B8: 2 | H8: =IF(OR(N(F8)=0,N(G8)=0),"",ROUNDUP(F8/G8,0)) | K8: =IF(OR(H8="",I8=""),"",I8-H8) | L8: =IF(K8="","",IF(K8<0,"Falta gente",IF(K8=0,"Justo","Com folga"))) | M8: =IF(C8="","",IF(N(F8)=0,"Falta a demanda",IF(N(G8)=0,"Falta a produtividade",IF(I8="","Falta o número escalado",IF(J8="","Falta o número de qualificados",IF(J8>I8,"Mais qualificados que escalados",IF(K8<0,IF(K8=-1,"Falta 1 pessoa","Faltam "&-K8&" pessoas"),IF(J8=0,"Sem pessoa qualificada na escala","OK"))))))))
B9: 3 | H9: =IF(OR(N(F9)=0,N(G9)=0),"",ROUNDUP(F9/G9,0)) | K9: =IF(OR(H9="",I9=""),"",I9-H9) | L9: =IF(K9="","",IF(K9<0,"Falta gente",IF(K9=0,"Justo","Com folga"))) | M9: =IF(C9="","",IF(N(F9)=0,"Falta a demanda",IF(N(G9)=0,"Falta a produtividade",IF(I9="","Falta o número escalado",IF(J9="","Falta o número de qualificados",IF(J9>I9,"Mais qualificados que escalados",IF(K9<0,IF(K9=-1,"Falta 1 pessoa","Faltam "&-K9&" pessoas"),IF(J9=0,"Sem pessoa qualificada na escala","OK"))))))))
B10: 4 | H10: =IF(OR(N(F10)=0,N(G10)=0),"",ROUNDUP(F10/G10,0)) | K10: =IF(OR(H10="",I10=""),"",I10-H10) | L10: =IF(K10="","",IF(K10<0,"Falta gente",IF(K10=0,"Justo","Com folga"))) | M10: =IF(C10="","",IF(N(F10)=0,"Falta a demanda",IF(N(G10)=0,"Falta a produtividade",IF(I10="","Falta o número escalado",IF(J10="","Falta o número de qualificados",IF(J10>I10,"Mais qualificados que escalados",IF(K10<0,IF(K10=-1,"Falta 1 pessoa","Faltam "&-K10&" pessoas"),IF(J10=0,"Sem pessoa qualificada na escala","OK"))))))))
B11: 5 | H11: =IF(OR(N(F11)=0,N(G11)=0),"",ROUNDUP(F11/G11,0)) | K11: =IF(OR(H11="",I11=""),"",I11-H11) | L11: =IF(K11="","",IF(K11<0,"Falta gente",IF(K11=0,"Justo","Com folga"))) | M11: =IF(C11="","",IF(N(F11)=0,"Falta a demanda",IF(N(G11)=0,"Falta a produtividade",IF(I11="","Falta o número escalado",IF(J11="","Falta o número de qualificados",IF(J11>I11,"Mais qualificados que escalados",IF(K11<0,IF(K11=-1,"Falta 1 pessoa","Faltam "&-K11&" pessoas"),IF(J11=0,"Sem pessoa qualificada na escala","OK"))))))))
B12: 6 | H12: =IF(OR(N(F12)=0,N(G12)=0),"",ROUNDUP(F12/G12,0)) | K12: =IF(OR(H12="",I12=""),"",I12-H12) | L12: =IF(K12="","",IF(K12<0,"Falta gente",IF(K12=0,"Justo","Com folga"))) | M12: =IF(C12="","",IF(N(F12)=0,"Falta a demanda",IF(N(G12)=0,"Falta a produtividade",IF(I12="","Falta o número escalado",IF(J12="","Falta o número de qualificados",IF(J12>I12,"Mais qualificados que escalados",IF(K12<0,IF(K12=-1,"Falta 1 pessoa","Faltam "&-K12&" pessoas"),IF(J12=0,"Sem pessoa qualificada na escala","OK"))))))))
B13: 7 | H13: =IF(OR(N(F13)=0,N(G13)=0),"",ROUNDUP(F13/G13,0)) | K13: =IF(OR(H13="",I13=""),"",I13-H13) | L13: =IF(K13="","",IF(K13<0,"Falta gente",IF(K13=0,"Justo","Com folga"))) | M13: =IF(C13="","",IF(N(F13)=0,"Falta a demanda",IF(N(G13)=0,"Falta a produtividade",IF(I13="","Falta o número escalado",IF(J13="","Falta o número de qualificados",IF(J13>I13,"Mais qualificados que escalados",IF(K13<0,IF(K13=-1,"Falta 1 pessoa","Faltam "&-K13&" pessoas"),IF(J13=0,"Sem pessoa qualificada na escala","OK"))))))))
B14: 8 | H14: =IF(OR(N(F14)=0,N(G14)=0),"",ROUNDUP(F14/G14,0)) | K14: =IF(OR(H14="",I14=""),"",I14-H14) | L14: =IF(K14="","",IF(K14<0,"Falta gente",IF(K14=0,"Justo","Com folga"))) | M14: =IF(C14="","",IF(N(F14)=0,"Falta a demanda",IF(N(G14)=0,"Falta a produtividade",IF(I14="","Falta o número escalado",IF(J14="","Falta o número de qualificados",IF(J14>I14,"Mais qualificados que escalados",IF(K14<0,IF(K14=-1,"Falta 1 pessoa","Faltam "&-K14&" pessoas"),IF(J14=0,"Sem pessoa qualificada na escala","OK"))))))))
B15: 9 | H15: =IF(OR(N(F15)=0,N(G15)=0),"",ROUNDUP(F15/G15,0)) | K15: =IF(OR(H15="",I15=""),"",I15-H15) | L15: =IF(K15="","",IF(K15<0,"Falta gente",IF(K15=0,"Justo","Com folga"))) | M15: =IF(C15="","",IF(N(F15)=0,"Falta a demanda",IF(N(G15)=0,"Falta a produtividade",IF(I15="","Falta o número escalado",IF(J15="","Falta o número de qualificados",IF(J15>I15,"Mais qualificados que escalados",IF(K15<0,IF(K15=-1,"Falta 1 pessoa","Faltam "&-K15&" pessoas"),IF(J15=0,"Sem pessoa qualificada na escala","OK"))))))))
B16: 10 | H16: =IF(OR(N(F16)=0,N(G16)=0),"",ROUNDUP(F16/G16,0)) | K16: =IF(OR(H16="",I16=""),"",I16-H16) | L16: =IF(K16="","",IF(K16<0,"Falta gente",IF(K16=0,"Justo","Com folga"))) | M16: =IF(C16="","",IF(N(F16)=0,"Falta a demanda",IF(N(G16)=0,"Falta a produtividade",IF(I16="","Falta o número escalado",IF(J16="","Falta o número de qualificados",IF(J16>I16,"Mais qualificados que escalados",IF(K16<0,IF(K16=-1,"Falta 1 pessoa","Faltam "&-K16&" pessoas"),IF(J16=0,"Sem pessoa qualificada na escala","OK"))))))))
B17: 11 | H17: =IF(OR(N(F17)=0,N(G17)=0),"",ROUNDUP(F17/G17,0)) | K17: =IF(OR(H17="",I17=""),"",I17-H17) | L17: =IF(K17="","",IF(K17<0,"Falta gente",IF(K17=0,"Justo","Com folga"))) | M17: =IF(C17="","",IF(N(F17)=0,"Falta a demanda",IF(N(G17)=0,"Falta a produtividade",IF(I17="","Falta o número escalado",IF(J17="","Falta o número de qualificados",IF(J17>I17,"Mais qualificados que escalados",IF(K17<0,IF(K17=-1,"Falta 1 pessoa","Faltam "&-K17&" pessoas"),IF(J17=0,"Sem pessoa qualificada na escala","OK"))))))))
B18: 12 | H18: =IF(OR(N(F18)=0,N(G18)=0),"",ROUNDUP(F18/G18,0)) | K18: =IF(OR(H18="",I18=""),"",I18-H18) | L18: =IF(K18="","",IF(K18<0,"Falta gente",IF(K18=0,"Justo","Com folga"))) | M18: =IF(C18="","",IF(N(F18)=0,"Falta a demanda",IF(N(G18)=0,"Falta a produtividade",IF(I18="","Falta o número escalado",IF(J18="","Falta o número de qualificados",IF(J18>I18,"Mais qualificados que escalados",IF(K18<0,IF(K18=-1,"Falta 1 pessoa","Faltam "&-K18&" pessoas"),IF(J18=0,"Sem pessoa qualificada na escala","OK"))))))))
... B36: 30 | H36: =IF(OR(N(F36)=0,N(G36)=0),"",ROUNDUP(F36/G36,0)) | K36: =IF(OR(H36="",I36=""),"",I36-H36) | L36: =IF(K36="","",IF(K36<0,"Falta gente",IF(K36=0,"Justo","Com folga"))) | M36: =IF(C36="","",IF(N(F36)=0,"Falta a demanda",IF(N(G36)=0,"Falta a produtividade",IF(I36="","Falta o número escalado",IF(J36="","Falta o número de qualificados",IF(J36>I36,"Mais qualificados que escalados",IF(K36<0,IF(K36=-1,"Falta 1 pessoa","Faltam "&-K36&" pessoas"),IF(J36=0,"Sem pessoa qualificada na escala","OK"))))))))
B38: Resumo automático
B39: Funções e períodos | E39: =COUNTA(C7:C36) -> 0
B40: Com falta de gente | E40: =COUNTIF(L7:L36,"Falta gente")&" linhas, "&-SUMIF(K7:K36,"<0")&" pessoas a menos no pico" -> 0 linhas, 0 pessoas a menos no pico
B41: Aviso | E41: =IF(E39=0,"Liste as funções e os períodos",IF(COUNTIF(L7:L36,"Falta gente")>0,"Há função com falta de gente no pico",IF(COUNTIF(M7:M36,"Sem pessoa qualificada na escala")>0,"Há função sem pessoa qualificada na escala",IF(SUMPRODUCT((M7:M36<>"")*(M7:M36<>"OK"))>0,"Há linha a completar: veja a coluna Conferência","OK")))) -> Liste as funções e os períodos

Sheet Infraestrutura
B1: Infraestrutura
B2: Um item por linha: criticidade, preventiva, contingência e o que as quebras do período custaram.
B4: Início do período | F4: As quebras e as horas paradas contam só as corretivas com data entre o início e o fim.
B5: Fim do período | F5: Também é a data da leitura: a situação da preventiva é calculada nela.
B6: Meta de disponibilidade | F6: A disponibilidade mínima aceita para os itens com horas programadas.
B8: # | C8: Código | D8: Item | E8: Tipo | F8: Local | G8: Criticidade | H8: Preventiva (meses) | I8: Última preventiva | J8: Contingência | K8: Horas programadas | L8: Próxima | M8: Situação | N8: Quebras | O8: Horas paradas | P8: Disponib. | Q8: Conferência
C9: FOR-01 | E9: Lista | G9: Lista | H9: Número | I9: Data | J9: O que fazer se parar | K9: No período | L9: Calculada | M9: Calculada | N9: Calculada | O9: Calculada | P9: Calculada | Q9: Calculada
B10: 1 | L10: =IF(OR(I10="",H10=""),"",EDATE(I10,H10)) | M10: =IF(C10="","",IF(H10="","Sem plano",IF(I10="","Atrasada",IF(AND(ISNUMBER($E$5),L10<$E$5),"Atrasada",IF(AND(ISNUMBER($E$5),L10-$E$5<=7),"Vence em 7 dias","Em dia"))))) | N10: =IF(OR(C10="",$E$4="",$E$5=""),"",COUNTIFS(Manutenções!$D$7:$D$86,C10,Manutenções!$F$7:$F$86,"Corretiva",Manutenções!$C$7:$C$86,">="&$E$4,Manutenções!$C$7:$C$86,"<="&$E$5)) | O10: =IF(OR(C10="",$E$4="",$E$5=""),"",SUMIFS(Manutenções!$G$7:$G$86,Manutenções!$D$7:$D$86,C10,Manutenções!$F$7:$F$86,"Corretiva",Manutenções!$C$7:$C$86,">="&$E$4,Manutenções!$C$7:$C$86,"<="&$E$5)) | P10: =IF(OR(N(K10)=0,O10=""),"",(K10-O10)/K10) | Q10: =IF(C10="","",IF(E10="","Falta o tipo",IF(G10="","Falta a criticidade",IF(AND(OR(G10="Alta",G10="Média"),H10=""),"Sem plano de preventiva",IF(M10="Atrasada","Preventiva atrasada",IF(AND(G10="Alta",J10=""),"Crítico sem contingência",IF(AND(ISNUMBER(P10),ISNUMBER($E$6)),IF(P10<$E$6-0.000000001,"Disponibilidade abaixo da meta","OK"),"OK")))))))
B11: 2 | L11: =IF(OR(I11="",H11=""),"",EDATE(I11,H11)) | M11: =IF(C11="","",IF(H11="","Sem plano",IF(I11="","Atrasada",IF(AND(ISNUMBER($E$5),L11<$E$5),"Atrasada",IF(AND(ISNUMBER($E$5),L11-$E$5<=7),"Vence em 7 dias","Em dia"))))) | N11: =IF(OR(C11="",$E$4="",$E$5=""),"",COUNTIFS(Manutenções!$D$7:$D$86,C11,Manutenções!$F$7:$F$86,"Corretiva",Manutenções!$C$7:$C$86,">="&$E$4,Manutenções!$C$7:$C$86,"<="&$E$5)) | O11: =IF(OR(C11="",$E$4="",$E$5=""),"",SUMIFS(Manutenções!$G$7:$G$86,Manutenções!$D$7:$D$86,C11,Manutenções!$F$7:$F$86,"Corretiva",Manutenções!$C$7:$C$86,">="&$E$4,Manutenções!$C$7:$C$86,"<="&$E$5)) | P11: =IF(OR(N(K11)=0,O11=""),"",(K11-O11)/K11) | Q11: =IF(C11="","",IF(E11="","Falta o tipo",IF(G11="","Falta a criticidade",IF(AND(OR(G11="Alta",G11="Média"),H11=""),"Sem plano de preventiva",IF(M11="Atrasada","Preventiva atrasada",IF(AND(G11="Alta",J11=""),"Crítico sem contingência",IF(AND(ISNUMBER(P11),ISNUMBER($E$6)),IF(P11<$E$6-0.000000001,"Disponibilidade abaixo da meta","OK"),"OK")))))))
B12: 3 | L12: =IF(OR(I12="",H12=""),"",EDATE(I12,H12)) | M12: =IF(C12="","",IF(H12="","Sem plano",IF(I12="","Atrasada",IF(AND(ISNUMBER($E$5),L12<$E$5),"Atrasada",IF(AND(ISNUMBER($E$5),L12-$E$5<=7),"Vence em 7 dias","Em dia"))))) | N12: =IF(OR(C12="",$E$4="",$E$5=""),"",COUNTIFS(Manutenções!$D$7:$D$86,C12,Manutenções!$F$7:$F$86,"Corretiva",Manutenções!$C$7:$C$86,">="&$E$4,Manutenções!$C$7:$C$86,"<="&$E$5)) | O12: =IF(OR(C12="",$E$4="",$E$5=""),"",SUMIFS(Manutenções!$G$7:$G$86,Manutenções!$D$7:$D$86,C12,Manutenções!$F$7:$F$86,"Corretiva",Manutenções!$C$7:$C$86,">="&$E$4,Manutenções!$C$7:$C$86,"<="&$E$5)) | P12: =IF(OR(N(K12)=0,O12=""),"",(K12-O12)/K12) | Q12: =IF(C12="","",IF(E12="","Falta o tipo",IF(G12="","Falta a criticidade",IF(AND(OR(G12="Alta",G12="Média"),H12=""),"Sem plano de preventiva",IF(M12="Atrasada","Preventiva atrasada",IF(AND(G12="Alta",J12=""),"Crítico sem contingência",IF(AND(ISNUMBER(P12),ISNUMBER($E$6)),IF(P12<$E$6-0.000000001,"Disponibilidade abaixo da meta","OK"),"OK")))))))
B13: 4 | L13: =IF(OR(I13="",H13=""),"",EDATE(I13,H13)) | M13: =IF(C13="","",IF(H13="","Sem plano",IF(I13="","Atrasada",IF(AND(ISNUMBER($E$5),L13<$E$5),"Atrasada",IF(AND(ISNUMBER($E$5),L13-$E$5<=7),"Vence em 7 dias","Em dia"))))) | N13: =IF(OR(C13="",$E$4="",$E$5=""),"",COUNTIFS(Manutenções!$D$7:$D$86,C13,Manutenções!$F$7:$F$86,"Corretiva",Manutenções!$C$7:$C$86,">="&$E$4,Manutenções!$C$7:$C$86,"<="&$E$5)) | O13: =IF(OR(C13="",$E$4="",$E$5=""),"",SUMIFS(Manutenções!$G$7:$G$86,Manutenções!$D$7:$D$86,C13,Manutenções!$F$7:$F$86,"Corretiva",Manutenções!$C$7:$C$86,">="&$E$4,Manutenções!$C$7:$C$86,"<="&$E$5)) | P13: =IF(OR(N(K13)=0,O13=""),"",(K13-O13)/K13) | Q13: =IF(C13="","",IF(E13="","Falta o tipo",IF(G13="","Falta a criticidade",IF(AND(OR(G13="Alta",G13="Média"),H13=""),"Sem plano de preventiva",IF(M13="Atrasada","Preventiva atrasada",IF(AND(G13="Alta",J13=""),"Crítico sem contingência",IF(AND(ISNUMBER(P13),ISNUMBER($E$6)),IF(P13<$E$6-0.000000001,"Disponibilidade abaixo da meta","OK"),"OK")))))))
B14: 5 | L14: =IF(OR(I14="",H14=""),"",EDATE(I14,H14)) | M14: =IF(C14="","",IF(H14="","Sem plano",IF(I14="","Atrasada",IF(AND(ISNUMBER($E$5),L14<$E$5),"Atrasada",IF(AND(ISNUMBER($E$5),L14-$E$5<=7),"Vence em 7 dias","Em dia"))))) | N14: =IF(OR(C14="",$E$4="",$E$5=""),"",COUNTIFS(Manutenções!$D$7:$D$86,C14,Manutenções!$F$7:$F$86,"Corretiva",Manutenções!$C$7:$C$86,">="&$E$4,Manutenções!$C$7:$C$86,"<="&$E$5)) | O14: =IF(OR(C14="",$E$4="",$E$5=""),"",SUMIFS(Manutenções!$G$7:$G$86,Manutenções!$D$7:$D$86,C14,Manutenções!$F$7:$F$86,"Corretiva",Manutenções!$C$7:$C$86,">="&$E$4,Manutenções!$C$7:$C$86,"<="&$E$5)) | P14: =IF(OR(N(K14)=0,O14=""),"",(K14-O14)/K14) | Q14: =IF(C14="","",IF(E14="","Falta o tipo",IF(G14="","Falta a criticidade",IF(AND(OR(G14="Alta",G14="Média"),H14=""),"Sem plano de preventiva",IF(M14="Atrasada","Preventiva atrasada",IF(AND(G14="Alta",J14=""),"Crítico sem contingência",IF(AND(ISNUMBER(P14),ISNUMBER($E$6)),IF(P14<$E$6-0.000000001,"Disponibilidade abaixo da meta","OK"),"OK")))))))
B15: 6 | L15: =IF(OR(I15="",H15=""),"",EDATE(I15,H15)) | M15: =IF(C15="","",IF(H15="","Sem plano",IF(I15="","Atrasada",IF(AND(ISNUMBER($E$5),L15<$E$5),"Atrasada",IF(AND(ISNUMBER($E$5),L15-$E$5<=7),"Vence em 7 dias","Em dia"))))) | N15: =IF(OR(C15="",$E$4="",$E$5=""),"",COUNTIFS(Manutenções!$D$7:$D$86,C15,Manutenções!$F$7:$F$86,"Corretiva",Manutenções!$C$7:$C$86,">="&$E$4,Manutenções!$C$7:$C$86,"<="&$E$5)) | O15: =IF(OR(C15="",$E$4="",$E$5=""),"",SUMIFS(Manutenções!$G$7:$G$86,Manutenções!$D$7:$D$86,C15,Manutenções!$F$7:$F$86,"Corretiva",Manutenções!$C$7:$C$86,">="&$E$4,Manutenções!$C$7:$C$86,"<="&$E$5)) | P15: =IF(OR(N(K15)=0,O15=""),"",(K15-O15)/K15) | Q15: =IF(C15="","",IF(E15="","Falta o tipo",IF(G15="","Falta a criticidade",IF(AND(OR(G15="Alta",G15="Média"),H15=""),"Sem plano de preventiva",IF(M15="Atrasada","Preventiva atrasada",IF(AND(G15="Alta",J15=""),"Crítico sem contingência",IF(AND(ISNUMBER(P15),ISNUMBER($E$6)),IF(P15<$E$6-0.000000001,"Disponibilidade abaixo da meta","OK"),"OK")))))))
B16: 7 | L16: =IF(OR(I16="",H16=""),"",EDATE(I16,H16)) | M16: =IF(C16="","",IF(H16="","Sem plano",IF(I16="","Atrasada",IF(AND(ISNUMBER($E$5),L16<$E$5),"Atrasada",IF(AND(ISNUMBER($E$5),L16-$E$5<=7),"Vence em 7 dias","Em dia"))))) | N16: =IF(OR(C16="",$E$4="",$E$5=""),"",COUNTIFS(Manutenções!$D$7:$D$86,C16,Manutenções!$F$7:$F$86,"Corretiva",Manutenções!$C$7:$C$86,">="&$E$4,Manutenções!$C$7:$C$86,"<="&$E$5)) | O16: =IF(OR(C16="",$E$4="",$E$5=""),"",SUMIFS(Manutenções!$G$7:$G$86,Manutenções!$D$7:$D$86,C16,Manutenções!$F$7:$F$86,"Corretiva",Manutenções!$C$7:$C$86,">="&$E$4,Manutenções!$C$7:$C$86,"<="&$E$5)) | P16: =IF(OR(N(K16)=0,O16=""),"",(K16-O16)/K16) | Q16: =IF(C16="","",IF(E16="","Falta o tipo",IF(G16="","Falta a criticidade",IF(AND(OR(G16="Alta",G16="Média"),H16=""),"Sem plano de preventiva",IF(M16="Atrasada","Preventiva atrasada",IF(AND(G16="Alta",J16=""),"Crítico sem contingência",IF(AND(ISNUMBER(P16),ISNUMBER($E$6)),IF(P16<$E$6-0.000000001,"Disponibilidade abaixo da meta","OK"),"OK")))))))
B17: 8 | L17: =IF(OR(I17="",H17=""),"",EDATE(I17,H17)) | M17: =IF(C17="","",IF(H17="","Sem plano",IF(I17="","Atrasada",IF(AND(ISNUMBER($E$5),L17<$E$5),"Atrasada",IF(AND(ISNUMBER($E$5),L17-$E$5<=7),"Vence em 7 dias","Em dia"))))) | N17: =IF(OR(C17="",$E$4="",$E$5=""),"",COUNTIFS(Manutenções!$D$7:$D$86,C17,Manutenções!$F$7:$F$86,"Corretiva",Manutenções!$C$7:$C$86,">="&$E$4,Manutenções!$C$7:$C$86,"<="&$E$5)) | O17: =IF(OR(C17="",$E$4="",$E$5=""),"",SUMIFS(Manutenções!$G$7:$G$86,Manutenções!$D$7:$D$86,C17,Manutenções!$F$7:$F$86,"Corretiva",Manutenções!$C$7:$C$86,">="&$E$4,Manutenções!$C$7:$C$86,"<="&$E$5)) | P17: =IF(OR(N(K17)=0,O17=""),"",(K17-O17)/K17) | Q17: =IF(C17="","",IF(E17="","Falta o tipo",IF(G17="","Falta a criticidade",IF(AND(OR(G17="Alta",G17="Média"),H17=""),"Sem plano de preventiva",IF(M17="Atrasada","Preventiva atrasada",IF(AND(G17="Alta",J17=""),"Crítico sem contingência",IF(AND(ISNUMBER(P17),ISNUMBER($E$6)),IF(P17<$E$6-0.000000001,"Disponibilidade abaixo da meta","OK"),"OK")))))))
B18: 9 | L18: =IF(OR(I18="",H18=""),"",EDATE(I18,H18)) | M18: =IF(C18="","",IF(H18="","Sem plano",IF(I18="","Atrasada",IF(AND(ISNUMBER($E$5),L18<$E$5),"Atrasada",IF(AND(ISNUMBER($E$5),L18-$E$5<=7),"Vence em 7 dias","Em dia"))))) | N18: =IF(OR(C18="",$E$4="",$E$5=""),"",COUNTIFS(Manutenções!$D$7:$D$86,C18,Manutenções!$F$7:$F$86,"Corretiva",Manutenções!$C$7:$C$86,">="&$E$4,Manutenções!$C$7:$C$86,"<="&$E$5)) | O18: =IF(OR(C18="",$E$4="",$E$5=""),"",SUMIFS(Manutenções!$G$7:$G$86,Manutenções!$D$7:$D$86,C18,Manutenções!$F$7:$F$86,"Corretiva",Manutenções!$C$7:$C$86,">="&$E$4,Manutenções!$C$7:$C$86,"<="&$E$5)) | P18: =IF(OR(N(K18)=0,O18=""),"",(K18-O18)/K18) | Q18: =IF(C18="","",IF(E18="","Falta o tipo",IF(G18="","Falta a criticidade",IF(AND(OR(G18="Alta",G18="Média"),H18=""),"Sem plano de preventiva",IF(M18="Atrasada","Preventiva atrasada",IF(AND(G18="Alta",J18=""),"Crítico sem contingência",IF(AND(ISNUMBER(P18),ISNUMBER($E$6)),IF(P18<$E$6-0.000000001,"Disponibilidade abaixo da meta","OK"),"OK")))))))
B19: 10 | L19: =IF(OR(I19="",H19=""),"",EDATE(I19,H19)) | M19: =IF(C19="","",IF(H19="","Sem plano",IF(I19="","Atrasada",IF(AND(ISNUMBER($E$5),L19<$E$5),"Atrasada",IF(AND(ISNUMBER($E$5),L19-$E$5<=7),"Vence em 7 dias","Em dia"))))) | N19: =IF(OR(C19="",$E$4="",$E$5=""),"",COUNTIFS(Manutenções!$D$7:$D$86,C19,Manutenções!$F$7:$F$86,"Corretiva",Manutenções!$C$7:$C$86,">="&$E$4,Manutenções!$C$7:$C$86,"<="&$E$5)) | O19: =IF(OR(C19="",$E$4="",$E$5=""),"",SUMIFS(Manutenções!$G$7:$G$86,Manutenções!$D$7:$D$86,C19,Manutenções!$F$7:$F$86,"Corretiva",Manutenções!$C$7:$C$86,">="&$E$4,Manutenções!$C$7:$C$86,"<="&$E$5)) | P19: =IF(OR(N(K19)=0,O19=""),"",(K19-O19)/K19) | Q19: =IF(C19="","",IF(E19="","Falta o tipo",IF(G19="","Falta a criticidade",IF(AND(OR(G19="Alta",G19="Média"),H19=""),"Sem plano de preventiva",IF(M19="Atrasada","Preventiva atrasada",IF(AND(G19="Alta",J19=""),"Crítico sem contingência",IF(AND(ISNUMBER(P19),ISNUMBER($E$6)),IF(P19<$E$6-0.000000001,"Disponibilidade abaixo da meta","OK"),"OK")))))))
B20: 11 | L20: =IF(OR(I20="",H20=""),"",EDATE(I20,H20)) | M20: =IF(C20="","",IF(H20="","Sem plano",IF(I20="","Atrasada",IF(AND(ISNUMBER($E$5),L20<$E$5),"Atrasada",IF(AND(ISNUMBER($E$5),L20-$E$5<=7),"Vence em 7 dias","Em dia"))))) | N20: =IF(OR(C20="",$E$4="",$E$5=""),"",COUNTIFS(Manutenções!$D$7:$D$86,C20,Manutenções!$F$7:$F$86,"Corretiva",Manutenções!$C$7:$C$86,">="&$E$4,Manutenções!$C$7:$C$86,"<="&$E$5)) | O20: =IF(OR(C20="",$E$4="",$E$5=""),"",SUMIFS(Manutenções!$G$7:$G$86,Manutenções!$D$7:$D$86,C20,Manutenções!$F$7:$F$86,"Corretiva",Manutenções!$C$7:$C$86,">="&$E$4,Manutenções!$C$7:$C$86,"<="&$E$5)) | P20: =IF(OR(N(K20)=0,O20=""),"",(K20-O20)/K20) | Q20: =IF(C20="","",IF(E20="","Falta o tipo",IF(G20="","Falta a criticidade",IF(AND(OR(G20="Alta",G20="Média"),H20=""),"Sem plano de preventiva",IF(M20="Atrasada","Preventiva atrasada",IF(AND(G20="Alta",J20=""),"Crítico sem contingência",IF(AND(ISNUMBER(P20),ISNUMBER($E$6)),IF(P20<$E$6-0.000000001,"Disponibilidade abaixo da meta","OK"),"OK")))))))
B21: 12 | L21: =IF(OR(I21="",H21=""),"",EDATE(I21,H21)) | M21: =IF(C21="","",IF(H21="","Sem plano",IF(I21="","Atrasada",IF(AND(ISNUMBER($E$5),L21<$E$5),"Atrasada",IF(AND(ISNUMBER($E$5),L21-$E$5<=7),"Vence em 7 dias","Em dia"))))) | N21: =IF(OR(C21="",$E$4="",$E$5=""),"",COUNTIFS(Manutenções!$D$7:$D$86,C21,Manutenções!$F$7:$F$86,"Corretiva",Manutenções!$C$7:$C$86,">="&$E$4,Manutenções!$C$7:$C$86,"<="&$E$5)) | O21: =IF(OR(C21="",$E$4="",$E$5=""),"",SUMIFS(Manutenções!$G$7:$G$86,Manutenções!$D$7:$D$86,C21,Manutenções!$F$7:$F$86,"Corretiva",Manutenções!$C$7:$C$86,">="&$E$4,Manutenções!$C$7:$C$86,"<="&$E$5)) | P21: =IF(OR(N(K21)=0,O21=""),"",(K21-O21)/K21) | Q21: =IF(C21="","",IF(E21="","Falta o tipo",IF(G21="","Falta a criticidade",IF(AND(OR(G21="Alta",G21="Média"),H21=""),"Sem plano de preventiva",IF(M21="Atrasada","Preventiva atrasada",IF(AND(G21="Alta",J21=""),"Crítico sem contingência",IF(AND(ISNUMBER(P21),ISNUMBER($E$6)),IF(P21<$E$6-0.000000001,"Disponibilidade abaixo da meta","OK"),"OK")))))))
... B49: 40 | L49: =IF(OR(I49="",H49=""),"",EDATE(I49,H49)) | M49: =IF(C49="","",IF(H49="","Sem plano",IF(I49="","Atrasada",IF(AND(ISNUMBER($E$5),L49<$E$5),"Atrasada",IF(AND(ISNUMBER($E$5),L49-$E$5<=7),"Vence em 7 dias","Em dia"))))) | N49: =IF(OR(C49="",$E$4="",$E$5=""),"",COUNTIFS(Manutenções!$D$7:$D$86,C49,Manutenções!$F$7:$F$86,"Corretiva",Manutenções!$C$7:$C$86,">="&$E$4,Manutenções!$C$7:$C$86,"<="&$E$5)) | O49: =IF(OR(C49="",$E$4="",$E$5=""),"",SUMIFS(Manutenções!$G$7:$G$86,Manutenções!$D$7:$D$86,C49,Manutenções!$F$7:$F$86,"Corretiva",Manutenções!$C$7:$C$86,">="&$E$4,Manutenções!$C$7:$C$86,"<="&$E$5)) | P49: =IF(OR(N(K49)=0,O49=""),"",(K49-O49)/K49) | Q49: =IF(C49="","",IF(E49="","Falta o tipo",IF(G49="","Falta a criticidade",IF(AND(OR(G49="Alta",G49="Média"),H49=""),"Sem plano de preventiva",IF(M49="Atrasada","Preventiva atrasada",IF(AND(G49="Alta",J49=""),"Crítico sem contingência",IF(AND(ISNUMBER(P49),ISNUMBER($E$6)),IF(P49<$E$6-0.000000001,"Disponibilidade abaixo da meta","OK"),"OK")))))))
B51: Resumo automático
B52: Itens cadastrados | E52: =COUNTA(C10:C49)&" itens, "&COUNTIF(G10:G49,"Alta")&" críticos" -> 0 itens, 0 críticos
B53: Preventivas | E53: =COUNTIF(M10:M49,"Em dia")&" em dia"&", "&COUNTIF(M10:M49,"Vence em 7 dias")&" vence em 7 dias"&", "&COUNTIF(M10:M49,"Atrasada")&" atrasada"&", "&COUNTIF(M10:M49,"Sem plano")&" sem plano" -> 0 em dia, 0 vence em 7 dias, 0 atrasada, 0 sem plano
B54: Quebras no período | E54: =SUM(N10:N49)&" corretivas, "&SUM(O10:O49)&" horas paradas" -> 0 corretivas, 0 horas paradas
B55: Aviso | E55: =IF(COUNTA(C10:C49)=0,"Cadastre os itens",IF(OR(E4="",E5=""),"Informe o início e o fim do período",IF(COUNTIF(M10:M49,"Atrasada")>0,"Há preventiva atrasada",IF(SUMPRODUCT((G10:G49="Alta")*(J10:J49=""))>0,"Há item crítico sem contingência",IF(AND(ISNUMBER(E6),COUNTIF(P10:P49,"<"&(E6-0.000000001))>0),"Há item abaixo da meta de disponibilidade",IF(SUMPRODUCT((Q10:Q49<>"")*(Q10:Q49<>"OK"))>0,"Há item a completar: veja a coluna Conferência",IF(COUNTIF(M10:M49,"Vence em 7 dias")>0,"Há preventiva que vence em 7 dias: confirme","OK"))))))) -> Cadastre os itens

Sheet Manutenções
B1: Manutenções
B2: Uma preventiva ou uma corretiva por linha. As corretivas alimentam as quebras e a disponibilidade da aba Infraestrutura.
B4: # | C4: Data | D4: Código | E4: Item | F4: Tipo | G4: Horas paradas | H4: O que aconteceu | I4: Causa | J4: Ação | K4: Afetou o produto? | L4: Tratamento do produto | M4: Conferência
C5: Data | D5: Lista | E5: Vem do cadastro | F5: Lista | G5: Número | I5: Na corretiva | J5: Na corretiva | K5: Lista | L5: Se afetou | M5: Calculada
B6: Ex. | C6: 46496 | D6: MOT-02 | E6: Moto de entrega 2 | F6: Corretiva | G6: 12 | H6: Corrente partiu na entrega | I6: Corrente gasta | J6: Corrente trocada | K6: Sim | L6: Desconto ao cliente | M6: OK
B7: 1 | E7: =IF(D7="","",IFERROR(INDEX(Infraestrutura!$D$10:$D$49,MATCH(D7,Infraestrutura!$C$10:$C$49,0))&"","")) | M7: =IF(D7="",IF(COUNTA(C7,F7:L7)>0,"Falta o item",""),IF(ISNA(MATCH(D7,Infraestrutura!$C$10:$C$49,0)),"Item não cadastrado",IF(C7="","Falta a data",IF(F7="","Falta o tipo",IF(G7="","Falta o tempo parado",IF(F7="Corretiva",IF(I7="","Falta a causa",IF(J7="","Falta a ação",IF(K7="","Falta dizer se afetou o produto",IF(AND(K7="Sim",L7=""),"Produto afetado sem tratamento","OK")))),"OK"))))))
B8: 2 | E8: =IF(D8="","",IFERROR(INDEX(Infraestrutura!$D$10:$D$49,MATCH(D8,Infraestrutura!$C$10:$C$49,0))&"","")) | M8: =IF(D8="",IF(COUNTA(C8,F8:L8)>0,"Falta o item",""),IF(ISNA(MATCH(D8,Infraestrutura!$C$10:$C$49,0)),"Item não cadastrado",IF(C8="","Falta a data",IF(F8="","Falta o tipo",IF(G8="","Falta o tempo parado",IF(F8="Corretiva",IF(I8="","Falta a causa",IF(J8="","Falta a ação",IF(K8="","Falta dizer se afetou o produto",IF(AND(K8="Sim",L8=""),"Produto afetado sem tratamento","OK")))),"OK"))))))
B9: 3 | E9: =IF(D9="","",IFERROR(INDEX(Infraestrutura!$D$10:$D$49,MATCH(D9,Infraestrutura!$C$10:$C$49,0))&"","")) | M9: =IF(D9="",IF(COUNTA(C9,F9:L9)>0,"Falta o item",""),IF(ISNA(MATCH(D9,Infraestrutura!$C$10:$C$49,0)),"Item não cadastrado",IF(C9="","Falta a data",IF(F9="","Falta o tipo",IF(G9="","Falta o tempo parado",IF(F9="Corretiva",IF(I9="","Falta a causa",IF(J9="","Falta a ação",IF(K9="","Falta dizer se afetou o produto",IF(AND(K9="Sim",L9=""),"Produto afetado sem tratamento","OK")))),"OK"))))))
B10: 4 | E10: =IF(D10="","",IFERROR(INDEX(Infraestrutura!$D$10:$D$49,MATCH(D10,Infraestrutura!$C$10:$C$49,0))&"","")) | M10: =IF(D10="",IF(COUNTA(C10,F10:L10)>0,"Falta o item",""),IF(ISNA(MATCH(D10,Infraestrutura!$C$10:$C$49,0)),"Item não cadastrado",IF(C10="","Falta a data",IF(F10="","Falta o tipo",IF(G10="","Falta o tempo parado",IF(F10="Corretiva",IF(I10="","Falta a causa",IF(J10="","Falta a ação",IF(K10="","Falta dizer se afetou o produto",IF(AND(K10="Sim",L10=""),"Produto afetado sem tratamento","OK")))),"OK"))))))
B11: 5 | E11: =IF(D11="","",IFERROR(INDEX(Infraestrutura!$D$10:$D$49,MATCH(D11,Infraestrutura!$C$10:$C$49,0))&"","")) | M11: =IF(D11="",IF(COUNTA(C11,F11:L11)>0,"Falta o item",""),IF(ISNA(MATCH(D11,Infraestrutura!$C$10:$C$49,0)),"Item não cadastrado",IF(C11="","Falta a data",IF(F11="","Falta o tipo",IF(G11="","Falta o tempo parado",IF(F11="Corretiva",IF(I11="","Falta a causa",IF(J11="","Falta a ação",IF(K11="","Falta dizer se afetou o produto",IF(AND(K11="Sim",L11=""),"Produto afetado sem tratamento","OK")))),"OK"))))))
B12: 6 | E12: =IF(D12="","",IFERROR(INDEX(Infraestrutura!$D$10:$D$49,MATCH(D12,Infraestrutura!$C$10:$C$49,0))&"","")) | M12: =IF(D12="",IF(COUNTA(C12,F12:L12)>0,"Falta o item",""),IF(ISNA(MATCH(D12,Infraestrutura!$C$10:$C$49,0)),"Item não cadastrado",IF(C12="","Falta a data",IF(F12="","Falta o tipo",IF(G12="","Falta o tempo parado",IF(F12="Corretiva",IF(I12="","Falta a causa",IF(J12="","Falta a ação",IF(K12="","Falta dizer se afetou o produto",IF(AND(K12="Sim",L12=""),"Produto afetado sem tratamento","OK")))),"OK"))))))
B13: 7 | E13: =IF(D13="","",IFERROR(INDEX(Infraestrutura!$D$10:$D$49,MATCH(D13,Infraestrutura!$C$10:$C$49,0))&"","")) | M13: =IF(D13="",IF(COUNTA(C13,F13:L13)>0,"Falta o item",""),IF(ISNA(MATCH(D13,Infraestrutura!$C$10:$C$49,0)),"Item não cadastrado",IF(C13="","Falta a data",IF(F13="","Falta o tipo",IF(G13="","Falta o tempo parado",IF(F13="Corretiva",IF(I13="","Falta a causa",IF(J13="","Falta a ação",IF(K13="","Falta dizer se afetou o produto",IF(AND(K13="Sim",L13=""),"Produto afetado sem tratamento","OK")))),"OK"))))))
B14: 8 | E14: =IF(D14="","",IFERROR(INDEX(Infraestrutura!$D$10:$D$49,MATCH(D14,Infraestrutura!$C$10:$C$49,0))&"","")) | M14: =IF(D14="",IF(COUNTA(C14,F14:L14)>0,"Falta o item",""),IF(ISNA(MATCH(D14,Infraestrutura!$C$10:$C$49,0)),"Item não cadastrado",IF(C14="","Falta a data",IF(F14="","Falta o tipo",IF(G14="","Falta o tempo parado",IF(F14="Corretiva",IF(I14="","Falta a causa",IF(J14="","Falta a ação",IF(K14="","Falta dizer se afetou o produto",IF(AND(K14="Sim",L14=""),"Produto afetado sem tratamento","OK")))),"OK"))))))
B15: 9 | E15: =IF(D15="","",IFERROR(INDEX(Infraestrutura!$D$10:$D$49,MATCH(D15,Infraestrutura!$C$10:$C$49,0))&"","")) | M15: =IF(D15="",IF(COUNTA(C15,F15:L15)>0,"Falta o item",""),IF(ISNA(MATCH(D15,Infraestrutura!$C$10:$C$49,0)),"Item não cadastrado",IF(C15="","Falta a data",IF(F15="","Falta o tipo",IF(G15="","Falta o tempo parado",IF(F15="Corretiva",IF(I15="","Falta a causa",IF(J15="","Falta a ação",IF(K15="","Falta dizer se afetou o produto",IF(AND(K15="Sim",L15=""),"Produto afetado sem tratamento","OK")))),"OK"))))))
B16: 10 | E16: =IF(D16="","",IFERROR(INDEX(Infraestrutura!$D$10:$D$49,MATCH(D16,Infraestrutura!$C$10:$C$49,0))&"","")) | M16: =IF(D16="",IF(COUNTA(C16,F16:L16)>0,"Falta o item",""),IF(ISNA(MATCH(D16,Infraestrutura!$C$10:$C$49,0)),"Item não cadastrado",IF(C16="","Falta a data",IF(F16="","Falta o tipo",IF(G16="","Falta o tempo parado",IF(F16="Corretiva",IF(I16="","Falta a causa",IF(J16="","Falta a ação",IF(K16="","Falta dizer se afetou o produto",IF(AND(K16="Sim",L16=""),"Produto afetado sem tratamento","OK")))),"OK"))))))
B17: 11 | E17: =IF(D17="","",IFERROR(INDEX(Infraestrutura!$D$10:$D$49,MATCH(D17,Infraestrutura!$C$10:$C$49,0))&"","")) | M17: =IF(D17="",IF(COUNTA(C17,F17:L17)>0,"Falta o item",""),IF(ISNA(MATCH(D17,Infraestrutura!$C$10:$C$49,0)),"Item não cadastrado",IF(C17="","Falta a data",IF(F17="","Falta o tipo",IF(G17="","Falta o tempo parado",IF(F17="Corretiva",IF(I17="","Falta a causa",IF(J17="","Falta a ação",IF(K17="","Falta dizer se afetou o produto",IF(AND(K17="Sim",L17=""),"Produto afetado sem tratamento","OK")))),"OK"))))))
B18: 12 | E18: =IF(D18="","",IFERROR(INDEX(Infraestrutura!$D$10:$D$49,MATCH(D18,Infraestrutura!$C$10:$C$49,0))&"","")) | M18: =IF(D18="",IF(COUNTA(C18,F18:L18)>0,"Falta o item",""),IF(ISNA(MATCH(D18,Infraestrutura!$C$10:$C$49,0)),"Item não cadastrado",IF(C18="","Falta a data",IF(F18="","Falta o tipo",IF(G18="","Falta o tempo parado",IF(F18="Corretiva",IF(I18="","Falta a causa",IF(J18="","Falta a ação",IF(K18="","Falta dizer se afetou o produto",IF(AND(K18="Sim",L18=""),"Produto afetado sem tratamento","OK")))),"OK"))))))
... B86: 80 | E86: =IF(D86="","",IFERROR(INDEX(Infraestrutura!$D$10:$D$49,MATCH(D86,Infraestrutura!$C$10:$C$49,0))&"","")) | M86: =IF(D86="",IF(COUNTA(C86,F86:L86)>0,"Falta o item",""),IF(ISNA(MATCH(D86,Infraestrutura!$C$10:$C$49,0)),"Item não cadastrado",IF(C86="","Falta a data",IF(F86="","Falta o tipo",IF(G86="","Falta o tempo parado",IF(F86="Corretiva",IF(I86="","Falta a causa",IF(J86="","Falta a ação",IF(K86="","Falta dizer se afetou o produto",IF(AND(K86="Sim",L86=""),"Produto afetado sem tratamento","OK")))),"OK"))))))
B88: Resumo automático
B89: Registros | E89: =COUNTA(D7:D86) -> 0
B90: Por tipo | E90: =COUNTIF(F7:F86,"Corretiva")&" corretivas, "&COUNTIF(F7:F86,"Preventiva")&" preventivas, "&SUMIF(F7:F86,"Corretiva",G7:G86)&" horas paradas nas corretivas" -> 0 corretivas, 0 preventivas, 0 horas paradas nas corretivas
B91: Aviso | E91: =IF(E89=0,"Lance as manutenções",IF(COUNTIF(M7:M86,"Produto afetado sem tratamento")>0,"Há produto afetado sem tratamento",IF(SUMPRODUCT((M7:M86<>"")*(M7:M86<>"OK"))>0,"Há registro a completar: veja a coluna Conferência","OK"))) -> Lance as manutenções

Sheet Ambiente
B1: Ambiente dos processos
B2: Um fator por linha: por que afeta o produto, o limite, como é controlado e a última medição.
B4: # | C4: Fator | D4: Tipo | E4: Local | F4: Por que afeta o produto | G4: Unidade | H4: Mínimo | I4: Máximo | J4: Como é controlado | K4: Última medição | L4: Ação, se fora | M4: Situação | N4: Conferência
D5: Lista | F5: Numa frase | G5: °C, %, lux | H5: Número | I5: Número | J5: Como, quem, quando | K5: Número | M5: Calculada | N5: Calculada
B6: Ex. | C6: Temperatura da cozinha | D6: Físico | E6: Cozinha | F6: Acima de 32 °C, a massa passa do ponto | G6: °C | I6: 32 | J6: Termômetro de parede, às 21h | K6: 34 | L6: Segundo ventilador | M6: Fora | N6: OK
B7: 1 | M7: =IF(C7="","",IF(K7="","Sem medição",IF(OR(AND(H7<>"",K7<H7),AND(I7<>"",K7>I7)),"Fora","Dentro"))) | N7: =IF(C7="","",IF(F7="","Falta por que afeta o produto",IF(J7="","Falta como é controlado",IF(AND(H7="",I7=""),"Falta o limite",IF(M7="Sem medição","Falta a medição",IF(AND(M7="Fora",L7=""),"Fora do limite: falta a ação","OK"))))))
B8: 2 | M8: =IF(C8="","",IF(K8="","Sem medição",IF(OR(AND(H8<>"",K8<H8),AND(I8<>"",K8>I8)),"Fora","Dentro"))) | N8: =IF(C8="","",IF(F8="","Falta por que afeta o produto",IF(J8="","Falta como é controlado",IF(AND(H8="",I8=""),"Falta o limite",IF(M8="Sem medição","Falta a medição",IF(AND(M8="Fora",L8=""),"Fora do limite: falta a ação","OK"))))))
B9: 3 | M9: =IF(C9="","",IF(K9="","Sem medição",IF(OR(AND(H9<>"",K9<H9),AND(I9<>"",K9>I9)),"Fora","Dentro"))) | N9: =IF(C9="","",IF(F9="","Falta por que afeta o produto",IF(J9="","Falta como é controlado",IF(AND(H9="",I9=""),"Falta o limite",IF(M9="Sem medição","Falta a medição",IF(AND(M9="Fora",L9=""),"Fora do limite: falta a ação","OK"))))))
B10: 4 | M10: =IF(C10="","",IF(K10="","Sem medição",IF(OR(AND(H10<>"",K10<H10),AND(I10<>"",K10>I10)),"Fora","Dentro"))) | N10: =IF(C10="","",IF(F10="","Falta por que afeta o produto",IF(J10="","Falta como é controlado",IF(AND(H10="",I10=""),"Falta o limite",IF(M10="Sem medição","Falta a medição",IF(AND(M10="Fora",L10=""),"Fora do limite: falta a ação","OK"))))))
B11: 5 | M11: =IF(C11="","",IF(K11="","Sem medição",IF(OR(AND(H11<>"",K11<H11),AND(I11<>"",K11>I11)),"Fora","Dentro"))) | N11: =IF(C11="","",IF(F11="","Falta por que afeta o produto",IF(J11="","Falta como é controlado",IF(AND(H11="",I11=""),"Falta o limite",IF(M11="Sem medição","Falta a medição",IF(AND(M11="Fora",L11=""),"Fora do limite: falta a ação","OK"))))))
B12: 6 | M12: =IF(C12="","",IF(K12="","Sem medição",IF(OR(AND(H12<>"",K12<H12),AND(I12<>"",K12>I12)),"Fora","Dentro"))) | N12: =IF(C12="","",IF(F12="","Falta por que afeta o produto",IF(J12="","Falta como é controlado",IF(AND(H12="",I12=""),"Falta o limite",IF(M12="Sem medição","Falta a medição",IF(AND(M12="Fora",L12=""),"Fora do limite: falta a ação","OK"))))))
B13: 7 | M13: =IF(C13="","",IF(K13="","Sem medição",IF(OR(AND(H13<>"",K13<H13),AND(I13<>"",K13>I13)),"Fora","Dentro"))) | N13: =IF(C13="","",IF(F13="","Falta por que afeta o produto",IF(J13="","Falta como é controlado",IF(AND(H13="",I13=""),"Falta o limite",IF(M13="Sem medição","Falta a medição",IF(AND(M13="Fora",L13=""),"Fora do limite: falta a ação","OK"))))))
B14: 8 | M14: =IF(C14="","",IF(K14="","Sem medição",IF(OR(AND(H14<>"",K14<H14),AND(I14<>"",K14>I14)),"Fora","Dentro"))) | N14: =IF(C14="","",IF(F14="","Falta por que afeta o produto",IF(J14="","Falta como é controlado",IF(AND(H14="",I14=""),"Falta o limite",IF(M14="Sem medição","Falta a medição",IF(AND(M14="Fora",L14=""),"Fora do limite: falta a ação","OK"))))))
B15: 9 | M15: =IF(C15="","",IF(K15="","Sem medição",IF(OR(AND(H15<>"",K15<H15),AND(I15<>"",K15>I15)),"Fora","Dentro"))) | N15: =IF(C15="","",IF(F15="","Falta por que afeta o produto",IF(J15="","Falta como é controlado",IF(AND(H15="",I15=""),"Falta o limite",IF(M15="Sem medição","Falta a medição",IF(AND(M15="Fora",L15=""),"Fora do limite: falta a ação","OK"))))))
B16: 10 | M16: =IF(C16="","",IF(K16="","Sem medição",IF(OR(AND(H16<>"",K16<H16),AND(I16<>"",K16>I16)),"Fora","Dentro"))) | N16: =IF(C16="","",IF(F16="","Falta por que afeta o produto",IF(J16="","Falta como é controlado",IF(AND(H16="",I16=""),"Falta o limite",IF(M16="Sem medição","Falta a medição",IF(AND(M16="Fora",L16=""),"Fora do limite: falta a ação","OK"))))))
B17: 11 | M17: =IF(C17="","",IF(K17="","Sem medição",IF(OR(AND(H17<>"",K17<H17),AND(I17<>"",K17>I17)),"Fora","Dentro"))) | N17: =IF(C17="","",IF(F17="","Falta por que afeta o produto",IF(J17="","Falta como é controlado",IF(AND(H17="",I17=""),"Falta o limite",IF(M17="Sem medição","Falta a medição",IF(AND(M17="Fora",L17=""),"Fora do limite: falta a ação","OK"))))))
B18: 12 | M18: =IF(C18="","",IF(K18="","Sem medição",IF(OR(AND(H18<>"",K18<H18),AND(I18<>"",K18>I18)),"Fora","Dentro"))) | N18: =IF(C18="","",IF(F18="","Falta por que afeta o produto",IF(J18="","Falta como é controlado",IF(AND(H18="",I18=""),"Falta o limite",IF(M18="Sem medição","Falta a medição",IF(AND(M18="Fora",L18=""),"Fora do limite: falta a ação","OK"))))))
... B36: 30 | M36: =IF(C36="","",IF(K36="","Sem medição",IF(OR(AND(H36<>"",K36<H36),AND(I36<>"",K36>I36)),"Fora","Dentro"))) | N36: =IF(C36="","",IF(F36="","Falta por que afeta o produto",IF(J36="","Falta como é controlado",IF(AND(H36="",I36=""),"Falta o limite",IF(M36="Sem medição","Falta a medição",IF(AND(M36="Fora",L36=""),"Fora do limite: falta a ação","OK"))))))
B38: Resumo automático
B39: Fatores | E39: =COUNTA(C7:C36)&" fatores: "&COUNTIF(D7:D36,"Físico")&" físicos, "&COUNTIF(D7:D36,"Social")&" sociais, "&COUNTIF(D7:D36,"Psicológico")&" psicológicos" -> 0 fatores: 0 físicos, 0 sociais, 0 psicológicos
B40: Situação | E40: =COUNTIF(M7:M36,"Dentro")&" dentro"&", "&COUNTIF(M7:M36,"Fora")&" fora"&", "&COUNTIF(M7:M36,"Sem medição")&" sem medição" -> 0 dentro, 0 fora, 0 sem medição
B41: Aviso | E41: =IF(COUNTA(C7:C36)=0,"Liste os fatores do ambiente",IF(COUNTIF(N7:N36,"Fora do limite: falta a ação")>0,"Há fator fora do limite sem ação",IF(SUMPRODUCT((N7:N36<>"")*(N7:N36<>"OK"))>0,"Há fator a completar: veja a coluna Conferência",IF(COUNTIF(M7:M36,"Fora")>0,"Há fator fora do limite, com ação: acompanhe","OK")))) -> Liste os fatores do ambiente

Sheet Painel
B1: Painel dos recursos
B2: Nada a preencher: tudo vem das outras abas.
B3: Período: início e fim | C3: =IF(Infraestrutura!$E$4="","",Infraestrutura!$E$4) | D3: =IF(Infraestrutura!$E$5="","",Infraestrutura!$E$5)
B5: Indicador | C5: Resultado | D5: Como se lê
B6: PESSOAS
B7: Funções e períodos | C7: =COUNTA(Pessoas!C7:C36) -> 0 | D7: Da aba Pessoas.
B8: Com falta de gente | C8: =COUNTIF(Pessoas!L7:L36,"Falta gente") -> 0 | D8: As escaladas não cobrem o pico.
B9: Pessoas a menos no pico | C9: =-SUMIF(Pessoas!K7:K36,"<0") -> 0 | D9: A soma das faltas.
B10: Sem pessoa qualificada | C10: =COUNTIF(Pessoas!M7:M36,"Sem pessoa qualificada na escala") -> 0 | D10: Ninguém na escala sabe fazer sozinho.
B11: INFRAESTRUTURA
B12: Itens cadastrados | C12: =COUNTA(Infraestrutura!C10:C49) -> 0 | D12: Da aba Infraestrutura.
B13: Itens críticos | C13: =COUNTIF(Infraestrutura!G10:G49,"Alta") -> 0 | D13: Criticidade alta.
B14: Atrasada | C14: =COUNTIF(Infraestrutura!M10:M49,"Atrasada") -> 0 | D14: Preventivas atrasadas: fazer antes de tudo.
B15: Vence em 7 dias | C15: =COUNTIF(Infraestrutura!M10:M49,"Vence em 7 dias") -> 0 | D15: Confirmar a data, as peças e quem faz.
B16: Críticos sem contingência | C16: =SUMPRODUCT((Infraestrutura!G10:G49="Alta")*(Infraestrutura!J10:J49="")) -> 0 | D16: Ninguém sabe o que fazer se parar.
B17: Abaixo da meta de disponibilidade | C17: =IF(ISNUMBER(Infraestrutura!$E$6),COUNTIF(Infraestrutura!P10:P49,"<"&(Infraestrutura!$E$6-0.000000001)),0) -> 0 | D17: Ler as causas das quebras.
B18: Quebras no período | C18: =SUM(Infraestrutura!N10:N49) -> 0 | D18: Só as corretivas dentro do período.
B19: Horas paradas no período | C19: =SUM(Infraestrutura!O10:O49) -> 0 | D19: Nas corretivas.
B20: MANUTENÇÕES E AMBIENTE
B21: Corretivas com produto afetado | C21: =IF(OR(Infraestrutura!$E$4="",Infraestrutura!$E$5=""),0,COUNTIFS(Manutenções!F7:F86,"Corretiva",Manutenções!K7:K86,"Sim",Manutenções!C7:C86,">="&Infraestrutura!$E$4,Manutenções!C7:C86,"<="&Infraestrutura!$E$5)) -> 0 | D21: No período.
B22: Produto afetado sem tratamento | C22: =COUNTIF(Manutenções!M7:M86,"Produto afetado sem tratamento") -> 0 | D22: Tratar como não conforme.
B23: Fatores do ambiente fora do limite | C23: =COUNTIF(Ambiente!M7:M36,"Fora") -> 0 | D23: Com ou sem ação.
B24: Fora do limite sem ação | C24: =COUNTIF(Ambiente!N7:N36,"Fora do limite: falta a ação") -> 0 | D24: Ninguém decidiu nada.
B25: Fatores sem medição | C25: =COUNTIF(Ambiente!M7:M36,"Sem medição") -> 0 | D25: Limite sem medição não controla.
B26: Linhas a completar | C26: =SUMPRODUCT((Pessoas!M7:M36<>"")*(Pessoas!M7:M36<>"OK"))+SUMPRODUCT((Infraestrutura!Q10:Q49<>"")*(Infraestrutura!Q10:Q49<>"OK"))+SUMPRODUCT((Manutenções!M7:M86<>"")*(Manutenções!M7:M86<>"OK"))+SUMPRODUCT((Ambiente!N7:N36<>"")*(Ambiente!N7:N36<>"OK")) -> 0 | D26: Conferências diferentes de OK nas quatro abas.
B28: Resumo automático
B29: Aviso | C29: =IF(C7+C12+COUNTA(Ambiente!C7:C36)=0,"Preencha as abas Pessoas, Infraestrutura e Ambiente",IF(C22>0,"Há produto afetado sem tratamento",IF(C8>0,"Há função com falta de gente no pico",IF(C14>0,"Há preventiva atrasada",IF(C16>0,"Há item crítico sem contingência",IF(C24>0,"Há fator do ambiente fora do limite sem ação",IF(C17>0,"Há item abaixo da meta de disponibilidade",IF(C10>0,"Há função sem pessoa qualificada na escala",IF(C26>0,"Há linha a completar: veja as conferências","OK"))))))))) -> Preencha as abas Pessoas, Infraestrutura e Ambiente
B30: Preventivas por situação
B31: Em dia | C31: =COUNTIF(Infraestrutura!M10:M49,B31) -> 0
B32: Vence em 7 dias | C32: =COUNTIF(Infraestrutura!M10:M49,B32) -> 0
B33: Atrasada | C33: =COUNTIF(Infraestrutura!M10:M49,B33) -> 0
B34: Sem plano | C34: =COUNTIF(Infraestrutura!M10:M49,B34) -> 0

Sheet Checklist
B1: Checklist dos recursos, da infraestrutura e do ambiente
B2: Escolha o status de cada item na lista suspensa (coluna em amarelo-claro).
B4: # | C4: Item de verificação | D4: Status | E4: Observações
B5: 1 | C5: As pessoas de cada processo estão dimensionadas pela demanda do pico, e não pelo costume.
B6: 2 | C6: Cada função e turno tem ao menos uma pessoa qualificada na escala.
B7: 3 | C7: Há um plano para as ausências: férias, faltas e afastamentos.
B8: 4 | C8: A infraestrutura que afeta o produto está listada, com a criticidade de cada item.
B9: 5 | C9: Cada item crítico tem manutenção preventiva com intervalo, feita no prazo.
B10: 6 | C10: Cada item crítico tem uma contingência escrita para quando parar.
B11: 7 | C11: As paradas são registradas com o tempo parado, a causa e a ação.
B12: 8 | C12: A disponibilidade dos itens críticos é acompanhada contra uma meta.
B13: 9 | C13: Quando uma parada afeta o produto, ele é avaliado e tratado como não conforme.
B14: 10 | C14: Os sistemas de informação têm cópia de segurança, e a restauração é testada.
B15: 11 | C15: Os fatores do ambiente que afetam o produto estão definidos, físicos, sociais e psicológicos, com limite e controle.
B16: 12 | C16: O ambiente é medido, e o que está fora do limite tem ação.
B18: Resumo automático
B19: Itens atendidos (Sim) | D19: =COUNTIF(D5:D16,"Sim") -> 0
B20: Itens parciais | D20: =COUNTIF(D5:D16,"Parcial") -> 0
B21: Itens não atendidos | D21: =COUNTIF(D5:D16,"Não") -> 0
B22: Itens sem resposta | D22: =COUNTBLANK(D5:D16) -> 12
B23: Percentual atendido | D23: =D19/ROWS(D5:D16) -> 0
B24: Situação | D24: =IF(D19=ROWS(D5:D16),"Validado",IF(D22>0,"Em andamento","Com pendências")) -> Em andamento

Sheet Exemplo 1 - Pizzaria
B1: Recursos, infraestrutura e ambiente
B2: Exemplo preenchido, para consulta. Use as abas de entrada para a sua organização.
B4: Organização | D4: Pizzaria (loja com salão e delivery)
B5: Responsável | D5: Gerente da loja, com o pizzaiolo líder
B6: Horas programadas | D6: Loja aberta das 18h à meia-noite: 180 horas no mês. Câmara fria e sistema ligados o tempo todo.
B7: Origem | D7: Requisitos 7.1.1, 7.1.3 e 7.1.4 atendidos no diagnóstico de 2026, mas a escala de pico era feita de cabeça, e a quebra da câmara fria em abril mostrou que não havia plano para ela parar.
B8: Início do período | D8: 46478
B9: Fim do período | D9: 46507
B10: Meta de disponibilidade | D10: 0.97
B12: Pessoas no pico
B13: Função | D13: Período | E13: Unidade | F13: Demanda | G13: Produtiv. | H13: Necessárias | I13: Escaladas | J13: Qualificadas | K13: Folga | L13: Situação | M13: Conferência
B14: Atendimento | D14: Sexta, 19h às 23h | E14: pedidos por hora | F14: 40 | G14: 20 | H14: =IF(OR(N(F14)=0,N(G14)=0),"",ROUNDUP(F14/G14,0)) -> 2 | I14: 2 | J14: 2 | K14: =IF(OR(H14="",I14=""),"",I14-H14) -> 0 | L14: =IF(K14="","",IF(K14<0,"Falta gente",IF(K14=0,"Justo","Com folga"))) -> Justo | M14: =IF(B14="","",IF(N(F14)=0,"Falta a demanda",IF(N(G14)=0,"Falta a produtividade",IF(I14="","Falta o número escalado",IF(J14="","Falta o número de qualificados",IF(J14>I14,"Mais qualificados que escalados",IF(K14<0,IF(K14=-1,"Falta 1 pessoa","Faltam "&-K14&" pessoas"),IF(J14=0,"Sem pessoa qualificada na escala","OK")))))))) -> OK
B15: Atendimento | D15: Sábado, 19h às 23h | E15: pedidos por hora | F15: 36 | G15: 20 | H15: =IF(OR(N(F15)=0,N(G15)=0),"",ROUNDUP(F15/G15,0)) -> 2 | I15: 2 | J15: 0 | K15: =IF(OR(H15="",I15=""),"",I15-H15) -> 0 | L15: =IF(K15="","",IF(K15<0,"Falta gente",IF(K15=0,"Justo","Com folga"))) -> Justo | M15: =IF(B15="","",IF(N(F15)=0,"Falta a demanda",IF(N(G15)=0,"Falta a produtividade",IF(I15="","Falta o número escalado",IF(J15="","Falta o número de qualificados",IF(J15>I15,"Mais qualificados que escalados",IF(K15<0,IF(K15=-1,"Falta 1 pessoa","Faltam "&-K15&" pessoas"),IF(J15=0,"Sem pessoa qualificada na escala","OK")))))))) -> Sem pessoa qualificada na escala
B16: Pizzaiolo | D16: Sexta, 20h às 22h | E16: pizzas por hora | F16: 60 | G16: 20 | H16: =IF(OR(N(F16)=0,N(G16)=0),"",ROUNDUP(F16/G16,0)) -> 3 | I16: 3 | J16: 2 | K16: =IF(OR(H16="",I16=""),"",I16-H16) -> 0 | L16: =IF(K16="","",IF(K16<0,"Falta gente",IF(K16=0,"Justo","Com folga"))) -> Justo | M16: =IF(B16="","",IF(N(F16)=0,"Falta a demanda",IF(N(G16)=0,"Falta a produtividade",IF(I16="","Falta o número escalado",IF(J16="","Falta o número de qualificados",IF(J16>I16,"Mais qualificados que escalados",IF(K16<0,IF(K16=-1,"Falta 1 pessoa","Faltam "&-K16&" pessoas"),IF(J16=0,"Sem pessoa qualificada na escala","OK")))))))) -> OK
B17: Forneiro | D17: Sexta, 20h às 22h | E17: pizzas por hora | F17: 60 | G17: 40 | H17: =IF(OR(N(F17)=0,N(G17)=0),"",ROUNDUP(F17/G17,0)) -> 2 | I17: 1 | J17: 1 | K17: =IF(OR(H17="",I17=""),"",I17-H17) -> -1 | L17: =IF(K17="","",IF(K17<0,"Falta gente",IF(K17=0,"Justo","Com folga"))) -> Falta gente | M17: =IF(B17="","",IF(N(F17)=0,"Falta a demanda",IF(N(G17)=0,"Falta a produtividade",IF(I17="","Falta o número escalado",IF(J17="","Falta o número de qualificados",IF(J17>I17,"Mais qualificados que escalados",IF(K17<0,IF(K17=-1,"Falta 1 pessoa","Faltam "&-K17&" pessoas"),IF(J17=0,"Sem pessoa qualificada na escala","OK")))))))) -> Falta 1 pessoa
B18: Expedição | D18: Sexta, 20h às 22h | E18: pedidos por hora | F18: 40 | G18: 30 | H18: =IF(OR(N(F18)=0,N(G18)=0),"",ROUNDUP(F18/G18,0)) -> 2 | I18: 2 | J18: 1 | K18: =IF(OR(H18="",I18=""),"",I18-H18) -> 0 | L18: =IF(K18="","",IF(K18<0,"Falta gente",IF(K18=0,"Justo","Com folga"))) -> Justo | M18: =IF(B18="","",IF(N(F18)=0,"Falta a demanda",IF(N(G18)=0,"Falta a produtividade",IF(I18="","Falta o número escalado",IF(J18="","Falta o número de qualificados",IF(J18>I18,"Mais qualificados que escalados",IF(K18<0,IF(K18=-1,"Falta 1 pessoa","Faltam "&-K18&" pessoas"),IF(J18=0,"Sem pessoa qualificada na escala","OK")))))))) -> OK
B19: Entregador | D19: Sexta, 20h às 22h | E19: entregas por hora | F19: 29 | G19: 3 | H19: =IF(OR(N(F19)=0,N(G19)=0),"",ROUNDUP(F19/G19,0)) -> 10 | I19: 8 | J19: 8 | K19: =IF(OR(H19="",I19=""),"",I19-H19) -> -2 | L19: =IF(K19="","",IF(K19<0,"Falta gente",IF(K19=0,"Justo","Com folga"))) -> Falta gente | M19: =IF(B19="","",IF(N(F19)=0,"Falta a demanda",IF(N(G19)=0,"Falta a produtividade",IF(I19="","Falta o número escalado",IF(J19="","Falta o número de qualificados",IF(J19>I19,"Mais qualificados que escalados",IF(K19<0,IF(K19=-1,"Falta 1 pessoa","Faltam "&-K19&" pessoas"),IF(J19=0,"Sem pessoa qualificada na escala","OK")))))))) -> Faltam 2 pessoas
B20: Entregador | D20: Terça, 19h às 22h | E20: entregas por hora | F20: 10 | G20: 3 | H20: =IF(OR(N(F20)=0,N(G20)=0),"",ROUNDUP(F20/G20,0)) -> 4 | I20: 4 | J20: 4 | K20: =IF(OR(H20="",I20=""),"",I20-H20) -> 0 | L20: =IF(K20="","",IF(K20<0,"Falta gente",IF(K20=0,"Justo","Com folga"))) -> Justo | M20: =IF(B20="","",IF(N(F20)=0,"Falta a demanda",IF(N(G20)=0,"Falta a produtividade",IF(I20="","Falta o número escalado",IF(J20="","Falta o número de qualificados",IF(J20>I20,"Mais qualificados que escalados",IF(K20<0,IF(K20=-1,"Falta 1 pessoa","Faltam "&-K20&" pessoas"),IF(J20=0,"Sem pessoa qualificada na escala","OK")))))))) -> OK
B21: Salão | D21: Sexta, 20h às 22h | E21: clientes por hora | F21: 30 | G21: 15 | H21: =IF(OR(N(F21)=0,N(G21)=0),"",ROUNDUP(F21/G21,0)) -> 2 | I21: 3 | J21: 3 | K21: =IF(OR(H21="",I21=""),"",I21-H21) -> 1 | L21: =IF(K21="","",IF(K21<0,"Falta gente",IF(K21=0,"Justo","Com folga"))) -> Com folga | M21: =IF(B21="","",IF(N(F21)=0,"Falta a demanda",IF(N(G21)=0,"Falta a produtividade",IF(I21="","Falta o número escalado",IF(J21="","Falta o número de qualificados",IF(J21>I21,"Mais qualificados que escalados",IF(K21<0,IF(K21=-1,"Falta 1 pessoa","Faltam "&-K21&" pessoas"),IF(J21=0,"Sem pessoa qualificada na escala","OK")))))))) -> OK
B23: Infraestrutura
B24: Código | C24: Item | D24: Tipo | E24: Local | F24: Criticidade | G24: Meses | H24: Última | I24: Próxima | J24: Contingência | K24: Horas prog. | L24: Situação | M24: Quebras | N24: Horas paradas | O24: Disponib. | P24: Conferência
B25: FOR-01 | C25: Forno de lastro a gás | D25: Equipamento | E25: Cozinha | F25: Alta | G25: 1 | H25: 46479 | I25: =IF(OR(H25="",G25=""),"",EDATE(H25,G25)) -> 46509 | J25: Forno elétrico reserva, com metade da capacidade, e cardápio reduzido. | K25: 180 | L25: =IF(B25="","",IF(G25="","Sem plano",IF(H25="","Atrasada",IF(AND(ISNUMBER($D$9),I25<$D$9),"Atrasada",IF(AND(ISNUMBER($D$9),I25-$D$9<=7),"Vence em 7 dias","Em dia"))))) -> Vence em 7 dias | M25: =IF(OR(B25="",$D$8="",$D$9=""),"",COUNTIFS($C$37:$C$44,B25,$D$37:$D$44,"Corretiva",$B$37:$B$44,">="&$D$8,$B$37:$B$44,"<="&$D$9)) -> 1 | N25: =IF(OR(B25="",$D$8="",$D$9=""),"",SUMIFS($E$37:$E$44,$C$37:$C$44,B25,$D$37:$D$44,"Corretiva",$B$37:$B$44,">="&$D$8,$B$37:$B$44,"<="&$D$9)) -> 3 | O25: =IF(OR(N(K25)=0,N25=""),"",(K25-N25)/K25) -> 0.98333333 | P25: =IF(B25="","",IF(D25="","Falta o tipo",IF(F25="","Falta a criticidade",IF(AND(OR(F25="Alta",F25="Média"),G25=""),"Sem plano de preventiva",IF(L25="Atrasada","Preventiva atrasada",IF(AND(F25="Alta",J25=""),"Crítico sem contingência",IF(AND(ISNUMBER(O25),ISNUMBER($D$10)),IF(O25<$D$10-0.000000001,"Disponibilidade abaixo da meta","OK"),"OK"))))))) -> OK
B26: CAM-01 | C26: Câmara fria | D26: Equipamento | E26: Estoque | F26: Alta | G26: 3 | H26: 46397 | I26: =IF(OR(H26="",G26=""),"",EDATE(H26,G26)) -> 46487 | J26: Freezer reserva e caixas térmicas com gelo. Acima de 5 °C, medir cada item com o TER-01. | K26: 720 | L26: =IF(B26="","",IF(G26="","Sem plano",IF(H26="","Atrasada",IF(AND(ISNUMBER($D$9),I26<$D$9),"Atrasada",IF(AND(ISNUMBER($D$9),I26-$D$9<=7),"Vence em 7 dias","Em dia"))))) -> Atrasada | M26: =IF(OR(B26="",$D$8="",$D$9=""),"",COUNTIFS($C$37:$C$44,B26,$D$37:$D$44,"Corretiva",$B$37:$B$44,">="&$D$8,$B$37:$B$44,"<="&$D$9)) -> 1 | N26: =IF(OR(B26="",$D$8="",$D$9=""),"",SUMIFS($E$37:$E$44,$C$37:$C$44,B26,$D$37:$D$44,"Corretiva",$B$37:$B$44,">="&$D$8,$B$37:$B$44,"<="&$D$9)) -> 9 | O26: =IF(OR(N(K26)=0,N26=""),"",(K26-N26)/K26) -> 0.9875 | P26: =IF(B26="","",IF(D26="","Falta o tipo",IF(F26="","Falta a criticidade",IF(AND(OR(F26="Alta",F26="Média"),G26=""),"Sem plano de preventiva",IF(L26="Atrasada","Preventiva atrasada",IF(AND(F26="Alta",J26=""),"Crítico sem contingência",IF(AND(ISNUMBER(O26),ISNUMBER($D$10)),IF(O26<$D$10-0.000000001,"Disponibilidade abaixo da meta","OK"),"OK"))))))) -> Preventiva atrasada
B27: MAS-01 | C27: Masseira | D27: Equipamento | E27: Produção | F27: Média | G27: 6 | H27: 46341 | I27: =IF(OR(H27="",G27=""),"",EDATE(H27,G27)) -> 46522 | K27: 180 | L27: =IF(B27="","",IF(G27="","Sem plano",IF(H27="","Atrasada",IF(AND(ISNUMBER($D$9),I27<$D$9),"Atrasada",IF(AND(ISNUMBER($D$9),I27-$D$9<=7),"Vence em 7 dias","Em dia"))))) -> Em dia | M27: =IF(OR(B27="",$D$8="",$D$9=""),"",COUNTIFS($C$37:$C$44,B27,$D$37:$D$44,"Corretiva",$B$37:$B$44,">="&$D$8,$B$37:$B$44,"<="&$D$9)) -> 0 | N27: =IF(OR(B27="",$D$8="",$D$9=""),"",SUMIFS($E$37:$E$44,$C$37:$C$44,B27,$D$37:$D$44,"Corretiva",$B$37:$B$44,">="&$D$8,$B$37:$B$44,"<="&$D$9)) -> 0 | O27: =IF(OR(N(K27)=0,N27=""),"",(K27-N27)/K27) -> 1 | P27: =IF(B27="","",IF(D27="","Falta o tipo",IF(F27="","Falta a criticidade",IF(AND(OR(F27="Alta",F27="Média"),G27=""),"Sem plano de preventiva",IF(L27="Atrasada","Preventiva atrasada",IF(AND(F27="Alta",J27=""),"Crítico sem contingência",IF(AND(ISNUMBER(O27),ISNUMBER($D$10)),IF(O27<$D$10-0.000000001,"Disponibilidade abaixo da meta","OK"),"OK"))))))) -> OK
B28: MOT-01 | C28: Moto de entrega 1 | D28: Transporte | E28: Expedição | F28: Alta | G28: 1 | H28: 46482 | I28: =IF(OR(H28="",G28=""),"",EDATE(H28,G28)) -> 46512 | J28: Entregador extra com moto própria, chamado pelo grupo. | K28: 180 | L28: =IF(B28="","",IF(G28="","Sem plano",IF(H28="","Atrasada",IF(AND(ISNUMBER($D$9),I28<$D$9),"Atrasada",IF(AND(ISNUMBER($D$9),I28-$D$9<=7),"Vence em 7 dias","Em dia"))))) -> Vence em 7 dias | M28: =IF(OR(B28="",$D$8="",$D$9=""),"",COUNTIFS($C$37:$C$44,B28,$D$37:$D$44,"Corretiva",$B$37:$B$44,">="&$D$8,$B$37:$B$44,"<="&$D$9)) -> 0 | N28: =IF(OR(B28="",$D$8="",$D$9=""),"",SUMIFS($E$37:$E$44,$C$37:$C$44,B28,$D$37:$D$44,"Corretiva",$B$37:$B$44,">="&$D$8,$B$37:$B$44,"<="&$D$9)) -> 0 | O28: =IF(OR(N(K28)=0,N28=""),"",(K28-N28)/K28) -> 1 | P28: =IF(B28="","",IF(D28="","Falta o tipo",IF(F28="","Falta a criticidade",IF(AND(OR(F28="Alta",F28="Média"),G28=""),"Sem plano de preventiva",IF(L28="Atrasada","Preventiva atrasada",IF(AND(F28="Alta",J28=""),"Crítico sem contingência",IF(AND(ISNUMBER(O28),ISNUMBER($D$10)),IF(O28<$D$10-0.000000001,"Disponibilidade abaixo da meta","OK"),"OK"))))))) -> OK
B29: MOT-02 | C29: Moto de entrega 2 | D29: Transporte | E29: Expedição | F29: Alta | G29: 1 | H29: 46482 | I29: =IF(OR(H29="",G29=""),"",EDATE(H29,G29)) -> 46512 | J29: Entregador extra com moto própria, chamado pelo grupo. | K29: 180 | L29: =IF(B29="","",IF(G29="","Sem plano",IF(H29="","Atrasada",IF(AND(ISNUMBER($D$9),I29<$D$9),"Atrasada",IF(AND(ISNUMBER($D$9),I29-$D$9<=7),"Vence em 7 dias","Em dia"))))) -> Vence em 7 dias | M29: =IF(OR(B29="",$D$8="",$D$9=""),"",COUNTIFS($C$37:$C$44,B29,$D$37:$D$44,"Corretiva",$B$37:$B$44,">="&$D$8,$B$37:$B$44,"<="&$D$9)) -> 1 | N29: =IF(OR(B29="",$D$8="",$D$9=""),"",SUMIFS($E$37:$E$44,$C$37:$C$44,B29,$D$37:$D$44,"Corretiva",$B$37:$B$44,">="&$D$8,$B$37:$B$44,"<="&$D$9)) -> 12 | O29: =IF(OR(N(K29)=0,N29=""),"",(K29-N29)/K29) -> 0.93333333 | P29: =IF(B29="","",IF(D29="","Falta o tipo",IF(F29="","Falta a criticidade",IF(AND(OR(F29="Alta",F29="Média"),G29=""),"Sem plano de preventiva",IF(L29="Atrasada","Preventiva atrasada",IF(AND(F29="Alta",J29=""),"Crítico sem contingência",IF(AND(ISNUMBER(O29),ISNUMBER($D$10)),IF(O29<$D$10-0.000000001,"Disponibilidade abaixo da meta","OK"),"OK"))))))) -> Disponibilidade abaixo da meta
B30: MOT-03 | C30: Moto de entrega 3 | D30: Transporte | E30: Expedição | F30: Alta | G30: 1 | H30: 46433 | I30: =IF(OR(H30="",G30=""),"",EDATE(H30,G30)) -> 46461 | J30: Entregador extra com moto própria, chamado pelo grupo. | K30: 180 | L30: =IF(B30="","",IF(G30="","Sem plano",IF(H30="","Atrasada",IF(AND(ISNUMBER($D$9),I30<$D$9),"Atrasada",IF(AND(ISNUMBER($D$9),I30-$D$9<=7),"Vence em 7 dias","Em dia"))))) -> Atrasada | M30: =IF(OR(B30="",$D$8="",$D$9=""),"",COUNTIFS($C$37:$C$44,B30,$D$37:$D$44,"Corretiva",$B$37:$B$44,">="&$D$8,$B$37:$B$44,"<="&$D$9)) -> 0 | N30: =IF(OR(B30="",$D$8="",$D$9=""),"",SUMIFS($E$37:$E$44,$C$37:$C$44,B30,$D$37:$D$44,"Corretiva",$B$37:$B$44,">="&$D$8,$B$37:$B$44,"<="&$D$9)) -> 0 | O30: =IF(OR(N(K30)=0,N30=""),"",(K30-N30)/K30) -> 1 | P30: =IF(B30="","",IF(D30="","Falta o tipo",IF(F30="","Falta a criticidade",IF(AND(OR(F30="Alta",F30="Média"),G30=""),"Sem plano de preventiva",IF(L30="Atrasada","Preventiva atrasada",IF(AND(F30="Alta",J30=""),"Crítico sem contingência",IF(AND(ISNUMBER(O30),ISNUMBER($D$10)),IF(O30<$D$10-0.000000001,"Disponibilidade abaixo da meta","OK"),"OK"))))))) -> Preventiva atrasada
