Workbook

Sheet Instruções
B1: Caso integrado — Como usar esta planilha
B2: Modelo para seguir o fio de um problema pelos registros e para manter o calendário anual do sistema.
B4: Legenda: onde preencher
B5: Amarelo-claro | C5: Células de entrada. É aqui que você digita.
B6: Cinza | C6: Células calculadas ou fixas (dias, previstas, feitas, atrasadas, situações, conferências). Não altere.
B7: Cinza em itálico | C7: Linha de exemplo (marcada com “Ex.”). Mostra o formato esperado e não entra nas contagens.
B8: Listas suspensas | C8: Estudo, próximo estudo, frequência e checklist aceitam apenas as opções da lista. Os estudos vêm da aba Estudos.
B9: Cores do calendário | C9: Azul-claro: feita. Vermelho: prevista e não feita até o mês da leitura. Cinza: prevista para depois. Amarelo: feita fora do plano.
B11: As regras de cálculo
B12: Dias | C12: A data do passo menos a data do passo da linha de cima.
B13: Conferência do rastro | C13: Cada passo, menos o último, precisa da saída e do próximo estudo, e o próximo estudo precisa ser o estudo da linha seguinte.
B14: Meses previstos | C14: Do mês de início até dezembro, a cada 1, 2, 3, 6 ou 12 meses, conforme a frequência.
B15: Previstas e feitas | C15: As vezes previstas até o mês da leitura, e quantas delas têm marca no mês.
B16: Em dia | C16: Todas as previstas até o mês da leitura foram feitas.
B17: Com atraso | C17: Ao menos uma prevista até o mês da leitura não foi feita.
B18: Ainda não começou | C18: O primeiro mês previsto é depois do mês da leitura.
B19: Fora do plano | C19: Marca num mês em que a atividade não estava prevista. Não entra nas feitas.
B21: Ordem recomendada de preenchimento
B22: Passo 1 | C22: Aba Rastro: dê um nome ao fio e registre os passos do mais antigo ao mais recente, um por linha, sem linhas em branco no meio.
B23: Passo 2 | C23: Aba Rastro: para cada passo, o que saiu e o próximo estudo. Leia a coluna Conferência.
B24: Passo 3 | C24: Aba Calendário: informe o ano e o mês da leitura.
B25: Passo 4 | C25: Aba Calendário: liste as atividades periódicas, com estudo, requisito, responsável, frequência e mês de início.
B26: Passo 5 | C26: Aba Calendário: marque com X os meses em que cada atividade foi feita.
B27: Passo 6 | C27: Aba Painel: leia os avisos. Depois, valide na aba Checklist.
B29: Abas da planilha
B30: Rastro | C30: O nome do fio e até 30 passos. Calcula os dias entre os passos e a conferência.
B31: Calendário | C31: O ano, o mês da leitura e até 40 atividades. Calcula as previstas, as feitas, as atrasadas, a situação e a conferência.
B32: Estudos | C32: Os 34 estudos da série, com o grupo e o ritmo recomendado. Alimenta as listas suspensas.
B33: Painel | C33: Os números do fio e do calendário, o gráfico e o aviso.
B34: Checklist | C34: Doze verificações do sistema integrado, com percentual de conclusão.
B35: Exemplo 1 - Pizzaria | C35: Os atrasos das noites de pico, e o calendário de 2027 lido em junho.
B36: Exemplo 2 - Indústria | C36: O filme fino da extrusora 3, e o calendário de 2027 lido em setembro.
B38: Regras e premissas do modelo
B39: Estudos | C39: A lista traz os estudos desta série. Para usar outro nome, acrescente uma linha no fim da aba Estudos.
B40: Marca do mês | C40: Qualquer texto vale como feito. Use X, ou a data em que foi feito.
B41: Frequências | C41: Mensal, bimestral, trimestral, semestral ou anual. O que é contínuo fica fora do calendário.
B42: Exemplos | C42: Os dados das abas de exemplo são ilustrativos, criados para este material.

Sheet Rastro
B1: Rastro de um fio
B2: Um passo por linha, do mais antigo ao mais recente. Cada passo diz o que saiu e para qual estudo foi.
B4: Fio
B5: O problema que está sendo seguido. Ex.: reclamação de filme fino do cliente A.
B6: Passo | C6: Data | D6: Estudo | E6: O que aconteceu | F6: Registro | G6: O que seguiu | H6: Próximo estudo | I6: Dias | J6: Conferência
C7: Data | D7: Lista | E7: A decisão ou a ação | F7: RNC, ata, folha | G7: A saída deste passo | H7: Lista | I7: Calculado | J7: Calculada
B8: 1 | I8: ="" | J8: =IF(COUNTA(C8:H8)=0,"",IF(C8="","Falta a data",IF(D8="","Falta o estudo",IF(E8="","Falta o que aconteceu",IF(F8="","Falta o registro",IF(AND(ISNUMBER(I8),I8<0),"Data antes do passo anterior",IF(COUNTA(C9:H9)=0,"OK",IF(G8="","Falta a saída",IF(H8="","Falta o próximo estudo",IF(H8<>D9,"O passo seguinte é de outro estudo","OK"))))))))))
B9: 2 | I9: =IF(OR(C9="",C8=""),"",C9-C8) | J9: =IF(COUNTA(C9:H9)=0,"",IF(C9="","Falta a data",IF(D9="","Falta o estudo",IF(E9="","Falta o que aconteceu",IF(F9="","Falta o registro",IF(AND(ISNUMBER(I9),I9<0),"Data antes do passo anterior",IF(COUNTA(C10:H10)=0,"OK",IF(G9="","Falta a saída",IF(H9="","Falta o próximo estudo",IF(H9<>D10,"O passo seguinte é de outro estudo","OK"))))))))))
B10: 3 | I10: =IF(OR(C10="",C9=""),"",C10-C9) | J10: =IF(COUNTA(C10:H10)=0,"",IF(C10="","Falta a data",IF(D10="","Falta o estudo",IF(E10="","Falta o que aconteceu",IF(F10="","Falta o registro",IF(AND(ISNUMBER(I10),I10<0),"Data antes do passo anterior",IF(COUNTA(C11:H11)=0,"OK",IF(G10="","Falta a saída",IF(H10="","Falta o próximo estudo",IF(H10<>D11,"O passo seguinte é de outro estudo","OK"))))))))))
B11: 4 | I11: =IF(OR(C11="",C10=""),"",C11-C10) | J11: =IF(COUNTA(C11:H11)=0,"",IF(C11="","Falta a data",IF(D11="","Falta o estudo",IF(E11="","Falta o que aconteceu",IF(F11="","Falta o registro",IF(AND(ISNUMBER(I11),I11<0),"Data antes do passo anterior",IF(COUNTA(C12:H12)=0,"OK",IF(G11="","Falta a saída",IF(H11="","Falta o próximo estudo",IF(H11<>D12,"O passo seguinte é de outro estudo","OK"))))))))))
B12: 5 | I12: =IF(OR(C12="",C11=""),"",C12-C11) | J12: =IF(COUNTA(C12:H12)=0,"",IF(C12="","Falta a data",IF(D12="","Falta o estudo",IF(E12="","Falta o que aconteceu",IF(F12="","Falta o registro",IF(AND(ISNUMBER(I12),I12<0),"Data antes do passo anterior",IF(COUNTA(C13:H13)=0,"OK",IF(G12="","Falta a saída",IF(H12="","Falta o próximo estudo",IF(H12<>D13,"O passo seguinte é de outro estudo","OK"))))))))))
B13: 6 | I13: =IF(OR(C13="",C12=""),"",C13-C12) | J13: =IF(COUNTA(C13:H13)=0,"",IF(C13="","Falta a data",IF(D13="","Falta o estudo",IF(E13="","Falta o que aconteceu",IF(F13="","Falta o registro",IF(AND(ISNUMBER(I13),I13<0),"Data antes do passo anterior",IF(COUNTA(C14:H14)=0,"OK",IF(G13="","Falta a saída",IF(H13="","Falta o próximo estudo",IF(H13<>D14,"O passo seguinte é de outro estudo","OK"))))))))))
B14: 7 | I14: =IF(OR(C14="",C13=""),"",C14-C13) | J14: =IF(COUNTA(C14:H14)=0,"",IF(C14="","Falta a data",IF(D14="","Falta o estudo",IF(E14="","Falta o que aconteceu",IF(F14="","Falta o registro",IF(AND(ISNUMBER(I14),I14<0),"Data antes do passo anterior",IF(COUNTA(C15:H15)=0,"OK",IF(G14="","Falta a saída",IF(H14="","Falta o próximo estudo",IF(H14<>D15,"O passo seguinte é de outro estudo","OK"))))))))))
B15: 8 | I15: =IF(OR(C15="",C14=""),"",C15-C14) | J15: =IF(COUNTA(C15:H15)=0,"",IF(C15="","Falta a data",IF(D15="","Falta o estudo",IF(E15="","Falta o que aconteceu",IF(F15="","Falta o registro",IF(AND(ISNUMBER(I15),I15<0),"Data antes do passo anterior",IF(COUNTA(C16:H16)=0,"OK",IF(G15="","Falta a saída",IF(H15="","Falta o próximo estudo",IF(H15<>D16,"O passo seguinte é de outro estudo","OK"))))))))))
B16: 9 | I16: =IF(OR(C16="",C15=""),"",C16-C15) | J16: =IF(COUNTA(C16:H16)=0,"",IF(C16="","Falta a data",IF(D16="","Falta o estudo",IF(E16="","Falta o que aconteceu",IF(F16="","Falta o registro",IF(AND(ISNUMBER(I16),I16<0),"Data antes do passo anterior",IF(COUNTA(C17:H17)=0,"OK",IF(G16="","Falta a saída",IF(H16="","Falta o próximo estudo",IF(H16<>D17,"O passo seguinte é de outro estudo","OK"))))))))))
B17: 10 | I17: =IF(OR(C17="",C16=""),"",C17-C16) | J17: =IF(COUNTA(C17:H17)=0,"",IF(C17="","Falta a data",IF(D17="","Falta o estudo",IF(E17="","Falta o que aconteceu",IF(F17="","Falta o registro",IF(AND(ISNUMBER(I17),I17<0),"Data antes do passo anterior",IF(COUNTA(C18:H18)=0,"OK",IF(G17="","Falta a saída",IF(H17="","Falta o próximo estudo",IF(H17<>D18,"O passo seguinte é de outro estudo","OK"))))))))))
B18: 11 | I18: =IF(OR(C18="",C17=""),"",C18-C17) | J18: =IF(COUNTA(C18:H18)=0,"",IF(C18="","Falta a data",IF(D18="","Falta o estudo",IF(E18="","Falta o que aconteceu",IF(F18="","Falta o registro",IF(AND(ISNUMBER(I18),I18<0),"Data antes do passo anterior",IF(COUNTA(C19:H19)=0,"OK",IF(G18="","Falta a saída",IF(H18="","Falta o próximo estudo",IF(H18<>D19,"O passo seguinte é de outro estudo","OK"))))))))))
B19: 12 | I19: =IF(OR(C19="",C18=""),"",C19-C18) | J19: =IF(COUNTA(C19:H19)=0,"",IF(C19="","Falta a data",IF(D19="","Falta o estudo",IF(E19="","Falta o que aconteceu",IF(F19="","Falta o registro",IF(AND(ISNUMBER(I19),I19<0),"Data antes do passo anterior",IF(COUNTA(C20:H20)=0,"OK",IF(G19="","Falta a saída",IF(H19="","Falta o próximo estudo",IF(H19<>D20,"O passo seguinte é de outro estudo","OK"))))))))))
B20: 13 | I20: =IF(OR(C20="",C19=""),"",C20-C19) | J20: =IF(COUNTA(C20:H20)=0,"",IF(C20="","Falta a data",IF(D20="","Falta o estudo",IF(E20="","Falta o que aconteceu",IF(F20="","Falta o registro",IF(AND(ISNUMBER(I20),I20<0),"Data antes do passo anterior",IF(COUNTA(C21:H21)=0,"OK",IF(G20="","Falta a saída",IF(H20="","Falta o próximo estudo",IF(H20<>D21,"O passo seguinte é de outro estudo","OK"))))))))))
... B37: 30 | I37: =IF(OR(C37="",C36=""),"",C37-C36) | J37: =IF(COUNTA(C37:H37)=0,"",IF(C37="","Falta a data",IF(D37="","Falta o estudo",IF(E37="","Falta o que aconteceu",IF(F37="","Falta o registro",IF(AND(ISNUMBER(I37),I37<0),"Data antes do passo anterior",IF(COUNTA(C38:H38)=0,"OK",IF(G37="","Falta a saída",IF(H37="","Falta o próximo estudo",IF(H37<>D38,"O passo seguinte é de outro estudo","OK"))))))))))
B39: Resumo automático
B40: Passos | E40: =COUNTA(D8:D37)&" passos, "&IF(COUNTA(D8:D37)=0,0,SUMPRODUCT((D8:D37<>"")/COUNTIF(D8:D37,D8:D37&"")))&" estudos" -> 0 passos, 0 estudos
B41: Duração | E41: =IF(COUNT(C8:C37)=0,"",MAX(C8:C37)-MIN(C8:C37)&" dias do primeiro ao último passo; maior intervalo de "&MAX(I8:I37)&" dias")
B42: Aviso | E42: =IF(COUNTA(D8:D37)=0,"Registre os passos do fio",IF(COUNTIF(J8:J37,"O passo seguinte é de outro estudo")>0,"O fio pulou um passo: veja a coluna Conferência",IF(SUMPRODUCT((J8:J37<>"")*(J8:J37<>"OK"))>0,"Há passo a completar: veja a coluna Conferência","OK"))) -> Registre os passos do fio

Sheet Calendário
B1: Calendário do sistema
B2: Uma atividade periódica por linha. Marque com X os meses em que foi feita.
B4: Ano | F4: O ano do calendário.
B5: Mês da leitura (1 a 12) | F5: As previstas e as atrasadas contam até este mês, inclusive.
B8: # | C8: Atividade | D8: Estudo | E8: Requisito | F8: Responsável | G8: Frequência | H8: Mês de início | I8: Jan | J8: Fev | K8: Mar | L8: Abr | M8: Mai | N8: Jun | O8: Jul | P8: Ago | Q8: Set | R8: Out | S8: Nov | T8: Dez | U8: Previstas | V8: Feitas | W8: Atrasadas | X8: Fora do plano | Y8: Situação | Z8: Conferência | AA8: A cada
D9: Lista | E9: Ex.: 9.2 | G9: Lista | H9: 1 a 12 | I9: 1 | J9: 2 | K9: 3 | L9: 4 | M9: 5 | N9: 6 | O9: 7 | P9: 8 | Q9: 9 | R9: 10 | S9: 11 | T9: 12 | U9: Calculado | V9: Calculado | W9: Calculado | X9: Calculado | Y9: Calculada | Z9: Calculada | AA9: Meses
B10: 1 | U10: =IF(OR(C10="",AA10="",H10="",$E$5=""),"",IF(OR(H10<1,H10>12),"",SUMPRODUCT(($I$9:$T$9>=$H10)*(MOD($I$9:$T$9-$H10,$AA10)=0)*($I$9:$T$9<=$E$5)))) | V10: =IF(U10="","",SUMPRODUCT(($I$9:$T$9>=$H10)*(MOD($I$9:$T$9-$H10,$AA10)=0)*($I$9:$T$9<=$E$5)*(I10:T10<>""))) | W10: =IF(U10="","",U10-V10) | X10: =IF(U10="","",SUMPRODUCT((1-($I$9:$T$9>=$H10)*(MOD($I$9:$T$9-$H10,$AA10)=0))*(I10:T10<>""))) | Y10: =IF(U10="","",IF(U10=0,"Ainda não começou",IF(W10>0,"Com atraso","Em dia"))) | Z10: =IF(C10="","",IF(D10="","Falta o estudo",IF(F10="","Falta o responsável",IF(G10="","Falta a frequência",IF(H10="","Falta o mês de início",IF(OR(H10<1,H10>12),"Mês de início fora de 1 a 12","OK")))))) | AA10: =IF(G10="","",IFERROR(CHOOSE(MATCH(G10,{"Mensal","Bimestral","Trimestral","Semestral","Anual"},0),1,2,3,6,12),""))
B11: 2 | U11: =IF(OR(C11="",AA11="",H11="",$E$5=""),"",IF(OR(H11<1,H11>12),"",SUMPRODUCT(($I$9:$T$9>=$H11)*(MOD($I$9:$T$9-$H11,$AA11)=0)*($I$9:$T$9<=$E$5)))) | V11: =IF(U11="","",SUMPRODUCT(($I$9:$T$9>=$H11)*(MOD($I$9:$T$9-$H11,$AA11)=0)*($I$9:$T$9<=$E$5)*(I11:T11<>""))) | W11: =IF(U11="","",U11-V11) | X11: =IF(U11="","",SUMPRODUCT((1-($I$9:$T$9>=$H11)*(MOD($I$9:$T$9-$H11,$AA11)=0))*(I11:T11<>""))) | Y11: =IF(U11="","",IF(U11=0,"Ainda não começou",IF(W11>0,"Com atraso","Em dia"))) | Z11: =IF(C11="","",IF(D11="","Falta o estudo",IF(F11="","Falta o responsável",IF(G11="","Falta a frequência",IF(H11="","Falta o mês de início",IF(OR(H11<1,H11>12),"Mês de início fora de 1 a 12","OK")))))) | AA11: =IF(G11="","",IFERROR(CHOOSE(MATCH(G11,{"Mensal","Bimestral","Trimestral","Semestral","Anual"},0),1,2,3,6,12),""))
B12: 3 | U12: =IF(OR(C12="",AA12="",H12="",$E$5=""),"",IF(OR(H12<1,H12>12),"",SUMPRODUCT(($I$9:$T$9>=$H12)*(MOD($I$9:$T$9-$H12,$AA12)=0)*($I$9:$T$9<=$E$5)))) | V12: =IF(U12="","",SUMPRODUCT(($I$9:$T$9>=$H12)*(MOD($I$9:$T$9-$H12,$AA12)=0)*($I$9:$T$9<=$E$5)*(I12:T12<>""))) | W12: =IF(U12="","",U12-V12) | X12: =IF(U12="","",SUMPRODUCT((1-($I$9:$T$9>=$H12)*(MOD($I$9:$T$9-$H12,$AA12)=0))*(I12:T12<>""))) | Y12: =IF(U12="","",IF(U12=0,"Ainda não começou",IF(W12>0,"Com atraso","Em dia"))) | Z12: =IF(C12="","",IF(D12="","Falta o estudo",IF(F12="","Falta o responsável",IF(G12="","Falta a frequência",IF(H12="","Falta o mês de início",IF(OR(H12<1,H12>12),"Mês de início fora de 1 a 12","OK")))))) | AA12: =IF(G12="","",IFERROR(CHOOSE(MATCH(G12,{"Mensal","Bimestral","Trimestral","Semestral","Anual"},0),1,2,3,6,12),""))
B13: 4 | U13: =IF(OR(C13="",AA13="",H13="",$E$5=""),"",IF(OR(H13<1,H13>12),"",SUMPRODUCT(($I$9:$T$9>=$H13)*(MOD($I$9:$T$9-$H13,$AA13)=0)*($I$9:$T$9<=$E$5)))) | V13: =IF(U13="","",SUMPRODUCT(($I$9:$T$9>=$H13)*(MOD($I$9:$T$9-$H13,$AA13)=0)*($I$9:$T$9<=$E$5)*(I13:T13<>""))) | W13: =IF(U13="","",U13-V13) | X13: =IF(U13="","",SUMPRODUCT((1-($I$9:$T$9>=$H13)*(MOD($I$9:$T$9-$H13,$AA13)=0))*(I13:T13<>""))) | Y13: =IF(U13="","",IF(U13=0,"Ainda não começou",IF(W13>0,"Com atraso","Em dia"))) | Z13: =IF(C13="","",IF(D13="","Falta o estudo",IF(F13="","Falta o responsável",IF(G13="","Falta a frequência",IF(H13="","Falta o mês de início",IF(OR(H13<1,H13>12),"Mês de início fora de 1 a 12","OK")))))) | AA13: =IF(G13="","",IFERROR(CHOOSE(MATCH(G13,{"Mensal","Bimestral","Trimestral","Semestral","Anual"},0),1,2,3,6,12),""))
B14: 5 | U14: =IF(OR(C14="",AA14="",H14="",$E$5=""),"",IF(OR(H14<1,H14>12),"",SUMPRODUCT(($I$9:$T$9>=$H14)*(MOD($I$9:$T$9-$H14,$AA14)=0)*($I$9:$T$9<=$E$5)))) | V14: =IF(U14="","",SUMPRODUCT(($I$9:$T$9>=$H14)*(MOD($I$9:$T$9-$H14,$AA14)=0)*($I$9:$T$9<=$E$5)*(I14:T14<>""))) | W14: =IF(U14="","",U14-V14) | X14: =IF(U14="","",SUMPRODUCT((1-($I$9:$T$9>=$H14)*(MOD($I$9:$T$9-$H14,$AA14)=0))*(I14:T14<>""))) | Y14: =IF(U14="","",IF(U14=0,"Ainda não começou",IF(W14>0,"Com atraso","Em dia"))) | Z14: =IF(C14="","",IF(D14="","Falta o estudo",IF(F14="","Falta o responsável",IF(G14="","Falta a frequência",IF(H14="","Falta o mês de início",IF(OR(H14<1,H14>12),"Mês de início fora de 1 a 12","OK")))))) | AA14: =IF(G14="","",IFERROR(CHOOSE(MATCH(G14,{"Mensal","Bimestral","Trimestral","Semestral","Anual"},0),1,2,3,6,12),""))
B15: 6 | U15: =IF(OR(C15="",AA15="",H15="",$E$5=""),"",IF(OR(H15<1,H15>12),"",SUMPRODUCT(($I$9:$T$9>=$H15)*(MOD($I$9:$T$9-$H15,$AA15)=0)*($I$9:$T$9<=$E$5)))) | V15: =IF(U15="","",SUMPRODUCT(($I$9:$T$9>=$H15)*(MOD($I$9:$T$9-$H15,$AA15)=0)*($I$9:$T$9<=$E$5)*(I15:T15<>""))) | W15: =IF(U15="","",U15-V15) | X15: =IF(U15="","",SUMPRODUCT((1-($I$9:$T$9>=$H15)*(MOD($I$9:$T$9-$H15,$AA15)=0))*(I15:T15<>""))) | Y15: =IF(U15="","",IF(U15=0,"Ainda não começou",IF(W15>0,"Com atraso","Em dia"))) | Z15: =IF(C15="","",IF(D15="","Falta o estudo",IF(F15="","Falta o responsável",IF(G15="","Falta a frequência",IF(H15="","Falta o mês de início",IF(OR(H15<1,H15>12),"Mês de início fora de 1 a 12","OK")))))) | AA15: =IF(G15="","",IFERROR(CHOOSE(MATCH(G15,{"Mensal","Bimestral","Trimestral","Semestral","Anual"},0),1,2,3,6,12),""))
B16: 7 | U16: =IF(OR(C16="",AA16="",H16="",$E$5=""),"",IF(OR(H16<1,H16>12),"",SUMPRODUCT(($I$9:$T$9>=$H16)*(MOD($I$9:$T$9-$H16,$AA16)=0)*($I$9:$T$9<=$E$5)))) | V16: =IF(U16="","",SUMPRODUCT(($I$9:$T$9>=$H16)*(MOD($I$9:$T$9-$H16,$AA16)=0)*($I$9:$T$9<=$E$5)*(I16:T16<>""))) | W16: =IF(U16="","",U16-V16) | X16: =IF(U16="","",SUMPRODUCT((1-($I$9:$T$9>=$H16)*(MOD($I$9:$T$9-$H16,$AA16)=0))*(I16:T16<>""))) | Y16: =IF(U16="","",IF(U16=0,"Ainda não começou",IF(W16>0,"Com atraso","Em dia"))) | Z16: =IF(C16="","",IF(D16="","Falta o estudo",IF(F16="","Falta o responsável",IF(G16="","Falta a frequência",IF(H16="","Falta o mês de início",IF(OR(H16<1,H16>12),"Mês de início fora de 1 a 12","OK")))))) | AA16: =IF(G16="","",IFERROR(CHOOSE(MATCH(G16,{"Mensal","Bimestral","Trimestral","Semestral","Anual"},0),1,2,3,6,12),""))
B17: 8 | U17: =IF(OR(C17="",AA17="",H17="",$E$5=""),"",IF(OR(H17<1,H17>12),"",SUMPRODUCT(($I$9:$T$9>=$H17)*(MOD($I$9:$T$9-$H17,$AA17)=0)*($I$9:$T$9<=$E$5)))) | V17: =IF(U17="","",SUMPRODUCT(($I$9:$T$9>=$H17)*(MOD($I$9:$T$9-$H17,$AA17)=0)*($I$9:$T$9<=$E$5)*(I17:T17<>""))) | W17: =IF(U17="","",U17-V17) | X17: =IF(U17="","",SUMPRODUCT((1-($I$9:$T$9>=$H17)*(MOD($I$9:$T$9-$H17,$AA17)=0))*(I17:T17<>""))) | Y17: =IF(U17="","",IF(U17=0,"Ainda não começou",IF(W17>0,"Com atraso","Em dia"))) | Z17: =IF(C17="","",IF(D17="","Falta o estudo",IF(F17="","Falta o responsável",IF(G17="","Falta a frequência",IF(H17="","Falta o mês de início",IF(OR(H17<1,H17>12),"Mês de início fora de 1 a 12","OK")))))) | AA17: =IF(G17="","",IFERROR(CHOOSE(MATCH(G17,{"Mensal","Bimestral","Trimestral","Semestral","Anual"},0),1,2,3,6,12),""))
B18: 9 | U18: =IF(OR(C18="",AA18="",H18="",$E$5=""),"",IF(OR(H18<1,H18>12),"",SUMPRODUCT(($I$9:$T$9>=$H18)*(MOD($I$9:$T$9-$H18,$AA18)=0)*($I$9:$T$9<=$E$5)))) | V18: =IF(U18="","",SUMPRODUCT(($I$9:$T$9>=$H18)*(MOD($I$9:$T$9-$H18,$AA18)=0)*($I$9:$T$9<=$E$5)*(I18:T18<>""))) | W18: =IF(U18="","",U18-V18) | X18: =IF(U18="","",SUMPRODUCT((1-($I$9:$T$9>=$H18)*(MOD($I$9:$T$9-$H18,$AA18)=0))*(I18:T18<>""))) | Y18: =IF(U18="","",IF(U18=0,"Ainda não começou",IF(W18>0,"Com atraso","Em dia"))) | Z18: =IF(C18="","",IF(D18="","Falta o estudo",IF(F18="","Falta o responsável",IF(G18="","Falta a frequência",IF(H18="","Falta o mês de início",IF(OR(H18<1,H18>12),"Mês de início fora de 1 a 12","OK")))))) | AA18: =IF(G18="","",IFERROR(CHOOSE(MATCH(G18,{"Mensal","Bimestral","Trimestral","Semestral","Anual"},0),1,2,3,6,12),""))
B19: 10 | U19: =IF(OR(C19="",AA19="",H19="",$E$5=""),"",IF(OR(H19<1,H19>12),"",SUMPRODUCT(($I$9:$T$9>=$H19)*(MOD($I$9:$T$9-$H19,$AA19)=0)*($I$9:$T$9<=$E$5)))) | V19: =IF(U19="","",SUMPRODUCT(($I$9:$T$9>=$H19)*(MOD($I$9:$T$9-$H19,$AA19)=0)*($I$9:$T$9<=$E$5)*(I19:T19<>""))) | W19: =IF(U19="","",U19-V19) | X19: =IF(U19="","",SUMPRODUCT((1-($I$9:$T$9>=$H19)*(MOD($I$9:$T$9-$H19,$AA19)=0))*(I19:T19<>""))) | Y19: =IF(U19="","",IF(U19=0,"Ainda não começou",IF(W19>0,"Com atraso","Em dia"))) | Z19: =IF(C19="","",IF(D19="","Falta o estudo",IF(F19="","Falta o responsável",IF(G19="","Falta a frequência",IF(H19="","Falta o mês de início",IF(OR(H19<1,H19>12),"Mês de início fora de 1 a 12","OK")))))) | AA19: =IF(G19="","",IFERROR(CHOOSE(MATCH(G19,{"Mensal","Bimestral","Trimestral","Semestral","Anual"},0),1,2,3,6,12),""))
B20: 11 | U20: =IF(OR(C20="",AA20="",H20="",$E$5=""),"",IF(OR(H20<1,H20>12),"",SUMPRODUCT(($I$9:$T$9>=$H20)*(MOD($I$9:$T$9-$H20,$AA20)=0)*($I$9:$T$9<=$E$5)))) | V20: =IF(U20="","",SUMPRODUCT(($I$9:$T$9>=$H20)*(MOD($I$9:$T$9-$H20,$AA20)=0)*($I$9:$T$9<=$E$5)*(I20:T20<>""))) | W20: =IF(U20="","",U20-V20) | X20: =IF(U20="","",SUMPRODUCT((1-($I$9:$T$9>=$H20)*(MOD($I$9:$T$9-$H20,$AA20)=0))*(I20:T20<>""))) | Y20: =IF(U20="","",IF(U20=0,"Ainda não começou",IF(W20>0,"Com atraso","Em dia"))) | Z20: =IF(C20="","",IF(D20="","Falta o estudo",IF(F20="","Falta o responsável",IF(G20="","Falta a frequência",IF(H20="","Falta o mês de início",IF(OR(H20<1,H20>12),"Mês de início fora de 1 a 12","OK")))))) | AA20: =IF(G20="","",IFERROR(CHOOSE(MATCH(G20,{"Mensal","Bimestral","Trimestral","Semestral","Anual"},0),1,2,3,6,12),""))
B21: 12 | U21: =IF(OR(C21="",AA21="",H21="",$E$5=""),"",IF(OR(H21<1,H21>12),"",SUMPRODUCT(($I$9:$T$9>=$H21)*(MOD($I$9:$T$9-$H21,$AA21)=0)*($I$9:$T$9<=$E$5)))) | V21: =IF(U21="","",SUMPRODUCT(($I$9:$T$9>=$H21)*(MOD($I$9:$T$9-$H21,$AA21)=0)*($I$9:$T$9<=$E$5)*(I21:T21<>""))) | W21: =IF(U21="","",U21-V21) | X21: =IF(U21="","",SUMPRODUCT((1-($I$9:$T$9>=$H21)*(MOD($I$9:$T$9-$H21,$AA21)=0))*(I21:T21<>""))) | Y21: =IF(U21="","",IF(U21=0,"Ainda não começou",IF(W21>0,"Com atraso","Em dia"))) | Z21: =IF(C21="","",IF(D21="","Falta o estudo",IF(F21="","Falta o responsável",IF(G21="","Falta a frequência",IF(H21="","Falta o mês de início",IF(OR(H21<1,H21>12),"Mês de início fora de 1 a 12","OK")))))) | AA21: =IF(G21="","",IFERROR(CHOOSE(MATCH(G21,{"Mensal","Bimestral","Trimestral","Semestral","Anual"},0),1,2,3,6,12),""))
... B49: 40 | U49: =IF(OR(C49="",AA49="",H49="",$E$5=""),"",IF(OR(H49<1,H49>12),"",SUMPRODUCT(($I$9:$T$9>=$H49)*(MOD($I$9:$T$9-$H49,$AA49)=0)*($I$9:$T$9<=$E$5)))) | V49: =IF(U49="","",SUMPRODUCT(($I$9:$T$9>=$H49)*(MOD($I$9:$T$9-$H49,$AA49)=0)*($I$9:$T$9<=$E$5)*(I49:T49<>""))) | W49: =IF(U49="","",U49-V49) | X49: =IF(U49="","",SUMPRODUCT((1-($I$9:$T$9>=$H49)*(MOD($I$9:$T$9-$H49,$AA49)=0))*(I49:T49<>""))) | Y49: =IF(U49="","",IF(U49=0,"Ainda não começou",IF(W49>0,"Com atraso","Em dia"))) | Z49: =IF(C49="","",IF(D49="","Falta o estudo",IF(F49="","Falta o responsável",IF(G49="","Falta a frequência",IF(H49="","Falta o mês de início",IF(OR(H49<1,H49>12),"Mês de início fora de 1 a 12","OK")))))) | AA49: =IF(G49="","",IFERROR(CHOOSE(MATCH(G49,{"Mensal","Bimestral","Trimestral","Semestral","Anual"},0),1,2,3,6,12),""))
B51: Resumo automático
B52: Atividades | E52: =COUNTA(C10:C49) -> 0
B53: Até o mês da leitura | E53: =IF(SUM(U10:U49)=0,"",SUM(V10:V49)&" de "&SUM(U10:U49)&" feitas, "&SUM(W10:W49)&" atrasadas, "&SUM(X10:X49)&" fora do plano")
B54: Por situação | E54: =COUNTIF(Y10:Y49,"Em dia")&" em dia"&", "&COUNTIF(Y10:Y49,"Com atraso")&" com atraso"&", "&COUNTIF(Y10:Y49,"Ainda não começou")&" ainda não começou" -> 0 em dia, 0 com atraso, 0 ainda não começou
B55: Aviso | E55: =IF(E52=0,"Liste as atividades do calendário",IF(E5="","Informe o mês da leitura",IF(COUNTIF(Y10:Y49,"Com atraso")>0,"Há atividade atrasada: marque a data nova",IF(SUMPRODUCT((Z10:Z49<>"")*(Z10:Z49<>"OK"))>0,"Há atividade a completar: veja a coluna Conferência","OK")))) -> Liste as atividades do calendário

Sheet Estudos
B1: Os estudos da série
B2: A lista usada nas listas suspensas, com o ritmo recomendado por este material.
B4: # | C4: Estudo | D4: Título | E4: Grupo | F4: Ritmo | G4: O que se faz
B5: 1 | C5: ISO 9001 | D5: ISO 9001 requisito a requisito | E5: Conhecer a norma e montar o sistema | F5: Anual | G5: Diagnóstico requisito a requisito, uma vez por ano.
B6: 2 | C6: ISO 9001:2026 | D6: ISO 9001:2026: o que muda | E6: Conhecer a norma e montar o sistema | F6: Quando necessário | G6: Uma vez, na transição, com o plano lido no calendário.
B7: 3 | C7: Escopo e liderança | D7: Escopo e liderança | E7: Conhecer a norma e montar o sistema | F7: Anual | G7: Revisão do escopo e dos compromissos da direção.
B8: 4 | C8: Informação documentada | D8: Informação documentada | E8: Conhecer a norma e montar o sistema | F8: Anual | G8: Revisão da lista mestra e da retenção.
B9: 5 | C9: Matriz de competências | D9: Matriz de competências e treinamento | E9: Conhecer a norma e montar o sistema | F9: Semestral | G9: Matriz atualizada e plano de treinamento.
B10: 6 | C10: Calibração | D10: Calibração e recursos de medição | E10: Conhecer a norma e montar o sistema | F10: Mensal | G10: Leitura dos vencimentos e ronda metrológica.
B11: 7 | C11: Recursos e infraestrutura | D11: Recursos, infraestrutura e ambiente | E11: Conhecer a norma e montar o sistema | F11: Mensal | G11: Ronda dos recursos: escala, preventivas, ambiente.
B12: 8 | C12: Conhecimento e pós-entrega | D12: Conhecimento organizacional e pós-entrega | E12: Conhecer a norma e montar o sistema | F12: Mensal | G12: Ronda do aprendizado: lições e atendimentos.
B13: 9 | C13: Partes interessadas | D13: Partes interessadas | E13: Conhecer a organização e planejar | F13: Anual | G13: Revisão das partes e dos requisitos.
B14: 10 | C14: Matriz SWOT | D14: Matriz SWOT | E14: Conhecer a organização e planejar | F14: Anual | G14: Diagnóstico estratégico, antes do planejamento do ano.
B15: 11 | C15: Objetivos da qualidade | D15: Objetivos da qualidade | E15: Conhecer a organização e planejar | F15: Trimestral | G15: Acompanhamento dos objetivos e dos planos.
B16: 12 | C16: Requisitos do cliente | D16: Requisitos do cliente e análise de pedidos | E16: Conhecer a organização e planejar | F16: Contínuo | G16: A cada pedido, com leitura mensal dos registros.
... B38: 34 | C38: Caso integrado | D38: Caso integrado | E38: Verificar e corrigir o sistema | F38: Mensal | G38: Leitura mensal do calendário e dos fios abertos.

Sheet Painel
B1: Painel do sistema integrado
B2: Nada a preencher: tudo vem das outras abas.
B3: Fio | C3: =IF(Rastro!D4="","",Rastro!D4)
B5: Indicador | C5: Resultado | D5: Como se lê
B6: O FIO
B7: Passos | C7: =COUNTA(Rastro!D8:D37) -> 0 | D7: Da aba Rastro.
B8: Estudos diferentes | C8: =IF(COUNTA(Rastro!D8:D37)=0,0,SUMPRODUCT((Rastro!D8:D37<>"")/COUNTIF(Rastro!D8:D37,Rastro!D8:D37&""))) -> 0 | D8: Por quantos estudos o problema passou.
B9: Dias do primeiro ao último passo | C9: =IF(COUNT(Rastro!C8:C37)=0,"",MAX(Rastro!C8:C37)-MIN(Rastro!C8:C37)) | D9: A duração do fio.
B10: Maior intervalo entre passos | C10: =IF(COUNT(Rastro!I8:I37)=0,"",MAX(Rastro!I8:I37)) | D10: Onde o fio esperou mais.
B11: Passos a completar | C11: =SUMPRODUCT((Rastro!J8:J37<>"")*(Rastro!J8:J37<>"OK")) -> 0 | D11: Conferências diferentes de OK.
B12: O CALENDÁRIO
B13: Mês da leitura | C13: =IF(Calendário!E5="","",Calendário!E5) | D13: Da aba Calendário.
B14: Atividades | C14: =COUNTA(Calendário!C10:C49) -> 0 | D14: Atividades periódicas do sistema.
B15: Previstas até o mês | C15: =SUM(Calendário!U10:U49) -> 0 | D15: Vezes previstas até o mês da leitura.
B16: Feitas | C16: =SUM(Calendário!V10:V49) -> 0 | D16: Das previstas, as que têm marca.
B17: Cumprimento | C17: =IFERROR(SUM(Calendário!V10:V49)/SUM(Calendário!U10:U49),"") | D17: Feitas ÷ previstas.
B18: Atrasadas | C18: =SUM(Calendário!W10:W49) -> 0 | D18: Previstas e não feitas.
B19: Atividades com atraso | C19: =COUNTIF(Calendário!Y10:Y49,"Com atraso") -> 0 | D19: Levar à reunião mensal.
B20: Feitas fora do plano | C20: =SUM(Calendário!X10:X49) -> 0 | D20: Recuperação de atraso, ou plano a rever.
B21: Atividades a completar | C21: =SUMPRODUCT((Calendário!Z10:Z49<>"")*(Calendário!Z10:Z49<>"OK")) -> 0 | D21: Conferências diferentes de OK.
B23: Resumo automático
B24: Aviso | C24: =IF(C7+C14=0,"Preencha as abas Rastro e Calendário",IF(C19>0,"Há atividade atrasada no calendário",IF(COUNTIF(Rastro!J8:J37,"O passo seguinte é de outro estudo")>0,"O fio pulou um passo: veja a aba Rastro",IF(C11>0,"Há passo do fio a completar",IF(C21>0,"Há atividade do calendário a completar","OK"))))) -> Preencha as abas Rastro e Calendário
B26: Atividades por situação
B27: Em dia | C27: =COUNTIF(Calendário!Y10:Y49,B27) -> 0
B28: Com atraso | C28: =COUNTIF(Calendário!Y10:Y49,B28) -> 0
B29: Ainda não começou | C29: =COUNTIF(Calendário!Y10:Y49,B29) -> 0

Sheet Checklist
B1: Checklist do sistema integrado
B2: Escolha o status de cada item na lista suspensa (coluna em amarelo-claro).
B4: # | C4: Item de verificação | D4: Status | E4: Observações
B5: 1 | C5: Cada estudo usado na organização tem dono e frequência definidos.
B6: 2 | C6: Existe um calendário anual com as atividades do sistema, os meses e os responsáveis.
B7: 3 | C7: O calendário é lido todo mês, e as atividades atrasadas ganham data nova.
B8: 4 | C8: As saídas de cada processo do sistema têm destino conhecido.
B9: 5 | C9: É possível seguir um problema importante do primeiro registro à decisão final.
B10: 6 | C10: Os registros citam uns aos outros: o RNC cita a reclamação, a ata cita o RNC.
B11: 7 | C11: Os intervalos longos entre um passo e o seguinte são percebidos e discutidos.
B12: 8 | C12: A análise crítica recebe o que os estudos produziram, e não só os indicadores.
B13: 9 | C13: As decisões da análise crítica voltam aos objetivos, aos recursos e aos riscos.
B14: 10 | C14: O que se aprende no fio vira lição incorporada.
B15: 11 | C15: A implantação seguiu uma ordem: base, planejamento, operação, verificação.
B16: 12 | C16: A equipe sabe explicar como o seu trabalho entra no sistema.
B18: Resumo automático
B19: Itens atendidos (Sim) | D19: =COUNTIF(D5:D16,"Sim") -> 0
B20: Itens parciais | D20: =COUNTIF(D5:D16,"Parcial") -> 0
B21: Itens não atendidos | D21: =COUNTIF(D5:D16,"Não") -> 0
B22: Itens sem resposta | D22: =COUNTBLANK(D5:D16) -> 12
B23: Percentual atendido | D23: =D19/ROWS(D5:D16) -> 0
B24: Situação | D24: =IF(D19=ROWS(D5:D16),"Validado",IF(D22>0,"Em andamento","Com pendências")) -> Em andamento

Sheet Exemplo 1 - Pizzaria
B1: Caso integrado
B2: Exemplo preenchido, para consulta. Use as abas Rastro e Calendário para a sua organização.
B4: Organização | D4: Pizzaria (loja com salão e delivery)
B5: Fio | D5: Os atrasos das noites de sexta e de sábado
B6: Origem | D6: 18% das entregas chegavam depois de 40 minutos em junho de 2026.
B7: Responsável pelo calendário | D7: Gerente da loja
B8: Ano e mês da leitura | D8: 2027 | E8: 6
B10: Rastro do fio
B11: Passo | C11: Data | D11: Estudo | E11: O que aconteceu | F11: Registro | G11: O que seguiu | H11: Próximo estudo | I11: Dias | J11: Conferência
B12: 1 | C12: 46188 | D12: PDCA | E12: Ciclo aberto: 18% das entregas depois de 40 minutos. Meta de 95% em 12 semanas. | F12: Ciclo PDCA dos atrasos | G12: O problema medido, para estratificar | H12: Pareto | I12: ="" | J12: =IF(COUNTA(C12:H12)=0,"",IF(C12="","Falta a data",IF(D12="","Falta o estudo",IF(E12="","Falta o que aconteceu",IF(F12="","Falta o registro",IF(AND(ISNUMBER(I12),I12<0),"Data antes do passo anterior",IF(COUNTA(C13:H13)=0,"OK",IF(G12="","Falta a saída",IF(H12="","Falta o próximo estudo",IF(H12<>D13,"O passo seguinte é de outro estudo","OK")))))))))) -> OK
B13: 2 | C13: 46213 | D13: Pareto | E13: Folha de verificação: em 46% dos atrasos, a pizza pronta esperou entregador, nas sextas e nos sábados. | F13: Folha de verificação de 15/06 a 09/07 | G13: Os dois motivos principais | H13: Ishikawa | I13: =IF(OR(C13="",C12=""),"",C13-C12) -> 25 | J13: =IF(COUNTA(C13:H13)=0,"",IF(C13="","Falta a data",IF(D13="","Falta o estudo",IF(E13="","Falta o que aconteceu",IF(F13="","Falta o registro",IF(AND(ISNUMBER(I13),I13<0),"Data antes do passo anterior",IF(COUNTA(C14:H14)=0,"OK",IF(G13="","Falta a saída",IF(H13="","Falta o próximo estudo",IF(H13<>D14,"O passo seguinte é de outro estudo","OK")))))))))) -> OK
B14: 3 | C14: 46220 | D14: Ishikawa | E14: Cinco causas confirmadas; quatro vão para o plano: escala igual todos os dias, pedidos sem agrupamento por bairro, endereço sem complemento e tempo medido só pela média do dia. A fila do forno fica para depois. | F14: Diagrama de 17/07/2026 | G14: Quatro causas para o plano | H14: 5W2H | I14: =IF(OR(C14="",C13=""),"",C14-C13) -> 7 | J14: =IF(COUNTA(C14:H14)=0,"",IF(C14="","Falta a data",IF(D14="","Falta o estudo",IF(E14="","Falta o que aconteceu",IF(F14="","Falta o registro",IF(AND(ISNUMBER(I14),I14<0),"Data antes do passo anterior",IF(COUNTA(C15:H15)=0,"OK",IF(G14="","Falta a saída",IF(H14="","Falta o próximo estudo",IF(H14<>D15,"O passo seguinte é de outro estudo","OK")))))))))) -> OK
B15: 4 | C15: 46227 | D15: 5W2H | E15: Seis ações, de A1 a A6: reforçar a escala no pico, tornar o complemento obrigatório, treinar a expedição, agrupar os pedidos por bairro, medir o tempo por faixa de horário e atualizar a instrução da expedição. | F15: Plano de ação de 24/07/2026 | G15: Ações com dono e prazo | H15: PDCA | I15: =IF(OR(C15="",C14=""),"",C15-C14) -> 7 | J15: =IF(COUNTA(C15:H15)=0,"",IF(C15="","Falta a data",IF(D15="","Falta o estudo",IF(E15="","Falta o que aconteceu",IF(F15="","Falta o registro",IF(AND(ISNUMBER(I15),I15<0),"Data antes do passo anterior",IF(COUNTA(C16:H16)=0,"OK",IF(G15="","Falta a saída",IF(H15="","Falta o próximo estudo",IF(H15<>D16,"O passo seguinte é de outro estudo","OK")))))))))) -> OK
B16: 5 | C16: 46271 | D16: PDCA | E16: Média de 95,5% nas semanas 9 a 12. Meta atingida, e a escala do pico vira padrão. | F16: Ciclo PDCA, etapa de padronização | G16: O segundo motivo, a fila do forno, fica para depois | H16: Matriz GUT | I16: =IF(OR(C16="",C15=""),"",C16-C15) -> 44 | J16: =IF(COUNTA(C16:H16)=0,"",IF(C16="","Falta a data",IF(D16="","Falta o estudo",IF(E16="","Falta o que aconteceu",IF(F16="","Falta o registro",IF(AND(ISNUMBER(I16),I16<0),"Data antes do passo anterior",IF(COUNTA(C17:H17)=0,"OK",IF(G16="","Falta a saída",IF(H16="","Falta o próximo estudo",IF(H16<>D17,"O passo seguinte é de outro estudo","OK")))))))))) -> OK
B17: 6 | C17: 46294 | D17: Matriz GUT | E17: O forno único no limite do pico entra na lista dos problemas do trimestre. | F17: Matriz GUT de 29/09/2026 | G17: Os problemas do trimestre, para acompanhar | H17: Indicadores | I17: =IF(OR(C17="",C16=""),"",C17-C16) -> 23 | J17: =IF(COUNTA(C17:H17)=0,"",IF(C17="","Falta a data",IF(D17="","Falta o estudo",IF(E17="","Falta o que aconteceu",IF(F17="","Falta o registro",IF(AND(ISNUMBER(I17),I17<0),"Data antes do passo anterior",IF(COUNTA(C18:H18)=0,"OK",IF(G17="","Falta a saída",IF(H17="","Falta o próximo estudo",IF(H17<>D18,"O passo seguinte é de outro estudo","OK")))))))))) -> OK
B18: 7 | C18: 46301 | D18: Indicadores | E18: Entregas em até 40 minutos: 95% em setembro, com o padrão mantido. | F18: Painel de indicadores, P1 | G18: O indicador estável e o forno no limite | H18: Análise crítica | I18: =IF(OR(C18="",C17=""),"",C18-C17) -> 7 | J18: =IF(COUNTA(C18:H18)=0,"",IF(C18="","Falta a data",IF(D18="","Falta o estudo",IF(E18="","Falta o que aconteceu",IF(F18="","Falta o registro",IF(AND(ISNUMBER(I18),I18<0),"Data antes do passo anterior",IF(COUNTA(C19:H19)=0,"OK",IF(G18="","Falta a saída",IF(H18="","Falta o próximo estudo",IF(H18<>D19,"O passo seguinte é de outro estudo","OK")))))))))) -> OK
B19: 8 | C19: 46370 | D19: Análise crítica | E19: Decisões: atendente de salão nas noites de pico, e um segundo pizzaiolo treinado no forno. | F19: Ata da análise crítica de 14/12/2026 | G19: Objetivos e metas para 2027 | H19: Objetivos da qualidade | I19: =IF(OR(C19="",C18=""),"",C19-C18) -> 69 | J19: =IF(COUNTA(C19:H19)=0,"",IF(C19="","Falta a data",IF(D19="","Falta o estudo",IF(E19="","Falta o que aconteceu",IF(F19="","Falta o registro",IF(AND(ISNUMBER(I19),I19<0),"Data antes do passo anterior",IF(COUNTA(C20:H20)=0,"OK",IF(G19="","Falta a saída",IF(H19="","Falta o próximo estudo",IF(H19<>D20,"O passo seguinte é de outro estudo","OK")))))))))) -> OK
B20: 9 | C20: 46437 | D20: Objetivos da qualidade | E20: Objetivo O1: 96% das entregas em até 40 minutos. Ações: rever a escala com os condomínios novos e estudar o segundo forno. | F20: Objetivos de 2027, O1 | G20: A escala revista em março | H20: Recursos e infraestrutura | I20: =IF(OR(C20="",C19=""),"",C20-C19) -> 67 | J20: =IF(COUNTA(C20:H20)=0,"",IF(C20="","Falta a data",IF(D20="","Falta o estudo",IF(E20="","Falta o que aconteceu",IF(F20="","Falta o registro",IF(AND(ISNUMBER(I20),I20<0),"Data antes do passo anterior",IF(COUNTA(C21:H21)=0,"OK",IF(G20="","Falta a saída",IF(H20="","Falta o próximo estudo",IF(H20<>D21,"O passo seguinte é de outro estudo","OK")))))))))) -> OK
B21: 10 | C21: 46493 | D21: Recursos e infraestrutura | E21: Na sexta, pico de 29 entregas por hora para 8 entregadores: faltam 2, mesmo com os extras de março. Falta também um forneiro. | F21: Dimensionamento das pessoas no pico | G21: O forno e a escala como gargalos da sexta | H21: Conhecimento e pós-entrega | I21: =IF(OR(C21="",C20=""),"",C21-C20) -> 56 | J21: =IF(COUNTA(C21:H21)=0,"",IF(C21="","Falta a data",IF(D21="","Falta o estudo",IF(E21="","Falta o que aconteceu",IF(F21="","Falta o registro",IF(AND(ISNUMBER(I21),I21<0),"Data antes do passo anterior",IF(COUNTA(C22:H22)=0,"OK",IF(G21="","Falta a saída",IF(H21="","Falta o próximo estudo",IF(H21<>D22,"O passo seguinte é de outro estudo","OK")))))))))) -> OK
B22: 11 | C22: 46538 | D22: Conhecimento e pós-entrega | E22: A regulagem do forno está só na cabeça do pizzaiolo líder, que sai em agosto. Transferência planejada até 30/06. | F22: Mapa do conhecimento, K-01 | G22: O risco do forno, com prazo | H22: Análise crítica | I22: =IF(OR(C22="",C21=""),"",C22-C21) -> 45 | J22: =IF(COUNTA(C22:H22)=0,"",IF(C22="","Falta a data",IF(D22="","Falta o estudo",IF(E22="","Falta o que aconteceu",IF(F22="","Falta o registro",IF(AND(ISNUMBER(I22),I22<0),"Data antes do passo anterior",IF(COUNTA(C23:H23)=0,"OK",IF(G22="","Falta a saída",IF(H22="","Falta o próximo estudo",IF(H22<>D23,"O passo seguinte é de outro estudo","OK")))))))))) -> OK
B23: 12 | C23: 46552 | D23: Análise crítica | E23: Entradas: o objetivo O1, a falta de gente no pico e a saída do pizzaiolo líder. Decisões: segundo forno e escala nova da sexta. | F23: Ata da análise crítica de 14/06/2027 | I23: =IF(OR(C23="",C22=""),"",C23-C22) -> 14 | J23: =IF(COUNTA(C23:H23)=0,"",IF(C23="","Falta a data",IF(D23="","Falta o estudo",IF(E23="","Falta o que aconteceu",IF(F23="","Falta o registro",IF(AND(ISNUMBER(I23),I23<0),"Data antes do passo anterior",IF(COUNTA(C24:H24)=0,"OK",IF(G23="","Falta a saída",IF(H23="","Falta o próximo estudo",IF(H23<>D24,"O passo seguinte é de outro estudo","OK")))))))))) -> OK
B25: Calendário do sistema
B26: # | C26: Atividade | D26: Estudo | E26: Requisito | F26: Responsável | G26: Frequência | H26: Início | I26: Jan | J26: Fev | K26: Mar | L26: Abr | M26: Mai | N26: Jun | O26: Jul | P26: Ago | Q26: Set | R26: Out | S26: Nov | T26: Dez | U26: Previstas | V26: Feitas | W26: Atrasadas | X26: Fora | Y26: Situação | Z26: Conferência | AA26: A cada
I27: 1 | J27: 2 | K27: 3 | L27: 4 | M27: 5 | N27: 6 | O27: 7 | P27: 8 | Q27: 9 | R27: 10 | S27: 11 | T27: 12
B28: 1 | C28: Reunião de indicadores | D28: Indicadores | E28: 9.1.3 | F28: Gerente da loja | G28: Mensal | H28: 1 | I28: X | J28: X | K28: X | M28: X | N28: X | U28: =IF(OR(C28="",AA28="",H28="",$E$8=""),"",IF(OR(H28<1,H28>12),"",SUMPRODUCT(($I$27:$T$27>=$H28)*(MOD($I$27:$T$27-$H28,$AA28)=0)*($I$27:$T$27<=$E$8)))) -> 6 | V28: =IF(U28="","",SUMPRODUCT(($I$27:$T$27>=$H28)*(MOD($I$27:$T$27-$H28,$AA28)=0)*($I$27:$T$27<=$E$8)*(I28:T28<>""))) -> 5 | W28: =IF(U28="","",U28-V28) -> 1 | X28: =IF(U28="","",SUMPRODUCT((1-($I$27:$T$27>=$H28)*(MOD($I$27:$T$27-$H28,$AA28)=0))*(I28:T28<>""))) -> 0 | Y28: =IF(U28="","",IF(U28=0,"Ainda não começou",IF(W28>0,"Com atraso","Em dia"))) -> Com atraso | Z28: =IF(C28="","",IF(D28="","Falta o estudo",IF(F28="","Falta o responsável",IF(G28="","Falta a frequência",IF(H28="","Falta o mês de início",IF(OR(H28<1,H28>12),"Mês de início fora de 1 a 12","OK")))))) -> OK | AA28: =IF(G28="","",IFERROR(CHOOSE(MATCH(G28,{"Mensal","Bimestral","Trimestral","Semestral","Anual"},0),1,2,3,6,12),"")) -> 1
B29: 2 | C29: Verificação dos termômetros e da balança | D29: Calibração | E29: 7.1.5 | F29: Pizzaiolo líder | G29: Mensal | H29: 1 | I29: X | J29: X | K29: X | L29: X | M29: X | N29: X | U29: =IF(OR(C29="",AA29="",H29="",$E$8=""),"",IF(OR(H29<1,H29>12),"",SUMPRODUCT(($I$27:$T$27>=$H29)*(MOD($I$27:$T$27-$H29,$AA29)=0)*($I$27:$T$27<=$E$8)))) -> 6 | V29: =IF(U29="","",SUMPRODUCT(($I$27:$T$27>=$H29)*(MOD($I$27:$T$27-$H29,$AA29)=0)*($I$27:$T$27<=$E$8)*(I29:T29<>""))) -> 6 | W29: =IF(U29="","",U29-V29) -> 0 | X29: =IF(U29="","",SUMPRODUCT((1-($I$27:$T$27>=$H29)*(MOD($I$27:$T$27-$H29,$AA29)=0))*(I29:T29<>""))) -> 0 | Y29: =IF(U29="","",IF(U29=0,"Ainda não começou",IF(W29>0,"Com atraso","Em dia"))) -> Em dia | Z29: =IF(C29="","",IF(D29="","Falta o estudo",IF(F29="","Falta o responsável",IF(G29="","Falta a frequência",IF(H29="","Falta o mês de início",IF(OR(H29<1,H29>12),"Mês de início fora de 1 a 12","OK")))))) -> OK | AA29: =IF(G29="","",IFERROR(CHOOSE(MATCH(G29,{"Mensal","Bimestral","Trimestral","Semestral","Anual"},0),1,2,3,6,12),"")) -> 1
B30: 3 | C30: Revisão do forno e das motos | D30: Recursos e infraestrutura | E30: 7.1.3 | F30: Gerente da loja | G30: Mensal | H30: 1 | I30: X | J30: X | K30: X | L30: X | M30: X | N30: X | U30: =IF(OR(C30="",AA30="",H30="",$E$8=""),"",IF(OR(H30<1,H30>12),"",SUMPRODUCT(($I$27:$T$27>=$H30)*(MOD($I$27:$T$27-$H30,$AA30)=0)*($I$27:$T$27<=$E$8)))) -> 6 | V30: =IF(U30="","",SUMPRODUCT(($I$27:$T$27>=$H30)*(MOD($I$27:$T$27-$H30,$AA30)=0)*($I$27:$T$27<=$E$8)*(I30:T30<>""))) -> 6 | W30: =IF(U30="","",U30-V30) -> 0 | X30: =IF(U30="","",SUMPRODUCT((1-($I$27:$T$27>=$H30)*(MOD($I$27:$T$27-$H30,$AA30)=0))*(I30:T30<>""))) -> 0 | Y30: =IF(U30="","",IF(U30=0,"Ainda não começou",IF(W30>0,"Com atraso","Em dia"))) -> Em dia | Z30: =IF(C30="","",IF(D30="","Falta o estudo",IF(F30="","Falta o responsável",IF(G30="","Falta a frequência",IF(H30="","Falta o mês de início",IF(OR(H30<1,H30>12),"Mês de início fora de 1 a 12","OK")))))) -> OK | AA30: =IF(G30="","",IFERROR(CHOOSE(MATCH(G30,{"Mensal","Bimestral","Trimestral","Semestral","Anual"},0),1,2,3,6,12),"")) -> 1
B31: 4 | C31: Revisão da câmara fria | D31: Recursos e infraestrutura | E31: 7.1.3 | F31: Pizzaiolo líder | G31: Trimestral | H31: 1 | I31: X | U31: =IF(OR(C31="",AA31="",H31="",$E$8=""),"",IF(OR(H31<1,H31>12),"",SUMPRODUCT(($I$27:$T$27>=$H31)*(MOD($I$27:$T$27-$H31,$AA31)=0)*($I$27:$T$27<=$E$8)))) -> 2 | V31: =IF(U31="","",SUMPRODUCT(($I$27:$T$27>=$H31)*(MOD($I$27:$T$27-$H31,$AA31)=0)*($I$27:$T$27<=$E$8)*(I31:T31<>""))) -> 1 | W31: =IF(U31="","",U31-V31) -> 1 | X31: =IF(U31="","",SUMPRODUCT((1-($I$27:$T$27>=$H31)*(MOD($I$27:$T$27-$H31,$AA31)=0))*(I31:T31<>""))) -> 0 | Y31: =IF(U31="","",IF(U31=0,"Ainda não começou",IF(W31>0,"Com atraso","Em dia"))) -> Com atraso | Z31: =IF(C31="","",IF(D31="","Falta o estudo",IF(F31="","Falta o responsável",IF(G31="","Falta a frequência",IF(H31="","Falta o mês de início",IF(OR(H31<1,H31>12),"Mês de início fora de 1 a 12","OK")))))) -> OK | AA31: =IF(G31="","",IFERROR(CHOOSE(MATCH(G31,{"Mensal","Bimestral","Trimestral","Semestral","Anual"},0),1,2,3,6,12),"")) -> 3
B32: 5 | C32: Ronda do aprendizado | D32: Conhecimento e pós-entrega | E32: 7.1.6 · 8.5.5 | F32: Gerente da loja | G32: Mensal | H32: 5 | M32: X | N32: X | U32: =IF(OR(C32="",AA32="",H32="",$E$8=""),"",IF(OR(H32<1,H32>12),"",SUMPRODUCT(($I$27:$T$27>=$H32)*(MOD($I$27:$T$27-$H32,$AA32)=0)*($I$27:$T$27<=$E$8)))) -> 2 | V32: =IF(U32="","",SUMPRODUCT(($I$27:$T$27>=$H32)*(MOD($I$27:$T$27-$H32,$AA32)=0)*($I$27:$T$27<=$E$8)*(I32:T32<>""))) -> 2 | W32: =IF(U32="","",U32-V32) -> 0 | X32: =IF(U32="","",SUMPRODUCT((1-($I$27:$T$27>=$H32)*(MOD($I$27:$T$27-$H32,$AA32)=0))*(I32:T32<>""))) -> 0 | Y32: =IF(U32="","",IF(U32=0,"Ainda não começou",IF(W32>0,"Com atraso","Em dia"))) -> Em dia | Z32: =IF(C32="","",IF(D32="","Falta o estudo",IF(F32="","Falta o responsável",IF(G32="","Falta a frequência",IF(H32="","Falta o mês de início",IF(OR(H32<1,H32>12),"Mês de início fora de 1 a 12","OK")))))) -> OK | AA32: =IF(G32="","",IFERROR(CHOOSE(MATCH(G32,{"Mensal","Bimestral","Trimestral","Semestral","Anual"},0),1,2,3,6,12),"")) -> 1
B33: 6 | C33: Pesquisa de satisfação | D33: Satisfação do cliente | E33: 9.1.2 | F33: Atendente líder | G33: Trimestral | H33: 2 | J33: X | M33: X | U33: =IF(OR(C33="",AA33="",H33="",$E$8=""),"",IF(OR(H33<1,H33>12),"",SUMPRODUCT(($I$27:$T$27>=$H33)*(MOD($I$27:$T$27-$H33,$AA33)=0)*($I$27:$T$27<=$E$8)))) -> 2 | V33: =IF(U33="","",SUMPRODUCT(($I$27:$T$27>=$H33)*(MOD($I$27:$T$27-$H33,$AA33)=0)*($I$27:$T$27<=$E$8)*(I33:T33<>""))) -> 2 | W33: =IF(U33="","",U33-V33) -> 0 | X33: =IF(U33="","",SUMPRODUCT((1-($I$27:$T$27>=$H33)*(MOD($I$27:$T$27-$H33,$AA33)=0))*(I33:T33<>""))) -> 0 | Y33: =IF(U33="","",IF(U33=0,"Ainda não começou",IF(W33>0,"Com atraso","Em dia"))) -> Em dia | Z33: =IF(C33="","",IF(D33="","Falta o estudo",IF(F33="","Falta o responsável",IF(G33="","Falta a frequência",IF(H33="","Falta o mês de início",IF(OR(H33<1,H33>12),"Mês de início fora de 1 a 12","OK")))))) -> OK | AA33: =IF(G33="","",IFERROR(CHOOSE(MATCH(G33,{"Mensal","Bimestral","Trimestral","Semestral","Anual"},0),1,2,3,6,12),"")) -> 3
B34: 7 | C34: Acompanhamento dos objetivos | D34: Objetivos da qualidade | E34: 6.2 | F34: Gerente da loja | G34: Trimestral | H34: 2 | J34: X | M34: X | U34: =IF(OR(C34="",AA34="",H34="",$E$8=""),"",IF(OR(H34<1,H34>12),"",SUMPRODUCT(($I$27:$T$27>=$H34)*(MOD($I$27:$T$27-$H34,$AA34)=0)*($I$27:$T$27<=$E$8)))) -> 2 | V34: =IF(U34="","",SUMPRODUCT(($I$27:$T$27>=$H34)*(MOD($I$27:$T$27-$H34,$AA34)=0)*($I$27:$T$27<=$E$8)*(I34:T34<>""))) -> 2 | W34: =IF(U34="","",U34-V34) -> 0 | X34: =IF(U34="","",SUMPRODUCT((1-($I$27:$T$27>=$H34)*(MOD($I$27:$T$27-$H34,$AA34)=0))*(I34:T34<>""))) -> 0 | Y34: =IF(U34="","",IF(U34=0,"Ainda não começou",IF(W34>0,"Com atraso","Em dia"))) -> Em dia | Z34: =IF(C34="","",IF(D34="","Falta o estudo",IF(F34="","Falta o responsável",IF(G34="","Falta a frequência",IF(H34="","Falta o mês de início",IF(OR(H34<1,H34>12),"Mês de início fora de 1 a 12","OK")))))) -> OK | AA34: =IF(G34="","",IFERROR(CHOOSE(MATCH(G34,{"Mensal","Bimestral","Trimestral","Semestral","Anual"},0),1,2,3,6,12),"")) -> 3
B35: 8 | C35: Escolha dos problemas do trimestre | D35: Matriz GUT | E35: 10.1 | F35: Gerente da loja | G35: Trimestral | H35: 1 | I35: X | L35: X | U35: =IF(OR(C35="",AA35="",H35="",$E$8=""),"",IF(OR(H35<1,H35>12),"",SUMPRODUCT(($I$27:$T$27>=$H35)*(MOD($I$27:$T$27-$H35,$AA35)=0)*($I$27:$T$27<=$E$8)))) -> 2 | V35: =IF(U35="","",SUMPRODUCT(($I$27:$T$27>=$H35)*(MOD($I$27:$T$27-$H35,$AA35)=0)*($I$27:$T$27<=$E$8)*(I35:T35<>""))) -> 2 | W35: =IF(U35="","",U35-V35) -> 0 | X35: =IF(U35="","",SUMPRODUCT((1-($I$27:$T$27>=$H35)*(MOD($I$27:$T$27-$H35,$AA35)=0))*(I35:T35<>""))) -> 0 | Y35: =IF(U35="","",IF(U35=0,"Ainda não começou",IF(W35>0,"Com atraso","Em dia"))) -> Em dia | Z35: =IF(C35="","",IF(D35="","Falta o estudo",IF(F35="","Falta o responsável",IF(G35="","Falta a frequência",IF(H35="","Falta o mês de início",IF(OR(H35<1,H35>12),"Mês de início fora de 1 a 12","OK")))))) -> OK | AA35: =IF(G35="","",IFERROR(CHOOSE(MATCH(G35,{"Mensal","Bimestral","Trimestral","Semestral","Anual"},0),1,2,3,6,12),"")) -> 3
B36: 9 | C36: Avaliação dos fornecedores | D36: Avaliação de fornecedores | E36: 8.4 | F36: Gerente da loja | G36: Semestral | H36: 2 | J36: X | U36: =IF(OR(C36="",AA36="",H36="",$E$8=""),"",IF(OR(H36<1,H36>12),"",SUMPRODUCT(($I$27:$T$27>=$H36)*(MOD($I$27:$T$27-$H36,$AA36)=0)*($I$27:$T$27<=$E$8)))) -> 1 | V36: =IF(U36="","",SUMPRODUCT(($I$27:$T$27>=$H36)*(MOD($I$27:$T$27-$H36,$AA36)=0)*($I$27:$T$27<=$E$8)*(I36:T36<>""))) -> 1 | W36: =IF(U36="","",U36-V36) -> 0 | X36: =IF(U36="","",SUMPRODUCT((1-($I$27:$T$27>=$H36)*(MOD($I$27:$T$27-$H36,$AA36)=0))*(I36:T36<>""))) -> 0 | Y36: =IF(U36="","",IF(U36=0,"Ainda não começou",IF(W36>0,"Com atraso","Em dia"))) -> Em dia | Z36: =IF(C36="","",IF(D36="","Falta o estudo",IF(F36="","Falta o responsável",IF(G36="","Falta a frequência",IF(H36="","Falta o mês de início",IF(OR(H36<1,H36>12),"Mês de início fora de 1 a 12","OK")))))) -> OK | AA36: =IF(G36="","",IFERROR(CHOOSE(MATCH(G36,{"Mensal","Bimestral","Trimestral","Semestral","Anual"},0),1,2,3,6,12),"")) -> 6
B37: 10 | C37: Revisão da matriz de riscos | D37: Matriz de riscos | E37: 6.1 | F37: Gerente da loja | G37: Semestral | H37: 4 | L37: X | U37: =IF(OR(C37="",AA37="",H37="",$E$8=""),"",IF(OR(H37<1,H37>12),"",SUMPRODUCT(($I$27:$T$27>=$H37)*(MOD($I$27:$T$27-$H37,$AA37)=0)*($I$27:$T$27<=$E$8)))) -> 1 | V37: =IF(U37="","",SUMPRODUCT(($I$27:$T$27>=$H37)*(MOD($I$27:$T$27-$H37,$AA37)=0)*($I$27:$T$27<=$E$8)*(I37:T37<>""))) -> 1 | W37: =IF(U37="","",U37-V37) -> 0 | X37: =IF(U37="","",SUMPRODUCT((1-($I$27:$T$27>=$H37)*(MOD($I$27:$T$27-$H37,$AA37)=0))*(I37:T37<>""))) -> 0 | Y37: =IF(U37="","",IF(U37=0,"Ainda não começou",IF(W37>0,"Com atraso","Em dia"))) -> Em dia | Z37: =IF(C37="","",IF(D37="","Falta o estudo",IF(F37="","Falta o responsável",IF(G37="","Falta a frequência",IF(H37="","Falta o mês de início",IF(OR(H37<1,H37>12),"Mês de início fora de 1 a 12","OK")))))) -> OK | AA37: =IF(G37="","",IFERROR(CHOOSE(MATCH(G37,{"Mensal","Bimestral","Trimestral","Semestral","Anual"},0),1,2,3,6,12),"")) -> 6
B38: 11 | C38: Auditoria interna | D38: Auditoria interna | E38: 9.2 | F38: Atendente líder | G38: Semestral | H38: 3 | K38: X | U38: =IF(OR(C38="",AA38="",H38="",$E$8=""),"",IF(OR(H38<1,H38>12),"",SUMPRODUCT(($I$27:$T$27>=$H38)*(MOD($I$27:$T$27-$H38,$AA38)=0)*($I$27:$T$27<=$E$8)))) -> 1 | V38: =IF(U38="","",SUMPRODUCT(($I$27:$T$27>=$H38)*(MOD($I$27:$T$27-$H38,$AA38)=0)*($I$27:$T$27<=$E$8)*(I38:T38<>""))) -> 1 | W38: =IF(U38="","",U38-V38) -> 0 | X38: =IF(U38="","",SUMPRODUCT((1-($I$27:$T$27>=$H38)*(MOD($I$27:$T$27-$H38,$AA38)=0))*(I38:T38<>""))) -> 0 | Y38: =IF(U38="","",IF(U38=0,"Ainda não começou",IF(W38>0,"Com atraso","Em dia"))) -> Em dia | Z38: =IF(C38="","",IF(D38="","Falta o estudo",IF(F38="","Falta o responsável",IF(G38="","Falta a frequência",IF(H38="","Falta o mês de início",IF(OR(H38<1,H38>12),"Mês de início fora de 1 a 12","OK")))))) -> OK | AA38: =IF(G38="","",IFERROR(CHOOSE(MATCH(G38,{"Mensal","Bimestral","Trimestral","Semestral","Anual"},0),1,2,3,6,12),"")) -> 6
B39: 12 | C39: Matriz de competências e treinamento | D39: Matriz de competências | E39: 7.2 | F39: Gerente da loja | G39: Semestral | H39: 1 | I39: X | U39: =IF(OR(C39="",AA39="",H39="",$E$8=""),"",IF(OR(H39<1,H39>12),"",SUMPRODUCT(($I$27:$T$27>=$H39)*(MOD($I$27:$T$27-$H39,$AA39)=0)*($I$27:$T$27<=$E$8)))) -> 1 | V39: =IF(U39="","",SUMPRODUCT(($I$27:$T$27>=$H39)*(MOD($I$27:$T$27-$H39,$AA39)=0)*($I$27:$T$27<=$E$8)*(I39:T39<>""))) -> 1 | W39: =IF(U39="","",U39-V39) -> 0 | X39: =IF(U39="","",SUMPRODUCT((1-($I$27:$T$27>=$H39)*(MOD($I$27:$T$27-$H39,$AA39)=0))*(I39:T39<>""))) -> 0 | Y39: =IF(U39="","",IF(U39=0,"Ainda não começou",IF(W39>0,"Com atraso","Em dia"))) -> Em dia | Z39: =IF(C39="","",IF(D39="","Falta o estudo",IF(F39="","Falta o responsável",IF(G39="","Falta a frequência",IF(H39="","Falta o mês de início",IF(OR(H39<1,H39>12),"Mês de início fora de 1 a 12","OK")))))) -> OK | AA39: =IF(G39="","",IFERROR(CHOOSE(MATCH(G39,{"Mensal","Bimestral","Trimestral","Semestral","Anual"},0),1,2,3,6,12),"")) -> 6
B40: 13 | C40: Análise crítica pela direção | D40: Análise crítica | E40: 9.3 | F40: Dono da loja | G40: Semestral | H40: 6 | N40: X | U40: =IF(OR(C40="",AA40="",H40="",$E$8=""),"",IF(OR(H40<1,H40>12),"",SUMPRODUCT(($I$27:$T$27>=$H40)*(MOD($I$27:$T$27-$H40,$AA40)=0)*($I$27:$T$27<=$E$8)))) -> 1 | V40: =IF(U40="","",SUMPRODUCT(($I$27:$T$27>=$H40)*(MOD($I$27:$T$27-$H40,$AA40)=0)*($I$27:$T$27<=$E$8)*(I40:T40<>""))) -> 1 | W40: =IF(U40="","",U40-V40) -> 0 | X40: =IF(U40="","",SUMPRODUCT((1-($I$27:$T$27>=$H40)*(MOD($I$27:$T$27-$H40,$AA40)=0))*(I40:T40<>""))) -> 0 | Y40: =IF(U40="","",IF(U40=0,"Ainda não começou",IF(W40>0,"Com atraso","Em dia"))) -> Em dia | Z40: =IF(C40="","",IF(D40="","Falta o estudo",IF(F40="","Falta o responsável",IF(G40="","Falta a frequência",IF(H40="","Falta o mês de início",IF(OR(H40<1,H40>12),"Mês de início fora de 1 a 12","OK")))))) -> OK | AA40: =IF(G40="","",IFERROR(CHOOSE(MATCH(G40,{"Mensal","Bimestral","Trimestral","Semestral","Anual"},0),1,2,3,6,12),"")) -> 6
B41: 14 | C41: Revisão da lista mestra de documentos | D41: Informação documentada | E41: 7.5 | F41: Gerente da loja | G41: Anual | H41: 3 | U41: =IF(OR(C41="",AA41="",H41="",$E$8=""),"",IF(OR(H41<1,H41>12),"",SUMPRODUCT(($I$27:$T$27>=$H41)*(MOD($I$27:$T$27-$H41,$AA41)=0)*($I$27:$T$27<=$E$8)))) -> 1 | V41: =IF(U41="","",SUMPRODUCT(($I$27:$T$27>=$H41)*(MOD($I$27:$T$27-$H41,$AA41)=0)*($I$27:$T$27<=$E$8)*(I41:T41<>""))) -> 0 | W41: =IF(U41="","",U41-V41) -> 1 | X41: =IF(U41="","",SUMPRODUCT((1-($I$27:$T$27>=$H41)*(MOD($I$27:$T$27-$H41,$AA41)=0))*(I41:T41<>""))) -> 0 | Y41: =IF(U41="","",IF(U41=0,"Ainda não começou",IF(W41>0,"Com atraso","Em dia"))) -> Com atraso | Z41: =IF(C41="","",IF(D41="","Falta o estudo",IF(F41="","Falta o responsável",IF(G41="","Falta a frequência",IF(H41="","Falta o mês de início",IF(OR(H41<1,H41>12),"Mês de início fora de 1 a 12","OK")))))) -> OK | AA41: =IF(G41="","",IFERROR(CHOOSE(MATCH(G41,{"Mensal","Bimestral","Trimestral","Semestral","Anual"},0),1,2,3,6,12),"")) -> 12
B42: 15 | C42: SWOT e partes interessadas | D42: Matriz SWOT | E42: 4.1 · 4.2 | F42: Dono da loja | G42: Anual | H42: 9 | U42: =IF(OR(C42="",AA42="",H42="",$E$8=""),"",IF(OR(H42<1,H42>12),"",SUMPRODUCT(($I$27:$T$27>=$H42)*(MOD($I$27:$T$27-$H42,$AA42)=0)*($I$27:$T$27<=$E$8)))) -> 0 | V42: =IF(U42="","",SUMPRODUCT(($I$27:$T$27>=$H42)*(MOD($I$27:$T$27-$H42,$AA42)=0)*($I$27:$T$27<=$E$8)*(I42:T42<>""))) -> 0 | W42: =IF(U42="","",U42-V42) -> 0 | X42: =IF(U42="","",SUMPRODUCT((1-($I$27:$T$27>=$H42)*(MOD($I$27:$T$27-$H42,$AA42)=0))*(I42:T42<>""))) -> 0 | Y42: =IF(U42="","",IF(U42=0,"Ainda não começou",IF(W42>0,"Com atraso","Em dia"))) -> Ainda não começou | Z42: =IF(C42="","",IF(D42="","Falta o estudo",IF(F42="","Falta o responsável",IF(G42="","Falta a frequência",IF(H42="","Falta o mês de início",IF(OR(H42<1,H42>12),"Mês de início fora de 1 a 12","OK")))))) -> OK | AA42: =IF(G42="","",IFERROR(CHOOSE(MATCH(G42,{"Mensal","Bimestral","Trimestral","Semestral","Anual"},0),1,2,3,6,12),"")) -> 12
B44: Resumo automático
...

Sheet Exemplo 2 - Indústria
B1: Caso integrado
B2: Exemplo preenchido, para consulta. Use as abas Rastro e Calendário para a sua organização.
B4: Organização | D4: Indústria de embalagens plásticas
B5: Fio | D5: O filme fino da extrusora 3
B6: Origem | D6: Sétima reclamação do cliente A em 2026, a quinta por espessura.
B7: Responsável pelo calendário | D7: Coordenador da Qualidade
B8: Ano e mês da leitura | D8: 2027 | E8: 9
B10: Rastro do fio
B11: Passo | C11: Data | D11: Estudo | E11: O que aconteceu | F11: Registro | G11: O que seguiu | H11: Próximo estudo | I11: Dias | J11: Conferência
B12: 1 | C12: 46279 | D12: Satisfação do cliente | E12: Cliente A reclama de espessura fora: a sétima reclamação do ano, a quinta pelo mesmo motivo. | F12: Registro de reclamação de 14/09/2026 | G12: A reclamação, para análise de causa | H12: Não conformidade | I12: ="" | J12: =IF(COUNTA(C12:H12)=0,"",IF(C12="","Falta a data",IF(D12="","Falta o estudo",IF(E12="","Falta o que aconteceu",IF(F12="","Falta o registro",IF(AND(ISNUMBER(I12),I12<0),"Data antes do passo anterior",IF(COUNTA(C13:H13)=0,"OK",IF(G12="","Falta a saída",IF(H12="","Falta o próximo estudo",IF(H12<>D13,"O passo seguinte é de outro estudo","OK")))))))))) -> OK
B13: 2 | C13: 46288 | D13: Não conformidade | E13: Causa: variação de espessura na extrusora 3, sem medidor em linha. Inspeção de 100% das bobinas do cliente A. | F13: RNC 2026-32 | G13: A proposta dos dois medidores de espessura em linha | H13: Análise crítica | I13: =IF(OR(C13="",C12=""),"",C13-C12) -> 9 | J13: =IF(COUNTA(C13:H13)=0,"",IF(C13="","Falta a data",IF(D13="","Falta o estudo",IF(E13="","Falta o que aconteceu",IF(F13="","Falta o registro",IF(AND(ISNUMBER(I13),I13<0),"Data antes do passo anterior",IF(COUNTA(C14:H14)=0,"OK",IF(G13="","Falta a saída",IF(H13="","Falta o próximo estudo",IF(H13<>D14,"O passo seguinte é de outro estudo","OK")))))))))) -> OK
B14: 3 | C14: 46436 | D14: Análise crítica | E14: Aprova os dois medidores em linha e cobra a homologação do segundo fornecedor de resina, ação da matriz de riscos. | F14: Ata da análise crítica de 18/02/2027 | G14: A homologação, com prazo | H14: Avaliação de fornecedores | I14: =IF(OR(C14="",C13=""),"",C14-C13) -> 148 | J14: =IF(COUNTA(C14:H14)=0,"",IF(C14="","Falta a data",IF(D14="","Falta o estudo",IF(E14="","Falta o que aconteceu",IF(F14="","Falta o registro",IF(AND(ISNUMBER(I14),I14<0),"Data antes do passo anterior",IF(COUNTA(C15:H15)=0,"OK",IF(G14="","Falta a saída",IF(H14="","Falta o próximo estudo",IF(H14<>D15,"O passo seguinte é de outro estudo","OK")))))))))) -> OK
B15: 4 | C15: 46475 | D15: Avaliação de fornecedores | E15: Segundo fornecedor de resina homologado. | F15: Registro de homologação de 29/03/2027 | G15: A resina nova liberada para uso | H15: Controle de produção | I15: =IF(OR(C15="",C14=""),"",C15-C14) -> 39 | J15: =IF(COUNTA(C15:H15)=0,"",IF(C15="","Falta a data",IF(D15="","Falta o estudo",IF(E15="","Falta o que aconteceu",IF(F15="","Falta o registro",IF(AND(ISNUMBER(I15),I15<0),"Data antes do passo anterior",IF(COUNTA(C16:H16)=0,"OK",IF(G15="","Falta a saída",IF(H15="","Falta o próximo estudo",IF(H15<>D16,"O passo seguinte é de outro estudo","OK")))))))))) -> OK
B16: 5 | C16: 46521 | D16: Controle de produção | E16: Mudança registrada: resina do segundo fornecedor na extrusora 3, depois do lote piloto 127, de duas bobinas; o lote 135 é o primeiro da produção regular. | F16: Registro de mudança de 14/05/2027 | G16: O lote 135, para liberar | H16: Liberação e produto não conforme | I16: =IF(OR(C16="",C15=""),"",C16-C15) -> 46 | J16: =IF(COUNTA(C16:H16)=0,"",IF(C16="","Falta a data",IF(D16="","Falta o estudo",IF(E16="","Falta o que aconteceu",IF(F16="","Falta o registro",IF(AND(ISNUMBER(I16),I16<0),"Data antes do passo anterior",IF(COUNTA(C17:H17)=0,"OK",IF(G16="","Falta a saída",IF(H16="","Falta o próximo estudo",IF(H16<>D17,"O passo seguinte é de outro estudo","OK")))))))))) -> OK
B17: 6 | C17: 46521 | D17: Liberação e produto não conforme | E17: Bobina 1 com 37,4 µm, segregada. Bobina 2 com 39,1 µm, liberada e embarcada em 17/05. | F17: Registro de produto não conforme 2027-19 | G17: A bobina 2, no cliente A | H17: Satisfação do cliente | I17: =IF(OR(C17="",C16=""),"",C17-C16) -> 0 | J17: =IF(COUNTA(C17:H17)=0,"",IF(C17="","Falta a data",IF(D17="","Falta o estudo",IF(E17="","Falta o que aconteceu",IF(F17="","Falta o registro",IF(AND(ISNUMBER(I17),I17<0),"Data antes do passo anterior",IF(COUNTA(C18:H18)=0,"OK",IF(G17="","Falta a saída",IF(H17="","Falta o próximo estudo",IF(H17<>D18,"O passo seguinte é de outro estudo","OK")))))))))) -> OK
B18: 7 | C18: 46531 | D18: Satisfação do cliente | E18: Cliente A reclama de filme fino no lote 135. Bobina recolhida e reposta em 26/05. | F18: Registro de produto não conforme 2027-22 | G18: A dúvida sobre a medição | H18: Calibração | I18: =IF(OR(C18="",C17=""),"",C18-C17) -> 10 | J18: =IF(COUNTA(C18:H18)=0,"",IF(C18="","Falta a data",IF(D18="","Falta o estudo",IF(E18="","Falta o que aconteceu",IF(F18="","Falta o registro",IF(AND(ISNUMBER(I18),I18<0),"Data antes do passo anterior",IF(COUNTA(C19:H19)=0,"OK",IF(G18="","Falta a saída",IF(H18="","Falta o próximo estudo",IF(H18<>D19,"O passo seguinte é de outro estudo","OK")))))))))) -> OK
B19: 8 | C19: 46550 | D19: Calibração | E19: O micrômetro marca 1,6 µm a mais. Medições corrigidas desde 10/01: 6 bobinas abaixo de 38 µm, 2 entregues. Clientes informados em 14/06. | F19: Registro de verificação FV-12 | G19: A lição sobre reclamação de espessura | H19: Conhecimento e pós-entrega | I19: =IF(OR(C19="",C18=""),"",C19-C18) -> 19 | J19: =IF(COUNTA(C19:H19)=0,"",IF(C19="","Falta a data",IF(D19="","Falta o estudo",IF(E19="","Falta o que aconteceu",IF(F19="","Falta o registro",IF(AND(ISNUMBER(I19),I19<0),"Data antes do passo anterior",IF(COUNTA(C20:H20)=0,"OK",IF(G19="","Falta a saída",IF(H19="","Falta o próximo estudo",IF(H19<>D20,"O passo seguinte é de outro estudo","OK")))))))))) -> OK
