Workbook

Sheet Instruções
B1: Avaliação de fornecedores — Como usar esta planilha
B2: Modelo para cadastrar e homologar fornecedores, avaliar o desempenho do período e registrar as ocorrências.
B4: Legenda: onde preencher
B5: Amarelo-claro | C5: Células de entrada. É aqui que você digita.
B6: Cinza | C6: Células calculadas ou fixas (rótulos, percentuais, índice, classe, conduta, avisos). Não altere.
B7: Cinza em itálico | C7: Linha de exemplo (marcada com “Ex.”). Mostra o formato esperado e não entra nas contagens.
B8: Listas suspensas | C8: Colunas de tipo, criticidade, documentos, resultado e situação aceitam apenas as opções da lista.
B9: Comentários | C9: Células com triângulo vermelho no canto trazem uma dica de preenchimento. Passe o mouse sobre elas.
B11: O índice de desempenho e as classes
B12: Qualidade · peso 50 | C12: Lotes ou serviços aceitos, sobre os recebidos.
B13: Prazo · peso 30 | C13: Entregas no prazo, sobre as entregas.
B14: Atendimento · peso 20 | C14: Nota do comprador, de 0 a 10: resposta, documentação, flexibilidade.
B15: Classe A · Preferencial | C15: Índice de 90 ou mais. Manter. Pode ter menos inspeção no recebimento.
B16: Classe B · Aprovado | C16: Índice de 75 a 89. Manter e acompanhar. Comunicar o resultado ao fornecedor.
B17: Classe C · Com plano de ação | C17: Índice de 60 a 74. Pedir plano de ação, com prazo. Reavaliar no período seguinte.
B18: Classe D · Reprovado | C18: Índice abaixo de 60. Suspender as compras até um plano aprovado, ou desqualificar.
B20: Ordem recomendada de preenchimento
B21: Passo 1 | C21: Aba Cadastro: escreva a organização, a data de referência e a validade padrão da homologação. Cadastre os fornecedores, com o que fornecem, o tipo e a criticidade.
B22: Passo 2 | C22: Aba Cadastro: para cada fornecedor crítico, registre a data da homologação e se os documentos estão em dia.
B23: Passo 3 | C23: Aba Homologação: preencha a ficha de um fornecedor novo, critério por critério, e leve a data para o Cadastro quando ele for homologado.
B24: Passo 4 | C24: Aba Avaliação: no fim do período, lance os dados do recebimento de cada fornecedor crítico e a nota de atendimento.
B25: Passo 5 | C25: Aba Avaliação: leia o índice, a classe e a conduta, e escreva o plano de ação ou a decisão.
B26: Passo 6 | C26: Aba Ocorrências: registre as falhas do período, com o tratamento e a situação.
B27: Passo 7 | C27: Aba Checklist: valide o controle de fornecedores.
B29: Abas da planilha
B30: Cadastro | C30: Até 30 fornecedores, com a validade da homologação e a situação de cada um calculadas.
B31: Homologação | C31: A ficha de um fornecedor novo: seis critérios, resultado, evidência e decisão calculada.
B32: Avaliação | C32: Até 30 avaliações, com percentuais, índice, classe, conduta e gráfico.
B33: Ocorrências | C33: Até 25 ocorrências com fornecedores, com a conferência de cada uma.
B34: Checklist | C34: Doze verificações de qualidade do controle de fornecedores, com percentual de conclusão.
B35: Exemplo 1 - Indústria | C35: A avaliação semestral dos doze fornecedores críticos de uma indústria.
B36: Exemplo 2 - Pizzaria | C36: A primeira avaliação dos fornecedores de uma loja.
B38: Regras e premissas do modelo
B39: Índice | C39: Índice = 50 × qualidade + 30 × prazo + 20 × atendimento, com os três em percentual. Os pesos e as classes são uma convenção deste modelo.
B40: Dados do índice | C40: Lotes aceitos não podem passar dos recebidos, nem entregas no prazo das entregas. Quando isso acontece, o índice fica em branco e a conferência avisa.
B41: Homologação | C41: Vale 24 meses, neste modelo. A situação “Homologação vencida” aparece quando a validade passa da data de referência.
B42: Não crítico | C42: Fornecedor não crítico fica no cadastro, sem homologação nem avaliação obrigatórias.
B43: Data de referência | C43: A situação da homologação é calculada pela data de referência da aba Cadastro. Se ela estiver em branco, a planilha usa a data de hoje.
B44: Exemplos | C44: Os dados das abas de exemplo são ilustrativos, criados para este material.

Sheet Cadastro
B1: Cadastro de fornecedores
B2: Um fornecedor por linha. Para os críticos, registre a homologação. A validade e a situação são calculadas.
B4: Organização
B5: Data de referência | F5: Em branco, vale a data de hoje.
B6: Validade padrão da homologação, em meses | E6: 24 | F6: Usada nas linhas sem validade própria.
C7: Ex.: F-01 | D7: Razão social ou nome | E7: Item ou serviço | F7: Escolha na lista | G7: Escolha na lista | H7: Data da decisão | I7: Em branco: padrão | J7: Calculada | K7: Sim ou Não | L7: Calculada
B8: # | C8: Código | D8: Fornecedor | E8: O que fornece | F8: Tipo | G8: Criticidade | H8: Homologado em | I8: Validade (meses) | J8: Válida até | K8: Documentos em dia? | L8: Situação
B9: 1 | J9: =IF(OR(H9="",D9=""),"",EDATE(H9,IF(I9="",$E$6,I9))) | L9: =IF(D9="","",IF(G9="","Falta a criticidade",IF(G9="Não crítico","Não crítico: sem homologação",IF(H9="","Falta a homologação",IF(K9="Não","Documentos pendentes",IF(J9<IF(Cadastro!$E$5="",TODAY(),Cadastro!$E$5),"Homologação vencida","Homologado"))))))
B10: 2 | J10: =IF(OR(H10="",D10=""),"",EDATE(H10,IF(I10="",$E$6,I10))) | L10: =IF(D10="","",IF(G10="","Falta a criticidade",IF(G10="Não crítico","Não crítico: sem homologação",IF(H10="","Falta a homologação",IF(K10="Não","Documentos pendentes",IF(J10<IF(Cadastro!$E$5="",TODAY(),Cadastro!$E$5),"Homologação vencida","Homologado"))))))
B11: 3 | J11: =IF(OR(H11="",D11=""),"",EDATE(H11,IF(I11="",$E$6,I11))) | L11: =IF(D11="","",IF(G11="","Falta a criticidade",IF(G11="Não crítico","Não crítico: sem homologação",IF(H11="","Falta a homologação",IF(K11="Não","Documentos pendentes",IF(J11<IF(Cadastro!$E$5="",TODAY(),Cadastro!$E$5),"Homologação vencida","Homologado"))))))
B12: 4 | J12: =IF(OR(H12="",D12=""),"",EDATE(H12,IF(I12="",$E$6,I12))) | L12: =IF(D12="","",IF(G12="","Falta a criticidade",IF(G12="Não crítico","Não crítico: sem homologação",IF(H12="","Falta a homologação",IF(K12="Não","Documentos pendentes",IF(J12<IF(Cadastro!$E$5="",TODAY(),Cadastro!$E$5),"Homologação vencida","Homologado"))))))
B13: 5 | J13: =IF(OR(H13="",D13=""),"",EDATE(H13,IF(I13="",$E$6,I13))) | L13: =IF(D13="","",IF(G13="","Falta a criticidade",IF(G13="Não crítico","Não crítico: sem homologação",IF(H13="","Falta a homologação",IF(K13="Não","Documentos pendentes",IF(J13<IF(Cadastro!$E$5="",TODAY(),Cadastro!$E$5),"Homologação vencida","Homologado"))))))
B14: 6 | J14: =IF(OR(H14="",D14=""),"",EDATE(H14,IF(I14="",$E$6,I14))) | L14: =IF(D14="","",IF(G14="","Falta a criticidade",IF(G14="Não crítico","Não crítico: sem homologação",IF(H14="","Falta a homologação",IF(K14="Não","Documentos pendentes",IF(J14<IF(Cadastro!$E$5="",TODAY(),Cadastro!$E$5),"Homologação vencida","Homologado"))))))
B15: 7 | J15: =IF(OR(H15="",D15=""),"",EDATE(H15,IF(I15="",$E$6,I15))) | L15: =IF(D15="","",IF(G15="","Falta a criticidade",IF(G15="Não crítico","Não crítico: sem homologação",IF(H15="","Falta a homologação",IF(K15="Não","Documentos pendentes",IF(J15<IF(Cadastro!$E$5="",TODAY(),Cadastro!$E$5),"Homologação vencida","Homologado"))))))
B16: 8 | J16: =IF(OR(H16="",D16=""),"",EDATE(H16,IF(I16="",$E$6,I16))) | L16: =IF(D16="","",IF(G16="","Falta a criticidade",IF(G16="Não crítico","Não crítico: sem homologação",IF(H16="","Falta a homologação",IF(K16="Não","Documentos pendentes",IF(J16<IF(Cadastro!$E$5="",TODAY(),Cadastro!$E$5),"Homologação vencida","Homologado"))))))
B17: 9 | J17: =IF(OR(H17="",D17=""),"",EDATE(H17,IF(I17="",$E$6,I17))) | L17: =IF(D17="","",IF(G17="","Falta a criticidade",IF(G17="Não crítico","Não crítico: sem homologação",IF(H17="","Falta a homologação",IF(K17="Não","Documentos pendentes",IF(J17<IF(Cadastro!$E$5="",TODAY(),Cadastro!$E$5),"Homologação vencida","Homologado"))))))
B18: 10 | J18: =IF(OR(H18="",D18=""),"",EDATE(H18,IF(I18="",$E$6,I18))) | L18: =IF(D18="","",IF(G18="","Falta a criticidade",IF(G18="Não crítico","Não crítico: sem homologação",IF(H18="","Falta a homologação",IF(K18="Não","Documentos pendentes",IF(J18<IF(Cadastro!$E$5="",TODAY(),Cadastro!$E$5),"Homologação vencida","Homologado"))))))
B19: 11 | J19: =IF(OR(H19="",D19=""),"",EDATE(H19,IF(I19="",$E$6,I19))) | L19: =IF(D19="","",IF(G19="","Falta a criticidade",IF(G19="Não crítico","Não crítico: sem homologação",IF(H19="","Falta a homologação",IF(K19="Não","Documentos pendentes",IF(J19<IF(Cadastro!$E$5="",TODAY(),Cadastro!$E$5),"Homologação vencida","Homologado"))))))
B20: 12 | J20: =IF(OR(H20="",D20=""),"",EDATE(H20,IF(I20="",$E$6,I20))) | L20: =IF(D20="","",IF(G20="","Falta a criticidade",IF(G20="Não crítico","Não crítico: sem homologação",IF(H20="","Falta a homologação",IF(K20="Não","Documentos pendentes",IF(J20<IF(Cadastro!$E$5="",TODAY(),Cadastro!$E$5),"Homologação vencida","Homologado"))))))
... B38: 30 | J38: =IF(OR(H38="",D38=""),"",EDATE(H38,IF(I38="",$E$6,I38))) | L38: =IF(D38="","",IF(G38="","Falta a criticidade",IF(G38="Não crítico","Não crítico: sem homologação",IF(H38="","Falta a homologação",IF(K38="Não","Documentos pendentes",IF(J38<IF(Cadastro!$E$5="",TODAY(),Cadastro!$E$5),"Homologação vencida","Homologado"))))))
B40: Resumo automático
B41: Fornecedores cadastrados | E41: =COUNTA(D9:D38) -> 0
B42: Críticos | E42: =COUNTIF(G9:G38,"Crítico") -> 0
B43: Críticos homologados, em dia | E43: =COUNTIF(L9:L38,"Homologado") -> 0
B44: Com homologação vencida ou documentos pendentes | E44: =COUNTIF(L9:L38,"Homologação vencida")+COUNTIF(L9:L38,"Documentos pendentes") -> 0
B45: Críticos sem homologação | E45: =COUNTIF(L9:L38,"Falta a homologação") -> 0
B46: Aviso | E46: =IF(E41=0,"Cadastre os fornecedores",IF(COUNTIF(L9:L38,"Falta a criticidade")>0,"Há fornecedor sem criticidade",IF(E45>0,"Há fornecedor crítico sem homologação",IF(E44>0,"Há homologação vencida ou documentos pendentes","OK")))) -> Cadastre os fornecedores

Sheet Homologação
B1: Ficha de homologação
B2: Um fornecedor por ficha. Para o seguinte, duplique a aba ou salve uma cópia do arquivo.
B4: Código e fornecedor
B5: O que fornece
B6: Data da avaliação
B7: Quem avaliou
B9: Critério | C9: O que se confere | D9: Resultado | E9: Evidência
B10: Documentos legais | C10: Empresa regular, com as licenças da atividade.
B11: Capacidade técnica | C11: Consegue fazer o que se pede, na quantidade e no prazo.
B12: Qualidade do produto | C12: A amostra ou o lote piloto atende à especificação.
B13: Sistema de gestão | C13: Tem controle do próprio processo.
B14: Condições comerciais | C14: Preço, prazo de pagamento e de entrega compatíveis.
B15: Segurança e meio ambiente | C15: Cumpre o que a lei e o cliente exigem.
B17: Decisão
B18: Critérios atendidos | C18: =COUNTIF(D10:D15,"Atende")&" de "&(ROWS(D10:D15)-COUNTIF(D10:D15,"Não se aplica")) -> 0 de 6
B19: Resultado | C19: =IF(C4="","Informe o fornecedor",IF(COUNTBLANK(D10:D15)>0,"Preencha os critérios",IF(COUNTIF(D10:D15,"Não atende")>0,"Não homologado",IF(COUNTIF(D10:D15,"Pendente")>0,"Em homologação: há critério pendente",IF(COUNTIF(E10:E15,"")>COUNTIF(D10:D15,"Não se aplica"),"Homologado, mas falta evidência","Homologado por "&Cadastro!$E$6&" meses"))))) -> Informe o fornecedor
B20: Válida até | C20: =IF(LEFT(C19,14)="Homologado por",EDATE(C6,Cadastro!$E$6),"")
B21: Aprovado por

Sheet Avaliação
B1: Avaliação de desempenho
B2: Uma linha por fornecedor e período. Lance os dados do recebimento e a nota de atendimento: o índice, a classe e a conduta são calculados.
B4: Período avaliado | G4: Ex.: julho a dezembro de 2026
B5: # | C5: Código | D5: Fornecedor | E5: Período | F5: Lotes recebidos | G5: Lotes aceitos | H5: Entregas | I5: Entregas no prazo | J5: Nota (0 a 10) | K5: Qualidade | L5: Prazo | M5: Índice | N5: Classe | O5: Conduta | P5: Plano de ação ou decisão | Q5: Conferência
C6: Do Cadastro | D6: Do Cadastro | E6: Semestre, ano | F6: Ou serviços prestados | G6: Sem recusa | H6: No período | I6: Na data combinada | J6: Do comprador | K6: Calculada | L6: Calculada | M6: Calculado | N6: Calculada | O6: Calculada | P6: O que foi combinado com o fornecedor | Q6: Calculada
B7: 1 | D7: =IF(C7="","",IFERROR(VLOOKUP(C7,Cadastro!$C$9:$D$38,2,FALSE()),"Não está no cadastro")) | K7: =IF(OR(F7="",F7=0,G7>F7),"",N(G7)/F7) | L7: =IF(OR(H7="",H7=0,I7>H7),"",N(I7)/H7) | M7: =IF(OR(C7="",F7="",H7="",J7=""),"",IF(OR(G7>F7,I7>H7,F7=0,H7=0),"",ROUND(50*N(G7)/F7+30*N(I7)/H7+20*J7/10,1))) | N7: =IF(M7="","",IF(M7>=90,"A",IF(M7>=75,"B",IF(M7>=60,"C","D")))) | O7: =IF(N7="A","Manter. Pode ter menos inspeção no recebimento.",IF(N7="B","Manter e acompanhar. Comunicar o resultado ao fornecedor.",IF(N7="C","Pedir plano de ação, com prazo. Reavaliar no período seguinte.",IF(N7="D","Suspender as compras até um plano aprovado, ou desqualificar.","")))) | Q7: =IF(C7="","",IF(OR(F7="",H7="",J7=""),"Faltam dados",IF(OR(G7>F7,I7>H7),"Confira os dados: aceitos ou no prazo maiores que o total",IF(OR(F7=0,H7=0),"Confira os dados: total zero","Calculada"))))
B8: 2 | D8: =IF(C8="","",IFERROR(VLOOKUP(C8,Cadastro!$C$9:$D$38,2,FALSE()),"Não está no cadastro")) | K8: =IF(OR(F8="",F8=0,G8>F8),"",N(G8)/F8) | L8: =IF(OR(H8="",H8=0,I8>H8),"",N(I8)/H8) | M8: =IF(OR(C8="",F8="",H8="",J8=""),"",IF(OR(G8>F8,I8>H8,F8=0,H8=0),"",ROUND(50*N(G8)/F8+30*N(I8)/H8+20*J8/10,1))) | N8: =IF(M8="","",IF(M8>=90,"A",IF(M8>=75,"B",IF(M8>=60,"C","D")))) | O8: =IF(N8="A","Manter. Pode ter menos inspeção no recebimento.",IF(N8="B","Manter e acompanhar. Comunicar o resultado ao fornecedor.",IF(N8="C","Pedir plano de ação, com prazo. Reavaliar no período seguinte.",IF(N8="D","Suspender as compras até um plano aprovado, ou desqualificar.","")))) | Q8: =IF(C8="","",IF(OR(F8="",H8="",J8=""),"Faltam dados",IF(OR(G8>F8,I8>H8),"Confira os dados: aceitos ou no prazo maiores que o total",IF(OR(F8=0,H8=0),"Confira os dados: total zero","Calculada"))))
B9: 3 | D9: =IF(C9="","",IFERROR(VLOOKUP(C9,Cadastro!$C$9:$D$38,2,FALSE()),"Não está no cadastro")) | K9: =IF(OR(F9="",F9=0,G9>F9),"",N(G9)/F9) | L9: =IF(OR(H9="",H9=0,I9>H9),"",N(I9)/H9) | M9: =IF(OR(C9="",F9="",H9="",J9=""),"",IF(OR(G9>F9,I9>H9,F9=0,H9=0),"",ROUND(50*N(G9)/F9+30*N(I9)/H9+20*J9/10,1))) | N9: =IF(M9="","",IF(M9>=90,"A",IF(M9>=75,"B",IF(M9>=60,"C","D")))) | O9: =IF(N9="A","Manter. Pode ter menos inspeção no recebimento.",IF(N9="B","Manter e acompanhar. Comunicar o resultado ao fornecedor.",IF(N9="C","Pedir plano de ação, com prazo. Reavaliar no período seguinte.",IF(N9="D","Suspender as compras até um plano aprovado, ou desqualificar.","")))) | Q9: =IF(C9="","",IF(OR(F9="",H9="",J9=""),"Faltam dados",IF(OR(G9>F9,I9>H9),"Confira os dados: aceitos ou no prazo maiores que o total",IF(OR(F9=0,H9=0),"Confira os dados: total zero","Calculada"))))
B10: 4 | D10: =IF(C10="","",IFERROR(VLOOKUP(C10,Cadastro!$C$9:$D$38,2,FALSE()),"Não está no cadastro")) | K10: =IF(OR(F10="",F10=0,G10>F10),"",N(G10)/F10) | L10: =IF(OR(H10="",H10=0,I10>H10),"",N(I10)/H10) | M10: =IF(OR(C10="",F10="",H10="",J10=""),"",IF(OR(G10>F10,I10>H10,F10=0,H10=0),"",ROUND(50*N(G10)/F10+30*N(I10)/H10+20*J10/10,1))) | N10: =IF(M10="","",IF(M10>=90,"A",IF(M10>=75,"B",IF(M10>=60,"C","D")))) | O10: =IF(N10="A","Manter. Pode ter menos inspeção no recebimento.",IF(N10="B","Manter e acompanhar. Comunicar o resultado ao fornecedor.",IF(N10="C","Pedir plano de ação, com prazo. Reavaliar no período seguinte.",IF(N10="D","Suspender as compras até um plano aprovado, ou desqualificar.","")))) | Q10: =IF(C10="","",IF(OR(F10="",H10="",J10=""),"Faltam dados",IF(OR(G10>F10,I10>H10),"Confira os dados: aceitos ou no prazo maiores que o total",IF(OR(F10=0,H10=0),"Confira os dados: total zero","Calculada"))))
B11: 5 | D11: =IF(C11="","",IFERROR(VLOOKUP(C11,Cadastro!$C$9:$D$38,2,FALSE()),"Não está no cadastro")) | K11: =IF(OR(F11="",F11=0,G11>F11),"",N(G11)/F11) | L11: =IF(OR(H11="",H11=0,I11>H11),"",N(I11)/H11) | M11: =IF(OR(C11="",F11="",H11="",J11=""),"",IF(OR(G11>F11,I11>H11,F11=0,H11=0),"",ROUND(50*N(G11)/F11+30*N(I11)/H11+20*J11/10,1))) | N11: =IF(M11="","",IF(M11>=90,"A",IF(M11>=75,"B",IF(M11>=60,"C","D")))) | O11: =IF(N11="A","Manter. Pode ter menos inspeção no recebimento.",IF(N11="B","Manter e acompanhar. Comunicar o resultado ao fornecedor.",IF(N11="C","Pedir plano de ação, com prazo. Reavaliar no período seguinte.",IF(N11="D","Suspender as compras até um plano aprovado, ou desqualificar.","")))) | Q11: =IF(C11="","",IF(OR(F11="",H11="",J11=""),"Faltam dados",IF(OR(G11>F11,I11>H11),"Confira os dados: aceitos ou no prazo maiores que o total",IF(OR(F11=0,H11=0),"Confira os dados: total zero","Calculada"))))
B12: 6 | D12: =IF(C12="","",IFERROR(VLOOKUP(C12,Cadastro!$C$9:$D$38,2,FALSE()),"Não está no cadastro")) | K12: =IF(OR(F12="",F12=0,G12>F12),"",N(G12)/F12) | L12: =IF(OR(H12="",H12=0,I12>H12),"",N(I12)/H12) | M12: =IF(OR(C12="",F12="",H12="",J12=""),"",IF(OR(G12>F12,I12>H12,F12=0,H12=0),"",ROUND(50*N(G12)/F12+30*N(I12)/H12+20*J12/10,1))) | N12: =IF(M12="","",IF(M12>=90,"A",IF(M12>=75,"B",IF(M12>=60,"C","D")))) | O12: =IF(N12="A","Manter. Pode ter menos inspeção no recebimento.",IF(N12="B","Manter e acompanhar. Comunicar o resultado ao fornecedor.",IF(N12="C","Pedir plano de ação, com prazo. Reavaliar no período seguinte.",IF(N12="D","Suspender as compras até um plano aprovado, ou desqualificar.","")))) | Q12: =IF(C12="","",IF(OR(F12="",H12="",J12=""),"Faltam dados",IF(OR(G12>F12,I12>H12),"Confira os dados: aceitos ou no prazo maiores que o total",IF(OR(F12=0,H12=0),"Confira os dados: total zero","Calculada"))))
B13: 7 | D13: =IF(C13="","",IFERROR(VLOOKUP(C13,Cadastro!$C$9:$D$38,2,FALSE()),"Não está no cadastro")) | K13: =IF(OR(F13="",F13=0,G13>F13),"",N(G13)/F13) | L13: =IF(OR(H13="",H13=0,I13>H13),"",N(I13)/H13) | M13: =IF(OR(C13="",F13="",H13="",J13=""),"",IF(OR(G13>F13,I13>H13,F13=0,H13=0),"",ROUND(50*N(G13)/F13+30*N(I13)/H13+20*J13/10,1))) | N13: =IF(M13="","",IF(M13>=90,"A",IF(M13>=75,"B",IF(M13>=60,"C","D")))) | O13: =IF(N13="A","Manter. Pode ter menos inspeção no recebimento.",IF(N13="B","Manter e acompanhar. Comunicar o resultado ao fornecedor.",IF(N13="C","Pedir plano de ação, com prazo. Reavaliar no período seguinte.",IF(N13="D","Suspender as compras até um plano aprovado, ou desqualificar.","")))) | Q13: =IF(C13="","",IF(OR(F13="",H13="",J13=""),"Faltam dados",IF(OR(G13>F13,I13>H13),"Confira os dados: aceitos ou no prazo maiores que o total",IF(OR(F13=0,H13=0),"Confira os dados: total zero","Calculada"))))
B14: 8 | D14: =IF(C14="","",IFERROR(VLOOKUP(C14,Cadastro!$C$9:$D$38,2,FALSE()),"Não está no cadastro")) | K14: =IF(OR(F14="",F14=0,G14>F14),"",N(G14)/F14) | L14: =IF(OR(H14="",H14=0,I14>H14),"",N(I14)/H14) | M14: =IF(OR(C14="",F14="",H14="",J14=""),"",IF(OR(G14>F14,I14>H14,F14=0,H14=0),"",ROUND(50*N(G14)/F14+30*N(I14)/H14+20*J14/10,1))) | N14: =IF(M14="","",IF(M14>=90,"A",IF(M14>=75,"B",IF(M14>=60,"C","D")))) | O14: =IF(N14="A","Manter. Pode ter menos inspeção no recebimento.",IF(N14="B","Manter e acompanhar. Comunicar o resultado ao fornecedor.",IF(N14="C","Pedir plano de ação, com prazo. Reavaliar no período seguinte.",IF(N14="D","Suspender as compras até um plano aprovado, ou desqualificar.","")))) | Q14: =IF(C14="","",IF(OR(F14="",H14="",J14=""),"Faltam dados",IF(OR(G14>F14,I14>H14),"Confira os dados: aceitos ou no prazo maiores que o total",IF(OR(F14=0,H14=0),"Confira os dados: total zero","Calculada"))))
B15: 9 | D15: =IF(C15="","",IFERROR(VLOOKUP(C15,Cadastro!$C$9:$D$38,2,FALSE()),"Não está no cadastro")) | K15: =IF(OR(F15="",F15=0,G15>F15),"",N(G15)/F15) | L15: =IF(OR(H15="",H15=0,I15>H15),"",N(I15)/H15) | M15: =IF(OR(C15="",F15="",H15="",J15=""),"",IF(OR(G15>F15,I15>H15,F15=0,H15=0),"",ROUND(50*N(G15)/F15+30*N(I15)/H15+20*J15/10,1))) | N15: =IF(M15="","",IF(M15>=90,"A",IF(M15>=75,"B",IF(M15>=60,"C","D")))) | O15: =IF(N15="A","Manter. Pode ter menos inspeção no recebimento.",IF(N15="B","Manter e acompanhar. Comunicar o resultado ao fornecedor.",IF(N15="C","Pedir plano de ação, com prazo. Reavaliar no período seguinte.",IF(N15="D","Suspender as compras até um plano aprovado, ou desqualificar.","")))) | Q15: =IF(C15="","",IF(OR(F15="",H15="",J15=""),"Faltam dados",IF(OR(G15>F15,I15>H15),"Confira os dados: aceitos ou no prazo maiores que o total",IF(OR(F15=0,H15=0),"Confira os dados: total zero","Calculada"))))
B16: 10 | D16: =IF(C16="","",IFERROR(VLOOKUP(C16,Cadastro!$C$9:$D$38,2,FALSE()),"Não está no cadastro")) | K16: =IF(OR(F16="",F16=0,G16>F16),"",N(G16)/F16) | L16: =IF(OR(H16="",H16=0,I16>H16),"",N(I16)/H16) | M16: =IF(OR(C16="",F16="",H16="",J16=""),"",IF(OR(G16>F16,I16>H16,F16=0,H16=0),"",ROUND(50*N(G16)/F16+30*N(I16)/H16+20*J16/10,1))) | N16: =IF(M16="","",IF(M16>=90,"A",IF(M16>=75,"B",IF(M16>=60,"C","D")))) | O16: =IF(N16="A","Manter. Pode ter menos inspeção no recebimento.",IF(N16="B","Manter e acompanhar. Comunicar o resultado ao fornecedor.",IF(N16="C","Pedir plano de ação, com prazo. Reavaliar no período seguinte.",IF(N16="D","Suspender as compras até um plano aprovado, ou desqualificar.","")))) | Q16: =IF(C16="","",IF(OR(F16="",H16="",J16=""),"Faltam dados",IF(OR(G16>F16,I16>H16),"Confira os dados: aceitos ou no prazo maiores que o total",IF(OR(F16=0,H16=0),"Confira os dados: total zero","Calculada"))))
B17: 11 | D17: =IF(C17="","",IFERROR(VLOOKUP(C17,Cadastro!$C$9:$D$38,2,FALSE()),"Não está no cadastro")) | K17: =IF(OR(F17="",F17=0,G17>F17),"",N(G17)/F17) | L17: =IF(OR(H17="",H17=0,I17>H17),"",N(I17)/H17) | M17: =IF(OR(C17="",F17="",H17="",J17=""),"",IF(OR(G17>F17,I17>H17,F17=0,H17=0),"",ROUND(50*N(G17)/F17+30*N(I17)/H17+20*J17/10,1))) | N17: =IF(M17="","",IF(M17>=90,"A",IF(M17>=75,"B",IF(M17>=60,"C","D")))) | O17: =IF(N17="A","Manter. Pode ter menos inspeção no recebimento.",IF(N17="B","Manter e acompanhar. Comunicar o resultado ao fornecedor.",IF(N17="C","Pedir plano de ação, com prazo. Reavaliar no período seguinte.",IF(N17="D","Suspender as compras até um plano aprovado, ou desqualificar.","")))) | Q17: =IF(C17="","",IF(OR(F17="",H17="",J17=""),"Faltam dados",IF(OR(G17>F17,I17>H17),"Confira os dados: aceitos ou no prazo maiores que o total",IF(OR(F17=0,H17=0),"Confira os dados: total zero","Calculada"))))
B18: 12 | D18: =IF(C18="","",IFERROR(VLOOKUP(C18,Cadastro!$C$9:$D$38,2,FALSE()),"Não está no cadastro")) | K18: =IF(OR(F18="",F18=0,G18>F18),"",N(G18)/F18) | L18: =IF(OR(H18="",H18=0,I18>H18),"",N(I18)/H18) | M18: =IF(OR(C18="",F18="",H18="",J18=""),"",IF(OR(G18>F18,I18>H18,F18=0,H18=0),"",ROUND(50*N(G18)/F18+30*N(I18)/H18+20*J18/10,1))) | N18: =IF(M18="","",IF(M18>=90,"A",IF(M18>=75,"B",IF(M18>=60,"C","D")))) | O18: =IF(N18="A","Manter. Pode ter menos inspeção no recebimento.",IF(N18="B","Manter e acompanhar. Comunicar o resultado ao fornecedor.",IF(N18="C","Pedir plano de ação, com prazo. Reavaliar no período seguinte.",IF(N18="D","Suspender as compras até um plano aprovado, ou desqualificar.","")))) | Q18: =IF(C18="","",IF(OR(F18="",H18="",J18=""),"Faltam dados",IF(OR(G18>F18,I18>H18),"Confira os dados: aceitos ou no prazo maiores que o total",IF(OR(F18=0,H18=0),"Confira os dados: total zero","Calculada"))))
... B36: 30 | D36: =IF(C36="","",IFERROR(VLOOKUP(C36,Cadastro!$C$9:$D$38,2,FALSE()),"Não está no cadastro")) | K36: =IF(OR(F36="",F36=0,G36>F36),"",N(G36)/F36) | L36: =IF(OR(H36="",H36=0,I36>H36),"",N(I36)/H36) | M36: =IF(OR(C36="",F36="",H36="",J36=""),"",IF(OR(G36>F36,I36>H36,F36=0,H36=0),"",ROUND(50*N(G36)/F36+30*N(I36)/H36+20*J36/10,1))) | N36: =IF(M36="","",IF(M36>=90,"A",IF(M36>=75,"B",IF(M36>=60,"C","D")))) | O36: =IF(N36="A","Manter. Pode ter menos inspeção no recebimento.",IF(N36="B","Manter e acompanhar. Comunicar o resultado ao fornecedor.",IF(N36="C","Pedir plano de ação, com prazo. Reavaliar no período seguinte.",IF(N36="D","Suspender as compras até um plano aprovado, ou desqualificar.","")))) | Q36: =IF(C36="","",IF(OR(F36="",H36="",J36=""),"Faltam dados",IF(OR(G36>F36,I36>H36),"Confira os dados: aceitos ou no prazo maiores que o total",IF(OR(F36=0,H36=0),"Confira os dados: total zero","Calculada"))))
B38: Resumo automático | K38: Índice por fornecedor
B39: Fornecedores avaliados | E39: =COUNT(M7:M36) -> 0
B40: Classe A, B, C e D | E40: =COUNTIF(N7:N36,"A")&", "&COUNTIF(N7:N36,"B")&", "&COUNTIF(N7:N36,"C")&" e "&COUNTIF(N7:N36,"D") -> 0, 0, 0 e 0
B41: Média do índice | E41: =IF(E39=0,"",AVERAGE(M7:M36))
B42: Classe C ou D sem plano ou decisão | E42: =COUNTIFS(N7:N36,"C",P7:P36,"")+COUNTIFS(N7:N36,"D",P7:P36,"") -> 0
B43: Aviso | E43: =IF(COUNTA(C7:C36)=0,"Registre as avaliações",IF(COUNTIF(D7:D36,"Não está no cadastro")>0,"Há código que não está no cadastro",IF(COUNTIF(Q7:Q36,"Faltam dados")+COUNTIF(Q7:Q36,"Confira*")>0,"Há avaliação com dados a conferir: veja a coluna Conferência",IF(E42>0,"Há fornecedor de classe C ou D sem plano ou decisão","OK")))) -> Registre as avaliações

Sheet Ocorrências
B1: Ocorrências com fornecedores
B2: Uma linha para cada falha registrada pelo recebimento: lote recusado, atraso, documento errado, atendimento.
B4: # | C4: Data | D4: Código | E4: Fornecedor | F4: Tipo | G4: Descrição | H4: Tratamento | I4: RNC nº | J4: Situação | K4: Conferência
C5: Da ocorrência | D5: Do Cadastro | E5: Do Cadastro | F5: Escolha na lista | G5: O que aconteceu, com o lote ou o pedido | H5: Devolução, reposição, plano do fornecedor | I5: Se abriu RNC | J5: Escolha na lista | K5: Calculada
B6: Ex. | C6: 46302 | D6: F-08 | E6: Paletes Rápido | F6: Qualidade | G6: Lote de 40 paletes com madeira sem tratamento. Nota fiscal 1.223. | H6: Lote devolvido. Reposição em 5 dias. | I6: 2026-35 | J6: Encerrada | K6: Completa
B7: 1 | E7: =IF(D7="","",IFERROR(VLOOKUP(D7,Cadastro!$C$9:$D$38,2,FALSE()),"Não está no cadastro")) | K7: =IF(G7="","",IF(C7="","Falta a data",IF(D7="","Falta o fornecedor",IF(F7="","Falta o tipo",IF(J7="","Falta a situação",IF(AND(J7<>"Aberta",H7=""),"Falta o tratamento","Completa"))))))
B8: 2 | E8: =IF(D8="","",IFERROR(VLOOKUP(D8,Cadastro!$C$9:$D$38,2,FALSE()),"Não está no cadastro")) | K8: =IF(G8="","",IF(C8="","Falta a data",IF(D8="","Falta o fornecedor",IF(F8="","Falta o tipo",IF(J8="","Falta a situação",IF(AND(J8<>"Aberta",H8=""),"Falta o tratamento","Completa"))))))
B9: 3 | E9: =IF(D9="","",IFERROR(VLOOKUP(D9,Cadastro!$C$9:$D$38,2,FALSE()),"Não está no cadastro")) | K9: =IF(G9="","",IF(C9="","Falta a data",IF(D9="","Falta o fornecedor",IF(F9="","Falta o tipo",IF(J9="","Falta a situação",IF(AND(J9<>"Aberta",H9=""),"Falta o tratamento","Completa"))))))
B10: 4 | E10: =IF(D10="","",IFERROR(VLOOKUP(D10,Cadastro!$C$9:$D$38,2,FALSE()),"Não está no cadastro")) | K10: =IF(G10="","",IF(C10="","Falta a data",IF(D10="","Falta o fornecedor",IF(F10="","Falta o tipo",IF(J10="","Falta a situação",IF(AND(J10<>"Aberta",H10=""),"Falta o tratamento","Completa"))))))
B11: 5 | E11: =IF(D11="","",IFERROR(VLOOKUP(D11,Cadastro!$C$9:$D$38,2,FALSE()),"Não está no cadastro")) | K11: =IF(G11="","",IF(C11="","Falta a data",IF(D11="","Falta o fornecedor",IF(F11="","Falta o tipo",IF(J11="","Falta a situação",IF(AND(J11<>"Aberta",H11=""),"Falta o tratamento","Completa"))))))
B12: 6 | E12: =IF(D12="","",IFERROR(VLOOKUP(D12,Cadastro!$C$9:$D$38,2,FALSE()),"Não está no cadastro")) | K12: =IF(G12="","",IF(C12="","Falta a data",IF(D12="","Falta o fornecedor",IF(F12="","Falta o tipo",IF(J12="","Falta a situação",IF(AND(J12<>"Aberta",H12=""),"Falta o tratamento","Completa"))))))
B13: 7 | E13: =IF(D13="","",IFERROR(VLOOKUP(D13,Cadastro!$C$9:$D$38,2,FALSE()),"Não está no cadastro")) | K13: =IF(G13="","",IF(C13="","Falta a data",IF(D13="","Falta o fornecedor",IF(F13="","Falta o tipo",IF(J13="","Falta a situação",IF(AND(J13<>"Aberta",H13=""),"Falta o tratamento","Completa"))))))
B14: 8 | E14: =IF(D14="","",IFERROR(VLOOKUP(D14,Cadastro!$C$9:$D$38,2,FALSE()),"Não está no cadastro")) | K14: =IF(G14="","",IF(C14="","Falta a data",IF(D14="","Falta o fornecedor",IF(F14="","Falta o tipo",IF(J14="","Falta a situação",IF(AND(J14<>"Aberta",H14=""),"Falta o tratamento","Completa"))))))
B15: 9 | E15: =IF(D15="","",IFERROR(VLOOKUP(D15,Cadastro!$C$9:$D$38,2,FALSE()),"Não está no cadastro")) | K15: =IF(G15="","",IF(C15="","Falta a data",IF(D15="","Falta o fornecedor",IF(F15="","Falta o tipo",IF(J15="","Falta a situação",IF(AND(J15<>"Aberta",H15=""),"Falta o tratamento","Completa"))))))
B16: 10 | E16: =IF(D16="","",IFERROR(VLOOKUP(D16,Cadastro!$C$9:$D$38,2,FALSE()),"Não está no cadastro")) | K16: =IF(G16="","",IF(C16="","Falta a data",IF(D16="","Falta o fornecedor",IF(F16="","Falta o tipo",IF(J16="","Falta a situação",IF(AND(J16<>"Aberta",H16=""),"Falta o tratamento","Completa"))))))
B17: 11 | E17: =IF(D17="","",IFERROR(VLOOKUP(D17,Cadastro!$C$9:$D$38,2,FALSE()),"Não está no cadastro")) | K17: =IF(G17="","",IF(C17="","Falta a data",IF(D17="","Falta o fornecedor",IF(F17="","Falta o tipo",IF(J17="","Falta a situação",IF(AND(J17<>"Aberta",H17=""),"Falta o tratamento","Completa"))))))
B18: 12 | E18: =IF(D18="","",IFERROR(VLOOKUP(D18,Cadastro!$C$9:$D$38,2,FALSE()),"Não está no cadastro")) | K18: =IF(G18="","",IF(C18="","Falta a data",IF(D18="","Falta o fornecedor",IF(F18="","Falta o tipo",IF(J18="","Falta a situação",IF(AND(J18<>"Aberta",H18=""),"Falta o tratamento","Completa"))))))
... B31: 25 | E31: =IF(D31="","",IFERROR(VLOOKUP(D31,Cadastro!$C$9:$D$38,2,FALSE()),"Não está no cadastro")) | K31: =IF(G31="","",IF(C31="","Falta a data",IF(D31="","Falta o fornecedor",IF(F31="","Falta o tipo",IF(J31="","Falta a situação",IF(AND(J31<>"Aberta",H31=""),"Falta o tratamento","Completa"))))))
B33: Resumo automático
B34: Ocorrências registradas | E34: =COUNTA(G7:G31) -> 0
B35: Abertas | E35: =COUNTIF(J7:J31,"Aberta") -> 0
B36: Qualidade, prazo, documentação e atendimento | E36: =COUNTIF(F7:F31,"Qualidade")&", "&COUNTIF(F7:F31,"Prazo")&", "&COUNTIF(F7:F31,"Documentação")&" e "&COUNTIF(F7:F31,"Atendimento") -> 0, 0, 0 e 0
B37: Aviso | E37: =IF(E34=0,"Registre as ocorrências",IF(COUNTIF(K7:K31,"Falta*")>0,"Há ocorrência com campos em branco: veja a coluna Conferência",IF(E35>0,"Há ocorrência aberta","OK"))) -> Registre as ocorrências

Sheet Checklist
B1: Checklist do controle de fornecedores
B2: Escolha o status de cada item na lista suspensa (coluna em amarelo-claro).
B4: # | C4: Item de verificação | D4: Status | E4: Observações
B5: 1 | C5: Os itens e serviços críticos estão identificados, com o motivo.
B6: 2 | C6: Os critérios de homologação estão escritos e são os mesmos para todos os fornecedores do mesmo tipo.
B7: 3 | C7: Todo fornecedor crítico tem homologação registrada e dentro da validade.
B8: 4 | C8: O pedido de compra informa os requisitos do produto ou do serviço.
B9: 5 | C9: O recebimento confere o que chega, com registro, antes da liberação.
B10: 6 | C10: Os indicadores de desempenho e os pesos estão definidos e foram comunicados aos fornecedores.
B11: 7 | C11: A avaliação é feita no período definido, com os dados do recebimento.
B12: 8 | C12: Cada fornecedor avaliado tem classe e conduta registradas.
B13: 9 | C13: Os fornecedores com plano de ação têm prazo e responsável.
B14: 10 | C14: Os fornecedores reprovados estão bloqueados no sistema de compras.
B15: 11 | C15: As ocorrências com fornecedores são registradas e tratadas.
B16: 12 | C16: Os processos terceirizados têm o controle definido: o que a organização confere e quando.
B18: Resumo automático
B19: Itens atendidos (Sim) | D19: =COUNTIF(D5:D16,"Sim") -> 0
B20: Itens parciais | D20: =COUNTIF(D5:D16,"Parcial") -> 0
B21: Itens não atendidos | D21: =COUNTIF(D5:D16,"Não") -> 0
B22: Itens sem resposta | D22: =COUNTBLANK(D5:D16) -> 12
B23: Percentual atendido | D23: =D19/ROWS(D5:D16) -> 0
B24: Situação | D24: =IF(D19=ROWS(D5:D16),"Validado",IF(D22>0,"Em andamento","Com pendências")) -> Em andamento

Sheet Exemplo 1 - Indústria
B1: Avaliação de fornecedores
B2: Exemplo preenchido, para consulta. Use as abas Cadastro, Homologação, Avaliação e Ocorrências para os seus fornecedores.
B4: Organização | D4: Indústria de embalagens plásticas · Suprimentos
B5: Data de referência | D5: 46367
B6: Período avaliado | D6: Julho a dezembro de 2026
B7: Quem avaliou | D7: Comprador sênior, com o Gerente de Suprimentos e a Qualidade
B8: Origem | D8: Constatação nº 2 da auditoria 2026-07: cinco fornecedores críticos sem avaliação em 2026. Avaliação semestral, PR-SUP-02 rev. 2.
B10: Cadastro e homologação
B11: Código | C11: Fornecedor | D11: O que fornece | E11: Tipo | F11: Criticidade | G11: Homologado em | H11: Válida até | I11: Docs. em dia? | J11: Situação
B12: F-01 | C12: Polímeros do Vale | D12: Resina de polietileno | E12: Produto | F12: Crítico | G12: 45726 | H12: =IF(G12="","",EDATE(G12,24)) -> 46456 | I12: Sim | J12: =IF(F12="Não crítico","Não crítico: sem homologação",IF(G12="","Falta a homologação",IF(I12="Não","Documentos pendentes",IF(H12<$D$5,"Homologação vencida","Homologado")))) -> Homologado
B13: F-02 | C13: Petroquímica Sul | D13: Resina de polipropileno | E13: Produto | F13: Crítico | G13: 45810 | H13: =IF(G13="","",EDATE(G13,24)) -> 46540 | I13: Sim | J13: =IF(F13="Não crítico","Não crítico: sem homologação",IF(G13="","Falta a homologação",IF(I13="Não","Documentos pendentes",IF(H13<$D$5,"Homologação vencida","Homologado")))) -> Homologado
B14: F-03 | C14: Colorfix | D14: Masterbatch e pigmentos | E14: Produto | F14: Crítico | G14: 45614 | H14: =IF(G14="","",EDATE(G14,24)) -> 46344 | I14: Sim | J14: =IF(F14="Não crítico","Não crítico: sem homologação",IF(G14="","Falta a homologação",IF(I14="Não","Documentos pendentes",IF(H14<$D$5,"Homologação vencida","Homologado")))) -> Homologação vencida
B15: F-04 | C15: Tintas Gráficas Ltda. | D15: Tintas de impressão | E15: Produto | F15: Crítico | G15: 45712 | H15: =IF(G15="","",EDATE(G15,24)) -> 46442 | I15: Sim | J15: =IF(F15="Não crítico","Não crítico: sem homologação",IF(G15="","Falta a homologação",IF(I15="Não","Documentos pendentes",IF(H15<$D$5,"Homologação vencida","Homologado")))) -> Homologado
B16: F-05 | C16: Cliché Print | D16: Clichês e matrizes | E16: Produto | F16: Crítico | G16: 45880 | H16: =IF(G16="","",EDATE(G16,24)) -> 46610 | I16: Sim | J16: =IF(F16="Não crítico","Não crítico: sem homologação",IF(G16="","Falta a homologação",IF(I16="Não","Documentos pendentes",IF(H16<$D$5,"Homologação vencida","Homologado")))) -> Homologado
B17: F-06 | C17: Filmes Técnicos | D17: Filme para laminação | E17: Produto | F17: Crítico | G17: 46042 | H17: =IF(G17="","",EDATE(G17,24)) -> 46772 | I17: Sim | J17: =IF(F17="Não crítico","Não crítico: sem homologação",IF(G17="","Falta a homologação",IF(I17="Não","Documentos pendentes",IF(H17<$D$5,"Homologação vencida","Homologado")))) -> Homologado
B18: F-07 | C18: Papelão Oeste | D18: Caixas de papelão | E18: Produto | F18: Crítico | G18: 45565 | H18: =IF(G18="","",EDATE(G18,24)) -> 46295 | I18: Sim | J18: =IF(F18="Não crítico","Não crítico: sem homologação",IF(G18="","Falta a homologação",IF(I18="Não","Documentos pendentes",IF(H18<$D$5,"Homologação vencida","Homologado")))) -> Homologação vencida
B19: F-08 | C19: Paletes Rápido | D19: Paletes de madeira | E19: Produto | F19: Crítico | G19: 45579 | H19: =IF(G19="","",EDATE(G19,24)) -> 46309 | I19: Não | J19: =IF(F19="Não crítico","Não crítico: sem homologação",IF(G19="","Falta a homologação",IF(I19="Não","Documentos pendentes",IF(H19<$D$5,"Homologação vencida","Homologado")))) -> Documentos pendentes
B20: F-09 | C20: Transportes Horizonte | D20: Transporte de produto acabado | E20: Serviço | F20: Crítico | G20: 45782 | H20: =IF(G20="","",EDATE(G20,24)) -> 46512 | I20: Sim | J20: =IF(F20="Não crítico","Não crítico: sem homologação",IF(G20="","Falta a homologação",IF(I20="Não","Documentos pendentes",IF(H20<$D$5,"Homologação vencida","Homologado")))) -> Homologado
B21: F-10 | C21: Mantec | D21: Manutenção de extrusoras | E21: Serviço | F21: Crítico | G21: 45769 | H21: =IF(G21="","",EDATE(G21,24)) -> 46499 | I21: Sim | J21: =IF(F21="Não crítico","Não crítico: sem homologação",IF(G21="","Falta a homologação",IF(I21="Não","Documentos pendentes",IF(H21<$D$5,"Homologação vencida","Homologado")))) -> Homologado
B22: F-11 | C22: Laboratório Analítica | D22: Ensaios de migração e espessura | E22: Serviço | F22: Crítico | G22: 45846 | H22: =IF(G22="","",EDATE(G22,24)) -> 46576 | I22: Sim | J22: =IF(F22="Não crítico","Não crítico: sem homologação",IF(G22="","Falta a homologação",IF(I22="Não","Documentos pendentes",IF(H22<$D$5,"Homologação vencida","Homologado")))) -> Homologado
B23: F-12 | C23: Ferramentaria Precisa | D23: Usinagem de moldes | E23: Processo terceirizado | F23: Crítico | G23: 45670 | H23: =IF(G23="","",EDATE(G23,24)) -> 46400 | I23: Sim | J23: =IF(F23="Não crítico","Não crítico: sem homologação",IF(G23="","Falta a homologação",IF(I23="Não","Documentos pendentes",IF(H23<$D$5,"Homologação vencida","Homologado")))) -> Homologado
B25: Avaliação de desempenho · julho a dezembro de 2026
B26: Código | C26: Fornecedor | D26: Lotes recebidos · aceitos | E26: Entregas · no prazo | F26: Nota | G26: Qualidade | H26: Prazo | I26: Índice | J26: Classe | K26: Observação e conduta
B27: F-01 | C27: Polímeros do Vale | D27: 26 · 26 | E27: 26 · 24 | F27: 8 | G27: =26/26 -> 1 | H27: =24/26 -> 0.92307692 | I27: =ROUND(50*G27+30*H27+20*F27/10,1) -> 93.7 | J27: =IF(I27="","",IF(I27>=90,"A",IF(I27>=75,"B",IF(I27>=60,"C","D")))) -> A | K27: Fornecedor único da resina. Segundo fornecedor em homologação. Conduta: Manter. Pode ter menos inspeção no recebimento.
B28: F-02 | C28: Petroquímica Sul | D28: 14 · 14 | E28: 14 · 14 | F28: 9 | G28: =14/14 -> 1 | H28: =14/14 -> 1 | I28: =ROUND(50*G28+30*H28+20*F28/10,1) -> 98 | J28: =IF(I28="","",IF(I28>=90,"A",IF(I28>=75,"B",IF(I28>=60,"C","D")))) -> A | K28: Conduta: Manter. Pode ter menos inspeção no recebimento.
B29: F-03 | C29: Colorfix | D29: 18 · 13 | E29: 18 · 15 | F29: 6 | G29: =13/18 -> 0.72222222 | H29: =15/18 -> 0.83333333 | I29: =ROUND(50*G29+30*H29+20*F29/10,1) -> 73.1 | J29: =IF(I29="","",IF(I29>=90,"A",IF(I29>=75,"B",IF(I29>=60,"C","D")))) -> C | K29: Cinco lotes com tonalidade fora do padrão, devolvidos. Três entregas atrasadas. Conduta: Pedir plano de ação, com prazo. Reavaliar no período seguinte.
B30: F-04 | C30: Tintas Gráficas Ltda. | D30: 9 · 9 | E30: 9 · 9 | F30: 9 | G30: =9/9 -> 1 | H30: =9/9 -> 1 | I30: =ROUND(50*G30+30*H30+20*F30/10,1) -> 98 | J30: =IF(I30="","",IF(I30>=90,"A",IF(I30>=75,"B",IF(I30>=60,"C","D")))) -> A | K30: Conduta: Manter. Pode ter menos inspeção no recebimento.
B31: F-05 | C31: Cliché Print | D31: 22 · 21 | E31: 22 · 20 | F31: 8 | G31: =21/22 -> 0.95454545 | H31: =20/22 -> 0.90909091 | I31: =ROUND(50*G31+30*H31+20*F31/10,1) -> 91 | J31: =IF(I31="","",IF(I31>=90,"A",IF(I31>=75,"B",IF(I31>=60,"C","D")))) -> A | K31: Conduta: Manter. Pode ter menos inspeção no recebimento.
B32: F-06 | C32: Filmes Técnicos | D32: 11 · 11 | E32: 11 · 11 | F32: 8 | G32: =11/11 -> 1 | H32: =11/11 -> 1 | I32: =ROUND(50*G32+30*H32+20*F32/10,1) -> 96 | J32: =IF(I32="","",IF(I32>=90,"A",IF(I32>=75,"B",IF(I32>=60,"C","D")))) -> A | K32: Primeira avaliação depois da homologação. Conduta: Manter. Pode ter menos inspeção no recebimento.
B33: F-07 | C33: Papelão Oeste | D33: 30 · 25 | E33: 30 · 19 | F33: 5 | G33: =25/30 -> 0.83333333 | H33: =19/30 -> 0.63333333 | I33: =ROUND(50*G33+30*H33+20*F33/10,1) -> 70.7 | J33: =IF(I33="","",IF(I33>=90,"A",IF(I33>=75,"B",IF(I33>=60,"C","D")))) -> C | K33: Onze entregas atrasadas. Caixas úmidas em cinco lotes. Conduta: Pedir plano de ação, com prazo. Reavaliar no período seguinte.
B34: F-08 | C34: Paletes Rápido | D34: 12 · 8 | E34: 12 · 7 | F34: 4 | G34: =8/12 -> 0.66666667 | H34: =7/12 -> 0.58333333 | I34: =ROUND(50*G34+30*H34+20*F34/10,1) -> 58.8 | J34: =IF(I34="","",IF(I34>=90,"A",IF(I34>=75,"B",IF(I34>=60,"C","D")))) -> D | K34: Paletes fora da medida e madeira sem tratamento. Licença ambiental vencida. Conduta: Suspender as compras até um plano aprovado, ou desqualificar.
B35: F-09 | C35: Transportes Horizonte | D35: 60 · 58 | E35: 60 · 55 | F35: 8 | G35: =58/60 -> 0.96666667 | H35: =55/60 -> 0.91666667 | I35: =ROUND(50*G35+30*H35+20*F35/10,1) -> 91.8 | J35: =IF(I35="","",IF(I35>=90,"A",IF(I35>=75,"B",IF(I35>=60,"C","D")))) -> A | K35: Duas cargas com avaria. Conduta: Manter. Pode ter menos inspeção no recebimento.
B36: F-10 | C36: Mantec | D36: 6 · 6 | E36: 6 · 5 | F36: 9 | G36: =6/6 -> 1 | H36: =5/6 -> 0.83333333 | I36: =ROUND(50*G36+30*H36+20*F36/10,1) -> 93 | J36: =IF(I36="","",IF(I36>=90,"A",IF(I36>=75,"B",IF(I36>=60,"C","D")))) -> A | K36: Uma manutenção reprogramada pela produção. Conduta: Manter. Pode ter menos inspeção no recebimento.
B37: F-11 | C37: Laboratório Analítica | D37: 15 · 15 | E37: 15 · 12 | F37: 7 | G37: =15/15 -> 1 | H37: =12/15 -> 0.8 | I37: =ROUND(50*G37+30*H37+20*F37/10,1) -> 88 | J37: =IF(I37="","",IF(I37>=90,"A",IF(I37>=75,"B",IF(I37>=60,"C","D")))) -> B | K37: Laudos entregues com atraso em três pedidos. Conduta: Manter e acompanhar. Comunicar o resultado ao fornecedor.
B38: F-12 | C38: Ferramentaria Precisa | D38: 5 · 5 | E38: 5 · 5 | F38: 8 | G38: =5/5 -> 1 | H38: =5/5 -> 1 | I38: =ROUND(50*G38+30*H38+20*F38/10,1) -> 96 | J38: =IF(I38="","",IF(I38>=90,"A",IF(I38>=75,"B",IF(I38>=60,"C","D")))) -> A | K38: Conduta: Manter. Pode ter menos inspeção no recebimento.
B40: Resumo automático | H40: Índice por fornecedor
B41: Fornecedores avaliados | E41: =COUNT(I27:I38) -> 12
B42: Classe A, B, C e D | E42: =COUNTIF(J27:J38,"A")&", "&COUNTIF(J27:J38,"B")&", "&COUNTIF(J27:J38,"C")&" e "&COUNTIF(J27:J38,"D") -> 8, 1, 2 e 1
B43: Média do índice | E43: =AVERAGE(I27:I38) -> 87.341667
B44: Menor índice | E44: =INDEX(C27:C38,MATCH(MIN(I27:I38),I27:I38,0)) -> Paletes Rápido
...

Sheet Exemplo 2 - Pizzaria
B1: Avaliação de fornecedores
B2: Exemplo preenchido, para consulta. Use as abas Cadastro, Homologação, Avaliação e Ocorrências para os seus fornecedores.
B4: Organização | D4: Pizzaria (loja com salão e delivery)
B5: Data de referência | D5: 46433
B6: Período avaliado | D6: Agosto de 2026 a janeiro de 2027
B7: Quem avaliou | D7: Gerente da loja, com o pizzaiolo líder
B8: Origem | D8: Decisão da análise crítica de 14/12/2026: avaliar os fornecedores de insumos críticos a cada semestre, com registro.
B10: Cadastro e homologação
B11: Código | C11: Fornecedor | D11: O que fornece | E11: Tipo | F11: Criticidade | G11: Homologado em | H11: Válida até | I11: Docs. em dia? | J11: Situação
B12: P1 | C12: Laticínios Serra | D12: Queijo muçarela | E12: Produto | F12: Crítico | G12: 46360 | H12: =IF(G12="","",EDATE(G12,24)) -> 47091 | I12: Sim | J12: =IF(F12="Não crítico","Não crítico: sem homologação",IF(G12="","Falta a homologação",IF(I12="Não","Documentos pendentes",IF(H12<$D$5,"Homologação vencida","Homologado")))) -> Homologado
B13: P2 | C13: Queijaria do Campo | D13: Queijo muçarela, segundo fornecedor | E13: Produto | F13: Crítico | G13: 46346 | H13: =IF(G13="","",EDATE(G13,24)) -> 47077 | I13: Sim | J13: =IF(F13="Não crítico","Não crítico: sem homologação",IF(G13="","Falta a homologação",IF(I13="Não","Documentos pendentes",IF(H13<$D$5,"Homologação vencida","Homologado")))) -> Homologado
B14: P3 | C14: Moinho Bom Trigo | D14: Farinha de trigo | E14: Produto | F14: Crítico | G14: 46360 | H14: =IF(G14="","",EDATE(G14,24)) -> 47091 | I14: Sim | J14: =IF(F14="Não crítico","Não crítico: sem homologação",IF(G14="","Falta a homologação",IF(I14="Não","Documentos pendentes",IF(H14<$D$5,"Homologação vencida","Homologado")))) -> Homologado
B15: P4 | C15: Conservas Vale Verde | D15: Molho e tomate pelado | E15: Produto | F15: Crítico | G15: 46360 | H15: =IF(G15="","",EDATE(G15,24)) -> 47091 | I15: Sim | J15: =IF(F15="Não crítico","Não crítico: sem homologação",IF(G15="","Falta a homologação",IF(I15="Não","Documentos pendentes",IF(H15<$D$5,"Homologação vencida","Homologado")))) -> Homologado
B16: P5 | C16: Embalagens Rápidas | D16: Caixas de pizza | E16: Produto | F16: Não crítico | G16: 46360 | H16: =IF(G16="","",EDATE(G16,24)) -> 47091 | I16: Sim | J16: =IF(F16="Não crítico","Não crítico: sem homologação",IF(G16="","Falta a homologação",IF(I16="Não","Documentos pendentes",IF(H16<$D$5,"Homologação vencida","Homologado")))) -> Não crítico: sem homologação
B17: P6 | C17: Gás Central | D17: Gás de cozinha | E17: Produto | F17: Crítico | G17: 46360 | H17: =IF(G17="","",EDATE(G17,24)) -> 47091 | I17: Não | J17: =IF(F17="Não crítico","Não crítico: sem homologação",IF(G17="","Falta a homologação",IF(I17="Não","Documentos pendentes",IF(H17<$D$5,"Homologação vencida","Homologado")))) -> Documentos pendentes
B18: P7 | C18: Oficina Duas Rodas | D18: Revisão mensal das motos | E18: Serviço | F18: Crítico | G18: 46360 | H18: =IF(G18="","",EDATE(G18,24)) -> 47091 | I18: Sim | J18: =IF(F18="Não crítico","Não crítico: sem homologação",IF(G18="","Falta a homologação",IF(I18="Não","Documentos pendentes",IF(H18<$D$5,"Homologação vencida","Homologado")))) -> Homologado
B20: Avaliação de desempenho · agosto de 2026 a janeiro de 2027
B21: Código | C21: Fornecedor | D21: Lotes recebidos · aceitos | E21: Entregas · no prazo | F21: Nota | G21: Qualidade | H21: Prazo | I21: Índice | J21: Classe | K21: Observação e conduta
B22: P1 | C22: Laticínios Serra | D22: 24 · 23 | E22: 24 · 21 | F22: 7 | G22: =23/24 -> 0.95833333 | H22: =21/24 -> 0.875 | I22: =ROUND(50*G22+30*H22+20*F22/10,1) -> 88.2 | J22: =IF(I22="","",IF(I22>=90,"A",IF(I22>=75,"B",IF(I22>=60,"C","D")))) -> B | K22: Três atrasos, um deles no sábado. Um lote devolvido por temperatura. Conduta: Manter e acompanhar. Comunicar o resultado ao fornecedor.
B23: P2 | C23: Queijaria do Campo | D23: 8 · 8 | E23: 8 · 8 | F23: 8 | G23: =8/8 -> 1 | H23: =8/8 -> 1 | I23: =ROUND(50*G23+30*H23+20*F23/10,1) -> 96 | J23: =IF(I23="","",IF(I23>=90,"A",IF(I23>=75,"B",IF(I23>=60,"C","D")))) -> A | K23: Fornece desde novembro. Primeira avaliação. Conduta: Manter. Pode ter menos inspeção no recebimento.
B24: P3 | C24: Moinho Bom Trigo | D24: 12 · 12 | E24: 12 · 12 | F24: 9 | G24: =12/12 -> 1 | H24: =12/12 -> 1 | I24: =ROUND(50*G24+30*H24+20*F24/10,1) -> 98 | J24: =IF(I24="","",IF(I24>=90,"A",IF(I24>=75,"B",IF(I24>=60,"C","D")))) -> A | K24: Conduta: Manter. Pode ter menos inspeção no recebimento.
B25: P4 | C25: Conservas Vale Verde | D25: 12 · 12 | E25: 12 · 11 | F25: 8 | G25: =12/12 -> 1 | H25: =11/12 -> 0.91666667 | I25: =ROUND(50*G25+30*H25+20*F25/10,1) -> 93.5 | J25: =IF(I25="","",IF(I25>=90,"A",IF(I25>=75,"B",IF(I25>=60,"C","D")))) -> A | K25: Conduta: Manter. Pode ter menos inspeção no recebimento.
B26: P5 | C26: Embalagens Rápidas | D26: 6 · 6 | E26: 6 · 6 | F26: 8 | G26: =6/6 -> 1 | H26: =6/6 -> 1 | I26: =ROUND(50*G26+30*H26+20*F26/10,1) -> 96 | J26: =IF(I26="","",IF(I26>=90,"A",IF(I26>=75,"B",IF(I26>=60,"C","D")))) -> A | K26: Conduta: Manter. Pode ter menos inspeção no recebimento.
B27: P6 | C27: Gás Central | D27: 26 · 26 | E27: 26 · 26 | F27: 7 | G27: =26/26 -> 1 | H27: =26/26 -> 1 | I27: =ROUND(50*G27+30*H27+20*F27/10,1) -> 94 | J27: =IF(I27="","",IF(I27>=90,"A",IF(I27>=75,"B",IF(I27>=60,"C","D")))) -> A | K27: Nota fiscal sem o número do contrato em cinco entregas. Conduta: Manter. Pode ter menos inspeção no recebimento.
B28: P7 | C28: Oficina Duas Rodas | D28: 6 · 5 | E28: 6 · 6 | F28: 8 | G28: =5/6 -> 0.83333333 | H28: =6/6 -> 1 | I28: =ROUND(50*G28+30*H28+20*F28/10,1) -> 87.7 | J28: =IF(I28="","",IF(I28>=90,"A",IF(I28>=75,"B",IF(I28>=60,"C","D")))) -> B | K28: Uma revisão refeita: freio com folga. Conduta: Manter e acompanhar. Comunicar o resultado ao fornecedor.
B30: Resumo automático | H30: Índice por fornecedor
B31: Fornecedores avaliados | E31: =COUNT(I22:I28) -> 7
B32: Classe A, B, C e D | E32: =COUNTIF(J22:J28,"A")&", "&COUNTIF(J22:J28,"B")&", "&COUNTIF(J22:J28,"C")&" e "&COUNTIF(J22:J28,"D") -> 5, 2, 0 e 0
B33: Média do índice | E33: =AVERAGE(I22:I28) -> 93.342857
B34: Menor índice | E34: =INDEX(C22:C28,MATCH(MIN(I22:I28),I22:I28,0)) -> Oficina Duas Rodas
B35: Homologações vencidas ou pendentes | E35: =COUNTIF(J12:J18,"Homologação vencida")+COUNTIF(J12:J18,"Documentos pendentes")+COUNTIF(J12:J18,"Falta a homologação") -> 1
