Workbook

Sheet Instruções
B1: Ishikawa — Como usar esta planilha
B2: Modelo para levantar, verificar e aprofundar as causas de um problema.
B4: Legenda: onde preencher
B5: Amarelo-claro | C5: Células de entrada. É aqui que você digita.
B6: Cinza | C6: Células calculadas ou fixas (rótulos, contagens, avisos). Não altere.
B7: Cinza em itálico | C7: Linha de exemplo (marcada com “Ex.”). Mostra o formato esperado e não entra nas contagens.
B8: Listas suspensas | C8: Colunas de probabilidade, resultado, código e status aceitam apenas as opções da lista.
B9: Comentários | C9: Células com triângulo vermelho no canto trazem uma dica de preenchimento. Passe o mouse sobre elas.
B11: As seis categorias (6M)
B12: A — Método | C12: Como o trabalho é feito: procedimentos, sequência, regras.
B13: B — Mão de obra | C13: Quem faz o trabalho: treinamento, quantidade, escala.
B14: C — Máquina | C14: Com o que se faz: equipamentos, ferramentas, sistemas.
B15: D — Material | C15: O que entra no processo: insumos e informações.
B16: E — Medição | C16: Como se mede: instrumentos, indicadores, critérios.
B17: F — Meio ambiente | C17: Onde se faz: espaço, temperatura, ruído, clima de trabalho.
B18: Nomes | C18: Os nomes das categorias podem ser trocados na aba Ishikawa. Em serviços, é comum usar procedimentos, pessoas, sistemas, informações, indicadores e ambiente.
B20: Ordem recomendada de preenchimento
B21: Passo 1 | C21: Aba Ishikawa: preencha o cabeçalho, com o efeito escrito como problema, com número, local e período.
B22: Passo 2 | C22: Aba Ishikawa: confira os nomes das seis categorias e ajuste ao seu processo.
B23: Passo 3 | C23: Aba Ishikawa: escreva as causas de cada categoria e a subcausa de cada uma (por quê?).
B24: Passo 4 | C24: Aba Ishikawa: marque a probabilidade e defina como verificar as causas mais prováveis.
B25: Passo 5 | C25: Aba Ishikawa: depois da verificação, registre o resultado e a evidência de cada causa.
B26: Passo 6 | C26: Aba Diagrama: leia o diagrama montado e confira se ele conta a história do problema.
B27: Passo 7 | C27: Aba 5 Porquês: aprofunde as causas confirmadas até a causa raiz.
B28: Passo 8 | C28: Aba Ishikawa: marque as causas que seguem para o plano. Aba Plano de ação: defina as ações.
B29: Passo 9 | C29: Aba Checklist: valide a análise com o grupo.
B31: Abas da planilha
B32: Ishikawa | C32: Modelo principal. Cabeçalho, seis categorias com cinco causas cada e resumo automático.
B33: Diagrama | C33: Visão do diagrama para leitura e impressão. É toda calculada.
B34: 5 Porquês | C34: Cadeia de porquês de até seis causas, com a causa raiz e o teste de volta.
B35: Plano de ação | C35: Lista sozinha as causas que seguem para o plano e pede ação, responsável e prazo.
B36: Checklist | C36: Doze verificações de qualidade da análise, com percentual de conclusão.
B37: Exemplo 1 - Pizzaria | C37: Análise preenchida com as seis categorias dos 6M e doze hipóteses.
B38: Exemplo 2 - Compras | C38: Análise preenchida com categorias adaptadas e uma categoria sem causas.
B40: Regras e premissas do modelo
B41: Códigos | C41: Cada causa tem um código fixo, formado pela letra da categoria e pelo número da linha: de A1 a F5. As abas 5 Porquês e Plano de ação usam o código para buscar o texto da causa.
B42: Hipótese e causa | C42: Toda causa começa como hipótese. O resultado só deve ser marcado como Confirmada ou Descartada depois da verificação, com a evidência registrada.
B43: Marcações do diagrama | C43: Na aba Diagrama, ● indica causa confirmada que segue para o plano; ○, causa confirmada que fica para depois; ✕, causa descartada. Causa sem marca ainda não foi verificada.
B44: Ação atrasada | C44: Uma ação é considerada atrasada quando o prazo é anterior à data de hoje e o status não é Concluída nem Cancelada.
B45: Capacidade | C45: A planilha comporta 30 causas, 6 cadeias de porquês e 12 causas no plano de ação. Se faltar espaço, o efeito provavelmente está amplo demais: divida o problema.
...

Sheet Ishikawa
B1: Ishikawa — Análise de causa e efeito
B2: Preencha as células em amarelo-claro. As células cinza são calculadas automaticamente.
B4: Tema da análise | G4: Responsável
B5: Área / unidade | G5: Data
B6: Elaborado por | G6: Versão
B7: Efeito (problema)
B8: Onde e quando ocorre | G8: Participantes
B9: Origem da análise
B11: # | C11: Causa provável | E11: Por quê? (subcausa) | F11: Probabilidade | G11: Como verificar | H11: Resultado | I11: Evidência | J11: Segue para o plano?
C12: Fato que pode produzir o efeito | E12: Por que essa causa acontece? | F12: Na opinião do grupo | G12: Contagem, comparação, observação, medição ou teste | H12: O que os dados mostraram | I12: Número ou fato que sustenta o resultado | J12: Sim ou Não
B13: Ex. | C13: Pedidos saem um a um, sem agrupamento por bairro | E13: A expedição não separa os pedidos por zona | F13: Alta | G13: Acompanhar 50 saídas no pico e mapear as rotas | H13: Confirmada | I13: Em 31 das 50 saídas, outro entregador saiu para o mesmo bairro menos de 10 minutos depois | J13: Sim | L13: Apoio
B14: A | C14: Método | F14: Como o trabalho é feito: procedimentos, sequência, regras.
B15: A1 | L15: =IF(J15="Sim",COUNTIF($J$14:J15,"Sim"),"")
B16: A2 | L16: =IF(J16="Sim",COUNTIF($J$14:J16,"Sim"),"")
B17: A3 | L17: =IF(J17="Sim",COUNTIF($J$14:J17,"Sim"),"")
B18: A4 | L18: =IF(J18="Sim",COUNTIF($J$14:J18,"Sim"),"")
B19: A5 | L19: =IF(J19="Sim",COUNTIF($J$14:J19,"Sim"),"")
B20: B | C20: Mão de obra | F20: Quem faz o trabalho: treinamento, quantidade, escala.
B21: B1 | L21: =IF(J21="Sim",COUNTIF($J$14:J21,"Sim"),"")
B22: B2 | L22: =IF(J22="Sim",COUNTIF($J$14:J22,"Sim"),"")
B23: B3 | L23: =IF(J23="Sim",COUNTIF($J$14:J23,"Sim"),"")
B24: B4 | L24: =IF(J24="Sim",COUNTIF($J$14:J24,"Sim"),"")
B25: B5 | L25: =IF(J25="Sim",COUNTIF($J$14:J25,"Sim"),"")
B26: C | C26: Máquina | F26: Com o que se faz: equipamentos, ferramentas, sistemas.
B27: C1 | L27: =IF(J27="Sim",COUNTIF($J$14:J27,"Sim"),"")
B28: C2 | L28: =IF(J28="Sim",COUNTIF($J$14:J28,"Sim"),"")
B29: C3 | L29: =IF(J29="Sim",COUNTIF($J$14:J29,"Sim"),"")
B30: C4 | L30: =IF(J30="Sim",COUNTIF($J$14:J30,"Sim"),"")
B31: C5 | L31: =IF(J31="Sim",COUNTIF($J$14:J31,"Sim"),"")
B32: D | C32: Material | F32: O que entra no processo: insumos e informações.
B33: D1 | L33: =IF(J33="Sim",COUNTIF($J$14:J33,"Sim"),"")
B34: D2 | L34: =IF(J34="Sim",COUNTIF($J$14:J34,"Sim"),"")
B35: D3 | L35: =IF(J35="Sim",COUNTIF($J$14:J35,"Sim"),"")
B36: D4 | L36: =IF(J36="Sim",COUNTIF($J$14:J36,"Sim"),"")
B37: D5 | L37: =IF(J37="Sim",COUNTIF($J$14:J37,"Sim"),"")
B38: E | C38: Medição | F38: Como se mede: instrumentos, indicadores, critérios.
B39: E1 | L39: =IF(J39="Sim",COUNTIF($J$14:J39,"Sim"),"")
B40: E2 | L40: =IF(J40="Sim",COUNTIF($J$14:J40,"Sim"),"")
B41: E3 | L41: =IF(J41="Sim",COUNTIF($J$14:J41,"Sim"),"")
B42: E4 | L42: =IF(J42="Sim",COUNTIF($J$14:J42,"Sim"),"")
...

Sheet Diagrama
B1: Diagrama de Ishikawa
B2: Esta aba é calculada a partir da aba Ishikawa. Não há nada para digitar aqui.
B4: =Ishikawa!C14 -> Método | C4: =Ishikawa!C20 -> Mão de obra | D4: =Ishikawa!C26 -> Máquina
B5: =IF(Ishikawa!C15="","",IF(Ishikawa!H15="Confirmada",IF(Ishikawa!J15="Sim","● ","○ "),IF(Ishikawa!H15="Descartada","✕ ",""))&Ishikawa!C15) | C5: =IF(Ishikawa!C21="","",IF(Ishikawa!H21="Confirmada",IF(Ishikawa!J21="Sim","● ","○ "),IF(Ishikawa!H21="Descartada","✕ ",""))&Ishikawa!C21) | D5: =IF(Ishikawa!C27="","",IF(Ishikawa!H27="Confirmada",IF(Ishikawa!J27="Sim","● ","○ "),IF(Ishikawa!H27="Descartada","✕ ",""))&Ishikawa!C27)
B6: =IF(Ishikawa!C16="","",IF(Ishikawa!H16="Confirmada",IF(Ishikawa!J16="Sim","● ","○ "),IF(Ishikawa!H16="Descartada","✕ ",""))&Ishikawa!C16) | C6: =IF(Ishikawa!C22="","",IF(Ishikawa!H22="Confirmada",IF(Ishikawa!J22="Sim","● ","○ "),IF(Ishikawa!H22="Descartada","✕ ",""))&Ishikawa!C22) | D6: =IF(Ishikawa!C28="","",IF(Ishikawa!H28="Confirmada",IF(Ishikawa!J28="Sim","● ","○ "),IF(Ishikawa!H28="Descartada","✕ ",""))&Ishikawa!C28)
B7: =IF(Ishikawa!C17="","",IF(Ishikawa!H17="Confirmada",IF(Ishikawa!J17="Sim","● ","○ "),IF(Ishikawa!H17="Descartada","✕ ",""))&Ishikawa!C17) | C7: =IF(Ishikawa!C23="","",IF(Ishikawa!H23="Confirmada",IF(Ishikawa!J23="Sim","● ","○ "),IF(Ishikawa!H23="Descartada","✕ ",""))&Ishikawa!C23) | D7: =IF(Ishikawa!C29="","",IF(Ishikawa!H29="Confirmada",IF(Ishikawa!J29="Sim","● ","○ "),IF(Ishikawa!H29="Descartada","✕ ",""))&Ishikawa!C29) | F7: EFEITO
B8: =IF(Ishikawa!C18="","",IF(Ishikawa!H18="Confirmada",IF(Ishikawa!J18="Sim","● ","○ "),IF(Ishikawa!H18="Descartada","✕ ",""))&Ishikawa!C18) | C8: =IF(Ishikawa!C24="","",IF(Ishikawa!H24="Confirmada",IF(Ishikawa!J24="Sim","● ","○ "),IF(Ishikawa!H24="Descartada","✕ ",""))&Ishikawa!C24) | D8: =IF(Ishikawa!C30="","",IF(Ishikawa!H30="Confirmada",IF(Ishikawa!J30="Sim","● ","○ "),IF(Ishikawa!H30="Descartada","✕ ",""))&Ishikawa!C30) | F8: =IF(Ishikawa!D7="","Efeito: preencha na aba Ishikawa",Ishikawa!D7) -> Efeito: preencha na aba Ishikawa
B9: =IF(Ishikawa!C19="","",IF(Ishikawa!H19="Confirmada",IF(Ishikawa!J19="Sim","● ","○ "),IF(Ishikawa!H19="Descartada","✕ ",""))&Ishikawa!C19) | C9: =IF(Ishikawa!C25="","",IF(Ishikawa!H25="Confirmada",IF(Ishikawa!J25="Sim","● ","○ "),IF(Ishikawa!H25="Descartada","✕ ",""))&Ishikawa!C25) | D9: =IF(Ishikawa!C31="","",IF(Ishikawa!H31="Confirmada",IF(Ishikawa!J31="Sim","● ","○ "),IF(Ishikawa!H31="Descartada","✕ ",""))&Ishikawa!C31)
E10: ►
B11: =IF(Ishikawa!C37="","",IF(Ishikawa!H37="Confirmada",IF(Ishikawa!J37="Sim","● ","○ "),IF(Ishikawa!H37="Descartada","✕ ",""))&Ishikawa!C37) | C11: =IF(Ishikawa!C43="","",IF(Ishikawa!H43="Confirmada",IF(Ishikawa!J43="Sim","● ","○ "),IF(Ishikawa!H43="Descartada","✕ ",""))&Ishikawa!C43) | D11: =IF(Ishikawa!C49="","",IF(Ishikawa!H49="Confirmada",IF(Ishikawa!J49="Sim","● ","○ "),IF(Ishikawa!H49="Descartada","✕ ",""))&Ishikawa!C49)
B12: =IF(Ishikawa!C36="","",IF(Ishikawa!H36="Confirmada",IF(Ishikawa!J36="Sim","● ","○ "),IF(Ishikawa!H36="Descartada","✕ ",""))&Ishikawa!C36) | C12: =IF(Ishikawa!C42="","",IF(Ishikawa!H42="Confirmada",IF(Ishikawa!J42="Sim","● ","○ "),IF(Ishikawa!H42="Descartada","✕ ",""))&Ishikawa!C42) | D12: =IF(Ishikawa!C48="","",IF(Ishikawa!H48="Confirmada",IF(Ishikawa!J48="Sim","● ","○ "),IF(Ishikawa!H48="Descartada","✕ ",""))&Ishikawa!C48)
B13: =IF(Ishikawa!C35="","",IF(Ishikawa!H35="Confirmada",IF(Ishikawa!J35="Sim","● ","○ "),IF(Ishikawa!H35="Descartada","✕ ",""))&Ishikawa!C35) | C13: =IF(Ishikawa!C41="","",IF(Ishikawa!H41="Confirmada",IF(Ishikawa!J41="Sim","● ","○ "),IF(Ishikawa!H41="Descartada","✕ ",""))&Ishikawa!C41) | D13: =IF(Ishikawa!C47="","",IF(Ishikawa!H47="Confirmada",IF(Ishikawa!J47="Sim","● ","○ "),IF(Ishikawa!H47="Descartada","✕ ",""))&Ishikawa!C47)
B14: =IF(Ishikawa!C34="","",IF(Ishikawa!H34="Confirmada",IF(Ishikawa!J34="Sim","● ","○ "),IF(Ishikawa!H34="Descartada","✕ ",""))&Ishikawa!C34) | C14: =IF(Ishikawa!C40="","",IF(Ishikawa!H40="Confirmada",IF(Ishikawa!J40="Sim","● ","○ "),IF(Ishikawa!H40="Descartada","✕ ",""))&Ishikawa!C40) | D14: =IF(Ishikawa!C46="","",IF(Ishikawa!H46="Confirmada",IF(Ishikawa!J46="Sim","● ","○ "),IF(Ishikawa!H46="Descartada","✕ ",""))&Ishikawa!C46)
B15: =IF(Ishikawa!C33="","",IF(Ishikawa!H33="Confirmada",IF(Ishikawa!J33="Sim","● ","○ "),IF(Ishikawa!H33="Descartada","✕ ",""))&Ishikawa!C33) | C15: =IF(Ishikawa!C39="","",IF(Ishikawa!H39="Confirmada",IF(Ishikawa!J39="Sim","● ","○ "),IF(Ishikawa!H39="Descartada","✕ ",""))&Ishikawa!C39) | D15: =IF(Ishikawa!C45="","",IF(Ishikawa!H45="Confirmada",IF(Ishikawa!J45="Sim","● ","○ "),IF(Ishikawa!H45="Descartada","✕ ",""))&Ishikawa!C45)
B16: =Ishikawa!C32 -> Material | C16: =Ishikawa!C38 -> Medição | D16: =Ishikawa!C44 -> Meio ambiente
B18: Marcações: ● confirmada, segue para o plano · ○ confirmada, fica para depois · ✕ descartada pelos dados · sem marca: ainda não verificada
B20: Resumo automático
B21: Causas levantadas | D21: =Ishikawa!F52 -> 0
B22: Causas confirmadas | D22: =Ishikawa!F54 -> 0
B23: Causas descartadas | D23: =Ishikawa!F55 -> 0
B24: Causas que seguem para o plano | D24: =Ishikawa!F57 -> 0

Sheet 5 Porquês
B1: 5 porquês — da causa à causa raiz
B2: Escolha o código de uma causa confirmada e pergunte por quê a cada resposta, até chegar a algo que se possa mudar.
B4: # | C4: Código | D4: Causa | E4: 1º por quê? | F4: 2º por quê? | G4: 3º por quê? | H4: 4º por quê? | I4: 5º por quê? | J4: Causa raiz | K4: Teste de volta | L4: Situação
B5: Ex. | C5: B1 | D5: Escala de entregadores igual em todos os dias | E5: A escala foi montada pelo movimento médio da semana | F5: Os pedidos não são analisados por faixa de horário | G5: O relatório do aplicativo mostra só o total do dia | J5: A escala não acompanha o pico, porque os pedidos não são analisados por horário | K5: Sim | L5: Concluída
B6: 1 | D6: =IF(C6="","",INDEX(Ishikawa!$C$14:$C$49,(CODE(LEFT(C6,1))-65)*6+VALUE(MID(C6,2,1))+1)&"") | L6: =IF(C6="","",IF(D6="","Código sem causa",IF(COUNTA(E6:I6)<3,"Poucos porquês",IF(J6="","Falta a causa raiz",IF(K6="Sim","Concluída",IF(K6="Não","Refazer a cadeia","Falta o teste de volta"))))))
B7: 2 | D7: =IF(C7="","",INDEX(Ishikawa!$C$14:$C$49,(CODE(LEFT(C7,1))-65)*6+VALUE(MID(C7,2,1))+1)&"") | L7: =IF(C7="","",IF(D7="","Código sem causa",IF(COUNTA(E7:I7)<3,"Poucos porquês",IF(J7="","Falta a causa raiz",IF(K7="Sim","Concluída",IF(K7="Não","Refazer a cadeia","Falta o teste de volta"))))))
B8: 3 | D8: =IF(C8="","",INDEX(Ishikawa!$C$14:$C$49,(CODE(LEFT(C8,1))-65)*6+VALUE(MID(C8,2,1))+1)&"") | L8: =IF(C8="","",IF(D8="","Código sem causa",IF(COUNTA(E8:I8)<3,"Poucos porquês",IF(J8="","Falta a causa raiz",IF(K8="Sim","Concluída",IF(K8="Não","Refazer a cadeia","Falta o teste de volta"))))))
B9: 4 | D9: =IF(C9="","",INDEX(Ishikawa!$C$14:$C$49,(CODE(LEFT(C9,1))-65)*6+VALUE(MID(C9,2,1))+1)&"") | L9: =IF(C9="","",IF(D9="","Código sem causa",IF(COUNTA(E9:I9)<3,"Poucos porquês",IF(J9="","Falta a causa raiz",IF(K9="Sim","Concluída",IF(K9="Não","Refazer a cadeia","Falta o teste de volta"))))))
B10: 5 | D10: =IF(C10="","",INDEX(Ishikawa!$C$14:$C$49,(CODE(LEFT(C10,1))-65)*6+VALUE(MID(C10,2,1))+1)&"") | L10: =IF(C10="","",IF(D10="","Código sem causa",IF(COUNTA(E10:I10)<3,"Poucos porquês",IF(J10="","Falta a causa raiz",IF(K10="Sim","Concluída",IF(K10="Não","Refazer a cadeia","Falta o teste de volta"))))))
B11: 6 | D11: =IF(C11="","",INDEX(Ishikawa!$C$14:$C$49,(CODE(LEFT(C11,1))-65)*6+VALUE(MID(C11,2,1))+1)&"") | L11: =IF(C11="","",IF(D11="","Código sem causa",IF(COUNTA(E11:I11)<3,"Poucos porquês",IF(J11="","Falta a causa raiz",IF(K11="Sim","Concluída",IF(K11="Não","Refazer a cadeia","Falta o teste de volta"))))))
B13: Resumo automático
B14: Cadeias registradas | J14: =COUNTA(C6:C11) -> 0
B15: Cadeias concluídas | J15: =COUNTIF(L6:L11,"Concluída") -> 0
B16: Causas confirmadas sem cadeia de porquês | J16: =SUMPRODUCT((Ishikawa!H14:H49="Confirmada")*(COUNTIF($C$6:$C$11,Ishikawa!B14:B49)=0)) -> 0
B17: Aviso | J17: =IF(J14=0,"Escolha as causas a aprofundar",IF(J15<J14,"Há cadeia incompleta: veja a coluna Situação","OK")) -> Escolha as causas a aprofundar

Sheet Plano de ação
B1: Plano de ação
B2: As causas marcadas com “Sim” na aba Ishikawa aparecem aqui. Defina a ação de cada uma.
B4: # | C4: Código | D4: Categoria | E4: Causa confirmada | F4: Ação | G4: Responsável | H4: Prazo | I4: Status | J4: Situação
B5: Ex. | C5: A1 | D5: Método | E5: Pedidos saem um a um, sem agrupamento por bairro | F5: Agrupar os pedidos por bairro antes da saída | G5: Líder da expedição | H5: 46325 | I5: Em andamento | J5: No prazo
B6: 1 | C6: =IFERROR(INDEX(Ishikawa!$B$14:$B$49,MATCH($B6,Ishikawa!$L$14:$L$49,0))&"","") | D6: =IFERROR(INDEX(Ishikawa!$C$14:$C$49,INT((MATCH($B6,Ishikawa!$L$14:$L$49,0)-1)/6)*6+1)&"","") | E6: =IFERROR(INDEX(Ishikawa!$C$14:$C$49,MATCH($B6,Ishikawa!$L$14:$L$49,0))&"","") | J6: =IF(F6="","",IF(OR(I6="Concluída",I6="Cancelada"),I6,IF(H6="","Sem prazo",IF(H6<TODAY(),"Atrasada","No prazo"))))
B7: 2 | C7: =IFERROR(INDEX(Ishikawa!$B$14:$B$49,MATCH($B7,Ishikawa!$L$14:$L$49,0))&"","") | D7: =IFERROR(INDEX(Ishikawa!$C$14:$C$49,INT((MATCH($B7,Ishikawa!$L$14:$L$49,0)-1)/6)*6+1)&"","") | E7: =IFERROR(INDEX(Ishikawa!$C$14:$C$49,MATCH($B7,Ishikawa!$L$14:$L$49,0))&"","") | J7: =IF(F7="","",IF(OR(I7="Concluída",I7="Cancelada"),I7,IF(H7="","Sem prazo",IF(H7<TODAY(),"Atrasada","No prazo"))))
B8: 3 | C8: =IFERROR(INDEX(Ishikawa!$B$14:$B$49,MATCH($B8,Ishikawa!$L$14:$L$49,0))&"","") | D8: =IFERROR(INDEX(Ishikawa!$C$14:$C$49,INT((MATCH($B8,Ishikawa!$L$14:$L$49,0)-1)/6)*6+1)&"","") | E8: =IFERROR(INDEX(Ishikawa!$C$14:$C$49,MATCH($B8,Ishikawa!$L$14:$L$49,0))&"","") | J8: =IF(F8="","",IF(OR(I8="Concluída",I8="Cancelada"),I8,IF(H8="","Sem prazo",IF(H8<TODAY(),"Atrasada","No prazo"))))
B9: 4 | C9: =IFERROR(INDEX(Ishikawa!$B$14:$B$49,MATCH($B9,Ishikawa!$L$14:$L$49,0))&"","") | D9: =IFERROR(INDEX(Ishikawa!$C$14:$C$49,INT((MATCH($B9,Ishikawa!$L$14:$L$49,0)-1)/6)*6+1)&"","") | E9: =IFERROR(INDEX(Ishikawa!$C$14:$C$49,MATCH($B9,Ishikawa!$L$14:$L$49,0))&"","") | J9: =IF(F9="","",IF(OR(I9="Concluída",I9="Cancelada"),I9,IF(H9="","Sem prazo",IF(H9<TODAY(),"Atrasada","No prazo"))))
B10: 5 | C10: =IFERROR(INDEX(Ishikawa!$B$14:$B$49,MATCH($B10,Ishikawa!$L$14:$L$49,0))&"","") | D10: =IFERROR(INDEX(Ishikawa!$C$14:$C$49,INT((MATCH($B10,Ishikawa!$L$14:$L$49,0)-1)/6)*6+1)&"","") | E10: =IFERROR(INDEX(Ishikawa!$C$14:$C$49,MATCH($B10,Ishikawa!$L$14:$L$49,0))&"","") | J10: =IF(F10="","",IF(OR(I10="Concluída",I10="Cancelada"),I10,IF(H10="","Sem prazo",IF(H10<TODAY(),"Atrasada","No prazo"))))
B11: 6 | C11: =IFERROR(INDEX(Ishikawa!$B$14:$B$49,MATCH($B11,Ishikawa!$L$14:$L$49,0))&"","") | D11: =IFERROR(INDEX(Ishikawa!$C$14:$C$49,INT((MATCH($B11,Ishikawa!$L$14:$L$49,0)-1)/6)*6+1)&"","") | E11: =IFERROR(INDEX(Ishikawa!$C$14:$C$49,MATCH($B11,Ishikawa!$L$14:$L$49,0))&"","") | J11: =IF(F11="","",IF(OR(I11="Concluída",I11="Cancelada"),I11,IF(H11="","Sem prazo",IF(H11<TODAY(),"Atrasada","No prazo"))))
B12: 7 | C12: =IFERROR(INDEX(Ishikawa!$B$14:$B$49,MATCH($B12,Ishikawa!$L$14:$L$49,0))&"","") | D12: =IFERROR(INDEX(Ishikawa!$C$14:$C$49,INT((MATCH($B12,Ishikawa!$L$14:$L$49,0)-1)/6)*6+1)&"","") | E12: =IFERROR(INDEX(Ishikawa!$C$14:$C$49,MATCH($B12,Ishikawa!$L$14:$L$49,0))&"","") | J12: =IF(F12="","",IF(OR(I12="Concluída",I12="Cancelada"),I12,IF(H12="","Sem prazo",IF(H12<TODAY(),"Atrasada","No prazo"))))
B13: 8 | C13: =IFERROR(INDEX(Ishikawa!$B$14:$B$49,MATCH($B13,Ishikawa!$L$14:$L$49,0))&"","") | D13: =IFERROR(INDEX(Ishikawa!$C$14:$C$49,INT((MATCH($B13,Ishikawa!$L$14:$L$49,0)-1)/6)*6+1)&"","") | E13: =IFERROR(INDEX(Ishikawa!$C$14:$C$49,MATCH($B13,Ishikawa!$L$14:$L$49,0))&"","") | J13: =IF(F13="","",IF(OR(I13="Concluída",I13="Cancelada"),I13,IF(H13="","Sem prazo",IF(H13<TODAY(),"Atrasada","No prazo"))))
B14: 9 | C14: =IFERROR(INDEX(Ishikawa!$B$14:$B$49,MATCH($B14,Ishikawa!$L$14:$L$49,0))&"","") | D14: =IFERROR(INDEX(Ishikawa!$C$14:$C$49,INT((MATCH($B14,Ishikawa!$L$14:$L$49,0)-1)/6)*6+1)&"","") | E14: =IFERROR(INDEX(Ishikawa!$C$14:$C$49,MATCH($B14,Ishikawa!$L$14:$L$49,0))&"","") | J14: =IF(F14="","",IF(OR(I14="Concluída",I14="Cancelada"),I14,IF(H14="","Sem prazo",IF(H14<TODAY(),"Atrasada","No prazo"))))
B15: 10 | C15: =IFERROR(INDEX(Ishikawa!$B$14:$B$49,MATCH($B15,Ishikawa!$L$14:$L$49,0))&"","") | D15: =IFERROR(INDEX(Ishikawa!$C$14:$C$49,INT((MATCH($B15,Ishikawa!$L$14:$L$49,0)-1)/6)*6+1)&"","") | E15: =IFERROR(INDEX(Ishikawa!$C$14:$C$49,MATCH($B15,Ishikawa!$L$14:$L$49,0))&"","") | J15: =IF(F15="","",IF(OR(I15="Concluída",I15="Cancelada"),I15,IF(H15="","Sem prazo",IF(H15<TODAY(),"Atrasada","No prazo"))))
B16: 11 | C16: =IFERROR(INDEX(Ishikawa!$B$14:$B$49,MATCH($B16,Ishikawa!$L$14:$L$49,0))&"","") | D16: =IFERROR(INDEX(Ishikawa!$C$14:$C$49,INT((MATCH($B16,Ishikawa!$L$14:$L$49,0)-1)/6)*6+1)&"","") | E16: =IFERROR(INDEX(Ishikawa!$C$14:$C$49,MATCH($B16,Ishikawa!$L$14:$L$49,0))&"","") | J16: =IF(F16="","",IF(OR(I16="Concluída",I16="Cancelada"),I16,IF(H16="","Sem prazo",IF(H16<TODAY(),"Atrasada","No prazo"))))
B17: 12 | C17: =IFERROR(INDEX(Ishikawa!$B$14:$B$49,MATCH($B17,Ishikawa!$L$14:$L$49,0))&"","") | D17: =IFERROR(INDEX(Ishikawa!$C$14:$C$49,INT((MATCH($B17,Ishikawa!$L$14:$L$49,0)-1)/6)*6+1)&"","") | E17: =IFERROR(INDEX(Ishikawa!$C$14:$C$49,MATCH($B17,Ishikawa!$L$14:$L$49,0))&"","") | J17: =IF(F17="","",IF(OR(I17="Concluída",I17="Cancelada"),I17,IF(H17="","Sem prazo",IF(H17<TODAY(),"Atrasada","No prazo"))))
B19: Resumo automático
B20: Causas que seguem para o plano | G20: =COUNTIF(Ishikawa!J14:J49,"Sim") -> 0
B21: Causas com ação definida | G21: =SUMPRODUCT((E6:E17<>"")*(F6:F17<>"")) -> 0
B22: Ações concluídas | G22: =COUNTIF(I6:I17,"Concluída") -> 0
B23: Ações atrasadas | G23: =COUNTIF(J6:J17,"Atrasada") -> 0
B24: Ações sem responsável ou sem prazo | G24: =SUMPRODUCT((F6:F17<>"")*((G6:G17="")+(H6:H17="")>0)) -> 0
B25: Aviso | G25: =IF(G20=0,"Marque na aba Ishikawa as causas que seguem para o plano",IF(G20>12,"Mais de 12 causas marcadas: priorize",IF(G21<G20,"Há causa sem ação definida","OK"))) -> Marque na aba Ishikawa as causas que seguem para o plano

Sheet Checklist
B1: Checklist de validação do Diagrama de Ishikawa
B2: Escolha o status de cada item na lista suspensa (coluna em amarelo-claro).
B4: # | C4: Item de verificação | D4: Status | E4: Observações
B5: 1 | C5: O efeito está escrito como problema, com número, local e período.
B6: 2 | C6: O efeito não traz causa nem solução embutida.
B7: 3 | C7: Participaram pessoas que conhecem o processo, de funções diferentes.
B8: 4 | C8: As categorias foram escolhidas de acordo com o tipo de processo.
B9: 5 | C9: Todas as categorias foram discutidas, mesmo as que ficaram sem causa.
B10: 6 | C10: Cada causa é um fato que pode ser verificado, e não uma opinião ou a falta de uma solução.
B11: 7 | C11: As causas foram aprofundadas com a pergunta “por quê?”.
B12: 8 | C12: Nenhuma causa aponta uma pessoa como culpada.
B13: 9 | C13: As causas mais prováveis foram escolhidas pelo grupo, com critério combinado.
B14: 10 | C14: As causas escolhidas foram verificadas com dados ou no local.
B15: 11 | C15: As causas descartadas ficaram registradas, com o motivo.
B16: 12 | C16: As causas confirmadas seguiram para o plano de ação.
B18: Resumo automático
B19: Itens atendidos (Sim) | D19: =COUNTIF(D5:D16,"Sim") -> 0
B20: Itens parciais | D20: =COUNTIF(D5:D16,"Parcial") -> 0
B21: Itens não atendidos | D21: =COUNTIF(D5:D16,"Não") -> 0
B22: Itens sem resposta | D22: =COUNTBLANK(D5:D16) -> 12
B23: Percentual atendido | D23: =D19/ROWS(D5:D16) -> 0
B24: Situação | D24: =IF(D19=ROWS(D5:D16),"Validado",IF(D22>0,"Em andamento","Com pendências")) -> Em andamento

Sheet Exemplo 1 - Pizzaria
B1: Ishikawa — Análise de causa e efeito
B2: Exemplo preenchido, para consulta. Use a aba Ishikawa para a sua análise.
B4: Tema da análise | D4: Atrasos nas entregas de delivery | G4: Responsável | H4: Gerente da loja
B5: Área / unidade | D5: Pizzaria (loja) | G5: Data | H5: 46220
B6: Elaborado por | D6: Equipe da loja | G6: Versão | H6: 1.0
B7: Efeito (problema) | D7: 18% das entregas chegam depois de 40 minutos.
B8: Onde e quando ocorre | D8: Sextas e sábados, das 19h às 22h | G8: Participantes | H8: Gerente, líder da expedição, pizzaiolo, atendente e um entregador
B9: Origem da análise | D9: Ciclo PDCA: etapa de análise das causas
B11: # | C11: Causa provável | E11: Por quê? (subcausa) | F11: Probabilidade | G11: Como verificar | H11: Resultado | I11: Evidência | J11: Segue para o plano?
C12: Fato que pode produzir o efeito | E12: Por que essa causa acontece? | F12: Na opinião do grupo | G12: Contagem, comparação, observação, medição ou teste | H12: O que os dados mostraram | I12: Número ou fato que sustenta o resultado | J12: Sim ou Não
B13: Cada causa é uma hipótese até ser verificada. As descartadas ficam registradas, com a evidência. Só as confirmadas podem seguir para o plano de ação. | L13: Apoio
B14: A | C14: Método | F14: Como o trabalho é feito: procedimentos, sequência, regras.
B15: A1 | C15: Pedidos saem um a um, sem agrupamento por bairro | E15: A expedição não separa os pedidos por zona | F15: Alta | G15: Acompanhar 50 saídas no pico e mapear as rotas | H15: Confirmada | I15: Em 31 das 50 saídas, outro entregador saiu para o mesmo bairro menos de 10 minutos depois | J15: Sim | L15: =IF(J15="Sim",COUNTIF($J$14:J15,"Sim"),"") -> 1
B16: A2 | C16: Rota escolhida por cada entregador | E16: Não há roteiro sugerido | F16: Média | G16: Comparar o tempo de rota entre os entregadores | H16: Descartada | I16: Tempos parecidos entre os entregadores | J16: Não | L16: =IF(J16="Sim",COUNTIF($J$14:J16,"Sim"),"")
B17: A3 | L17: =IF(J17="Sim",COUNTIF($J$14:J17,"Sim"),"")
B18: A4 | L18: =IF(J18="Sim",COUNTIF($J$14:J18,"Sim"),"")
B19: A5 | L19: =IF(J19="Sim",COUNTIF($J$14:J19,"Sim"),"")
B20: B | C20: Mão de obra | F20: Quem faz o trabalho: treinamento, quantidade, escala.
B21: B1 | C21: Escala de entregadores igual em todos os dias | E21: A escala foi montada pelo movimento médio da semana | F21: Alta | G21: Comparar os entregadores disponíveis e as entregas por noite | H21: Confirmada | I21: Mesmo número de entregadores todos os dias; nas sextas e nos sábados, 74 entregas por noite, contra 35 nos outros dias | J21: Sim | L21: =IF(J21="Sim",COUNTIF($J$14:J21,"Sim"),"") -> 2
B22: B2 | C22: Expedição sem responsável definido no pico | E22: Quem está livre faz o despacho | F22: Média | G22: Observar a expedição em três noites de pico | H22: Não verificada | J22: Não | L22: =IF(J22="Sim",COUNTIF($J$14:J22,"Sim"),"")
B23: B3 | L23: =IF(J23="Sim",COUNTIF($J$14:J23,"Sim"),"")
B24: B4 | L24: =IF(J24="Sim",COUNTIF($J$14:J24,"Sim"),"")
B25: B5 | L25: =IF(J25="Sim",COUNTIF($J$14:J25,"Sim"),"")
B26: C | C26: Máquina | F26: Com o que se faz: equipamentos, ferramentas, sistemas.
B27: C1 | C27: Forno único, com fila no horário de pico | E27: O forno assa seis pizzas por vez | F27: Alta | G27: Medir o tempo de espera antes do forno | H27: Confirmada | I27: Espera média de 12 minutos antes do forno no pico, contra 3 fora dele. Fica para o próximo ciclo | J27: Não | L27: =IF(J27="Sim",COUNTIF($J$14:J27,"Sim"),"")
B28: C2 | C28: Motos com manutenção atrasada | F28: Baixa | G28: Conferir o registro de quebras do trimestre | H28: Descartada | I28: Nenhuma quebra em horário de pico | J28: Não | L28: =IF(J28="Sim",COUNTIF($J$14:J28,"Sim"),"")
B29: C3 | L29: =IF(J29="Sim",COUNTIF($J$14:J29,"Sim"),"")
B30: C4 | L30: =IF(J30="Sim",COUNTIF($J$14:J30,"Sim"),"")
B31: C5 | L31: =IF(J31="Sim",COUNTIF($J$14:J31,"Sim"),"")
B32: D | C32: Material | F32: O que entra no processo: insumos e informações.
B33: D1 | C33: Pedido chega com endereço sem complemento | E33: O formulário não exige o campo | F33: Alta | G33: Contar os atrasos com endereço incompleto | H33: Confirmada | I33: Endereço incompleto em 15% dos atrasos | J33: Sim | L33: =IF(J33="Sim",COUNTIF($J$14:J33,"Sim"),"") -> 3
B34: D2 | C34: Bolsas térmicas insuficientes | F34: Baixa | G34: Contar bolsas e entregadores no pico | H34: Descartada | I34: Há bolsas para todos os entregadores | J34: Não | L34: =IF(J34="Sim",COUNTIF($J$14:J34,"Sim"),"")
B35: D3 | L35: =IF(J35="Sim",COUNTIF($J$14:J35,"Sim"),"")
B36: D4 | L36: =IF(J36="Sim",COUNTIF($J$14:J36,"Sim"),"")
B37: D5 | L37: =IF(J37="Sim",COUNTIF($J$14:J37,"Sim"),"")
B38: E | C38: Medição | F38: Como se mede: instrumentos, indicadores, critérios.
B39: E1 | C39: Tempo de entrega medido só pela média do dia (causa de não detecção) | E39: O relatório padrão do aplicativo não separa por horário | F39: Média | G39: Refazer o indicador por faixa de horário | H39: Confirmada | I39: No prazo: 91% fora do pico e 68% no pico. A média do dia, de 82%, escondia o pico | J39: Sim | L39: =IF(J39="Sim",COUNTIF($J$14:J39,"Sim"),"") -> 4
B40: E2 | C40: Prazo prometido igual para todos os bairros | F40: Média | G40: Comparar os atrasos por distância | H40: Não verificada | J40: Não | L40: =IF(J40="Sim",COUNTIF($J$14:J40,"Sim"),"")
B41: E3 | L41: =IF(J41="Sim",COUNTIF($J$14:J41,"Sim"),"")
B42: E4 | L42: =IF(J42="Sim",COUNTIF($J$14:J42,"Sim"),"")
...

Sheet Exemplo 2 - Compras
B1: Ishikawa — Análise de causa e efeito
B2: Exemplo preenchido, para consulta. Use a aba Ishikawa para a sua análise.
B4: Tema da análise | D4: Requisições de compra devolvidas | G4: Responsável | H4: Gerente de Suprimentos
B5: Área / unidade | D5: Distribuidora de materiais elétricos · Compras | G5: Data | H5: 46199
B6: Elaborado por | D6: Equipe de compras | G6: Versão | H6: 1.0
B7: Efeito (problema) | D7: 40% das requisições de compra são devolvidas ao requisitante.
B8: Onde e quando ocorre | D8: Todas as áreas requisitantes, no último trimestre | G8: Participantes | H8: Gerente, compradores, dois requisitantes e TI
B9: Origem da análise | D9: Ciclo PDCA e Matriz GUT da área
B11: # | C11: Causa provável | E11: Por quê? (subcausa) | F11: Probabilidade | G11: Como verificar | H11: Resultado | I11: Evidência | J11: Segue para o plano?
C12: Fato que pode produzir o efeito | E12: Por que essa causa acontece? | F12: Na opinião do grupo | G12: Contagem, comparação, observação, medição ou teste | H12: O que os dados mostraram | I12: Número ou fato que sustenta o resultado | J12: Sim ou Não
B13: Cada causa é uma hipótese até ser verificada. As descartadas ficam registradas, com a evidência. Só as confirmadas podem seguir para o plano de ação. | L13: Apoio
B14: A | C14: Procedimentos | F14: Como o trabalho é feito: procedimentos, sequência, regras.
B15: A1 | C15: Formulário de requisição sem campos obrigatórios | E15: O formulário foi criado antes do sistema atual | F15: Alta | G15: Analisar 100 requisições devolvidas | H15: Confirmada | I15: 72 das 100 tinham campo essencial em branco | J15: Sim | L15: =IF(J15="Sim",COUNTIF($J$14:J15,"Sim"),"") -> 1
B16: A2 | C16: Procedimento não define quem confere a especificação | F16: Média | G16: Entrevistar compradores e requisitantes | H16: Não verificada | J16: Não | L16: =IF(J16="Sim",COUNTIF($J$14:J16,"Sim"),"")
B17: A3 | L17: =IF(J17="Sim",COUNTIF($J$14:J17,"Sim"),"")
B18: A4 | L18: =IF(J18="Sim",COUNTIF($J$14:J18,"Sim"),"")
B19: A5 | L19: =IF(J19="Sim",COUNTIF($J$14:J19,"Sim"),"")
B20: B | C20: Pessoas | F20: Quem faz o trabalho: treinamento, quantidade, escala.
B21: B1 | C21: Requisitantes nunca foram treinados no processo de compras | E21: A integração não inclui o processo de compras | F21: Alta | G21: Conferir os registros de treinamento | H21: Confirmada | I21: Nenhum dos 38 requisitantes foi treinado | J21: Sim | L21: =IF(J21="Sim",COUNTIF($J$14:J21,"Sim"),"") -> 2
B22: B2 | C22: Troca frequente de requisitantes nas áreas | F22: Baixa | G22: Levantar as trocas dos últimos 12 meses | H22: Descartada | I22: Só 3 trocas em 12 meses | J22: Não | L22: =IF(J22="Sim",COUNTIF($J$14:J22,"Sim"),"")
B23: B3 | L23: =IF(J23="Sim",COUNTIF($J$14:J23,"Sim"),"")
B24: B4 | L24: =IF(J24="Sim",COUNTIF($J$14:J24,"Sim"),"")
B25: B5 | L25: =IF(J25="Sim",COUNTIF($J$14:J25,"Sim"),"")
B26: C | C26: Sistemas | F26: Com o que se faz: equipamentos, ferramentas, sistemas.
B27: C1 | C27: Sistema aceita a descrição do item em texto livre | E27: Não há catálogo de itens cadastrado | F27: Alta | G27: Comparar as descrições de um mesmo item | H27: Confirmada | I27: Um mesmo rolamento com 9 descrições diferentes | J27: Sim | L27: =IF(J27="Sim",COUNTIF($J$14:J27,"Sim"),"") -> 3
B28: C2 | C28: Sistema lento no fechamento do mês | F28: Baixa | G28: Comparar as devoluções por semana do mês | H28: Descartada | I28: Devoluções iguais ao longo do mês | J28: Não | L28: =IF(J28="Sim",COUNTIF($J$14:J28,"Sim"),"")
B29: C3 | L29: =IF(J29="Sim",COUNTIF($J$14:J29,"Sim"),"")
B30: C4 | L30: =IF(J30="Sim",COUNTIF($J$14:J30,"Sim"),"")
B31: C5 | L31: =IF(J31="Sim",COUNTIF($J$14:J31,"Sim"),"")
B32: D | C32: Informações | F32: O que entra no processo: insumos e informações.
B33: D1 | C33: Desenhos técnicos desatualizados na rede | F33: Média | G33: Conferir uma amostra de 20 desenhos | H33: Não verificada | J33: Não | L33: =IF(J33="Sim",COUNTIF($J$14:J33,"Sim"),"")
B34: D2 | C34: Requisitante não conhece o prazo de cada tipo de compra | E34: Os prazos não estão publicados | F34: Média | G34: Perguntar a 10 requisitantes | H34: Confirmada | I34: 8 em 10 não souberam informar. Tratado em outro plano | J34: Não | L34: =IF(J34="Sim",COUNTIF($J$14:J34,"Sim"),"")
B35: D3 | L35: =IF(J35="Sim",COUNTIF($J$14:J35,"Sim"),"")
B36: D4 | L36: =IF(J36="Sim",COUNTIF($J$14:J36,"Sim"),"")
B37: D5 | L37: =IF(J37="Sim",COUNTIF($J$14:J37,"Sim"),"")
B38: E | C38: Indicadores | F38: Como se mede: instrumentos, indicadores, critérios.
B39: E1 | C39: Devoluções não são medidas por área requisitante | E39: O relatório mostra só o total do mês | F39: Média | G39: Verificar os relatórios disponíveis | H39: Confirmada | I39: Só existe o total mensal | J39: Sim | L39: =IF(J39="Sim",COUNTIF($J$14:J39,"Sim"),"") -> 4
B40: E2 | L40: =IF(J40="Sim",COUNTIF($J$14:J40,"Sim"),"")
B41: E3 | L41: =IF(J41="Sim",COUNTIF($J$14:J41,"Sim"),"")
B42: E4 | L42: =IF(J42="Sim",COUNTIF($J$14:J42,"Sim"),"")
...
