Workbook

Sheet Instruções
B1: Técnica de auditoria — Como usar esta planilha
B2: Modelo para dimensionar as amostras, pesar as evidências e avaliar os auditores em campo.
B4: Legenda: onde preencher
B5: Amarelo-claro | C5: Células de entrada. É aqui que você digita.
B6: Cinza | C6: Células calculadas ou fixas (amostra, passo, conclusão, fontes, força, nível, conferências). Não altere.
B7: Cinza em itálico | C7: Linha de exemplo (marcada com “Ex.”). Mostra o formato esperado e não entra nas contagens.
B8: Listas suspensas | C8: Risco, constatação e checklist aceitam apenas as opções da lista. As notas aceitam de 0 a 3.
B9: Comentários | C9: Células com triângulo vermelho no canto trazem uma dica de preenchimento. Passe o mouse sobre elas.
B11: O tamanho da amostra
B12: População até 5 | C12: Todos os casos.
B13: População de 6 a 20 | C13: Amostra-base de 5. Risco alto: 8. Médio: 5. Baixo: 3.
B14: População de 21 a 50 | C14: Amostra-base de 8. Risco alto: 12. Médio: 8. Baixo: 5.
B15: População de 51 a 100 | C15: Amostra-base de 10. Risco alto: 15. Médio: 10. Baixo: 6.
B16: População de 101 a 500 | C16: Amostra-base de 15. Risco alto: 23. Médio: 15. Baixo: 9.
B17: População acima de 500 | C17: Amostra-base de 20. Risco alto: 30. Médio: 20. Baixo: 12.
B18: Regra | C18: A amostra-base vezes o fator de risco (alto 1,5, médio 1.0, baixo 0,6), arredondada para cima, com mínimo de 3 e máximo igual à população.
B19: Passo e início | C19: O passo é a população dividida pela amostra. O auditor sorteia o início entre 1 e o passo e verifica um caso a cada passo.
B21: As outras regras de cálculo
B22: Conforme na amostra | C22: Amostra completa, sem desvio.
B23: Desvio pontual: não conformidade, ampliar a amostra | C23: Amostra completa, com um desvio. Já é não conformidade; amplie a amostra para saber se é pontual ou repetido.
B24: Desvio repetido: não conformidade | C24: Amostra completa, com dois desvios ou mais.
B25: Amostra incompleta | C25: Menos verificados do que a amostra calculada.
B26: Força da evidência | C26: Forte: duas fontes ou mais. Média: só observação ou só registro. Fraca: só entrevista. Não conformidade pede ao menos uma fonte objetiva (força média ou forte); a que só tem entrevista pede corroboração.
B27: Nível do auditor | C27: Com pelo menos 8 critérios observados: 80% ou mais, apto a liderar; de 60% a 79%, apto a auditar em equipe; abaixo, em formação. Um critério crítico com nota 0 ou 1 leva a em formação.
B28: Notas | C28: 0: não fez. 1: fez em parte. 2: fez bem. 3: referência para os outros. Em branco: não observado.
B30: Ordem recomendada de preenchimento
B31: Passo 1 | C31: Aba Amostras: os dados da auditoria e, para cada registro a verificar, a população e o risco. Sorteie o início entre 1 e o passo.
B32: Passo 2 | C32: Aba Amostras, durante a auditoria: quantos foram verificados e quantos desvios.
B33: Passo 3 | C33: Aba Evidências: cada pergunta, o requisito, as fontes e a constatação.
B34: Passo 4 | C34: Aba Auditores, se houver observador: o nome, o papel e as notas de cada auditor.
B35: Passo 5 | C35: Aba Painel: leia os avisos. Depois, valide na aba Checklist.
B37: Abas da planilha
B38: Amostras | C38: Os dados da auditoria e até 30 amostras. Calcula o tamanho, o passo, a conclusão e a conferência.
B39: Evidências | C39: Até 60 perguntas. Calcula as fontes, a força e a conferência.
B40: Auditores | C40: Até 4 auditores, com notas nos 12 critérios. Calcula os pontos, o percentual, o nível e a conferência.
B41: Painel | C41: Os números das três abas, o gráfico das amostras e o aviso.
B42: Checklist | C42: Doze verificações da técnica de auditoria, com percentual de conclusão.
B43: Exemplo 1 - Pizzaria | C43: A auditoria do salão e do recebimento, em 18/03/2027.
B44: Exemplo 2 - Indústria | C44: A auditoria da produção, em 06/10/2027.
B46: Premissas do modelo
...

Sheet Amostras
B1: Amostras da auditoria
B2: Uma amostra por linha: o que se verifica, de que população, com que risco. O tamanho e o passo saem da tabela.
B4: Auditoria nº
B5: Processo auditado
B6: Data
B7: Auditor líder
B9: # | C9: O que se verifica | D9: Requisito | E9: Período | F9: População | G9: Risco | H9: Início | I9: Amostra | J9: Passo | K9: Verificados | L9: Desvios | M9: Observação | N9: Conclusão | O9: Conferência
C10: Registro e o que conferir | D10: Ex.: 8.4 | F10: Quantos existem | G10: Lista | H10: Sorteado | I10: Calculada | J10: Calculado | K10: Número | L10: Número | M10: O que se viu | N10: Calculada | O10: Calculada
B11: Ex. | C11: Notas de recebimento com a temperatura | D11: 8.4 | E11: Fevereiro | F11: 48 | G11: Alto | H11: 3 | I11: 12 | J11: 4 | K11: 12 | L11: 0 | N11: Conforme na amostra | O11: OK
B12: 1 | I12: =IF(OR(N(F12)=0,G12=""),"",IF(F12<=5,F12,IFERROR(MIN(F12,MAX(3,ROUNDUP(IF(F12<=20,5,IF(F12<=50,8,IF(F12<=100,10,IF(F12<=500,15,20))))*IF(G12="Alto",1.5,IF(G12="Médio",1,IF(G12="Baixo",0.6,"")))-0.000000001,0))),""))) | J12: =IF(I12="","",INT(F12/I12)) | N12: =IF(OR(I12="",K12="",L12=""),"",IF(K12<I12,"Amostra incompleta",IF(L12=0,"Conforme na amostra",IF(L12=1,"Desvio pontual: não conformidade, ampliar a amostra","Desvio repetido: não conformidade")))) | O12: =IF(C12="","",IF(N(F12)=0,"Falta a população",IF(G12="","Falta o risco",IF(OR(H12="",H12<1,H12>J12),"Início deve ir de 1 a "&J12,IF(K12="","Falta quantos foram verificados",IF(K12>F12,"Verificados acima da população",IF(L12="","Falta quantos desvios",IF(L12>K12,"Mais desvios que verificados","OK"))))))))
B13: 2 | I13: =IF(OR(N(F13)=0,G13=""),"",IF(F13<=5,F13,IFERROR(MIN(F13,MAX(3,ROUNDUP(IF(F13<=20,5,IF(F13<=50,8,IF(F13<=100,10,IF(F13<=500,15,20))))*IF(G13="Alto",1.5,IF(G13="Médio",1,IF(G13="Baixo",0.6,"")))-0.000000001,0))),""))) | J13: =IF(I13="","",INT(F13/I13)) | N13: =IF(OR(I13="",K13="",L13=""),"",IF(K13<I13,"Amostra incompleta",IF(L13=0,"Conforme na amostra",IF(L13=1,"Desvio pontual: não conformidade, ampliar a amostra","Desvio repetido: não conformidade")))) | O13: =IF(C13="","",IF(N(F13)=0,"Falta a população",IF(G13="","Falta o risco",IF(OR(H13="",H13<1,H13>J13),"Início deve ir de 1 a "&J13,IF(K13="","Falta quantos foram verificados",IF(K13>F13,"Verificados acima da população",IF(L13="","Falta quantos desvios",IF(L13>K13,"Mais desvios que verificados","OK"))))))))
B14: 3 | I14: =IF(OR(N(F14)=0,G14=""),"",IF(F14<=5,F14,IFERROR(MIN(F14,MAX(3,ROUNDUP(IF(F14<=20,5,IF(F14<=50,8,IF(F14<=100,10,IF(F14<=500,15,20))))*IF(G14="Alto",1.5,IF(G14="Médio",1,IF(G14="Baixo",0.6,"")))-0.000000001,0))),""))) | J14: =IF(I14="","",INT(F14/I14)) | N14: =IF(OR(I14="",K14="",L14=""),"",IF(K14<I14,"Amostra incompleta",IF(L14=0,"Conforme na amostra",IF(L14=1,"Desvio pontual: não conformidade, ampliar a amostra","Desvio repetido: não conformidade")))) | O14: =IF(C14="","",IF(N(F14)=0,"Falta a população",IF(G14="","Falta o risco",IF(OR(H14="",H14<1,H14>J14),"Início deve ir de 1 a "&J14,IF(K14="","Falta quantos foram verificados",IF(K14>F14,"Verificados acima da população",IF(L14="","Falta quantos desvios",IF(L14>K14,"Mais desvios que verificados","OK"))))))))
B15: 4 | I15: =IF(OR(N(F15)=0,G15=""),"",IF(F15<=5,F15,IFERROR(MIN(F15,MAX(3,ROUNDUP(IF(F15<=20,5,IF(F15<=50,8,IF(F15<=100,10,IF(F15<=500,15,20))))*IF(G15="Alto",1.5,IF(G15="Médio",1,IF(G15="Baixo",0.6,"")))-0.000000001,0))),""))) | J15: =IF(I15="","",INT(F15/I15)) | N15: =IF(OR(I15="",K15="",L15=""),"",IF(K15<I15,"Amostra incompleta",IF(L15=0,"Conforme na amostra",IF(L15=1,"Desvio pontual: não conformidade, ampliar a amostra","Desvio repetido: não conformidade")))) | O15: =IF(C15="","",IF(N(F15)=0,"Falta a população",IF(G15="","Falta o risco",IF(OR(H15="",H15<1,H15>J15),"Início deve ir de 1 a "&J15,IF(K15="","Falta quantos foram verificados",IF(K15>F15,"Verificados acima da população",IF(L15="","Falta quantos desvios",IF(L15>K15,"Mais desvios que verificados","OK"))))))))
B16: 5 | I16: =IF(OR(N(F16)=0,G16=""),"",IF(F16<=5,F16,IFERROR(MIN(F16,MAX(3,ROUNDUP(IF(F16<=20,5,IF(F16<=50,8,IF(F16<=100,10,IF(F16<=500,15,20))))*IF(G16="Alto",1.5,IF(G16="Médio",1,IF(G16="Baixo",0.6,"")))-0.000000001,0))),""))) | J16: =IF(I16="","",INT(F16/I16)) | N16: =IF(OR(I16="",K16="",L16=""),"",IF(K16<I16,"Amostra incompleta",IF(L16=0,"Conforme na amostra",IF(L16=1,"Desvio pontual: não conformidade, ampliar a amostra","Desvio repetido: não conformidade")))) | O16: =IF(C16="","",IF(N(F16)=0,"Falta a população",IF(G16="","Falta o risco",IF(OR(H16="",H16<1,H16>J16),"Início deve ir de 1 a "&J16,IF(K16="","Falta quantos foram verificados",IF(K16>F16,"Verificados acima da população",IF(L16="","Falta quantos desvios",IF(L16>K16,"Mais desvios que verificados","OK"))))))))
B17: 6 | I17: =IF(OR(N(F17)=0,G17=""),"",IF(F17<=5,F17,IFERROR(MIN(F17,MAX(3,ROUNDUP(IF(F17<=20,5,IF(F17<=50,8,IF(F17<=100,10,IF(F17<=500,15,20))))*IF(G17="Alto",1.5,IF(G17="Médio",1,IF(G17="Baixo",0.6,"")))-0.000000001,0))),""))) | J17: =IF(I17="","",INT(F17/I17)) | N17: =IF(OR(I17="",K17="",L17=""),"",IF(K17<I17,"Amostra incompleta",IF(L17=0,"Conforme na amostra",IF(L17=1,"Desvio pontual: não conformidade, ampliar a amostra","Desvio repetido: não conformidade")))) | O17: =IF(C17="","",IF(N(F17)=0,"Falta a população",IF(G17="","Falta o risco",IF(OR(H17="",H17<1,H17>J17),"Início deve ir de 1 a "&J17,IF(K17="","Falta quantos foram verificados",IF(K17>F17,"Verificados acima da população",IF(L17="","Falta quantos desvios",IF(L17>K17,"Mais desvios que verificados","OK"))))))))
B18: 7 | I18: =IF(OR(N(F18)=0,G18=""),"",IF(F18<=5,F18,IFERROR(MIN(F18,MAX(3,ROUNDUP(IF(F18<=20,5,IF(F18<=50,8,IF(F18<=100,10,IF(F18<=500,15,20))))*IF(G18="Alto",1.5,IF(G18="Médio",1,IF(G18="Baixo",0.6,"")))-0.000000001,0))),""))) | J18: =IF(I18="","",INT(F18/I18)) | N18: =IF(OR(I18="",K18="",L18=""),"",IF(K18<I18,"Amostra incompleta",IF(L18=0,"Conforme na amostra",IF(L18=1,"Desvio pontual: não conformidade, ampliar a amostra","Desvio repetido: não conformidade")))) | O18: =IF(C18="","",IF(N(F18)=0,"Falta a população",IF(G18="","Falta o risco",IF(OR(H18="",H18<1,H18>J18),"Início deve ir de 1 a "&J18,IF(K18="","Falta quantos foram verificados",IF(K18>F18,"Verificados acima da população",IF(L18="","Falta quantos desvios",IF(L18>K18,"Mais desvios que verificados","OK"))))))))
B19: 8 | I19: =IF(OR(N(F19)=0,G19=""),"",IF(F19<=5,F19,IFERROR(MIN(F19,MAX(3,ROUNDUP(IF(F19<=20,5,IF(F19<=50,8,IF(F19<=100,10,IF(F19<=500,15,20))))*IF(G19="Alto",1.5,IF(G19="Médio",1,IF(G19="Baixo",0.6,"")))-0.000000001,0))),""))) | J19: =IF(I19="","",INT(F19/I19)) | N19: =IF(OR(I19="",K19="",L19=""),"",IF(K19<I19,"Amostra incompleta",IF(L19=0,"Conforme na amostra",IF(L19=1,"Desvio pontual: não conformidade, ampliar a amostra","Desvio repetido: não conformidade")))) | O19: =IF(C19="","",IF(N(F19)=0,"Falta a população",IF(G19="","Falta o risco",IF(OR(H19="",H19<1,H19>J19),"Início deve ir de 1 a "&J19,IF(K19="","Falta quantos foram verificados",IF(K19>F19,"Verificados acima da população",IF(L19="","Falta quantos desvios",IF(L19>K19,"Mais desvios que verificados","OK"))))))))
B20: 9 | I20: =IF(OR(N(F20)=0,G20=""),"",IF(F20<=5,F20,IFERROR(MIN(F20,MAX(3,ROUNDUP(IF(F20<=20,5,IF(F20<=50,8,IF(F20<=100,10,IF(F20<=500,15,20))))*IF(G20="Alto",1.5,IF(G20="Médio",1,IF(G20="Baixo",0.6,"")))-0.000000001,0))),""))) | J20: =IF(I20="","",INT(F20/I20)) | N20: =IF(OR(I20="",K20="",L20=""),"",IF(K20<I20,"Amostra incompleta",IF(L20=0,"Conforme na amostra",IF(L20=1,"Desvio pontual: não conformidade, ampliar a amostra","Desvio repetido: não conformidade")))) | O20: =IF(C20="","",IF(N(F20)=0,"Falta a população",IF(G20="","Falta o risco",IF(OR(H20="",H20<1,H20>J20),"Início deve ir de 1 a "&J20,IF(K20="","Falta quantos foram verificados",IF(K20>F20,"Verificados acima da população",IF(L20="","Falta quantos desvios",IF(L20>K20,"Mais desvios que verificados","OK"))))))))
B21: 10 | I21: =IF(OR(N(F21)=0,G21=""),"",IF(F21<=5,F21,IFERROR(MIN(F21,MAX(3,ROUNDUP(IF(F21<=20,5,IF(F21<=50,8,IF(F21<=100,10,IF(F21<=500,15,20))))*IF(G21="Alto",1.5,IF(G21="Médio",1,IF(G21="Baixo",0.6,"")))-0.000000001,0))),""))) | J21: =IF(I21="","",INT(F21/I21)) | N21: =IF(OR(I21="",K21="",L21=""),"",IF(K21<I21,"Amostra incompleta",IF(L21=0,"Conforme na amostra",IF(L21=1,"Desvio pontual: não conformidade, ampliar a amostra","Desvio repetido: não conformidade")))) | O21: =IF(C21="","",IF(N(F21)=0,"Falta a população",IF(G21="","Falta o risco",IF(OR(H21="",H21<1,H21>J21),"Início deve ir de 1 a "&J21,IF(K21="","Falta quantos foram verificados",IF(K21>F21,"Verificados acima da população",IF(L21="","Falta quantos desvios",IF(L21>K21,"Mais desvios que verificados","OK"))))))))
B22: 11 | I22: =IF(OR(N(F22)=0,G22=""),"",IF(F22<=5,F22,IFERROR(MIN(F22,MAX(3,ROUNDUP(IF(F22<=20,5,IF(F22<=50,8,IF(F22<=100,10,IF(F22<=500,15,20))))*IF(G22="Alto",1.5,IF(G22="Médio",1,IF(G22="Baixo",0.6,"")))-0.000000001,0))),""))) | J22: =IF(I22="","",INT(F22/I22)) | N22: =IF(OR(I22="",K22="",L22=""),"",IF(K22<I22,"Amostra incompleta",IF(L22=0,"Conforme na amostra",IF(L22=1,"Desvio pontual: não conformidade, ampliar a amostra","Desvio repetido: não conformidade")))) | O22: =IF(C22="","",IF(N(F22)=0,"Falta a população",IF(G22="","Falta o risco",IF(OR(H22="",H22<1,H22>J22),"Início deve ir de 1 a "&J22,IF(K22="","Falta quantos foram verificados",IF(K22>F22,"Verificados acima da população",IF(L22="","Falta quantos desvios",IF(L22>K22,"Mais desvios que verificados","OK"))))))))
B23: 12 | I23: =IF(OR(N(F23)=0,G23=""),"",IF(F23<=5,F23,IFERROR(MIN(F23,MAX(3,ROUNDUP(IF(F23<=20,5,IF(F23<=50,8,IF(F23<=100,10,IF(F23<=500,15,20))))*IF(G23="Alto",1.5,IF(G23="Médio",1,IF(G23="Baixo",0.6,"")))-0.000000001,0))),""))) | J23: =IF(I23="","",INT(F23/I23)) | N23: =IF(OR(I23="",K23="",L23=""),"",IF(K23<I23,"Amostra incompleta",IF(L23=0,"Conforme na amostra",IF(L23=1,"Desvio pontual: não conformidade, ampliar a amostra","Desvio repetido: não conformidade")))) | O23: =IF(C23="","",IF(N(F23)=0,"Falta a população",IF(G23="","Falta o risco",IF(OR(H23="",H23<1,H23>J23),"Início deve ir de 1 a "&J23,IF(K23="","Falta quantos foram verificados",IF(K23>F23,"Verificados acima da população",IF(L23="","Falta quantos desvios",IF(L23>K23,"Mais desvios que verificados","OK"))))))))
... B41: 30 | I41: =IF(OR(N(F41)=0,G41=""),"",IF(F41<=5,F41,IFERROR(MIN(F41,MAX(3,ROUNDUP(IF(F41<=20,5,IF(F41<=50,8,IF(F41<=100,10,IF(F41<=500,15,20))))*IF(G41="Alto",1.5,IF(G41="Médio",1,IF(G41="Baixo",0.6,"")))-0.000000001,0))),""))) | J41: =IF(I41="","",INT(F41/I41)) | N41: =IF(OR(I41="",K41="",L41=""),"",IF(K41<I41,"Amostra incompleta",IF(L41=0,"Conforme na amostra",IF(L41=1,"Desvio pontual: não conformidade, ampliar a amostra","Desvio repetido: não conformidade")))) | O41: =IF(C41="","",IF(N(F41)=0,"Falta a população",IF(G41="","Falta o risco",IF(OR(H41="",H41<1,H41>J41),"Início deve ir de 1 a "&J41,IF(K41="","Falta quantos foram verificados",IF(K41>F41,"Verificados acima da população",IF(L41="","Falta quantos desvios",IF(L41>K41,"Mais desvios que verificados","OK"))))))))
B43: Resumo automático
B44: Amostras | E44: =COUNTA(C12:C41)&" amostras, "&SUM(K12:K41)&" registros verificados, "&SUM(L12:L41)&" desvios" -> 0 amostras, 0 registros verificados, 0 desvios
B45: Conclusões | E45: =COUNTIF(N12:N41,"Conforme na amostra")&" conforme na amostra"&", "&COUNTIF(N12:N41,"Desvio pontual: não conformidade, ampliar a amostra")&" desvio pontual: não conformidade, ampliar a amostra"&", "&COUNTIF(N12:N41,"Desvio repetido: não conformidade")&" desvio repetido: não conformidade"&", "&COUNTIF(N12:N41,"Amostra incompleta")&" amostra incompleta" -> 0 conforme na amostra, 0 desvio pontual: não conformidade, ampliar a amostra, 0 desvio repetido: não conformidade, 0 amostra incompleta
B46: Aviso | E46: =IF(COUNTA(C12:C41)=0,"Liste as amostras da auditoria",IF(COUNTIF(N12:N41,"Desvio pontual: não conformidade, ampliar a amostra")>0,"Há desvio pontual: amplie a amostra para medir a extensão",IF(COUNTIF(N12:N41,"Amostra incompleta")>0,"Há amostra incompleta: complete ou registre por quê",IF(SUMPRODUCT((O12:O41<>"")*(O12:O41<>"OK"))>0,"Há amostra a completar: veja a coluna Conferência","OK")))) -> Liste as amostras da auditoria

Sheet Evidências
B1: Evidências
B2: Uma pergunta por linha, com as três fontes possíveis e a constatação. A força sai do número e do tipo de fontes.
B4: # | C4: Pergunta | D4: Requisito | E4: Entrevista | F4: Observação | G4: Registro | H4: Constatação | I4: Fontes | J4: Força | K4: Conferência
C5: Aberta | D5: Ex.: 7.1.5 | E5: Quem disse o quê | F5: O que o auditor viu | G5: Qual registro, com a amostra | H5: Lista | I5: Calculado | J5: Calculada | K5: Calculada
B6: Ex. | C6: Como o recebimento confere a temperatura? | D6: 8.4 | E6: Atendente que recebe | F6: Recebimento das 15h: temperatura anotada | G6: 12 notas de fevereiro com a temperatura | H6: Conforme | I6: 3 | J6: Forte | K6: OK
B7: 1 | I7: =IF(AND(C7="",D7=""),"",COUNTA(E7:G7)) | J7: =IF(N(I7)=0,"",IF(I7>=2,"Forte",IF(OR(F7<>"",G7<>""),"Média","Fraca"))) | K7: =IF(AND(C7="",D7="",COUNTA(E7:H7)=0),"",IF(D7="","Falta o requisito",IF(C7="","Falta a pergunta",IF(N(I7)=0,"Falta a evidência",IF(H7="","Falta a constatação",IF(AND(H7="Não conformidade",J7="Fraca"),"Não conformidade sem evidência objetiva","OK"))))))
B8: 2 | I8: =IF(AND(C8="",D8=""),"",COUNTA(E8:G8)) | J8: =IF(N(I8)=0,"",IF(I8>=2,"Forte",IF(OR(F8<>"",G8<>""),"Média","Fraca"))) | K8: =IF(AND(C8="",D8="",COUNTA(E8:H8)=0),"",IF(D8="","Falta o requisito",IF(C8="","Falta a pergunta",IF(N(I8)=0,"Falta a evidência",IF(H8="","Falta a constatação",IF(AND(H8="Não conformidade",J8="Fraca"),"Não conformidade sem evidência objetiva","OK"))))))
B9: 3 | I9: =IF(AND(C9="",D9=""),"",COUNTA(E9:G9)) | J9: =IF(N(I9)=0,"",IF(I9>=2,"Forte",IF(OR(F9<>"",G9<>""),"Média","Fraca"))) | K9: =IF(AND(C9="",D9="",COUNTA(E9:H9)=0),"",IF(D9="","Falta o requisito",IF(C9="","Falta a pergunta",IF(N(I9)=0,"Falta a evidência",IF(H9="","Falta a constatação",IF(AND(H9="Não conformidade",J9="Fraca"),"Não conformidade sem evidência objetiva","OK"))))))
B10: 4 | I10: =IF(AND(C10="",D10=""),"",COUNTA(E10:G10)) | J10: =IF(N(I10)=0,"",IF(I10>=2,"Forte",IF(OR(F10<>"",G10<>""),"Média","Fraca"))) | K10: =IF(AND(C10="",D10="",COUNTA(E10:H10)=0),"",IF(D10="","Falta o requisito",IF(C10="","Falta a pergunta",IF(N(I10)=0,"Falta a evidência",IF(H10="","Falta a constatação",IF(AND(H10="Não conformidade",J10="Fraca"),"Não conformidade sem evidência objetiva","OK"))))))
B11: 5 | I11: =IF(AND(C11="",D11=""),"",COUNTA(E11:G11)) | J11: =IF(N(I11)=0,"",IF(I11>=2,"Forte",IF(OR(F11<>"",G11<>""),"Média","Fraca"))) | K11: =IF(AND(C11="",D11="",COUNTA(E11:H11)=0),"",IF(D11="","Falta o requisito",IF(C11="","Falta a pergunta",IF(N(I11)=0,"Falta a evidência",IF(H11="","Falta a constatação",IF(AND(H11="Não conformidade",J11="Fraca"),"Não conformidade sem evidência objetiva","OK"))))))
B12: 6 | I12: =IF(AND(C12="",D12=""),"",COUNTA(E12:G12)) | J12: =IF(N(I12)=0,"",IF(I12>=2,"Forte",IF(OR(F12<>"",G12<>""),"Média","Fraca"))) | K12: =IF(AND(C12="",D12="",COUNTA(E12:H12)=0),"",IF(D12="","Falta o requisito",IF(C12="","Falta a pergunta",IF(N(I12)=0,"Falta a evidência",IF(H12="","Falta a constatação",IF(AND(H12="Não conformidade",J12="Fraca"),"Não conformidade sem evidência objetiva","OK"))))))
B13: 7 | I13: =IF(AND(C13="",D13=""),"",COUNTA(E13:G13)) | J13: =IF(N(I13)=0,"",IF(I13>=2,"Forte",IF(OR(F13<>"",G13<>""),"Média","Fraca"))) | K13: =IF(AND(C13="",D13="",COUNTA(E13:H13)=0),"",IF(D13="","Falta o requisito",IF(C13="","Falta a pergunta",IF(N(I13)=0,"Falta a evidência",IF(H13="","Falta a constatação",IF(AND(H13="Não conformidade",J13="Fraca"),"Não conformidade sem evidência objetiva","OK"))))))
B14: 8 | I14: =IF(AND(C14="",D14=""),"",COUNTA(E14:G14)) | J14: =IF(N(I14)=0,"",IF(I14>=2,"Forte",IF(OR(F14<>"",G14<>""),"Média","Fraca"))) | K14: =IF(AND(C14="",D14="",COUNTA(E14:H14)=0),"",IF(D14="","Falta o requisito",IF(C14="","Falta a pergunta",IF(N(I14)=0,"Falta a evidência",IF(H14="","Falta a constatação",IF(AND(H14="Não conformidade",J14="Fraca"),"Não conformidade sem evidência objetiva","OK"))))))
B15: 9 | I15: =IF(AND(C15="",D15=""),"",COUNTA(E15:G15)) | J15: =IF(N(I15)=0,"",IF(I15>=2,"Forte",IF(OR(F15<>"",G15<>""),"Média","Fraca"))) | K15: =IF(AND(C15="",D15="",COUNTA(E15:H15)=0),"",IF(D15="","Falta o requisito",IF(C15="","Falta a pergunta",IF(N(I15)=0,"Falta a evidência",IF(H15="","Falta a constatação",IF(AND(H15="Não conformidade",J15="Fraca"),"Não conformidade sem evidência objetiva","OK"))))))
B16: 10 | I16: =IF(AND(C16="",D16=""),"",COUNTA(E16:G16)) | J16: =IF(N(I16)=0,"",IF(I16>=2,"Forte",IF(OR(F16<>"",G16<>""),"Média","Fraca"))) | K16: =IF(AND(C16="",D16="",COUNTA(E16:H16)=0),"",IF(D16="","Falta o requisito",IF(C16="","Falta a pergunta",IF(N(I16)=0,"Falta a evidência",IF(H16="","Falta a constatação",IF(AND(H16="Não conformidade",J16="Fraca"),"Não conformidade sem evidência objetiva","OK"))))))
B17: 11 | I17: =IF(AND(C17="",D17=""),"",COUNTA(E17:G17)) | J17: =IF(N(I17)=0,"",IF(I17>=2,"Forte",IF(OR(F17<>"",G17<>""),"Média","Fraca"))) | K17: =IF(AND(C17="",D17="",COUNTA(E17:H17)=0),"",IF(D17="","Falta o requisito",IF(C17="","Falta a pergunta",IF(N(I17)=0,"Falta a evidência",IF(H17="","Falta a constatação",IF(AND(H17="Não conformidade",J17="Fraca"),"Não conformidade sem evidência objetiva","OK"))))))
B18: 12 | I18: =IF(AND(C18="",D18=""),"",COUNTA(E18:G18)) | J18: =IF(N(I18)=0,"",IF(I18>=2,"Forte",IF(OR(F18<>"",G18<>""),"Média","Fraca"))) | K18: =IF(AND(C18="",D18="",COUNTA(E18:H18)=0),"",IF(D18="","Falta o requisito",IF(C18="","Falta a pergunta",IF(N(I18)=0,"Falta a evidência",IF(H18="","Falta a constatação",IF(AND(H18="Não conformidade",J18="Fraca"),"Não conformidade sem evidência objetiva","OK"))))))
... B66: 60 | I66: =IF(AND(C66="",D66=""),"",COUNTA(E66:G66)) | J66: =IF(N(I66)=0,"",IF(I66>=2,"Forte",IF(OR(F66<>"",G66<>""),"Média","Fraca"))) | K66: =IF(AND(C66="",D66="",COUNTA(E66:H66)=0),"",IF(D66="","Falta o requisito",IF(C66="","Falta a pergunta",IF(N(I66)=0,"Falta a evidência",IF(H66="","Falta a constatação",IF(AND(H66="Não conformidade",J66="Fraca"),"Não conformidade sem evidência objetiva","OK"))))))
B68: Resumo automático
B69: Perguntas | E69: =COUNTA(C7:C66)&" perguntas: "&COUNTIF(H7:H66,"Conforme")&" conforme"&", "&COUNTIF(H7:H66,"Não conformidade")&" não conformidade"&", "&COUNTIF(H7:H66,"Oportunidade de melhoria")&" oportunidade de melhoria" -> 0 perguntas: 0 conforme, 0 não conformidade, 0 oportunidade de melhoria
B70: Força | E70: =COUNTIF(J7:J66,"Forte")&" forte"&", "&COUNTIF(J7:J66,"Média")&" média"&", "&COUNTIF(J7:J66,"Fraca")&" fraca" -> 0 forte, 0 média, 0 fraca
B71: Aviso | E71: =IF(COUNTA(C7:C66)=0,"Registre as perguntas e as evidências",IF(COUNTIF(K7:K66,"Não conformidade sem evidência objetiva")>0,"Há não conformidade sem evidência objetiva: busque registro ou observação",IF(SUMPRODUCT((K7:K66<>"")*(K7:K66<>"OK"))>0,"Há pergunta a completar: veja a coluna Conferência","OK"))) -> Registre as perguntas e as evidências

Sheet Auditores
B1: Avaliação dos auditores em campo
B2: Uma coluna por auditor observado. Notas de 0 a 3; em branco, não observado.
B5: Auditor
B6: Papel na auditoria
B7: # | C7: Critério | D7: Etapa | E7: Crítico | F7: Auditor 1 | G7: Auditor 2 | H7: Auditor 3 | I7: Auditor 4
B8: 1 | C8: Leu os documentos e o relatório da auditoria anterior antes de ir a campo. | D8: Preparação | E8: —
B9: 2 | C9: Preparou a lista de verificação e o tamanho das amostras com antecedência. | D9: Preparação | E9: —
B10: 3 | C10: Confirmou o objetivo, o escopo, os critérios e o plano na reunião de abertura. | D10: Abertura | E10: —
B11: 4 | C11: Fez perguntas abertas e pediu para ver: “mostre-me”. | D11: Entrevista | E11: —
B12: 5 | C12: Ouviu sem interromper e sem sugerir a resposta. | D12: Entrevista | E12: —
B13: 6 | C13: Escolheu a amostra, em vez de aceitar a oferecida pelo auditado. | D13: Amostra | E13: Sim
B14: 7 | C14: Anotou o tamanho de cada amostra e o que encontrou nela. | D14: Amostra | E14: —
B15: 8 | C15: Corroborou o que ouviu com observação ou registro. | D15: Evidência | E15: Sim
B16: 9 | C16: Seguiu ao menos uma trilha até o fim, de um registro ao seguinte. | D16: Evidência | E16: —
B17: 10 | C17: Escreveu cada não conformidade com requisito, evidência e desvio. | D17: Constatação | E17: Sim
B18: 11 | C18: Não apontou culpados nem ditou a solução. | D18: Constatação | E18: —
B19: 12 | C19: Comunicou as constatações durante a auditoria, sem surpresa no encerramento. | D19: Encerramento | E19: —
B21: Critérios observados | F21: =IF(F$5="","",COUNT(F8:F19)) | G21: =IF(G$5="","",COUNT(G8:G19)) | H21: =IF(H$5="","",COUNT(H8:H19)) | I21: =IF(I$5="","",COUNT(I8:I19))
B22: Pontos | F22: =IF(F$5="","",SUM(F8:F19)) | G22: =IF(G$5="","",SUM(G8:G19)) | H22: =IF(H$5="","",SUM(H8:H19)) | I22: =IF(I$5="","",SUM(I8:I19))
B23: Percentual | F23: =IF(OR(F$5="",N(F21)=0),"",F22/(3*F21)) | G23: =IF(OR(G$5="",N(G21)=0),"",G22/(3*G21)) | H23: =IF(OR(H$5="",N(H21)=0),"",H22/(3*H21)) | I23: =IF(OR(I$5="",N(I21)=0),"",I22/(3*I21))
B24: Nível | F24: =IF(F$5="","",IF(F21=0,"",IF(F21<8,"Observação insuficiente",IF(SUMPRODUCT(($E$8:$E$19="Sim")*(F8:F19<>"")*(F8:F19<=1))>0,"Em formação",IF(F23>=0.8-0.000000001,"Apto a liderar",IF(F23>=0.6-0.000000001,"Apto a auditar em equipe","Em formação")))))) | G24: =IF(G$5="","",IF(G21=0,"",IF(G21<8,"Observação insuficiente",IF(SUMPRODUCT(($E$8:$E$19="Sim")*(G8:G19<>"")*(G8:G19<=1))>0,"Em formação",IF(G23>=0.8-0.000000001,"Apto a liderar",IF(G23>=0.6-0.000000001,"Apto a auditar em equipe","Em formação")))))) | H24: =IF(H$5="","",IF(H21=0,"",IF(H21<8,"Observação insuficiente",IF(SUMPRODUCT(($E$8:$E$19="Sim")*(H8:H19<>"")*(H8:H19<=1))>0,"Em formação",IF(H23>=0.8-0.000000001,"Apto a liderar",IF(H23>=0.6-0.000000001,"Apto a auditar em equipe","Em formação")))))) | I24: =IF(I$5="","",IF(I21=0,"",IF(I21<8,"Observação insuficiente",IF(SUMPRODUCT(($E$8:$E$19="Sim")*(I8:I19<>"")*(I8:I19<=1))>0,"Em formação",IF(I23>=0.8-0.000000001,"Apto a liderar",IF(I23>=0.6-0.000000001,"Apto a auditar em equipe","Em formação"))))))
B25: Conferência | F25: =IF(F$5="",IF(COUNT(F8:F19)>0,"Falta o nome",""),IF(F21=0,"Faltam as notas",IF(F21<8,"Observar mais critérios","OK"))) | G25: =IF(G$5="",IF(COUNT(G8:G19)>0,"Falta o nome",""),IF(G21=0,"Faltam as notas",IF(G21<8,"Observar mais critérios","OK"))) | H25: =IF(H$5="",IF(COUNT(H8:H19)>0,"Falta o nome",""),IF(H21=0,"Faltam as notas",IF(H21<8,"Observar mais critérios","OK"))) | I25: =IF(I$5="",IF(COUNT(I8:I19)>0,"Falta o nome",""),IF(I21=0,"Faltam as notas",IF(I21<8,"Observar mais critérios","OK")))
B27: Resumo automático
B28: Auditores avaliados | F28: =COUNTA(F5:I5) -> 0
B29: Por nível | F29: =COUNTIF(F24:I24,"Apto a liderar")&" apto a liderar"&", "&COUNTIF(F24:I24,"Apto a auditar em equipe")&" apto a auditar em equipe"&", "&COUNTIF(F24:I24,"Em formação")&" em formação"&", "&COUNTIF(F24:I24,"Observação insuficiente")&" observação insuficiente" -> 0 apto a liderar, 0 apto a auditar em equipe, 0 em formação, 0 observação insuficiente
B30: Aviso | F30: =IF(F28=0,"Informe os auditores observados",IF(SUMPRODUCT((F25:I25<>"")*(F25:I25<>"OK"))>0,"Há auditor a completar: veja a linha Conferência",IF(COUNTIF(F24:I24,"Em formação")>0,"Há auditor em formação: planeje o acompanhamento","OK"))) -> Informe os auditores observados

Sheet Painel
B1: Painel da técnica de auditoria
B2: Nada a preencher: tudo vem das outras abas.
B3: Auditoria | C3: =IF(Amostras!D4="","",Amostras!D4&IF(Amostras!D5="",""," · "&Amostras!D5))
B5: Indicador | C5: Resultado | D5: Como se lê
B6: AMOSTRAS
B7: Amostras | C7: =COUNTA(Amostras!C12:C41) -> 0 | D7: Da aba Amostras.
B8: Registros verificados | C8: =SUM(Amostras!K12:K41) -> 0 | D8: A soma das amostras.
B9: Desvios | C9: =SUM(Amostras!L12:L41) -> 0 | D9: Em todas as amostras.
B10: Conforme na amostra | C10: =COUNTIF(Amostras!N12:N41,"Conforme na amostra") -> 0 | D10: Amostras sem desvio.
B11: Desvio pontual | C11: =COUNTIF(Amostras!N12:N41,"Desvio pontual: não conformidade, ampliar a amostra") -> 0 | D11: Não conformidade; ampliar para medir a extensão.
B12: Desvio repetido | C12: =COUNTIF(Amostras!N12:N41,"Desvio repetido: não conformidade") -> 0 | D12: Não conformidade sustentada.
B13: Amostra incompleta | C13: =COUNTIF(Amostras!N12:N41,"Amostra incompleta") -> 0 | D13: Completar ou registrar por quê.
B14: EVIDÊNCIAS
B15: Perguntas | C15: =COUNTA(Evidências!C7:C66) -> 0 | D15: Da aba Evidências.
B16: Não conformidades | C16: =COUNTIF(Evidências!H7:H66,"Não conformidade") -> 0 | D16: Constatações de não conformidade.
B17: Evidências fortes | C17: =COUNTIF(Evidências!J7:J66,"Forte") -> 0 | D17: Duas fontes ou mais.
B18: Evidências fracas | C18: =COUNTIF(Evidências!J7:J66,"Fraca") -> 0 | D18: Só entrevista.
B19: Não conformidades sem evidência objetiva | C19: =COUNTIF(Evidências!K7:K66,"Não conformidade sem evidência objetiva") -> 0 | D19: Buscar registro ou observação antes do relatório.
B20: AUDITORES
B21: Auditores avaliados | C21: =COUNTA(Auditores!F5:I5) -> 0 | D21: Da aba Auditores.
B22: Apto a liderar | C22: =COUNTIF(Auditores!F24:I24,"Apto a liderar") -> 0 | D22: Podem conduzir auditorias.
B23: Apto a auditar em equipe | C23: =COUNTIF(Auditores!F24:I24,"Apto a auditar em equipe") -> 0 | D23: Auditam com um líder.
B24: Em formação | C24: =COUNTIF(Auditores!F24:I24,"Em formação") -> 0 | D24: Acompanhamento até a próxima observação.
B25: Linhas a completar | C25: =SUMPRODUCT((Amostras!O12:O41<>"")*(Amostras!O12:O41<>"OK"))+SUMPRODUCT((Evidências!K7:K66<>"")*(Evidências!K7:K66<>"OK")) -> 0 | D25: Conferências diferentes de OK nas amostras e nas evidências.
B27: Resumo automático
B28: Aviso | C28: =IF(C7+C15=0,"Preencha as abas Amostras e Evidências",IF(C19>0,"Há não conformidade sem evidência objetiva",IF(C11>0,"Há desvio pontual: amplie a amostra",IF(C13>0,"Há amostra incompleta",IF(C25>0,"Há linha a completar: veja as conferências",IF(C24>0,"Há auditor em formação: planeje o acompanhamento","OK")))))) -> Preencha as abas Amostras e Evidências
B30: Amostras por conclusão
B31: Conforme na amostra | C31: =COUNTIF(Amostras!N12:N41,B31) -> 0
B32: Desvio pontual: não conformidade, ampliar a amostra | C32: =COUNTIF(Amostras!N12:N41,B32) -> 0
B33: Desvio repetido: não conformidade | C33: =COUNTIF(Amostras!N12:N41,B33) -> 0
B34: Amostra incompleta | C34: =COUNTIF(Amostras!N12:N41,B34) -> 0

Sheet Checklist
B1: Checklist da técnica de auditoria
B2: Escolha o status de cada item na lista suspensa (coluna em amarelo-claro).
B4: # | C4: Item de verificação | D4: Status | E4: Observações
B5: 1 | C5: Cada item da lista de verificação vira uma pergunta aberta, com o requisito ao lado.
B6: 2 | C6: O tamanho de cada amostra é decidido antes, pela população e pelo risco.
B7: 3 | C7: O auditor escolhe a amostra, e o ponto de partida não vem do auditado.
B8: 4 | C8: O tamanho da amostra e o resultado ficam anotados: quantos se viu e quantos desvios.
B9: 5 | C9: Um desvio pontual já é não conformidade, e a amostra é ampliada para medir a extensão.
B10: 6 | C10: Cada constatação tem ao menos uma evidência objetiva: observação ou registro.
B11: 7 | C11: Toda não conformidade tem ao menos uma evidência objetiva; a que nasce de entrevista é corroborada.
B12: 8 | C12: O auditor segue ao menos uma trilha até o fim em cada processo.
B13: 9 | C13: As perguntas indutoras são evitadas, e o auditado fala mais que o auditor.
B14: 10 | C14: As constatações são mostradas ao auditado durante a auditoria.
B15: 11 | C15: Os auditores são avaliados em campo, por auditoria testemunhada, com critérios escritos.
B16: 12 | C16: Quem está em formação audita em equipe até alcançar o nível de liderar.
B18: Resumo automático
B19: Itens atendidos (Sim) | D19: =COUNTIF(D5:D16,"Sim") -> 0
B20: Itens parciais | D20: =COUNTIF(D5:D16,"Parcial") -> 0
B21: Itens não atendidos | D21: =COUNTIF(D5:D16,"Não") -> 0
B22: Itens sem resposta | D22: =COUNTBLANK(D5:D16) -> 12
B23: Percentual atendido | D23: =D19/ROWS(D5:D16) -> 0
B24: Situação | D24: =IF(D19=ROWS(D5:D16),"Validado",IF(D22>0,"Em andamento","Com pendências")) -> Em andamento

Sheet Exemplo 1 - Pizzaria
B1: Técnica de auditoria
B2: Exemplo preenchido, para consulta. Use as abas Amostras, Evidências e Auditores para a sua auditoria.
B4: Auditoria | D4: 2027-02 · Atender no salão e receber insumos
B5: Organização | D5: Pizzaria (loja com salão e delivery)
B6: Auditor líder | D6: Atendente do turno da tarde
B7: Equipe | D7: Pizzaiolo do turno da tarde
B8: Observador | D8: Consultor que acompanhou a primeira auditoria do salão
B9: Critérios | D9: ISO 9001:2015, requisitos 7 e 8. Instrução do salão IT-SAL-01 rev. 2. Rotina de recebimento de insumos.
B10: Data | D10: 46464
B12: Amostras
B13: # | C13: O que se verifica | D13: Requisito | E13: Período | F13: População | G13: Risco | H13: Início | I13: Amostra | J13: Passo | K13: Verificados | L13: Desvios | M13: Observação | N13: Conclusão | O13: Conferência
B14: 1 | C14: Comandas do salão: mesa e horário anotados | D14: 8.5.1 | E14: Fevereiro de 2027 | F14: 620 | G14: Médio | H14: 7 | I14: =IF(OR(N(F14)=0,G14=""),"",IF(F14<=5,F14,IFERROR(MIN(F14,MAX(3,ROUNDUP(IF(F14<=20,5,IF(F14<=50,8,IF(F14<=100,10,IF(F14<=500,15,20))))*IF(G14="Alto",1.5,IF(G14="Médio",1,IF(G14="Baixo",0.6,"")))-0.000000001,0))),""))) -> 20 | J14: =IF(I14="","",INT(F14/I14)) -> 31 | K14: 20 | L14: 3 | M14: Três comandas sem mesa ou sem horário, todas de sábado. | N14: =IF(OR(I14="",K14="",L14=""),"",IF(K14<I14,"Amostra incompleta",IF(L14=0,"Conforme na amostra",IF(L14=1,"Desvio pontual: não conformidade, ampliar a amostra","Desvio repetido: não conformidade")))) -> Desvio repetido: não conformidade | O14: =IF(C14="","",IF(N(F14)=0,"Falta a população",IF(G14="","Falta o risco",IF(OR(H14="",H14<1,H14>J14),"Início deve ir de 1 a "&J14,IF(K14="","Falta quantos foram verificados",IF(K14>F14,"Verificados acima da população",IF(L14="","Falta quantos desvios",IF(L14>K14,"Mais desvios que verificados","OK")))))))) -> OK
B15: 2 | C15: Leituras de temperatura da câmara fria | D15: 7.1.4 | E15: Fevereiro de 2027 | F15: 56 | G15: Médio | H15: 2 | I15: =IF(OR(N(F15)=0,G15=""),"",IF(F15<=5,F15,IFERROR(MIN(F15,MAX(3,ROUNDUP(IF(F15<=20,5,IF(F15<=50,8,IF(F15<=100,10,IF(F15<=500,15,20))))*IF(G15="Alto",1.5,IF(G15="Médio",1,IF(G15="Baixo",0.6,"")))-0.000000001,0))),""))) -> 10 | J15: =IF(I15="","",INT(F15/I15)) -> 5 | K15: 10 | L15: 1 | M15: Leitura do domingo, 14/02, sem anotação. | N15: =IF(OR(I15="",K15="",L15=""),"",IF(K15<I15,"Amostra incompleta",IF(L15=0,"Conforme na amostra",IF(L15=1,"Desvio pontual: não conformidade, ampliar a amostra","Desvio repetido: não conformidade")))) -> Desvio pontual: não conformidade, ampliar a amostra | O15: =IF(C15="","",IF(N(F15)=0,"Falta a população",IF(G15="","Falta o risco",IF(OR(H15="",H15<1,H15>J15),"Início deve ir de 1 a "&J15,IF(K15="","Falta quantos foram verificados",IF(K15>F15,"Verificados acima da população",IF(L15="","Falta quantos desvios",IF(L15>K15,"Mais desvios que verificados","OK")))))))) -> OK
B16: 3 | C16: Notas de recebimento com a temperatura anotada | D16: 8.4 | E16: Fevereiro de 2027 | F16: 48 | G16: Alto | H16: 3 | I16: =IF(OR(N(F16)=0,G16=""),"",IF(F16<=5,F16,IFERROR(MIN(F16,MAX(3,ROUNDUP(IF(F16<=20,5,IF(F16<=50,8,IF(F16<=100,10,IF(F16<=500,15,20))))*IF(G16="Alto",1.5,IF(G16="Médio",1,IF(G16="Baixo",0.6,"")))-0.000000001,0))),""))) -> 12 | J16: =IF(I16="","",INT(F16/I16)) -> 4 | K16: 12 | L16: 0 | N16: =IF(OR(I16="",K16="",L16=""),"",IF(K16<I16,"Amostra incompleta",IF(L16=0,"Conforme na amostra",IF(L16=1,"Desvio pontual: não conformidade, ampliar a amostra","Desvio repetido: não conformidade")))) -> Conforme na amostra | O16: =IF(C16="","",IF(N(F16)=0,"Falta a população",IF(G16="","Falta o risco",IF(OR(H16="",H16<1,H16>J16),"Início deve ir de 1 a "&J16,IF(K16="","Falta quantos foram verificados",IF(K16>F16,"Verificados acima da população",IF(L16="","Falta quantos desvios",IF(L16>K16,"Mais desvios que verificados","OK")))))))) -> OK
B17: 4 | C17: Fichas de treinamento da equipe nova do salão | D17: 7.2 | E17: Admissões de 2027 | F17: 6 | G17: Baixo | H17: 1 | I17: =IF(OR(N(F17)=0,G17=""),"",IF(F17<=5,F17,IFERROR(MIN(F17,MAX(3,ROUNDUP(IF(F17<=20,5,IF(F17<=50,8,IF(F17<=100,10,IF(F17<=500,15,20))))*IF(G17="Alto",1.5,IF(G17="Médio",1,IF(G17="Baixo",0.6,"")))-0.000000001,0))),""))) -> 3 | J17: =IF(I17="","",INT(F17/I17)) -> 2 | K17: 3 | L17: 0 | N17: =IF(OR(I17="",K17="",L17=""),"",IF(K17<I17,"Amostra incompleta",IF(L17=0,"Conforme na amostra",IF(L17=1,"Desvio pontual: não conformidade, ampliar a amostra","Desvio repetido: não conformidade")))) -> Conforme na amostra | O17: =IF(C17="","",IF(N(F17)=0,"Falta a população",IF(G17="","Falta o risco",IF(OR(H17="",H17<1,H17>J17),"Início deve ir de 1 a "&J17,IF(K17="","Falta quantos foram verificados",IF(K17>F17,"Verificados acima da população",IF(L17="","Falta quantos desvios",IF(L17>K17,"Mais desvios que verificados","OK")))))))) -> OK
B18: 5 | C18: Checklists de limpeza do salão | D18: 7.1.4 | E18: Fevereiro de 2027 | F18: 28 | G18: Médio | H18: 2 | I18: =IF(OR(N(F18)=0,G18=""),"",IF(F18<=5,F18,IFERROR(MIN(F18,MAX(3,ROUNDUP(IF(F18<=20,5,IF(F18<=50,8,IF(F18<=100,10,IF(F18<=500,15,20))))*IF(G18="Alto",1.5,IF(G18="Médio",1,IF(G18="Baixo",0.6,"")))-0.000000001,0))),""))) -> 8 | J18: =IF(I18="","",INT(F18/I18)) -> 3 | K18: 6 | L18: 0 | M18: Dois checklists não estavam na pasta no dia. | N18: =IF(OR(I18="",K18="",L18=""),"",IF(K18<I18,"Amostra incompleta",IF(L18=0,"Conforme na amostra",IF(L18=1,"Desvio pontual: não conformidade, ampliar a amostra","Desvio repetido: não conformidade")))) -> Amostra incompleta | O18: =IF(C18="","",IF(N(F18)=0,"Falta a população",IF(G18="","Falta o risco",IF(OR(H18="",H18<1,H18>J18),"Início deve ir de 1 a "&J18,IF(K18="","Falta quantos foram verificados",IF(K18>F18,"Verificados acima da população",IF(L18="","Falta quantos desvios",IF(L18>K18,"Mais desvios que verificados","OK")))))))) -> OK
B20: Evidências
B21: # | C21: Pergunta | D21: Requisito | E21: Entrevista | F21: Observação | H21: Registro | K21: Constatação | M21: Força | N21: Conferência
B22: 1 | C22: Como a comanda do salão registra a mesa e o horário? | D22: 8.5.1 | E22: Garçom do turno da noite | F22: Duas comandas abertas na hora; uma sem horário | H22: 20 comandas de fevereiro: 3 sem mesa ou sem horário | K22: Não conformidade | M22: =IF(COUNTA(E22,F22,H22)=0,"",IF(COUNTA(E22,F22,H22)>=2,"Forte",IF(OR(F22<>"",H22<>""),"Média","Fraca"))) -> Forte | N22: =IF(D22="","Falta o requisito",IF(C22="","Falta a pergunta",IF(COUNTA(E22,F22,H22)=0,"Falta a evidência",IF(K22="","Falta a constatação",IF(AND(K22="Não conformidade",M22="Fraca"),"Não conformidade sem evidência objetiva","OK"))))) -> OK
B23: 2 | C23: Como vocês sabem que o termômetro da câmara mede certo? | D23: 7.1.5 | E23: Pizzaiolo líder: “verificamos todo mês” | H23: Planilha FR-07: termômetro da câmara verificado em 15/03, reprovado e trocado; leituras anteriores não revistas | K23: Não conformidade | M23: =IF(COUNTA(E23,F23,H23)=0,"",IF(COUNTA(E23,F23,H23)>=2,"Forte",IF(OR(F23<>"",H23<>""),"Média","Fraca"))) -> Forte | N23: =IF(D23="","Falta o requisito",IF(C23="","Falta a pergunta",IF(COUNTA(E23,F23,H23)=0,"Falta a evidência",IF(K23="","Falta a constatação",IF(AND(K23="Não conformidade",M23="Fraca"),"Não conformidade sem evidência objetiva","OK"))))) -> OK
B24: 3 | C24: Como as leituras de temperatura da câmara fria são registradas? | D24: 7.1.4 | H24: 10 leituras de fevereiro: 1 sem anotação, a do domingo, 14/02 | K24: Não conformidade | M24: =IF(COUNTA(E24,F24,H24)=0,"",IF(COUNTA(E24,F24,H24)>=2,"Forte",IF(OR(F24<>"",H24<>""),"Média","Fraca"))) -> Média | N24: =IF(D24="","Falta o requisito",IF(C24="","Falta a pergunta",IF(COUNTA(E24,F24,H24)=0,"Falta a evidência",IF(K24="","Falta a constatação",IF(AND(K24="Não conformidade",M24="Fraca"),"Não conformidade sem evidência objetiva","OK"))))) -> OK
B25: 4 | C25: Como o recebimento confere a temperatura dos refrigerados? | D25: 8.4 | E25: Atendente que recebe | F25: Recebimento do laticínio às 15h: temperatura medida e anotada | H25: 12 notas de fevereiro com a temperatura anotada | K25: Conforme | M25: =IF(COUNTA(E25,F25,H25)=0,"",IF(COUNTA(E25,F25,H25)>=2,"Forte",IF(OR(F25<>"",H25<>""),"Média","Fraca"))) -> Forte | N25: =IF(D25="","Falta o requisito",IF(C25="","Falta a pergunta",IF(COUNTA(E25,F25,H25)=0,"Falta a evidência",IF(K25="","Falta a constatação",IF(AND(K25="Não conformidade",M25="Fraca"),"Não conformidade sem evidência objetiva","OK"))))) -> OK
B26: 5 | C26: Quem treinou a equipe nova do salão, e como? | D26: 7.2 | E26: Gerente da loja | H26: 3 fichas de treinamento assinadas, com a instrução IT-SAL-01 | K26: Conforme | M26: =IF(COUNTA(E26,F26,H26)=0,"",IF(COUNTA(E26,F26,H26)>=2,"Forte",IF(OR(F26<>"",H26<>""),"Média","Fraca"))) -> Forte | N26: =IF(D26="","Falta o requisito",IF(C26="","Falta a pergunta",IF(COUNTA(E26,F26,H26)=0,"Falta a evidência",IF(K26="","Falta a constatação",IF(AND(K26="Não conformidade",M26="Fraca"),"Não conformidade sem evidência objetiva","OK"))))) -> OK
B27: 6 | C27: O cliente do salão é avisado do tempo de espera? | D27: 8.2.1 | E27: Garçom: “nem sempre avisamos” | K27: Não conformidade | M27: =IF(COUNTA(E27,F27,H27)=0,"",IF(COUNTA(E27,F27,H27)>=2,"Forte",IF(OR(F27<>"",H27<>""),"Média","Fraca"))) -> Fraca | N27: =IF(D27="","Falta o requisito",IF(C27="","Falta a pergunta",IF(COUNTA(E27,F27,H27)=0,"Falta a evidência",IF(K27="","Falta a constatação",IF(AND(K27="Não conformidade",M27="Fraca"),"Não conformidade sem evidência objetiva","OK"))))) -> Não conformidade sem evidência objetiva
B28: 7 | C28: Como as reclamações do salão são registradas? | D28: 9.1.2 | E28: Gerente da loja | H28: Registro de reclamações só com o delivery; o salão não aparece | K28: Oportunidade de melhoria | M28: =IF(COUNTA(E28,F28,H28)=0,"",IF(COUNTA(E28,F28,H28)>=2,"Forte",IF(OR(F28<>"",H28<>""),"Média","Fraca"))) -> Forte | N28: =IF(D28="","Falta o requisito",IF(C28="","Falta a pergunta",IF(COUNTA(E28,F28,H28)=0,"Falta a evidência",IF(K28="","Falta a constatação",IF(AND(K28="Não conformidade",M28="Fraca"),"Não conformidade sem evidência objetiva","OK"))))) -> OK
B29: 8 | C29: A instrução do salão em uso é a vigente? | D29: 7.5 | F29: Instrução no balcão na revisão 1 | H29: Lista mestra: IT-SAL-01 na revisão 2, de 10/02/2027 | K29: Não conformidade | M29: =IF(COUNTA(E29,F29,H29)=0,"",IF(COUNTA(E29,F29,H29)>=2,"Forte",IF(OR(F29<>"",H29<>""),"Média","Fraca"))) -> Forte | N29: =IF(D29="","Falta o requisito",IF(C29="","Falta a pergunta",IF(COUNTA(E29,F29,H29)=0,"Falta a evidência",IF(K29="","Falta a constatação",IF(AND(K29="Não conformidade",M29="Fraca"),"Não conformidade sem evidência objetiva","OK"))))) -> OK
B30: 9 | C30: Como os insumos são guardados depois do recebimento? | D30: 8.5.4 | E30: Pizzaiolo do turno | F30: Câmara organizada, com etiquetas de validade | K30: Conforme | M30: =IF(COUNTA(E30,F30,H30)=0,"",IF(COUNTA(E30,F30,H30)>=2,"Forte",IF(OR(F30<>"",H30<>""),"Média","Fraca"))) -> Forte | N30: =IF(D30="","Falta o requisito",IF(C30="","Falta a pergunta",IF(COUNTA(E30,F30,H30)=0,"Falta a evidência",IF(K30="","Falta a constatação",IF(AND(K30="Não conformidade",M30="Fraca"),"Não conformidade sem evidência objetiva","OK"))))) -> OK
B31: 10 | C31: Como a pizza do salão é conferida antes de servir? | D31: 8.5.1 | E31: Pizzaiolo do turno | F31: Conferência do sabor pela comanda, no passa-pratos | M31: =IF(COUNTA(E31,F31,H31)=0,"",IF(COUNTA(E31,F31,H31)>=2,"Forte",IF(OR(F31<>"",H31<>""),"Média","Fraca"))) -> Forte | N31: =IF(D31="","Falta o requisito",IF(C31="","Falta a pergunta",IF(COUNTA(E31,F31,H31)=0,"Falta a evidência",IF(K31="","Falta a constatação",IF(AND(K31="Não conformidade",M31="Fraca"),"Não conformidade sem evidência objetiva","OK"))))) -> Falta a constatação
B33: Avaliação dos auditores em campo
B34: # | C34: Critério | D34: Etapa | E34: Crítico | F34: Atendente do turno da tarde | G34: Pizzaiolo do turno da tarde
B35: Papel | F35: Auditor líder | G35: Auditor
B36: 1 | C36: Leu os documentos e o relatório da auditoria anterior antes de ir a campo. | D36: Preparação | E36: — | F36: 2 | G36: 1
B37: 2 | C37: Preparou a lista de verificação e o tamanho das amostras com antecedência. | D37: Preparação | E37: — | F37: 2 | G37: 1
B38: 3 | C38: Confirmou o objetivo, o escopo, os critérios e o plano na reunião de abertura. | D38: Abertura | E38: — | F38: 3
B39: 4 | C39: Fez perguntas abertas e pediu para ver: “mostre-me”. | D39: Entrevista | E39: — | F39: 2 | G39: 2
B40: 5 | C40: Ouviu sem interromper e sem sugerir a resposta. | D40: Entrevista | E40: — | F40: 1 | G40: 2
B41: 6 | C41: Escolheu a amostra, em vez de aceitar a oferecida pelo auditado. | D41: Amostra | E41: Sim | F41: 3 | G41: 2
B42: 7 | C42: Anotou o tamanho de cada amostra e o que encontrou nela. | D42: Amostra | E42: — | F42: 2 | G42: 1
B43: 8 | C43: Corroborou o que ouviu com observação ou registro. | D43: Evidência | E43: Sim | F43: 1 | G43: 2
B44: 9 | C44: Seguiu ao menos uma trilha até o fim, de um registro ao seguinte. | D44: Evidência | E44: — | F44: 2 | G44: 3
...

Sheet Exemplo 2 - Indústria
B1: Técnica de auditoria
B2: Exemplo preenchido, para consulta. Use as abas Amostras, Evidências e Auditores para a sua auditoria.
B4: Auditoria | D4: 2027-11 · Produção (extrusão e rebobinamento)
B5: Organização | D5: Indústria de embalagens plásticas
B6: Auditor líder | D6: Coordenador da Qualidade
B7: Equipe | D7: Engenheiro de processos e Analista de RH (auditor em formação)
B8: Observador | D8: Gerente de RH, que mantém a avaliação dos auditores internos
B9: Critérios | D9: ISO 9001:2015, requisitos 7.1, 7.2, 8.5 e 8.7. Plano de controle da extrusão rev. 6. Procedimento de mudanças PG-05.
B10: Data | D10: 46666
B12: Amostras
B13: # | C13: O que se verifica | D13: Requisito | E13: Período | F13: População | G13: Risco | H13: Início | I13: Amostra | J13: Passo | K13: Verificados | L13: Desvios | M13: Observação | N13: Conclusão | O13: Conferência
B14: 1 | C14: Registros de espessura por bobina, com cinco pontos | D14: 8.5.1 | E14: Julho e agosto de 2027 | F14: 1150 | G14: Alto | H14: 12 | I14: =IF(OR(N(F14)=0,G14=""),"",IF(F14<=5,F14,IFERROR(MIN(F14,MAX(3,ROUNDUP(IF(F14<=20,5,IF(F14<=50,8,IF(F14<=100,10,IF(F14<=500,15,20))))*IF(G14="Alto",1.5,IF(G14="Médio",1,IF(G14="Baixo",0.6,"")))-0.000000001,0))),""))) -> 30 | J14: =IF(I14="","",INT(F14/I14)) -> 38 | K14: 30 | L14: 0 | N14: =IF(OR(I14="",K14="",L14=""),"",IF(K14<I14,"Amostra incompleta",IF(L14=0,"Conforme na amostra",IF(L14=1,"Desvio pontual: não conformidade, ampliar a amostra","Desvio repetido: não conformidade")))) -> Conforme na amostra | O14: =IF(C14="","",IF(N(F14)=0,"Falta a população",IF(G14="","Falta o risco",IF(OR(H14="",H14<1,H14>J14),"Início deve ir de 1 a "&J14,IF(K14="","Falta quantos foram verificados",IF(K14>F14,"Verificados acima da população",IF(L14="","Falta quantos desvios",IF(L14>K14,"Mais desvios que verificados","OK")))))))) -> OK
B15: 2 | C15: Registros de mudança de processo, com autorização | D15: 8.5.6 | E15: 2027 até setembro | F15: 9 | G15: Alto | H15: 1 | I15: =IF(OR(N(F15)=0,G15=""),"",IF(F15<=5,F15,IFERROR(MIN(F15,MAX(3,ROUNDUP(IF(F15<=20,5,IF(F15<=50,8,IF(F15<=100,10,IF(F15<=500,15,20))))*IF(G15="Alto",1.5,IF(G15="Médio",1,IF(G15="Baixo",0.6,"")))-0.000000001,0))),""))) -> 8 | J15: =IF(I15="","",INT(F15/I15)) -> 1 | K15: 8 | L15: 2 | M15: Duas mudanças de velocidade do turno C sem autorização. | N15: =IF(OR(I15="",K15="",L15=""),"",IF(K15<I15,"Amostra incompleta",IF(L15=0,"Conforme na amostra",IF(L15=1,"Desvio pontual: não conformidade, ampliar a amostra","Desvio repetido: não conformidade")))) -> Desvio repetido: não conformidade | O15: =IF(C15="","",IF(N(F15)=0,"Falta a população",IF(G15="","Falta o risco",IF(OR(H15="",H15<1,H15>J15),"Início deve ir de 1 a "&J15,IF(K15="","Falta quantos foram verificados",IF(K15>F15,"Verificados acima da população",IF(L15="","Falta quantos desvios",IF(L15>K15,"Mais desvios que verificados","OK")))))))) -> OK
B16: 3 | C16: Ordens de manutenção corretiva, com o produto afetado | D16: 8.7 | E16: Julho e agosto de 2027 | F16: 14 | G16: Médio | H16: 2 | I16: =IF(OR(N(F16)=0,G16=""),"",IF(F16<=5,F16,IFERROR(MIN(F16,MAX(3,ROUNDUP(IF(F16<=20,5,IF(F16<=50,8,IF(F16<=100,10,IF(F16<=500,15,20))))*IF(G16="Alto",1.5,IF(G16="Médio",1,IF(G16="Baixo",0.6,"")))-0.000000001,0))),""))) -> 5 | J16: =IF(I16="","",INT(F16/I16)) -> 2 | K16: 5 | L16: 1 | M16: Quebra do chiller, 22/07: produto afetado sem destino. | N16: =IF(OR(I16="",K16="",L16=""),"",IF(K16<I16,"Amostra incompleta",IF(L16=0,"Conforme na amostra",IF(L16=1,"Desvio pontual: não conformidade, ampliar a amostra","Desvio repetido: não conformidade")))) -> Desvio pontual: não conformidade, ampliar a amostra | O16: =IF(C16="","",IF(N(F16)=0,"Falta a população",IF(G16="","Falta o risco",IF(OR(H16="",H16<1,H16>J16),"Início deve ir de 1 a "&J16,IF(K16="","Falta quantos foram verificados",IF(K16>F16,"Verificados acima da população",IF(L16="","Falta quantos desvios",IF(L16>K16,"Mais desvios que verificados","OK")))))))) -> OK
B17: 4 | C17: Instrumentos do posto com etiqueta em dia | D17: 7.1.5 | E17: Na data da auditoria | F17: 25 | G17: Alto | H17: 1 | I17: =IF(OR(N(F17)=0,G17=""),"",IF(F17<=5,F17,IFERROR(MIN(F17,MAX(3,ROUNDUP(IF(F17<=20,5,IF(F17<=50,8,IF(F17<=100,10,IF(F17<=500,15,20))))*IF(G17="Alto",1.5,IF(G17="Médio",1,IF(G17="Baixo",0.6,"")))-0.000000001,0))),""))) -> 12 | J17: =IF(I17="","",INT(F17/I17)) -> 2 | K17: 12 | L17: 0 | N17: =IF(OR(I17="",K17="",L17=""),"",IF(K17<I17,"Amostra incompleta",IF(L17=0,"Conforme na amostra",IF(L17=1,"Desvio pontual: não conformidade, ampliar a amostra","Desvio repetido: não conformidade")))) -> Conforme na amostra | O17: =IF(C17="","",IF(N(F17)=0,"Falta a população",IF(G17="","Falta o risco",IF(OR(H17="",H17<1,H17>J17),"Início deve ir de 1 a "&J17,IF(K17="","Falta quantos foram verificados",IF(K17>F17,"Verificados acima da população",IF(L17="","Falta quantos desvios",IF(L17>K17,"Mais desvios que verificados","OK")))))))) -> OK
B18: 5 | C18: Registros de treinamento do turno C | D18: 7.2 | E18: Admissões e remanejamentos de 2027 | F18: 12 | G18: Médio | H18: 2 | I18: =IF(OR(N(F18)=0,G18=""),"",IF(F18<=5,F18,IFERROR(MIN(F18,MAX(3,ROUNDUP(IF(F18<=20,5,IF(F18<=50,8,IF(F18<=100,10,IF(F18<=500,15,20))))*IF(G18="Alto",1.5,IF(G18="Médio",1,IF(G18="Baixo",0.6,"")))-0.000000001,0))),""))) -> 5 | J18: =IF(I18="","",INT(F18/I18)) -> 2 | K18: 5 | L18: 0 | N18: =IF(OR(I18="",K18="",L18=""),"",IF(K18<I18,"Amostra incompleta",IF(L18=0,"Conforme na amostra",IF(L18=1,"Desvio pontual: não conformidade, ampliar a amostra","Desvio repetido: não conformidade")))) -> Conforme na amostra | O18: =IF(C18="","",IF(N(F18)=0,"Falta a população",IF(G18="","Falta o risco",IF(OR(H18="",H18<1,H18>J18),"Início deve ir de 1 a "&J18,IF(K18="","Falta quantos foram verificados",IF(K18>F18,"Verificados acima da população",IF(L18="","Falta quantos desvios",IF(L18>K18,"Mais desvios que verificados","OK")))))))) -> OK
B20: Evidências
B21: # | C21: Pergunta | D21: Requisito | E21: Entrevista | F21: Observação | H21: Registro | K21: Constatação | M21: Força | N21: Conferência
B22: 1 | C22: Como uma mudança de processo é autorizada? | D22: 8.5.6 | E22: Líder do turno C | H22: 8 registros de mudança de 2027: 2 sem autorização | K22: Não conformidade | M22: =IF(COUNTA(E22,F22,H22)=0,"",IF(COUNTA(E22,F22,H22)>=2,"Forte",IF(OR(F22<>"",H22<>""),"Média","Fraca"))) -> Forte | N22: =IF(D22="","Falta o requisito",IF(C22="","Falta a pergunta",IF(COUNTA(E22,F22,H22)=0,"Falta a evidência",IF(K22="","Falta a constatação",IF(AND(K22="Não conformidade",M22="Fraca"),"Não conformidade sem evidência objetiva","OK"))))) -> OK
B23: 2 | C23: Como a espessura é medida na extrusora 3? | D23: 8.5.1 | E23: Operador do turno A | F23: Medição em cinco pontos com o micrômetro de 0,1 µm | H23: 30 bobinas de julho e agosto, todas com os cinco pontos | K23: Conforme | M23: =IF(COUNTA(E23,F23,H23)=0,"",IF(COUNTA(E23,F23,H23)>=2,"Forte",IF(OR(F23<>"",H23<>""),"Média","Fraca"))) -> Forte | N23: =IF(D23="","Falta o requisito",IF(C23="","Falta a pergunta",IF(COUNTA(E23,F23,H23)=0,"Falta a evidência",IF(K23="","Falta a constatação",IF(AND(K23="Não conformidade",M23="Fraca"),"Não conformidade sem evidência objetiva","OK"))))) -> OK
B24: 3 | C24: O que acontece com o produto quando uma máquina quebra? | D24: 8.7 | E24: Supervisor de manutenção | H24: 5 ordens corretivas: 1 sem o destino do produto afetado | K24: Não conformidade | M24: =IF(COUNTA(E24,F24,H24)=0,"",IF(COUNTA(E24,F24,H24)>=2,"Forte",IF(OR(F24<>"",H24<>""),"Média","Fraca"))) -> Forte | N24: =IF(D24="","Falta o requisito",IF(C24="","Falta a pergunta",IF(COUNTA(E24,F24,H24)=0,"Falta a evidência",IF(K24="","Falta a constatação",IF(AND(K24="Não conformidade",M24="Fraca"),"Não conformidade sem evidência objetiva","OK"))))) -> OK
B25: 4 | C25: Quem mais sabe regular a extrusora 3? | D25: 7.1.6 | E25: Operador sênior e operador do turno C | F25: Operador do turno C regulando com acompanhamento | H25: Mapa do conhecimento, C-01, ação até 30/11 | K25: Conforme | M25: =IF(COUNTA(E25,F25,H25)=0,"",IF(COUNTA(E25,F25,H25)>=2,"Forte",IF(OR(F25<>"",H25<>""),"Média","Fraca"))) -> Forte | N25: =IF(D25="","Falta o requisito",IF(C25="","Falta a pergunta",IF(COUNTA(E25,F25,H25)=0,"Falta a evidência",IF(K25="","Falta a constatação",IF(AND(K25="Não conformidade",M25="Fraca"),"Não conformidade sem evidência objetiva","OK"))))) -> OK
B26: 5 | C26: Os instrumentos do posto estão identificados e em dia? | D26: 7.1.5 | F26: 12 instrumentos com etiqueta em dia | H26: Lista de instrumentos de 30/09 | K26: Conforme | M26: =IF(COUNTA(E26,F26,H26)=0,"",IF(COUNTA(E26,F26,H26)>=2,"Forte",IF(OR(F26<>"",H26<>""),"Média","Fraca"))) -> Forte | N26: =IF(D26="","Falta o requisito",IF(C26="","Falta a pergunta",IF(COUNTA(E26,F26,H26)=0,"Falta a evidência",IF(K26="","Falta a constatação",IF(AND(K26="Não conformidade",M26="Fraca"),"Não conformidade sem evidência objetiva","OK"))))) -> OK
B27: 6 | C27: O operador novo do turno C foi treinado na regulagem? | D27: 7.2 | E27: Operador novo: “aprendi com o colega” | K27: Não conformidade | M27: =IF(COUNTA(E27,F27,H27)=0,"",IF(COUNTA(E27,F27,H27)>=2,"Forte",IF(OR(F27<>"",H27<>""),"Média","Fraca"))) -> Fraca | N27: =IF(D27="","Falta o requisito",IF(C27="","Falta a pergunta",IF(COUNTA(E27,F27,H27)=0,"Falta a evidência",IF(K27="","Falta a constatação",IF(AND(K27="Não conformidade",M27="Fraca"),"Não conformidade sem evidência objetiva","OK"))))) -> Não conformidade sem evidência objetiva
B28: 7 | C28: Como o refugo da extrusão é analisado? | D28: 9.1.3 | E28: Gerente industrial | H28: Painel de indicadores de setembro, com o Pareto do refugo | K28: Conforme | M28: =IF(COUNTA(E28,F28,H28)=0,"",IF(COUNTA(E28,F28,H28)>=2,"Forte",IF(OR(F28<>"",H28<>""),"Média","Fraca"))) -> Forte | N28: =IF(D28="","Falta o requisito",IF(C28="","Falta a pergunta",IF(COUNTA(E28,F28,H28)=0,"Falta a evidência",IF(K28="","Falta a constatação",IF(AND(K28="Não conformidade",M28="Fraca"),"Não conformidade sem evidência objetiva","OK"))))) -> OK
B29: 8 | C29: O que se faz com a bobina fora de espessura? | D29: 8.7 | E29: Líder do turno | F29: Bobina com etiqueta vermelha na área de segregação | H29: Registro de produto não conforme de 03/10 | K29: Conforme | M29: =IF(COUNTA(E29,F29,H29)=0,"",IF(COUNTA(E29,F29,H29)>=2,"Forte",IF(OR(F29<>"",H29<>""),"Média","Fraca"))) -> Forte | N29: =IF(D29="","Falta o requisito",IF(C29="","Falta a pergunta",IF(COUNTA(E29,F29,H29)=0,"Falta a evidência",IF(K29="","Falta a constatação",IF(AND(K29="Não conformidade",M29="Fraca"),"Não conformidade sem evidência objetiva","OK"))))) -> OK
B31: Avaliação dos auditores em campo
B32: # | C32: Critério | D32: Etapa | E32: Crítico | F32: Coordenador da Qualidade | G32: Engenheiro de processos | H32: Analista de RH
B33: Papel | F33: Auditor líder | G33: Auditor | H33: Auditor em formação
B34: 1 | C34: Leu os documentos e o relatório da auditoria anterior antes de ir a campo. | D34: Preparação | E34: — | F34: 3 | G34: 2 | H34: 2
B35: 2 | C35: Preparou a lista de verificação e o tamanho das amostras com antecedência. | D35: Preparação | E35: — | F35: 3 | G35: 2 | H35: 1
B36: 3 | C36: Confirmou o objetivo, o escopo, os critérios e o plano na reunião de abertura. | D36: Abertura | E36: — | F36: 3
B37: 4 | C37: Fez perguntas abertas e pediu para ver: “mostre-me”. | D37: Entrevista | E37: — | F37: 3 | G37: 2 | H37: 2
B38: 5 | C38: Ouviu sem interromper e sem sugerir a resposta. | D38: Entrevista | E38: — | F38: 2 | G38: 2 | H38: 2
B39: 6 | C39: Escolheu a amostra, em vez de aceitar a oferecida pelo auditado. | D39: Amostra | E39: Sim | F39: 3 | G39: 3 | H39: 1
B40: 7 | C40: Anotou o tamanho de cada amostra e o que encontrou nela. | D40: Amostra | E40: — | F40: 3 | G40: 2 | H40: 1
B41: 8 | C41: Corroborou o que ouviu com observação ou registro. | D41: Evidência | E41: Sim | F41: 3 | G41: 2 | H41: 1
B42: 9 | C42: Seguiu ao menos uma trilha até o fim, de um registro ao seguinte. | D42: Evidência | E42: — | F42: 3 | G42: 3
B43: 10 | C43: Escreveu cada não conformidade com requisito, evidência e desvio. | D43: Constatação | E43: Sim | F43: 3 | G43: 2
B44: 11 | C44: Não apontou culpados nem ditou a solução. | D44: Constatação | E44: — | F44: 2 | G44: 1 | H44: 2
...
