Workbook

Sheet Instruções
B1: Informação documentada — Como usar esta planilha
B2: Modelo de lista mestra, tabela de retenção de registros, lista de documentos externos e histórico de alterações.
B4: Legenda: onde preencher
B5: Amarelo-claro | C5: Células de entrada. É aqui que você digita.
B6: Cinza | C6: Células calculadas ou fixas (rótulos, próxima revisão, situação, contagens, avisos). Não altere.
B7: Cinza em itálico | C7: Linha de exemplo (marcada com “Ex.”). Mostra o formato esperado e não entra nas contagens.
B8: Listas suspensas | C8: Colunas de tipo, meio, status e conferência aceitam apenas as opções da lista.
B9: Comentários | C9: Células com triângulo vermelho no canto trazem uma dica de preenchimento. Passe o mouse sobre elas.
B11: Os tipos de documento
B12: PO · Política | C12: Compromisso da direção, em uma página. Ex.: Política da qualidade, política de compras.
B13: MP · Mapa e descrição de processo | C13: Como os processos se ligam, e o que cada um precisa. Ex.: Mapa de processos, SIPOC, tartaruga.
B14: PR · Procedimento | C14: Como um processo é feito: quem faz o quê, em que ordem, com que critério. Ex.: PR-SUP-01, aquisição de materiais e serviços.
B15: IT · Instrução de trabalho | C15: Como uma atividade é feita, passo a passo, no posto de trabalho. Ex.: IT-EXP-01, expedição e agrupamento por zona.
B16: ES · Especificação | C16: O que o produto ou o serviço deve ser. Ex.: Cardápio com composição, ficha técnica do produto.
B17: FR · Formulário | C17: Modelo em branco, que vira registro quando preenchido. Ex.: Requisição de compra, ficha de alergênicos.
B18: DE · Documento externo | C18: Vem de fora e a organização precisa seguir. Ex.: Norma ISO 9001, desenho do cliente, manual do forno.
B20: Ordem recomendada de preenchimento
B21: Passo 1 | C21: Aba Lista mestra: escreva a organização, a data de referência e o intervalo padrão de revisão.
B22: Passo 2 | C22: Aba Lista mestra: cadastre cada documento, com código, tipo, processo, revisão, data, quem elaborou e quem aprovou.
B23: Passo 3 | C23: Aba Lista mestra: leia a coluna Situação e trate o que falta.
B24: Passo 4 | C24: Aba Registros: cadastre cada registro, com local de guarda, meio, prazo de retenção, acesso e disposição.
B25: Passo 5 | C25: Aba Externos: liste as normas, as leis e os documentos de cliente, com o responsável e o intervalo de verificação.
B26: Passo 6 | C26: Aba Alterações: a cada revisão de documento, registre o que mudou e confira os documentos ligados.
B27: Passo 7 | C27: Aba Checklist: valide o controle de documentos.
B29: Abas da planilha
B30: Lista mestra | C30: Até 30 documentos, com a próxima revisão e a situação calculadas, contagem por situação e gráfico.
B31: Registros | C31: Até 20 registros, com a conferência dos campos de retenção.
B32: Externos | C32: Até 15 documentos de origem externa, com a próxima verificação e a situação calculadas.
B33: Alterações | C33: Histórico de até 20 alterações, com a conferência dos documentos ligados.
B34: Checklist | C34: Doze verificações de qualidade do controle de documentos, com percentual de conclusão.
B35: Exemplo 1 - Pizzaria | C35: A lista mestra e a tabela de retenção de uma loja, depois do levantamento.
B36: Exemplo 2 - Compras | C36: Os documentos e os registros do processo de aquisição de uma indústria.
B38: Regras e premissas do modelo
B39: Situação do documento | C39: Vigente: tem código, revisão, aprovação e a próxima revisão ainda não chegou. Revisão vencida: passou da data prevista. Falta o código, a revisão ou a aprovação: o documento está em uso, mas fora do controle. Em revisão e Obsoleto vêm da coluna Status.
B40: Próxima revisão | C40: É a data da revisão mais o intervalo, em meses. Sem intervalo na linha, vale o intervalo padrão da aba, de 24 meses.
B41: Data de referência | C41: A situação é calculada pela data de referência da aba Lista mestra. Se ela estiver em branco, a planilha usa a data de hoje.
B42: Documento obsoleto | C42: Continua na lista, marcado, para que ninguém reaproveite o código. Sai dos postos de trabalho.
B43: Registros | C43: A retenção é contada em meses, a partir da data em que o registro é gerado. Doze meses valem um ano.
B44: Tipos e códigos | C44: Os tipos, as siglas e a regra de código são uma convenção deste modelo. A norma não os define.
B45: Exemplos | C45: Os dados das abas de exemplo são ilustrativos, criados para este material.

Sheet Lista mestra
B1: Lista mestra de documentos
B2: Um documento por linha. A próxima revisão e a situação são calculadas. Os formulários em branco entram aqui; os preenchidos vão para a aba Registros.
B4: Organização
B5: Data de referência | E5: Data em que a lista é conferida. Em branco, vale a data de hoje.
B6: Intervalo padrão de revisão, em meses | D6: 24 | E6: Usado nas linhas sem intervalo próprio.
B7: # | C7: Código | D7: Título | E7: Tipo | F7: Processo | G7: Revisão | H7: Data da revisão | I7: Elaborou | J7: Aprovou | K7: Meio | L7: Local da versão em vigor | M7: Revisar a cada (meses) | N7: Próxima revisão | O7: Status | P7: Situação
C8: Tipo-processo-nº | D8: Como está no cabeçalho | E8: Sigla | F8: Do mapa de processos | G8: Número ou data | H8: Da aprovação | I8: Nome ou cargo | J8: Nome ou cargo | K8: Escolha na lista | L8: Onde está a versão em vigor | M8: Em branco: padrão | N8: Calculada | O8: Escolha na lista | P8: Calculada
B9: 1 | N9: =IF(OR(H9="",D9=""),"",EDATE(H9,IF(M9="",$D$6,M9))) | P9: =IF(D9="","",IF(C9="","Falta o código",IF(O9="Obsoleto","Obsoleto",IF(OR(G9="",H9=""),"Falta a revisão",IF(J9="","Falta a aprovação",IF(O9="Em revisão","Em revisão",IF(N9<IF($D$5="",TODAY(),$D$5),"Revisão vencida","Vigente")))))))
B10: 2 | N10: =IF(OR(H10="",D10=""),"",EDATE(H10,IF(M10="",$D$6,M10))) | P10: =IF(D10="","",IF(C10="","Falta o código",IF(O10="Obsoleto","Obsoleto",IF(OR(G10="",H10=""),"Falta a revisão",IF(J10="","Falta a aprovação",IF(O10="Em revisão","Em revisão",IF(N10<IF($D$5="",TODAY(),$D$5),"Revisão vencida","Vigente")))))))
B11: 3 | N11: =IF(OR(H11="",D11=""),"",EDATE(H11,IF(M11="",$D$6,M11))) | P11: =IF(D11="","",IF(C11="","Falta o código",IF(O11="Obsoleto","Obsoleto",IF(OR(G11="",H11=""),"Falta a revisão",IF(J11="","Falta a aprovação",IF(O11="Em revisão","Em revisão",IF(N11<IF($D$5="",TODAY(),$D$5),"Revisão vencida","Vigente")))))))
B12: 4 | N12: =IF(OR(H12="",D12=""),"",EDATE(H12,IF(M12="",$D$6,M12))) | P12: =IF(D12="","",IF(C12="","Falta o código",IF(O12="Obsoleto","Obsoleto",IF(OR(G12="",H12=""),"Falta a revisão",IF(J12="","Falta a aprovação",IF(O12="Em revisão","Em revisão",IF(N12<IF($D$5="",TODAY(),$D$5),"Revisão vencida","Vigente")))))))
B13: 5 | N13: =IF(OR(H13="",D13=""),"",EDATE(H13,IF(M13="",$D$6,M13))) | P13: =IF(D13="","",IF(C13="","Falta o código",IF(O13="Obsoleto","Obsoleto",IF(OR(G13="",H13=""),"Falta a revisão",IF(J13="","Falta a aprovação",IF(O13="Em revisão","Em revisão",IF(N13<IF($D$5="",TODAY(),$D$5),"Revisão vencida","Vigente")))))))
B14: 6 | N14: =IF(OR(H14="",D14=""),"",EDATE(H14,IF(M14="",$D$6,M14))) | P14: =IF(D14="","",IF(C14="","Falta o código",IF(O14="Obsoleto","Obsoleto",IF(OR(G14="",H14=""),"Falta a revisão",IF(J14="","Falta a aprovação",IF(O14="Em revisão","Em revisão",IF(N14<IF($D$5="",TODAY(),$D$5),"Revisão vencida","Vigente")))))))
B15: 7 | N15: =IF(OR(H15="",D15=""),"",EDATE(H15,IF(M15="",$D$6,M15))) | P15: =IF(D15="","",IF(C15="","Falta o código",IF(O15="Obsoleto","Obsoleto",IF(OR(G15="",H15=""),"Falta a revisão",IF(J15="","Falta a aprovação",IF(O15="Em revisão","Em revisão",IF(N15<IF($D$5="",TODAY(),$D$5),"Revisão vencida","Vigente")))))))
B16: 8 | N16: =IF(OR(H16="",D16=""),"",EDATE(H16,IF(M16="",$D$6,M16))) | P16: =IF(D16="","",IF(C16="","Falta o código",IF(O16="Obsoleto","Obsoleto",IF(OR(G16="",H16=""),"Falta a revisão",IF(J16="","Falta a aprovação",IF(O16="Em revisão","Em revisão",IF(N16<IF($D$5="",TODAY(),$D$5),"Revisão vencida","Vigente")))))))
B17: 9 | N17: =IF(OR(H17="",D17=""),"",EDATE(H17,IF(M17="",$D$6,M17))) | P17: =IF(D17="","",IF(C17="","Falta o código",IF(O17="Obsoleto","Obsoleto",IF(OR(G17="",H17=""),"Falta a revisão",IF(J17="","Falta a aprovação",IF(O17="Em revisão","Em revisão",IF(N17<IF($D$5="",TODAY(),$D$5),"Revisão vencida","Vigente")))))))
B18: 10 | N18: =IF(OR(H18="",D18=""),"",EDATE(H18,IF(M18="",$D$6,M18))) | P18: =IF(D18="","",IF(C18="","Falta o código",IF(O18="Obsoleto","Obsoleto",IF(OR(G18="",H18=""),"Falta a revisão",IF(J18="","Falta a aprovação",IF(O18="Em revisão","Em revisão",IF(N18<IF($D$5="",TODAY(),$D$5),"Revisão vencida","Vigente")))))))
B19: 11 | N19: =IF(OR(H19="",D19=""),"",EDATE(H19,IF(M19="",$D$6,M19))) | P19: =IF(D19="","",IF(C19="","Falta o código",IF(O19="Obsoleto","Obsoleto",IF(OR(G19="",H19=""),"Falta a revisão",IF(J19="","Falta a aprovação",IF(O19="Em revisão","Em revisão",IF(N19<IF($D$5="",TODAY(),$D$5),"Revisão vencida","Vigente")))))))
B20: 12 | N20: =IF(OR(H20="",D20=""),"",EDATE(H20,IF(M20="",$D$6,M20))) | P20: =IF(D20="","",IF(C20="","Falta o código",IF(O20="Obsoleto","Obsoleto",IF(OR(G20="",H20=""),"Falta a revisão",IF(J20="","Falta a aprovação",IF(O20="Em revisão","Em revisão",IF(N20<IF($D$5="",TODAY(),$D$5),"Revisão vencida","Vigente")))))))
... B38: 30 | N38: =IF(OR(H38="",D38=""),"",EDATE(H38,IF(M38="",$D$6,M38))) | P38: =IF(D38="","",IF(C38="","Falta o código",IF(O38="Obsoleto","Obsoleto",IF(OR(G38="",H38=""),"Falta a revisão",IF(J38="","Falta a aprovação",IF(O38="Em revisão","Em revisão",IF(N38<IF($D$5="",TODAY(),$D$5),"Revisão vencida","Vigente")))))))
B40: Resumo automático | H40: Documentos por situação
B41: Documentos cadastrados | E41: =COUNTA(D9:D38) -> 0 | H41: Vigente | L41: =COUNTIF(P9:P38,"Vigente") -> 0
B42: Em vigor, sem pendência | E42: =COUNTIF(P9:P38,"Vigente")+COUNTIF(P9:P38,"Em revisão") -> 0 | H42: Em revisão | L42: =COUNTIF(P9:P38,"Em revisão") -> 0
B43: Percentual em vigor, sem os obsoletos | E43: =IF(E41-COUNTIF(P9:P38,"Obsoleto")=0,"",E42/(E41-COUNTIF(P9:P38,"Obsoleto"))) | H43: Revisão vencida | L43: =COUNTIF(P9:P38,"Revisão vencida") -> 0
B44: Com revisão vencida | E44: =COUNTIF(P9:P38,"Revisão vencida") -> 0 | H44: Falta o código | L44: =COUNTIF(P9:P38,"Falta o código") -> 0
B45: Sem controle: falta código, revisão ou aprovação | E45: =COUNTIF(P9:P38,"Falta*") -> 0 | H45: Falta a revisão | L45: =COUNTIF(P9:P38,"Falta a revisão") -> 0
B46: Aviso | E46: =IF(E41=0,"Cadastre os documentos",IF(E45>0,"Há documento sem controle: veja a coluna Situação",IF(E44>0,"Há documento com a revisão vencida","OK"))) -> Cadastre os documentos | H46: Falta a aprovação | L46: =COUNTIF(P9:P38,"Falta a aprovação") -> 0
H47: Obsoleto | L47: =COUNTIF(P9:P38,"Obsoleto") -> 0

Sheet Registros
B1: Tabela de retenção de registros
B2: Um registro por linha: onde é gerado, onde fica guardado, por quanto tempo, quem pode ver e o que se faz no fim do prazo.
B4: # | C4: Registro | D4: Formulário ou origem | E4: Processo | F4: Gerado em | G4: Guardado em | H4: Meio | I4: Retenção (meses) | J4: Acesso | K4: Disposição no fim do prazo | L4: Conferência
C5: O que prova | D5: Código do formulário ou sistema | E5: Do mapa de processos | F5: Posto ou sistema | G5: Pasta, armário ou sistema | H5: Escolha na lista | I5: 12 = um ano | J5: Quem pode ver | K5: Descarte ou arquivo | L5: Calculada
B6: Ex. | C6: Planilha de temperatura da câmara fria | D6: FR-02 | E6: Comprar e armazenar insumos | F6: Câmara fria | G6: Pasta da cozinha | H6: Papel | I6: 12 | J6: Pizzaiolo líder | K6: Picotar | L6: Completa
B7: 1 | L7: =IF(C7="","",IF(G7="","Falta o local de guarda",IF(I7="","Falta o prazo de retenção",IF(H7="","Falta o meio",IF(K7="","Falta a disposição","Completa")))))
B8: 2 | L8: =IF(C8="","",IF(G8="","Falta o local de guarda",IF(I8="","Falta o prazo de retenção",IF(H8="","Falta o meio",IF(K8="","Falta a disposição","Completa")))))
B9: 3 | L9: =IF(C9="","",IF(G9="","Falta o local de guarda",IF(I9="","Falta o prazo de retenção",IF(H9="","Falta o meio",IF(K9="","Falta a disposição","Completa")))))
B10: 4 | L10: =IF(C10="","",IF(G10="","Falta o local de guarda",IF(I10="","Falta o prazo de retenção",IF(H10="","Falta o meio",IF(K10="","Falta a disposição","Completa")))))
B11: 5 | L11: =IF(C11="","",IF(G11="","Falta o local de guarda",IF(I11="","Falta o prazo de retenção",IF(H11="","Falta o meio",IF(K11="","Falta a disposição","Completa")))))
B12: 6 | L12: =IF(C12="","",IF(G12="","Falta o local de guarda",IF(I12="","Falta o prazo de retenção",IF(H12="","Falta o meio",IF(K12="","Falta a disposição","Completa")))))
B13: 7 | L13: =IF(C13="","",IF(G13="","Falta o local de guarda",IF(I13="","Falta o prazo de retenção",IF(H13="","Falta o meio",IF(K13="","Falta a disposição","Completa")))))
B14: 8 | L14: =IF(C14="","",IF(G14="","Falta o local de guarda",IF(I14="","Falta o prazo de retenção",IF(H14="","Falta o meio",IF(K14="","Falta a disposição","Completa")))))
B15: 9 | L15: =IF(C15="","",IF(G15="","Falta o local de guarda",IF(I15="","Falta o prazo de retenção",IF(H15="","Falta o meio",IF(K15="","Falta a disposição","Completa")))))
B16: 10 | L16: =IF(C16="","",IF(G16="","Falta o local de guarda",IF(I16="","Falta o prazo de retenção",IF(H16="","Falta o meio",IF(K16="","Falta a disposição","Completa")))))
B17: 11 | L17: =IF(C17="","",IF(G17="","Falta o local de guarda",IF(I17="","Falta o prazo de retenção",IF(H17="","Falta o meio",IF(K17="","Falta a disposição","Completa")))))
B18: 12 | L18: =IF(C18="","",IF(G18="","Falta o local de guarda",IF(I18="","Falta o prazo de retenção",IF(H18="","Falta o meio",IF(K18="","Falta a disposição","Completa")))))
... B26: 20 | L26: =IF(C26="","",IF(G26="","Falta o local de guarda",IF(I26="","Falta o prazo de retenção",IF(H26="","Falta o meio",IF(K26="","Falta a disposição","Completa")))))
B28: Resumo automático
B29: Registros cadastrados | E29: =COUNTA(C7:C26) -> 0
B30: Em papel, ou nos dois meios | E30: =COUNTIF(H7:H26,"Papel")+COUNTIF(H7:H26,"Ambos") -> 0
B31: Maior prazo de retenção, em meses | E31: =IF(COUNT(I7:I26)=0,"",MAX(I7:I26))
B32: Aviso | E32: =IF(E29=0,"Cadastre os registros",IF(COUNTIF(L7:L26,"Falta*")>0,"Há registro com campos em branco: veja a coluna Conferência","OK")) -> Cadastre os registros

Sheet Externos
B1: Documentos de origem externa
B2: Normas, leis, desenhos de cliente e manuais que a organização precisa seguir. A pergunta é: existe versão nova?
B4: # | C4: Documento | D4: Origem | E4: Versão em uso | F4: Onde se aplica | G4: Como se sabe da atualização | H4: Responsável | I4: Verificado em | J4: Verificar a cada (meses) | K4: Próxima verificação | L4: Situação
C5: Nome e assunto | D5: Quem publica | E5: Edição, revisão ou data | F5: Processos que usam | G5: Site, aviso, contrato | H5: Nome ou cargo | I5: Última conferência | J5: Em branco: padrão | K5: Calculada | L5: Calculada
B6: Ex. | C6: Desenhos e especificações do cliente | D6: Cada cliente | E6: Revisão informada no desenho | F6: Desenvolvimento e Produção | G6: O cliente envia a revisão nova | H6: Gerente de engenharia | I6: 46438 | J6: 3 | K6: 46527 | L6: Verificado
B7: 1 | K7: =IF(OR(I7="",C7=""),"",EDATE(I7,IF(J7="",'Lista mestra'!$D$6,J7))) | L7: =IF(C7="","",IF(I7="","Falta a verificação",IF(H7="","Falta o responsável",IF(K7<IF('Lista mestra'!$D$5="",TODAY(),'Lista mestra'!$D$5),"Verificação vencida","Verificado"))))
B8: 2 | K8: =IF(OR(I8="",C8=""),"",EDATE(I8,IF(J8="",'Lista mestra'!$D$6,J8))) | L8: =IF(C8="","",IF(I8="","Falta a verificação",IF(H8="","Falta o responsável",IF(K8<IF('Lista mestra'!$D$5="",TODAY(),'Lista mestra'!$D$5),"Verificação vencida","Verificado"))))
B9: 3 | K9: =IF(OR(I9="",C9=""),"",EDATE(I9,IF(J9="",'Lista mestra'!$D$6,J9))) | L9: =IF(C9="","",IF(I9="","Falta a verificação",IF(H9="","Falta o responsável",IF(K9<IF('Lista mestra'!$D$5="",TODAY(),'Lista mestra'!$D$5),"Verificação vencida","Verificado"))))
B10: 4 | K10: =IF(OR(I10="",C10=""),"",EDATE(I10,IF(J10="",'Lista mestra'!$D$6,J10))) | L10: =IF(C10="","",IF(I10="","Falta a verificação",IF(H10="","Falta o responsável",IF(K10<IF('Lista mestra'!$D$5="",TODAY(),'Lista mestra'!$D$5),"Verificação vencida","Verificado"))))
B11: 5 | K11: =IF(OR(I11="",C11=""),"",EDATE(I11,IF(J11="",'Lista mestra'!$D$6,J11))) | L11: =IF(C11="","",IF(I11="","Falta a verificação",IF(H11="","Falta o responsável",IF(K11<IF('Lista mestra'!$D$5="",TODAY(),'Lista mestra'!$D$5),"Verificação vencida","Verificado"))))
B12: 6 | K12: =IF(OR(I12="",C12=""),"",EDATE(I12,IF(J12="",'Lista mestra'!$D$6,J12))) | L12: =IF(C12="","",IF(I12="","Falta a verificação",IF(H12="","Falta o responsável",IF(K12<IF('Lista mestra'!$D$5="",TODAY(),'Lista mestra'!$D$5),"Verificação vencida","Verificado"))))
B13: 7 | K13: =IF(OR(I13="",C13=""),"",EDATE(I13,IF(J13="",'Lista mestra'!$D$6,J13))) | L13: =IF(C13="","",IF(I13="","Falta a verificação",IF(H13="","Falta o responsável",IF(K13<IF('Lista mestra'!$D$5="",TODAY(),'Lista mestra'!$D$5),"Verificação vencida","Verificado"))))
B14: 8 | K14: =IF(OR(I14="",C14=""),"",EDATE(I14,IF(J14="",'Lista mestra'!$D$6,J14))) | L14: =IF(C14="","",IF(I14="","Falta a verificação",IF(H14="","Falta o responsável",IF(K14<IF('Lista mestra'!$D$5="",TODAY(),'Lista mestra'!$D$5),"Verificação vencida","Verificado"))))
B15: 9 | K15: =IF(OR(I15="",C15=""),"",EDATE(I15,IF(J15="",'Lista mestra'!$D$6,J15))) | L15: =IF(C15="","",IF(I15="","Falta a verificação",IF(H15="","Falta o responsável",IF(K15<IF('Lista mestra'!$D$5="",TODAY(),'Lista mestra'!$D$5),"Verificação vencida","Verificado"))))
B16: 10 | K16: =IF(OR(I16="",C16=""),"",EDATE(I16,IF(J16="",'Lista mestra'!$D$6,J16))) | L16: =IF(C16="","",IF(I16="","Falta a verificação",IF(H16="","Falta o responsável",IF(K16<IF('Lista mestra'!$D$5="",TODAY(),'Lista mestra'!$D$5),"Verificação vencida","Verificado"))))
B17: 11 | K17: =IF(OR(I17="",C17=""),"",EDATE(I17,IF(J17="",'Lista mestra'!$D$6,J17))) | L17: =IF(C17="","",IF(I17="","Falta a verificação",IF(H17="","Falta o responsável",IF(K17<IF('Lista mestra'!$D$5="",TODAY(),'Lista mestra'!$D$5),"Verificação vencida","Verificado"))))
B18: 12 | K18: =IF(OR(I18="",C18=""),"",EDATE(I18,IF(J18="",'Lista mestra'!$D$6,J18))) | L18: =IF(C18="","",IF(I18="","Falta a verificação",IF(H18="","Falta o responsável",IF(K18<IF('Lista mestra'!$D$5="",TODAY(),'Lista mestra'!$D$5),"Verificação vencida","Verificado"))))
... B21: 15 | K21: =IF(OR(I21="",C21=""),"",EDATE(I21,IF(J21="",'Lista mestra'!$D$6,J21))) | L21: =IF(C21="","",IF(I21="","Falta a verificação",IF(H21="","Falta o responsável",IF(K21<IF('Lista mestra'!$D$5="",TODAY(),'Lista mestra'!$D$5),"Verificação vencida","Verificado"))))
B23: Resumo automático
B24: Documentos externos cadastrados | E24: =COUNTA(C7:C21) -> 0
B25: Verificados no prazo | E25: =COUNTIF(L7:L21,"Verificado") -> 0
B26: Com verificação vencida | E26: =COUNTIF(L7:L21,"Verificação vencida") -> 0
B27: Aviso | E27: =IF(E24=0,"Cadastre os documentos externos",IF(COUNTIF(L7:L21,"Falta*")>0,"Há documento externo com campos em branco: veja a coluna Situação",IF(E26>0,"Há documento com a verificação vencida","OK"))) -> Cadastre os documentos externos

Sheet Alterações
B1: Histórico de alterações
B2: Uma linha para cada revisão de documento: o que mudou, por quê, quem aprovou, e se os documentos ligados foram conferidos.
B4: # | C4: Data | D4: Código | E4: Revisão nova | F4: O que mudou | G4: Motivo | H4: Solicitou | I4: Aprovou | J4: Ligados conferidos? | K4: Conferência
C5: Da aprovação | D5: Da lista mestra | E5: Número ou data | F5: Em uma ou duas frases | G5: Ação corretiva, mudança, revisão periódica | H5: Nome ou cargo | I5: Nome ou cargo | J5: Escolha na lista | K5: Calculada
B6: Ex. | C6: 46311 | D6: PR-SUP-01 | E6: 6 | F6: Cadastro do item antes da compra, devolução da requisição incompleta e prazo contado da requisição completa. | G6: RNC 2026-31 | H6: Gerente de Suprimentos | I6: Diretor geral | J6: Sim | K6: Completa
B7: 1 | K7: =IF(D7="","",IF(COUNTIF('Lista mestra'!$C$9:$C$38,D7)=0,"Código fora da lista mestra",IF(E7="","Falta a revisão",IF(F7="","Falta a descrição",IF(I7="","Falta a aprovação",IF(J7="","Falta conferir os ligados",IF(J7="Não","Ligados não conferidos","Completa")))))))
B8: 2 | K8: =IF(D8="","",IF(COUNTIF('Lista mestra'!$C$9:$C$38,D8)=0,"Código fora da lista mestra",IF(E8="","Falta a revisão",IF(F8="","Falta a descrição",IF(I8="","Falta a aprovação",IF(J8="","Falta conferir os ligados",IF(J8="Não","Ligados não conferidos","Completa")))))))
B9: 3 | K9: =IF(D9="","",IF(COUNTIF('Lista mestra'!$C$9:$C$38,D9)=0,"Código fora da lista mestra",IF(E9="","Falta a revisão",IF(F9="","Falta a descrição",IF(I9="","Falta a aprovação",IF(J9="","Falta conferir os ligados",IF(J9="Não","Ligados não conferidos","Completa")))))))
B10: 4 | K10: =IF(D10="","",IF(COUNTIF('Lista mestra'!$C$9:$C$38,D10)=0,"Código fora da lista mestra",IF(E10="","Falta a revisão",IF(F10="","Falta a descrição",IF(I10="","Falta a aprovação",IF(J10="","Falta conferir os ligados",IF(J10="Não","Ligados não conferidos","Completa")))))))
B11: 5 | K11: =IF(D11="","",IF(COUNTIF('Lista mestra'!$C$9:$C$38,D11)=0,"Código fora da lista mestra",IF(E11="","Falta a revisão",IF(F11="","Falta a descrição",IF(I11="","Falta a aprovação",IF(J11="","Falta conferir os ligados",IF(J11="Não","Ligados não conferidos","Completa")))))))
B12: 6 | K12: =IF(D12="","",IF(COUNTIF('Lista mestra'!$C$9:$C$38,D12)=0,"Código fora da lista mestra",IF(E12="","Falta a revisão",IF(F12="","Falta a descrição",IF(I12="","Falta a aprovação",IF(J12="","Falta conferir os ligados",IF(J12="Não","Ligados não conferidos","Completa")))))))
B13: 7 | K13: =IF(D13="","",IF(COUNTIF('Lista mestra'!$C$9:$C$38,D13)=0,"Código fora da lista mestra",IF(E13="","Falta a revisão",IF(F13="","Falta a descrição",IF(I13="","Falta a aprovação",IF(J13="","Falta conferir os ligados",IF(J13="Não","Ligados não conferidos","Completa")))))))
B14: 8 | K14: =IF(D14="","",IF(COUNTIF('Lista mestra'!$C$9:$C$38,D14)=0,"Código fora da lista mestra",IF(E14="","Falta a revisão",IF(F14="","Falta a descrição",IF(I14="","Falta a aprovação",IF(J14="","Falta conferir os ligados",IF(J14="Não","Ligados não conferidos","Completa")))))))
B15: 9 | K15: =IF(D15="","",IF(COUNTIF('Lista mestra'!$C$9:$C$38,D15)=0,"Código fora da lista mestra",IF(E15="","Falta a revisão",IF(F15="","Falta a descrição",IF(I15="","Falta a aprovação",IF(J15="","Falta conferir os ligados",IF(J15="Não","Ligados não conferidos","Completa")))))))
B16: 10 | K16: =IF(D16="","",IF(COUNTIF('Lista mestra'!$C$9:$C$38,D16)=0,"Código fora da lista mestra",IF(E16="","Falta a revisão",IF(F16="","Falta a descrição",IF(I16="","Falta a aprovação",IF(J16="","Falta conferir os ligados",IF(J16="Não","Ligados não conferidos","Completa")))))))
B17: 11 | K17: =IF(D17="","",IF(COUNTIF('Lista mestra'!$C$9:$C$38,D17)=0,"Código fora da lista mestra",IF(E17="","Falta a revisão",IF(F17="","Falta a descrição",IF(I17="","Falta a aprovação",IF(J17="","Falta conferir os ligados",IF(J17="Não","Ligados não conferidos","Completa")))))))
B18: 12 | K18: =IF(D18="","",IF(COUNTIF('Lista mestra'!$C$9:$C$38,D18)=0,"Código fora da lista mestra",IF(E18="","Falta a revisão",IF(F18="","Falta a descrição",IF(I18="","Falta a aprovação",IF(J18="","Falta conferir os ligados",IF(J18="Não","Ligados não conferidos","Completa")))))))
... B26: 20 | K26: =IF(D26="","",IF(COUNTIF('Lista mestra'!$C$9:$C$38,D26)=0,"Código fora da lista mestra",IF(E26="","Falta a revisão",IF(F26="","Falta a descrição",IF(I26="","Falta a aprovação",IF(J26="","Falta conferir os ligados",IF(J26="Não","Ligados não conferidos","Completa")))))))
B28: Resumo automático
B29: Alterações registradas | F29: =COUNTA(D7:D26) -> 0
B30: Com os documentos ligados conferidos | F30: =COUNTIF(J7:J26,"Sim")+COUNTIF(J7:J26,"Não há") -> 0
B31: Aviso | F31: =IF(F29=0,"Registre as alterações",IF(COUNTIF(K7:K26,"Código fora*")>0,"Há alteração de documento que não está na lista mestra",IF(COUNTIF(K7:K26,"Falta*")>0,"Há alteração com o registro incompleto: veja a coluna Conferência",IF(COUNTIF(K7:K26,"Ligados não conferidos")>0,"Há alteração sem a conferência dos documentos ligados","OK")))) -> Registre as alterações

Sheet Checklist
B1: Checklist do controle de documentos
B2: Escolha o status de cada item na lista suspensa (coluna em amarelo-claro).
B4: # | C4: Item de verificação | D4: Status | E4: Observações
B5: 1 | C5: A lista mestra existe e traz todos os documentos em uso, com código, revisão e data.
B6: 2 | C6: Cada documento tem um responsável por elaborar e um por aprovar.
B7: 3 | C7: A revisão em uso no posto de trabalho é a mesma da lista mestra.
B8: 4 | C8: As versões antigas foram retiradas de circulação, ou estão marcadas como obsoletas.
B9: 5 | C9: Cada documento tem data de revisão prevista, ou é revisto quando o processo muda.
B10: 6 | C10: Quando um documento muda, os documentos ligados a ele são conferidos.
B11: 7 | C11: Os formulários em uso são a versão em vigor.
B12: 8 | C12: Cada registro tem prazo de retenção, local de guarda e forma de descarte definidos.
B13: 9 | C13: Os registros em papel estão legíveis e protegidos de perda e de alteração.
B14: 10 | C14: Os registros eletrônicos têm cópia de segurança e controle de acesso.
B15: 11 | C15: Os documentos de origem externa estão listados, com a data da última verificação.
B16: 12 | C16: A lista dos documentos e registros exigidos pela norma foi conferida.
B18: Resumo automático
B19: Itens atendidos (Sim) | D19: =COUNTIF(D5:D16,"Sim") -> 0
B20: Itens parciais | D20: =COUNTIF(D5:D16,"Parcial") -> 0
B21: Itens não atendidos | D21: =COUNTIF(D5:D16,"Não") -> 0
B22: Itens sem resposta | D22: =COUNTBLANK(D5:D16) -> 12
B23: Percentual atendido | D23: =D19/ROWS(D5:D16) -> 0
B24: Situação | D24: =IF(D19=ROWS(D5:D16),"Validado",IF(D22>0,"Em andamento","Com pendências")) -> Em andamento

Sheet Exemplo 1 - Pizzaria
B1: Informação documentada
B2: Exemplo preenchido, para consulta. Use as abas Lista mestra, Registros, Externos e Alterações para os seus documentos.
B4: Organização | D4: Pizzaria (loja com salão e delivery)
B5: Data de referência | D5: 46409
B6: Participantes | D6: Gerente da loja, com os líderes
B7: Regra de revisão | D7: Documentos revistos a cada 24 meses, ou quando o processo muda.
B8: Origem | D8: Decisão da análise crítica de 14/12/2026 e lacuna do requisito 7.5 no diagnóstico de 02/10/2026.
B10: Lista mestra
B11: Código | C11: Título | D11: Tipo | E11: Processo | F11: Revisão | G11: Data | H11: Elaborou | I11: Aprovou | J11: Meio | K11: Local | L11: Meses | M11: Próxima | N11: Status | O11: Situação
B12: IT-EXP-01 | C12: Expedição e agrupamento por zona | D12: IT | E12: Entregar o pedido | F12: 2 | G12: 46280 | H12: Líder da expedição | I12: Gerente da loja | J12: Papel | K12: Quadro da expedição | L12: 24 | M12: =IF(OR(G12="",C12=""),"",EDATE(G12,IF(L12="",24,L12))) -> 47011 | N12: Vigente | O12: =IF(C12="","",IF(B12="","Falta o código",IF(N12="Obsoleto","Obsoleto",IF(OR(F12="",G12=""),"Falta a revisão",IF(I12="","Falta a aprovação",IF(N12="Em revisão","Em revisão",IF(M12<$D$5,"Revisão vencida","Vigente"))))))) -> Vigente
B13: IT-ATE-01 | C13: Roteiro de atendimento por telefone e mensagens | D13: IT | E13: Registrar o pedido | F13: 2 | G13: 46303 | H13: Atendente líder | I13: Gerente da loja | J13: Papel | K13: Balcão | L13: 24 | M13: =IF(OR(G13="",C13=""),"",EDATE(G13,IF(L13="",24,L13))) -> 47034 | N13: Vigente | O13: =IF(C13="","",IF(B13="","Falta o código",IF(N13="Obsoleto","Obsoleto",IF(OR(F13="",G13=""),"Falta a revisão",IF(I13="","Falta a aprovação",IF(N13="Em revisão","Em revisão",IF(M13<$D$5,"Revisão vencida","Vigente"))))))) -> Vigente
C14: Escala padrão de entregadores | D14: IT | E14: Entregar o pedido | H14: Líder da expedição | J14: Papel | K14: Quadro da expedição | L14: 24 | M14: =IF(OR(G14="",C14=""),"",EDATE(G14,IF(L14="",24,L14))) | N14: Vigente | O14: =IF(C14="","",IF(B14="","Falta o código",IF(N14="Obsoleto","Obsoleto",IF(OR(F14="",G14=""),"Falta a revisão",IF(I14="","Falta a aprovação",IF(N14="Em revisão","Em revisão",IF(M14<$D$5,"Revisão vencida","Vigente"))))))) -> Falta o código
B15: IT-PRO-01 | C15: Rotina de controle de temperatura | D15: IT | E15: Comprar e armazenar insumos | F15: 1 | G15: 46295 | H15: Pizzaiolo líder | I15: Gerente da loja | J15: Papel | K15: Porta da câmara fria | L15: 24 | M15: =IF(OR(G15="",C15=""),"",EDATE(G15,IF(L15="",24,L15))) -> 47026 | N15: Vigente | O15: =IF(C15="","",IF(B15="","Falta o código",IF(N15="Obsoleto","Obsoleto",IF(OR(F15="",G15=""),"Falta a revisão",IF(I15="","Falta a aprovação",IF(N15="Em revisão","Em revisão",IF(M15<$D$5,"Revisão vencida","Vigente"))))))) -> Vigente
B16: FR-02 | C16: Planilha de temperatura | D16: FR | E16: Comprar e armazenar insumos | F16: 1 | G16: 46295 | H16: Pizzaiolo líder | I16: Gerente da loja | J16: Papel | K16: Porta da câmara fria | L16: 24 | M16: =IF(OR(G16="",C16=""),"",EDATE(G16,IF(L16="",24,L16))) -> 47026 | N16: Vigente | O16: =IF(C16="","",IF(B16="","Falta o código",IF(N16="Obsoleto","Obsoleto",IF(OR(F16="",G16=""),"Falta a revisão",IF(I16="","Falta a aprovação",IF(N16="Em revisão","Em revisão",IF(M16<$D$5,"Revisão vencida","Vigente"))))))) -> Vigente
B17: PR-GES-01 | C17: Rotina de documentos | D17: PR | E17: Medir e melhorar | F17: 3 | G17: 46309 | H17: Gerente da loja | I17: Dono da loja | J17: Eletrônico | K17: Pasta da gerência | L17: 24 | M17: =IF(OR(G17="",C17=""),"",EDATE(G17,IF(L17="",24,L17))) -> 47040 | N17: Vigente | O17: =IF(C17="","",IF(B17="","Falta o código",IF(N17="Obsoleto","Obsoleto",IF(OR(F17="",G17=""),"Falta a revisão",IF(I17="","Falta a aprovação",IF(N17="Em revisão","Em revisão",IF(M17<$D$5,"Revisão vencida","Vigente"))))))) -> Vigente
B18: FR-06 | C18: Registro de não conformidade | D18: FR | E18: Medir e melhorar | F18: 1 | G18: 46266 | H18: Gerente da loja | I18: Dono da loja | J18: Ambos | K18: Pasta da qualidade | L18: 24 | M18: =IF(OR(G18="",C18=""),"",EDATE(G18,IF(L18="",24,L18))) -> 46997 | N18: Vigente | O18: =IF(C18="","",IF(B18="","Falta o código",IF(N18="Obsoleto","Obsoleto",IF(OR(F18="",G18=""),"Falta a revisão",IF(I18="","Falta a aprovação",IF(N18="Em revisão","Em revisão",IF(M18<$D$5,"Revisão vencida","Vigente"))))))) -> Vigente
B19: FR-09 | C19: Relatório de auditoria interna | D19: FR | E19: Medir e melhorar | F19: 1 | G19: 46266 | H19: Gerente da loja | I19: Dono da loja | J19: Eletrônico | K19: Pasta da qualidade | L19: 24 | M19: =IF(OR(G19="",C19=""),"",EDATE(G19,IF(L19="",24,L19))) -> 46997 | N19: Vigente | O19: =IF(C19="","",IF(B19="","Falta o código",IF(N19="Obsoleto","Obsoleto",IF(OR(F19="",G19=""),"Falta a revisão",IF(I19="","Falta a aprovação",IF(N19="Em revisão","Em revisão",IF(M19<$D$5,"Revisão vencida","Vigente"))))))) -> Vigente
B20: FR-03 | C20: Ficha de alergênicos | D20: FR | E20: Produzir e embalar | F20: 1 | G20: 46311 | H20: Pizzaiolo líder | I20: Gerente da loja | J20: Ambos | K20: Sistema de pedidos | L20: 24 | M20: =IF(OR(G20="",C20=""),"",EDATE(G20,IF(L20="",24,L20))) -> 47042 | N20: Vigente | O20: =IF(C20="","",IF(B20="","Falta o código",IF(N20="Obsoleto","Obsoleto",IF(OR(F20="",G20=""),"Falta a revisão",IF(I20="","Falta a aprovação",IF(N20="Em revisão","Em revisão",IF(M20<$D$5,"Revisão vencida","Vigente"))))))) -> Vigente
C21: Receitas padrão | D21: IT | E21: Produzir e embalar | H21: Pizzaiolo líder | J21: Papel | K21: Caderno do pizzaiolo | L21: 24 | M21: =IF(OR(G21="",C21=""),"",EDATE(G21,IF(L21="",24,L21))) | N21: Vigente | O21: =IF(C21="","",IF(B21="","Falta o código",IF(N21="Obsoleto","Obsoleto",IF(OR(F21="",G21=""),"Falta a revisão",IF(I21="","Falta a aprovação",IF(N21="Em revisão","Em revisão",IF(M21<$D$5,"Revisão vencida","Vigente"))))))) -> Falta o código
C22: Cardápio | D22: ES | E22: Atender no salão | F22: 2026-2 | G22: 46204 | H22: Gerente da loja | I22: Dono da loja | J22: Ambos | K22: Mesas e site | L22: 12 | M22: =IF(OR(G22="",C22=""),"",EDATE(G22,IF(L22="",24,L22))) -> 46569 | N22: Vigente | O22: =IF(C22="","",IF(B22="","Falta o código",IF(N22="Obsoleto","Obsoleto",IF(OR(F22="",G22=""),"Falta a revisão",IF(I22="","Falta a aprovação",IF(N22="Em revisão","Em revisão",IF(M22<$D$5,"Revisão vencida","Vigente"))))))) -> Falta o código
B23: FR-04 | C23: Planilha de descarte de insumos | D23: FR | E23: Comprar e armazenar insumos | F23: 1 | G23: 46237 | H23: Gerente da loja | I23: Gerente da loja | J23: Eletrônico | K23: Planilha da gerência | L23: 24 | M23: =IF(OR(G23="",C23=""),"",EDATE(G23,IF(L23="",24,L23))) -> 46968 | N23: Vigente | O23: =IF(C23="","",IF(B23="","Falta o código",IF(N23="Obsoleto","Obsoleto",IF(OR(F23="",G23=""),"Falta a revisão",IF(I23="","Falta a aprovação",IF(N23="Em revisão","Em revisão",IF(M23<$D$5,"Revisão vencida","Vigente"))))))) -> Vigente
B24: FR-05 | C24: Ficha de treinamento | D24: FR | E24: Treinar a equipe | F24: 1 | G24: 46213 | H24: Gerente da loja | J24: Papel | K24: Pasta de pessoal | L24: 24 | M24: =IF(OR(G24="",C24=""),"",EDATE(G24,IF(L24="",24,L24))) -> 46944 | N24: Vigente | O24: =IF(C24="","",IF(B24="","Falta o código",IF(N24="Obsoleto","Obsoleto",IF(OR(F24="",G24=""),"Falta a revisão",IF(I24="","Falta a aprovação",IF(N24="Em revisão","Em revisão",IF(M24<$D$5,"Revisão vencida","Vigente"))))))) -> Falta a aprovação
B25: MP-01 | C25: Mapa de processos | D25: MP | E25: Planejar e dirigir a loja | F25: 1 | G25: 46309 | H25: Gerente da loja | I25: Dono da loja | J25: Eletrônico | K25: Pasta da gerência | L25: 12 | M25: =IF(OR(G25="",C25=""),"",EDATE(G25,IF(L25="",24,L25))) -> 46674 | N25: Vigente | O25: =IF(C25="","",IF(B25="","Falta o código",IF(N25="Obsoleto","Obsoleto",IF(OR(F25="",G25=""),"Falta a revisão",IF(I25="","Falta a aprovação",IF(N25="Em revisão","Em revisão",IF(M25<$D$5,"Revisão vencida","Vigente"))))))) -> Vigente
B26: MP-02 | C26: Matriz de riscos do delivery | D26: MP | E26: Planejar e dirigir a loja | F26: 1 | G26: 46300 | H26: Gerente da loja | I26: Dono da loja | J26: Eletrônico | K26: Pasta da gerência | L26: 6 | M26: =IF(OR(G26="",C26=""),"",EDATE(G26,IF(L26="",24,L26))) -> 46482 | N26: Vigente | O26: =IF(C26="","",IF(B26="","Falta o código",IF(N26="Obsoleto","Obsoleto",IF(OR(F26="",G26=""),"Falta a revisão",IF(I26="","Falta a aprovação",IF(N26="Em revisão","Em revisão",IF(M26<$D$5,"Revisão vencida","Vigente"))))))) -> Vigente
B27: FR-08 | C27: Ata da análise crítica | D27: FR | E27: Planejar e dirigir a loja | F27: 1 | G27: 46357 | H27: Gerente da loja | I27: Dono da loja | J27: Eletrônico | K27: Pasta da gerência | L27: 24 | M27: =IF(OR(G27="",C27=""),"",EDATE(G27,IF(L27="",24,L27))) -> 47088 | N27: Vigente | O27: =IF(C27="","",IF(B27="","Falta o código",IF(N27="Obsoleto","Obsoleto",IF(OR(F27="",G27=""),"Falta a revisão",IF(I27="","Falta a aprovação",IF(N27="Em revisão","Em revisão",IF(M27<$D$5,"Revisão vencida","Vigente"))))))) -> Vigente
B28: IT-CAI-01 | C28: Fechamento de caixa | D28: IT | E28: Atender no salão | F28: 1 | G28: 45728 | H28: Gerente da loja | I28: Dono da loja | J28: Papel | K28: Gaveta do caixa | L28: 24 | M28: =IF(OR(G28="",C28=""),"",EDATE(G28,IF(L28="",24,L28))) -> 46458 | N28: Obsoleto | O28: =IF(C28="","",IF(B28="","Falta o código",IF(N28="Obsoleto","Obsoleto",IF(OR(F28="",G28=""),"Falta a revisão",IF(I28="","Falta a aprovação",IF(N28="Em revisão","Em revisão",IF(M28<$D$5,"Revisão vencida","Vigente"))))))) -> Obsoleto
B30: Documentos por situação
B31: Vigente | E31: =COUNTIF(O12:O28,"Vigente") -> 12
B32: Em revisão | E32: =COUNTIF(O12:O28,"Em revisão") -> 0
B33: Revisão vencida | E33: =COUNTIF(O12:O28,"Revisão vencida") -> 0
B34: Falta o código | E34: =COUNTIF(O12:O28,"Falta o código") -> 3
B35: Falta a revisão | E35: =COUNTIF(O12:O28,"Falta a revisão") -> 0
B36: Falta a aprovação | E36: =COUNTIF(O12:O28,"Falta a aprovação") -> 1
B37: Obsoleto | E37: =COUNTIF(O12:O28,"Obsoleto") -> 1
B38: Em vigor, sem os obsoletos | E38: =(E31+E32)/(SUM(E31:E37)-E37) -> 0.75
B41: Tabela de retenção de registros
B42: Registro | D42: Formulário ou origem | F42: Processo | H42: Gerado em | I42: Guardado em | J42: Meio | K42: Acesso | L42: Retenção (meses) | N42: Disposição
B43: Pedido registrado | D43: Sistema de pedidos | F43: Registrar o pedido | H43: Balcão e site | I43: Sistema, na nuvem | J43: Eletrônico | K43: Gerente e atendentes | L43: 24 | N43: Exclusão pelo sistema
B44: Planilha de temperatura | D44: FR-02 | F44: Comprar e armazenar insumos | H44: Câmara fria | I44: Pasta da cozinha | J44: Papel | K44: Pizzaiolo líder | L44: 12 | N44: Picotar
B45: Etiqueta de conferência do pedido | D45: Etiqueta do sistema | F45: Produzir e embalar | H45: Bancada de embalagem | I45: Caixa da expedição | J45: Papel | K45: Líder da expedição | L45: 1 | N45: Descartar após 30 dias
...

Sheet Exemplo 2 - Compras
B1: Informação documentada
B2: Exemplo preenchido, para consulta. Use as abas Lista mestra, Registros, Externos e Alterações para os seus documentos.
B4: Organização | D4: Indústria de embalagens plásticas · Suprimentos
B5: Data de referência | D5: 46451
B6: Participantes | D6: Gerente de Suprimentos, com o Coordenador da Qualidade
B7: Regra de revisão | D7: Documentos revistos a cada 24 meses. Formulários e listas, a cada 12; a lista de fornecedores homologados, a cada 6, com a avaliação semestral. Registros retidos por 3 anos; os de compra, por 5, pelo prazo fiscal; os contratos, por 10.
B8: Origem | D8: Preparação da auditoria de certificação, decidida na análise crítica de 18/02/2027.
B10: Lista mestra
B11: Código | C11: Título | D11: Tipo | E11: Processo | F11: Revisão | G11: Data | H11: Elaborou | I11: Aprovou | J11: Meio | K11: Local | L11: Meses | M11: Próxima | N11: Status | O11: Situação
B12: PR-SUP-01 | C12: Aquisição de materiais e serviços | D12: PR | E12: Suprimentos | F12: 6 | G12: 46311 | H12: Gerente de Suprimentos | I12: Diretor geral | J12: Eletrônico | K12: Rede, pasta Qualidade | L12: 24 | M12: =IF(OR(G12="",C12=""),"",EDATE(G12,IF(L12="",24,L12))) -> 47042 | N12: Vigente | O12: =IF(C12="","",IF(B12="","Falta o código",IF(N12="Obsoleto","Obsoleto",IF(OR(F12="",G12=""),"Falta a revisão",IF(I12="","Falta a aprovação",IF(N12="Em revisão","Em revisão",IF(M12<$D$5,"Revisão vencida","Vigente"))))))) -> Vigente
B13: PO-02 | C13: Política de compras e alçadas | D13: PO | E13: Suprimentos | F13: 3 | G13: 45981 | H13: Diretor geral | I13: Diretor geral | J13: Eletrônico | K13: Rede, pasta Qualidade | L13: 24 | M13: =IF(OR(G13="",C13=""),"",EDATE(G13,IF(L13="",24,L13))) -> 46711 | N13: Vigente | O13: =IF(C13="","",IF(B13="","Falta o código",IF(N13="Obsoleto","Obsoleto",IF(OR(F13="",G13=""),"Falta a revisão",IF(I13="","Falta a aprovação",IF(N13="Em revisão","Em revisão",IF(M13<$D$5,"Revisão vencida","Vigente"))))))) -> Vigente
B14: PR-SUP-02 | C14: Homologação e avaliação de fornecedores | D14: PR | E14: Suprimentos | F14: 2 | G14: 46353 | H14: Comprador sênior | I14: Gerente de Suprimentos | J14: Eletrônico | K14: Rede, pasta Qualidade | L14: 24 | M14: =IF(OR(G14="",C14=""),"",EDATE(G14,IF(L14="",24,L14))) -> 47084 | N14: Vigente | O14: =IF(C14="","",IF(B14="","Falta o código",IF(N14="Obsoleto","Obsoleto",IF(OR(F14="",G14=""),"Falta a revisão",IF(I14="","Falta a aprovação",IF(N14="Em revisão","Em revisão",IF(M14<$D$5,"Revisão vencida","Vigente"))))))) -> Vigente
B15: PR-SUP-03 | C15: Compras de urgência | D15: PR | E15: Suprimentos | F15: 1 | G15: 45755 | H15: Gerente de Suprimentos | I15: Diretor geral | J15: Eletrônico | K15: Rede, pasta Qualidade | L15: 24 | M15: =IF(OR(G15="",C15=""),"",EDATE(G15,IF(L15="",24,L15))) -> 46485 | N15: Em revisão | O15: =IF(C15="","",IF(B15="","Falta o código",IF(N15="Obsoleto","Obsoleto",IF(OR(F15="",G15=""),"Falta a revisão",IF(I15="","Falta a aprovação",IF(N15="Em revisão","Em revisão",IF(M15<$D$5,"Revisão vencida","Vigente"))))))) -> Em revisão
B16: IT-REC-01 | C16: Recebimento e conferência de materiais | D16: IT | E16: Recebimento | F16: 1 | G16: 45705 | H16: Líder do Recebimento | I16: Gerente de Suprimentos | J16: Papel | K16: Quadro do almoxarifado | L16: 24 | M16: =IF(OR(G16="",C16=""),"",EDATE(G16,IF(L16="",24,L16))) -> 46435 | N16: Vigente | O16: =IF(C16="","",IF(B16="","Falta o código",IF(N16="Obsoleto","Obsoleto",IF(OR(F16="",G16=""),"Falta a revisão",IF(I16="","Falta a aprovação",IF(N16="Em revisão","Em revisão",IF(M16<$D$5,"Revisão vencida","Vigente"))))))) -> Revisão vencida
B17: FR-11 | C17: Requisição de compra | D17: FR | E17: Suprimentos | F17: 4 | G17: 46309 | H17: Analista de sistemas | I17: Gerente de Suprimentos | J17: Eletrônico | K17: Sistema de compras | L17: 12 | M17: =IF(OR(G17="",C17=""),"",EDATE(G17,IF(L17="",24,L17))) -> 46674 | N17: Vigente | O17: =IF(C17="","",IF(B17="","Falta o código",IF(N17="Obsoleto","Obsoleto",IF(OR(F17="",G17=""),"Falta a revisão",IF(I17="","Falta a aprovação",IF(N17="Em revisão","Em revisão",IF(M17<$D$5,"Revisão vencida","Vigente"))))))) -> Vigente
B18: FR-12 | C18: Avaliação de desempenho de fornecedor | D18: FR | E18: Suprimentos | F18: 2 | G18: 46353 | H18: Comprador sênior | I18: Gerente de Suprimentos | J18: Eletrônico | K18: Rede, pasta Suprimentos | L18: 12 | M18: =IF(OR(G18="",C18=""),"",EDATE(G18,IF(L18="",24,L18))) -> 46718 | N18: Vigente | O18: =IF(C18="","",IF(B18="","Falta o código",IF(N18="Obsoleto","Obsoleto",IF(OR(F18="",G18=""),"Falta a revisão",IF(I18="","Falta a aprovação",IF(N18="Em revisão","Em revisão",IF(M18<$D$5,"Revisão vencida","Vigente"))))))) -> Vigente
B19: FR-13 | C19: Registro de devolução ao fornecedor | D19: FR | E19: Recebimento | F19: 1 | G19: 45705 | H19: Líder do Recebimento | I19: Gerente de Suprimentos | J19: Papel | K19: Almoxarifado | L19: 12 | M19: =IF(OR(G19="",C19=""),"",EDATE(G19,IF(L19="",24,L19))) -> 46070 | N19: Vigente | O19: =IF(C19="","",IF(B19="","Falta o código",IF(N19="Obsoleto","Obsoleto",IF(OR(F19="",G19=""),"Falta a revisão",IF(I19="","Falta a aprovação",IF(N19="Em revisão","Em revisão",IF(M19<$D$5,"Revisão vencida","Vigente"))))))) -> Revisão vencida
B20: LS-01 | C20: Lista de fornecedores homologados | D20: FR | E20: Suprimentos | F20: 2027-02 | G20: 46444 | H20: Comprador sênior | I20: Gerente de Suprimentos | J20: Eletrônico | K20: Rede, pasta Suprimentos | L20: 6 | M20: =IF(OR(G20="",C20=""),"",EDATE(G20,IF(L20="",24,L20))) -> 46625 | N20: Vigente | O20: =IF(C20="","",IF(B20="","Falta o código",IF(N20="Obsoleto","Obsoleto",IF(OR(F20="",G20=""),"Falta a revisão",IF(I20="","Falta a aprovação",IF(N20="Em revisão","Em revisão",IF(M20<$D$5,"Revisão vencida","Vigente"))))))) -> Vigente
C21: Cadastro de itens com especificação padrão | D21: FR | E21: Suprimentos | G21: 46318 | H21: Supervisor de manutenção | J21: Eletrônico | K21: Sistema de compras | L21: 12 | M21: =IF(OR(G21="",C21=""),"",EDATE(G21,IF(L21="",24,L21))) -> 46683 | N21: Vigente | O21: =IF(C21="","",IF(B21="","Falta o código",IF(N21="Obsoleto","Obsoleto",IF(OR(F21="",G21=""),"Falta a revisão",IF(I21="","Falta a aprovação",IF(N21="Em revisão","Em revisão",IF(M21<$D$5,"Revisão vencida","Vigente"))))))) -> Falta o código
B23: Documentos por situação
B24: Vigente | E24: =COUNTIF(O12:O21,"Vigente") -> 6
B25: Em revisão | E25: =COUNTIF(O12:O21,"Em revisão") -> 1
B26: Revisão vencida | E26: =COUNTIF(O12:O21,"Revisão vencida") -> 2
B27: Falta o código | E27: =COUNTIF(O12:O21,"Falta o código") -> 1
B28: Falta a revisão | E28: =COUNTIF(O12:O21,"Falta a revisão") -> 0
B29: Falta a aprovação | E29: =COUNTIF(O12:O21,"Falta a aprovação") -> 0
B30: Obsoleto | E30: =COUNTIF(O12:O21,"Obsoleto") -> 0
B31: Em vigor, sem os obsoletos | E31: =(E24+E25)/(SUM(E24:E30)-E30) -> 0.7
B34: Tabela de retenção de registros
B35: Registro | D35: Formulário ou origem | F35: Processo | H35: Gerado em | I35: Guardado em | J35: Meio | K35: Acesso | L35: Retenção (meses) | N35: Disposição
B36: Requisição de compra aprovada | D36: FR-11 | F36: Suprimentos | H36: Sistema de compras | I36: Sistema de compras | J36: Eletrônico | K36: Compradores e requisitantes | L36: 60 | N36: Arquivo morto do sistema
B37: Cotações e mapa comparativo | D37: Planilha de cotação | F37: Suprimentos | H37: Comprador | I37: Rede, pasta do pedido | J37: Eletrônico | K37: Compradores | L37: 60 | N37: Exclusão
B38: Pedido de compra emitido | D38: Sistema de compras | F38: Suprimentos | H38: Sistema de compras | I38: Sistema de compras | J38: Eletrônico | K38: Compradores e Fiscal | L38: 60 | N38: Arquivo morto do sistema
B39: Registro de recebimento e conferência | D39: FR-14 | F39: Recebimento | H39: Almoxarifado | I39: Pasta do almoxarifado e sistema | J39: Ambos | K39: Recebimento e Qualidade | L39: 36 | N39: Picotar
B40: Avaliação de desempenho de fornecedor | D40: FR-12 | F40: Suprimentos | H40: Comprador sênior | I40: Rede, pasta Suprimentos | J40: Eletrônico | K40: Suprimentos e Qualidade | L40: 60 | N40: Exclusão
B41: Dossiê de homologação | D41: PR-SUP-02, anexo A | F41: Suprimentos | H41: Comprador sênior | I41: Rede, pasta Fornecedores | J41: Eletrônico | K41: Suprimentos e Qualidade | L41: 60 | N41: Exclusão após o descredenciamento
B42: Registro de devolução | D42: FR-13 | F42: Recebimento | H42: Almoxarifado | I42: Pasta do almoxarifado | J42: Papel | K42: Recebimento | L42: 36 | N42: Picotar
B43: Contrato com fornecedor | D43: Modelo jurídico | F43: Suprimentos | H43: Gerente de Suprimentos | I43: Cofre da diretoria | J43: Papel | K43: Diretoria e Jurídico | L43: 120 | N43: Picotar após o fim do contrato
B45: Resumo automático
B46: Documentos cadastrados | E46: =COUNTA(C12:C21) -> 10
...
