Workbook

Sheet Instruções
B1: Mapa de processos e tartaruga — Como usar esta planilha
B2: Modelo para listar os processos, descrever as ligações, detalhar um processo e avaliar os oito elementos.
B4: Legenda: onde preencher
B5: Amarelo-claro | C5: Células de entrada. É aqui que você digita.
B6: Cinza | C6: Células calculadas ou fixas (rótulos, nomes, contagens, avisos). Não altere.
B7: Cinza em itálico | C7: Linha de exemplo (marcada com “Ex.”). Mostra o formato esperado e não entra nas contagens.
B8: Listas suspensas | C8: Colunas de tipo e de avaliação aceitam apenas as opções da lista.
B9: Comentários | C9: Células com triângulo vermelho no canto trazem uma dica de preenchimento. Passe o mouse sobre elas.
B11: Os três tipos de processo
B12: Gestão | C12: Define o rumo, os objetivos e os recursos, e confere os resultados.
B13: Principal | C13: Transforma o pedido do cliente em produto ou serviço entregue.
B14: Apoio | C14: Fornece os recursos de que os outros processos precisam.
B16: Ordem recomendada de preenchimento
B17: Passo 1 | C17: Aba Processos: liste os processos, começando pelos principais, com tipo, dono e objetivo.
B18: Passo 2 | C18: Aba Processos: escreva as principais entradas e saídas, o cliente e o indicador de cada processo.
B19: Passo 3 | C19: Aba Interações: escreva, na linha de cada processo, o que ele entrega aos processos das colunas.
B20: Passo 4 | C20: Aba Elementos: avalie os oito elementos de cada processo.
B21: Passo 5 | C21: Aba Tartaruga: informe o número de um processo e preencha as sete partes.
B22: Passo 6 | C22: Aba Tartaruga: confira se as entradas e as saídas aparecem na aba Interações.
B23: Passo 7 | C23: Aba Checklist: valide o mapa com quem executa os processos.
B25: Abas da planilha
B26: Processos | C26: Lista de até 12 processos, com conferência dos campos e contagem por tipo.
B27: Interações | C27: Matriz com o que cada processo entrega aos outros, e situação de cada processo.
B28: Tartaruga | C28: As sete partes de um processo, com conferência de cada parte.
B29: Elementos | C29: Avaliação dos oito elementos de cada processo, com percentual e gráfico.
B30: Checklist | C30: Doze verificações de qualidade do mapa, com percentual de conclusão.
B31: Exemplo 1 - Pizzaria | C31: Lista de processos, avaliação dos elementos e tartaruga do processo de entrega.
B32: Exemplo 2 - Compras | C32: Tartaruga do processo de aquisição e interações com os outros processos.
B34: Regras e premissas do modelo
B35: Número do processo | C35: As abas Interações, Tartaruga e Elementos usam o número da linha da aba Processos. Não troque a ordem dos processos depois de preencher as outras abas.
B36: Interações | C36: A matriz mostra as ligações entre processos. O primeiro processo principal recebe do cliente, e o último entrega ao cliente: nos dois casos, a situação aparece em amarelo, e não é um erro.
B37: Elementos | C37: São os oito itens do requisito 4.4.1 da ISO 9001:2015, resumidos com palavras próprias. “Sim” vale 1 ponto, e “Parcial”, meio. A pontuação é uma convenção deste modelo.
B38: Uma tartaruga por vez | C38: A aba Tartaruga serve a um processo. Para o processo seguinte, duplique a aba ou salve uma cópia do arquivo.
B39: Três tipos | C39: A divisão em gestão, principais e apoio é a mais usada. A norma não a exige.
B40: Exemplos | C40: Os dados das abas de exemplo são ilustrativos, criados para este material.

Sheet Processos
B1: Lista de processos
B2: Um processo por linha. Use verbo no infinitivo no nome: registrar o pedido, produzir, entregar.
B4: Organização | G4: Data
B5: O que o cliente pede | G5: O que o cliente recebe
B7: # | C7: Processo | D7: Tipo | E7: Dono | F7: Objetivo | G7: Principais entradas | H7: Principais saídas | I7: Cliente do processo | J7: Indicador | K7: Conferência
C8: Verbo no infinitivo | D8: Escolha na lista | E8: Quem responde pelo resultado | F8: O que o processo deve entregar | G8: O que recebe | H8: O que entrega | I8: Quem recebe a saída | J8: Como o resultado é medido | K8: Campos da linha
B9: Ex. | C9: Entregar o pedido | D9: Principal | E9: Líder da expedição | F9: Entregar o pedido certo, quente e no prazo. | G9: Pedido embalado e endereço completo | H9: Pedido entregue e horário de chegada | I9: Cliente | J9: Entregas em até 40 minutos | K9: Completo
B10: 1 | K10: =IF(C10="","",IF(D10="","Falta o tipo",IF(E10="","Falta o dono",IF(F10="","Falta o objetivo",IF(OR(G10="",H10=""),"Faltam entradas ou saídas",IF(I10="","Falta o cliente do processo",IF(J10="","Falta o indicador","Completo")))))))
B11: 2 | K11: =IF(C11="","",IF(D11="","Falta o tipo",IF(E11="","Falta o dono",IF(F11="","Falta o objetivo",IF(OR(G11="",H11=""),"Faltam entradas ou saídas",IF(I11="","Falta o cliente do processo",IF(J11="","Falta o indicador","Completo")))))))
B12: 3 | K12: =IF(C12="","",IF(D12="","Falta o tipo",IF(E12="","Falta o dono",IF(F12="","Falta o objetivo",IF(OR(G12="",H12=""),"Faltam entradas ou saídas",IF(I12="","Falta o cliente do processo",IF(J12="","Falta o indicador","Completo")))))))
B13: 4 | K13: =IF(C13="","",IF(D13="","Falta o tipo",IF(E13="","Falta o dono",IF(F13="","Falta o objetivo",IF(OR(G13="",H13=""),"Faltam entradas ou saídas",IF(I13="","Falta o cliente do processo",IF(J13="","Falta o indicador","Completo")))))))
B14: 5 | K14: =IF(C14="","",IF(D14="","Falta o tipo",IF(E14="","Falta o dono",IF(F14="","Falta o objetivo",IF(OR(G14="",H14=""),"Faltam entradas ou saídas",IF(I14="","Falta o cliente do processo",IF(J14="","Falta o indicador","Completo")))))))
B15: 6 | K15: =IF(C15="","",IF(D15="","Falta o tipo",IF(E15="","Falta o dono",IF(F15="","Falta o objetivo",IF(OR(G15="",H15=""),"Faltam entradas ou saídas",IF(I15="","Falta o cliente do processo",IF(J15="","Falta o indicador","Completo")))))))
B16: 7 | K16: =IF(C16="","",IF(D16="","Falta o tipo",IF(E16="","Falta o dono",IF(F16="","Falta o objetivo",IF(OR(G16="",H16=""),"Faltam entradas ou saídas",IF(I16="","Falta o cliente do processo",IF(J16="","Falta o indicador","Completo")))))))
B17: 8 | K17: =IF(C17="","",IF(D17="","Falta o tipo",IF(E17="","Falta o dono",IF(F17="","Falta o objetivo",IF(OR(G17="",H17=""),"Faltam entradas ou saídas",IF(I17="","Falta o cliente do processo",IF(J17="","Falta o indicador","Completo")))))))
B18: 9 | K18: =IF(C18="","",IF(D18="","Falta o tipo",IF(E18="","Falta o dono",IF(F18="","Falta o objetivo",IF(OR(G18="",H18=""),"Faltam entradas ou saídas",IF(I18="","Falta o cliente do processo",IF(J18="","Falta o indicador","Completo")))))))
B19: 10 | K19: =IF(C19="","",IF(D19="","Falta o tipo",IF(E19="","Falta o dono",IF(F19="","Falta o objetivo",IF(OR(G19="",H19=""),"Faltam entradas ou saídas",IF(I19="","Falta o cliente do processo",IF(J19="","Falta o indicador","Completo")))))))
B20: 11 | K20: =IF(C20="","",IF(D20="","Falta o tipo",IF(E20="","Falta o dono",IF(F20="","Falta o objetivo",IF(OR(G20="",H20=""),"Faltam entradas ou saídas",IF(I20="","Falta o cliente do processo",IF(J20="","Falta o indicador","Completo")))))))
B21: 12 | K21: =IF(C21="","",IF(D21="","Falta o tipo",IF(E21="","Falta o dono",IF(F21="","Falta o objetivo",IF(OR(G21="",H21=""),"Faltam entradas ou saídas",IF(I21="","Falta o cliente do processo",IF(J21="","Falta o indicador","Completo")))))))
B23: Resumo automático
B24: Processos cadastrados | E24: =COUNTA(C10:C21) -> 0
B25: De gestão | E25: =COUNTIF(D10:D21,"Gestão") -> 0
B26: Principais | E26: =COUNTIF(D10:D21,"Principal") -> 0
B27: De apoio | E27: =COUNTIF(D10:D21,"Apoio") -> 0
B28: Sem indicador | E28: =SUMPRODUCT((C10:C21<>"")*(J10:J21="")) -> 0
B29: Aviso | E29: =IF(E24=0,"Cadastre os processos",IF(E26=0,"Não há processo principal",IF(OR(E25=0,E27=0),"Falta processo de gestão ou de apoio",IF(COUNTIF(K10:K21,"Falta*")>0,"Há processo com o cadastro incompleto: veja a coluna Conferência","OK")))) -> Cadastre os processos

Sheet Interações
B1: Matriz de interações
B2: Na linha de cada processo, escreva o que ele entrega ao processo de cada coluna. Deixe em branco quando não houver entrega.
B4: # | C4: Quem entrega | D4: Quem recebe | P4: Entrega a | Q4: Recebe de | R4: Situação
C5: Os nomes vêm da aba Processos | D5: =1&IF(Processos!C10="",""," · "&Processos!C10) -> 1 | E5: =2&IF(Processos!C11="",""," · "&Processos!C11) -> 2 | F5: =3&IF(Processos!C12="",""," · "&Processos!C12) -> 3 | G5: =4&IF(Processos!C13="",""," · "&Processos!C13) -> 4 | H5: =5&IF(Processos!C14="",""," · "&Processos!C14) -> 5 | I5: =6&IF(Processos!C15="",""," · "&Processos!C15) -> 6 | J5: =7&IF(Processos!C16="",""," · "&Processos!C16) -> 7 | K5: =8&IF(Processos!C17="",""," · "&Processos!C17) -> 8 | L5: =9&IF(Processos!C18="",""," · "&Processos!C18) -> 9 | M5: =10&IF(Processos!C19="",""," · "&Processos!C19) -> 10 | N5: =11&IF(Processos!C20="",""," · "&Processos!C20) -> 11 | O5: =12&IF(Processos!C21="",""," · "&Processos!C21) -> 12 | P5: Processos | Q5: Processos | R5: Calculada
B6: 1 | C6: =IF(Processos!C10="","",Processos!C10) | P6: =IF(C6="","",COUNTA(D6:O6)) | Q6: =IF(C6="","",COUNTA(INDEX($D$6:$O$17,0,1))) | R6: =IF(C6="","",IF(AND(P6=0,Q6=0),"Sem ligação",IF(P6=0,"Não entrega a outro processo",IF(Q6=0,"Não recebe de outro processo","Ligado"))))
B7: 2 | C7: =IF(Processos!C11="","",Processos!C11) | P7: =IF(C7="","",COUNTA(D7:O7)) | Q7: =IF(C7="","",COUNTA(INDEX($D$6:$O$17,0,2))) | R7: =IF(C7="","",IF(AND(P7=0,Q7=0),"Sem ligação",IF(P7=0,"Não entrega a outro processo",IF(Q7=0,"Não recebe de outro processo","Ligado"))))
B8: 3 | C8: =IF(Processos!C12="","",Processos!C12) | P8: =IF(C8="","",COUNTA(D8:O8)) | Q8: =IF(C8="","",COUNTA(INDEX($D$6:$O$17,0,3))) | R8: =IF(C8="","",IF(AND(P8=0,Q8=0),"Sem ligação",IF(P8=0,"Não entrega a outro processo",IF(Q8=0,"Não recebe de outro processo","Ligado"))))
B9: 4 | C9: =IF(Processos!C13="","",Processos!C13) | P9: =IF(C9="","",COUNTA(D9:O9)) | Q9: =IF(C9="","",COUNTA(INDEX($D$6:$O$17,0,4))) | R9: =IF(C9="","",IF(AND(P9=0,Q9=0),"Sem ligação",IF(P9=0,"Não entrega a outro processo",IF(Q9=0,"Não recebe de outro processo","Ligado"))))
B10: 5 | C10: =IF(Processos!C14="","",Processos!C14) | P10: =IF(C10="","",COUNTA(D10:O10)) | Q10: =IF(C10="","",COUNTA(INDEX($D$6:$O$17,0,5))) | R10: =IF(C10="","",IF(AND(P10=0,Q10=0),"Sem ligação",IF(P10=0,"Não entrega a outro processo",IF(Q10=0,"Não recebe de outro processo","Ligado"))))
B11: 6 | C11: =IF(Processos!C15="","",Processos!C15) | P11: =IF(C11="","",COUNTA(D11:O11)) | Q11: =IF(C11="","",COUNTA(INDEX($D$6:$O$17,0,6))) | R11: =IF(C11="","",IF(AND(P11=0,Q11=0),"Sem ligação",IF(P11=0,"Não entrega a outro processo",IF(Q11=0,"Não recebe de outro processo","Ligado"))))
B12: 7 | C12: =IF(Processos!C16="","",Processos!C16) | P12: =IF(C12="","",COUNTA(D12:O12)) | Q12: =IF(C12="","",COUNTA(INDEX($D$6:$O$17,0,7))) | R12: =IF(C12="","",IF(AND(P12=0,Q12=0),"Sem ligação",IF(P12=0,"Não entrega a outro processo",IF(Q12=0,"Não recebe de outro processo","Ligado"))))
B13: 8 | C13: =IF(Processos!C17="","",Processos!C17) | P13: =IF(C13="","",COUNTA(D13:O13)) | Q13: =IF(C13="","",COUNTA(INDEX($D$6:$O$17,0,8))) | R13: =IF(C13="","",IF(AND(P13=0,Q13=0),"Sem ligação",IF(P13=0,"Não entrega a outro processo",IF(Q13=0,"Não recebe de outro processo","Ligado"))))
B14: 9 | C14: =IF(Processos!C18="","",Processos!C18) | P14: =IF(C14="","",COUNTA(D14:O14)) | Q14: =IF(C14="","",COUNTA(INDEX($D$6:$O$17,0,9))) | R14: =IF(C14="","",IF(AND(P14=0,Q14=0),"Sem ligação",IF(P14=0,"Não entrega a outro processo",IF(Q14=0,"Não recebe de outro processo","Ligado"))))
B15: 10 | C15: =IF(Processos!C19="","",Processos!C19) | P15: =IF(C15="","",COUNTA(D15:O15)) | Q15: =IF(C15="","",COUNTA(INDEX($D$6:$O$17,0,10))) | R15: =IF(C15="","",IF(AND(P15=0,Q15=0),"Sem ligação",IF(P15=0,"Não entrega a outro processo",IF(Q15=0,"Não recebe de outro processo","Ligado"))))
B16: 11 | C16: =IF(Processos!C20="","",Processos!C20) | P16: =IF(C16="","",COUNTA(D16:O16)) | Q16: =IF(C16="","",COUNTA(INDEX($D$6:$O$17,0,11))) | R16: =IF(C16="","",IF(AND(P16=0,Q16=0),"Sem ligação",IF(P16=0,"Não entrega a outro processo",IF(Q16=0,"Não recebe de outro processo","Ligado"))))
B17: 12 | C17: =IF(Processos!C21="","",Processos!C21) | P17: =IF(C17="","",COUNTA(D17:O17)) | Q17: =IF(C17="","",COUNTA(INDEX($D$6:$O$17,0,12))) | R17: =IF(C17="","",IF(AND(P17=0,Q17=0),"Sem ligação",IF(P17=0,"Não entrega a outro processo",IF(Q17=0,"Não recebe de outro processo","Ligado"))))
B19: Resumo automático
B20: Ligações registradas | D20: =COUNTA(D6:O17) -> 0
B21: Processos ligados | D21: =COUNTIF(R6:R17,"Ligado") -> 0
B22: Processos sem ligação | D22: =COUNTIF(R6:R17,"Sem ligação") -> 0
B23: Processos que só entregam ou só recebem | D23: =COUNTIF(R6:R17,"Não*") -> 0
B24: Aviso | D24: =IF(COUNTA(Processos!C10:C21)=0,"Cadastre os processos na aba Processos",IF(D20=0,"Registre as ligações",IF((IF(Processos!C10="",COUNTA(D6:O6)+COUNTA(D6:D17),0)+IF(Processos!C11="",COUNTA(D7:O7)+COUNTA(E6:E17),0)+IF(Processos!C12="",COUNTA(D8:O8)+COUNTA(F6:F17),0)+IF(Processos!C13="",COUNTA(D9:O9)+COUNTA(G6:G17),0)+IF(Processos!C14="",COUNTA(D10:O10)+COUNTA(H6:H17),0)+IF(Processos!C15="",COUNTA(D11:O11)+COUNTA(I6:I17),0)+IF(Processos!C16="",COUNTA(D12:O12)+COUNTA(J6:J17),0)+IF(Processos!C17="",COUNTA(D13:O13)+COUNTA(K6:K17),0)+IF(Processos!C18="",COUNTA(D14:O14)+COUNTA(L6:L17),0)+IF(Processos!C19="",COUNTA(D15:O15)+COUNTA(M6:M17),0)+IF(Processos!C20="",COUNTA(D16:O16)+COUNTA(N6:N17),0)+IF(Processos!C21="",COUNTA(D17:O17)+COUNTA(O6:O17),0))>0,"Há ligação com processo sem cadastro",IF(D22>0,"Há processo sem ligação: confira o mapa","OK")))) -> Cadastre os processos na aba Processos

Sheet Tartaruga
B1: Diagrama de tartaruga
B2: Informe o número do processo e preencha as sete partes. Escreva o que existe hoje, e marque o que falta.
B4: Processo nº, de 1 a 12 | F4: Data
B5: Processo | D5: =IF($D$4="","",IF(INDEX(Processos!$C$10:$C$21,$D$4)="","Processo sem cadastro",INDEX(Processos!$C$10:$C$21,$D$4)))
B6: Tipo e dono | D6: =IF($D$4="","",IF(INDEX(Processos!$C$10:$C$21,$D$4)="","",INDEX(Processos!$D$10:$D$21,$D$4)&" · "&INDEX(Processos!$E$10:$E$21,$D$4)))
B7: Objetivo | D7: =IF($D$4="","",IF(INDEX(Processos!$C$10:$C$21,$D$4)="","",INDEX(Processos!$F$10:$F$21,$D$4)&""))
B9: Entradas · O que entra? | F9: Saídas · O que sai?
B10: # | C10: Entrada | D10: De onde vem | F10: # | G10: Saída | H10: Para onde vai
B11: 1 | F11: 1
B12: 2 | F12: 2
B13: 3 | F13: 3
B14: 4 | F14: 4
B16: Recursos · Com o quê? | F16: Pessoas · Com quem?
B17: # | C17: Recurso | D17: Condição ou quantidade | F17: # | G17: Função | H17: Competência necessária
B18: 1 | F18: 1
B19: 2 | F19: 2
B20: 3 | F20: 3
B21: 4 | F21: 4
B23: Métodos · Como? | F23: Indicadores · Quanto?
B24: # | C24: Documento ou método | D24: Código, revisão ou assunto | F24: # | G24: Indicador | H24: Meta
B25: 1 | F25: 1
B26: 2 | F26: 2
B27: 3 | F27: 3
B28: 4 | F28: 4
B30: Riscos · E se? | F30: Conferência automática
B31: # | C31: Risco | D31: Resposta | F31: Entradas | H31: =IF(COUNTA(C11:C14)=0,"Falta preencher",IF(COUNTA(D11:D14)<COUNTA(C11:C14),"Falta o detalhe","Completa")) -> Falta preencher
B32: 1 | F32: Saídas | H32: =IF(COUNTA(G11:G14)=0,"Falta preencher",IF(COUNTA(H11:H14)<COUNTA(G11:G14),"Falta o detalhe","Completa")) -> Falta preencher
B33: 2 | F33: Recursos | H33: =IF(COUNTA(C18:C21)=0,"Falta preencher",IF(COUNTA(D18:D21)<COUNTA(C18:C21),"Falta o detalhe","Completa")) -> Falta preencher
B34: 3 | F34: Pessoas | H34: =IF(COUNTA(G18:G21)=0,"Falta preencher",IF(COUNTA(H18:H21)<COUNTA(G18:G21),"Falta o detalhe","Completa")) -> Falta preencher
B35: 4 | F35: Métodos | H35: =IF(COUNTA(C25:C28)=0,"Falta preencher",IF(COUNTA(D25:D28)<COUNTA(C25:C28),"Falta o detalhe","Completa")) -> Falta preencher
F36: Indicadores | H36: =IF(COUNTA(G25:G28)=0,"Falta preencher",IF(COUNTA(H25:H28)<COUNTA(G25:G28),"Falta o detalhe","Completa")) -> Falta preencher
F37: Riscos | H37: =IF(COUNTA(C32:C35)=0,"Falta preencher",IF(COUNTA(D32:D35)<COUNTA(C32:C35),"Falta o detalhe","Completa")) -> Falta preencher
F38: Situação | H38: =IF($D$4="","Informe o processo",IF(D5="Processo sem cadastro","Processo sem cadastro",IF(COUNTIF(H31:H37,"Completa")=7,"Tartaruga completa","Há partes incompletas"))) -> Informe o processo

Sheet Elementos
B1: Os oito elementos de cada processo
B2: Avalie cada elemento com Sim, Parcial ou Não. Os nomes dos processos vêm da aba Processos.
B4: # | C4: Processo | D4: a · Entradas e saídas | E4: b · Sequência e interação | F4: c · Critérios e indicadores | G4: d · Recursos | H4: e · Responsabilidades | I4: f · Riscos e oportunidades | J4: g · Avaliação e mudanças | K4: h · Melhoria | L4: Pontos | M4: Percentual | N4: Conferência
B5: 1 | C5: =IF(Processos!C10="","",Processos!C10) | L5: =IF(COUNTA(D5:K5)=0,"",COUNTIF(D5:K5,"Sim")+0.5*COUNTIF(D5:K5,"Parcial")) | M5: =IF(L5="","",L5/8) | N5: =IF(AND(C5="",COUNTA(D5:K5)=0),"",IF(C5="","Processo sem cadastro",IF(COUNTA(D5:K5)=0,"Não avaliado",IF(COUNTA(D5:K5)<8,"Avaliação incompleta","Completa"))))
B6: 2 | C6: =IF(Processos!C11="","",Processos!C11) | L6: =IF(COUNTA(D6:K6)=0,"",COUNTIF(D6:K6,"Sim")+0.5*COUNTIF(D6:K6,"Parcial")) | M6: =IF(L6="","",L6/8) | N6: =IF(AND(C6="",COUNTA(D6:K6)=0),"",IF(C6="","Processo sem cadastro",IF(COUNTA(D6:K6)=0,"Não avaliado",IF(COUNTA(D6:K6)<8,"Avaliação incompleta","Completa"))))
B7: 3 | C7: =IF(Processos!C12="","",Processos!C12) | L7: =IF(COUNTA(D7:K7)=0,"",COUNTIF(D7:K7,"Sim")+0.5*COUNTIF(D7:K7,"Parcial")) | M7: =IF(L7="","",L7/8) | N7: =IF(AND(C7="",COUNTA(D7:K7)=0),"",IF(C7="","Processo sem cadastro",IF(COUNTA(D7:K7)=0,"Não avaliado",IF(COUNTA(D7:K7)<8,"Avaliação incompleta","Completa"))))
B8: 4 | C8: =IF(Processos!C13="","",Processos!C13) | L8: =IF(COUNTA(D8:K8)=0,"",COUNTIF(D8:K8,"Sim")+0.5*COUNTIF(D8:K8,"Parcial")) | M8: =IF(L8="","",L8/8) | N8: =IF(AND(C8="",COUNTA(D8:K8)=0),"",IF(C8="","Processo sem cadastro",IF(COUNTA(D8:K8)=0,"Não avaliado",IF(COUNTA(D8:K8)<8,"Avaliação incompleta","Completa"))))
B9: 5 | C9: =IF(Processos!C14="","",Processos!C14) | L9: =IF(COUNTA(D9:K9)=0,"",COUNTIF(D9:K9,"Sim")+0.5*COUNTIF(D9:K9,"Parcial")) | M9: =IF(L9="","",L9/8) | N9: =IF(AND(C9="",COUNTA(D9:K9)=0),"",IF(C9="","Processo sem cadastro",IF(COUNTA(D9:K9)=0,"Não avaliado",IF(COUNTA(D9:K9)<8,"Avaliação incompleta","Completa"))))
B10: 6 | C10: =IF(Processos!C15="","",Processos!C15) | L10: =IF(COUNTA(D10:K10)=0,"",COUNTIF(D10:K10,"Sim")+0.5*COUNTIF(D10:K10,"Parcial")) | M10: =IF(L10="","",L10/8) | N10: =IF(AND(C10="",COUNTA(D10:K10)=0),"",IF(C10="","Processo sem cadastro",IF(COUNTA(D10:K10)=0,"Não avaliado",IF(COUNTA(D10:K10)<8,"Avaliação incompleta","Completa"))))
B11: 7 | C11: =IF(Processos!C16="","",Processos!C16) | L11: =IF(COUNTA(D11:K11)=0,"",COUNTIF(D11:K11,"Sim")+0.5*COUNTIF(D11:K11,"Parcial")) | M11: =IF(L11="","",L11/8) | N11: =IF(AND(C11="",COUNTA(D11:K11)=0),"",IF(C11="","Processo sem cadastro",IF(COUNTA(D11:K11)=0,"Não avaliado",IF(COUNTA(D11:K11)<8,"Avaliação incompleta","Completa"))))
B12: 8 | C12: =IF(Processos!C17="","",Processos!C17) | L12: =IF(COUNTA(D12:K12)=0,"",COUNTIF(D12:K12,"Sim")+0.5*COUNTIF(D12:K12,"Parcial")) | M12: =IF(L12="","",L12/8) | N12: =IF(AND(C12="",COUNTA(D12:K12)=0),"",IF(C12="","Processo sem cadastro",IF(COUNTA(D12:K12)=0,"Não avaliado",IF(COUNTA(D12:K12)<8,"Avaliação incompleta","Completa"))))
B13: 9 | C13: =IF(Processos!C18="","",Processos!C18) | L13: =IF(COUNTA(D13:K13)=0,"",COUNTIF(D13:K13,"Sim")+0.5*COUNTIF(D13:K13,"Parcial")) | M13: =IF(L13="","",L13/8) | N13: =IF(AND(C13="",COUNTA(D13:K13)=0),"",IF(C13="","Processo sem cadastro",IF(COUNTA(D13:K13)=0,"Não avaliado",IF(COUNTA(D13:K13)<8,"Avaliação incompleta","Completa"))))
B14: 10 | C14: =IF(Processos!C19="","",Processos!C19) | L14: =IF(COUNTA(D14:K14)=0,"",COUNTIF(D14:K14,"Sim")+0.5*COUNTIF(D14:K14,"Parcial")) | M14: =IF(L14="","",L14/8) | N14: =IF(AND(C14="",COUNTA(D14:K14)=0),"",IF(C14="","Processo sem cadastro",IF(COUNTA(D14:K14)=0,"Não avaliado",IF(COUNTA(D14:K14)<8,"Avaliação incompleta","Completa"))))
B15: 11 | C15: =IF(Processos!C20="","",Processos!C20) | L15: =IF(COUNTA(D15:K15)=0,"",COUNTIF(D15:K15,"Sim")+0.5*COUNTIF(D15:K15,"Parcial")) | M15: =IF(L15="","",L15/8) | N15: =IF(AND(C15="",COUNTA(D15:K15)=0),"",IF(C15="","Processo sem cadastro",IF(COUNTA(D15:K15)=0,"Não avaliado",IF(COUNTA(D15:K15)<8,"Avaliação incompleta","Completa"))))
B16: 12 | C16: =IF(Processos!C21="","",Processos!C21) | L16: =IF(COUNTA(D16:K16)=0,"",COUNTIF(D16:K16,"Sim")+0.5*COUNTIF(D16:K16,"Parcial")) | M16: =IF(L16="","",L16/8) | N16: =IF(AND(C16="",COUNTA(D16:K16)=0),"",IF(C16="","Processo sem cadastro",IF(COUNTA(D16:K16)=0,"Não avaliado",IF(COUNTA(D16:K16)<8,"Avaliação incompleta","Completa"))))
B17: Sim | D17: =COUNTIF(D5:D16,"Sim") -> 0 | E17: =COUNTIF(E5:E16,"Sim") -> 0 | F17: =COUNTIF(F5:F16,"Sim") -> 0 | G17: =COUNTIF(G5:G16,"Sim") -> 0 | H17: =COUNTIF(H5:H16,"Sim") -> 0 | I17: =COUNTIF(I5:I16,"Sim") -> 0 | J17: =COUNTIF(J5:J16,"Sim") -> 0 | K17: =COUNTIF(K5:K16,"Sim") -> 0
B18: Parcial | D18: =COUNTIF(D5:D16,"Parcial") -> 0 | E18: =COUNTIF(E5:E16,"Parcial") -> 0 | F18: =COUNTIF(F5:F16,"Parcial") -> 0 | G18: =COUNTIF(G5:G16,"Parcial") -> 0 | H18: =COUNTIF(H5:H16,"Parcial") -> 0 | I18: =COUNTIF(I5:I16,"Parcial") -> 0 | J18: =COUNTIF(J5:J16,"Parcial") -> 0 | K18: =COUNTIF(K5:K16,"Parcial") -> 0
B19: Não | D19: =COUNTIF(D5:D16,"Não") -> 0 | E19: =COUNTIF(E5:E16,"Não") -> 0 | F19: =COUNTIF(F5:F16,"Não") -> 0 | G19: =COUNTIF(G5:G16,"Não") -> 0 | H19: =COUNTIF(H5:H16,"Não") -> 0 | I19: =COUNTIF(I5:I16,"Não") -> 0 | J19: =COUNTIF(J5:J16,"Não") -> 0 | K19: =COUNTIF(K5:K16,"Não") -> 0
B20: Percentual do elemento | D20: =IF(COUNTA(D5:D16)=0,"",(D17+0.5*D18)/COUNTA(D5:D16)) | E20: =IF(COUNTA(E5:E16)=0,"",(E17+0.5*E18)/COUNTA(E5:E16)) | F20: =IF(COUNTA(F5:F16)=0,"",(F17+0.5*F18)/COUNTA(F5:F16)) | G20: =IF(COUNTA(G5:G16)=0,"",(G17+0.5*G18)/COUNTA(G5:G16)) | H20: =IF(COUNTA(H5:H16)=0,"",(H17+0.5*H18)/COUNTA(H5:H16)) | I20: =IF(COUNTA(I5:I16)=0,"",(I17+0.5*I18)/COUNTA(I5:I16)) | J20: =IF(COUNTA(J5:J16)=0,"",(J17+0.5*J18)/COUNTA(J5:J16)) | K20: =IF(COUNTA(K5:K16)=0,"",(K17+0.5*K18)/COUNTA(K5:K16))
B22: Resumo automático
B23: Processos avaliados | D23: =COUNT(L5:L16) -> 0
B24: Média dos processos | D24: =IF(D23=0,"",AVERAGE(M5:M16))
B25: Processo com o menor percentual | D25: =IF(D23=0,"",INDEX(C5:C16,MATCH(MIN(M5:M16),M5:M16,0)))
B26: Elemento com o menor percentual | D26: =IF(D23=0,"",INDEX(D4:K4,MATCH(MIN(D20:K20),D20:K20,0)))
B27: Aviso | D27: =IF(D23=0,"Avalie os elementos",IF(COUNTIF(N5:N16,"Processo sem cadastro")>0,"Há avaliação de processo sem cadastro",IF(COUNTIF(N5:N16,"Avaliação incompleta")>0,"Há processo com a avaliação incompleta",IF(COUNTIF(N5:N16,"Não avaliado")>0,"Há processo sem avaliação","OK")))) -> Avalie os elementos

Sheet Checklist
B1: Checklist de validação do mapa
B2: Escolha o status de cada item na lista suspensa (coluna em amarelo-claro).
B4: # | C4: Item de verificação | D4: Status | E4: Observações
B5: 1 | C5: O mapa mostra todos os processos necessários para atender ao cliente.
B6: 2 | C6: Os processos principais estão em sequência, do pedido à entrega.
B7: 3 | C7: Os processos de gestão e de apoio estão identificados.
B8: 4 | C8: Cada processo tem um dono, que responde pelo resultado.
B9: 5 | C9: As entradas e as saídas de cada processo estão definidas.
B10: 6 | C10: As interações estão descritas: o que um processo entrega ao outro.
B11: 7 | C11: Os recursos e as competências de cada processo estão definidos.
B12: 8 | C12: Os métodos e os documentos de cada processo estão identificados.
B13: 9 | C13: Cada processo tem pelo menos um indicador, com meta.
B14: 10 | C14: Os riscos e as oportunidades de cada processo foram avaliados.
B15: 11 | C15: O mapa foi validado por quem executa os processos.
B16: 12 | C16: O mapa é revisto a cada mudança e pelo menos uma vez por ano.
B18: Resumo automático
B19: Itens atendidos (Sim) | D19: =COUNTIF(D5:D16,"Sim") -> 0
B20: Itens parciais | D20: =COUNTIF(D5:D16,"Parcial") -> 0
B21: Itens não atendidos | D21: =COUNTIF(D5:D16,"Não") -> 0
B22: Itens sem resposta | D22: =COUNTBLANK(D5:D16) -> 12
B23: Percentual atendido | D23: =D19/ROWS(D5:D16) -> 0
B24: Situação | D24: =IF(D19=ROWS(D5:D16),"Validado",IF(D22>0,"Em andamento","Com pendências")) -> Em andamento

Sheet Exemplo 1 - Pizzaria
B1: Mapa de processos e diagrama de tartaruga
B2: Exemplo preenchido, para consulta. Use as abas Processos, Interações, Tartaruga e Elementos para o seu mapa.
B4: Organização | D4: Pizzaria (loja com salão e delivery)
B5: Data e participantes | D5: 14/10/2026. Gerente da loja, com os líderes dos dois turnos.
B6: Origem | D6: Lacuna do requisito 4.4 no diagnóstico de 02/10/2026: só o delivery estava mapeado.
B7: O cliente | D7: Entrada: cliente com fome. Resultado: cliente atendido.
B9: Processos | H9: Os oito elementos de cada processo
B10: Nº | C10: Processo | D10: Tipo | E10: Dono | F10: Objetivo | G10: Indicador | H10: a · Entradas e saídas | I10: b · Sequência e interação | J10: c · Critérios e indicadores | K10: d · Recursos | L10: e · Responsabilidades | M10: f · Riscos e oportunidades | N10: g · Avaliação e mudanças | O10: h · Melhoria | P10: Pontos | Q10: Percentual
B11: G1 | C11: Planejar e dirigir a loja | D11: Gestão | E11: Dono da loja | F11: Definir objetivos, recursos e prioridades. | G11: Objetivos alcançados no ano | H11: Sim | I11: Parcial | J11: Não | K11: Sim | L11: Sim | M11: Parcial | N11: Parcial | O11: Parcial | P11: =IF(COUNTA(H11:O11)=0,"",COUNTIF(H11:O11,"Sim")+0.5*COUNTIF(H11:O11,"Parcial")) -> 5 | Q11: =P11/8 -> 0.625
B12: G2 | C12: Medir e melhorar | D12: Gestão | E12: Gerente da loja | F12: Acompanhar os resultados e tratar os desvios. | G12: Indicadores na meta | H12: Sim | I12: Sim | J12: Sim | K12: Sim | L12: Sim | M12: Parcial | N12: Parcial | O12: Sim | P12: =IF(COUNTA(H12:O12)=0,"",COUNTIF(H12:O12,"Sim")+0.5*COUNTIF(H12:O12,"Parcial")) -> 7 | Q12: =P12/8 -> 0.875
B13: P1 | C13: Registrar o pedido | D13: Principal | E13: Atendente líder | F13: Registrar o pedido certo, com endereço completo. | G13: Pedidos refeitos por erro | H13: Sim | I13: Sim | J13: Parcial | K13: Sim | L13: Sim | M13: Sim | N13: Parcial | O13: Parcial | P13: =IF(COUNTA(H13:O13)=0,"",COUNTIF(H13:O13,"Sim")+0.5*COUNTIF(H13:O13,"Parcial")) -> 6.5 | Q13: =P13/8 -> 0.8125
B14: P2 | C14: Produzir e embalar | D14: Principal | E14: Pizzaiolo líder | F14: Produzir a pizza pedida, no padrão da receita. | G14: Desperdício de insumos | H14: Sim | I14: Sim | J14: Sim | K14: Sim | L14: Sim | M14: Parcial | N14: Sim | O14: Parcial | P14: =IF(COUNTA(H14:O14)=0,"",COUNTIF(H14:O14,"Sim")+0.5*COUNTIF(H14:O14,"Parcial")) -> 7 | Q14: =P14/8 -> 0.875
B15: P3 | C15: Entregar o pedido | D15: Principal | E15: Líder da expedição | F15: Entregar o pedido certo, quente e no prazo. | G15: Entregas em até 40 minutos | H15: Sim | I15: Sim | J15: Sim | K15: Sim | L15: Sim | M15: Sim | N15: Sim | O15: Sim | P15: =IF(COUNTA(H15:O15)=0,"",COUNTIF(H15:O15,"Sim")+0.5*COUNTIF(H15:O15,"Parcial")) -> 8 | Q15: =P15/8 -> 1
B16: P4 | C16: Atender no salão | D16: Principal | E16: Gerente da loja | F16: Servir o cliente da mesa no tempo prometido. | G16: Sem indicador | H16: Parcial | I16: Não | J16: Não | K16: Sim | L16: Sim | M16: Não | N16: Não | O16: Não | P16: =IF(COUNTA(H16:O16)=0,"",COUNTIF(H16:O16,"Sim")+0.5*COUNTIF(H16:O16,"Parcial")) -> 2.5 | Q16: =P16/8 -> 0.3125
B17: A1 | C17: Comprar e armazenar insumos | D17: Apoio | E17: Gerente da loja | F17: Ter os insumos certos, dentro da validade. | G17: Sem indicador | H17: Sim | I17: Parcial | J17: Não | K17: Sim | L17: Sim | M17: Parcial | N17: Não | O17: Não | P17: =IF(COUNTA(H17:O17)=0,"",COUNTIF(H17:O17,"Sim")+0.5*COUNTIF(H17:O17,"Parcial")) -> 4 | Q17: =P17/8 -> 0.5
B18: A2 | C18: Manter equipamentos e motos | D18: Apoio | E18: Pizzaiolo líder | F18: Manter forno, câmara fria e motos disponíveis. | G18: Sem indicador | H18: Parcial | I18: Parcial | J18: Não | K18: Sim | L18: Sim | M18: Parcial | N18: Não | O18: Não | P18: =IF(COUNTA(H18:O18)=0,"",COUNTIF(H18:O18,"Sim")+0.5*COUNTIF(H18:O18,"Parcial")) -> 3.5 | Q18: =P18/8 -> 0.4375
B19: A3 | C19: Treinar a equipe | D19: Apoio | E19: Gerente da loja | F19: Ter pessoas treinadas em todas as funções. | G19: Sem indicador | H19: Parcial | I19: Parcial | J19: Não | K19: Parcial | L19: Sim | M19: Não | N19: Não | O19: Não | P19: =IF(COUNTA(H19:O19)=0,"",COUNTIF(H19:O19,"Sim")+0.5*COUNTIF(H19:O19,"Parcial")) -> 2.5 | Q19: =P19/8 -> 0.3125
B20: Percentual do elemento | H20: =(COUNTIF(H11:H19,"Sim")+0.5*COUNTIF(H11:H19,"Parcial"))/ROWS(H11:H19) -> 0.83333333 | I20: =(COUNTIF(I11:I19,"Sim")+0.5*COUNTIF(I11:I19,"Parcial"))/ROWS(I11:I19) -> 0.66666667 | J20: =(COUNTIF(J11:J19,"Sim")+0.5*COUNTIF(J11:J19,"Parcial"))/ROWS(J11:J19) -> 0.38888889 | K20: =(COUNTIF(K11:K19,"Sim")+0.5*COUNTIF(K11:K19,"Parcial"))/ROWS(K11:K19) -> 0.94444444 | L20: =(COUNTIF(L11:L19,"Sim")+0.5*COUNTIF(L11:L19,"Parcial"))/ROWS(L11:L19) -> 1 | M20: =(COUNTIF(M11:M19,"Sim")+0.5*COUNTIF(M11:M19,"Parcial"))/ROWS(M11:M19) -> 0.5 | N20: =(COUNTIF(N11:N19,"Sim")+0.5*COUNTIF(N11:N19,"Parcial"))/ROWS(N11:N19) -> 0.38888889 | O20: =(COUNTIF(O11:O19,"Sim")+0.5*COUNTIF(O11:O19,"Parcial"))/ROWS(O11:O19) -> 0.38888889 | Q20: =AVERAGE(Q11:Q19) -> 0.63888889
B22: Resumo automático | H22: Elementos definidos em cada processo
B23: Processos | E23: =COUNTA(C11:C19) -> 9
B24: De gestão, principais e de apoio | E24: =COUNTIF(D11:D19,"Gestão")&", "&COUNTIF(D11:D19,"Principal")&" e "&COUNTIF(D11:D19,"Apoio") -> 2, 4 e 3
B25: Processos sem indicador | E25: =COUNTIF(G11:G19,"Sem indicador") -> 4
B26: Média dos elementos definidos | E26: =Q20 -> 0.63888889
B27: Processo com o menor percentual | E27: =INDEX(C11:C19,MATCH(MIN(Q11:Q19),Q11:Q19,0)) -> Atender no salão
B28: Elemento com o menor percentual | E28: =INDEX(H10:O10,MATCH(MIN(H20:O20),H20:O20,0)) -> c · Critérios e indicadores
B41: Tartaruga do processo P3 · Entregar o pedido · dono: Líder da expedição
B42: Parte | D42: Item | G42: De onde vem, para onde vai, condição, meta ou resposta
B43: Entradas · O que entra? | D43: Pedido embalado e conferido | G43: Produzir e embalar
B44: Entradas · O que entra? | D44: Endereço completo do cliente | G44: Registrar o pedido
B45: Entradas · O que entra? | D45: Escala de entregadores do turno | G45: Planejar e dirigir a loja
B46: Saídas · O que sai? | D46: Pedido entregue ao cliente | G46: Cliente
B47: Saídas · O que sai? | D47: Horário de saída e de chegada | G47: Medir e melhorar
B48: Saídas · O que sai? | D48: Reclamações e devoluções | G48: Medir e melhorar
B49: Recursos · Com o quê? | D49: Motos revisadas | G49: Revisão mensal
B50: Recursos · Com o quê? | D50: Bolsas térmicas | G50: Uma por entregador
B51: Recursos · Com o quê? | D51: Sistema de pedidos e celular | G51: Com internet móvel
B52: Pessoas · Com quem? | D52: Líder da expedição | G52: Conhece a instrução e a escala
B53: Pessoas · Com quem? | D53: Entregadores | G53: Habilitação e direção segura
... B61: Riscos · E se? | D61: Acidente com o entregador | G61: Compartilhar: seguro

Sheet Exemplo 2 - Compras
B1: Diagrama de tartaruga
B2: Exemplo preenchido, para consulta. Use as abas Tartaruga e Interações para o seu processo.
B4: Organização | D4: Indústria de embalagens plásticas
B5: Processo | D5: 3 · Adquirir materiais e serviços
B6: Tipo e dono | D6: Apoio · Gerente de Suprimentos
B7: Objetivo | D7: Fornecer os materiais certos, no prazo, sem parar a produção.
B8: Data e participantes | D8: 20/10/2026. Gerente de Suprimentos, com compradores e Recebimento.
B9: Origem | D9: Preparação da auditoria de acompanhamento do processo de aquisição.
B11: As sete partes da tartaruga
B12: Parte | D12: Item | G12: De onde vem, para onde vai, condição, meta ou resposta
B13: Entradas · O que entra? | D13: Requisição aprovada, com especificação | G13: Produção e Manutenção
B14: Entradas · O que entra? | D14: Plano de produção do mês | G14: Produção
B15: Entradas · O que entra? | D15: Especificação de materiais | G15: Desenvolvimento de produto
B16: Entradas · O que entra? | D16: Resultado da inspeção de recebimento | G16: Laboratório e controle da qualidade
B17: Entradas · O que entra? | D17: Resultados de auditoria e ações | G17: Gestão do sistema da qualidade
B18: Saídas · O que sai? | D18: Pedido de compra emitido | G18: Fornecedor
B19: Saídas · O que sai? | D19: Material recebido e conferido | G19: Produção e Manutenção
B20: Saídas · O que sai? | D20: Avaliação dos fornecedores | G20: Gestão do sistema da qualidade
B21: Recursos · Com o quê? | D21: Sistema de compras | G21: Campo de especificação obrigatório
B22: Recursos · Com o quê? | D22: Cadastro de itens e de fornecedores | G22: Com especificação padrão
B23: Recursos · Com o quê? | D23: Área de recebimento e balança | G23: Balança verificada
... B36: Riscos · E se? | D36: Compra de fornecedor não homologado | G36: Evitar: bloqueio no sistema
B38: Interações do processo 3 com os outros processos
B39: Sentido | D39: Processo | G39: O que é entregue
B40: Recebe de | D40: 2 · Desenvolvimento de produto | G40: Especificação de materiais
B41: Recebe de | D41: 4 · Produção | G41: Requisição de compra, com especificação, e plano de produção do mês
B42: Recebe de | D42: 5 · Laboratório e controle da qualidade | G42: Resultado da inspeção de recebimento
B43: Recebe de | D43: 7 · Manutenção | G43: Requisição de compra, com especificação
B44: Recebe de | D44: 9 · Gestão do sistema da qualidade | G44: Resultados de auditoria e ações
B45: Entrega a | D45: 4 · Produção | G45: Material recebido e conferido
B46: Entrega a | D46: 7 · Manutenção | G46: Peças e serviços de manutenção
B47: Entrega a | D47: 9 · Gestão do sistema da qualidade | G47: Avaliação dos fornecedores
B49: Resumo automático
B50: Itens em entradas | F50: =COUNTA(D13:D17) -> 5
B51: Itens em saídas | F51: =COUNTA(D18:D20) -> 3
B52: Itens em recursos | F52: =COUNTA(D21:D23) -> 3
B53: Itens em pessoas | F53: =COUNTA(D24:D26) -> 3
B54: Itens em métodos | F54: =COUNTA(D27:D29) -> 3
B55: Itens em indicadores | F55: =COUNTA(D30:D33) -> 4
B56: Itens em riscos | F56: =COUNTA(D34:D36) -> 3
...
