Workbook

Sheet Instruções
B1: GUT — Como usar esta planilha
B2: Modelo para priorizar problemas por gravidade, urgência e tendência.
B4: Legenda: onde preencher
B5: Amarelo-claro | C5: Células de entrada. É aqui que você digita.
B6: Cinza | C6: Células calculadas ou fixas (rótulos, contagens, avisos). Não altere.
B7: Cinza em itálico | C7: Linha de exemplo (marcada com “Ex.”). Mostra o formato esperado e não entra nas contagens.
B8: Listas suspensas | C8: Colunas de origem, código e status aceitam apenas as opções da lista. As notas aceitam números inteiros de 1 a 5.
B9: Comentários | C9: Células com triângulo vermelho no canto trazem uma dica de preenchimento. Passe o mouse sobre elas.
B11: Os três critérios
B12: G | C12: Gravidade: tamanho do dano que o problema causa ou pode causar, se nada for feito.
B13: U | C13: Urgência: tempo disponível para agir antes que o dano aconteça ou aumente.
B14: T | C14: Tendência: evolução esperada do problema com o passar do tempo, se nada for feito.
B15: Pontos | C15: Gravidade × urgência × tendência, de 1 a 125. Quanto maior a pontuação, mais cedo o problema é tratado.
B17: Ordem recomendada de preenchimento
B18: Passo 1 | C18: Aba GUT: preencha o cabeçalho, com o tema, o objetivo e a origem da lista.
B19: Passo 2 | C19: Aba GUT: liste os problemas, cada um como resultado indesejado. Retire causas e soluções.
B20: Passo 3 | C20: Aba Escala: leia a escala com o grupo e ajuste os textos à realidade da lista.
B21: Passo 4 | C21: Aba GUT: dê as notas de gravidade da lista toda. Depois as de urgência. Depois as de tendência.
B22: Passo 5 | C22: Aba Priorização: veja a ordem de tratamento e o gráfico. Nada para digitar.
B23: Passo 6 | C23: Aba GUT: avalie os alertas de gravidade máxima, qualquer que seja a pontuação.
B24: Passo 7 | C24: Aba Plano de ação: defina ação, responsável e prazo para os problemas escolhidos.
B25: Passo 8 | C25: Aba Checklist: valide a matriz com o grupo e marque a data da próxima revisão.
B27: Abas da planilha
B28: GUT | C28: Modelo principal. Cabeçalho, lista de até 20 problemas com as três notas e resumo automático.
B29: Priorização | C29: Problemas em ordem de tratamento, com gráfico das pontuações.
B30: Escala | C30: Descrição das notas de 1 a 5 e cortes das faixas de prioridade. Os dois podem ser ajustados.
B31: Plano de ação | C31: Ações para os problemas escolhidos, com situação calculada a partir do prazo e do status.
B32: Checklist | C32: Doze verificações de qualidade da matriz, com percentual de conclusão.
B33: Exemplo 1 - Pizzaria | C33: Matriz preenchida com oito problemas de uma operação, incluindo um alerta de gravidade máxima.
B34: Exemplo 2 - Compras | C34: Matriz preenchida com sete problemas de uma área, incluindo um empate.
B36: Regras e premissas do modelo
B37: Códigos | C37: Cada problema tem um código fixo, de P1 a P20, que corresponde à linha da lista. A aba Plano de ação usa o código para buscar o texto e a pontuação do problema.
B38: Faixas de prioridade | C38: O modelo parte de dois cortes: 64 pontos para a faixa alta, que equivale a nota 4 nos três critérios, e 27 pontos para a faixa média, que equivale a nota 3 nos três. Os cortes podem ser alterados na aba Escala.
B39: Empates | C39: Problemas com a mesma pontuação são ordenados pela maior gravidade, depois pela maior urgência e depois pela maior tendência. Se o empate continuar, vale a ordem da lista.
B40: Regra de exceção | C40: Todo problema com gravidade 5 recebe um alerta e deve ser avaliado pelo grupo, qualquer que seja a pontuação.
B41: Ação atrasada | C41: Uma ação é considerada atrasada quando o prazo é anterior à data de hoje e o status não é Concluída nem Cancelada.
B42: Capacidade | C42: A planilha comporta 20 problemas e 15 ações. Se faltar espaço, agrupe problemas parecidos ou divida a lista por área.
B43: Exemplos | C43: Os dados das abas de exemplo são ilustrativos, criados para este material.

Sheet GUT
B1: GUT — Matriz de priorização
B2: Preencha as células em amarelo-claro. As células cinza são calculadas automaticamente.
B4: Tema da priorização | F4: Responsável
B5: Área / unidade | F5: Data
B6: Elaborado por | F6: Versão
B7: Objetivo da priorização
B8: Origem da lista | F8: Participantes
B9: Fora do escopo
B11: Lista de problemas | F11: G | G11: U | H11: T | I11: Resultado
B12: # | C12: Problema | E12: Origem | F12: Gravidade | G12: Urgência | H12: Tendência | I12: Pontos | J12: Posição | K12: Prioridade | L12: Alerta
C13: Resultado indesejado, com fato, local e número | E13: De onde veio | F13: Qual é o dano? | G13: Qual é o prazo? | H13: Vai piorar? | I13: G × U × T | J13: 1 = primeiro | K13: Faixa | L13: Gravidade 5
B14: Ex. | C14: Câmara fria com falha intermitente de temperatura | E14: Reunião | F14: 5 | G14: 5 | H14: 4 | I14: 100 | J14: 1 | K14: Alta | L14: Gravidade máxima | N14: Apoio
B15: P1 | I15: =IF(COUNT(F15:H15)<3,"",F15*G15*H15) | J15: =IF(N15="","",RANK(N15,$N$15:$N$34)+COUNTIF($N$14:N14,N15)) | K15: =IF(I15="","",IF(I15>=Escala!$C$14,"Alta",IF(I15>=Escala!$C$15,"Média","Baixa"))) | L15: =IF(F15=5,"Gravidade máxima","") | N15: =IF(I15="","",I15*1000+F15*100+G15*10+H15)
B16: P2 | I16: =IF(COUNT(F16:H16)<3,"",F16*G16*H16) | J16: =IF(N16="","",RANK(N16,$N$15:$N$34)+COUNTIF($N$14:N15,N16)) | K16: =IF(I16="","",IF(I16>=Escala!$C$14,"Alta",IF(I16>=Escala!$C$15,"Média","Baixa"))) | L16: =IF(F16=5,"Gravidade máxima","") | N16: =IF(I16="","",I16*1000+F16*100+G16*10+H16)
B17: P3 | I17: =IF(COUNT(F17:H17)<3,"",F17*G17*H17) | J17: =IF(N17="","",RANK(N17,$N$15:$N$34)+COUNTIF($N$14:N16,N17)) | K17: =IF(I17="","",IF(I17>=Escala!$C$14,"Alta",IF(I17>=Escala!$C$15,"Média","Baixa"))) | L17: =IF(F17=5,"Gravidade máxima","") | N17: =IF(I17="","",I17*1000+F17*100+G17*10+H17)
B18: P4 | I18: =IF(COUNT(F18:H18)<3,"",F18*G18*H18) | J18: =IF(N18="","",RANK(N18,$N$15:$N$34)+COUNTIF($N$14:N17,N18)) | K18: =IF(I18="","",IF(I18>=Escala!$C$14,"Alta",IF(I18>=Escala!$C$15,"Média","Baixa"))) | L18: =IF(F18=5,"Gravidade máxima","") | N18: =IF(I18="","",I18*1000+F18*100+G18*10+H18)
B19: P5 | I19: =IF(COUNT(F19:H19)<3,"",F19*G19*H19) | J19: =IF(N19="","",RANK(N19,$N$15:$N$34)+COUNTIF($N$14:N18,N19)) | K19: =IF(I19="","",IF(I19>=Escala!$C$14,"Alta",IF(I19>=Escala!$C$15,"Média","Baixa"))) | L19: =IF(F19=5,"Gravidade máxima","") | N19: =IF(I19="","",I19*1000+F19*100+G19*10+H19)
B20: P6 | I20: =IF(COUNT(F20:H20)<3,"",F20*G20*H20) | J20: =IF(N20="","",RANK(N20,$N$15:$N$34)+COUNTIF($N$14:N19,N20)) | K20: =IF(I20="","",IF(I20>=Escala!$C$14,"Alta",IF(I20>=Escala!$C$15,"Média","Baixa"))) | L20: =IF(F20=5,"Gravidade máxima","") | N20: =IF(I20="","",I20*1000+F20*100+G20*10+H20)
B21: P7 | I21: =IF(COUNT(F21:H21)<3,"",F21*G21*H21) | J21: =IF(N21="","",RANK(N21,$N$15:$N$34)+COUNTIF($N$14:N20,N21)) | K21: =IF(I21="","",IF(I21>=Escala!$C$14,"Alta",IF(I21>=Escala!$C$15,"Média","Baixa"))) | L21: =IF(F21=5,"Gravidade máxima","") | N21: =IF(I21="","",I21*1000+F21*100+G21*10+H21)
B22: P8 | I22: =IF(COUNT(F22:H22)<3,"",F22*G22*H22) | J22: =IF(N22="","",RANK(N22,$N$15:$N$34)+COUNTIF($N$14:N21,N22)) | K22: =IF(I22="","",IF(I22>=Escala!$C$14,"Alta",IF(I22>=Escala!$C$15,"Média","Baixa"))) | L22: =IF(F22=5,"Gravidade máxima","") | N22: =IF(I22="","",I22*1000+F22*100+G22*10+H22)
B23: P9 | I23: =IF(COUNT(F23:H23)<3,"",F23*G23*H23) | J23: =IF(N23="","",RANK(N23,$N$15:$N$34)+COUNTIF($N$14:N22,N23)) | K23: =IF(I23="","",IF(I23>=Escala!$C$14,"Alta",IF(I23>=Escala!$C$15,"Média","Baixa"))) | L23: =IF(F23=5,"Gravidade máxima","") | N23: =IF(I23="","",I23*1000+F23*100+G23*10+H23)
B24: P10 | I24: =IF(COUNT(F24:H24)<3,"",F24*G24*H24) | J24: =IF(N24="","",RANK(N24,$N$15:$N$34)+COUNTIF($N$14:N23,N24)) | K24: =IF(I24="","",IF(I24>=Escala!$C$14,"Alta",IF(I24>=Escala!$C$15,"Média","Baixa"))) | L24: =IF(F24=5,"Gravidade máxima","") | N24: =IF(I24="","",I24*1000+F24*100+G24*10+H24)
B25: P11 | I25: =IF(COUNT(F25:H25)<3,"",F25*G25*H25) | J25: =IF(N25="","",RANK(N25,$N$15:$N$34)+COUNTIF($N$14:N24,N25)) | K25: =IF(I25="","",IF(I25>=Escala!$C$14,"Alta",IF(I25>=Escala!$C$15,"Média","Baixa"))) | L25: =IF(F25=5,"Gravidade máxima","") | N25: =IF(I25="","",I25*1000+F25*100+G25*10+H25)
B26: P12 | I26: =IF(COUNT(F26:H26)<3,"",F26*G26*H26) | J26: =IF(N26="","",RANK(N26,$N$15:$N$34)+COUNTIF($N$14:N25,N26)) | K26: =IF(I26="","",IF(I26>=Escala!$C$14,"Alta",IF(I26>=Escala!$C$15,"Média","Baixa"))) | L26: =IF(F26=5,"Gravidade máxima","") | N26: =IF(I26="","",I26*1000+F26*100+G26*10+H26)
... B34: P20 | I34: =IF(COUNT(F34:H34)<3,"",F34*G34*H34) | J34: =IF(N34="","",RANK(N34,$N$15:$N$34)+COUNTIF($N$14:N33,N34)) | K34: =IF(I34="","",IF(I34>=Escala!$C$14,"Alta",IF(I34>=Escala!$C$15,"Média","Baixa"))) | L34: =IF(F34=5,"Gravidade máxima","") | N34: =IF(I34="","",I34*1000+F34*100+G34*10+H34)
B36: Resumo automático
B37: Problemas listados | F37: =COUNTA(C15:C34) -> 0
B38: Problemas com as três notas | F38: =COUNT(I15:I34) -> 0
B39: Prioridade alta | F39: =COUNTIF(K15:K34,"Alta") -> 0
B40: Prioridade média | F40: =COUNTIF(K15:K34,"Média") -> 0
B41: Prioridade baixa | F41: =COUNTIF(K15:K34,"Baixa") -> 0
B42: Alertas de gravidade máxima | F42: =COUNTIF(F15:F34,5) -> 0
B43: Aviso: notas | F43: =IF(F37=0,"Liste os problemas",IF(F38<F37,"Há problema sem as três notas","OK")) -> Liste os problemas
B44: Aviso: distribuição | F44: =IF(F38<4,"OK",IF(F39>F38/2,"Mais da metade em prioridade alta: revise as notas",IF(MAX(I15:I34)=MIN(I15:I34),"Todas as pontuações são iguais: revise as notas","OK"))) -> OK
B45: Campos do cabeçalho preenchidos | F45: =COUNTA(D4,I4,D5,I5,D6,I6,D7,D8,I8,D9) -> 0

Sheet Priorização
B1: Priorização — ordem de tratamento
B2: Esta aba é calculada a partir da aba GUT. Não há nada para digitar aqui.
B4: Problemas em ordem de pontuação
B5: Pos. | C5: Código | D5: Problema | E5: Origem | F5: G | G5: U | H5: T | I5: Pontos | J5: Prioridade | K5: Alerta
B6: 1 | C6: =IFERROR(INDEX(GUT!$B$15:$B$34,MATCH($B6,GUT!$J$15:$J$34,0))&"","") | D6: =IFERROR(INDEX(GUT!$C$15:$C$34,MATCH($B6,GUT!$J$15:$J$34,0))&"","") | E6: =IFERROR(INDEX(GUT!$E$15:$E$34,MATCH($B6,GUT!$J$15:$J$34,0))&"","") | F6: =IFERROR(INDEX(GUT!$F$15:$F$34,MATCH($B6,GUT!$J$15:$J$34,0)),"") | G6: =IFERROR(INDEX(GUT!$G$15:$G$34,MATCH($B6,GUT!$J$15:$J$34,0)),"") | H6: =IFERROR(INDEX(GUT!$H$15:$H$34,MATCH($B6,GUT!$J$15:$J$34,0)),"") | I6: =IFERROR(INDEX(GUT!$I$15:$I$34,MATCH($B6,GUT!$J$15:$J$34,0)),"") | J6: =IFERROR(INDEX(GUT!$K$15:$K$34,MATCH($B6,GUT!$J$15:$J$34,0))&"","") | K6: =IFERROR(INDEX(GUT!$L$15:$L$34,MATCH($B6,GUT!$J$15:$J$34,0))&"","")
B7: 2 | C7: =IFERROR(INDEX(GUT!$B$15:$B$34,MATCH($B7,GUT!$J$15:$J$34,0))&"","") | D7: =IFERROR(INDEX(GUT!$C$15:$C$34,MATCH($B7,GUT!$J$15:$J$34,0))&"","") | E7: =IFERROR(INDEX(GUT!$E$15:$E$34,MATCH($B7,GUT!$J$15:$J$34,0))&"","") | F7: =IFERROR(INDEX(GUT!$F$15:$F$34,MATCH($B7,GUT!$J$15:$J$34,0)),"") | G7: =IFERROR(INDEX(GUT!$G$15:$G$34,MATCH($B7,GUT!$J$15:$J$34,0)),"") | H7: =IFERROR(INDEX(GUT!$H$15:$H$34,MATCH($B7,GUT!$J$15:$J$34,0)),"") | I7: =IFERROR(INDEX(GUT!$I$15:$I$34,MATCH($B7,GUT!$J$15:$J$34,0)),"") | J7: =IFERROR(INDEX(GUT!$K$15:$K$34,MATCH($B7,GUT!$J$15:$J$34,0))&"","") | K7: =IFERROR(INDEX(GUT!$L$15:$L$34,MATCH($B7,GUT!$J$15:$J$34,0))&"","")
B8: 3 | C8: =IFERROR(INDEX(GUT!$B$15:$B$34,MATCH($B8,GUT!$J$15:$J$34,0))&"","") | D8: =IFERROR(INDEX(GUT!$C$15:$C$34,MATCH($B8,GUT!$J$15:$J$34,0))&"","") | E8: =IFERROR(INDEX(GUT!$E$15:$E$34,MATCH($B8,GUT!$J$15:$J$34,0))&"","") | F8: =IFERROR(INDEX(GUT!$F$15:$F$34,MATCH($B8,GUT!$J$15:$J$34,0)),"") | G8: =IFERROR(INDEX(GUT!$G$15:$G$34,MATCH($B8,GUT!$J$15:$J$34,0)),"") | H8: =IFERROR(INDEX(GUT!$H$15:$H$34,MATCH($B8,GUT!$J$15:$J$34,0)),"") | I8: =IFERROR(INDEX(GUT!$I$15:$I$34,MATCH($B8,GUT!$J$15:$J$34,0)),"") | J8: =IFERROR(INDEX(GUT!$K$15:$K$34,MATCH($B8,GUT!$J$15:$J$34,0))&"","") | K8: =IFERROR(INDEX(GUT!$L$15:$L$34,MATCH($B8,GUT!$J$15:$J$34,0))&"","")
B9: 4 | C9: =IFERROR(INDEX(GUT!$B$15:$B$34,MATCH($B9,GUT!$J$15:$J$34,0))&"","") | D9: =IFERROR(INDEX(GUT!$C$15:$C$34,MATCH($B9,GUT!$J$15:$J$34,0))&"","") | E9: =IFERROR(INDEX(GUT!$E$15:$E$34,MATCH($B9,GUT!$J$15:$J$34,0))&"","") | F9: =IFERROR(INDEX(GUT!$F$15:$F$34,MATCH($B9,GUT!$J$15:$J$34,0)),"") | G9: =IFERROR(INDEX(GUT!$G$15:$G$34,MATCH($B9,GUT!$J$15:$J$34,0)),"") | H9: =IFERROR(INDEX(GUT!$H$15:$H$34,MATCH($B9,GUT!$J$15:$J$34,0)),"") | I9: =IFERROR(INDEX(GUT!$I$15:$I$34,MATCH($B9,GUT!$J$15:$J$34,0)),"") | J9: =IFERROR(INDEX(GUT!$K$15:$K$34,MATCH($B9,GUT!$J$15:$J$34,0))&"","") | K9: =IFERROR(INDEX(GUT!$L$15:$L$34,MATCH($B9,GUT!$J$15:$J$34,0))&"","")
B10: 5 | C10: =IFERROR(INDEX(GUT!$B$15:$B$34,MATCH($B10,GUT!$J$15:$J$34,0))&"","") | D10: =IFERROR(INDEX(GUT!$C$15:$C$34,MATCH($B10,GUT!$J$15:$J$34,0))&"","") | E10: =IFERROR(INDEX(GUT!$E$15:$E$34,MATCH($B10,GUT!$J$15:$J$34,0))&"","") | F10: =IFERROR(INDEX(GUT!$F$15:$F$34,MATCH($B10,GUT!$J$15:$J$34,0)),"") | G10: =IFERROR(INDEX(GUT!$G$15:$G$34,MATCH($B10,GUT!$J$15:$J$34,0)),"") | H10: =IFERROR(INDEX(GUT!$H$15:$H$34,MATCH($B10,GUT!$J$15:$J$34,0)),"") | I10: =IFERROR(INDEX(GUT!$I$15:$I$34,MATCH($B10,GUT!$J$15:$J$34,0)),"") | J10: =IFERROR(INDEX(GUT!$K$15:$K$34,MATCH($B10,GUT!$J$15:$J$34,0))&"","") | K10: =IFERROR(INDEX(GUT!$L$15:$L$34,MATCH($B10,GUT!$J$15:$J$34,0))&"","")
B11: 6 | C11: =IFERROR(INDEX(GUT!$B$15:$B$34,MATCH($B11,GUT!$J$15:$J$34,0))&"","") | D11: =IFERROR(INDEX(GUT!$C$15:$C$34,MATCH($B11,GUT!$J$15:$J$34,0))&"","") | E11: =IFERROR(INDEX(GUT!$E$15:$E$34,MATCH($B11,GUT!$J$15:$J$34,0))&"","") | F11: =IFERROR(INDEX(GUT!$F$15:$F$34,MATCH($B11,GUT!$J$15:$J$34,0)),"") | G11: =IFERROR(INDEX(GUT!$G$15:$G$34,MATCH($B11,GUT!$J$15:$J$34,0)),"") | H11: =IFERROR(INDEX(GUT!$H$15:$H$34,MATCH($B11,GUT!$J$15:$J$34,0)),"") | I11: =IFERROR(INDEX(GUT!$I$15:$I$34,MATCH($B11,GUT!$J$15:$J$34,0)),"") | J11: =IFERROR(INDEX(GUT!$K$15:$K$34,MATCH($B11,GUT!$J$15:$J$34,0))&"","") | K11: =IFERROR(INDEX(GUT!$L$15:$L$34,MATCH($B11,GUT!$J$15:$J$34,0))&"","")
B12: 7 | C12: =IFERROR(INDEX(GUT!$B$15:$B$34,MATCH($B12,GUT!$J$15:$J$34,0))&"","") | D12: =IFERROR(INDEX(GUT!$C$15:$C$34,MATCH($B12,GUT!$J$15:$J$34,0))&"","") | E12: =IFERROR(INDEX(GUT!$E$15:$E$34,MATCH($B12,GUT!$J$15:$J$34,0))&"","") | F12: =IFERROR(INDEX(GUT!$F$15:$F$34,MATCH($B12,GUT!$J$15:$J$34,0)),"") | G12: =IFERROR(INDEX(GUT!$G$15:$G$34,MATCH($B12,GUT!$J$15:$J$34,0)),"") | H12: =IFERROR(INDEX(GUT!$H$15:$H$34,MATCH($B12,GUT!$J$15:$J$34,0)),"") | I12: =IFERROR(INDEX(GUT!$I$15:$I$34,MATCH($B12,GUT!$J$15:$J$34,0)),"") | J12: =IFERROR(INDEX(GUT!$K$15:$K$34,MATCH($B12,GUT!$J$15:$J$34,0))&"","") | K12: =IFERROR(INDEX(GUT!$L$15:$L$34,MATCH($B12,GUT!$J$15:$J$34,0))&"","")
B13: 8 | C13: =IFERROR(INDEX(GUT!$B$15:$B$34,MATCH($B13,GUT!$J$15:$J$34,0))&"","") | D13: =IFERROR(INDEX(GUT!$C$15:$C$34,MATCH($B13,GUT!$J$15:$J$34,0))&"","") | E13: =IFERROR(INDEX(GUT!$E$15:$E$34,MATCH($B13,GUT!$J$15:$J$34,0))&"","") | F13: =IFERROR(INDEX(GUT!$F$15:$F$34,MATCH($B13,GUT!$J$15:$J$34,0)),"") | G13: =IFERROR(INDEX(GUT!$G$15:$G$34,MATCH($B13,GUT!$J$15:$J$34,0)),"") | H13: =IFERROR(INDEX(GUT!$H$15:$H$34,MATCH($B13,GUT!$J$15:$J$34,0)),"") | I13: =IFERROR(INDEX(GUT!$I$15:$I$34,MATCH($B13,GUT!$J$15:$J$34,0)),"") | J13: =IFERROR(INDEX(GUT!$K$15:$K$34,MATCH($B13,GUT!$J$15:$J$34,0))&"","") | K13: =IFERROR(INDEX(GUT!$L$15:$L$34,MATCH($B13,GUT!$J$15:$J$34,0))&"","")
B14: 9 | C14: =IFERROR(INDEX(GUT!$B$15:$B$34,MATCH($B14,GUT!$J$15:$J$34,0))&"","") | D14: =IFERROR(INDEX(GUT!$C$15:$C$34,MATCH($B14,GUT!$J$15:$J$34,0))&"","") | E14: =IFERROR(INDEX(GUT!$E$15:$E$34,MATCH($B14,GUT!$J$15:$J$34,0))&"","") | F14: =IFERROR(INDEX(GUT!$F$15:$F$34,MATCH($B14,GUT!$J$15:$J$34,0)),"") | G14: =IFERROR(INDEX(GUT!$G$15:$G$34,MATCH($B14,GUT!$J$15:$J$34,0)),"") | H14: =IFERROR(INDEX(GUT!$H$15:$H$34,MATCH($B14,GUT!$J$15:$J$34,0)),"") | I14: =IFERROR(INDEX(GUT!$I$15:$I$34,MATCH($B14,GUT!$J$15:$J$34,0)),"") | J14: =IFERROR(INDEX(GUT!$K$15:$K$34,MATCH($B14,GUT!$J$15:$J$34,0))&"","") | K14: =IFERROR(INDEX(GUT!$L$15:$L$34,MATCH($B14,GUT!$J$15:$J$34,0))&"","")
B15: 10 | C15: =IFERROR(INDEX(GUT!$B$15:$B$34,MATCH($B15,GUT!$J$15:$J$34,0))&"","") | D15: =IFERROR(INDEX(GUT!$C$15:$C$34,MATCH($B15,GUT!$J$15:$J$34,0))&"","") | E15: =IFERROR(INDEX(GUT!$E$15:$E$34,MATCH($B15,GUT!$J$15:$J$34,0))&"","") | F15: =IFERROR(INDEX(GUT!$F$15:$F$34,MATCH($B15,GUT!$J$15:$J$34,0)),"") | G15: =IFERROR(INDEX(GUT!$G$15:$G$34,MATCH($B15,GUT!$J$15:$J$34,0)),"") | H15: =IFERROR(INDEX(GUT!$H$15:$H$34,MATCH($B15,GUT!$J$15:$J$34,0)),"") | I15: =IFERROR(INDEX(GUT!$I$15:$I$34,MATCH($B15,GUT!$J$15:$J$34,0)),"") | J15: =IFERROR(INDEX(GUT!$K$15:$K$34,MATCH($B15,GUT!$J$15:$J$34,0))&"","") | K15: =IFERROR(INDEX(GUT!$L$15:$L$34,MATCH($B15,GUT!$J$15:$J$34,0))&"","")
B16: 11 | C16: =IFERROR(INDEX(GUT!$B$15:$B$34,MATCH($B16,GUT!$J$15:$J$34,0))&"","") | D16: =IFERROR(INDEX(GUT!$C$15:$C$34,MATCH($B16,GUT!$J$15:$J$34,0))&"","") | E16: =IFERROR(INDEX(GUT!$E$15:$E$34,MATCH($B16,GUT!$J$15:$J$34,0))&"","") | F16: =IFERROR(INDEX(GUT!$F$15:$F$34,MATCH($B16,GUT!$J$15:$J$34,0)),"") | G16: =IFERROR(INDEX(GUT!$G$15:$G$34,MATCH($B16,GUT!$J$15:$J$34,0)),"") | H16: =IFERROR(INDEX(GUT!$H$15:$H$34,MATCH($B16,GUT!$J$15:$J$34,0)),"") | I16: =IFERROR(INDEX(GUT!$I$15:$I$34,MATCH($B16,GUT!$J$15:$J$34,0)),"") | J16: =IFERROR(INDEX(GUT!$K$15:$K$34,MATCH($B16,GUT!$J$15:$J$34,0))&"","") | K16: =IFERROR(INDEX(GUT!$L$15:$L$34,MATCH($B16,GUT!$J$15:$J$34,0))&"","")
B17: 12 | C17: =IFERROR(INDEX(GUT!$B$15:$B$34,MATCH($B17,GUT!$J$15:$J$34,0))&"","") | D17: =IFERROR(INDEX(GUT!$C$15:$C$34,MATCH($B17,GUT!$J$15:$J$34,0))&"","") | E17: =IFERROR(INDEX(GUT!$E$15:$E$34,MATCH($B17,GUT!$J$15:$J$34,0))&"","") | F17: =IFERROR(INDEX(GUT!$F$15:$F$34,MATCH($B17,GUT!$J$15:$J$34,0)),"") | G17: =IFERROR(INDEX(GUT!$G$15:$G$34,MATCH($B17,GUT!$J$15:$J$34,0)),"") | H17: =IFERROR(INDEX(GUT!$H$15:$H$34,MATCH($B17,GUT!$J$15:$J$34,0)),"") | I17: =IFERROR(INDEX(GUT!$I$15:$I$34,MATCH($B17,GUT!$J$15:$J$34,0)),"") | J17: =IFERROR(INDEX(GUT!$K$15:$K$34,MATCH($B17,GUT!$J$15:$J$34,0))&"","") | K17: =IFERROR(INDEX(GUT!$L$15:$L$34,MATCH($B17,GUT!$J$15:$J$34,0))&"","")
... B25: 20 | C25: =IFERROR(INDEX(GUT!$B$15:$B$34,MATCH($B25,GUT!$J$15:$J$34,0))&"","") | D25: =IFERROR(INDEX(GUT!$C$15:$C$34,MATCH($B25,GUT!$J$15:$J$34,0))&"","") | E25: =IFERROR(INDEX(GUT!$E$15:$E$34,MATCH($B25,GUT!$J$15:$J$34,0))&"","") | F25: =IFERROR(INDEX(GUT!$F$15:$F$34,MATCH($B25,GUT!$J$15:$J$34,0)),"") | G25: =IFERROR(INDEX(GUT!$G$15:$G$34,MATCH($B25,GUT!$J$15:$J$34,0)),"") | H25: =IFERROR(INDEX(GUT!$H$15:$H$34,MATCH($B25,GUT!$J$15:$J$34,0)),"") | I25: =IFERROR(INDEX(GUT!$I$15:$I$34,MATCH($B25,GUT!$J$15:$J$34,0)),"") | J25: =IFERROR(INDEX(GUT!$K$15:$K$34,MATCH($B25,GUT!$J$15:$J$34,0))&"","") | K25: =IFERROR(INDEX(GUT!$L$15:$L$34,MATCH($B25,GUT!$J$15:$J$34,0))&"","")
B27: Gráfico: pontuação em ordem de tratamento

Sheet Escala
B1: Escala das notas e faixas de prioridade
B2: Leia a escala com o grupo antes de pontuar. Os textos e os cortes em amarelo-claro podem ser ajustados.
B4: Escala das notas
B5: Nota | C5: G — Gravidade | D5: U — Urgência | E5: T — Tendência
B6: 1 | C6: Sem gravidade: dano desprezível. | D6: Pode esperar: não há prazo definido. | E6: Estável: não vai piorar.
B7: 2 | C7: Pouco grave: dano pequeno. | D7: Pouco urgente: agir em alguns meses. | E7: Piora lenta: a longo prazo.
B8: 3 | C8: Grave: dano considerável. | D8: Merece atenção: agir em algumas semanas. | E8: Piora moderada: a médio prazo.
B9: 4 | C9: Muito grave: dano grande. | D9: Muito urgente: agir em alguns dias. | E9: Piora rápida: a curto prazo.
B10: 5 | C10: Extremamente grave: dano difícil de reverter, risco à vida ou descumprimento legal. | D10: Ação imediata: agir hoje. | E10: Piora imediata, se nada for feito.
B12: Faixas de prioridade
B13: Faixa | C13: A partir de (pontos) | D13: Leitura | E13: Encaminhamento
B14: Alta | C14: 64 | D14: Pesa muito nos três critérios. | E14: Tratar agora, com responsável, prazo e acompanhamento semanal.
B15: Média | C15: 27 | D15: Pesa em pelo menos dois critérios. | E15: Planejar o tratamento, com data de início definida.
B16: Baixa | C16: 1 | D16: Pesa pouco ou em um critério só. | E16: Registrar e reavaliar na próxima revisão da matriz.
B17: Aviso | C17: =IF(OR(C14="",C15=""),"Informe os dois cortes",IF(C15>=C14,"O corte da faixa média deve ser menor que o da alta","OK")) -> OK
B19: Regras da priorização
B20: Exceção | C20: Todo problema com gravidade 5 é avaliado pelo grupo, qualquer que seja a pontuação.
B21: Desempate | C21: Na mesma pontuação, vem primeiro a maior gravidade, depois a maior urgência, depois a maior tendência.
B22: Método | C22: Pontue um critério por vez, para a lista toda. Registre a justificativa das notas 4 e 5.

Sheet Plano de ação
B1: Plano de ação
B2: Escolha o código do problema. O texto e a pontuação vêm da aba GUT.
B4: # | C4: Código | D4: Problema | E4: Pontos | F4: Ação | G4: Responsável | H4: Prazo | I4: Status | J4: Situação
B5: Ex. | C5: P3 | D5: Câmara fria com falha intermitente de temperatura | E5: 100 | F5: Chamar a assistência técnica e registrar a temperatura duas vezes por turno | G5: Gerente da loja | H5: 46325 | I5: Em andamento | J5: No prazo
B6: 1 | D6: =IF(C6="","",INDEX(GUT!$C$15:$C$34,VALUE(MID(C6,2,2)))&"") | E6: =IF(C6="","",IFERROR(INDEX(GUT!$I$15:$I$34,VALUE(MID(C6,2,2)))+0,"")) | J6: =IF(F6="","",IF(OR(I6="Concluída",I6="Cancelada"),I6,IF(H6="","Sem prazo",IF(H6<TODAY(),"Atrasada","No prazo"))))
B7: 2 | D7: =IF(C7="","",INDEX(GUT!$C$15:$C$34,VALUE(MID(C7,2,2)))&"") | E7: =IF(C7="","",IFERROR(INDEX(GUT!$I$15:$I$34,VALUE(MID(C7,2,2)))+0,"")) | J7: =IF(F7="","",IF(OR(I7="Concluída",I7="Cancelada"),I7,IF(H7="","Sem prazo",IF(H7<TODAY(),"Atrasada","No prazo"))))
B8: 3 | D8: =IF(C8="","",INDEX(GUT!$C$15:$C$34,VALUE(MID(C8,2,2)))&"") | E8: =IF(C8="","",IFERROR(INDEX(GUT!$I$15:$I$34,VALUE(MID(C8,2,2)))+0,"")) | J8: =IF(F8="","",IF(OR(I8="Concluída",I8="Cancelada"),I8,IF(H8="","Sem prazo",IF(H8<TODAY(),"Atrasada","No prazo"))))
B9: 4 | D9: =IF(C9="","",INDEX(GUT!$C$15:$C$34,VALUE(MID(C9,2,2)))&"") | E9: =IF(C9="","",IFERROR(INDEX(GUT!$I$15:$I$34,VALUE(MID(C9,2,2)))+0,"")) | J9: =IF(F9="","",IF(OR(I9="Concluída",I9="Cancelada"),I9,IF(H9="","Sem prazo",IF(H9<TODAY(),"Atrasada","No prazo"))))
B10: 5 | D10: =IF(C10="","",INDEX(GUT!$C$15:$C$34,VALUE(MID(C10,2,2)))&"") | E10: =IF(C10="","",IFERROR(INDEX(GUT!$I$15:$I$34,VALUE(MID(C10,2,2)))+0,"")) | J10: =IF(F10="","",IF(OR(I10="Concluída",I10="Cancelada"),I10,IF(H10="","Sem prazo",IF(H10<TODAY(),"Atrasada","No prazo"))))
B11: 6 | D11: =IF(C11="","",INDEX(GUT!$C$15:$C$34,VALUE(MID(C11,2,2)))&"") | E11: =IF(C11="","",IFERROR(INDEX(GUT!$I$15:$I$34,VALUE(MID(C11,2,2)))+0,"")) | J11: =IF(F11="","",IF(OR(I11="Concluída",I11="Cancelada"),I11,IF(H11="","Sem prazo",IF(H11<TODAY(),"Atrasada","No prazo"))))
B12: 7 | D12: =IF(C12="","",INDEX(GUT!$C$15:$C$34,VALUE(MID(C12,2,2)))&"") | E12: =IF(C12="","",IFERROR(INDEX(GUT!$I$15:$I$34,VALUE(MID(C12,2,2)))+0,"")) | J12: =IF(F12="","",IF(OR(I12="Concluída",I12="Cancelada"),I12,IF(H12="","Sem prazo",IF(H12<TODAY(),"Atrasada","No prazo"))))
B13: 8 | D13: =IF(C13="","",INDEX(GUT!$C$15:$C$34,VALUE(MID(C13,2,2)))&"") | E13: =IF(C13="","",IFERROR(INDEX(GUT!$I$15:$I$34,VALUE(MID(C13,2,2)))+0,"")) | J13: =IF(F13="","",IF(OR(I13="Concluída",I13="Cancelada"),I13,IF(H13="","Sem prazo",IF(H13<TODAY(),"Atrasada","No prazo"))))
B14: 9 | D14: =IF(C14="","",INDEX(GUT!$C$15:$C$34,VALUE(MID(C14,2,2)))&"") | E14: =IF(C14="","",IFERROR(INDEX(GUT!$I$15:$I$34,VALUE(MID(C14,2,2)))+0,"")) | J14: =IF(F14="","",IF(OR(I14="Concluída",I14="Cancelada"),I14,IF(H14="","Sem prazo",IF(H14<TODAY(),"Atrasada","No prazo"))))
B15: 10 | D15: =IF(C15="","",INDEX(GUT!$C$15:$C$34,VALUE(MID(C15,2,2)))&"") | E15: =IF(C15="","",IFERROR(INDEX(GUT!$I$15:$I$34,VALUE(MID(C15,2,2)))+0,"")) | J15: =IF(F15="","",IF(OR(I15="Concluída",I15="Cancelada"),I15,IF(H15="","Sem prazo",IF(H15<TODAY(),"Atrasada","No prazo"))))
B16: 11 | D16: =IF(C16="","",INDEX(GUT!$C$15:$C$34,VALUE(MID(C16,2,2)))&"") | E16: =IF(C16="","",IFERROR(INDEX(GUT!$I$15:$I$34,VALUE(MID(C16,2,2)))+0,"")) | J16: =IF(F16="","",IF(OR(I16="Concluída",I16="Cancelada"),I16,IF(H16="","Sem prazo",IF(H16<TODAY(),"Atrasada","No prazo"))))
B17: 12 | D17: =IF(C17="","",INDEX(GUT!$C$15:$C$34,VALUE(MID(C17,2,2)))&"") | E17: =IF(C17="","",IFERROR(INDEX(GUT!$I$15:$I$34,VALUE(MID(C17,2,2)))+0,"")) | J17: =IF(F17="","",IF(OR(I17="Concluída",I17="Cancelada"),I17,IF(H17="","Sem prazo",IF(H17<TODAY(),"Atrasada","No prazo"))))
... B20: 15 | D20: =IF(C20="","",INDEX(GUT!$C$15:$C$34,VALUE(MID(C20,2,2)))&"") | E20: =IF(C20="","",IFERROR(INDEX(GUT!$I$15:$I$34,VALUE(MID(C20,2,2)))+0,"")) | J20: =IF(F20="","",IF(OR(I20="Concluída",I20="Cancelada"),I20,IF(H20="","Sem prazo",IF(H20<TODAY(),"Atrasada","No prazo"))))
B22: Resumo automático
B23: Ações registradas | G23: =COUNTA(F6:F20) -> 0
B24: Concluídas | G24: =COUNTIF(I6:I20,"Concluída") -> 0
B25: Em andamento | G25: =COUNTIF(I6:I20,"Em andamento") -> 0
B26: Não iniciadas | G26: =COUNTIF(I6:I20,"Não iniciada") -> 0
B27: Atrasadas | G27: =COUNTIF(J6:J20,"Atrasada") -> 0
B28: Ações sem responsável ou sem prazo | G28: =SUMPRODUCT((F6:F20<>"")*((G6:G20="")+(H6:H20="")>0)) -> 0
B29: Percentual concluído | G29: =IF(G23=0,0,G24/G23) -> 0
B30: Problemas de prioridade alta sem ação | G30: =SUMPRODUCT((GUT!$K$15:$K$34="Alta")*(COUNTIF($C$6:$C$20,GUT!$B$15:$B$34)=0)) -> 0
B31: Alertas de gravidade máxima sem ação | G31: =SUMPRODUCT((GUT!$F$15:$F$34=5)*(COUNTIF($C$6:$C$20,GUT!$B$15:$B$34)=0)) -> 0

Sheet Checklist
B1: Checklist de validação da Matriz GUT
B2: Escolha o status de cada item na lista suspensa (coluna em amarelo-claro).
B4: # | C4: Item de verificação | D4: Status | E4: Observações
B5: 1 | C5: A lista tem problemas, e não causas nem soluções.
B6: 2 | C6: Cada problema está descrito com fato, local e número, quando houver.
B7: 3 | C7: Os problemas da lista são comparáveis: mesmo tipo e mesmo tamanho.
B8: 4 | C8: A escala de notas foi combinada pelo grupo antes da pontuação.
B9: 5 | C9: As notas foram dadas em grupo, por pessoas que conhecem os problemas.
B10: 6 | C10: Cada critério foi pontuado para a lista toda antes de passar ao seguinte.
B11: 7 | C11: As notas se apoiam em dados, quando eles existem.
B12: 8 | C12: Os empates foram resolvidos por um critério combinado.
B13: 9 | C13: Os problemas de gravidade máxima foram avaliados, qualquer que seja a pontuação.
B14: 10 | C14: Os problemas de maior prioridade têm ação, responsável e prazo.
B15: 11 | C15: Os problemas de baixa prioridade foram registrados, e não descartados.
B16: 12 | C16: A data da próxima revisão da matriz está marcada.
B18: Resumo automático
B19: Itens atendidos (Sim) | D19: =COUNTIF(D5:D16,"Sim") -> 0
B20: Itens parciais | D20: =COUNTIF(D5:D16,"Parcial") -> 0
B21: Itens não atendidos | D21: =COUNTIF(D5:D16,"Não") -> 0
B22: Itens sem resposta | D22: =COUNTBLANK(D5:D16) -> 12
B23: Percentual atendido | D23: =D19/ROWS(D5:D16) -> 0
B24: Situação | D24: =IF(D19=ROWS(D5:D16),"Validado",IF(D22>0,"Em andamento","Com pendências")) -> Em andamento

Sheet Exemplo 1 - Pizzaria
B1: GUT — Matriz de priorização
B2: Exemplo preenchido, para consulta. Use a aba GUT para a sua lista.
B4: Tema da priorização | D4: Problemas da operação da pizzaria | F4: Responsável | I4: Gerente da loja
B5: Área / unidade | D5: Pizzaria (loja) | F5: Data | I5: 46294
B6: Elaborado por | D6: Equipe da loja | F6: Versão | I6: 1.0
B7: Objetivo da priorização | D7: Escolher os problemas que serão tratados no trimestre.
B8: Origem da lista | D8: Reclamações, indicadores e reunião mensal da equipe | F8: Participantes | I8: Gerente, líder da expedição, pizzaiolo e atendente
B9: Fora do escopo | D9: Problemas do salão e decisões de cardápio.
B11: Lista de problemas | F11: G | G11: U | H11: T | I11: Resultado
B12: # | C12: Problema | E12: Origem | F12: Gravidade | G12: Urgência | H12: Tendência | I12: Pontos | J12: Posição | K12: Prioridade | L12: Alerta
C13: Resultado indesejado, com fato, local e número | E13: De onde veio | F13: Qual é o dano? | G13: Qual é o prazo? | H13: Vai piorar? | I13: G × U × T | J13: 1 = primeiro | K13: Faixa | L13: Gravidade 5
B14: As notas foram dadas em grupo, um critério por vez. A posição segue a pontuação; nos empates, vale a maior gravidade, depois a maior urgência e a maior tendência. | N14: Apoio
B15: P1 | C15: Forno único opera no limite no horário de pico | E15: Indicador | F15: 4 | G15: 3 | H15: 4 | I15: =IF(COUNT(F15:H15)<3,"",F15*G15*H15) -> 48 | J15: =IF(N15="","",RANK(N15,$N$15:$N$34)+COUNTIF($N$14:N14,N15)) -> 3 | K15: =IF(I15="","",IF(I15>=Escala!$C$14,"Alta",IF(I15>=Escala!$C$15,"Média","Baixa"))) -> Média | L15: =IF(F15=5,"Gravidade máxima","") | N15: =IF(I15="","",I15*1000+F15*100+G15*10+H15) -> 48434
B16: P2 | C16: Margem do delivery caiu com o aumento da taxa do aplicativo | E16: Indicador | F16: 4 | G16: 4 | H16: 4 | I16: =IF(COUNT(F16:H16)<3,"",F16*G16*H16) -> 64 | J16: =IF(N16="","",RANK(N16,$N$15:$N$34)+COUNTIF($N$14:N15,N16)) -> 2 | K16: =IF(I16="","",IF(I16>=Escala!$C$14,"Alta",IF(I16>=Escala!$C$15,"Média","Baixa"))) -> Alta | L16: =IF(F16=5,"Gravidade máxima","") | N16: =IF(I16="","",I16*1000+F16*100+G16*10+H16) -> 64444
B17: P3 | C17: Câmara fria com falha intermitente de temperatura | E17: Reunião | F17: 5 | G17: 5 | H17: 4 | I17: =IF(COUNT(F17:H17)<3,"",F17*G17*H17) -> 100 | J17: =IF(N17="","",RANK(N17,$N$15:$N$34)+COUNTIF($N$14:N16,N17)) -> 1 | K17: =IF(I17="","",IF(I17>=Escala!$C$14,"Alta",IF(I17>=Escala!$C$15,"Média","Baixa"))) -> Alta | L17: =IF(F17=5,"Gravidade máxima","") -> Gravidade máxima | N17: =IF(I17="","",I17*1000+F17*100+G17*10+H17) -> 100554
B18: P4 | C18: Erros de sabor ou de tamanho em 3% dos pedidos | E18: Reclamação | F18: 3 | G18: 3 | H18: 2 | I18: =IF(COUNT(F18:H18)<3,"",F18*G18*H18) -> 18 | J18: =IF(N18="","",RANK(N18,$N$15:$N$34)+COUNTIF($N$14:N17,N18)) -> 6 | K18: =IF(I18="","",IF(I18>=Escala!$C$14,"Alta",IF(I18>=Escala!$C$15,"Média","Baixa"))) -> Baixa | L18: =IF(F18=5,"Gravidade máxima","") | N18: =IF(I18="","",I18*1000+F18*100+G18*10+H18) -> 18332
B19: P5 | C19: Desperdício de ingredientes acima de 8% do consumo | E19: Indicador | F19: 3 | G19: 2 | H19: 3 | I19: =IF(COUNT(F19:H19)<3,"",F19*G19*H19) -> 18 | J19: =IF(N19="","",RANK(N19,$N$15:$N$34)+COUNTIF($N$14:N18,N19)) -> 7 | K19: =IF(I19="","",IF(I19>=Escala!$C$14,"Alta",IF(I19>=Escala!$C$15,"Média","Baixa"))) -> Baixa | L19: =IF(F19=5,"Gravidade máxima","") | N19: =IF(I19="","",I19*1000+F19*100+G19*10+H19) -> 18323
B20: P6 | C20: Licença sanitária vence em 45 dias | E20: Reunião | F20: 5 | G20: 4 | H20: 2 | I20: =IF(COUNT(F20:H20)<3,"",F20*G20*H20) -> 40 | J20: =IF(N20="","",RANK(N20,$N$15:$N$34)+COUNTIF($N$14:N19,N20)) -> 4 | K20: =IF(I20="","",IF(I20>=Escala!$C$14,"Alta",IF(I20>=Escala!$C$15,"Média","Baixa"))) -> Média | L20: =IF(F20=5,"Gravidade máxima","") -> Gravidade máxima | N20: =IF(I20="","",I20*1000+F20*100+G20*10+H20) -> 40542
B21: P7 | C21: Saídas de entregadores subiram de 2 para 5 por trimestre | E21: Indicador | F21: 3 | G21: 3 | H21: 4 | I21: =IF(COUNT(F21:H21)<3,"",F21*G21*H21) -> 36 | J21: =IF(N21="","",RANK(N21,$N$15:$N$34)+COUNTIF($N$14:N20,N21)) -> 5 | K21: =IF(I21="","",IF(I21>=Escala!$C$14,"Alta",IF(I21>=Escala!$C$15,"Média","Baixa"))) -> Média | L21: =IF(F21=5,"Gravidade máxima","") | N21: =IF(I21="","",I21*1000+F21*100+G21*10+H21) -> 36334
B22: P8 | C22: Fila no balcão de retirada nas noites de sábado | E22: Reclamação | F22: 2 | G22: 1 | H22: 2 | I22: =IF(COUNT(F22:H22)<3,"",F22*G22*H22) -> 4 | J22: =IF(N22="","",RANK(N22,$N$15:$N$34)+COUNTIF($N$14:N21,N22)) -> 8 | K22: =IF(I22="","",IF(I22>=Escala!$C$14,"Alta",IF(I22>=Escala!$C$15,"Média","Baixa"))) -> Baixa | L22: =IF(F22=5,"Gravidade máxima","") | N22: =IF(I22="","",I22*1000+F22*100+G22*10+H22) -> 4212
B23: P9 | I23: =IF(COUNT(F23:H23)<3,"",F23*G23*H23) | J23: =IF(N23="","",RANK(N23,$N$15:$N$34)+COUNTIF($N$14:N22,N23)) | K23: =IF(I23="","",IF(I23>=Escala!$C$14,"Alta",IF(I23>=Escala!$C$15,"Média","Baixa"))) | L23: =IF(F23=5,"Gravidade máxima","") | N23: =IF(I23="","",I23*1000+F23*100+G23*10+H23)
B24: P10 | I24: =IF(COUNT(F24:H24)<3,"",F24*G24*H24) | J24: =IF(N24="","",RANK(N24,$N$15:$N$34)+COUNTIF($N$14:N23,N24)) | K24: =IF(I24="","",IF(I24>=Escala!$C$14,"Alta",IF(I24>=Escala!$C$15,"Média","Baixa"))) | L24: =IF(F24=5,"Gravidade máxima","") | N24: =IF(I24="","",I24*1000+F24*100+G24*10+H24)
B25: P11 | I25: =IF(COUNT(F25:H25)<3,"",F25*G25*H25) | J25: =IF(N25="","",RANK(N25,$N$15:$N$34)+COUNTIF($N$14:N24,N25)) | K25: =IF(I25="","",IF(I25>=Escala!$C$14,"Alta",IF(I25>=Escala!$C$15,"Média","Baixa"))) | L25: =IF(F25=5,"Gravidade máxima","") | N25: =IF(I25="","",I25*1000+F25*100+G25*10+H25)
B26: P12 | I26: =IF(COUNT(F26:H26)<3,"",F26*G26*H26) | J26: =IF(N26="","",RANK(N26,$N$15:$N$34)+COUNTIF($N$14:N25,N26)) | K26: =IF(I26="","",IF(I26>=Escala!$C$14,"Alta",IF(I26>=Escala!$C$15,"Média","Baixa"))) | L26: =IF(F26=5,"Gravidade máxima","") | N26: =IF(I26="","",I26*1000+F26*100+G26*10+H26)
B27: P13 | I27: =IF(COUNT(F27:H27)<3,"",F27*G27*H27) | J27: =IF(N27="","",RANK(N27,$N$15:$N$34)+COUNTIF($N$14:N26,N27)) | K27: =IF(I27="","",IF(I27>=Escala!$C$14,"Alta",IF(I27>=Escala!$C$15,"Média","Baixa"))) | L27: =IF(F27=5,"Gravidade máxima","") | N27: =IF(I27="","",I27*1000+F27*100+G27*10+H27)
B28: P14 | I28: =IF(COUNT(F28:H28)<3,"",F28*G28*H28) | J28: =IF(N28="","",RANK(N28,$N$15:$N$34)+COUNTIF($N$14:N27,N28)) | K28: =IF(I28="","",IF(I28>=Escala!$C$14,"Alta",IF(I28>=Escala!$C$15,"Média","Baixa"))) | L28: =IF(F28=5,"Gravidade máxima","") | N28: =IF(I28="","",I28*1000+F28*100+G28*10+H28)
B29: P15 | I29: =IF(COUNT(F29:H29)<3,"",F29*G29*H29) | J29: =IF(N29="","",RANK(N29,$N$15:$N$34)+COUNTIF($N$14:N28,N29)) | K29: =IF(I29="","",IF(I29>=Escala!$C$14,"Alta",IF(I29>=Escala!$C$15,"Média","Baixa"))) | L29: =IF(F29=5,"Gravidade máxima","") | N29: =IF(I29="","",I29*1000+F29*100+G29*10+H29)
B30: P16 | I30: =IF(COUNT(F30:H30)<3,"",F30*G30*H30) | J30: =IF(N30="","",RANK(N30,$N$15:$N$34)+COUNTIF($N$14:N29,N30)) | K30: =IF(I30="","",IF(I30>=Escala!$C$14,"Alta",IF(I30>=Escala!$C$15,"Média","Baixa"))) | L30: =IF(F30=5,"Gravidade máxima","") | N30: =IF(I30="","",I30*1000+F30*100+G30*10+H30)
B31: P17 | I31: =IF(COUNT(F31:H31)<3,"",F31*G31*H31) | J31: =IF(N31="","",RANK(N31,$N$15:$N$34)+COUNTIF($N$14:N30,N31)) | K31: =IF(I31="","",IF(I31>=Escala!$C$14,"Alta",IF(I31>=Escala!$C$15,"Média","Baixa"))) | L31: =IF(F31=5,"Gravidade máxima","") | N31: =IF(I31="","",I31*1000+F31*100+G31*10+H31)
B32: P18 | I32: =IF(COUNT(F32:H32)<3,"",F32*G32*H32) | J32: =IF(N32="","",RANK(N32,$N$15:$N$34)+COUNTIF($N$14:N31,N32)) | K32: =IF(I32="","",IF(I32>=Escala!$C$14,"Alta",IF(I32>=Escala!$C$15,"Média","Baixa"))) | L32: =IF(F32=5,"Gravidade máxima","") | N32: =IF(I32="","",I32*1000+F32*100+G32*10+H32)
B33: P19 | I33: =IF(COUNT(F33:H33)<3,"",F33*G33*H33) | J33: =IF(N33="","",RANK(N33,$N$15:$N$34)+COUNTIF($N$14:N32,N33)) | K33: =IF(I33="","",IF(I33>=Escala!$C$14,"Alta",IF(I33>=Escala!$C$15,"Média","Baixa"))) | L33: =IF(F33=5,"Gravidade máxima","") | N33: =IF(I33="","",I33*1000+F33*100+G33*10+H33)
B34: P20 | I34: =IF(COUNT(F34:H34)<3,"",F34*G34*H34) | J34: =IF(N34="","",RANK(N34,$N$15:$N$34)+COUNTIF($N$14:N33,N34)) | K34: =IF(I34="","",IF(I34>=Escala!$C$14,"Alta",IF(I34>=Escala!$C$15,"Média","Baixa"))) | L34: =IF(F34=5,"Gravidade máxima","") | N34: =IF(I34="","",I34*1000+F34*100+G34*10+H34)
B36: Resumo automático
B37: Problemas listados | F37: =COUNTA(C15:C34) -> 8
B38: Problemas com as três notas | F38: =COUNT(I15:I34) -> 8
B39: Prioridade alta | F39: =COUNTIF(K15:K34,"Alta") -> 2
B40: Prioridade média | F40: =COUNTIF(K15:K34,"Média") -> 3
B41: Prioridade baixa | F41: =COUNTIF(K15:K34,"Baixa") -> 3
B42: Alertas de gravidade máxima | F42: =COUNTIF(F15:F34,5) -> 2
B43: Aviso: notas | F43: =IF(F37=0,"Liste os problemas",IF(F38<F37,"Há problema sem as três notas","OK")) -> OK
...

Sheet Exemplo 2 - Compras
B1: GUT — Matriz de priorização
B2: Exemplo preenchido, para consulta. Use a aba GUT para a sua lista.
B4: Tema da priorização | D4: Problemas do processo de compras | F4: Responsável | I4: Gerente de Suprimentos
B5: Área / unidade | D5: Suprimentos | F5: Data | I5: 46294
B6: Elaborado por | D6: Equipe de compras | F6: Versão | I6: 1.0
B7: Objetivo da priorização | D7: Definir a ordem dos projetos de melhoria do semestre.
B8: Origem da lista | D8: Matriz SWOT da área, indicadores e auditoria interna | F8: Participantes | I8: Gerente, compradores, Controladoria e Qualidade
B9: Fora do escopo | D9: Gestão de estoques e pagamento a fornecedores.
B11: Lista de problemas | F11: G | G11: U | H11: T | I11: Resultado
B12: # | C12: Problema | E12: Origem | F12: Gravidade | G12: Urgência | H12: Tendência | I12: Pontos | J12: Posição | K12: Prioridade | L12: Alerta
C13: Resultado indesejado, com fato, local e número | E13: De onde veio | F13: Qual é o dano? | G13: Qual é o prazo? | H13: Vai piorar? | I13: G × U × T | J13: 1 = primeiro | K13: Faixa | L13: Gravidade 5
B14: As notas foram dadas em grupo, um critério por vez. A posição segue a pontuação; nos empates, vale a maior gravidade, depois a maior urgência e a maior tendência. | N14: Apoio
B15: P1 | C15: Fornecedor único contratado para três itens críticos | E15: SWOT | F15: 5 | G15: 3 | H15: 4 | I15: =IF(COUNT(F15:H15)<3,"",F15*G15*H15) -> 60 | J15: =IF(N15="","",RANK(N15,$N$15:$N$34)+COUNTIF($N$14:N14,N15)) -> 2 | K15: =IF(I15="","",IF(I15>=Escala!$C$14,"Alta",IF(I15>=Escala!$C$15,"Média","Baixa"))) -> Média | L15: =IF(F15=5,"Gravidade máxima","") -> Gravidade máxima | N15: =IF(I15="","",I15*1000+F15*100+G15*10+H15) -> 60534
B16: P2 | C16: 40% das requisições são devolvidas por especificação incompleta | E16: Indicador | F16: 3 | G16: 3 | H16: 3 | I16: =IF(COUNT(F16:H16)<3,"",F16*G16*H16) -> 27 | J16: =IF(N16="","",RANK(N16,$N$15:$N$34)+COUNTIF($N$14:N15,N16)) -> 5 | K16: =IF(I16="","",IF(I16>=Escala!$C$14,"Alta",IF(I16>=Escala!$C$15,"Média","Baixa"))) -> Média | L16: =IF(F16=5,"Gravidade máxima","") | N16: =IF(I16="","",I16*1000+F16*100+G16*10+H16) -> 27333
B17: P3 | C17: Pedido de compra leva 12 dias úteis para ser emitido | E17: Indicador | F17: 4 | G17: 4 | H17: 3 | I17: =IF(COUNT(F17:H17)<3,"",F17*G17*H17) -> 48 | J17: =IF(N17="","",RANK(N17,$N$15:$N$34)+COUNTIF($N$14:N16,N17)) -> 3 | K17: =IF(I17="","",IF(I17>=Escala!$C$14,"Alta",IF(I17>=Escala!$C$15,"Média","Baixa"))) -> Média | L17: =IF(F17=5,"Gravidade máxima","") | N17: =IF(I17="","",I17*1000+F17*100+G17*10+H17) -> 48443
B18: P4 | C18: Contrato de frete vence em 60 dias, sem renegociação iniciada | E18: Reunião | F18: 4 | G18: 5 | H18: 2 | I18: =IF(COUNT(F18:H18)<3,"",F18*G18*H18) -> 40 | J18: =IF(N18="","",RANK(N18,$N$15:$N$34)+COUNTIF($N$14:N17,N18)) -> 4 | K18: =IF(I18="","",IF(I18>=Escala!$C$14,"Alta",IF(I18>=Escala!$C$15,"Média","Baixa"))) -> Média | L18: =IF(F18=5,"Gravidade máxima","") | N18: =IF(I18="","",I18*1000+F18*100+G18*10+H18) -> 40452
B19: P5 | C19: Cadastro de fornecedores com dados desatualizados | E19: Auditoria | F19: 2 | G19: 2 | H19: 3 | I19: =IF(COUNT(F19:H19)<3,"",F19*G19*H19) -> 12 | J19: =IF(N19="","",RANK(N19,$N$15:$N$34)+COUNTIF($N$14:N18,N19)) -> 7 | K19: =IF(I19="","",IF(I19>=Escala!$C$14,"Alta",IF(I19>=Escala!$C$15,"Média","Baixa"))) -> Baixa | L19: =IF(F19=5,"Gravidade máxima","") | N19: =IF(I19="","",I19*1000+F19*100+G19*10+H19) -> 12223
B20: P6 | C20: Compras urgentes fora do processo cresceram 30% no semestre | E20: Indicador | F20: 4 | G20: 4 | H20: 5 | I20: =IF(COUNT(F20:H20)<3,"",F20*G20*H20) -> 80 | J20: =IF(N20="","",RANK(N20,$N$15:$N$34)+COUNTIF($N$14:N19,N20)) -> 1 | K20: =IF(I20="","",IF(I20>=Escala!$C$14,"Alta",IF(I20>=Escala!$C$15,"Média","Baixa"))) -> Alta | L20: =IF(F20=5,"Gravidade máxima","") | N20: =IF(I20="","",I20*1000+F20*100+G20*10+H20) -> 80445
B21: P7 | C21: Avaliação de fornecedores não distingue bom e mau desempenho | E21: Auditoria | F21: 3 | G21: 2 | H21: 2 | I21: =IF(COUNT(F21:H21)<3,"",F21*G21*H21) -> 12 | J21: =IF(N21="","",RANK(N21,$N$15:$N$34)+COUNTIF($N$14:N20,N21)) -> 6 | K21: =IF(I21="","",IF(I21>=Escala!$C$14,"Alta",IF(I21>=Escala!$C$15,"Média","Baixa"))) -> Baixa | L21: =IF(F21=5,"Gravidade máxima","") | N21: =IF(I21="","",I21*1000+F21*100+G21*10+H21) -> 12322
B22: P8 | I22: =IF(COUNT(F22:H22)<3,"",F22*G22*H22) | J22: =IF(N22="","",RANK(N22,$N$15:$N$34)+COUNTIF($N$14:N21,N22)) | K22: =IF(I22="","",IF(I22>=Escala!$C$14,"Alta",IF(I22>=Escala!$C$15,"Média","Baixa"))) | L22: =IF(F22=5,"Gravidade máxima","") | N22: =IF(I22="","",I22*1000+F22*100+G22*10+H22)
B23: P9 | I23: =IF(COUNT(F23:H23)<3,"",F23*G23*H23) | J23: =IF(N23="","",RANK(N23,$N$15:$N$34)+COUNTIF($N$14:N22,N23)) | K23: =IF(I23="","",IF(I23>=Escala!$C$14,"Alta",IF(I23>=Escala!$C$15,"Média","Baixa"))) | L23: =IF(F23=5,"Gravidade máxima","") | N23: =IF(I23="","",I23*1000+F23*100+G23*10+H23)
B24: P10 | I24: =IF(COUNT(F24:H24)<3,"",F24*G24*H24) | J24: =IF(N24="","",RANK(N24,$N$15:$N$34)+COUNTIF($N$14:N23,N24)) | K24: =IF(I24="","",IF(I24>=Escala!$C$14,"Alta",IF(I24>=Escala!$C$15,"Média","Baixa"))) | L24: =IF(F24=5,"Gravidade máxima","") | N24: =IF(I24="","",I24*1000+F24*100+G24*10+H24)
B25: P11 | I25: =IF(COUNT(F25:H25)<3,"",F25*G25*H25) | J25: =IF(N25="","",RANK(N25,$N$15:$N$34)+COUNTIF($N$14:N24,N25)) | K25: =IF(I25="","",IF(I25>=Escala!$C$14,"Alta",IF(I25>=Escala!$C$15,"Média","Baixa"))) | L25: =IF(F25=5,"Gravidade máxima","") | N25: =IF(I25="","",I25*1000+F25*100+G25*10+H25)
B26: P12 | I26: =IF(COUNT(F26:H26)<3,"",F26*G26*H26) | J26: =IF(N26="","",RANK(N26,$N$15:$N$34)+COUNTIF($N$14:N25,N26)) | K26: =IF(I26="","",IF(I26>=Escala!$C$14,"Alta",IF(I26>=Escala!$C$15,"Média","Baixa"))) | L26: =IF(F26=5,"Gravidade máxima","") | N26: =IF(I26="","",I26*1000+F26*100+G26*10+H26)
B27: P13 | I27: =IF(COUNT(F27:H27)<3,"",F27*G27*H27) | J27: =IF(N27="","",RANK(N27,$N$15:$N$34)+COUNTIF($N$14:N26,N27)) | K27: =IF(I27="","",IF(I27>=Escala!$C$14,"Alta",IF(I27>=Escala!$C$15,"Média","Baixa"))) | L27: =IF(F27=5,"Gravidade máxima","") | N27: =IF(I27="","",I27*1000+F27*100+G27*10+H27)
B28: P14 | I28: =IF(COUNT(F28:H28)<3,"",F28*G28*H28) | J28: =IF(N28="","",RANK(N28,$N$15:$N$34)+COUNTIF($N$14:N27,N28)) | K28: =IF(I28="","",IF(I28>=Escala!$C$14,"Alta",IF(I28>=Escala!$C$15,"Média","Baixa"))) | L28: =IF(F28=5,"Gravidade máxima","") | N28: =IF(I28="","",I28*1000+F28*100+G28*10+H28)
B29: P15 | I29: =IF(COUNT(F29:H29)<3,"",F29*G29*H29) | J29: =IF(N29="","",RANK(N29,$N$15:$N$34)+COUNTIF($N$14:N28,N29)) | K29: =IF(I29="","",IF(I29>=Escala!$C$14,"Alta",IF(I29>=Escala!$C$15,"Média","Baixa"))) | L29: =IF(F29=5,"Gravidade máxima","") | N29: =IF(I29="","",I29*1000+F29*100+G29*10+H29)
B30: P16 | I30: =IF(COUNT(F30:H30)<3,"",F30*G30*H30) | J30: =IF(N30="","",RANK(N30,$N$15:$N$34)+COUNTIF($N$14:N29,N30)) | K30: =IF(I30="","",IF(I30>=Escala!$C$14,"Alta",IF(I30>=Escala!$C$15,"Média","Baixa"))) | L30: =IF(F30=5,"Gravidade máxima","") | N30: =IF(I30="","",I30*1000+F30*100+G30*10+H30)
B31: P17 | I31: =IF(COUNT(F31:H31)<3,"",F31*G31*H31) | J31: =IF(N31="","",RANK(N31,$N$15:$N$34)+COUNTIF($N$14:N30,N31)) | K31: =IF(I31="","",IF(I31>=Escala!$C$14,"Alta",IF(I31>=Escala!$C$15,"Média","Baixa"))) | L31: =IF(F31=5,"Gravidade máxima","") | N31: =IF(I31="","",I31*1000+F31*100+G31*10+H31)
B32: P18 | I32: =IF(COUNT(F32:H32)<3,"",F32*G32*H32) | J32: =IF(N32="","",RANK(N32,$N$15:$N$34)+COUNTIF($N$14:N31,N32)) | K32: =IF(I32="","",IF(I32>=Escala!$C$14,"Alta",IF(I32>=Escala!$C$15,"Média","Baixa"))) | L32: =IF(F32=5,"Gravidade máxima","") | N32: =IF(I32="","",I32*1000+F32*100+G32*10+H32)
B33: P19 | I33: =IF(COUNT(F33:H33)<3,"",F33*G33*H33) | J33: =IF(N33="","",RANK(N33,$N$15:$N$34)+COUNTIF($N$14:N32,N33)) | K33: =IF(I33="","",IF(I33>=Escala!$C$14,"Alta",IF(I33>=Escala!$C$15,"Média","Baixa"))) | L33: =IF(F33=5,"Gravidade máxima","") | N33: =IF(I33="","",I33*1000+F33*100+G33*10+H33)
B34: P20 | I34: =IF(COUNT(F34:H34)<3,"",F34*G34*H34) | J34: =IF(N34="","",RANK(N34,$N$15:$N$34)+COUNTIF($N$14:N33,N34)) | K34: =IF(I34="","",IF(I34>=Escala!$C$14,"Alta",IF(I34>=Escala!$C$15,"Média","Baixa"))) | L34: =IF(F34=5,"Gravidade máxima","") | N34: =IF(I34="","",I34*1000+F34*100+G34*10+H34)
B36: Resumo automático
B37: Problemas listados | F37: =COUNTA(C15:C34) -> 7
B38: Problemas com as três notas | F38: =COUNT(I15:I34) -> 7
B39: Prioridade alta | F39: =COUNTIF(K15:K34,"Alta") -> 1
B40: Prioridade média | F40: =COUNTIF(K15:K34,"Média") -> 4
B41: Prioridade baixa | F41: =COUNTIF(K15:K34,"Baixa") -> 2
B42: Alertas de gravidade máxima | F42: =COUNTIF(F15:F34,5) -> 1
B43: Aviso: notas | F43: =IF(F37=0,"Liste os problemas",IF(F38<F37,"Há problema sem as três notas","OK")) -> OK
...
