Workbook

Sheet Instruções
B1: SWOT — Como usar esta planilha
B2: Modelo para analisar forças, fraquezas, oportunidades e ameaças e transformar o diagnóstico em estratégia.
B4: Legenda: onde preencher
B5: Amarelo-claro | C5: Células de entrada. É aqui que você digita.
B6: Cinza | C6: Células calculadas ou fixas (rótulos, contagens, avisos). Não altere.
B7: Cinza em itálico | C7: Linha de exemplo (marcada com “Ex.”). Mostra o formato esperado e não entra nas contagens.
B8: Listas suspensas | C8: Colunas de código, prioridade e status aceitam apenas as opções da lista. As notas aceitam números de 1 a 5.
B9: Comentários | C9: Células com triângulo vermelho no canto trazem uma dica de preenchimento. Passe o mouse sobre elas.
B11: Os quatro quadrantes
B12: S | C12: Forças: características internas que favorecem o objetivo. A organização controla.
B13: W | C13: Fraquezas: características internas que dificultam o objetivo. A organização controla.
B14: O | C14: Oportunidades: fatos ou tendências do ambiente que podem favorecer o objetivo. A organização não controla.
B15: T | C15: Ameaças: fatos ou tendências do ambiente que podem prejudicar o objetivo. A organização não controla.
B17: Escala das notas
B18: Impacto | C18: Quanto o fator pesa no objetivo. 1 = quase não afeta; 3 = afeta de forma moderada; 5 = decide o resultado.
B19: Intensidade (S e W) | C19: O quanto a característica é marcante hoje. 1 = pouco perceptível; 3 = aparece com frequência; 5 = define a organização.
B20: Intensidade (O e T) | C20: A chance de acontecer no horizonte da análise. 1 = improvável; 3 = pode acontecer ou não; 5 = já está acontecendo.
B21: Pontos | C21: Impacto × intensidade, de 1 a 25. Prioridade alta: 15 ou mais. Média: de 8 a 14. Baixa: até 7.
B23: Ordem recomendada de preenchimento
B24: Passo 1 | C24: Aba SWOT: preencha o cabeçalho, com o objeto, o objetivo e o horizonte da análise.
B25: Passo 2 | C25: Aba SWOT, quadrantes O e T: liste as oportunidades e as ameaças. Comece pelo ambiente externo.
B26: Passo 3 | C26: Aba SWOT, quadrantes S e W: liste as forças e as fraquezas, com fatos que as sustentem.
B27: Passo 4 | C27: Aba SWOT: dê as notas de impacto e de intensidade a cada fator.
B28: Passo 5 | C28: Aba Priorização: veja os fatores em ordem de pontuação. Nada para digitar.
B29: Passo 6 | C29: Aba SWOT cruzada: combine os fatores de alta prioridade pelo código e escreva as estratégias.
B30: Passo 7 | C30: Aba Plano de ação: leve as estratégias escolhidas a ações, com responsável, prazo e indicador.
B31: Passo 8 | C31: Aba Checklist: valide a análise com o grupo e marque a data da próxima revisão.
B33: Abas da planilha
B34: SWOT | C34: Modelo principal. Cabeçalho da análise, quatro quadrantes com notas e resumo automático.
B35: Priorização | C35: Fatores em ordem de pontuação, faixas de prioridade e gráfico dos pontos por quadrante.
B36: SWOT cruzada | C36: Estratégias que combinam um fator interno com um fator externo.
B37: Plano de ação | C37: Ações de cada estratégia, com situação calculada a partir do prazo e do status.
B38: Checklist | C38: Doze verificações de qualidade da análise, com percentual de conclusão.
B39: Exemplo 1 - Pizzaria | C39: Análise preenchida com postura de desenvolvimento: crescer no delivery.
B40: Exemplo 2 - Compras | C40: Análise preenchida com postura de sobrevivência: reduzir o custo de aquisição.
B42: Regras e premissas do modelo
B43: Códigos | C43: Cada fator tem um código fixo, formado pela letra do quadrante e pelo número da linha: S1 a S8, W1 a W8, O1 a O8 e T1 a T8. A aba SWOT cruzada usa esses códigos para buscar o texto dos fatores.
B44: Postura estratégica | C44: A postura compara a soma dos pontos dos quadrantes: forças com fraquezas e oportunidades com ameaças. É uma leitura de apoio, que depende das notas dadas pelo grupo.
B45: Empates | C45: Na aba Priorização, fatores com a mesma pontuação aparecem na ordem dos quadrantes: S, W, O e T.
B46: Ação atrasada | C46: Uma ação é considerada atrasada quando o prazo é anterior à data de hoje e o status não é Concluída nem Cancelada.
...

Sheet SWOT
B1: SWOT — Matriz de análise
B2: Preencha as células em amarelo-claro. As células cinza são calculadas automaticamente.
B4: Objeto da análise | H4: Responsável
B5: Área / unidade | H5: Data
B6: Elaborado por | H6: Versão
B7: Objetivo da análise
B8: Horizonte de tempo | H8: Participantes
B9: Fora do escopo
B11: S | H11: W
B12: Forças (Strengths) · interno, ajuda | H12: Fraquezas (Weaknesses) · interno, atrapalha
B13: O que a organização faz bem e está sob o seu controle? | H13: O que a organização faz mal ou não tem, e poderia mudar?
B14: # | C14: Fator | E14: Impacto | F14: Intensidade | G14: Pontos | H14: # | I14: Fator | K14: Impacto | L14: Intensidade | M14: Pontos
B15: Ex. | C15: Receita própria, elogiada nas avaliações dos clientes | E15: 5 | F15: 4 | G15: 20 | H15: Ex. | I15: Forno único, que limita a produção no horário de pico | K15: 5 | L15: 4 | M15: 20
B16: S1 | G16: =IF(OR(E16="",F16=""),"",E16*F16) | H16: W1 | M16: =IF(OR(K16="",L16=""),"",K16*L16)
B17: S2 | G17: =IF(OR(E17="",F17=""),"",E17*F17) | H17: W2 | M17: =IF(OR(K17="",L17=""),"",K17*L17)
B18: S3 | G18: =IF(OR(E18="",F18=""),"",E18*F18) | H18: W3 | M18: =IF(OR(K18="",L18=""),"",K18*L18)
B19: S4 | G19: =IF(OR(E19="",F19=""),"",E19*F19) | H19: W4 | M19: =IF(OR(K19="",L19=""),"",K19*L19)
B20: S5 | G20: =IF(OR(E20="",F20=""),"",E20*F20) | H20: W5 | M20: =IF(OR(K20="",L20=""),"",K20*L20)
B21: S6 | G21: =IF(OR(E21="",F21=""),"",E21*F21) | H21: W6 | M21: =IF(OR(K21="",L21=""),"",K21*L21)
B22: S7 | G22: =IF(OR(E22="",F22=""),"",E22*F22) | H22: W7 | M22: =IF(OR(K22="",L22=""),"",K22*L22)
B23: S8 | G23: =IF(OR(E23="",F23=""),"",E23*F23) | H23: W8 | M23: =IF(OR(K23="",L23=""),"",K23*L23)
B25: O | H25: T
B26: Oportunidades (Opportunities) · externo, ajuda | H26: Ameaças (Threats) · externo, atrapalha
B27: O que acontece no ambiente e pode favorecer o objetivo? | H27: O que acontece no ambiente e pode prejudicar o objetivo?
B28: # | C28: Fator | E28: Impacto | F28: Intensidade | G28: Pontos | H28: # | I28: Fator | K28: Impacto | L28: Intensidade | M28: Pontos
B29: Ex. | C29: Novos condomínios em construção no bairro | E29: 5 | F29: 4 | G29: 20 | H29: Ex. | I29: Aumento da taxa cobrada pelo aplicativo de delivery | K29: 4 | L29: 4 | M29: 16
B30: O1 | G30: =IF(OR(E30="",F30=""),"",E30*F30) | H30: T1 | M30: =IF(OR(K30="",L30=""),"",K30*L30)
B31: O2 | G31: =IF(OR(E31="",F31=""),"",E31*F31) | H31: T2 | M31: =IF(OR(K31="",L31=""),"",K31*L31)
B32: O3 | G32: =IF(OR(E32="",F32=""),"",E32*F32) | H32: T3 | M32: =IF(OR(K32="",L32=""),"",K32*L32)
B33: O4 | G33: =IF(OR(E33="",F33=""),"",E33*F33) | H33: T4 | M33: =IF(OR(K33="",L33=""),"",K33*L33)
B34: O5 | G34: =IF(OR(E34="",F34=""),"",E34*F34) | H34: T5 | M34: =IF(OR(K34="",L34=""),"",K34*L34)
B35: O6 | G35: =IF(OR(E35="",F35=""),"",E35*F35) | H35: T6 | M35: =IF(OR(K35="",L35=""),"",K35*L35)
B36: O7 | G36: =IF(OR(E36="",F36=""),"",E36*F36) | H36: T7 | M36: =IF(OR(K36="",L36=""),"",K36*L36)
B37: O8 | G37: =IF(OR(E37="",F37=""),"",E37*F37) | H37: T8 | M37: =IF(OR(K37="",L37=""),"",K37*L37)
B39: Resumo automático
B40: Quadrante | E40: S — Forças | H40: W — Fraquezas | J40: O — Oportunidades | K40: T — Ameaças
B41: Fatores listados | E41: =COUNTA(C16:C23) -> 0 | H41: =COUNTA(I16:I23) -> 0 | J41: =COUNTA(C30:C37) -> 0 | K41: =COUNTA(I30:I37) -> 0
B42: Pontos | E42: =SUM(G16:G23) -> 0 | H42: =SUM(M16:M23) -> 0 | J42: =SUM(G30:G37) -> 0 | K42: =SUM(M30:M37) -> 0
B43: Aviso | E43: =IF(E41=0,"Liste os fatores",IF(E41<3,"Poucos fatores: liste ao menos 3",IF(COUNT(G16:G23)<E41,"Há fator sem nota","OK"))) -> Liste os fatores | H43: =IF(H41=0,"Liste os fatores",IF(H41<3,"Poucos fatores: liste ao menos 3",IF(COUNT(M16:M23)<H41,"Há fator sem nota","OK"))) -> Liste os fatores | J43: =IF(J41=0,"Liste os fatores",IF(J41<3,"Poucos fatores: liste ao menos 3",IF(COUNT(G30:G37)<J41,"Há fator sem nota","OK"))) -> Liste os fatores | K43: =IF(K41=0,"Liste os fatores",IF(K41<3,"Poucos fatores: liste ao menos 3",IF(COUNT(M30:M37)<K41,"Há fator sem nota","OK"))) -> Liste os fatores
B44: Balanço interno (forças menos fraquezas) | H44: =E42-H42 -> 0
...

Sheet Priorização
B1: Priorização dos fatores
B2: Esta aba é calculada a partir da aba SWOT. Não há nada para digitar aqui.
B4: Fatores em ordem de pontuação | L4: Apoio ao cálculo (não altere)
B5: Pos. | C5: Código | D5: Quadrante | E5: Fator | F5: Impacto | G5: Intensidade | H5: Pontos | I5: Prioridade | L5: Código | M5: Quadrante | N5: Fator | O5: Impacto | P5: Intensidade | Q5: Pontos | R5: Posição
B6: 1 | C6: =IFERROR(INDEX($L$6:$L$37,MATCH($B6,$R$6:$R$37,0)),"") | D6: =IFERROR(INDEX($M$6:$M$37,MATCH($B6,$R$6:$R$37,0)),"") | E6: =IFERROR(INDEX($N$6:$N$37,MATCH($B6,$R$6:$R$37,0)),"") | F6: =IFERROR(INDEX($O$6:$O$37,MATCH($B6,$R$6:$R$37,0)),"") | G6: =IFERROR(INDEX($P$6:$P$37,MATCH($B6,$R$6:$R$37,0)),"") | H6: =IFERROR(INDEX($Q$6:$Q$37,MATCH($B6,$R$6:$R$37,0)),"") | I6: =IF(H6="","",IF(H6>=15,"Alta",IF(H6>=8,"Média","Baixa"))) | L6: S1 | M6: Forças | N6: =IF(SWOT!C16="","",SWOT!C16) | O6: =IF(SWOT!E16="","",SWOT!E16) | P6: =IF(SWOT!F16="","",SWOT!F16) | Q6: =IF(SWOT!G16="","",SWOT!G16) | R6: =IF(Q6="","",RANK(Q6,$Q$6:$Q$37)+COUNTIF($Q$5:Q5,Q6))
B7: 2 | C7: =IFERROR(INDEX($L$6:$L$37,MATCH($B7,$R$6:$R$37,0)),"") | D7: =IFERROR(INDEX($M$6:$M$37,MATCH($B7,$R$6:$R$37,0)),"") | E7: =IFERROR(INDEX($N$6:$N$37,MATCH($B7,$R$6:$R$37,0)),"") | F7: =IFERROR(INDEX($O$6:$O$37,MATCH($B7,$R$6:$R$37,0)),"") | G7: =IFERROR(INDEX($P$6:$P$37,MATCH($B7,$R$6:$R$37,0)),"") | H7: =IFERROR(INDEX($Q$6:$Q$37,MATCH($B7,$R$6:$R$37,0)),"") | I7: =IF(H7="","",IF(H7>=15,"Alta",IF(H7>=8,"Média","Baixa"))) | L7: S2 | M7: Forças | N7: =IF(SWOT!C17="","",SWOT!C17) | O7: =IF(SWOT!E17="","",SWOT!E17) | P7: =IF(SWOT!F17="","",SWOT!F17) | Q7: =IF(SWOT!G17="","",SWOT!G17) | R7: =IF(Q7="","",RANK(Q7,$Q$6:$Q$37)+COUNTIF($Q$5:Q6,Q7))
B8: 3 | C8: =IFERROR(INDEX($L$6:$L$37,MATCH($B8,$R$6:$R$37,0)),"") | D8: =IFERROR(INDEX($M$6:$M$37,MATCH($B8,$R$6:$R$37,0)),"") | E8: =IFERROR(INDEX($N$6:$N$37,MATCH($B8,$R$6:$R$37,0)),"") | F8: =IFERROR(INDEX($O$6:$O$37,MATCH($B8,$R$6:$R$37,0)),"") | G8: =IFERROR(INDEX($P$6:$P$37,MATCH($B8,$R$6:$R$37,0)),"") | H8: =IFERROR(INDEX($Q$6:$Q$37,MATCH($B8,$R$6:$R$37,0)),"") | I8: =IF(H8="","",IF(H8>=15,"Alta",IF(H8>=8,"Média","Baixa"))) | L8: S3 | M8: Forças | N8: =IF(SWOT!C18="","",SWOT!C18) | O8: =IF(SWOT!E18="","",SWOT!E18) | P8: =IF(SWOT!F18="","",SWOT!F18) | Q8: =IF(SWOT!G18="","",SWOT!G18) | R8: =IF(Q8="","",RANK(Q8,$Q$6:$Q$37)+COUNTIF($Q$5:Q7,Q8))
B9: 4 | C9: =IFERROR(INDEX($L$6:$L$37,MATCH($B9,$R$6:$R$37,0)),"") | D9: =IFERROR(INDEX($M$6:$M$37,MATCH($B9,$R$6:$R$37,0)),"") | E9: =IFERROR(INDEX($N$6:$N$37,MATCH($B9,$R$6:$R$37,0)),"") | F9: =IFERROR(INDEX($O$6:$O$37,MATCH($B9,$R$6:$R$37,0)),"") | G9: =IFERROR(INDEX($P$6:$P$37,MATCH($B9,$R$6:$R$37,0)),"") | H9: =IFERROR(INDEX($Q$6:$Q$37,MATCH($B9,$R$6:$R$37,0)),"") | I9: =IF(H9="","",IF(H9>=15,"Alta",IF(H9>=8,"Média","Baixa"))) | L9: S4 | M9: Forças | N9: =IF(SWOT!C19="","",SWOT!C19) | O9: =IF(SWOT!E19="","",SWOT!E19) | P9: =IF(SWOT!F19="","",SWOT!F19) | Q9: =IF(SWOT!G19="","",SWOT!G19) | R9: =IF(Q9="","",RANK(Q9,$Q$6:$Q$37)+COUNTIF($Q$5:Q8,Q9))
B10: 5 | C10: =IFERROR(INDEX($L$6:$L$37,MATCH($B10,$R$6:$R$37,0)),"") | D10: =IFERROR(INDEX($M$6:$M$37,MATCH($B10,$R$6:$R$37,0)),"") | E10: =IFERROR(INDEX($N$6:$N$37,MATCH($B10,$R$6:$R$37,0)),"") | F10: =IFERROR(INDEX($O$6:$O$37,MATCH($B10,$R$6:$R$37,0)),"") | G10: =IFERROR(INDEX($P$6:$P$37,MATCH($B10,$R$6:$R$37,0)),"") | H10: =IFERROR(INDEX($Q$6:$Q$37,MATCH($B10,$R$6:$R$37,0)),"") | I10: =IF(H10="","",IF(H10>=15,"Alta",IF(H10>=8,"Média","Baixa"))) | L10: S5 | M10: Forças | N10: =IF(SWOT!C20="","",SWOT!C20) | O10: =IF(SWOT!E20="","",SWOT!E20) | P10: =IF(SWOT!F20="","",SWOT!F20) | Q10: =IF(SWOT!G20="","",SWOT!G20) | R10: =IF(Q10="","",RANK(Q10,$Q$6:$Q$37)+COUNTIF($Q$5:Q9,Q10))
B11: 6 | C11: =IFERROR(INDEX($L$6:$L$37,MATCH($B11,$R$6:$R$37,0)),"") | D11: =IFERROR(INDEX($M$6:$M$37,MATCH($B11,$R$6:$R$37,0)),"") | E11: =IFERROR(INDEX($N$6:$N$37,MATCH($B11,$R$6:$R$37,0)),"") | F11: =IFERROR(INDEX($O$6:$O$37,MATCH($B11,$R$6:$R$37,0)),"") | G11: =IFERROR(INDEX($P$6:$P$37,MATCH($B11,$R$6:$R$37,0)),"") | H11: =IFERROR(INDEX($Q$6:$Q$37,MATCH($B11,$R$6:$R$37,0)),"") | I11: =IF(H11="","",IF(H11>=15,"Alta",IF(H11>=8,"Média","Baixa"))) | L11: S6 | M11: Forças | N11: =IF(SWOT!C21="","",SWOT!C21) | O11: =IF(SWOT!E21="","",SWOT!E21) | P11: =IF(SWOT!F21="","",SWOT!F21) | Q11: =IF(SWOT!G21="","",SWOT!G21) | R11: =IF(Q11="","",RANK(Q11,$Q$6:$Q$37)+COUNTIF($Q$5:Q10,Q11))
B12: 7 | C12: =IFERROR(INDEX($L$6:$L$37,MATCH($B12,$R$6:$R$37,0)),"") | D12: =IFERROR(INDEX($M$6:$M$37,MATCH($B12,$R$6:$R$37,0)),"") | E12: =IFERROR(INDEX($N$6:$N$37,MATCH($B12,$R$6:$R$37,0)),"") | F12: =IFERROR(INDEX($O$6:$O$37,MATCH($B12,$R$6:$R$37,0)),"") | G12: =IFERROR(INDEX($P$6:$P$37,MATCH($B12,$R$6:$R$37,0)),"") | H12: =IFERROR(INDEX($Q$6:$Q$37,MATCH($B12,$R$6:$R$37,0)),"") | I12: =IF(H12="","",IF(H12>=15,"Alta",IF(H12>=8,"Média","Baixa"))) | L12: S7 | M12: Forças | N12: =IF(SWOT!C22="","",SWOT!C22) | O12: =IF(SWOT!E22="","",SWOT!E22) | P12: =IF(SWOT!F22="","",SWOT!F22) | Q12: =IF(SWOT!G22="","",SWOT!G22) | R12: =IF(Q12="","",RANK(Q12,$Q$6:$Q$37)+COUNTIF($Q$5:Q11,Q12))
B13: 8 | C13: =IFERROR(INDEX($L$6:$L$37,MATCH($B13,$R$6:$R$37,0)),"") | D13: =IFERROR(INDEX($M$6:$M$37,MATCH($B13,$R$6:$R$37,0)),"") | E13: =IFERROR(INDEX($N$6:$N$37,MATCH($B13,$R$6:$R$37,0)),"") | F13: =IFERROR(INDEX($O$6:$O$37,MATCH($B13,$R$6:$R$37,0)),"") | G13: =IFERROR(INDEX($P$6:$P$37,MATCH($B13,$R$6:$R$37,0)),"") | H13: =IFERROR(INDEX($Q$6:$Q$37,MATCH($B13,$R$6:$R$37,0)),"") | I13: =IF(H13="","",IF(H13>=15,"Alta",IF(H13>=8,"Média","Baixa"))) | L13: S8 | M13: Forças | N13: =IF(SWOT!C23="","",SWOT!C23) | O13: =IF(SWOT!E23="","",SWOT!E23) | P13: =IF(SWOT!F23="","",SWOT!F23) | Q13: =IF(SWOT!G23="","",SWOT!G23) | R13: =IF(Q13="","",RANK(Q13,$Q$6:$Q$37)+COUNTIF($Q$5:Q12,Q13))
B14: 9 | C14: =IFERROR(INDEX($L$6:$L$37,MATCH($B14,$R$6:$R$37,0)),"") | D14: =IFERROR(INDEX($M$6:$M$37,MATCH($B14,$R$6:$R$37,0)),"") | E14: =IFERROR(INDEX($N$6:$N$37,MATCH($B14,$R$6:$R$37,0)),"") | F14: =IFERROR(INDEX($O$6:$O$37,MATCH($B14,$R$6:$R$37,0)),"") | G14: =IFERROR(INDEX($P$6:$P$37,MATCH($B14,$R$6:$R$37,0)),"") | H14: =IFERROR(INDEX($Q$6:$Q$37,MATCH($B14,$R$6:$R$37,0)),"") | I14: =IF(H14="","",IF(H14>=15,"Alta",IF(H14>=8,"Média","Baixa"))) | L14: W1 | M14: Fraquezas | N14: =IF(SWOT!I16="","",SWOT!I16) | O14: =IF(SWOT!K16="","",SWOT!K16) | P14: =IF(SWOT!L16="","",SWOT!L16) | Q14: =IF(SWOT!M16="","",SWOT!M16) | R14: =IF(Q14="","",RANK(Q14,$Q$6:$Q$37)+COUNTIF($Q$5:Q13,Q14))
B15: 10 | C15: =IFERROR(INDEX($L$6:$L$37,MATCH($B15,$R$6:$R$37,0)),"") | D15: =IFERROR(INDEX($M$6:$M$37,MATCH($B15,$R$6:$R$37,0)),"") | E15: =IFERROR(INDEX($N$6:$N$37,MATCH($B15,$R$6:$R$37,0)),"") | F15: =IFERROR(INDEX($O$6:$O$37,MATCH($B15,$R$6:$R$37,0)),"") | G15: =IFERROR(INDEX($P$6:$P$37,MATCH($B15,$R$6:$R$37,0)),"") | H15: =IFERROR(INDEX($Q$6:$Q$37,MATCH($B15,$R$6:$R$37,0)),"") | I15: =IF(H15="","",IF(H15>=15,"Alta",IF(H15>=8,"Média","Baixa"))) | L15: W2 | M15: Fraquezas | N15: =IF(SWOT!I17="","",SWOT!I17) | O15: =IF(SWOT!K17="","",SWOT!K17) | P15: =IF(SWOT!L17="","",SWOT!L17) | Q15: =IF(SWOT!M17="","",SWOT!M17) | R15: =IF(Q15="","",RANK(Q15,$Q$6:$Q$37)+COUNTIF($Q$5:Q14,Q15))
B16: 11 | C16: =IFERROR(INDEX($L$6:$L$37,MATCH($B16,$R$6:$R$37,0)),"") | D16: =IFERROR(INDEX($M$6:$M$37,MATCH($B16,$R$6:$R$37,0)),"") | E16: =IFERROR(INDEX($N$6:$N$37,MATCH($B16,$R$6:$R$37,0)),"") | F16: =IFERROR(INDEX($O$6:$O$37,MATCH($B16,$R$6:$R$37,0)),"") | G16: =IFERROR(INDEX($P$6:$P$37,MATCH($B16,$R$6:$R$37,0)),"") | H16: =IFERROR(INDEX($Q$6:$Q$37,MATCH($B16,$R$6:$R$37,0)),"") | I16: =IF(H16="","",IF(H16>=15,"Alta",IF(H16>=8,"Média","Baixa"))) | L16: W3 | M16: Fraquezas | N16: =IF(SWOT!I18="","",SWOT!I18) | O16: =IF(SWOT!K18="","",SWOT!K18) | P16: =IF(SWOT!L18="","",SWOT!L18) | Q16: =IF(SWOT!M18="","",SWOT!M18) | R16: =IF(Q16="","",RANK(Q16,$Q$6:$Q$37)+COUNTIF($Q$5:Q15,Q16))
B17: 12 | C17: =IFERROR(INDEX($L$6:$L$37,MATCH($B17,$R$6:$R$37,0)),"") | D17: =IFERROR(INDEX($M$6:$M$37,MATCH($B17,$R$6:$R$37,0)),"") | E17: =IFERROR(INDEX($N$6:$N$37,MATCH($B17,$R$6:$R$37,0)),"") | F17: =IFERROR(INDEX($O$6:$O$37,MATCH($B17,$R$6:$R$37,0)),"") | G17: =IFERROR(INDEX($P$6:$P$37,MATCH($B17,$R$6:$R$37,0)),"") | H17: =IFERROR(INDEX($Q$6:$Q$37,MATCH($B17,$R$6:$R$37,0)),"") | I17: =IF(H17="","",IF(H17>=15,"Alta",IF(H17>=8,"Média","Baixa"))) | L17: W4 | M17: Fraquezas | N17: =IF(SWOT!I19="","",SWOT!I19) | O17: =IF(SWOT!K19="","",SWOT!K19) | P17: =IF(SWOT!L19="","",SWOT!L19) | Q17: =IF(SWOT!M19="","",SWOT!M19) | R17: =IF(Q17="","",RANK(Q17,$Q$6:$Q$37)+COUNTIF($Q$5:Q16,Q17))
B18: 13 | C18: =IFERROR(INDEX($L$6:$L$37,MATCH($B18,$R$6:$R$37,0)),"") | D18: =IFERROR(INDEX($M$6:$M$37,MATCH($B18,$R$6:$R$37,0)),"") | E18: =IFERROR(INDEX($N$6:$N$37,MATCH($B18,$R$6:$R$37,0)),"") | F18: =IFERROR(INDEX($O$6:$O$37,MATCH($B18,$R$6:$R$37,0)),"") | G18: =IFERROR(INDEX($P$6:$P$37,MATCH($B18,$R$6:$R$37,0)),"") | H18: =IFERROR(INDEX($Q$6:$Q$37,MATCH($B18,$R$6:$R$37,0)),"") | I18: =IF(H18="","",IF(H18>=15,"Alta",IF(H18>=8,"Média","Baixa"))) | L18: W5 | M18: Fraquezas | N18: =IF(SWOT!I20="","",SWOT!I20) | O18: =IF(SWOT!K20="","",SWOT!K20) | P18: =IF(SWOT!L20="","",SWOT!L20) | Q18: =IF(SWOT!M20="","",SWOT!M20) | R18: =IF(Q18="","",RANK(Q18,$Q$6:$Q$37)+COUNTIF($Q$5:Q17,Q18))
B19: 14 | C19: =IFERROR(INDEX($L$6:$L$37,MATCH($B19,$R$6:$R$37,0)),"") | D19: =IFERROR(INDEX($M$6:$M$37,MATCH($B19,$R$6:$R$37,0)),"") | E19: =IFERROR(INDEX($N$6:$N$37,MATCH($B19,$R$6:$R$37,0)),"") | F19: =IFERROR(INDEX($O$6:$O$37,MATCH($B19,$R$6:$R$37,0)),"") | G19: =IFERROR(INDEX($P$6:$P$37,MATCH($B19,$R$6:$R$37,0)),"") | H19: =IFERROR(INDEX($Q$6:$Q$37,MATCH($B19,$R$6:$R$37,0)),"") | I19: =IF(H19="","",IF(H19>=15,"Alta",IF(H19>=8,"Média","Baixa"))) | L19: W6 | M19: Fraquezas | N19: =IF(SWOT!I21="","",SWOT!I21) | O19: =IF(SWOT!K21="","",SWOT!K21) | P19: =IF(SWOT!L21="","",SWOT!L21) | Q19: =IF(SWOT!M21="","",SWOT!M21) | R19: =IF(Q19="","",RANK(Q19,$Q$6:$Q$37)+COUNTIF($Q$5:Q18,Q19))
B20: 15 | C20: =IFERROR(INDEX($L$6:$L$37,MATCH($B20,$R$6:$R$37,0)),"") | D20: =IFERROR(INDEX($M$6:$M$37,MATCH($B20,$R$6:$R$37,0)),"") | E20: =IFERROR(INDEX($N$6:$N$37,MATCH($B20,$R$6:$R$37,0)),"") | F20: =IFERROR(INDEX($O$6:$O$37,MATCH($B20,$R$6:$R$37,0)),"") | G20: =IFERROR(INDEX($P$6:$P$37,MATCH($B20,$R$6:$R$37,0)),"") | H20: =IFERROR(INDEX($Q$6:$Q$37,MATCH($B20,$R$6:$R$37,0)),"") | I20: =IF(H20="","",IF(H20>=15,"Alta",IF(H20>=8,"Média","Baixa"))) | L20: W7 | M20: Fraquezas | N20: =IF(SWOT!I22="","",SWOT!I22) | O20: =IF(SWOT!K22="","",SWOT!K22) | P20: =IF(SWOT!L22="","",SWOT!L22) | Q20: =IF(SWOT!M22="","",SWOT!M22) | R20: =IF(Q20="","",RANK(Q20,$Q$6:$Q$37)+COUNTIF($Q$5:Q19,Q20))
B21: 16 | C21: =IFERROR(INDEX($L$6:$L$37,MATCH($B21,$R$6:$R$37,0)),"") | D21: =IFERROR(INDEX($M$6:$M$37,MATCH($B21,$R$6:$R$37,0)),"") | E21: =IFERROR(INDEX($N$6:$N$37,MATCH($B21,$R$6:$R$37,0)),"") | F21: =IFERROR(INDEX($O$6:$O$37,MATCH($B21,$R$6:$R$37,0)),"") | G21: =IFERROR(INDEX($P$6:$P$37,MATCH($B21,$R$6:$R$37,0)),"") | H21: =IFERROR(INDEX($Q$6:$Q$37,MATCH($B21,$R$6:$R$37,0)),"") | I21: =IF(H21="","",IF(H21>=15,"Alta",IF(H21>=8,"Média","Baixa"))) | L21: W8 | M21: Fraquezas | N21: =IF(SWOT!I23="","",SWOT!I23) | O21: =IF(SWOT!K23="","",SWOT!K23) | P21: =IF(SWOT!L23="","",SWOT!L23) | Q21: =IF(SWOT!M23="","",SWOT!M23) | R21: =IF(Q21="","",RANK(Q21,$Q$6:$Q$37)+COUNTIF($Q$5:Q20,Q21))
B22: 17 | C22: =IFERROR(INDEX($L$6:$L$37,MATCH($B22,$R$6:$R$37,0)),"") | D22: =IFERROR(INDEX($M$6:$M$37,MATCH($B22,$R$6:$R$37,0)),"") | E22: =IFERROR(INDEX($N$6:$N$37,MATCH($B22,$R$6:$R$37,0)),"") | F22: =IFERROR(INDEX($O$6:$O$37,MATCH($B22,$R$6:$R$37,0)),"") | G22: =IFERROR(INDEX($P$6:$P$37,MATCH($B22,$R$6:$R$37,0)),"") | H22: =IFERROR(INDEX($Q$6:$Q$37,MATCH($B22,$R$6:$R$37,0)),"") | I22: =IF(H22="","",IF(H22>=15,"Alta",IF(H22>=8,"Média","Baixa"))) | L22: O1 | M22: Oportunidades | N22: =IF(SWOT!C30="","",SWOT!C30) | O22: =IF(SWOT!E30="","",SWOT!E30) | P22: =IF(SWOT!F30="","",SWOT!F30) | Q22: =IF(SWOT!G30="","",SWOT!G30) | R22: =IF(Q22="","",RANK(Q22,$Q$6:$Q$37)+COUNTIF($Q$5:Q21,Q22))
B23: 18 | C23: =IFERROR(INDEX($L$6:$L$37,MATCH($B23,$R$6:$R$37,0)),"") | D23: =IFERROR(INDEX($M$6:$M$37,MATCH($B23,$R$6:$R$37,0)),"") | E23: =IFERROR(INDEX($N$6:$N$37,MATCH($B23,$R$6:$R$37,0)),"") | F23: =IFERROR(INDEX($O$6:$O$37,MATCH($B23,$R$6:$R$37,0)),"") | G23: =IFERROR(INDEX($P$6:$P$37,MATCH($B23,$R$6:$R$37,0)),"") | H23: =IFERROR(INDEX($Q$6:$Q$37,MATCH($B23,$R$6:$R$37,0)),"") | I23: =IF(H23="","",IF(H23>=15,"Alta",IF(H23>=8,"Média","Baixa"))) | L23: O2 | M23: Oportunidades | N23: =IF(SWOT!C31="","",SWOT!C31) | O23: =IF(SWOT!E31="","",SWOT!E31) | P23: =IF(SWOT!F31="","",SWOT!F31) | Q23: =IF(SWOT!G31="","",SWOT!G31) | R23: =IF(Q23="","",RANK(Q23,$Q$6:$Q$37)+COUNTIF($Q$5:Q22,Q23))
B24: 19 | C24: =IFERROR(INDEX($L$6:$L$37,MATCH($B24,$R$6:$R$37,0)),"") | D24: =IFERROR(INDEX($M$6:$M$37,MATCH($B24,$R$6:$R$37,0)),"") | E24: =IFERROR(INDEX($N$6:$N$37,MATCH($B24,$R$6:$R$37,0)),"") | F24: =IFERROR(INDEX($O$6:$O$37,MATCH($B24,$R$6:$R$37,0)),"") | G24: =IFERROR(INDEX($P$6:$P$37,MATCH($B24,$R$6:$R$37,0)),"") | H24: =IFERROR(INDEX($Q$6:$Q$37,MATCH($B24,$R$6:$R$37,0)),"") | I24: =IF(H24="","",IF(H24>=15,"Alta",IF(H24>=8,"Média","Baixa"))) | L24: O3 | M24: Oportunidades | N24: =IF(SWOT!C32="","",SWOT!C32) | O24: =IF(SWOT!E32="","",SWOT!E32) | P24: =IF(SWOT!F32="","",SWOT!F32) | Q24: =IF(SWOT!G32="","",SWOT!G32) | R24: =IF(Q24="","",RANK(Q24,$Q$6:$Q$37)+COUNTIF($Q$5:Q23,Q24))
B25: 20 | C25: =IFERROR(INDEX($L$6:$L$37,MATCH($B25,$R$6:$R$37,0)),"") | D25: =IFERROR(INDEX($M$6:$M$37,MATCH($B25,$R$6:$R$37,0)),"") | E25: =IFERROR(INDEX($N$6:$N$37,MATCH($B25,$R$6:$R$37,0)),"") | F25: =IFERROR(INDEX($O$6:$O$37,MATCH($B25,$R$6:$R$37,0)),"") | G25: =IFERROR(INDEX($P$6:$P$37,MATCH($B25,$R$6:$R$37,0)),"") | H25: =IFERROR(INDEX($Q$6:$Q$37,MATCH($B25,$R$6:$R$37,0)),"") | I25: =IF(H25="","",IF(H25>=15,"Alta",IF(H25>=8,"Média","Baixa"))) | L25: O4 | M25: Oportunidades | N25: =IF(SWOT!C33="","",SWOT!C33) | O25: =IF(SWOT!E33="","",SWOT!E33) | P25: =IF(SWOT!F33="","",SWOT!F33) | Q25: =IF(SWOT!G33="","",SWOT!G33) | R25: =IF(Q25="","",RANK(Q25,$Q$6:$Q$37)+COUNTIF($Q$5:Q24,Q25))
B26: 21 | C26: =IFERROR(INDEX($L$6:$L$37,MATCH($B26,$R$6:$R$37,0)),"") | D26: =IFERROR(INDEX($M$6:$M$37,MATCH($B26,$R$6:$R$37,0)),"") | E26: =IFERROR(INDEX($N$6:$N$37,MATCH($B26,$R$6:$R$37,0)),"") | F26: =IFERROR(INDEX($O$6:$O$37,MATCH($B26,$R$6:$R$37,0)),"") | G26: =IFERROR(INDEX($P$6:$P$37,MATCH($B26,$R$6:$R$37,0)),"") | H26: =IFERROR(INDEX($Q$6:$Q$37,MATCH($B26,$R$6:$R$37,0)),"") | I26: =IF(H26="","",IF(H26>=15,"Alta",IF(H26>=8,"Média","Baixa"))) | L26: O5 | M26: Oportunidades | N26: =IF(SWOT!C34="","",SWOT!C34) | O26: =IF(SWOT!E34="","",SWOT!E34) | P26: =IF(SWOT!F34="","",SWOT!F34) | Q26: =IF(SWOT!G34="","",SWOT!G34) | R26: =IF(Q26="","",RANK(Q26,$Q$6:$Q$37)+COUNTIF($Q$5:Q25,Q26))
B27: 22 | C27: =IFERROR(INDEX($L$6:$L$37,MATCH($B27,$R$6:$R$37,0)),"") | D27: =IFERROR(INDEX($M$6:$M$37,MATCH($B27,$R$6:$R$37,0)),"") | E27: =IFERROR(INDEX($N$6:$N$37,MATCH($B27,$R$6:$R$37,0)),"") | F27: =IFERROR(INDEX($O$6:$O$37,MATCH($B27,$R$6:$R$37,0)),"") | G27: =IFERROR(INDEX($P$6:$P$37,MATCH($B27,$R$6:$R$37,0)),"") | H27: =IFERROR(INDEX($Q$6:$Q$37,MATCH($B27,$R$6:$R$37,0)),"") | I27: =IF(H27="","",IF(H27>=15,"Alta",IF(H27>=8,"Média","Baixa"))) | L27: O6 | M27: Oportunidades | N27: =IF(SWOT!C35="","",SWOT!C35) | O27: =IF(SWOT!E35="","",SWOT!E35) | P27: =IF(SWOT!F35="","",SWOT!F35) | Q27: =IF(SWOT!G35="","",SWOT!G35) | R27: =IF(Q27="","",RANK(Q27,$Q$6:$Q$37)+COUNTIF($Q$5:Q26,Q27))
B28: 23 | C28: =IFERROR(INDEX($L$6:$L$37,MATCH($B28,$R$6:$R$37,0)),"") | D28: =IFERROR(INDEX($M$6:$M$37,MATCH($B28,$R$6:$R$37,0)),"") | E28: =IFERROR(INDEX($N$6:$N$37,MATCH($B28,$R$6:$R$37,0)),"") | F28: =IFERROR(INDEX($O$6:$O$37,MATCH($B28,$R$6:$R$37,0)),"") | G28: =IFERROR(INDEX($P$6:$P$37,MATCH($B28,$R$6:$R$37,0)),"") | H28: =IFERROR(INDEX($Q$6:$Q$37,MATCH($B28,$R$6:$R$37,0)),"") | I28: =IF(H28="","",IF(H28>=15,"Alta",IF(H28>=8,"Média","Baixa"))) | L28: O7 | M28: Oportunidades | N28: =IF(SWOT!C36="","",SWOT!C36) | O28: =IF(SWOT!E36="","",SWOT!E36) | P28: =IF(SWOT!F36="","",SWOT!F36) | Q28: =IF(SWOT!G36="","",SWOT!G36) | R28: =IF(Q28="","",RANK(Q28,$Q$6:$Q$37)+COUNTIF($Q$5:Q27,Q28))
B29: 24 | C29: =IFERROR(INDEX($L$6:$L$37,MATCH($B29,$R$6:$R$37,0)),"") | D29: =IFERROR(INDEX($M$6:$M$37,MATCH($B29,$R$6:$R$37,0)),"") | E29: =IFERROR(INDEX($N$6:$N$37,MATCH($B29,$R$6:$R$37,0)),"") | F29: =IFERROR(INDEX($O$6:$O$37,MATCH($B29,$R$6:$R$37,0)),"") | G29: =IFERROR(INDEX($P$6:$P$37,MATCH($B29,$R$6:$R$37,0)),"") | H29: =IFERROR(INDEX($Q$6:$Q$37,MATCH($B29,$R$6:$R$37,0)),"") | I29: =IF(H29="","",IF(H29>=15,"Alta",IF(H29>=8,"Média","Baixa"))) | L29: O8 | M29: Oportunidades | N29: =IF(SWOT!C37="","",SWOT!C37) | O29: =IF(SWOT!E37="","",SWOT!E37) | P29: =IF(SWOT!F37="","",SWOT!F37) | Q29: =IF(SWOT!G37="","",SWOT!G37) | R29: =IF(Q29="","",RANK(Q29,$Q$6:$Q$37)+COUNTIF($Q$5:Q28,Q29))
B30: 25 | C30: =IFERROR(INDEX($L$6:$L$37,MATCH($B30,$R$6:$R$37,0)),"") | D30: =IFERROR(INDEX($M$6:$M$37,MATCH($B30,$R$6:$R$37,0)),"") | E30: =IFERROR(INDEX($N$6:$N$37,MATCH($B30,$R$6:$R$37,0)),"") | F30: =IFERROR(INDEX($O$6:$O$37,MATCH($B30,$R$6:$R$37,0)),"") | G30: =IFERROR(INDEX($P$6:$P$37,MATCH($B30,$R$6:$R$37,0)),"") | H30: =IFERROR(INDEX($Q$6:$Q$37,MATCH($B30,$R$6:$R$37,0)),"") | I30: =IF(H30="","",IF(H30>=15,"Alta",IF(H30>=8,"Média","Baixa"))) | L30: T1 | M30: Ameaças | N30: =IF(SWOT!I30="","",SWOT!I30) | O30: =IF(SWOT!K30="","",SWOT!K30) | P30: =IF(SWOT!L30="","",SWOT!L30) | Q30: =IF(SWOT!M30="","",SWOT!M30) | R30: =IF(Q30="","",RANK(Q30,$Q$6:$Q$37)+COUNTIF($Q$5:Q29,Q30))
B31: 26 | C31: =IFERROR(INDEX($L$6:$L$37,MATCH($B31,$R$6:$R$37,0)),"") | D31: =IFERROR(INDEX($M$6:$M$37,MATCH($B31,$R$6:$R$37,0)),"") | E31: =IFERROR(INDEX($N$6:$N$37,MATCH($B31,$R$6:$R$37,0)),"") | F31: =IFERROR(INDEX($O$6:$O$37,MATCH($B31,$R$6:$R$37,0)),"") | G31: =IFERROR(INDEX($P$6:$P$37,MATCH($B31,$R$6:$R$37,0)),"") | H31: =IFERROR(INDEX($Q$6:$Q$37,MATCH($B31,$R$6:$R$37,0)),"") | I31: =IF(H31="","",IF(H31>=15,"Alta",IF(H31>=8,"Média","Baixa"))) | L31: T2 | M31: Ameaças | N31: =IF(SWOT!I31="","",SWOT!I31) | O31: =IF(SWOT!K31="","",SWOT!K31) | P31: =IF(SWOT!L31="","",SWOT!L31) | Q31: =IF(SWOT!M31="","",SWOT!M31) | R31: =IF(Q31="","",RANK(Q31,$Q$6:$Q$37)+COUNTIF($Q$5:Q30,Q31))
B32: 27 | C32: =IFERROR(INDEX($L$6:$L$37,MATCH($B32,$R$6:$R$37,0)),"") | D32: =IFERROR(INDEX($M$6:$M$37,MATCH($B32,$R$6:$R$37,0)),"") | E32: =IFERROR(INDEX($N$6:$N$37,MATCH($B32,$R$6:$R$37,0)),"") | F32: =IFERROR(INDEX($O$6:$O$37,MATCH($B32,$R$6:$R$37,0)),"") | G32: =IFERROR(INDEX($P$6:$P$37,MATCH($B32,$R$6:$R$37,0)),"") | H32: =IFERROR(INDEX($Q$6:$Q$37,MATCH($B32,$R$6:$R$37,0)),"") | I32: =IF(H32="","",IF(H32>=15,"Alta",IF(H32>=8,"Média","Baixa"))) | L32: T3 | M32: Ameaças | N32: =IF(SWOT!I32="","",SWOT!I32) | O32: =IF(SWOT!K32="","",SWOT!K32) | P32: =IF(SWOT!L32="","",SWOT!L32) | Q32: =IF(SWOT!M32="","",SWOT!M32) | R32: =IF(Q32="","",RANK(Q32,$Q$6:$Q$37)+COUNTIF($Q$5:Q31,Q32))
B33: 28 | C33: =IFERROR(INDEX($L$6:$L$37,MATCH($B33,$R$6:$R$37,0)),"") | D33: =IFERROR(INDEX($M$6:$M$37,MATCH($B33,$R$6:$R$37,0)),"") | E33: =IFERROR(INDEX($N$6:$N$37,MATCH($B33,$R$6:$R$37,0)),"") | F33: =IFERROR(INDEX($O$6:$O$37,MATCH($B33,$R$6:$R$37,0)),"") | G33: =IFERROR(INDEX($P$6:$P$37,MATCH($B33,$R$6:$R$37,0)),"") | H33: =IFERROR(INDEX($Q$6:$Q$37,MATCH($B33,$R$6:$R$37,0)),"") | I33: =IF(H33="","",IF(H33>=15,"Alta",IF(H33>=8,"Média","Baixa"))) | L33: T4 | M33: Ameaças | N33: =IF(SWOT!I33="","",SWOT!I33) | O33: =IF(SWOT!K33="","",SWOT!K33) | P33: =IF(SWOT!L33="","",SWOT!L33) | Q33: =IF(SWOT!M33="","",SWOT!M33) | R33: =IF(Q33="","",RANK(Q33,$Q$6:$Q$37)+COUNTIF($Q$5:Q32,Q33))
B34: 29 | C34: =IFERROR(INDEX($L$6:$L$37,MATCH($B34,$R$6:$R$37,0)),"") | D34: =IFERROR(INDEX($M$6:$M$37,MATCH($B34,$R$6:$R$37,0)),"") | E34: =IFERROR(INDEX($N$6:$N$37,MATCH($B34,$R$6:$R$37,0)),"") | F34: =IFERROR(INDEX($O$6:$O$37,MATCH($B34,$R$6:$R$37,0)),"") | G34: =IFERROR(INDEX($P$6:$P$37,MATCH($B34,$R$6:$R$37,0)),"") | H34: =IFERROR(INDEX($Q$6:$Q$37,MATCH($B34,$R$6:$R$37,0)),"") | I34: =IF(H34="","",IF(H34>=15,"Alta",IF(H34>=8,"Média","Baixa"))) | L34: T5 | M34: Ameaças | N34: =IF(SWOT!I34="","",SWOT!I34) | O34: =IF(SWOT!K34="","",SWOT!K34) | P34: =IF(SWOT!L34="","",SWOT!L34) | Q34: =IF(SWOT!M34="","",SWOT!M34) | R34: =IF(Q34="","",RANK(Q34,$Q$6:$Q$37)+COUNTIF($Q$5:Q33,Q34))
B35: 30 | C35: =IFERROR(INDEX($L$6:$L$37,MATCH($B35,$R$6:$R$37,0)),"") | D35: =IFERROR(INDEX($M$6:$M$37,MATCH($B35,$R$6:$R$37,0)),"") | E35: =IFERROR(INDEX($N$6:$N$37,MATCH($B35,$R$6:$R$37,0)),"") | F35: =IFERROR(INDEX($O$6:$O$37,MATCH($B35,$R$6:$R$37,0)),"") | G35: =IFERROR(INDEX($P$6:$P$37,MATCH($B35,$R$6:$R$37,0)),"") | H35: =IFERROR(INDEX($Q$6:$Q$37,MATCH($B35,$R$6:$R$37,0)),"") | I35: =IF(H35="","",IF(H35>=15,"Alta",IF(H35>=8,"Média","Baixa"))) | L35: T6 | M35: Ameaças | N35: =IF(SWOT!I35="","",SWOT!I35) | O35: =IF(SWOT!K35="","",SWOT!K35) | P35: =IF(SWOT!L35="","",SWOT!L35) | Q35: =IF(SWOT!M35="","",SWOT!M35) | R35: =IF(Q35="","",RANK(Q35,$Q$6:$Q$37)+COUNTIF($Q$5:Q34,Q35))
B36: 31 | C36: =IFERROR(INDEX($L$6:$L$37,MATCH($B36,$R$6:$R$37,0)),"") | D36: =IFERROR(INDEX($M$6:$M$37,MATCH($B36,$R$6:$R$37,0)),"") | E36: =IFERROR(INDEX($N$6:$N$37,MATCH($B36,$R$6:$R$37,0)),"") | F36: =IFERROR(INDEX($O$6:$O$37,MATCH($B36,$R$6:$R$37,0)),"") | G36: =IFERROR(INDEX($P$6:$P$37,MATCH($B36,$R$6:$R$37,0)),"") | H36: =IFERROR(INDEX($Q$6:$Q$37,MATCH($B36,$R$6:$R$37,0)),"") | I36: =IF(H36="","",IF(H36>=15,"Alta",IF(H36>=8,"Média","Baixa"))) | L36: T7 | M36: Ameaças | N36: =IF(SWOT!I36="","",SWOT!I36) | O36: =IF(SWOT!K36="","",SWOT!K36) | P36: =IF(SWOT!L36="","",SWOT!L36) | Q36: =IF(SWOT!M36="","",SWOT!M36) | R36: =IF(Q36="","",RANK(Q36,$Q$6:$Q$37)+COUNTIF($Q$5:Q35,Q36))
B37: 32 | C37: =IFERROR(INDEX($L$6:$L$37,MATCH($B37,$R$6:$R$37,0)),"") | D37: =IFERROR(INDEX($M$6:$M$37,MATCH($B37,$R$6:$R$37,0)),"") | E37: =IFERROR(INDEX($N$6:$N$37,MATCH($B37,$R$6:$R$37,0)),"") | F37: =IFERROR(INDEX($O$6:$O$37,MATCH($B37,$R$6:$R$37,0)),"") | G37: =IFERROR(INDEX($P$6:$P$37,MATCH($B37,$R$6:$R$37,0)),"") | H37: =IFERROR(INDEX($Q$6:$Q$37,MATCH($B37,$R$6:$R$37,0)),"") | I37: =IF(H37="","",IF(H37>=15,"Alta",IF(H37>=8,"Média","Baixa"))) | L37: T8 | M37: Ameaças | N37: =IF(SWOT!I37="","",SWOT!I37) | O37: =IF(SWOT!K37="","",SWOT!K37) | P37: =IF(SWOT!L37="","",SWOT!L37) | Q37: =IF(SWOT!M37="","",SWOT!M37) | R37: =IF(Q37="","",RANK(Q37,$Q$6:$Q$37)+COUNTIF($Q$5:Q36,Q37))
B39: Resumo automático
B40: Fatores com pontuação | F40: =COUNT(H6:H37) -> 0
B41: Prioridade alta (15 pontos ou mais) | F41: =COUNTIF(I6:I37,"Alta") -> 0
B42: Prioridade média (de 8 a 14 pontos) | F42: =COUNTIF(I6:I37,"Média") -> 0
...

Sheet SWOT cruzada
B1: SWOT cruzada — estratégias
B2: Escolha o código de um fator interno e de um fator externo. O texto dos fatores vem da aba SWOT.
B4: # | C4: Interno | D4: Fator interno | E4: Externo | F4: Fator externo | G4: Cruzamento | H4: Estratégia | I4: Prioridade
B5: Ex. | C5: W2 | D5: Dependência de um aplicativo para 70% dos pedidos | E5: O4 | F5: Pedido por aplicativo de mensagens, com custo menor por venda | G5: WO — Crescimento | H5: Levar 30% dos pedidos do aplicativo para o canal próprio | I5: Alta
B6: 1 | D6: =IF(C6="","",IF(LEFT(C6,1)="S",INDEX(SWOT!$C$16:$C$23,VALUE(MID(C6,2,1))),INDEX(SWOT!$I$16:$I$23,VALUE(MID(C6,2,1))))&"") | F6: =IF(E6="","",IF(LEFT(E6,1)="O",INDEX(SWOT!$C$30:$C$37,VALUE(MID(E6,2,1))),INDEX(SWOT!$I$30:$I$37,VALUE(MID(E6,2,1))))&"") | G6: =IF(OR(C6="",E6=""),"",LEFT(C6,1)&LEFT(E6,1)&" — "&IF(LEFT(C6,1)="S",IF(LEFT(E6,1)="O","Desenvolvimento","Manutenção"),IF(LEFT(E6,1)="O","Crescimento","Sobrevivência")))
B7: 2 | D7: =IF(C7="","",IF(LEFT(C7,1)="S",INDEX(SWOT!$C$16:$C$23,VALUE(MID(C7,2,1))),INDEX(SWOT!$I$16:$I$23,VALUE(MID(C7,2,1))))&"") | F7: =IF(E7="","",IF(LEFT(E7,1)="O",INDEX(SWOT!$C$30:$C$37,VALUE(MID(E7,2,1))),INDEX(SWOT!$I$30:$I$37,VALUE(MID(E7,2,1))))&"") | G7: =IF(OR(C7="",E7=""),"",LEFT(C7,1)&LEFT(E7,1)&" — "&IF(LEFT(C7,1)="S",IF(LEFT(E7,1)="O","Desenvolvimento","Manutenção"),IF(LEFT(E7,1)="O","Crescimento","Sobrevivência")))
B8: 3 | D8: =IF(C8="","",IF(LEFT(C8,1)="S",INDEX(SWOT!$C$16:$C$23,VALUE(MID(C8,2,1))),INDEX(SWOT!$I$16:$I$23,VALUE(MID(C8,2,1))))&"") | F8: =IF(E8="","",IF(LEFT(E8,1)="O",INDEX(SWOT!$C$30:$C$37,VALUE(MID(E8,2,1))),INDEX(SWOT!$I$30:$I$37,VALUE(MID(E8,2,1))))&"") | G8: =IF(OR(C8="",E8=""),"",LEFT(C8,1)&LEFT(E8,1)&" — "&IF(LEFT(C8,1)="S",IF(LEFT(E8,1)="O","Desenvolvimento","Manutenção"),IF(LEFT(E8,1)="O","Crescimento","Sobrevivência")))
B9: 4 | D9: =IF(C9="","",IF(LEFT(C9,1)="S",INDEX(SWOT!$C$16:$C$23,VALUE(MID(C9,2,1))),INDEX(SWOT!$I$16:$I$23,VALUE(MID(C9,2,1))))&"") | F9: =IF(E9="","",IF(LEFT(E9,1)="O",INDEX(SWOT!$C$30:$C$37,VALUE(MID(E9,2,1))),INDEX(SWOT!$I$30:$I$37,VALUE(MID(E9,2,1))))&"") | G9: =IF(OR(C9="",E9=""),"",LEFT(C9,1)&LEFT(E9,1)&" — "&IF(LEFT(C9,1)="S",IF(LEFT(E9,1)="O","Desenvolvimento","Manutenção"),IF(LEFT(E9,1)="O","Crescimento","Sobrevivência")))
B10: 5 | D10: =IF(C10="","",IF(LEFT(C10,1)="S",INDEX(SWOT!$C$16:$C$23,VALUE(MID(C10,2,1))),INDEX(SWOT!$I$16:$I$23,VALUE(MID(C10,2,1))))&"") | F10: =IF(E10="","",IF(LEFT(E10,1)="O",INDEX(SWOT!$C$30:$C$37,VALUE(MID(E10,2,1))),INDEX(SWOT!$I$30:$I$37,VALUE(MID(E10,2,1))))&"") | G10: =IF(OR(C10="",E10=""),"",LEFT(C10,1)&LEFT(E10,1)&" — "&IF(LEFT(C10,1)="S",IF(LEFT(E10,1)="O","Desenvolvimento","Manutenção"),IF(LEFT(E10,1)="O","Crescimento","Sobrevivência")))
B11: 6 | D11: =IF(C11="","",IF(LEFT(C11,1)="S",INDEX(SWOT!$C$16:$C$23,VALUE(MID(C11,2,1))),INDEX(SWOT!$I$16:$I$23,VALUE(MID(C11,2,1))))&"") | F11: =IF(E11="","",IF(LEFT(E11,1)="O",INDEX(SWOT!$C$30:$C$37,VALUE(MID(E11,2,1))),INDEX(SWOT!$I$30:$I$37,VALUE(MID(E11,2,1))))&"") | G11: =IF(OR(C11="",E11=""),"",LEFT(C11,1)&LEFT(E11,1)&" — "&IF(LEFT(C11,1)="S",IF(LEFT(E11,1)="O","Desenvolvimento","Manutenção"),IF(LEFT(E11,1)="O","Crescimento","Sobrevivência")))
B12: 7 | D12: =IF(C12="","",IF(LEFT(C12,1)="S",INDEX(SWOT!$C$16:$C$23,VALUE(MID(C12,2,1))),INDEX(SWOT!$I$16:$I$23,VALUE(MID(C12,2,1))))&"") | F12: =IF(E12="","",IF(LEFT(E12,1)="O",INDEX(SWOT!$C$30:$C$37,VALUE(MID(E12,2,1))),INDEX(SWOT!$I$30:$I$37,VALUE(MID(E12,2,1))))&"") | G12: =IF(OR(C12="",E12=""),"",LEFT(C12,1)&LEFT(E12,1)&" — "&IF(LEFT(C12,1)="S",IF(LEFT(E12,1)="O","Desenvolvimento","Manutenção"),IF(LEFT(E12,1)="O","Crescimento","Sobrevivência")))
B13: 8 | D13: =IF(C13="","",IF(LEFT(C13,1)="S",INDEX(SWOT!$C$16:$C$23,VALUE(MID(C13,2,1))),INDEX(SWOT!$I$16:$I$23,VALUE(MID(C13,2,1))))&"") | F13: =IF(E13="","",IF(LEFT(E13,1)="O",INDEX(SWOT!$C$30:$C$37,VALUE(MID(E13,2,1))),INDEX(SWOT!$I$30:$I$37,VALUE(MID(E13,2,1))))&"") | G13: =IF(OR(C13="",E13=""),"",LEFT(C13,1)&LEFT(E13,1)&" — "&IF(LEFT(C13,1)="S",IF(LEFT(E13,1)="O","Desenvolvimento","Manutenção"),IF(LEFT(E13,1)="O","Crescimento","Sobrevivência")))
B14: 9 | D14: =IF(C14="","",IF(LEFT(C14,1)="S",INDEX(SWOT!$C$16:$C$23,VALUE(MID(C14,2,1))),INDEX(SWOT!$I$16:$I$23,VALUE(MID(C14,2,1))))&"") | F14: =IF(E14="","",IF(LEFT(E14,1)="O",INDEX(SWOT!$C$30:$C$37,VALUE(MID(E14,2,1))),INDEX(SWOT!$I$30:$I$37,VALUE(MID(E14,2,1))))&"") | G14: =IF(OR(C14="",E14=""),"",LEFT(C14,1)&LEFT(E14,1)&" — "&IF(LEFT(C14,1)="S",IF(LEFT(E14,1)="O","Desenvolvimento","Manutenção"),IF(LEFT(E14,1)="O","Crescimento","Sobrevivência")))
B15: 10 | D15: =IF(C15="","",IF(LEFT(C15,1)="S",INDEX(SWOT!$C$16:$C$23,VALUE(MID(C15,2,1))),INDEX(SWOT!$I$16:$I$23,VALUE(MID(C15,2,1))))&"") | F15: =IF(E15="","",IF(LEFT(E15,1)="O",INDEX(SWOT!$C$30:$C$37,VALUE(MID(E15,2,1))),INDEX(SWOT!$I$30:$I$37,VALUE(MID(E15,2,1))))&"") | G15: =IF(OR(C15="",E15=""),"",LEFT(C15,1)&LEFT(E15,1)&" — "&IF(LEFT(C15,1)="S",IF(LEFT(E15,1)="O","Desenvolvimento","Manutenção"),IF(LEFT(E15,1)="O","Crescimento","Sobrevivência")))
B16: 11 | D16: =IF(C16="","",IF(LEFT(C16,1)="S",INDEX(SWOT!$C$16:$C$23,VALUE(MID(C16,2,1))),INDEX(SWOT!$I$16:$I$23,VALUE(MID(C16,2,1))))&"") | F16: =IF(E16="","",IF(LEFT(E16,1)="O",INDEX(SWOT!$C$30:$C$37,VALUE(MID(E16,2,1))),INDEX(SWOT!$I$30:$I$37,VALUE(MID(E16,2,1))))&"") | G16: =IF(OR(C16="",E16=""),"",LEFT(C16,1)&LEFT(E16,1)&" — "&IF(LEFT(C16,1)="S",IF(LEFT(E16,1)="O","Desenvolvimento","Manutenção"),IF(LEFT(E16,1)="O","Crescimento","Sobrevivência")))
B17: 12 | D17: =IF(C17="","",IF(LEFT(C17,1)="S",INDEX(SWOT!$C$16:$C$23,VALUE(MID(C17,2,1))),INDEX(SWOT!$I$16:$I$23,VALUE(MID(C17,2,1))))&"") | F17: =IF(E17="","",IF(LEFT(E17,1)="O",INDEX(SWOT!$C$30:$C$37,VALUE(MID(E17,2,1))),INDEX(SWOT!$I$30:$I$37,VALUE(MID(E17,2,1))))&"") | G17: =IF(OR(C17="",E17=""),"",LEFT(C17,1)&LEFT(E17,1)&" — "&IF(LEFT(C17,1)="S",IF(LEFT(E17,1)="O","Desenvolvimento","Manutenção"),IF(LEFT(E17,1)="O","Crescimento","Sobrevivência")))
B19: Resumo automático
B20: Estratégias registradas | G20: =COUNTA(H6:H17) -> 0
B21: SO — Desenvolvimento | G21: =COUNTIF(G6:G17,"SO*") -> 0
B22: WO — Crescimento | G22: =COUNTIF(G6:G17,"WO*") -> 0
B23: ST — Manutenção | G23: =COUNTIF(G6:G17,"ST*") -> 0
B24: WT — Sobrevivência | G24: =COUNTIF(G6:G17,"WT*") -> 0
B25: Estratégias de prioridade alta | G25: =COUNTIF(I6:I17,"Alta") -> 0
B26: Aviso: cruzamento | G26: =IF(SUMPRODUCT((H6:H17<>"")*((C6:C17="")+(E6:E17="")>0))>0,"Há estratégia sem fator","OK") -> OK
B27: Aviso: fatores | G27: =IF(SUMPRODUCT(((C6:C17<>"")*(D6:D17=""))+((E6:E17<>"")*(F6:F17="")))>0,"Há código sem fator na aba SWOT","OK") -> OK

Sheet Plano de ação
B1: Plano de ação
B2: Uma linha por ação. Cada ação vem de uma estratégia e tem um único responsável.
B4: # | C4: Estratégia ou objetivo | D4: Ação | E4: Responsável | F4: Prazo | G4: Indicador de acompanhamento | H4: Status | I4: Situação
B5: Ex. | C5: Levar 30% dos pedidos do aplicativo para o canal próprio | D5: Divulgar o pedido por mensagem na embalagem e nas redes sociais | E5: Gerente da loja | F5: 46356 | G5: % de pedidos recebidos pelo canal próprio | H5: Em andamento | I5: No prazo
B6: 1 | I6: =IF(D6="","",IF(OR(H6="Concluída",H6="Cancelada"),H6,IF(F6="","Sem prazo",IF(F6<TODAY(),"Atrasada","No prazo"))))
B7: 2 | I7: =IF(D7="","",IF(OR(H7="Concluída",H7="Cancelada"),H7,IF(F7="","Sem prazo",IF(F7<TODAY(),"Atrasada","No prazo"))))
B8: 3 | I8: =IF(D8="","",IF(OR(H8="Concluída",H8="Cancelada"),H8,IF(F8="","Sem prazo",IF(F8<TODAY(),"Atrasada","No prazo"))))
B9: 4 | I9: =IF(D9="","",IF(OR(H9="Concluída",H9="Cancelada"),H9,IF(F9="","Sem prazo",IF(F9<TODAY(),"Atrasada","No prazo"))))
B10: 5 | I10: =IF(D10="","",IF(OR(H10="Concluída",H10="Cancelada"),H10,IF(F10="","Sem prazo",IF(F10<TODAY(),"Atrasada","No prazo"))))
B11: 6 | I11: =IF(D11="","",IF(OR(H11="Concluída",H11="Cancelada"),H11,IF(F11="","Sem prazo",IF(F11<TODAY(),"Atrasada","No prazo"))))
B12: 7 | I12: =IF(D12="","",IF(OR(H12="Concluída",H12="Cancelada"),H12,IF(F12="","Sem prazo",IF(F12<TODAY(),"Atrasada","No prazo"))))
B13: 8 | I13: =IF(D13="","",IF(OR(H13="Concluída",H13="Cancelada"),H13,IF(F13="","Sem prazo",IF(F13<TODAY(),"Atrasada","No prazo"))))
B14: 9 | I14: =IF(D14="","",IF(OR(H14="Concluída",H14="Cancelada"),H14,IF(F14="","Sem prazo",IF(F14<TODAY(),"Atrasada","No prazo"))))
B15: 10 | I15: =IF(D15="","",IF(OR(H15="Concluída",H15="Cancelada"),H15,IF(F15="","Sem prazo",IF(F15<TODAY(),"Atrasada","No prazo"))))
B16: 11 | I16: =IF(D16="","",IF(OR(H16="Concluída",H16="Cancelada"),H16,IF(F16="","Sem prazo",IF(F16<TODAY(),"Atrasada","No prazo"))))
B17: 12 | I17: =IF(D17="","",IF(OR(H17="Concluída",H17="Cancelada"),H17,IF(F17="","Sem prazo",IF(F17<TODAY(),"Atrasada","No prazo"))))
... B20: 15 | I20: =IF(D20="","",IF(OR(H20="Concluída",H20="Cancelada"),H20,IF(F20="","Sem prazo",IF(F20<TODAY(),"Atrasada","No prazo"))))
B22: Resumo automático
B23: Ações registradas | G23: =COUNTA(D6:D20) -> 0
B24: Concluídas | G24: =COUNTIF(H6:H20,"Concluída") -> 0
B25: Em andamento | G25: =COUNTIF(H6:H20,"Em andamento") -> 0
B26: Não iniciadas | G26: =COUNTIF(H6:H20,"Não iniciada") -> 0
B27: Atrasadas | G27: =COUNTIF(I6:I20,"Atrasada") -> 0
B28: Ações sem responsável ou sem prazo | G28: =SUMPRODUCT((D6:D20<>"")*((E6:E20="")+(F6:F20="")>0)) -> 0
B29: Percentual concluído | G29: =IF(G23=0,0,G24/G23) -> 0

Sheet Checklist
B1: Checklist de validação da Matriz SWOT
B2: Escolha o status de cada item na lista suspensa (coluna em amarelo-claro).
B4: # | C4: Item de verificação | D4: Status | E4: Observações
B5: 1 | C5: O objeto, o objetivo e o horizonte da análise estão definidos.
B6: 2 | C6: Participaram pessoas de áreas e níveis diferentes.
B7: 3 | C7: Cada fator é um fato ou uma tendência que pode ser verificada.
B8: 4 | C8: Forças e fraquezas são internas: a organização controla.
B9: 5 | C9: Oportunidades e ameaças são externas: existiriam sem a organização.
B10: 6 | C10: Nenhum fator é uma ação ou uma solução disfarçada.
B11: 7 | C11: Cada quadrante tem de 3 a 8 fatores.
B12: 8 | C12: Os fatores foram pontuados pelo grupo, com critérios combinados antes.
B13: 9 | C13: Os fatores de alta prioridade foram cruzados em estratégias.
B14: 10 | C14: Cada estratégia escolhida virou ação, com responsável, prazo e indicador.
B15: 11 | C15: As expectativas das partes interessadas foram consideradas.
B16: 12 | C16: A data da próxima revisão está marcada.
B18: Resumo automático
B19: Itens atendidos (Sim) | D19: =COUNTIF(D5:D16,"Sim") -> 0
B20: Itens parciais | D20: =COUNTIF(D5:D16,"Parcial") -> 0
B21: Itens não atendidos | D21: =COUNTIF(D5:D16,"Não") -> 0
B22: Itens sem resposta | D22: =COUNTBLANK(D5:D16) -> 12
B23: Percentual atendido | D23: =D19/ROWS(D5:D16) -> 0
B24: Situação | D24: =IF(D19=ROWS(D5:D16),"Validado",IF(D22>0,"Em andamento","Com pendências")) -> Em andamento

Sheet Exemplo 1 - Pizzaria
B1: SWOT — Matriz de análise
B2: Exemplo preenchido, para consulta. Use a aba SWOT para a sua análise.
B4: Objeto da análise | D4: Operação de delivery de uma pizzaria de bairro | H4: Responsável | J4: Gerente da loja
B5: Área / unidade | D5: Pizzaria (loja) | H5: Data | J5: 46294
B6: Elaborado por | D6: Equipe da loja | H6: Versão | J6: 1.0
B7: Objetivo da análise | D7: Aumentar em 20% o faturamento do delivery.
B8: Horizonte de tempo | D8: 12 meses | H8: Participantes | J8: Gerente, líder da expedição, pizzaiolo, atendente e um entregador
B9: Fora do escopo | D9: Atendimento no salão e abertura de novas unidades.
B11: S | H11: W
B12: Forças (Strengths) · interno, ajuda | H12: Fraquezas (Weaknesses) · interno, atrapalha
B13: O que a organização faz bem e está sob o seu controle? | H13: O que a organização faz mal ou não tem, e poderia mudar?
B14: # | C14: Fator | E14: Impacto | F14: Intensidade | G14: Pontos | H14: # | I14: Fator | K14: Impacto | L14: Intensidade | M14: Pontos
B15: Forças e fraquezas descrevem a organização como ela é hoje. Cada fator é um fato que pode ser verificado. Os pontos são o produto de impacto e intensidade, de 1 a 25.
B16: S1 | C16: Receita própria e massa de fermentação longa, elogiadas nas avaliações | E16: 5 | F16: 4 | G16: =IF(OR(E16="",F16=""),"",E16*F16) -> 20 | H16: W1 | I16: Forno único, que limita a produção no horário de pico | K16: 5 | L16: 4 | M16: =IF(OR(K16="",L16=""),"",K16*L16) -> 20
B17: S2 | C17: Entrega própria, com 95% dos pedidos no prazo | E17: 4 | F17: 4 | G17: =IF(OR(E17="",F17=""),"",E17*F17) -> 16 | H17: W2 | I17: Dependência de um aplicativo para 70% dos pedidos | K17: 4 | L17: 5 | M17: =IF(OR(K17="",L17=""),"",K17*L17) -> 20
B18: S3 | C18: Clientela fiel no bairro, com alta recompra | E18: 4 | F18: 3 | G18: =IF(OR(E18="",F18=""),"",E18*F18) -> 12 | H18: W3 | I18: Sem controle de custo por pizza | K18: 3 | L18: 3 | M18: =IF(OR(K18="",L18=""),"",K18*L18) -> 9
B19: S4 | C19: Equipe estável, com baixa rotatividade | E19: 3 | F19: 3 | G19: =IF(OR(E19="",F19=""),"",E19*F19) -> 9 | H19: W4 | I19: Pouca presença nas redes sociais | K19: 2 | L19: 3 | M19: =IF(OR(K19="",L19=""),"",K19*L19) -> 6
B20: S5 | G20: =IF(OR(E20="",F20=""),"",E20*F20) | H20: W5 | M20: =IF(OR(K20="",L20=""),"",K20*L20)
B21: S6 | G21: =IF(OR(E21="",F21=""),"",E21*F21) | H21: W6 | M21: =IF(OR(K21="",L21=""),"",K21*L21)
B22: S7 | G22: =IF(OR(E22="",F22=""),"",E22*F22) | H22: W7 | M22: =IF(OR(K22="",L22=""),"",K22*L22)
B23: S8 | G23: =IF(OR(E23="",F23=""),"",E23*F23) | H23: W8 | M23: =IF(OR(K23="",L23=""),"",K23*L23)
B25: O | H25: T
B26: Oportunidades (Opportunities) · externo, ajuda | H26: Ameaças (Threats) · externo, atrapalha
B27: O que acontece no ambiente e pode favorecer o objetivo? | H27: O que acontece no ambiente e pode prejudicar o objetivo?
B28: # | C28: Fator | E28: Impacto | F28: Intensidade | G28: Pontos | H28: # | I28: Fator | K28: Impacto | L28: Intensidade | M28: Pontos
B29: Oportunidades e ameaças vêm do ambiente: existiriam mesmo que a organização não existisse.
B30: O1 | C30: Novos condomínios em construção no bairro | E30: 5 | F30: 4 | G30: =IF(OR(E30="",F30=""),"",E30*F30) -> 20 | H30: T1 | I30: Aumento da taxa cobrada pelo aplicativo de delivery | K30: 4 | L30: 4 | M30: =IF(OR(K30="",L30=""),"",K30*L30) -> 16
B31: O2 | C31: Procura crescente por opções vegetarianas e sem glúten | E31: 3 | F31: 3 | G31: =IF(OR(E31="",F31=""),"",E31*F31) -> 9 | H31: T2 | I31: Chegada de uma rede de pizzarias ao bairro | K31: 4 | L31: 3 | M31: =IF(OR(K31="",L31=""),"",K31*L31) -> 12
B32: O3 | C32: Empresas da região buscando fornecedores para eventos | E32: 2 | F32: 3 | G32: =IF(OR(E32="",F32=""),"",E32*F32) -> 6 | H32: T3 | I32: Alta do preço do queijo e da farinha | K32: 3 | L32: 4 | M32: =IF(OR(K32="",L32=""),"",K32*L32) -> 12
B33: O4 | C33: Pedido por aplicativo de mensagens, com custo menor por venda | E33: 4 | F33: 4 | G33: =IF(OR(E33="",F33=""),"",E33*F33) -> 16 | H33: T4 | I33: Obras na avenida principal, que atrasam as entregas | K33: 2 | L33: 2 | M33: =IF(OR(K33="",L33=""),"",K33*L33) -> 4
B34: O5 | G34: =IF(OR(E34="",F34=""),"",E34*F34) | H34: T5 | M34: =IF(OR(K34="",L34=""),"",K34*L34)
B35: O6 | G35: =IF(OR(E35="",F35=""),"",E35*F35) | H35: T6 | M35: =IF(OR(K35="",L35=""),"",K35*L35)
B36: O7 | G36: =IF(OR(E36="",F36=""),"",E36*F36) | H36: T7 | M36: =IF(OR(K36="",L36=""),"",K36*L36)
B37: O8 | G37: =IF(OR(E37="",F37=""),"",E37*F37) | H37: T8 | M37: =IF(OR(K37="",L37=""),"",K37*L37)
B39: Resumo automático
B40: Quadrante | E40: S — Forças | H40: W — Fraquezas | J40: O — Oportunidades | K40: T — Ameaças
B41: Fatores listados | E41: =COUNTA(C16:C23) -> 4 | H41: =COUNTA(I16:I23) -> 4 | J41: =COUNTA(C30:C37) -> 4 | K41: =COUNTA(I30:I37) -> 4
B42: Pontos | E42: =SUM(G16:G23) -> 57 | H42: =SUM(M16:M23) -> 55 | J42: =SUM(G30:G37) -> 51 | K42: =SUM(M30:M37) -> 44
B43: Aviso | E43: =IF(E41=0,"Liste os fatores",IF(E41<3,"Poucos fatores: liste ao menos 3",IF(COUNT(G16:G23)<E41,"Há fator sem nota","OK"))) -> OK | H43: =IF(H41=0,"Liste os fatores",IF(H41<3,"Poucos fatores: liste ao menos 3",IF(COUNT(M16:M23)<H41,"Há fator sem nota","OK"))) -> OK | J43: =IF(J41=0,"Liste os fatores",IF(J41<3,"Poucos fatores: liste ao menos 3",IF(COUNT(G30:G37)<J41,"Há fator sem nota","OK"))) -> OK | K43: =IF(K41=0,"Liste os fatores",IF(K41<3,"Poucos fatores: liste ao menos 3",IF(COUNT(M30:M37)<K41,"Há fator sem nota","OK"))) -> OK
B44: Balanço interno (forças menos fraquezas) | H44: =E42-H42 -> 2
...

Sheet Exemplo 2 - Compras
B1: SWOT — Matriz de análise
B2: Exemplo preenchido, para consulta. Use a aba SWOT para a sua análise.
B4: Objeto da análise | D4: Área de Suprimentos de uma indústria | H4: Responsável | J4: Gerente de Suprimentos
B5: Área / unidade | D5: Suprimentos | H5: Data | J5: 46294
B6: Elaborado por | D6: Equipe de compras | H6: Versão | J6: 1.0
B7: Objetivo da análise | D7: Reduzir em 8% o custo total de aquisição, sem aumentar as faltas de material.
B8: Horizonte de tempo | D8: 12 meses | H8: Participantes | J8: Gerente, compradores, Controladoria, Produção e Qualidade
B9: Fora do escopo | D9: Gestão de estoques e pagamento a fornecedores.
B11: S | H11: W
B12: Forças (Strengths) · interno, ajuda | H12: Fraquezas (Weaknesses) · interno, atrapalha
B13: O que a organização faz bem e está sob o seu controle? | H13: O que a organização faz mal ou não tem, e poderia mudar?
B14: # | C14: Fator | E14: Impacto | F14: Intensidade | G14: Pontos | H14: # | I14: Fator | K14: Impacto | L14: Intensidade | M14: Pontos
B15: Forças e fraquezas descrevem a organização como ela é hoje. Cada fator é um fato que pode ser verificado. Os pontos são o produto de impacto e intensidade, de 1 a 25.
B16: S1 | C16: Compradores experientes, com conhecimento técnico dos itens | E16: 4 | F16: 4 | G16: =IF(OR(E16="",F16=""),"",E16*F16) -> 16 | H16: W1 | I16: Requisições chegam com especificação incompleta | K16: 4 | L16: 4 | M16: =IF(OR(K16="",L16=""),"",K16*L16) -> 16
B17: S2 | C17: Base de fornecedores homologados para todos os itens críticos | E17: 4 | F17: 4 | G17: =IF(OR(E17="",F17=""),"",E17*F17) -> 16 | H17: W2 | I17: Processo manual, em planilhas e e-mails | K17: 4 | L17: 4 | M17: =IF(OR(K17="",L17=""),"",K17*L17) -> 16
B18: S3 | C18: Contratos de longo prazo para os principais insumos | E18: 5 | F18: 3 | G18: =IF(OR(E18="",F18=""),"",E18*F18) -> 15 | H18: W3 | I18: Fornecedor único contratado para três itens críticos | K18: 5 | L18: 4 | M18: =IF(OR(K18="",L18=""),"",K18*L18) -> 20
B19: S4 | G19: =IF(OR(E19="",F19=""),"",E19*F19) | H19: W4 | I19: Avaliação de fornecedores sem indicadores objetivos | K19: 3 | L19: 3 | M19: =IF(OR(K19="",L19=""),"",K19*L19) -> 9
B20: S5 | G20: =IF(OR(E20="",F20=""),"",E20*F20) | H20: W5 | M20: =IF(OR(K20="",L20=""),"",K20*L20)
B21: S6 | G21: =IF(OR(E21="",F21=""),"",E21*F21) | H21: W6 | M21: =IF(OR(K21="",L21=""),"",K21*L21)
B22: S7 | G22: =IF(OR(E22="",F22=""),"",E22*F22) | H22: W7 | M22: =IF(OR(K22="",L22=""),"",K22*L22)
B23: S8 | G23: =IF(OR(E23="",F23=""),"",E23*F23) | H23: W8 | M23: =IF(OR(K23="",L23=""),"",K23*L23)
B25: O | H25: T
B26: Oportunidades (Opportunities) · externo, ajuda | H26: Ameaças (Threats) · externo, atrapalha
B27: O que acontece no ambiente e pode favorecer o objetivo? | H27: O que acontece no ambiente e pode prejudicar o objetivo?
B28: # | C28: Fator | E28: Impacto | F28: Intensidade | G28: Pontos | H28: # | I28: Fator | K28: Impacto | L28: Intensidade | M28: Pontos
B29: Oportunidades e ameaças vêm do ambiente: existiriam mesmo que a organização não existisse.
B30: O1 | C30: Novos fabricantes nacionais de itens hoje importados | E30: 4 | F30: 3 | G30: =IF(OR(E30="",F30=""),"",E30*F30) -> 12 | H30: T1 | I30: Variação do câmbio nos insumos importados | K30: 5 | L30: 4 | M30: =IF(OR(K30="",L30=""),"",K30*L30) -> 20
B31: O2 | C31: Plataformas de cotação eletrônica com custo acessível | E31: 4 | F31: 4 | G31: =IF(OR(E31="",F31=""),"",E31*F31) -> 16 | H31: T2 | I31: Aumento do frete e dos prazos logísticos | K31: 4 | L31: 3 | M31: =IF(OR(K31="",L31=""),"",K31*L31) -> 12
B32: O3 | C32: Outras unidades do grupo dispostas a comprar em conjunto | E32: 3 | F32: 3 | G32: =IF(OR(E32="",F32=""),"",E32*F32) -> 9 | H32: T3 | I32: Exigências ambientais e sociais sobre a cadeia de fornecedores | K32: 3 | L32: 3 | M32: =IF(OR(K32="",L32=""),"",K32*L32) -> 9
B33: O4 | G33: =IF(OR(E33="",F33=""),"",E33*F33) | H33: T4 | I33: Oferta de um insumo crítico concentrada em poucos fabricantes | K33: 4 | L33: 4 | M33: =IF(OR(K33="",L33=""),"",K33*L33) -> 16
B34: O5 | G34: =IF(OR(E34="",F34=""),"",E34*F34) | H34: T5 | M34: =IF(OR(K34="",L34=""),"",K34*L34)
B35: O6 | G35: =IF(OR(E35="",F35=""),"",E35*F35) | H35: T6 | M35: =IF(OR(K35="",L35=""),"",K35*L35)
B36: O7 | G36: =IF(OR(E36="",F36=""),"",E36*F36) | H36: T7 | M36: =IF(OR(K36="",L36=""),"",K36*L36)
B37: O8 | G37: =IF(OR(E37="",F37=""),"",E37*F37) | H37: T8 | M37: =IF(OR(K37="",L37=""),"",K37*L37)
B39: Resumo automático
B40: Quadrante | E40: S — Forças | H40: W — Fraquezas | J40: O — Oportunidades | K40: T — Ameaças
B41: Fatores listados | E41: =COUNTA(C16:C23) -> 3 | H41: =COUNTA(I16:I23) -> 4 | J41: =COUNTA(C30:C37) -> 3 | K41: =COUNTA(I30:I37) -> 4
B42: Pontos | E42: =SUM(G16:G23) -> 47 | H42: =SUM(M16:M23) -> 61 | J42: =SUM(G30:G37) -> 37 | K42: =SUM(M30:M37) -> 57
B43: Aviso | E43: =IF(E41=0,"Liste os fatores",IF(E41<3,"Poucos fatores: liste ao menos 3",IF(COUNT(G16:G23)<E41,"Há fator sem nota","OK"))) -> OK | H43: =IF(H41=0,"Liste os fatores",IF(H41<3,"Poucos fatores: liste ao menos 3",IF(COUNT(M16:M23)<H41,"Há fator sem nota","OK"))) -> OK | J43: =IF(J41=0,"Liste os fatores",IF(J41<3,"Poucos fatores: liste ao menos 3",IF(COUNT(G30:G37)<J41,"Há fator sem nota","OK"))) -> OK | K43: =IF(K41=0,"Liste os fatores",IF(K41<3,"Poucos fatores: liste ao menos 3",IF(COUNT(M30:M37)<K41,"Há fator sem nota","OK"))) -> OK
B44: Balanço interno (forças menos fraquezas) | H44: =E42-H42 -> -14
...
