Workbook

Sheet Instruções
B1: Objetivos da qualidade — Como usar esta planilha
B2: Modelo para escrever a política, definir os objetivos com medida, meta e prazo, planejar as ações e acompanhar o resultado.
B4: Legenda: onde preencher
B5: Amarelo-claro | C5: Células de entrada. É aqui que você digita.
B6: Cinza | C6: Células calculadas ou fixas (rótulos, tipos, situações, caminho percorrido, avisos). Não altere.
B7: Cinza em itálico | C7: Linha de exemplo (marcada com “Ex.”). Mostra o formato esperado e não entra nas contagens.
B8: Listas suspensas | C8: Compromisso, origem, sentido, frequência, objetivo da ação, status e checklist aceitam apenas as opções da lista.
B9: Comentários | C9: Células com triângulo vermelho no canto trazem uma dica de preenchimento. Passe o mouse sobre elas.
B11: As regras de cálculo
B12: Tipo do objetivo | C12: Melhorar: a meta é melhor do que a base. Manter: a meta é igual à base, ou pior. Realizar: o indicador conta etapas concluídas, e a base é zero.
B13: Último resultado | C13: O último período preenchido na aba Acompanhamento. Períodos vazios no meio são ignorados.
B14: Alcançado | C14: O último resultado atende à meta, no sentido definido: maior ou menor é melhor.
B15: No caminho | C15: Não atende à meta, e está melhor do que a base.
B16: Em risco | C16: Não atende à meta, e não está melhor do que a base.
B17: Em andamento | C17: Não atende à meta, e não há base para comparar.
B18: Não alcançado | C18: O prazo do objetivo é anterior à data da análise, e a meta não foi atendida.
B19: Caminho percorrido | C19: (Último − base) ÷ (meta − base), de 0% a 100%. Para o objetivo de manutenção: 100% se atende, 0% se não.
B20: Ação atrasada | C20: Ação não iniciada ou em andamento com prazo anterior à data da análise, informada na aba Painel.
B22: Ordem recomendada de preenchimento
B23: Passo 1 | C23: Aba Objetivos: escreva a política da qualidade e os seus compromissos, em até quatro frases.
B24: Passo 2 | C24: Aba Objetivos: escreva cada objetivo, com compromisso, origem, indicador, unidade, sentido, base, meta, prazo, processo, responsável e frequência.
B25: Passo 3 | C25: Aba Planos: para cada objetivo, as ações, com recursos, responsável, prazo, status e como se avalia.
B26: Passo 4 | C26: Aba Acompanhamento: escreva os nomes dos períodos e lance os resultados conforme chegam.
B27: Passo 5 | C27: Aba Painel: informe a data da análise e leia a situação de cada objetivo, o caminho percorrido e as ações atrasadas.
B28: Passo 6 | C28: Aba Checklist: valide o quadro.
B30: Abas da planilha
B31: Objetivos | C31: A política, com até 4 compromissos, e até 12 objetivos. Calcula o tipo e a conferência de cada um.
B32: Planos | C32: Até 36 ações, ligadas aos objetivos pelo código. Calcula a conferência e as contagens.
B33: Acompanhamento | C33: Os resultados de cada objetivo em até 12 períodos. Calcula o último resultado, o caminho e a situação.
B34: Painel | C34: Os indicadores gerais, a leitura de cada objetivo, as ações atrasadas e o gráfico do caminho percorrido.
B35: Checklist | C35: Doze verificações de qualidade do quadro, com percentual de conclusão.
B36: Exemplo 1 - Pizzaria | C36: Os sete objetivos de 2027 da loja, com os planos e quatro meses de resultados.
B37: Exemplo 2 - Indústria | C37: Os sete objetivos de 2027 da fábrica, com os planos e seis meses de resultados.
B39: Regras e premissas do modelo
B40: Poucos objetivos | C40: O modelo aceita 12. O usual é de quatro a oito: o que não cabe vira indicador de rotina, ou fica para o ano seguinte.
B41: Código do objetivo | C41: Os códigos O1 a O12 são fixos. Na aba Planos, cada ação é ligada ao objetivo pelo código.
B42: Objetivo de realização | C42: Escreva as etapas no indicador (“etapas concluídas, de seis”), base 0 e meta igual ao número de etapas. Lance a cada mês quantas foram concluídas.
B43: Exemplos | C43: Os dados das abas de exemplo são ilustrativos, criados para este material.

Sheet Objetivos
B1: Política e objetivos da qualidade
B2: A política no alto, com os compromissos. Abaixo, os objetivos: cada um responde a um compromisso e a uma fonte.
B4: Organização e período
B5: Política da qualidade
B7: C1 | C7: Compromisso 1
B8: C2 | C8: Compromisso 2
B9: C3 | C9: Compromisso 3
B10: C4 | C10: Compromisso 4
B12: # | C12: Objetivo | D12: Compromisso | E12: Origem | F12: Indicador | G12: Unidade | H12: Sentido | I12: Base | J12: Meta | K12: Prazo | L12: Processo ou área | M12: Responsável | N12: Frequência | O12: Tipo | P12: Conferência
C13: Verbo, resultado, meta e prazo | D13: Lista | E13: Lista | F13: O que se mede | G13: %, dias, etapas | H13: Lista | I13: Partida | J13: Alvo | K13: Data | L13: Quem entrega | M13: Uma pessoa | N13: Lista | O13: Calculado | P13: Calculada
B14: O1 | O14: =IF(OR(C14="",J14="",H14=""),"",IF(I14="","Sem base",IF(IF(H14="Maior é melhor",J14>I14,J14<I14),"Melhorar","Manter"))) | P14: =IF(C14="","",IF(D14="","Falta o compromisso",IF(F14="","Falta o indicador",IF(J14="","Falta a meta",IF(H14="","Falta o sentido",IF(K14="","Falta o prazo",IF(M14="","Falta o responsável",IF(COUNTIF(Planos!$C$7:$C$42,B14)=0,"Sem ação no plano","OK"))))))))
B15: O2 | O15: =IF(OR(C15="",J15="",H15=""),"",IF(I15="","Sem base",IF(IF(H15="Maior é melhor",J15>I15,J15<I15),"Melhorar","Manter"))) | P15: =IF(C15="","",IF(D15="","Falta o compromisso",IF(F15="","Falta o indicador",IF(J15="","Falta a meta",IF(H15="","Falta o sentido",IF(K15="","Falta o prazo",IF(M15="","Falta o responsável",IF(COUNTIF(Planos!$C$7:$C$42,B15)=0,"Sem ação no plano","OK"))))))))
B16: O3 | O16: =IF(OR(C16="",J16="",H16=""),"",IF(I16="","Sem base",IF(IF(H16="Maior é melhor",J16>I16,J16<I16),"Melhorar","Manter"))) | P16: =IF(C16="","",IF(D16="","Falta o compromisso",IF(F16="","Falta o indicador",IF(J16="","Falta a meta",IF(H16="","Falta o sentido",IF(K16="","Falta o prazo",IF(M16="","Falta o responsável",IF(COUNTIF(Planos!$C$7:$C$42,B16)=0,"Sem ação no plano","OK"))))))))
B17: O4 | O17: =IF(OR(C17="",J17="",H17=""),"",IF(I17="","Sem base",IF(IF(H17="Maior é melhor",J17>I17,J17<I17),"Melhorar","Manter"))) | P17: =IF(C17="","",IF(D17="","Falta o compromisso",IF(F17="","Falta o indicador",IF(J17="","Falta a meta",IF(H17="","Falta o sentido",IF(K17="","Falta o prazo",IF(M17="","Falta o responsável",IF(COUNTIF(Planos!$C$7:$C$42,B17)=0,"Sem ação no plano","OK"))))))))
B18: O5 | O18: =IF(OR(C18="",J18="",H18=""),"",IF(I18="","Sem base",IF(IF(H18="Maior é melhor",J18>I18,J18<I18),"Melhorar","Manter"))) | P18: =IF(C18="","",IF(D18="","Falta o compromisso",IF(F18="","Falta o indicador",IF(J18="","Falta a meta",IF(H18="","Falta o sentido",IF(K18="","Falta o prazo",IF(M18="","Falta o responsável",IF(COUNTIF(Planos!$C$7:$C$42,B18)=0,"Sem ação no plano","OK"))))))))
B19: O6 | O19: =IF(OR(C19="",J19="",H19=""),"",IF(I19="","Sem base",IF(IF(H19="Maior é melhor",J19>I19,J19<I19),"Melhorar","Manter"))) | P19: =IF(C19="","",IF(D19="","Falta o compromisso",IF(F19="","Falta o indicador",IF(J19="","Falta a meta",IF(H19="","Falta o sentido",IF(K19="","Falta o prazo",IF(M19="","Falta o responsável",IF(COUNTIF(Planos!$C$7:$C$42,B19)=0,"Sem ação no plano","OK"))))))))
B20: O7 | O20: =IF(OR(C20="",J20="",H20=""),"",IF(I20="","Sem base",IF(IF(H20="Maior é melhor",J20>I20,J20<I20),"Melhorar","Manter"))) | P20: =IF(C20="","",IF(D20="","Falta o compromisso",IF(F20="","Falta o indicador",IF(J20="","Falta a meta",IF(H20="","Falta o sentido",IF(K20="","Falta o prazo",IF(M20="","Falta o responsável",IF(COUNTIF(Planos!$C$7:$C$42,B20)=0,"Sem ação no plano","OK"))))))))
B21: O8 | O21: =IF(OR(C21="",J21="",H21=""),"",IF(I21="","Sem base",IF(IF(H21="Maior é melhor",J21>I21,J21<I21),"Melhorar","Manter"))) | P21: =IF(C21="","",IF(D21="","Falta o compromisso",IF(F21="","Falta o indicador",IF(J21="","Falta a meta",IF(H21="","Falta o sentido",IF(K21="","Falta o prazo",IF(M21="","Falta o responsável",IF(COUNTIF(Planos!$C$7:$C$42,B21)=0,"Sem ação no plano","OK"))))))))
B22: O9 | O22: =IF(OR(C22="",J22="",H22=""),"",IF(I22="","Sem base",IF(IF(H22="Maior é melhor",J22>I22,J22<I22),"Melhorar","Manter"))) | P22: =IF(C22="","",IF(D22="","Falta o compromisso",IF(F22="","Falta o indicador",IF(J22="","Falta a meta",IF(H22="","Falta o sentido",IF(K22="","Falta o prazo",IF(M22="","Falta o responsável",IF(COUNTIF(Planos!$C$7:$C$42,B22)=0,"Sem ação no plano","OK"))))))))
B23: O10 | O23: =IF(OR(C23="",J23="",H23=""),"",IF(I23="","Sem base",IF(IF(H23="Maior é melhor",J23>I23,J23<I23),"Melhorar","Manter"))) | P23: =IF(C23="","",IF(D23="","Falta o compromisso",IF(F23="","Falta o indicador",IF(J23="","Falta a meta",IF(H23="","Falta o sentido",IF(K23="","Falta o prazo",IF(M23="","Falta o responsável",IF(COUNTIF(Planos!$C$7:$C$42,B23)=0,"Sem ação no plano","OK"))))))))
B24: O11 | O24: =IF(OR(C24="",J24="",H24=""),"",IF(I24="","Sem base",IF(IF(H24="Maior é melhor",J24>I24,J24<I24),"Melhorar","Manter"))) | P24: =IF(C24="","",IF(D24="","Falta o compromisso",IF(F24="","Falta o indicador",IF(J24="","Falta a meta",IF(H24="","Falta o sentido",IF(K24="","Falta o prazo",IF(M24="","Falta o responsável",IF(COUNTIF(Planos!$C$7:$C$42,B24)=0,"Sem ação no plano","OK"))))))))
B25: O12 | O25: =IF(OR(C25="",J25="",H25=""),"",IF(I25="","Sem base",IF(IF(H25="Maior é melhor",J25>I25,J25<I25),"Melhorar","Manter"))) | P25: =IF(C25="","",IF(D25="","Falta o compromisso",IF(F25="","Falta o indicador",IF(J25="","Falta a meta",IF(H25="","Falta o sentido",IF(K25="","Falta o prazo",IF(M25="","Falta o responsável",IF(COUNTIF(Planos!$C$7:$C$42,B25)=0,"Sem ação no plano","OK"))))))))
B27: Resumo automático
B28: Compromissos escritos | D28: =COUNTA(D7:D10) -> 0
B29: Objetivos escritos | D29: =COUNTA(C14:C25) -> 0
B30: Por tipo | D30: =IF(D29=0,"",COUNTIF(O14:O25,"Melhorar")&" de melhorar, "&COUNTIF(O14:O25,"Manter")&" de manter, "&COUNTIF(O14:O25,"Sem base")&" sem base")
B31: Aviso | D31: =IF(D5="","Escreva a política da qualidade",IF(D28=0,"Escreva os compromissos",IF(D29=0,"Escreva os objetivos",IF(COUNTIF(P14:P25,"OK")<D29,"Há objetivo a rever: veja a coluna Conferência",IF(D29>8,"Muitos objetivos: o usual é de quatro a oito","OK"))))) -> Escreva a política da qualidade

Sheet Planos
B1: Planos para alcançar os objetivos
B2: Uma linha por ação. As cinco respostas do requisito 6.2.2: o quê, recursos, quem, até quando e como se avalia.
B4: # | C4: Objetivo | D4: Objetivo (texto) | E4: O que será feito | F4: Recursos | G4: Responsável | H4: Até quando | I4: Status | J4: Concluída em | K4: Como se avalia o resultado | L4: Conferência
C5: Código | D5: Vem da aba Objetivos | E5: Com verbo | F5: Pessoas, dinheiro, tempo | G5: Uma pessoa | H5: Data | I5: Lista | J5: Data | K5: A medida que dirá se funcionou | L5: Calculada
B6: Ex. | C6: O1 | D6: Entregar 96% dos pedidos em até 40 minutos. | E6: Rever a escala do pico em março. | F6: Dois entregadores extras nas sextas e nos sábados | G6: Líder da expedição | H6: 46477 | I6: Concluída | J6: 46472 | K6: Entregas no prazo nas noites de pico, por semana. | L6: OK
B7: 1 | D7: =IF(C7="","",IFERROR(INDEX(Objetivos!$C$14:$C$25,MATCH(C7,Objetivos!$B$14:$B$25,0)),"Código inválido")) | L7: =IF(E7="","",IF(C7="","Falta o objetivo",IF(D7="","Objetivo sem texto na aba Objetivos",IF(G7="","Falta o responsável",IF(H7="","Falta o prazo",IF(I7="","Falta o status",IF(AND(I7="Concluída",J7=""),"Falta a data de conclusão",IF(K7="","Falta como se avalia",IF(AND(ISNUMBER(H7),IFERROR(H7>INDEX(Objetivos!$K$14:$K$25,MATCH(C7,Objetivos!$B$14:$B$25,0)),FALSE())),"Prazo depois do prazo do objetivo","OK")))))))))
B8: 2 | D8: =IF(C8="","",IFERROR(INDEX(Objetivos!$C$14:$C$25,MATCH(C8,Objetivos!$B$14:$B$25,0)),"Código inválido")) | L8: =IF(E8="","",IF(C8="","Falta o objetivo",IF(D8="","Objetivo sem texto na aba Objetivos",IF(G8="","Falta o responsável",IF(H8="","Falta o prazo",IF(I8="","Falta o status",IF(AND(I8="Concluída",J8=""),"Falta a data de conclusão",IF(K8="","Falta como se avalia",IF(AND(ISNUMBER(H8),IFERROR(H8>INDEX(Objetivos!$K$14:$K$25,MATCH(C8,Objetivos!$B$14:$B$25,0)),FALSE())),"Prazo depois do prazo do objetivo","OK")))))))))
B9: 3 | D9: =IF(C9="","",IFERROR(INDEX(Objetivos!$C$14:$C$25,MATCH(C9,Objetivos!$B$14:$B$25,0)),"Código inválido")) | L9: =IF(E9="","",IF(C9="","Falta o objetivo",IF(D9="","Objetivo sem texto na aba Objetivos",IF(G9="","Falta o responsável",IF(H9="","Falta o prazo",IF(I9="","Falta o status",IF(AND(I9="Concluída",J9=""),"Falta a data de conclusão",IF(K9="","Falta como se avalia",IF(AND(ISNUMBER(H9),IFERROR(H9>INDEX(Objetivos!$K$14:$K$25,MATCH(C9,Objetivos!$B$14:$B$25,0)),FALSE())),"Prazo depois do prazo do objetivo","OK")))))))))
B10: 4 | D10: =IF(C10="","",IFERROR(INDEX(Objetivos!$C$14:$C$25,MATCH(C10,Objetivos!$B$14:$B$25,0)),"Código inválido")) | L10: =IF(E10="","",IF(C10="","Falta o objetivo",IF(D10="","Objetivo sem texto na aba Objetivos",IF(G10="","Falta o responsável",IF(H10="","Falta o prazo",IF(I10="","Falta o status",IF(AND(I10="Concluída",J10=""),"Falta a data de conclusão",IF(K10="","Falta como se avalia",IF(AND(ISNUMBER(H10),IFERROR(H10>INDEX(Objetivos!$K$14:$K$25,MATCH(C10,Objetivos!$B$14:$B$25,0)),FALSE())),"Prazo depois do prazo do objetivo","OK")))))))))
B11: 5 | D11: =IF(C11="","",IFERROR(INDEX(Objetivos!$C$14:$C$25,MATCH(C11,Objetivos!$B$14:$B$25,0)),"Código inválido")) | L11: =IF(E11="","",IF(C11="","Falta o objetivo",IF(D11="","Objetivo sem texto na aba Objetivos",IF(G11="","Falta o responsável",IF(H11="","Falta o prazo",IF(I11="","Falta o status",IF(AND(I11="Concluída",J11=""),"Falta a data de conclusão",IF(K11="","Falta como se avalia",IF(AND(ISNUMBER(H11),IFERROR(H11>INDEX(Objetivos!$K$14:$K$25,MATCH(C11,Objetivos!$B$14:$B$25,0)),FALSE())),"Prazo depois do prazo do objetivo","OK")))))))))
B12: 6 | D12: =IF(C12="","",IFERROR(INDEX(Objetivos!$C$14:$C$25,MATCH(C12,Objetivos!$B$14:$B$25,0)),"Código inválido")) | L12: =IF(E12="","",IF(C12="","Falta o objetivo",IF(D12="","Objetivo sem texto na aba Objetivos",IF(G12="","Falta o responsável",IF(H12="","Falta o prazo",IF(I12="","Falta o status",IF(AND(I12="Concluída",J12=""),"Falta a data de conclusão",IF(K12="","Falta como se avalia",IF(AND(ISNUMBER(H12),IFERROR(H12>INDEX(Objetivos!$K$14:$K$25,MATCH(C12,Objetivos!$B$14:$B$25,0)),FALSE())),"Prazo depois do prazo do objetivo","OK")))))))))
B13: 7 | D13: =IF(C13="","",IFERROR(INDEX(Objetivos!$C$14:$C$25,MATCH(C13,Objetivos!$B$14:$B$25,0)),"Código inválido")) | L13: =IF(E13="","",IF(C13="","Falta o objetivo",IF(D13="","Objetivo sem texto na aba Objetivos",IF(G13="","Falta o responsável",IF(H13="","Falta o prazo",IF(I13="","Falta o status",IF(AND(I13="Concluída",J13=""),"Falta a data de conclusão",IF(K13="","Falta como se avalia",IF(AND(ISNUMBER(H13),IFERROR(H13>INDEX(Objetivos!$K$14:$K$25,MATCH(C13,Objetivos!$B$14:$B$25,0)),FALSE())),"Prazo depois do prazo do objetivo","OK")))))))))
B14: 8 | D14: =IF(C14="","",IFERROR(INDEX(Objetivos!$C$14:$C$25,MATCH(C14,Objetivos!$B$14:$B$25,0)),"Código inválido")) | L14: =IF(E14="","",IF(C14="","Falta o objetivo",IF(D14="","Objetivo sem texto na aba Objetivos",IF(G14="","Falta o responsável",IF(H14="","Falta o prazo",IF(I14="","Falta o status",IF(AND(I14="Concluída",J14=""),"Falta a data de conclusão",IF(K14="","Falta como se avalia",IF(AND(ISNUMBER(H14),IFERROR(H14>INDEX(Objetivos!$K$14:$K$25,MATCH(C14,Objetivos!$B$14:$B$25,0)),FALSE())),"Prazo depois do prazo do objetivo","OK")))))))))
B15: 9 | D15: =IF(C15="","",IFERROR(INDEX(Objetivos!$C$14:$C$25,MATCH(C15,Objetivos!$B$14:$B$25,0)),"Código inválido")) | L15: =IF(E15="","",IF(C15="","Falta o objetivo",IF(D15="","Objetivo sem texto na aba Objetivos",IF(G15="","Falta o responsável",IF(H15="","Falta o prazo",IF(I15="","Falta o status",IF(AND(I15="Concluída",J15=""),"Falta a data de conclusão",IF(K15="","Falta como se avalia",IF(AND(ISNUMBER(H15),IFERROR(H15>INDEX(Objetivos!$K$14:$K$25,MATCH(C15,Objetivos!$B$14:$B$25,0)),FALSE())),"Prazo depois do prazo do objetivo","OK")))))))))
B16: 10 | D16: =IF(C16="","",IFERROR(INDEX(Objetivos!$C$14:$C$25,MATCH(C16,Objetivos!$B$14:$B$25,0)),"Código inválido")) | L16: =IF(E16="","",IF(C16="","Falta o objetivo",IF(D16="","Objetivo sem texto na aba Objetivos",IF(G16="","Falta o responsável",IF(H16="","Falta o prazo",IF(I16="","Falta o status",IF(AND(I16="Concluída",J16=""),"Falta a data de conclusão",IF(K16="","Falta como se avalia",IF(AND(ISNUMBER(H16),IFERROR(H16>INDEX(Objetivos!$K$14:$K$25,MATCH(C16,Objetivos!$B$14:$B$25,0)),FALSE())),"Prazo depois do prazo do objetivo","OK")))))))))
B17: 11 | D17: =IF(C17="","",IFERROR(INDEX(Objetivos!$C$14:$C$25,MATCH(C17,Objetivos!$B$14:$B$25,0)),"Código inválido")) | L17: =IF(E17="","",IF(C17="","Falta o objetivo",IF(D17="","Objetivo sem texto na aba Objetivos",IF(G17="","Falta o responsável",IF(H17="","Falta o prazo",IF(I17="","Falta o status",IF(AND(I17="Concluída",J17=""),"Falta a data de conclusão",IF(K17="","Falta como se avalia",IF(AND(ISNUMBER(H17),IFERROR(H17>INDEX(Objetivos!$K$14:$K$25,MATCH(C17,Objetivos!$B$14:$B$25,0)),FALSE())),"Prazo depois do prazo do objetivo","OK")))))))))
B18: 12 | D18: =IF(C18="","",IFERROR(INDEX(Objetivos!$C$14:$C$25,MATCH(C18,Objetivos!$B$14:$B$25,0)),"Código inválido")) | L18: =IF(E18="","",IF(C18="","Falta o objetivo",IF(D18="","Objetivo sem texto na aba Objetivos",IF(G18="","Falta o responsável",IF(H18="","Falta o prazo",IF(I18="","Falta o status",IF(AND(I18="Concluída",J18=""),"Falta a data de conclusão",IF(K18="","Falta como se avalia",IF(AND(ISNUMBER(H18),IFERROR(H18>INDEX(Objetivos!$K$14:$K$25,MATCH(C18,Objetivos!$B$14:$B$25,0)),FALSE())),"Prazo depois do prazo do objetivo","OK")))))))))
... B42: 36 | D42: =IF(C42="","",IFERROR(INDEX(Objetivos!$C$14:$C$25,MATCH(C42,Objetivos!$B$14:$B$25,0)),"Código inválido")) | L42: =IF(E42="","",IF(C42="","Falta o objetivo",IF(D42="","Objetivo sem texto na aba Objetivos",IF(G42="","Falta o responsável",IF(H42="","Falta o prazo",IF(I42="","Falta o status",IF(AND(I42="Concluída",J42=""),"Falta a data de conclusão",IF(K42="","Falta como se avalia",IF(AND(ISNUMBER(H42),IFERROR(H42>INDEX(Objetivos!$K$14:$K$25,MATCH(C42,Objetivos!$B$14:$B$25,0)),FALSE())),"Prazo depois do prazo do objetivo","OK")))))))))
B44: Resumo automático
B45: Ações escritas | E45: =COUNTA(E7:E42) -> 0
B46: Concluídas | E46: =COUNTIF(I7:I42,"Concluída") -> 0
B47: Em andamento e não iniciadas | E47: =COUNTIF(I7:I42,"Em andamento")+COUNTIF(I7:I42,"Não iniciada") -> 0
B48: Aviso | E48: =IF(E45=0,"Escreva as ações",IF(COUNTIF(L7:L42,"OK")<E45,"Há ação a rever: veja a coluna Conferência","OK")) -> Escreva as ações

Sheet Acompanhamento
B1: Acompanhamento dos objetivos
B2: Lance o resultado de cada objetivo a cada período. O último resultado, o caminho e a situação são calculados.
B4: Data da análise | E4: Usada para ler o prazo dos objetivos e das ações. Também aparece no Painel.
B6: # | C6: Indicador | D6: Unidade | E6: Sentido | F6: Base | G6: Meta | H6: Jan | I6: Fev | J6: Mar | K6: Abr | L6: Mai | M6: Jun | N6: Jul | O6: Ago | P6: Set | Q6: Out | R6: Nov | S6: Dez | T6: Último | U6: Caminho | V6: Situação
B7: O1 | C7: =IF(Objetivos!F14="","",Objetivos!F14) | D7: =IF(Objetivos!G14="","",Objetivos!G14) | E7: =IF(Objetivos!H14="","",IF(Objetivos!H14="Maior é melhor","Maior","Menor")) | F7: =IF(Objetivos!I14="","",Objetivos!I14) | G7: =IF(Objetivos!J14="","",Objetivos!J14) | T7: =IF(COUNT(H7:S7)=0,"",LOOKUP(2,1/ISNUMBER(H7:S7),H7:S7)) | U7: =IF(OR(T7="",F7="",G7=""),"",IF(IF(Objetivos!H14="Maior é melhor",G7<=F7,G7>=F7),IF(IF(Objetivos!H14="Maior é melhor",T7>=G7,T7<=G7),1,0),MAX(0,MIN(1,(T7-F7)/(G7-F7))))) | V7: =IF(OR(C7="",G7=""),"",IF(T7="","Sem resultado",IF(IF(Objetivos!H14="Maior é melhor",T7>=G7,T7<=G7),"Alcançado",IF(AND(ISNUMBER(Objetivos!K14),ISNUMBER($D$4),Objetivos!K14<$D$4),"Não alcançado",IF(F7="","Em andamento",IF(IF(Objetivos!H14="Maior é melhor",T7>F7,T7<F7),"No caminho","Em risco"))))))
B8: O2 | C8: =IF(Objetivos!F15="","",Objetivos!F15) | D8: =IF(Objetivos!G15="","",Objetivos!G15) | E8: =IF(Objetivos!H15="","",IF(Objetivos!H15="Maior é melhor","Maior","Menor")) | F8: =IF(Objetivos!I15="","",Objetivos!I15) | G8: =IF(Objetivos!J15="","",Objetivos!J15) | T8: =IF(COUNT(H8:S8)=0,"",LOOKUP(2,1/ISNUMBER(H8:S8),H8:S8)) | U8: =IF(OR(T8="",F8="",G8=""),"",IF(IF(Objetivos!H15="Maior é melhor",G8<=F8,G8>=F8),IF(IF(Objetivos!H15="Maior é melhor",T8>=G8,T8<=G8),1,0),MAX(0,MIN(1,(T8-F8)/(G8-F8))))) | V8: =IF(OR(C8="",G8=""),"",IF(T8="","Sem resultado",IF(IF(Objetivos!H15="Maior é melhor",T8>=G8,T8<=G8),"Alcançado",IF(AND(ISNUMBER(Objetivos!K15),ISNUMBER($D$4),Objetivos!K15<$D$4),"Não alcançado",IF(F8="","Em andamento",IF(IF(Objetivos!H15="Maior é melhor",T8>F8,T8<F8),"No caminho","Em risco"))))))
B9: O3 | C9: =IF(Objetivos!F16="","",Objetivos!F16) | D9: =IF(Objetivos!G16="","",Objetivos!G16) | E9: =IF(Objetivos!H16="","",IF(Objetivos!H16="Maior é melhor","Maior","Menor")) | F9: =IF(Objetivos!I16="","",Objetivos!I16) | G9: =IF(Objetivos!J16="","",Objetivos!J16) | T9: =IF(COUNT(H9:S9)=0,"",LOOKUP(2,1/ISNUMBER(H9:S9),H9:S9)) | U9: =IF(OR(T9="",F9="",G9=""),"",IF(IF(Objetivos!H16="Maior é melhor",G9<=F9,G9>=F9),IF(IF(Objetivos!H16="Maior é melhor",T9>=G9,T9<=G9),1,0),MAX(0,MIN(1,(T9-F9)/(G9-F9))))) | V9: =IF(OR(C9="",G9=""),"",IF(T9="","Sem resultado",IF(IF(Objetivos!H16="Maior é melhor",T9>=G9,T9<=G9),"Alcançado",IF(AND(ISNUMBER(Objetivos!K16),ISNUMBER($D$4),Objetivos!K16<$D$4),"Não alcançado",IF(F9="","Em andamento",IF(IF(Objetivos!H16="Maior é melhor",T9>F9,T9<F9),"No caminho","Em risco"))))))
B10: O4 | C10: =IF(Objetivos!F17="","",Objetivos!F17) | D10: =IF(Objetivos!G17="","",Objetivos!G17) | E10: =IF(Objetivos!H17="","",IF(Objetivos!H17="Maior é melhor","Maior","Menor")) | F10: =IF(Objetivos!I17="","",Objetivos!I17) | G10: =IF(Objetivos!J17="","",Objetivos!J17) | T10: =IF(COUNT(H10:S10)=0,"",LOOKUP(2,1/ISNUMBER(H10:S10),H10:S10)) | U10: =IF(OR(T10="",F10="",G10=""),"",IF(IF(Objetivos!H17="Maior é melhor",G10<=F10,G10>=F10),IF(IF(Objetivos!H17="Maior é melhor",T10>=G10,T10<=G10),1,0),MAX(0,MIN(1,(T10-F10)/(G10-F10))))) | V10: =IF(OR(C10="",G10=""),"",IF(T10="","Sem resultado",IF(IF(Objetivos!H17="Maior é melhor",T10>=G10,T10<=G10),"Alcançado",IF(AND(ISNUMBER(Objetivos!K17),ISNUMBER($D$4),Objetivos!K17<$D$4),"Não alcançado",IF(F10="","Em andamento",IF(IF(Objetivos!H17="Maior é melhor",T10>F10,T10<F10),"No caminho","Em risco"))))))
B11: O5 | C11: =IF(Objetivos!F18="","",Objetivos!F18) | D11: =IF(Objetivos!G18="","",Objetivos!G18) | E11: =IF(Objetivos!H18="","",IF(Objetivos!H18="Maior é melhor","Maior","Menor")) | F11: =IF(Objetivos!I18="","",Objetivos!I18) | G11: =IF(Objetivos!J18="","",Objetivos!J18) | T11: =IF(COUNT(H11:S11)=0,"",LOOKUP(2,1/ISNUMBER(H11:S11),H11:S11)) | U11: =IF(OR(T11="",F11="",G11=""),"",IF(IF(Objetivos!H18="Maior é melhor",G11<=F11,G11>=F11),IF(IF(Objetivos!H18="Maior é melhor",T11>=G11,T11<=G11),1,0),MAX(0,MIN(1,(T11-F11)/(G11-F11))))) | V11: =IF(OR(C11="",G11=""),"",IF(T11="","Sem resultado",IF(IF(Objetivos!H18="Maior é melhor",T11>=G11,T11<=G11),"Alcançado",IF(AND(ISNUMBER(Objetivos!K18),ISNUMBER($D$4),Objetivos!K18<$D$4),"Não alcançado",IF(F11="","Em andamento",IF(IF(Objetivos!H18="Maior é melhor",T11>F11,T11<F11),"No caminho","Em risco"))))))
B12: O6 | C12: =IF(Objetivos!F19="","",Objetivos!F19) | D12: =IF(Objetivos!G19="","",Objetivos!G19) | E12: =IF(Objetivos!H19="","",IF(Objetivos!H19="Maior é melhor","Maior","Menor")) | F12: =IF(Objetivos!I19="","",Objetivos!I19) | G12: =IF(Objetivos!J19="","",Objetivos!J19) | T12: =IF(COUNT(H12:S12)=0,"",LOOKUP(2,1/ISNUMBER(H12:S12),H12:S12)) | U12: =IF(OR(T12="",F12="",G12=""),"",IF(IF(Objetivos!H19="Maior é melhor",G12<=F12,G12>=F12),IF(IF(Objetivos!H19="Maior é melhor",T12>=G12,T12<=G12),1,0),MAX(0,MIN(1,(T12-F12)/(G12-F12))))) | V12: =IF(OR(C12="",G12=""),"",IF(T12="","Sem resultado",IF(IF(Objetivos!H19="Maior é melhor",T12>=G12,T12<=G12),"Alcançado",IF(AND(ISNUMBER(Objetivos!K19),ISNUMBER($D$4),Objetivos!K19<$D$4),"Não alcançado",IF(F12="","Em andamento",IF(IF(Objetivos!H19="Maior é melhor",T12>F12,T12<F12),"No caminho","Em risco"))))))
B13: O7 | C13: =IF(Objetivos!F20="","",Objetivos!F20) | D13: =IF(Objetivos!G20="","",Objetivos!G20) | E13: =IF(Objetivos!H20="","",IF(Objetivos!H20="Maior é melhor","Maior","Menor")) | F13: =IF(Objetivos!I20="","",Objetivos!I20) | G13: =IF(Objetivos!J20="","",Objetivos!J20) | T13: =IF(COUNT(H13:S13)=0,"",LOOKUP(2,1/ISNUMBER(H13:S13),H13:S13)) | U13: =IF(OR(T13="",F13="",G13=""),"",IF(IF(Objetivos!H20="Maior é melhor",G13<=F13,G13>=F13),IF(IF(Objetivos!H20="Maior é melhor",T13>=G13,T13<=G13),1,0),MAX(0,MIN(1,(T13-F13)/(G13-F13))))) | V13: =IF(OR(C13="",G13=""),"",IF(T13="","Sem resultado",IF(IF(Objetivos!H20="Maior é melhor",T13>=G13,T13<=G13),"Alcançado",IF(AND(ISNUMBER(Objetivos!K20),ISNUMBER($D$4),Objetivos!K20<$D$4),"Não alcançado",IF(F13="","Em andamento",IF(IF(Objetivos!H20="Maior é melhor",T13>F13,T13<F13),"No caminho","Em risco"))))))
B14: O8 | C14: =IF(Objetivos!F21="","",Objetivos!F21) | D14: =IF(Objetivos!G21="","",Objetivos!G21) | E14: =IF(Objetivos!H21="","",IF(Objetivos!H21="Maior é melhor","Maior","Menor")) | F14: =IF(Objetivos!I21="","",Objetivos!I21) | G14: =IF(Objetivos!J21="","",Objetivos!J21) | T14: =IF(COUNT(H14:S14)=0,"",LOOKUP(2,1/ISNUMBER(H14:S14),H14:S14)) | U14: =IF(OR(T14="",F14="",G14=""),"",IF(IF(Objetivos!H21="Maior é melhor",G14<=F14,G14>=F14),IF(IF(Objetivos!H21="Maior é melhor",T14>=G14,T14<=G14),1,0),MAX(0,MIN(1,(T14-F14)/(G14-F14))))) | V14: =IF(OR(C14="",G14=""),"",IF(T14="","Sem resultado",IF(IF(Objetivos!H21="Maior é melhor",T14>=G14,T14<=G14),"Alcançado",IF(AND(ISNUMBER(Objetivos!K21),ISNUMBER($D$4),Objetivos!K21<$D$4),"Não alcançado",IF(F14="","Em andamento",IF(IF(Objetivos!H21="Maior é melhor",T14>F14,T14<F14),"No caminho","Em risco"))))))
B15: O9 | C15: =IF(Objetivos!F22="","",Objetivos!F22) | D15: =IF(Objetivos!G22="","",Objetivos!G22) | E15: =IF(Objetivos!H22="","",IF(Objetivos!H22="Maior é melhor","Maior","Menor")) | F15: =IF(Objetivos!I22="","",Objetivos!I22) | G15: =IF(Objetivos!J22="","",Objetivos!J22) | T15: =IF(COUNT(H15:S15)=0,"",LOOKUP(2,1/ISNUMBER(H15:S15),H15:S15)) | U15: =IF(OR(T15="",F15="",G15=""),"",IF(IF(Objetivos!H22="Maior é melhor",G15<=F15,G15>=F15),IF(IF(Objetivos!H22="Maior é melhor",T15>=G15,T15<=G15),1,0),MAX(0,MIN(1,(T15-F15)/(G15-F15))))) | V15: =IF(OR(C15="",G15=""),"",IF(T15="","Sem resultado",IF(IF(Objetivos!H22="Maior é melhor",T15>=G15,T15<=G15),"Alcançado",IF(AND(ISNUMBER(Objetivos!K22),ISNUMBER($D$4),Objetivos!K22<$D$4),"Não alcançado",IF(F15="","Em andamento",IF(IF(Objetivos!H22="Maior é melhor",T15>F15,T15<F15),"No caminho","Em risco"))))))
B16: O10 | C16: =IF(Objetivos!F23="","",Objetivos!F23) | D16: =IF(Objetivos!G23="","",Objetivos!G23) | E16: =IF(Objetivos!H23="","",IF(Objetivos!H23="Maior é melhor","Maior","Menor")) | F16: =IF(Objetivos!I23="","",Objetivos!I23) | G16: =IF(Objetivos!J23="","",Objetivos!J23) | T16: =IF(COUNT(H16:S16)=0,"",LOOKUP(2,1/ISNUMBER(H16:S16),H16:S16)) | U16: =IF(OR(T16="",F16="",G16=""),"",IF(IF(Objetivos!H23="Maior é melhor",G16<=F16,G16>=F16),IF(IF(Objetivos!H23="Maior é melhor",T16>=G16,T16<=G16),1,0),MAX(0,MIN(1,(T16-F16)/(G16-F16))))) | V16: =IF(OR(C16="",G16=""),"",IF(T16="","Sem resultado",IF(IF(Objetivos!H23="Maior é melhor",T16>=G16,T16<=G16),"Alcançado",IF(AND(ISNUMBER(Objetivos!K23),ISNUMBER($D$4),Objetivos!K23<$D$4),"Não alcançado",IF(F16="","Em andamento",IF(IF(Objetivos!H23="Maior é melhor",T16>F16,T16<F16),"No caminho","Em risco"))))))
B17: O11 | C17: =IF(Objetivos!F24="","",Objetivos!F24) | D17: =IF(Objetivos!G24="","",Objetivos!G24) | E17: =IF(Objetivos!H24="","",IF(Objetivos!H24="Maior é melhor","Maior","Menor")) | F17: =IF(Objetivos!I24="","",Objetivos!I24) | G17: =IF(Objetivos!J24="","",Objetivos!J24) | T17: =IF(COUNT(H17:S17)=0,"",LOOKUP(2,1/ISNUMBER(H17:S17),H17:S17)) | U17: =IF(OR(T17="",F17="",G17=""),"",IF(IF(Objetivos!H24="Maior é melhor",G17<=F17,G17>=F17),IF(IF(Objetivos!H24="Maior é melhor",T17>=G17,T17<=G17),1,0),MAX(0,MIN(1,(T17-F17)/(G17-F17))))) | V17: =IF(OR(C17="",G17=""),"",IF(T17="","Sem resultado",IF(IF(Objetivos!H24="Maior é melhor",T17>=G17,T17<=G17),"Alcançado",IF(AND(ISNUMBER(Objetivos!K24),ISNUMBER($D$4),Objetivos!K24<$D$4),"Não alcançado",IF(F17="","Em andamento",IF(IF(Objetivos!H24="Maior é melhor",T17>F17,T17<F17),"No caminho","Em risco"))))))
B18: O12 | C18: =IF(Objetivos!F25="","",Objetivos!F25) | D18: =IF(Objetivos!G25="","",Objetivos!G25) | E18: =IF(Objetivos!H25="","",IF(Objetivos!H25="Maior é melhor","Maior","Menor")) | F18: =IF(Objetivos!I25="","",Objetivos!I25) | G18: =IF(Objetivos!J25="","",Objetivos!J25) | T18: =IF(COUNT(H18:S18)=0,"",LOOKUP(2,1/ISNUMBER(H18:S18),H18:S18)) | U18: =IF(OR(T18="",F18="",G18=""),"",IF(IF(Objetivos!H25="Maior é melhor",G18<=F18,G18>=F18),IF(IF(Objetivos!H25="Maior é melhor",T18>=G18,T18<=G18),1,0),MAX(0,MIN(1,(T18-F18)/(G18-F18))))) | V18: =IF(OR(C18="",G18=""),"",IF(T18="","Sem resultado",IF(IF(Objetivos!H25="Maior é melhor",T18>=G18,T18<=G18),"Alcançado",IF(AND(ISNUMBER(Objetivos!K25),ISNUMBER($D$4),Objetivos!K25<$D$4),"Não alcançado",IF(F18="","Em andamento",IF(IF(Objetivos!H25="Maior é melhor",T18>F18,T18<F18),"No caminho","Em risco"))))))
B20: Resumo automático
B21: Objetivos com resultado | D21: =COUNTIF(V7:V18,"<>Sem resultado")-COUNTBLANK(V7:V18) -> 0
B22: Por situação | D22: =IF(COUNTA(C7:C18)=0,"",COUNTIF(V7:V18,"Alcançado")&" alcançados, "&COUNTIF(V7:V18,"No caminho")&" no caminho, "&COUNTIF(V7:V18,"Em risco")&" em risco, "&COUNTIF(V7:V18,"Em andamento")&" em andamento, "&COUNTIF(V7:V18,"Não alcançado")&" não alcançados, "&COUNTIF(V7:V18,"Sem resultado")&" sem resultado") -> 0 alcançados, 0 no caminho, 0 em risco, 0 em andamento, 0 não alcançados, 0 sem resultado
B23: Aviso | D23: =IF(COUNTA(C7:C18)=0,"Escreva os objetivos na aba Objetivos",IF(D4="","Informe a data da análise",IF(COUNTIF(V7:V18,"Sem resultado")>0,"Há objetivo sem resultado",IF(COUNTIF(V7:V18,"Não alcançado")>0,"Há objetivo com prazo vencido sem alcançar a meta: decida na análise crítica",IF(COUNTIF(V7:V18,"Em risco")>0,"Há objetivo em risco: veja as ações","OK"))))) -> Informe a data da análise

Sheet Painel
B1: Painel dos objetivos
B2: A situação de cada objetivo, o caminho percorrido e as ações. A data da análise vem da aba Acompanhamento.
B4: Data da análise | D4: =IF(Acompanhamento!D4="","",Acompanhamento!D4) | E4: Informe na aba Acompanhamento.
B6: Indicador | D6: Resultado | E6: Como se lê
B7: Objetivos escritos | D7: =COUNTA(Objetivos!C14:C25) -> 0 | E7: Da aba Objetivos. O usual é de quatro a oito.
B8: Alcançado | D8: =COUNTIF(Acompanhamento!V7:V18,"Alcançado") -> 0 | E8: O último resultado atende à meta.
B9: No caminho | D9: =COUNTIF(Acompanhamento!V7:V18,"No caminho") -> 0 | E9: Não atende, mas está melhor do que a base.
B10: Em risco | D10: =COUNTIF(Acompanhamento!V7:V18,"Em risco") -> 0 | E10: Não atende, e não está melhor do que a base: olhar as ações.
B11: Não alcançados ou sem resultado | D11: =COUNTIF(Acompanhamento!V7:V18,"Não alcançado")+COUNTIF(Acompanhamento!V7:V18,"Sem resultado") -> 0 | E11: Prazo vencido sem a meta, ou nenhum resultado lançado.
B12: Caminho percorrido, em média | D12: =IF(COUNT(Acompanhamento!U7:U18)=0,"",AVERAGE(Acompanhamento!U7:U18)) | E12: Média dos objetivos com base e resultado.
B13: Ações: escritas, concluídas | D13: =COUNTA(Planos!E7:E42)&" escritas, "&COUNTIF(Planos!I7:I42,"Concluída")&" concluídas" -> 0 escritas, 0 concluídas | E13: Da aba Planos.
B14: Ações atrasadas | D14: =IF($D$4="","",SUMPRODUCT(((Planos!I7:I42="Não iniciada")+(Planos!I7:I42="Em andamento"))*ISNUMBER(Planos!H7:H42)*(Planos!H7:H42<$D$4))) | E14: Não iniciadas ou em andamento, com prazo anterior à data da análise.
B16: Leitura de cada objetivo
B17: # | C17: Objetivo | D17: Compromisso | E17: Base | F17: Último | G17: Meta | H17: Situação | I17: Caminho | J17: Ações | K17: Atrasadas | L17: Leitura
B18: O1 | C18: =IF(Objetivos!C14="","",Objetivos!C14) | D18: =IF(C18="","",Objetivos!D14) | E18: =IF(C18="","",Acompanhamento!F7) | F18: =IF(C18="","",Acompanhamento!T7) | G18: =IF(C18="","",Acompanhamento!G7) | H18: =IF(C18="","",Acompanhamento!V7) | I18: =IF(C18="","",Acompanhamento!U7) | J18: =IF(C18="","",COUNTIF(Planos!C7:C42,B18)) | K18: =IF(OR(C18="",$D$4=""),"",SUMPRODUCT((Planos!C7:C42=B18)*((Planos!I7:I42="Não iniciada")+(Planos!I7:I42="Em andamento"))*ISNUMBER(Planos!H7:H42)*(Planos!H7:H42<$D$4))) | L18: =IF(C18="","",IF(J18=0,"Sem plano",IF(H18="Alcançado","Manter até o prazo",IF(H18="Não alcançado","Decidir na análise crítica",IF(N(K18)>0,"Ação atrasada: cobrar",IF(H18="Em risco","Ação feita e não bastou? Rever o plano",IF(H18="Sem resultado","Lançar o resultado","Acompanhar o ritmo")))))))
B19: O2 | C19: =IF(Objetivos!C15="","",Objetivos!C15) | D19: =IF(C19="","",Objetivos!D15) | E19: =IF(C19="","",Acompanhamento!F8) | F19: =IF(C19="","",Acompanhamento!T8) | G19: =IF(C19="","",Acompanhamento!G8) | H19: =IF(C19="","",Acompanhamento!V8) | I19: =IF(C19="","",Acompanhamento!U8) | J19: =IF(C19="","",COUNTIF(Planos!C7:C42,B19)) | K19: =IF(OR(C19="",$D$4=""),"",SUMPRODUCT((Planos!C7:C42=B19)*((Planos!I7:I42="Não iniciada")+(Planos!I7:I42="Em andamento"))*ISNUMBER(Planos!H7:H42)*(Planos!H7:H42<$D$4))) | L19: =IF(C19="","",IF(J19=0,"Sem plano",IF(H19="Alcançado","Manter até o prazo",IF(H19="Não alcançado","Decidir na análise crítica",IF(N(K19)>0,"Ação atrasada: cobrar",IF(H19="Em risco","Ação feita e não bastou? Rever o plano",IF(H19="Sem resultado","Lançar o resultado","Acompanhar o ritmo")))))))
B20: O3 | C20: =IF(Objetivos!C16="","",Objetivos!C16) | D20: =IF(C20="","",Objetivos!D16) | E20: =IF(C20="","",Acompanhamento!F9) | F20: =IF(C20="","",Acompanhamento!T9) | G20: =IF(C20="","",Acompanhamento!G9) | H20: =IF(C20="","",Acompanhamento!V9) | I20: =IF(C20="","",Acompanhamento!U9) | J20: =IF(C20="","",COUNTIF(Planos!C7:C42,B20)) | K20: =IF(OR(C20="",$D$4=""),"",SUMPRODUCT((Planos!C7:C42=B20)*((Planos!I7:I42="Não iniciada")+(Planos!I7:I42="Em andamento"))*ISNUMBER(Planos!H7:H42)*(Planos!H7:H42<$D$4))) | L20: =IF(C20="","",IF(J20=0,"Sem plano",IF(H20="Alcançado","Manter até o prazo",IF(H20="Não alcançado","Decidir na análise crítica",IF(N(K20)>0,"Ação atrasada: cobrar",IF(H20="Em risco","Ação feita e não bastou? Rever o plano",IF(H20="Sem resultado","Lançar o resultado","Acompanhar o ritmo")))))))
B21: O4 | C21: =IF(Objetivos!C17="","",Objetivos!C17) | D21: =IF(C21="","",Objetivos!D17) | E21: =IF(C21="","",Acompanhamento!F10) | F21: =IF(C21="","",Acompanhamento!T10) | G21: =IF(C21="","",Acompanhamento!G10) | H21: =IF(C21="","",Acompanhamento!V10) | I21: =IF(C21="","",Acompanhamento!U10) | J21: =IF(C21="","",COUNTIF(Planos!C7:C42,B21)) | K21: =IF(OR(C21="",$D$4=""),"",SUMPRODUCT((Planos!C7:C42=B21)*((Planos!I7:I42="Não iniciada")+(Planos!I7:I42="Em andamento"))*ISNUMBER(Planos!H7:H42)*(Planos!H7:H42<$D$4))) | L21: =IF(C21="","",IF(J21=0,"Sem plano",IF(H21="Alcançado","Manter até o prazo",IF(H21="Não alcançado","Decidir na análise crítica",IF(N(K21)>0,"Ação atrasada: cobrar",IF(H21="Em risco","Ação feita e não bastou? Rever o plano",IF(H21="Sem resultado","Lançar o resultado","Acompanhar o ritmo")))))))
B22: O5 | C22: =IF(Objetivos!C18="","",Objetivos!C18) | D22: =IF(C22="","",Objetivos!D18) | E22: =IF(C22="","",Acompanhamento!F11) | F22: =IF(C22="","",Acompanhamento!T11) | G22: =IF(C22="","",Acompanhamento!G11) | H22: =IF(C22="","",Acompanhamento!V11) | I22: =IF(C22="","",Acompanhamento!U11) | J22: =IF(C22="","",COUNTIF(Planos!C7:C42,B22)) | K22: =IF(OR(C22="",$D$4=""),"",SUMPRODUCT((Planos!C7:C42=B22)*((Planos!I7:I42="Não iniciada")+(Planos!I7:I42="Em andamento"))*ISNUMBER(Planos!H7:H42)*(Planos!H7:H42<$D$4))) | L22: =IF(C22="","",IF(J22=0,"Sem plano",IF(H22="Alcançado","Manter até o prazo",IF(H22="Não alcançado","Decidir na análise crítica",IF(N(K22)>0,"Ação atrasada: cobrar",IF(H22="Em risco","Ação feita e não bastou? Rever o plano",IF(H22="Sem resultado","Lançar o resultado","Acompanhar o ritmo")))))))
B23: O6 | C23: =IF(Objetivos!C19="","",Objetivos!C19) | D23: =IF(C23="","",Objetivos!D19) | E23: =IF(C23="","",Acompanhamento!F12) | F23: =IF(C23="","",Acompanhamento!T12) | G23: =IF(C23="","",Acompanhamento!G12) | H23: =IF(C23="","",Acompanhamento!V12) | I23: =IF(C23="","",Acompanhamento!U12) | J23: =IF(C23="","",COUNTIF(Planos!C7:C42,B23)) | K23: =IF(OR(C23="",$D$4=""),"",SUMPRODUCT((Planos!C7:C42=B23)*((Planos!I7:I42="Não iniciada")+(Planos!I7:I42="Em andamento"))*ISNUMBER(Planos!H7:H42)*(Planos!H7:H42<$D$4))) | L23: =IF(C23="","",IF(J23=0,"Sem plano",IF(H23="Alcançado","Manter até o prazo",IF(H23="Não alcançado","Decidir na análise crítica",IF(N(K23)>0,"Ação atrasada: cobrar",IF(H23="Em risco","Ação feita e não bastou? Rever o plano",IF(H23="Sem resultado","Lançar o resultado","Acompanhar o ritmo")))))))
B24: O7 | C24: =IF(Objetivos!C20="","",Objetivos!C20) | D24: =IF(C24="","",Objetivos!D20) | E24: =IF(C24="","",Acompanhamento!F13) | F24: =IF(C24="","",Acompanhamento!T13) | G24: =IF(C24="","",Acompanhamento!G13) | H24: =IF(C24="","",Acompanhamento!V13) | I24: =IF(C24="","",Acompanhamento!U13) | J24: =IF(C24="","",COUNTIF(Planos!C7:C42,B24)) | K24: =IF(OR(C24="",$D$4=""),"",SUMPRODUCT((Planos!C7:C42=B24)*((Planos!I7:I42="Não iniciada")+(Planos!I7:I42="Em andamento"))*ISNUMBER(Planos!H7:H42)*(Planos!H7:H42<$D$4))) | L24: =IF(C24="","",IF(J24=0,"Sem plano",IF(H24="Alcançado","Manter até o prazo",IF(H24="Não alcançado","Decidir na análise crítica",IF(N(K24)>0,"Ação atrasada: cobrar",IF(H24="Em risco","Ação feita e não bastou? Rever o plano",IF(H24="Sem resultado","Lançar o resultado","Acompanhar o ritmo")))))))
B25: O8 | C25: =IF(Objetivos!C21="","",Objetivos!C21) | D25: =IF(C25="","",Objetivos!D21) | E25: =IF(C25="","",Acompanhamento!F14) | F25: =IF(C25="","",Acompanhamento!T14) | G25: =IF(C25="","",Acompanhamento!G14) | H25: =IF(C25="","",Acompanhamento!V14) | I25: =IF(C25="","",Acompanhamento!U14) | J25: =IF(C25="","",COUNTIF(Planos!C7:C42,B25)) | K25: =IF(OR(C25="",$D$4=""),"",SUMPRODUCT((Planos!C7:C42=B25)*((Planos!I7:I42="Não iniciada")+(Planos!I7:I42="Em andamento"))*ISNUMBER(Planos!H7:H42)*(Planos!H7:H42<$D$4))) | L25: =IF(C25="","",IF(J25=0,"Sem plano",IF(H25="Alcançado","Manter até o prazo",IF(H25="Não alcançado","Decidir na análise crítica",IF(N(K25)>0,"Ação atrasada: cobrar",IF(H25="Em risco","Ação feita e não bastou? Rever o plano",IF(H25="Sem resultado","Lançar o resultado","Acompanhar o ritmo")))))))
B26: O9 | C26: =IF(Objetivos!C22="","",Objetivos!C22) | D26: =IF(C26="","",Objetivos!D22) | E26: =IF(C26="","",Acompanhamento!F15) | F26: =IF(C26="","",Acompanhamento!T15) | G26: =IF(C26="","",Acompanhamento!G15) | H26: =IF(C26="","",Acompanhamento!V15) | I26: =IF(C26="","",Acompanhamento!U15) | J26: =IF(C26="","",COUNTIF(Planos!C7:C42,B26)) | K26: =IF(OR(C26="",$D$4=""),"",SUMPRODUCT((Planos!C7:C42=B26)*((Planos!I7:I42="Não iniciada")+(Planos!I7:I42="Em andamento"))*ISNUMBER(Planos!H7:H42)*(Planos!H7:H42<$D$4))) | L26: =IF(C26="","",IF(J26=0,"Sem plano",IF(H26="Alcançado","Manter até o prazo",IF(H26="Não alcançado","Decidir na análise crítica",IF(N(K26)>0,"Ação atrasada: cobrar",IF(H26="Em risco","Ação feita e não bastou? Rever o plano",IF(H26="Sem resultado","Lançar o resultado","Acompanhar o ritmo")))))))
B27: O10 | C27: =IF(Objetivos!C23="","",Objetivos!C23) | D27: =IF(C27="","",Objetivos!D23) | E27: =IF(C27="","",Acompanhamento!F16) | F27: =IF(C27="","",Acompanhamento!T16) | G27: =IF(C27="","",Acompanhamento!G16) | H27: =IF(C27="","",Acompanhamento!V16) | I27: =IF(C27="","",Acompanhamento!U16) | J27: =IF(C27="","",COUNTIF(Planos!C7:C42,B27)) | K27: =IF(OR(C27="",$D$4=""),"",SUMPRODUCT((Planos!C7:C42=B27)*((Planos!I7:I42="Não iniciada")+(Planos!I7:I42="Em andamento"))*ISNUMBER(Planos!H7:H42)*(Planos!H7:H42<$D$4))) | L27: =IF(C27="","",IF(J27=0,"Sem plano",IF(H27="Alcançado","Manter até o prazo",IF(H27="Não alcançado","Decidir na análise crítica",IF(N(K27)>0,"Ação atrasada: cobrar",IF(H27="Em risco","Ação feita e não bastou? Rever o plano",IF(H27="Sem resultado","Lançar o resultado","Acompanhar o ritmo")))))))
B28: O11 | C28: =IF(Objetivos!C24="","",Objetivos!C24) | D28: =IF(C28="","",Objetivos!D24) | E28: =IF(C28="","",Acompanhamento!F17) | F28: =IF(C28="","",Acompanhamento!T17) | G28: =IF(C28="","",Acompanhamento!G17) | H28: =IF(C28="","",Acompanhamento!V17) | I28: =IF(C28="","",Acompanhamento!U17) | J28: =IF(C28="","",COUNTIF(Planos!C7:C42,B28)) | K28: =IF(OR(C28="",$D$4=""),"",SUMPRODUCT((Planos!C7:C42=B28)*((Planos!I7:I42="Não iniciada")+(Planos!I7:I42="Em andamento"))*ISNUMBER(Planos!H7:H42)*(Planos!H7:H42<$D$4))) | L28: =IF(C28="","",IF(J28=0,"Sem plano",IF(H28="Alcançado","Manter até o prazo",IF(H28="Não alcançado","Decidir na análise crítica",IF(N(K28)>0,"Ação atrasada: cobrar",IF(H28="Em risco","Ação feita e não bastou? Rever o plano",IF(H28="Sem resultado","Lançar o resultado","Acompanhar o ritmo")))))))
B29: O12 | C29: =IF(Objetivos!C25="","",Objetivos!C25) | D29: =IF(C29="","",Objetivos!D25) | E29: =IF(C29="","",Acompanhamento!F18) | F29: =IF(C29="","",Acompanhamento!T18) | G29: =IF(C29="","",Acompanhamento!G18) | H29: =IF(C29="","",Acompanhamento!V18) | I29: =IF(C29="","",Acompanhamento!U18) | J29: =IF(C29="","",COUNTIF(Planos!C7:C42,B29)) | K29: =IF(OR(C29="",$D$4=""),"",SUMPRODUCT((Planos!C7:C42=B29)*((Planos!I7:I42="Não iniciada")+(Planos!I7:I42="Em andamento"))*ISNUMBER(Planos!H7:H42)*(Planos!H7:H42<$D$4))) | L29: =IF(C29="","",IF(J29=0,"Sem plano",IF(H29="Alcançado","Manter até o prazo",IF(H29="Não alcançado","Decidir na análise crítica",IF(N(K29)>0,"Ação atrasada: cobrar",IF(H29="Em risco","Ação feita e não bastou? Rever o plano",IF(H29="Sem resultado","Lançar o resultado","Acompanhar o ritmo")))))))
B31: Resumo automático
B32: Objetivos por compromisso | D32: =IF(D7=0,"",COUNTIF(D18:D29,"C1")&" em C1, "&COUNTIF(D18:D29,"C2")&" em C2, "&COUNTIF(D18:D29,"C3")&" em C3, "&COUNTIF(D18:D29,"C4")&" em C4")
B33: Aviso | D33: =IF(D7=0,"Escreva os objetivos na aba Objetivos",IF(D4="","Informe a data da análise na aba Acompanhamento",IF(COUNTIF(L18:L29,"Sem plano")>0,"Há objetivo sem plano",IF(N(D14)>0,"Há ação atrasada: veja a aba Planos",IF(D11>0,"Há objetivo não alcançado ou sem resultado",IF(D10>0,"Há objetivo em risco: leve à reunião","OK")))))) -> Escreva os objetivos na aba Objetivos

Sheet Checklist
B1: Checklist dos objetivos da qualidade
B2: Escolha o status de cada item na lista suspensa (coluna em amarelo-claro).
B4: # | C4: Item de verificação | D4: Status | E4: Observações
B5: 1 | C5: A política da qualidade está escrita, com compromissos que podem virar objetivos.
B6: 2 | C6: Cada objetivo responde a um compromisso da política e a uma fonte: estratégia, análise crítica, parte interessada ou requisito.
B7: 3 | C7: São poucos objetivos, de quatro a oito, e cabem em uma página.
B8: 4 | C8: Cada objetivo tem verbo, indicador, valor de partida, meta e prazo.
B9: 5 | C9: Cada objetivo tem um responsável, e um só.
B10: 6 | C10: Cada objetivo tem plano: o que será feito, com que recursos, por quem, até quando e como se avalia.
B11: 7 | C11: O prazo de cada ação é anterior ao prazo do objetivo.
B12: 8 | C12: Os objetivos foram desdobrados nos processos que mais pesam para cada um.
B13: 9 | C13: Os resultados são registrados na frequência definida, e a situação é lida a cada mês.
B14: 10 | C14: Objetivo em risco ou ação atrasada tem decisão registrada, com responsável e prazo.
B15: 11 | C15: A equipe conhece os objetivos do seu processo e sabe como contribui para eles.
B16: 12 | C16: Os objetivos são revistos na análise crítica, e os do ano seguinte saem dela.
B18: Resumo automático
B19: Itens atendidos (Sim) | D19: =COUNTIF(D5:D16,"Sim") -> 0
B20: Itens parciais | D20: =COUNTIF(D5:D16,"Parcial") -> 0
B21: Itens não atendidos | D21: =COUNTIF(D5:D16,"Não") -> 0
B22: Itens sem resposta | D22: =COUNTBLANK(D5:D16) -> 12
B23: Percentual atendido | D23: =D19/ROWS(D5:D16) -> 0
B24: Situação | D24: =IF(D19=ROWS(D5:D16),"Validado",IF(D22>0,"Em andamento","Com pendências")) -> Em andamento

Sheet Exemplo 1 - Pizzaria
B1: Objetivos da qualidade
B2: Exemplo preenchido, para consulta. Use as abas Objetivos, Planos e Acompanhamento para a sua organização.
B4: Organização | D4: Pizzaria (loja com salão e delivery)
B5: Definição | D5: 19/02/2027. Gerente da loja, com o dono e os três líderes. Ano de 2027.
B6: Política da qualidade | D6: Entregar a pizza certa, quente e no prazo, cuidar da segurança do alimento e de quem trabalha, e ouvir o cliente para melhorar todo mês.
B7: Origem | D7: Análise crítica de 14/12/2026: objetivos e metas para o ano, com indicador e meta para os processos que não tinham.
B8: Data da análise | D8: 46514
B9: C1 | D9: Entregar a pizza certa, quente e no prazo.
B10: C2 | D10: Cuidar da segurança do alimento e de quem trabalha.
B11: C3 | D11: Ouvir o cliente e melhorar todo mês.
B13: Quadro de objetivos
B14: # | C14: Objetivo | D14: Compromisso | E14: Origem | F14: Base | G14: Meta | H14: Prazo | I14: Indicador | J14: Responsável | K14: Sentido | L14: Tipo
B15: O1 | C15: Entregar 96% dos pedidos em até 40 minutos. | D15: C1 | E15: Estratégia (SWOT) | F15: 95 | G15: 96 | H15: 46752 | I15: Entregas em até 40 minutos (%) | J15: Líder da expedição | K15: Maior | L15: =IF(ISNUMBER(F15)=FALSE(),"Sem base",IF(IF(K15="Maior",G15>F15,G15<F15),"Melhorar","Manter")) -> Melhorar
B16: O2 | C16: Reduzir as reclamações para no máximo 1,5 por 100 pedidos. | D16: C3 | E16: Análise crítica | F16: 1.9 | G16: 1.5 | H16: 46752 | I16: Reclamações por 100 pedidos (por 100 pedidos) | J16: Atendente líder | K16: Menor | L16: =IF(ISNUMBER(F16)=FALSE(),"Sem base",IF(IF(K16="Maior",G16>F16,G16<F16),"Melhorar","Manter")) -> Melhorar
B17: O3 | C17: Alcançar a nota média 4,3 na pesquisa depois da entrega. | D17: C3 | E17: Análise crítica | F17: — | G17: 4.3 | H17: 46568 | I17: Nota média das três perguntas (de 1 a 5) | J17: Atendente líder | K17: Maior | L17: =IF(ISNUMBER(F17)=FALSE(),"Sem base",IF(IF(K17="Maior",G17>F17,G17<F17),"Melhorar","Manter")) -> Sem base
B18: O4 | C18: Reduzir os pedidos refeitos por erro para 1,5%. | D18: C1 | E18: Indicador fora da meta | F18: 2 | G18: 1.5 | H18: 46568 | I18: Pedidos refeitos por erro (%) | J18: Pizzaiolo líder | K18: Menor | L18: =IF(ISNUMBER(F18)=FALSE(),"Sem base",IF(IF(K18="Maior",G18>F18,G18<F18),"Melhorar","Manter")) -> Melhorar
B19: O5 | C19: Dar indicador e meta aos quatro processos que não têm. | D19: C3 | E19: Análise crítica | F19: 5 | G19: 9 | H19: 46444 | I19: Processos com indicador e meta (de 9) | J19: Gerente da loja | K19: Maior | L19: =IF(ISNUMBER(F19)=FALSE(),"Sem base",IF(IF(K19="Maior",G19>F19,G19<F19),"Melhorar","Manter")) -> Melhorar
B20: O6 | C20: Reduzir o desperdício de insumos para 3,5%. | D20: C1 | E20: Estratégia (SWOT) | F20: 3.9 | G20: 3.5 | H20: 46752 | I20: Desperdício de insumos (%) | J20: Gerente da loja | K20: Menor | L20: =IF(ISNUMBER(F20)=FALSE(),"Sem base",IF(IF(K20="Maior",G20>F20,G20<F20),"Melhorar","Manter")) -> Melhorar
B21: O7 | C21: Treinar toda a equipe nas funções da matriz de competências. | D21: C2 | E21: Parte interessada | F21: 60 | G21: 100 | H21: 46689 | I21: Cobertura da matriz de competências (%) | J21: Gerente da loja | K21: Maior | L21: =IF(ISNUMBER(F21)=FALSE(),"Sem base",IF(IF(K21="Maior",G21>F21,G21<F21),"Melhorar","Manter")) -> Melhorar
B23: Planos
B24: Obj. | C24: O que será feito | D24: Recursos | F24: Até quando | H24: Leitura | I24: Status | J24: Responsável | K24: Como se avalia
B25: O1 | C25: Rever a escala do pico com a entrega dos novos condomínios, em março. | D25: Dois entregadores extras nas sextas e nos sábados | F25: 46477 | H25: =IF(AND(OR(I25="Não iniciada",I25="Em andamento"),F25<$D$8),"Atrasada",I25) -> Concluída | I25: Concluída | J25: Líder da expedição | K25: Entregas no prazo nas noites de pico, por semana.
B26: O1 | C26: Estudar a compra do segundo forno, segundo item do Pareto dos atrasos. | D26: Orçamento de R$ 38.000 | F26: 46568 | H26: =IF(AND(OR(I26="Não iniciada",I26="Em andamento"),F26<$D$8),"Atrasada",I26) -> Em andamento | I26: Em andamento | J26: Pizzaiolo líder | K26: Decisão dos sócios em junho.
B27: O2 | C27: Tratar o motivo mais frequente de cada mês, com o Pareto das reclamações. | D27: Uma hora da reunião mensal | F27: 46752 | H27: =IF(AND(OR(I27="Não iniciada",I27="Em andamento"),F27<$D$8),"Atrasada",I27) -> Em andamento | I27: Em andamento | J27: Atendente líder | K27: Reclamações do motivo tratado, no mês seguinte.
B28: O2 | C28: Combinar a entrega na porta com as administrações dos condomínios. | D28: Duas horas do gerente por condomínio | F28: 46507 | H28: =IF(AND(OR(I28="Não iniciada",I28="Em andamento"),F28<$D$8),"Atrasada",I28) -> Concluída | I28: Concluída | J28: Gerente da loja | K28: Reclamações de pizza fria por condomínio, todo mês.
B29: O3 | C29: Imprimir o código da pesquisa nas caixas e divulgar aos clientes. | D29: Etiquetas: R$ 300 | F29: 46416 | H29: =IF(AND(OR(I29="Não iniciada",I29="Em andamento"),F29<$D$8),"Atrasada",I29) -> Concluída | I29: Concluída | J29: Atendente líder | K29: Taxa de resposta, todo mês.
B30: O3 | C30: Ler os comentários na reunião mensal e responder aos clientes. | D30: — | F30: 46568 | H30: =IF(AND(OR(I30="Não iniciada",I30="Em andamento"),F30<$D$8),"Atrasada",I30) -> Em andamento | I30: Em andamento | J30: Gerente da loja | K30: Nota por pergunta, todo mês.
B31: O4 | C31: Conferir o pedido na tela antes de montar, com a etiqueta rubricada. | D31: — | F31: 46446 | H31: =IF(AND(OR(I31="Não iniciada",I31="Em andamento"),F31<$D$8),"Atrasada",I31) -> Concluída | I31: Concluída | J31: Pizzaiolo líder | K31: Pedidos refeitos, todo mês.
B32: O5 | C32: Definir o indicador do salão, das compras, da manutenção e do treinamento, com os líderes. | D32: Quatro reuniões de uma hora | F32: 46444 | H32: =IF(AND(OR(I32="Não iniciada",I32="Em andamento"),F32<$D$8),"Atrasada",I32) -> Concluída | I32: Concluída | J32: Gerente da loja | K32: Processos com indicador no painel.
B33: O6 | C33: Implantar a ficha técnica e o custo por pizza. | D33: Oito horas do gerente e do pizzaiolo | F33: 46507 | H33: =IF(AND(OR(I33="Não iniciada",I33="Em andamento"),F33<$D$8),"Atrasada",I33) -> Atrasada | I33: Não iniciada | J33: Gerente da loja | K33: Desperdício por insumo, todo mês.
B34: O7 | C34: Treinar o segundo pizzaiolo na regulagem do forno. | D34: Oito horas | F34: 46409 | H34: =IF(AND(OR(I34="Não iniciada",I34="Em andamento"),F34<$D$8),"Atrasada",I34) -> Concluída | I34: Concluída | J34: Pizzaiolo líder | K34: Avaliação no posto, pelo pizzaiolo líder.
B35: O7 | C35: Cumprir o plano de treinamento do primeiro semestre. | D35: Quatro horas por semana | F35: 46568 | H35: =IF(AND(OR(I35="Não iniciada",I35="Em andamento"),F35<$D$8),"Atrasada",I35) -> Em andamento | I35: Em andamento | J35: Gerente da loja | K35: Cobertura da matriz, todo mês.
B37: Acompanhamento
B38: # | C38: Indicador | D38: Jan | E38: Fev | F38: Mar | G38: Abr | H38: Último | I38: Caminho | J38: Situação
B39: O1 | C39: Entregas em até 40 minutos | D39: 95 | E39: 94 | F39: 96 | G39: 95 | H39: =IF(COUNT(D39:G39)=0,"",LOOKUP(2,1/ISNUMBER(D39:G39),D39:G39)) -> 95 | I39: =IF(OR(H39="",IF(ISNUMBER(F15),F15,"")="",G15=""),"",IF(IF(IF(K15="Maior","Maior é melhor","Menor é melhor")="Maior é melhor",G15<=IF(ISNUMBER(F15),F15,""),G15>=IF(ISNUMBER(F15),F15,"")),IF(IF(IF(K15="Maior","Maior é melhor","Menor é melhor")="Maior é melhor",H39>=G15,H39<=G15),1,0),MAX(0,MIN(1,(H39-IF(ISNUMBER(F15),F15,""))/(G15-IF(ISNUMBER(F15),F15,"")))))) -> 0 | J39: =IF(H39="","Sem resultado",IF(IF(IF(K15="Maior","Maior é melhor","Menor é melhor")="Maior é melhor",H39>=G15,H39<=G15),"Alcançado",IF(AND(ISNUMBER(H15),ISNUMBER($D$8),H15<$D$8),"Não alcançado",IF(IF(ISNUMBER(F15),F15,"")="","Em andamento",IF(IF(IF(K15="Maior","Maior é melhor","Menor é melhor")="Maior é melhor",H39>IF(ISNUMBER(F15),F15,""),H39<IF(ISNUMBER(F15),F15,"")),"No caminho","Em risco"))))) -> Em risco
B40: O2 | C40: Reclamações por 100 pedidos | D40: 1.9 | E40: 1.9 | F40: 1.6 | G40: 1.4 | H40: =IF(COUNT(D40:G40)=0,"",LOOKUP(2,1/ISNUMBER(D40:G40),D40:G40)) -> 1.4 | I40: =IF(OR(H40="",IF(ISNUMBER(F16),F16,"")="",G16=""),"",IF(IF(IF(K16="Maior","Maior é melhor","Menor é melhor")="Maior é melhor",G16<=IF(ISNUMBER(F16),F16,""),G16>=IF(ISNUMBER(F16),F16,"")),IF(IF(IF(K16="Maior","Maior é melhor","Menor é melhor")="Maior é melhor",H40>=G16,H40<=G16),1,0),MAX(0,MIN(1,(H40-IF(ISNUMBER(F16),F16,""))/(G16-IF(ISNUMBER(F16),F16,"")))))) -> 1 | J40: =IF(H40="","Sem resultado",IF(IF(IF(K16="Maior","Maior é melhor","Menor é melhor")="Maior é melhor",H40>=G16,H40<=G16),"Alcançado",IF(AND(ISNUMBER(H16),ISNUMBER($D$8),H16<$D$8),"Não alcançado",IF(IF(ISNUMBER(F16),F16,"")="","Em andamento",IF(IF(IF(K16="Maior","Maior é melhor","Menor é melhor")="Maior é melhor",H40>IF(ISNUMBER(F16),F16,""),H40<IF(ISNUMBER(F16),F16,"")),"No caminho","Em risco"))))) -> Alcançado
B41: O3 | C41: Nota média das três perguntas | D41: — | E41: 4.33 | F41: 4.43 | G41: 4.53 | H41: =IF(COUNT(D41:G41)=0,"",LOOKUP(2,1/ISNUMBER(D41:G41),D41:G41)) -> 4.53 | I41: =IF(OR(H41="",IF(ISNUMBER(F17),F17,"")="",G17=""),"",IF(IF(IF(K17="Maior","Maior é melhor","Menor é melhor")="Maior é melhor",G17<=IF(ISNUMBER(F17),F17,""),G17>=IF(ISNUMBER(F17),F17,"")),IF(IF(IF(K17="Maior","Maior é melhor","Menor é melhor")="Maior é melhor",H41>=G17,H41<=G17),1,0),MAX(0,MIN(1,(H41-IF(ISNUMBER(F17),F17,""))/(G17-IF(ISNUMBER(F17),F17,"")))))) | J41: =IF(H41="","Sem resultado",IF(IF(IF(K17="Maior","Maior é melhor","Menor é melhor")="Maior é melhor",H41>=G17,H41<=G17),"Alcançado",IF(AND(ISNUMBER(H17),ISNUMBER($D$8),H17<$D$8),"Não alcançado",IF(IF(ISNUMBER(F17),F17,"")="","Em andamento",IF(IF(IF(K17="Maior","Maior é melhor","Menor é melhor")="Maior é melhor",H41>IF(ISNUMBER(F17),F17,""),H41<IF(ISNUMBER(F17),F17,"")),"No caminho","Em risco"))))) -> Alcançado
B42: O4 | C42: Pedidos refeitos por erro | D42: 1.6 | E42: 1.5 | F42: 1.4 | G42: 1.3 | H42: =IF(COUNT(D42:G42)=0,"",LOOKUP(2,1/ISNUMBER(D42:G42),D42:G42)) -> 1.3 | I42: =IF(OR(H42="",IF(ISNUMBER(F18),F18,"")="",G18=""),"",IF(IF(IF(K18="Maior","Maior é melhor","Menor é melhor")="Maior é melhor",G18<=IF(ISNUMBER(F18),F18,""),G18>=IF(ISNUMBER(F18),F18,"")),IF(IF(IF(K18="Maior","Maior é melhor","Menor é melhor")="Maior é melhor",H42>=G18,H42<=G18),1,0),MAX(0,MIN(1,(H42-IF(ISNUMBER(F18),F18,""))/(G18-IF(ISNUMBER(F18),F18,"")))))) -> 1 | J42: =IF(H42="","Sem resultado",IF(IF(IF(K18="Maior","Maior é melhor","Menor é melhor")="Maior é melhor",H42>=G18,H42<=G18),"Alcançado",IF(AND(ISNUMBER(H18),ISNUMBER($D$8),H18<$D$8),"Não alcançado",IF(IF(ISNUMBER(F18),F18,"")="","Em andamento",IF(IF(IF(K18="Maior","Maior é melhor","Menor é melhor")="Maior é melhor",H42>IF(ISNUMBER(F18),F18,""),H42<IF(ISNUMBER(F18),F18,"")),"No caminho","Em risco"))))) -> Alcançado
B43: O5 | C43: Processos com indicador e meta | D43: 5 | E43: 7 | F43: 9 | G43: 9 | H43: =IF(COUNT(D43:G43)=0,"",LOOKUP(2,1/ISNUMBER(D43:G43),D43:G43)) -> 9 | I43: =IF(OR(H43="",IF(ISNUMBER(F19),F19,"")="",G19=""),"",IF(IF(IF(K19="Maior","Maior é melhor","Menor é melhor")="Maior é melhor",G19<=IF(ISNUMBER(F19),F19,""),G19>=IF(ISNUMBER(F19),F19,"")),IF(IF(IF(K19="Maior","Maior é melhor","Menor é melhor")="Maior é melhor",H43>=G19,H43<=G19),1,0),MAX(0,MIN(1,(H43-IF(ISNUMBER(F19),F19,""))/(G19-IF(ISNUMBER(F19),F19,"")))))) -> 1 | J43: =IF(H43="","Sem resultado",IF(IF(IF(K19="Maior","Maior é melhor","Menor é melhor")="Maior é melhor",H43>=G19,H43<=G19),"Alcançado",IF(AND(ISNUMBER(H19),ISNUMBER($D$8),H19<$D$8),"Não alcançado",IF(IF(ISNUMBER(F19),F19,"")="","Em andamento",IF(IF(IF(K19="Maior","Maior é melhor","Menor é melhor")="Maior é melhor",H43>IF(ISNUMBER(F19),F19,""),H43<IF(ISNUMBER(F19),F19,"")),"No caminho","Em risco"))))) -> Alcançado
B44: O6 | C44: Desperdício de insumos | D44: 3.9 | E44: 4 | F44: 3.8 | G44: 3.9 | H44: =IF(COUNT(D44:G44)=0,"",LOOKUP(2,1/ISNUMBER(D44:G44),D44:G44)) -> 3.9 | I44: =IF(OR(H44="",IF(ISNUMBER(F20),F20,"")="",G20=""),"",IF(IF(IF(K20="Maior","Maior é melhor","Menor é melhor")="Maior é melhor",G20<=IF(ISNUMBER(F20),F20,""),G20>=IF(ISNUMBER(F20),F20,"")),IF(IF(IF(K20="Maior","Maior é melhor","Menor é melhor")="Maior é melhor",H44>=G20,H44<=G20),1,0),MAX(0,MIN(1,(H44-IF(ISNUMBER(F20),F20,""))/(G20-IF(ISNUMBER(F20),F20,"")))))) -> 0 | J44: =IF(H44="","Sem resultado",IF(IF(IF(K20="Maior","Maior é melhor","Menor é melhor")="Maior é melhor",H44>=G20,H44<=G20),"Alcançado",IF(AND(ISNUMBER(H20),ISNUMBER($D$8),H20<$D$8),"Não alcançado",IF(IF(ISNUMBER(F20),F20,"")="","Em andamento",IF(IF(IF(K20="Maior","Maior é melhor","Menor é melhor")="Maior é melhor",H44>IF(ISNUMBER(F20),F20,""),H44<IF(ISNUMBER(F20),F20,"")),"No caminho","Em risco"))))) -> Em risco
...

Sheet Exemplo 2 - Indústria
B1: Objetivos da qualidade
B2: Exemplo preenchido, para consulta. Use as abas Objetivos, Planos e Acompanhamento para a sua organização.
B4: Organização | D4: Indústria de embalagens plásticas
B5: Definição | D5: 18/02/2027. Diretor geral, com os gerentes e o Coordenador da Qualidade. Ano de 2027.
B6: Política da qualidade | D6: Entregar embalagens conformes e no prazo, cumprir os requisitos legais e os dos clientes, e melhorar os processos reduzindo as perdas.
B7: Origem | D7: Análise crítica de 18/02/2027: a certificação e a linha com material reciclado entram nos objetivos do ano.
B8: Data da análise | D8: 46577
B9: C1 | D9: Entregar embalagens conformes e no prazo.
B10: C2 | D10: Cumprir os requisitos legais e os dos clientes.
B11: C3 | D11: Melhorar os processos e reduzir as perdas.
B13: Quadro de objetivos
B14: # | C14: Objetivo | D14: Compromisso | E14: Origem | F14: Base | G14: Meta | H14: Prazo | I14: Indicador | J14: Responsável | K14: Sentido | L14: Tipo
B15: O1 | C15: Reduzir o refugo para 2,0% do peso produzido. | D15: C3 | E15: Análise crítica | F15: 2.6 | G15: 2 | H15: 46752 | I15: Refugo (% do peso) | J15: Gerente industrial | K15: Menor | L15: =IF(ISNUMBER(F15)=FALSE(),"Sem base",IF(IF(K15="Maior",G15>F15,G15<F15),"Melhorar","Manter")) -> Melhorar
B16: O2 | C16: Reduzir as reclamações para no máximo 50 por milhão de peças. | D16: C2 | E16: Parte interessada | F16: 62 | G16: 50 | H16: 46568 | I16: Reclamações por milhão de peças (por milhão) | J16: Gerente comercial | K16: Menor | L16: =IF(ISNUMBER(F16)=FALSE(),"Sem base",IF(IF(K16="Maior",G16>F16,G16<F16),"Melhorar","Manter")) -> Melhorar
B17: O3 | C17: Manter 96% das entregas na data confirmada. | D17: C1 | E17: Requisito legal ou contratual | F17: 97 | G17: 96 | H17: 46752 | I17: Entregas no prazo (%) | J17: Líder da expedição | K17: Maior | L17: =IF(ISNUMBER(F17)=FALSE(),"Sem base",IF(IF(K17="Maior",G17>F17,G17<F17),"Melhorar","Manter")) -> Manter
B18: O4 | C18: Obter a certificação ISO 9001 até dezembro. | D18: C2 | E18: Estratégia (SWOT) | F18: 0 | G18: 6 | H18: 46738 | I18: Etapas concluídas, de seis (etapas) | J18: Coordenador da Qualidade | K18: Maior | L18: =IF(ISNUMBER(F18)=FALSE(),"Sem base",IF(IF(K18="Maior",G18>F18,G18<F18),"Melhorar","Manter")) -> Melhorar
B19: O5 | C19: Produzir e aprovar o lote piloto com 30% de resina reciclada. | D19: C3 | E19: Parte interessada | F19: 0 | G19: 4 | H19: 46660 | I19: Etapas concluídas, de quatro (etapas) | J19: Gerente de engenharia | K19: Maior | L19: =IF(ISNUMBER(F19)=FALSE(),"Sem base",IF(IF(K19="Maior",G19>F19,G19<F19),"Melhorar","Manter")) -> Melhorar
B20: O6 | C20: Encerrar as não conformidades em até 60 dias. | D20: C3 | E20: Análise crítica | F20: 74 | G20: 60 | H20: 46568 | I20: Prazo médio de encerramento (dias) | J20: Coordenador da Qualidade | K20: Menor | L20: =IF(ISNUMBER(F20)=FALSE(),"Sem base",IF(IF(K20="Maior",G20>F20,G20<F20),"Melhorar","Manter")) -> Melhorar
B21: O7 | C21: Manter 100% dos fornecedores críticos avaliados a cada semestre. | D21: C2 | E21: Auditoria ou não conformidade | F21: 100 | G21: 100 | H21: 46752 | I21: Fornecedores críticos avaliados (%) | J21: Gerente de Suprimentos | K21: Maior | L21: =IF(ISNUMBER(F21)=FALSE(),"Sem base",IF(IF(K21="Maior",G21>F21,G21<F21),"Melhorar","Manter")) -> Manter
