Workbook

Sheet Instruções
B1: Matriz de competências e treinamento — Como usar esta planilha
B2: Modelo para definir o nível requerido por função, avaliar as pessoas, planejar o treinamento e registrar a eficácia.
B4: Legenda: onde preencher
B5: Amarelo-claro | C5: Células de entrada. É aqui que você digita.
B6: Cinza | C6: Células calculadas ou fixas (rótulos, requerido por pessoa, lacunas, contagens, avisos). Não altere.
B7: Cinza em itálico | C7: Linha de exemplo (marcada com “Ex.”). Mostra o formato esperado e não entra nas contagens.
B8: Listas suspensas | C8: Colunas de função, aprendizado, eficácia e status aceitam apenas as opções da lista. Os níveis aceitam 0, 1, 2 ou 3.
B9: Comentários | C9: Células com triângulo vermelho no canto trazem uma dica de preenchimento. Passe o mouse sobre elas.
B11: A escala de níveis
B12: Nível 0 · Não conhece | C12: Nunca fez, ou não sabe o que é. Evidência: nenhuma.
B13: Nível 1 · Executa com acompanhamento | C13: Conhece o padrão e faz com alguém por perto. Evidência: treinamento realizado, com avaliação de aprendizado.
B14: Nível 2 · Executa sozinho | C14: Faz no padrão, sem ajuda, com o resultado esperado. Evidência: avaliação no posto de trabalho, pelo líder.
B15: Nível 3 · Executa e treina | C15: Faz, resolve os problemas e ensina os outros. Evidência: treinamentos que deu, e resultados do processo.
B17: Ordem recomendada de preenchimento
B18: Passo 1 | C18: Aba Funções: escreva a organização, a data de referência, as competências e as funções, e o nível requerido de cada cruzamento.
B19: Passo 2 | C19: Aba Matriz: cadastre as pessoas, com a função, e o nível atual em cada competência.
B20: Passo 3 | C20: Aba Matriz: leia as lacunas de cada pessoa e a cobertura de cada competência.
B21: Passo 4 | C21: Aba Plano: escreva uma ação para cada lacuna, com quem treina e o prazo.
B22: Passo 5 | C22: Aba Plano: depois do treinamento, registre a data, o aprendizado e, no prazo, a eficácia.
B23: Passo 6 | C23: Aba Matriz: quando a eficácia for confirmada, atualize o nível da pessoa.
B24: Passo 7 | C24: Aba Registros: cadastre os treinamentos realizados, com a evidência. Aba Checklist: valide a matriz.
B26: Abas da planilha
B27: Funções | C27: Até 10 funções e 12 competências, com o nível requerido de cada cruzamento.
B28: Matriz | C28: Até 20 pessoas, com o nível atual, as lacunas, o percentual atendido, a cobertura de cada competência e o gráfico.
B29: Plano | C29: Até 25 ações de treinamento, com a situação de cada uma na data de referência.
B30: Registros | C30: Até 25 treinamentos realizados, com tema, instrutor, carga horária e participantes.
B31: Checklist | C31: Doze verificações de qualidade da matriz, com percentual de conclusão.
B32: Exemplo 1 - Pizzaria | C32: A matriz e o plano de uma loja, com oito pessoas e oito competências.
B33: Exemplo 2 - Compras | C33: A matriz e o plano do processo de aquisição de uma indústria.
B35: Regras e premissas do modelo
B36: Lacuna | C36: Nível atual abaixo do nível requerido pela função da pessoa. Nível em branco vale zero.
B37: Requerido por pessoa | C37: É lido da aba Funções, pela função escrita na aba Matriz. A função precisa estar escrita do mesmo jeito nas duas abas: use a lista.
B38: Cobertura | C38: Pessoas no nível 2 ou mais em uma competência. Menos de 2 é dependência de uma só pessoa. É uma convenção deste modelo.
B39: Eficácia | C39: Depois do treinamento, a eficácia é avaliada no posto. A planilha pede a avaliação 60 dias após a data de realização.
B40: Data de referência | C40: A situação das ações é calculada pela data de referência da aba Funções. Se ela estiver em branco, a planilha usa a data de hoje.
B41: Escala | C41: Os quatro níveis e as evidências são uma convenção deste modelo. A norma não define escala.
B42: Exemplos | C42: Os dados das abas de exemplo são ilustrativos, criados para este material.

Sheet Funções
B1: Funções e nível requerido
B2: Escreva as competências nas colunas e as funções nas linhas. Em cada cruzamento, o nível mínimo que a função exige: 0 quando não usa.
B4: Organização
B5: Data de referência | E5: Data da avaliação. Em branco, vale a data de hoje.
C7: Código | D7: C1 | E7: C2 | F7: C3 | G7: C4 | H7: C5 | I7: C6 | J7: C7 | K7: C8 | L7: C9 | M7: C10 | N7: C11 | O7: C12
C8: Competência
B9: # | C9: Função | D9: Nível requerido | E9: Nível requerido | F9: Nível requerido | G9: Nível requerido | H9: Nível requerido | I9: Nível requerido | J9: Nível requerido | K9: Nível requerido | L9: Nível requerido | M9: Nível requerido | N9: Nível requerido | O9: Nível requerido | P9: Competências exigidas
B10: 1 | P10: =IF(C10="","",COUNTIF(D10:O10,">0"))
B11: 2 | P11: =IF(C11="","",COUNTIF(D11:O11,">0"))
B12: 3 | P12: =IF(C12="","",COUNTIF(D12:O12,">0"))
B13: 4 | P13: =IF(C13="","",COUNTIF(D13:O13,">0"))
B14: 5 | P14: =IF(C14="","",COUNTIF(D14:O14,">0"))
B15: 6 | P15: =IF(C15="","",COUNTIF(D15:O15,">0"))
B16: 7 | P16: =IF(C16="","",COUNTIF(D16:O16,">0"))
B17: 8 | P17: =IF(C17="","",COUNTIF(D17:O17,">0"))
B18: 9 | P18: =IF(C18="","",COUNTIF(D18:O18,">0"))
B19: 10 | P19: =IF(C19="","",COUNTIF(D19:O19,">0"))
B21: Resumo automático
B22: Funções cadastradas | E22: =COUNTA(C10:C19) -> 0
B23: Competências cadastradas | E23: =COUNTA(D8:O8) -> 0
B24: Aviso | E24: =IF(E22=0,"Cadastre as funções",IF(E23=0,"Cadastre as competências",IF(COUNTIF(P10:P19,0)>0,"Há função sem nenhuma competência exigida",IF(SUMPRODUCT((D8:O8="")*(D10:O19>0))>0,"Há nível requerido em competência sem nome","OK")))) -> Cadastre as funções

Sheet Matriz
B1: Matriz de competências
B2: Uma pessoa por linha, com a função e o nível atual em cada competência. O requerido vem da função, e a lacuna é calculada.
B4: Organização | D4: =IF(Funções!D4="","",Funções!D4)
B5: Data de referência | D5: =IF(Funções!D5="","",Funções!D5)
B7: # | C7: Pessoa | D7: Função | E7: C1 | F7: C2 | G7: C3 | H7: C4 | I7: C5 | J7: C6 | K7: C7 | L7: C8 | M7: C9 | N7: C10 | O7: C11 | P7: C12 | Q7: Exigidas | R7: Lacunas | S7: Atendido | T7: Conferência
C8: Os nomes das competências vêm da aba Funções | E8: =IF(Funções!D8="","",Funções!D8) | F8: =IF(Funções!E8="","",Funções!E8) | G8: =IF(Funções!F8="","",Funções!F8) | H8: =IF(Funções!G8="","",Funções!G8) | I8: =IF(Funções!H8="","",Funções!H8) | J8: =IF(Funções!I8="","",Funções!I8) | K8: =IF(Funções!J8="","",Funções!J8) | L8: =IF(Funções!K8="","",Funções!K8) | ... P8: =IF(Funções!O8="","",Funções!O8)
C9: Nome | D9: Escolha na lista | E9: 0 a 3 | F9: 0 a 3 | G9: 0 a 3 | H9: 0 a 3 | I9: 0 a 3 | J9: 0 a 3 | K9: 0 a 3 | L9: 0 a 3 | M9: 0 a 3 | N9: 0 a 3 | O9: 0 a 3 | P9: 0 a 3 | Q9: Calculada | R9: Calculada | S9: Calculada | T9: Calculada
B10: 1 | Q10: =IF(C10="","",COUNTIF(E56:P56,">0")) | R10: =IF(C10="","",SUMPRODUCT((E56:P56>E10:P10)*1)) | S10: =IF(OR(C10="",Q10=0),"",1-R10/Q10) | T10: =IF(C10="","",IF(D10="","Falta a função",IF(ISNA(MATCH(D10,Funções!$C$10:$C$19,0)),"Função não cadastrada",IF(R10=0,"Sem lacunas","Com lacunas"))))
B11: 2 | Q11: =IF(C11="","",COUNTIF(E57:P57,">0")) | R11: =IF(C11="","",SUMPRODUCT((E57:P57>E11:P11)*1)) | S11: =IF(OR(C11="",Q11=0),"",1-R11/Q11) | T11: =IF(C11="","",IF(D11="","Falta a função",IF(ISNA(MATCH(D11,Funções!$C$10:$C$19,0)),"Função não cadastrada",IF(R11=0,"Sem lacunas","Com lacunas"))))
B12: 3 | Q12: =IF(C12="","",COUNTIF(E58:P58,">0")) | R12: =IF(C12="","",SUMPRODUCT((E58:P58>E12:P12)*1)) | S12: =IF(OR(C12="",Q12=0),"",1-R12/Q12) | T12: =IF(C12="","",IF(D12="","Falta a função",IF(ISNA(MATCH(D12,Funções!$C$10:$C$19,0)),"Função não cadastrada",IF(R12=0,"Sem lacunas","Com lacunas"))))
B13: 4 | Q13: =IF(C13="","",COUNTIF(E59:P59,">0")) | R13: =IF(C13="","",SUMPRODUCT((E59:P59>E13:P13)*1)) | S13: =IF(OR(C13="",Q13=0),"",1-R13/Q13) | T13: =IF(C13="","",IF(D13="","Falta a função",IF(ISNA(MATCH(D13,Funções!$C$10:$C$19,0)),"Função não cadastrada",IF(R13=0,"Sem lacunas","Com lacunas"))))
B14: 5 | Q14: =IF(C14="","",COUNTIF(E60:P60,">0")) | R14: =IF(C14="","",SUMPRODUCT((E60:P60>E14:P14)*1)) | S14: =IF(OR(C14="",Q14=0),"",1-R14/Q14) | T14: =IF(C14="","",IF(D14="","Falta a função",IF(ISNA(MATCH(D14,Funções!$C$10:$C$19,0)),"Função não cadastrada",IF(R14=0,"Sem lacunas","Com lacunas"))))
B15: 6 | Q15: =IF(C15="","",COUNTIF(E61:P61,">0")) | R15: =IF(C15="","",SUMPRODUCT((E61:P61>E15:P15)*1)) | S15: =IF(OR(C15="",Q15=0),"",1-R15/Q15) | T15: =IF(C15="","",IF(D15="","Falta a função",IF(ISNA(MATCH(D15,Funções!$C$10:$C$19,0)),"Função não cadastrada",IF(R15=0,"Sem lacunas","Com lacunas"))))
B16: 7 | Q16: =IF(C16="","",COUNTIF(E62:P62,">0")) | R16: =IF(C16="","",SUMPRODUCT((E62:P62>E16:P16)*1)) | S16: =IF(OR(C16="",Q16=0),"",1-R16/Q16) | T16: =IF(C16="","",IF(D16="","Falta a função",IF(ISNA(MATCH(D16,Funções!$C$10:$C$19,0)),"Função não cadastrada",IF(R16=0,"Sem lacunas","Com lacunas"))))
B17: 8 | Q17: =IF(C17="","",COUNTIF(E63:P63,">0")) | R17: =IF(C17="","",SUMPRODUCT((E63:P63>E17:P17)*1)) | S17: =IF(OR(C17="",Q17=0),"",1-R17/Q17) | T17: =IF(C17="","",IF(D17="","Falta a função",IF(ISNA(MATCH(D17,Funções!$C$10:$C$19,0)),"Função não cadastrada",IF(R17=0,"Sem lacunas","Com lacunas"))))
B18: 9 | Q18: =IF(C18="","",COUNTIF(E64:P64,">0")) | R18: =IF(C18="","",SUMPRODUCT((E64:P64>E18:P18)*1)) | S18: =IF(OR(C18="",Q18=0),"",1-R18/Q18) | T18: =IF(C18="","",IF(D18="","Falta a função",IF(ISNA(MATCH(D18,Funções!$C$10:$C$19,0)),"Função não cadastrada",IF(R18=0,"Sem lacunas","Com lacunas"))))
B19: 10 | Q19: =IF(C19="","",COUNTIF(E65:P65,">0")) | R19: =IF(C19="","",SUMPRODUCT((E65:P65>E19:P19)*1)) | S19: =IF(OR(C19="",Q19=0),"",1-R19/Q19) | T19: =IF(C19="","",IF(D19="","Falta a função",IF(ISNA(MATCH(D19,Funções!$C$10:$C$19,0)),"Função não cadastrada",IF(R19=0,"Sem lacunas","Com lacunas"))))
B20: 11 | Q20: =IF(C20="","",COUNTIF(E66:P66,">0")) | R20: =IF(C20="","",SUMPRODUCT((E66:P66>E20:P20)*1)) | S20: =IF(OR(C20="",Q20=0),"",1-R20/Q20) | T20: =IF(C20="","",IF(D20="","Falta a função",IF(ISNA(MATCH(D20,Funções!$C$10:$C$19,0)),"Função não cadastrada",IF(R20=0,"Sem lacunas","Com lacunas"))))
B21: 12 | Q21: =IF(C21="","",COUNTIF(E67:P67,">0")) | R21: =IF(C21="","",SUMPRODUCT((E67:P67>E21:P21)*1)) | S21: =IF(OR(C21="",Q21=0),"",1-R21/Q21) | T21: =IF(C21="","",IF(D21="","Falta a função",IF(ISNA(MATCH(D21,Funções!$C$10:$C$19,0)),"Função não cadastrada",IF(R21=0,"Sem lacunas","Com lacunas"))))
... B29: 20 | Q29: =IF(C29="","",COUNTIF(E75:P75,">0")) | R29: =IF(C29="","",SUMPRODUCT((E75:P75>E29:P29)*1)) | S29: =IF(OR(C29="",Q29=0),"",1-R29/Q29) | T29: =IF(C29="","",IF(D29="","Falta a função",IF(ISNA(MATCH(D29,Funções!$C$10:$C$19,0)),"Função não cadastrada",IF(R29=0,"Sem lacunas","Com lacunas"))))
B31: Leitura por competência
B32: Pessoas cuja função exige | E32: =IF(E8="","",SUMPRODUCT((Funções!D$10:D$19>0)*COUNTIF($D$10:$D$29,Funções!$C$10:$C$19))) | F32: =IF(F8="","",SUMPRODUCT((Funções!E$10:E$19>0)*COUNTIF($D$10:$D$29,Funções!$C$10:$C$19))) | G32: =IF(G8="","",SUMPRODUCT((Funções!F$10:F$19>0)*COUNTIF($D$10:$D$29,Funções!$C$10:$C$19))) | H32: =IF(H8="","",SUMPRODUCT((Funções!G$10:G$19>0)*COUNTIF($D$10:$D$29,Funções!$C$10:$C$19))) | I32: =IF(I8="","",SUMPRODUCT((Funções!H$10:H$19>0)*COUNTIF($D$10:$D$29,Funções!$C$10:$C$19))) | J32: =IF(J8="","",SUMPRODUCT((Funções!I$10:I$19>0)*COUNTIF($D$10:$D$29,Funções!$C$10:$C$19))) | K32: =IF(K8="","",SUMPRODUCT((Funções!J$10:J$19>0)*COUNTIF($D$10:$D$29,Funções!$C$10:$C$19))) | L32: =IF(L8="","",SUMPRODUCT((Funções!K$10:K$19>0)*COUNTIF($D$10:$D$29,Funções!$C$10:$C$19))) | ... P32: =IF(P8="","",SUMPRODUCT((Funções!O$10:O$19>0)*COUNTIF($D$10:$D$29,Funções!$C$10:$C$19)))
B33: Com lacuna | E33: =IF(E8="","",SUMPRODUCT((E$56:E$75>E$10:E$29)*1)) | F33: =IF(F8="","",SUMPRODUCT((F$56:F$75>F$10:F$29)*1)) | G33: =IF(G8="","",SUMPRODUCT((G$56:G$75>G$10:G$29)*1)) | H33: =IF(H8="","",SUMPRODUCT((H$56:H$75>H$10:H$29)*1)) | I33: =IF(I8="","",SUMPRODUCT((I$56:I$75>I$10:I$29)*1)) | J33: =IF(J8="","",SUMPRODUCT((J$56:J$75>J$10:J$29)*1)) | K33: =IF(K8="","",SUMPRODUCT((K$56:K$75>K$10:K$29)*1)) | L33: =IF(L8="","",SUMPRODUCT((L$56:L$75>L$10:L$29)*1)) | ... P33: =IF(P8="","",SUMPRODUCT((P$56:P$75>P$10:P$29)*1))
B34: No nível 2 ou mais | E34: =IF(E8="","",COUNTIF(E$10:E$29,">=2")) | F34: =IF(F8="","",COUNTIF(F$10:F$29,">=2")) | G34: =IF(G8="","",COUNTIF(G$10:G$29,">=2")) | H34: =IF(H8="","",COUNTIF(H$10:H$29,">=2")) | I34: =IF(I8="","",COUNTIF(I$10:I$29,">=2")) | J34: =IF(J8="","",COUNTIF(J$10:J$29,">=2")) | K34: =IF(K8="","",COUNTIF(K$10:K$29,">=2")) | L34: =IF(L8="","",COUNTIF(L$10:L$29,">=2")) | ... P34: =IF(P8="","",COUNTIF(P$10:P$29,">=2"))
B35: No nível 3 | E35: =IF(E8="","",COUNTIF(E$10:E$29,3)) | F35: =IF(F8="","",COUNTIF(F$10:F$29,3)) | G35: =IF(G8="","",COUNTIF(G$10:G$29,3)) | H35: =IF(H8="","",COUNTIF(H$10:H$29,3)) | I35: =IF(I8="","",COUNTIF(I$10:I$29,3)) | J35: =IF(J8="","",COUNTIF(J$10:J$29,3)) | K35: =IF(K8="","",COUNTIF(K$10:K$29,3)) | L35: =IF(L8="","",COUNTIF(L$10:L$29,3)) | ... P35: =IF(P8="","",COUNTIF(P$10:P$29,3))
B36: Cobertura | E36: =IF(OR(E8="",E32=0),"",IF(E34=0,"Ninguém no nível 2",IF(E34<2,"Uma só pessoa","Coberta"))) | F36: =IF(OR(F8="",F32=0),"",IF(F34=0,"Ninguém no nível 2",IF(F34<2,"Uma só pessoa","Coberta"))) | G36: =IF(OR(G8="",G32=0),"",IF(G34=0,"Ninguém no nível 2",IF(G34<2,"Uma só pessoa","Coberta"))) | H36: =IF(OR(H8="",H32=0),"",IF(H34=0,"Ninguém no nível 2",IF(H34<2,"Uma só pessoa","Coberta"))) | I36: =IF(OR(I8="",I32=0),"",IF(I34=0,"Ninguém no nível 2",IF(I34<2,"Uma só pessoa","Coberta"))) | J36: =IF(OR(J8="",J32=0),"",IF(J34=0,"Ninguém no nível 2",IF(J34<2,"Uma só pessoa","Coberta"))) | K36: =IF(OR(K8="",K32=0),"",IF(K34=0,"Ninguém no nível 2",IF(K34<2,"Uma só pessoa","Coberta"))) | L36: =IF(OR(L8="",L32=0),"",IF(L34=0,"Ninguém no nível 2",IF(L34<2,"Uma só pessoa","Coberta"))) | ... P36: =IF(OR(P8="",P32=0),"",IF(P34=0,"Ninguém no nível 2",IF(P34<2,"Uma só pessoa","Coberta")))
B38: Resumo automático | J38: Lacunas por competência
B39: Pessoas avaliadas | E39: =COUNTA(C10:C29) -> 0 | J39: =IF(E8="","C1","C1 · "&E8) -> C1 | P39: =IF(E8="","",E33)
B40: Lacunas | E40: =SUM(R10:R29) -> 0 | J40: =IF(F8="","C2","C2 · "&F8) -> C2 | P40: =IF(F8="","",F33)
B41: Percentual do requerido atendido | E41: =IF(SUM(Q10:Q29)=0,"",1-E40/SUM(Q10:Q29)) | J41: =IF(G8="","C3","C3 · "&G8) -> C3 | P41: =IF(G8="","",G33)
B42: Competências com uma só pessoa, ou nenhuma | E42: =COUNTIF(E36:P36,"Uma só pessoa")+COUNTIF(E36:P36,"Ninguém no nível 2") -> 0 | J42: =IF(H8="","C4","C4 · "&H8) -> C4 | P42: =IF(H8="","",H33)
B43: Aviso | E43: =IF(E39=0,"Cadastre as pessoas",IF(COUNTIF(T10:T29,"Falta*")+COUNTIF(T10:T29,"Função não cadastrada")>0,"Há pessoa sem função válida: veja a coluna Conferência",IF(E42>0,"Há competência que depende de uma só pessoa",IF(E40>0,"Há lacunas: leve ao plano de treinamento","OK")))) -> Cadastre as pessoas | J43: =IF(I8="","C5","C5 · "&I8) -> C5 | P43: =IF(I8="","",I33)
J44: =IF(J8="","C6","C6 · "&J8) -> C6 | P44: =IF(J8="","",J33)
J45: =IF(K8="","C7","C7 · "&K8) -> C7 | P45: =IF(K8="","",K33)
J46: =IF(L8="","C8","C8 · "&L8) -> C8 | P46: =IF(L8="","",L33)
J47: =IF(M8="","C9","C9 · "&M8) -> C9 | P47: =IF(M8="","",M33)
J48: =IF(N8="","C10","C10 · "&N8) -> C10 | P48: =IF(N8="","",N33)
J49: =IF(O8="","C11","C11 · "&O8) -> C11 | P49: =IF(O8="","",O33)
J50: =IF(P8="","C12","C12 · "&P8) -> C12 | P50: =IF(P8="","",P33)
B54: Nível requerido por pessoa, lido da aba Funções pela função de cada uma. Bloco calculado, usado nas lacunas.
...

Sheet Plano
B1: Plano de treinamento
B2: Uma ação para cada lacuna. Depois do treinamento, registre a data, o aprendizado e, no prazo, a eficácia no posto.
B4: # | C4: Pessoa | D4: Competência | E4: Ação | F4: Quem treina | G4: Prazo | H4: Realizada em | I4: Aprendizado | J4: Eficácia | K4: Eficácia avaliada em | L4: Observação | M4: Situação
C5: Nome, como na matriz | D5: Código, C1 a C12 | E5: Curso, instrução no posto, acompanhamento | F5: Nome ou cargo | G5: Combinado | H5: Data do treinamento | I5: Sim ou Não | J5: No posto, após o prazo | K5: Data da avaliação | L5: Resultado, indicador | M5: Calculada
B6: Ex. | C6: Bruno | D6: C3 | E6: Instrução no posto: regular o forno com o pizzaiolo líder, uma semana por turno. | F6: Rafael | G6: 46409 | H6: 46407 | I6: Sim | J6: Eficaz | K6: 46430 | L6: Regulou o forno sozinho em 8 turnos. | M6: Eficaz
B7: 1 | M7: =IF(E7="","",IF(H7="",IF(G7="","Falta o prazo",IF(G7<IF(Funções!$D$5="",TODAY(),Funções!$D$5),"Atrasada","Planejada")),IF(I7="","Falta a avaliação de aprendizado",IF(I7="Não","Não eficaz: refazer",IF(J7="",IF(H7+60<=IF(Funções!$D$5="",TODAY(),Funções!$D$5),"Avaliar a eficácia","Em acompanhamento"),IF(J7="Eficaz","Eficaz",IF(J7="Parcial","Parcial: reforçar","Não eficaz: refazer")))))))
B8: 2 | M8: =IF(E8="","",IF(H8="",IF(G8="","Falta o prazo",IF(G8<IF(Funções!$D$5="",TODAY(),Funções!$D$5),"Atrasada","Planejada")),IF(I8="","Falta a avaliação de aprendizado",IF(I8="Não","Não eficaz: refazer",IF(J8="",IF(H8+60<=IF(Funções!$D$5="",TODAY(),Funções!$D$5),"Avaliar a eficácia","Em acompanhamento"),IF(J8="Eficaz","Eficaz",IF(J8="Parcial","Parcial: reforçar","Não eficaz: refazer")))))))
B9: 3 | M9: =IF(E9="","",IF(H9="",IF(G9="","Falta o prazo",IF(G9<IF(Funções!$D$5="",TODAY(),Funções!$D$5),"Atrasada","Planejada")),IF(I9="","Falta a avaliação de aprendizado",IF(I9="Não","Não eficaz: refazer",IF(J9="",IF(H9+60<=IF(Funções!$D$5="",TODAY(),Funções!$D$5),"Avaliar a eficácia","Em acompanhamento"),IF(J9="Eficaz","Eficaz",IF(J9="Parcial","Parcial: reforçar","Não eficaz: refazer")))))))
B10: 4 | M10: =IF(E10="","",IF(H10="",IF(G10="","Falta o prazo",IF(G10<IF(Funções!$D$5="",TODAY(),Funções!$D$5),"Atrasada","Planejada")),IF(I10="","Falta a avaliação de aprendizado",IF(I10="Não","Não eficaz: refazer",IF(J10="",IF(H10+60<=IF(Funções!$D$5="",TODAY(),Funções!$D$5),"Avaliar a eficácia","Em acompanhamento"),IF(J10="Eficaz","Eficaz",IF(J10="Parcial","Parcial: reforçar","Não eficaz: refazer")))))))
B11: 5 | M11: =IF(E11="","",IF(H11="",IF(G11="","Falta o prazo",IF(G11<IF(Funções!$D$5="",TODAY(),Funções!$D$5),"Atrasada","Planejada")),IF(I11="","Falta a avaliação de aprendizado",IF(I11="Não","Não eficaz: refazer",IF(J11="",IF(H11+60<=IF(Funções!$D$5="",TODAY(),Funções!$D$5),"Avaliar a eficácia","Em acompanhamento"),IF(J11="Eficaz","Eficaz",IF(J11="Parcial","Parcial: reforçar","Não eficaz: refazer")))))))
B12: 6 | M12: =IF(E12="","",IF(H12="",IF(G12="","Falta o prazo",IF(G12<IF(Funções!$D$5="",TODAY(),Funções!$D$5),"Atrasada","Planejada")),IF(I12="","Falta a avaliação de aprendizado",IF(I12="Não","Não eficaz: refazer",IF(J12="",IF(H12+60<=IF(Funções!$D$5="",TODAY(),Funções!$D$5),"Avaliar a eficácia","Em acompanhamento"),IF(J12="Eficaz","Eficaz",IF(J12="Parcial","Parcial: reforçar","Não eficaz: refazer")))))))
B13: 7 | M13: =IF(E13="","",IF(H13="",IF(G13="","Falta o prazo",IF(G13<IF(Funções!$D$5="",TODAY(),Funções!$D$5),"Atrasada","Planejada")),IF(I13="","Falta a avaliação de aprendizado",IF(I13="Não","Não eficaz: refazer",IF(J13="",IF(H13+60<=IF(Funções!$D$5="",TODAY(),Funções!$D$5),"Avaliar a eficácia","Em acompanhamento"),IF(J13="Eficaz","Eficaz",IF(J13="Parcial","Parcial: reforçar","Não eficaz: refazer")))))))
B14: 8 | M14: =IF(E14="","",IF(H14="",IF(G14="","Falta o prazo",IF(G14<IF(Funções!$D$5="",TODAY(),Funções!$D$5),"Atrasada","Planejada")),IF(I14="","Falta a avaliação de aprendizado",IF(I14="Não","Não eficaz: refazer",IF(J14="",IF(H14+60<=IF(Funções!$D$5="",TODAY(),Funções!$D$5),"Avaliar a eficácia","Em acompanhamento"),IF(J14="Eficaz","Eficaz",IF(J14="Parcial","Parcial: reforçar","Não eficaz: refazer")))))))
B15: 9 | M15: =IF(E15="","",IF(H15="",IF(G15="","Falta o prazo",IF(G15<IF(Funções!$D$5="",TODAY(),Funções!$D$5),"Atrasada","Planejada")),IF(I15="","Falta a avaliação de aprendizado",IF(I15="Não","Não eficaz: refazer",IF(J15="",IF(H15+60<=IF(Funções!$D$5="",TODAY(),Funções!$D$5),"Avaliar a eficácia","Em acompanhamento"),IF(J15="Eficaz","Eficaz",IF(J15="Parcial","Parcial: reforçar","Não eficaz: refazer")))))))
B16: 10 | M16: =IF(E16="","",IF(H16="",IF(G16="","Falta o prazo",IF(G16<IF(Funções!$D$5="",TODAY(),Funções!$D$5),"Atrasada","Planejada")),IF(I16="","Falta a avaliação de aprendizado",IF(I16="Não","Não eficaz: refazer",IF(J16="",IF(H16+60<=IF(Funções!$D$5="",TODAY(),Funções!$D$5),"Avaliar a eficácia","Em acompanhamento"),IF(J16="Eficaz","Eficaz",IF(J16="Parcial","Parcial: reforçar","Não eficaz: refazer")))))))
B17: 11 | M17: =IF(E17="","",IF(H17="",IF(G17="","Falta o prazo",IF(G17<IF(Funções!$D$5="",TODAY(),Funções!$D$5),"Atrasada","Planejada")),IF(I17="","Falta a avaliação de aprendizado",IF(I17="Não","Não eficaz: refazer",IF(J17="",IF(H17+60<=IF(Funções!$D$5="",TODAY(),Funções!$D$5),"Avaliar a eficácia","Em acompanhamento"),IF(J17="Eficaz","Eficaz",IF(J17="Parcial","Parcial: reforçar","Não eficaz: refazer")))))))
B18: 12 | M18: =IF(E18="","",IF(H18="",IF(G18="","Falta o prazo",IF(G18<IF(Funções!$D$5="",TODAY(),Funções!$D$5),"Atrasada","Planejada")),IF(I18="","Falta a avaliação de aprendizado",IF(I18="Não","Não eficaz: refazer",IF(J18="",IF(H18+60<=IF(Funções!$D$5="",TODAY(),Funções!$D$5),"Avaliar a eficácia","Em acompanhamento"),IF(J18="Eficaz","Eficaz",IF(J18="Parcial","Parcial: reforçar","Não eficaz: refazer")))))))
... B31: 25 | M31: =IF(E31="","",IF(H31="",IF(G31="","Falta o prazo",IF(G31<IF(Funções!$D$5="",TODAY(),Funções!$D$5),"Atrasada","Planejada")),IF(I31="","Falta a avaliação de aprendizado",IF(I31="Não","Não eficaz: refazer",IF(J31="",IF(H31+60<=IF(Funções!$D$5="",TODAY(),Funções!$D$5),"Avaliar a eficácia","Em acompanhamento"),IF(J31="Eficaz","Eficaz",IF(J31="Parcial","Parcial: reforçar","Não eficaz: refazer")))))))
B33: Resumo automático
B34: Ações registradas | E34: =COUNTA(E7:E31) -> 0
B35: Planejadas, no prazo | E35: =COUNTIF(M7:M31,"Planejada") -> 0
B36: Atrasadas | E36: =COUNTIF(M7:M31,"Atrasada") -> 0
B37: Realizadas, a avaliar | E37: =COUNTIF(M7:M31,"Avaliar a eficácia")+COUNTIF(M7:M31,"Falta a avaliação de aprendizado") -> 0
B38: Eficazes | E38: =COUNTIF(M7:M31,"Eficaz") -> 0
B39: A reforçar ou refazer | E39: =COUNTIF(M7:M31,"Parcial: reforçar")+COUNTIF(M7:M31,"Não eficaz: refazer") -> 0
B40: Aviso | E40: =IF(E34=0,"Registre as ações",IF(COUNTIF(M7:M31,"Falta o prazo")>0,"Há ação sem prazo",IF(E36>0,"Há ação atrasada",IF(E37>0,"Há treinamento realizado com avaliação pendente",IF(E39>0,"Há ação a reforçar ou refazer","OK"))))) -> Registre as ações

Sheet Registros
B1: Registros de treinamento
B2: Um treinamento por linha, com a evidência de que aconteceu e de que o aprendizado foi avaliado.
B4: # | C4: Data | D4: Tema | E4: Instrutor | F4: Carga horária | G4: Participantes | H4: Aprendizado avaliado? | I4: Evidência | J4: Conferência
C5: Do treinamento | D5: Assunto e padrão | E5: Nome ou cargo | F5: Em horas | G5: Número de pessoas | H5: Sim ou Não | I5: Lista de presença, prova, certificado | J5: Calculada
B6: Ex. | C6: 46323 | D6: IT-EXP-01: agrupamento por zona e conferência do pedido | E6: Sérgio, líder da expedição | F6: 2 | G6: 1 | H6: Sim | I6: Lista de presença e demonstração no posto | J6: Completo
B7: 1 | J7: =IF(D7="","",IF(C7="","Falta a data",IF(I7="","Falta a evidência",IF(H7="","Falta a avaliação de aprendizado",IF(H7="Não","Sem avaliação de aprendizado","Completo")))))
B8: 2 | J8: =IF(D8="","",IF(C8="","Falta a data",IF(I8="","Falta a evidência",IF(H8="","Falta a avaliação de aprendizado",IF(H8="Não","Sem avaliação de aprendizado","Completo")))))
B9: 3 | J9: =IF(D9="","",IF(C9="","Falta a data",IF(I9="","Falta a evidência",IF(H9="","Falta a avaliação de aprendizado",IF(H9="Não","Sem avaliação de aprendizado","Completo")))))
B10: 4 | J10: =IF(D10="","",IF(C10="","Falta a data",IF(I10="","Falta a evidência",IF(H10="","Falta a avaliação de aprendizado",IF(H10="Não","Sem avaliação de aprendizado","Completo")))))
B11: 5 | J11: =IF(D11="","",IF(C11="","Falta a data",IF(I11="","Falta a evidência",IF(H11="","Falta a avaliação de aprendizado",IF(H11="Não","Sem avaliação de aprendizado","Completo")))))
B12: 6 | J12: =IF(D12="","",IF(C12="","Falta a data",IF(I12="","Falta a evidência",IF(H12="","Falta a avaliação de aprendizado",IF(H12="Não","Sem avaliação de aprendizado","Completo")))))
B13: 7 | J13: =IF(D13="","",IF(C13="","Falta a data",IF(I13="","Falta a evidência",IF(H13="","Falta a avaliação de aprendizado",IF(H13="Não","Sem avaliação de aprendizado","Completo")))))
B14: 8 | J14: =IF(D14="","",IF(C14="","Falta a data",IF(I14="","Falta a evidência",IF(H14="","Falta a avaliação de aprendizado",IF(H14="Não","Sem avaliação de aprendizado","Completo")))))
B15: 9 | J15: =IF(D15="","",IF(C15="","Falta a data",IF(I15="","Falta a evidência",IF(H15="","Falta a avaliação de aprendizado",IF(H15="Não","Sem avaliação de aprendizado","Completo")))))
B16: 10 | J16: =IF(D16="","",IF(C16="","Falta a data",IF(I16="","Falta a evidência",IF(H16="","Falta a avaliação de aprendizado",IF(H16="Não","Sem avaliação de aprendizado","Completo")))))
B17: 11 | J17: =IF(D17="","",IF(C17="","Falta a data",IF(I17="","Falta a evidência",IF(H17="","Falta a avaliação de aprendizado",IF(H17="Não","Sem avaliação de aprendizado","Completo")))))
B18: 12 | J18: =IF(D18="","",IF(C18="","Falta a data",IF(I18="","Falta a evidência",IF(H18="","Falta a avaliação de aprendizado",IF(H18="Não","Sem avaliação de aprendizado","Completo")))))
... B31: 25 | J31: =IF(D31="","",IF(C31="","Falta a data",IF(I31="","Falta a evidência",IF(H31="","Falta a avaliação de aprendizado",IF(H31="Não","Sem avaliação de aprendizado","Completo")))))
B33: Resumo automático
B34: Treinamentos registrados | E34: =COUNTA(D7:D31) -> 0
B35: Horas de treinamento | E35: =SUM(F7:F31) -> 0
B36: Pessoas-hora | E36: =SUMPRODUCT(F7:F31,G7:G31) -> 0
B37: Aviso | E37: =IF(E34=0,"Registre os treinamentos",IF(COUNTIF(J7:J31,"Falta*")>0,"Há treinamento com campos em branco: veja a coluna Conferência",IF(COUNTIF(J7:J31,"Sem avaliação*")>0,"Há treinamento sem avaliação de aprendizado","OK"))) -> Registre os treinamentos

Sheet Checklist
B1: Checklist da matriz de competências
B2: Escolha o status de cada item na lista suspensa (coluna em amarelo-claro).
B4: # | C4: Item de verificação | D4: Status | E4: Observações
B5: 1 | C5: As funções que afetam a qualidade estão listadas, com as competências que cada uma exige.
B6: 2 | C6: A escala de níveis está escrita e foi entendida pelos líderes.
B7: 3 | C7: Cada pessoa foi avaliada em cada competência da sua função, com evidência.
B8: 4 | C8: As lacunas estão identificadas: nível abaixo do requerido.
B9: 5 | C9: Cada lacuna tem uma ação no plano, com responsável e prazo.
B10: 6 | C10: Cada competência crítica tem pelo menos duas pessoas no nível 2 ou mais.
B11: 7 | C11: Os treinamentos realizados têm registro: data, tema, instrutor e presença.
B12: 8 | C12: O aprendizado é avaliado no fim de cada treinamento.
B13: 9 | C13: A eficácia é avaliada no posto de trabalho, depois de um prazo definido.
B14: 10 | C14: A matriz é atualizada depois da avaliação da eficácia.
B15: 11 | C15: Quem entra na equipe passa pela integração antes de trabalhar sozinho.
B16: 12 | C16: As pessoas sabem responder às perguntas de conscientização: política, objetivos, contribuição e consequências.
B18: Resumo automático
B19: Itens atendidos (Sim) | D19: =COUNTIF(D5:D16,"Sim") -> 0
B20: Itens parciais | D20: =COUNTIF(D5:D16,"Parcial") -> 0
B21: Itens não atendidos | D21: =COUNTIF(D5:D16,"Não") -> 0
B22: Itens sem resposta | D22: =COUNTBLANK(D5:D16) -> 12
B23: Percentual atendido | D23: =D19/ROWS(D5:D16) -> 0
B24: Situação | D24: =IF(D19=ROWS(D5:D16),"Validado",IF(D22>0,"Em andamento","Com pendências")) -> Em andamento

Sheet Exemplo 1 - Pizzaria
B1: Matriz de competências e treinamento
B2: Exemplo preenchido, para consulta. Use as abas Funções, Matriz, Plano e Registros para a sua equipe.
B4: Organização | C4: Pizzaria (loja com salão e delivery)
B5: Data de referência | C5: 46430
B6: Participantes | C6: Gerente da loja, com os três líderes
B7: Revisão | C7: A cada seis meses, e a cada admissão ou mudança de função.
B8: Origem | C8: Processo “Treinar a equipe” com 31% dos elementos definidos no mapa de 14/10/2026, e risco R6: só o pizzaiolo líder regula o forno.
B10: Competências e nível requerido por função
B11: Função | C11: Competência → | D11: C1 | E11: C2 | F11: C3 | G11: C4 | H11: C5 | I11: C6 | J11: C7 | K11: C8
C12: Nome da competência | D12: Registrar o pedido pelo roteiro | E12: Produzir no padrão das receitas | F12: Regular o forno | G12: Controlar a temperatura e as boas práticas | H12: Embalar e conferir o pedido | I12: Agrupar por zona e entregar | J12: Dirigir com segurança | K12: Atender no salão
B13: Gerente da loja | D13: 2 | E13: 1 | F13: 1 | G13: 2 | H13: 1 | I13: 2 | J13: 0 | K13: 3
B14: Atendente | D14: 2 | E14: 0 | F14: 0 | G14: 1 | H14: 2 | I14: 1 | J14: 0 | K14: 2
B15: Pizzaiolo | D15: 0 | E15: 3 | F15: 2 | G15: 3 | H15: 2 | I15: 0 | J15: 0 | K15: 0
B16: Líder da expedição | D16: 1 | E16: 0 | F16: 0 | G16: 1 | H16: 3 | I16: 3 | J16: 2 | K16: 0
B17: Entregador | D17: 0 | E17: 0 | F17: 0 | G17: 1 | H17: 1 | I17: 2 | J17: 2 | K17: 0
B19: Matriz · níveis em 12/02/2027
B20: Pessoa | C20: Função | D20: C1 | E20: C2 | F20: C3 | G20: C4 | H20: C5 | I20: C6 | J20: C7 | K20: C8 | L20: Lacunas | M20: Atendido | N20: Situação
B21: Marina | C21: Gerente da loja | D21: 3 | E21: 1 | F21: 1 | G21: 2 | H21: 2 | I21: 2 | J21: 0 | K21: 3 | L21: =SUMPRODUCT((D13:K13>D21:K21)*1) -> 0 | M21: =1-L21/COUNTIF(D13:K13,">0") -> 1 | N21: =IF(L21=0,"Sem lacunas","Com lacunas") -> Sem lacunas
B22: Carla | C22: Atendente | D22: 3 | E22: 0 | F22: 0 | G22: 1 | H22: 2 | I22: 2 | J22: 0 | K22: 2 | L22: =SUMPRODUCT((D14:K14>D22:K22)*1) -> 0 | M22: =1-L22/COUNTIF(D14:K14,">0") -> 1 | N22: =IF(L22=0,"Sem lacunas","Com lacunas") -> Sem lacunas
B23: Diego | C23: Atendente | D23: 2 | E23: 0 | F23: 0 | G23: 1 | H23: 1 | I23: 1 | J23: 0 | K23: 1 | L23: =SUMPRODUCT((D14:K14>D23:K23)*1) -> 2 | M23: =1-L23/COUNTIF(D14:K14,">0") -> 0.6 | N23: =IF(L23=0,"Sem lacunas","Com lacunas") -> Com lacunas
B24: Rafael | C24: Pizzaiolo | D24: 0 | E24: 3 | F24: 3 | G24: 3 | H24: 2 | I24: 0 | J24: 0 | K24: 0 | L24: =SUMPRODUCT((D15:K15>D24:K24)*1) -> 0 | M24: =1-L24/COUNTIF(D15:K15,">0") -> 1 | N24: =IF(L24=0,"Sem lacunas","Com lacunas") -> Sem lacunas
B25: Bruno | C25: Pizzaiolo | D25: 0 | E25: 2 | F25: 2 | G25: 2 | H25: 2 | I25: 0 | J25: 0 | K25: 0 | L25: =SUMPRODUCT((D15:K15>D25:K25)*1) -> 2 | M25: =1-L25/COUNTIF(D15:K15,">0") -> 0.5 | N25: =IF(L25=0,"Sem lacunas","Com lacunas") -> Com lacunas
B26: Sérgio | C26: Líder da expedição | D26: 1 | E26: 0 | F26: 0 | G26: 1 | H26: 3 | I26: 3 | J26: 2 | K26: 0 | L26: =SUMPRODUCT((D16:K16>D26:K26)*1) -> 0 | M26: =1-L26/COUNTIF(D16:K16,">0") -> 1 | N26: =IF(L26=0,"Sem lacunas","Com lacunas") -> Sem lacunas
B27: Paulo | C27: Entregador | D27: 0 | E27: 0 | F27: 0 | G27: 1 | H27: 1 | I27: 2 | J27: 2 | K27: 0 | L27: =SUMPRODUCT((D17:K17>D27:K27)*1) -> 0 | M27: =1-L27/COUNTIF(D17:K17,">0") -> 1 | N27: =IF(L27=0,"Sem lacunas","Com lacunas") -> Sem lacunas
B28: Igor | C28: Entregador | D28: 0 | E28: 0 | F28: 0 | G28: 0 | H28: 1 | I28: 1 | J28: 2 | K28: 0 | L28: =SUMPRODUCT((D17:K17>D28:K28)*1) -> 2 | M28: =1-L28/COUNTIF(D17:K17,">0") -> 0.5 | N28: =IF(L28=0,"Sem lacunas","Com lacunas") -> Com lacunas
B29: No nível 2 ou mais | D29: =COUNTIF(D21:D28,">=2") -> 3 | E29: =COUNTIF(E21:E28,">=2") -> 2 | F29: =COUNTIF(F21:F28,">=2") -> 2 | G29: =COUNTIF(G21:G28,">=2") -> 3 | H29: =COUNTIF(H21:H28,">=2") -> 5 | I29: =COUNTIF(I21:I28,">=2") -> 4 | J29: =COUNTIF(J21:J28,">=2") -> 3 | K29: =COUNTIF(K21:K28,">=2") -> 2
B30: No nível 3 | D30: =COUNTIF(D21:D28,3) -> 2 | E30: =COUNTIF(E21:E28,3) -> 1 | F30: =COUNTIF(F21:F28,3) -> 1 | G30: =COUNTIF(G21:G28,3) -> 1 | H30: =COUNTIF(H21:H28,3) -> 1 | I30: =COUNTIF(I21:I28,3) -> 1 | J30: =COUNTIF(J21:J28,3) -> 0 | K30: =COUNTIF(K21:K28,3) -> 1
B31: Célula com borda vermelha: lacuna, nível abaixo do requerido pela função.
B33: Plano de treinamento
B34: Pessoa | C34: Comp. | D34: Ação | H34: Quem treina | J34: Prazo | L34: Realizada | M34: Aprendizado | N34: Eficácia | O34: Situação
B35: Bruno | C35: C3 | D35: Instrução no posto: regular o forno com o pizzaiolo líder, uma semana por turno. | H35: Rafael | J35: 46409 | L35: 46407 | M35: Sim | N35: Eficaz | O35: =IF(D35="","",IF(L35="",IF(J35="","Falta o prazo",IF(J35<$C$5,"Atrasada","Planejada")),IF(M35="","Falta a avaliação de aprendizado",IF(M35="Não","Não eficaz: refazer",IF(N35="",IF(L35+60<=$C$5,"Avaliar a eficácia","Em acompanhamento"),IF(N35="Eficaz","Eficaz",IF(N35="Parcial","Parcial: reforçar","Não eficaz: refazer"))))))) -> Eficaz
B36: Bruno | C36: C2 | D36: Acompanhamento das receitas com maior desperdício, com conferência do pizzaiolo líder. | H36: Rafael | J36: 46458 | L36: 46423 | M36: Sim | O36: =IF(D36="","",IF(L36="",IF(J36="","Falta o prazo",IF(J36<$C$5,"Atrasada","Planejada")),IF(M36="","Falta a avaliação de aprendizado",IF(M36="Não","Não eficaz: refazer",IF(N36="",IF(L36+60<=$C$5,"Avaliar a eficácia","Em acompanhamento"),IF(N36="Eficaz","Eficaz",IF(N36="Parcial","Parcial: reforçar","Não eficaz: refazer"))))))) -> Em acompanhamento
B37: Bruno | C37: C4 | D37: Treinamento em boas práticas e controle de temperatura, com prova. | H37: Marina | J37: 46444 | L37: 46428 | M37: Sim | O37: =IF(D37="","",IF(L37="",IF(J37="","Falta o prazo",IF(J37<$C$5,"Atrasada","Planejada")),IF(M37="","Falta a avaliação de aprendizado",IF(M37="Não","Não eficaz: refazer",IF(N37="",IF(L37+60<=$C$5,"Avaliar a eficácia","Em acompanhamento"),IF(N37="Eficaz","Eficaz",IF(N37="Parcial","Parcial: reforçar","Não eficaz: refazer"))))))) -> Em acompanhamento
B38: Diego | C38: C5 | D38: Conferência do pedido com o líder da expedição, nas noites de sexta. | H38: Sérgio | J38: 46444 | O38: =IF(D38="","",IF(L38="",IF(J38="","Falta o prazo",IF(J38<$C$5,"Atrasada","Planejada")),IF(M38="","Falta a avaliação de aprendizado",IF(M38="Não","Não eficaz: refazer",IF(N38="",IF(L38+60<=$C$5,"Avaliar a eficácia","Em acompanhamento"),IF(N38="Eficaz","Eficaz",IF(N38="Parcial","Parcial: reforçar","Não eficaz: refazer"))))))) -> Planejada
B39: Diego | C39: C8 | D39: Atendimento no salão, depois do padrão de atendimento. | H39: Marina | J39: 46472 | O39: =IF(D39="","",IF(L39="",IF(J39="","Falta o prazo",IF(J39<$C$5,"Atrasada","Planejada")),IF(M39="","Falta a avaliação de aprendizado",IF(M39="Não","Não eficaz: refazer",IF(N39="",IF(L39+60<=$C$5,"Avaliar a eficácia","Em acompanhamento"),IF(N39="Eficaz","Eficaz",IF(N39="Parcial","Parcial: reforçar","Não eficaz: refazer"))))))) -> Planejada
B40: Igor | C40: C6 | D40: Treinamento na IT-EXP-01, com o líder da expedição. | H40: Sérgio | J40: 46325 | L40: 46323 | M40: Sim | N40: Parcial | O40: =IF(D40="","",IF(L40="",IF(J40="","Falta o prazo",IF(J40<$C$5,"Atrasada","Planejada")),IF(M40="","Falta a avaliação de aprendizado",IF(M40="Não","Não eficaz: refazer",IF(N40="",IF(L40+60<=$C$5,"Avaliar a eficácia","Em acompanhamento"),IF(N40="Eficaz","Eficaz",IF(N40="Parcial","Parcial: reforçar","Não eficaz: refazer"))))))) -> Parcial: reforçar
B41: Igor | C41: C4 | D41: Integração: boas práticas de manipulação. | H41: Marina | J41: 46416 | O41: =IF(D41="","",IF(L41="",IF(J41="","Falta o prazo",IF(J41<$C$5,"Atrasada","Planejada")),IF(M41="","Falta a avaliação de aprendizado",IF(M41="Não","Não eficaz: refazer",IF(N41="",IF(L41+60<=$C$5,"Avaliar a eficácia","Em acompanhamento"),IF(N41="Eficaz","Eficaz",IF(N41="Parcial","Parcial: reforçar","Não eficaz: refazer"))))))) -> Atrasada
B43: Resumo automático
B44: Pessoas avaliadas | F44: =COUNTA(B21:B28) -> 8
B45: Lacunas | F45: =SUM(L21:L28) -> 6
...

Sheet Exemplo 2 - Compras
B1: Matriz de competências e treinamento
B2: Exemplo preenchido, para consulta. Use as abas Funções, Matriz, Plano e Registros para a sua equipe.
B4: Organização | C4: Indústria de embalagens plásticas · Suprimentos
B5: Data de referência | C5: 46458
B6: Participantes | C6: Gerente de Suprimentos, com o Coordenador da Qualidade e o RH
B7: Revisão | C7: A cada seis meses, com a avaliação de desempenho.
B8: Origem | C8: Revisão 6 do PR-SUP-01, admissão de um comprador em janeiro e decisão da análise crítica de 18/02/2027: formar mais quatro auditores internos.
B10: Competências e nível requerido por função
B11: Função | C11: Competência → | D11: S1 | E11: S2 | F11: S3 | G11: S4 | H11: S5 | I11: S6 | J11: S7 | K11: S8
C12: Nome da competência | D12: Aplicar o PR-SUP-01 rev. 6 | E12: Especificar itens e usar o cadastro | F12: Cotar e negociar | G12: Homologar e avaliar fornecedores | H12: Operar o sistema de compras | I12: Receber e conferir materiais | J12: Requisitos da ISO 9001 para aquisição | K12: Auditar processos internamente
B13: Gerente de Suprimentos | D13: 3 | E13: 2 | F13: 3 | G13: 3 | H13: 2 | I13: 1 | J13: 2 | K13: 1
B14: Comprador | D14: 3 | E14: 2 | F14: 2 | G14: 2 | H14: 3 | I14: 1 | J14: 1 | K14: 0
B15: Líder do Recebimento | D15: 1 | E15: 2 | F15: 0 | G15: 0 | H15: 2 | I15: 3 | J15: 1 | K15: 0
B17: Matriz · níveis em 12/03/2027
B18: Pessoa | C18: Função | D18: S1 | E18: S2 | F18: S3 | G18: S4 | H18: S5 | I18: S6 | J18: S7 | K18: S8 | L18: Lacunas | M18: Atendido | N18: Situação
B19: Helena | C19: Gerente de Suprimentos | D19: 3 | E19: 2 | F19: 3 | G19: 3 | H19: 2 | I19: 1 | J19: 2 | K19: 0 | L19: =SUMPRODUCT((D13:K13>D19:K19)*1) -> 1 | M19: =1-L19/COUNTIF(D13:K13,">0") -> 0.875 | N19: =IF(L19=0,"Sem lacunas","Com lacunas") -> Com lacunas
B20: Antônio | C20: Comprador | D20: 3 | E20: 3 | F20: 3 | G20: 3 | H20: 3 | I20: 1 | J20: 2 | K20: 1 | L20: =SUMPRODUCT((D14:K14>D20:K20)*1) -> 0 | M20: =1-L20/COUNTIF(D14:K14,">0") -> 1 | N20: =IF(L20=0,"Sem lacunas","Com lacunas") -> Sem lacunas
B21: Luana | C21: Comprador | D21: 2 | E21: 2 | F21: 2 | G21: 1 | H21: 3 | I21: 1 | J21: 1 | K21: 0 | L21: =SUMPRODUCT((D14:K14>D21:K21)*1) -> 2 | M21: =1-L21/COUNTIF(D14:K14,">0") -> 0.71428571 | N21: =IF(L21=0,"Sem lacunas","Com lacunas") -> Com lacunas
B22: Felipe | C22: Comprador | D22: 3 | E22: 2 | F22: 2 | G22: 2 | H22: 3 | I22: 1 | J22: 0 | K22: 0 | L22: =SUMPRODUCT((D14:K14>D22:K22)*1) -> 1 | M22: =1-L22/COUNTIF(D14:K14,">0") -> 0.85714286 | N22: =IF(L22=0,"Sem lacunas","Com lacunas") -> Com lacunas
B23: Camila | C23: Comprador | D23: 1 | E23: 1 | F23: 1 | G23: 0 | H23: 2 | I23: 0 | J23: 0 | K23: 0 | L23: =SUMPRODUCT((D14:K14>D23:K23)*1) -> 7 | M23: =1-L23/COUNTIF(D14:K14,">0") -> 0 | N23: =IF(L23=0,"Sem lacunas","Com lacunas") -> Com lacunas
B24: Jorge | C24: Líder do Recebimento | D24: 1 | E24: 2 | F24: 0 | G24: 0 | H24: 2 | I24: 3 | J24: 1 | K24: 0 | L24: =SUMPRODUCT((D15:K15>D24:K24)*1) -> 0 | M24: =1-L24/COUNTIF(D15:K15,">0") -> 1 | N24: =IF(L24=0,"Sem lacunas","Com lacunas") -> Sem lacunas
B25: No nível 2 ou mais | D25: =COUNTIF(D19:D24,">=2") -> 4 | E25: =COUNTIF(E19:E24,">=2") -> 5 | F25: =COUNTIF(F19:F24,">=2") -> 4 | G25: =COUNTIF(G19:G24,">=2") -> 3 | H25: =COUNTIF(H19:H24,">=2") -> 6 | I25: =COUNTIF(I19:I24,">=2") -> 1 | J25: =COUNTIF(J19:J24,">=2") -> 2 | K25: =COUNTIF(K19:K24,">=2") -> 0
B26: No nível 3 | D26: =COUNTIF(D19:D24,3) -> 3 | E26: =COUNTIF(E19:E24,3) -> 1 | F26: =COUNTIF(F19:F24,3) -> 2 | G26: =COUNTIF(G19:G24,3) -> 2 | H26: =COUNTIF(H19:H24,3) -> 3 | I26: =COUNTIF(I19:I24,3) -> 1 | J26: =COUNTIF(J19:J24,3) -> 0 | K26: =COUNTIF(K19:K24,3) -> 0
B27: Célula com borda vermelha: lacuna, nível abaixo do requerido pela função.
B29: Plano de treinamento
B30: Pessoa | C30: Comp. | D30: Ação | H30: Quem treina | J30: Prazo | L30: Realizada | M30: Aprendizado | N30: Eficácia | O30: Situação
B31: Camila | C31: S1 | D31: Integração: leitura do PR-SUP-01 rev. 6 e prova de 10 questões. | H31: Antônio | J31: 46409 | L31: 46402 | M31: Sim | N31: Eficaz | O31: =IF(D31="","",IF(L31="",IF(J31="","Falta o prazo",IF(J31<$C$5,"Atrasada","Planejada")),IF(M31="","Falta a avaliação de aprendizado",IF(M31="Não","Não eficaz: refazer",IF(N31="",IF(L31+60<=$C$5,"Avaliar a eficácia","Em acompanhamento"),IF(N31="Eficaz","Eficaz",IF(N31="Parcial","Parcial: reforçar","Não eficaz: refazer"))))))) -> Eficaz
B32: Camila | C32: S5 | D32: Treinamento no sistema de compras, com 20 requisições acompanhadas. | H32: Antônio | J32: 46430 | L32: 46423 | M32: Sim | O32: =IF(D32="","",IF(L32="",IF(J32="","Falta o prazo",IF(J32<$C$5,"Atrasada","Planejada")),IF(M32="","Falta a avaliação de aprendizado",IF(M32="Não","Não eficaz: refazer",IF(N32="",IF(L32+60<=$C$5,"Avaliar a eficácia","Em acompanhamento"),IF(N32="Eficaz","Eficaz",IF(N32="Parcial","Parcial: reforçar","Não eficaz: refazer"))))))) -> Em acompanhamento
B33: Camila | C33: S2 | D33: Especificação técnica: acompanhamento com o supervisor de manutenção. | H33: Supervisor de manutenção | J33: 46477 | O33: =IF(D33="","",IF(L33="",IF(J33="","Falta o prazo",IF(J33<$C$5,"Atrasada","Planejada")),IF(M33="","Falta a avaliação de aprendizado",IF(M33="Não","Não eficaz: refazer",IF(N33="",IF(L33+60<=$C$5,"Avaliar a eficácia","Em acompanhamento"),IF(N33="Eficaz","Eficaz",IF(N33="Parcial","Parcial: reforçar","Não eficaz: refazer"))))))) -> Planejada
B34: Camila | C34: S3 | D34: Cotação e negociação: acompanhar 10 cotações do comprador sênior. | H34: Antônio | J34: 46507 | O34: =IF(D34="","",IF(L34="",IF(J34="","Falta o prazo",IF(J34<$C$5,"Atrasada","Planejada")),IF(M34="","Falta a avaliação de aprendizado",IF(M34="Não","Não eficaz: refazer",IF(N34="",IF(L34+60<=$C$5,"Avaliar a eficácia","Em acompanhamento"),IF(N34="Eficaz","Eficaz",IF(N34="Parcial","Parcial: reforçar","Não eficaz: refazer"))))))) -> Planejada
B35: Camila | C35: S4 | D35: Homologação de fornecedores: participar de duas homologações. | H35: Antônio | J35: 46535 | O35: =IF(D35="","",IF(L35="",IF(J35="","Falta o prazo",IF(J35<$C$5,"Atrasada","Planejada")),IF(M35="","Falta a avaliação de aprendizado",IF(M35="Não","Não eficaz: refazer",IF(N35="",IF(L35+60<=$C$5,"Avaliar a eficácia","Em acompanhamento"),IF(N35="Eficaz","Eficaz",IF(N35="Parcial","Parcial: reforçar","Não eficaz: refazer"))))))) -> Planejada
B36: Luana | C36: S1 | D36: Reciclagem no PR-SUP-01 rev. 6, com foco no cadastro do item antes da compra. | H36: Helena | J36: 46339 | L36: 46336 | M36: Sim | N36: Não eficaz | O36: =IF(D36="","",IF(L36="",IF(J36="","Falta o prazo",IF(J36<$C$5,"Atrasada","Planejada")),IF(M36="","Falta a avaliação de aprendizado",IF(M36="Não","Não eficaz: refazer",IF(N36="",IF(L36+60<=$C$5,"Avaliar a eficácia","Em acompanhamento"),IF(N36="Eficaz","Eficaz",IF(N36="Parcial","Parcial: reforçar","Não eficaz: refazer"))))))) -> Não eficaz: refazer
B37: Luana | C37: S4 | D37: Avaliação de fornecedores: fazer as 12 avaliações de junho com o comprador sênior. | H37: Antônio | J37: 46568 | O37: =IF(D37="","",IF(L37="",IF(J37="","Falta o prazo",IF(J37<$C$5,"Atrasada","Planejada")),IF(M37="","Falta a avaliação de aprendizado",IF(M37="Não","Não eficaz: refazer",IF(N37="",IF(L37+60<=$C$5,"Avaliar a eficácia","Em acompanhamento"),IF(N37="Eficaz","Eficaz",IF(N37="Parcial","Parcial: reforçar","Não eficaz: refazer"))))))) -> Planejada
B38: Felipe | C38: S7 | D38: Curso interno: requisitos da ISO 9001 para aquisição, 4 horas. | H38: Coordenador da Qualidade | J38: 46444 | L38: 46442 | M38: Sim | O38: =IF(D38="","",IF(L38="",IF(J38="","Falta o prazo",IF(J38<$C$5,"Atrasada","Planejada")),IF(M38="","Falta a avaliação de aprendizado",IF(M38="Não","Não eficaz: refazer",IF(N38="",IF(L38+60<=$C$5,"Avaliar a eficácia","Em acompanhamento"),IF(N38="Eficaz","Eficaz",IF(N38="Parcial","Parcial: reforçar","Não eficaz: refazer"))))))) -> Em acompanhamento
B39: Helena | C39: S8 | D39: Formação de auditor interno: curso de 16 horas e duas auditorias acompanhadas. | H39: Coordenador da Qualidade | J39: 46535 | O39: =IF(D39="","",IF(L39="",IF(J39="","Falta o prazo",IF(J39<$C$5,"Atrasada","Planejada")),IF(M39="","Falta a avaliação de aprendizado",IF(M39="Não","Não eficaz: refazer",IF(N39="",IF(L39+60<=$C$5,"Avaliar a eficácia","Em acompanhamento"),IF(N39="Eficaz","Eficaz",IF(N39="Parcial","Parcial: reforçar","Não eficaz: refazer"))))))) -> Planejada
B41: Resumo automático
B42: Pessoas avaliadas | F42: =COUNTA(B19:B24) -> 6
B43: Lacunas | F43: =SUM(L19:L24) -> 11
B44: Competências com uma só pessoa no nível 2, ou nenhuma | F44: =COUNTIF(D25:K25,"<2") -> 2
B45: Competências sem ninguém no nível 3 | F45: =COUNTIF(D26:K26,0) -> 2
...
