Workbook

Sheet Instruções
B1: Controle de produção e de serviço — Como usar esta planilha
B2: Modelo para escrever o plano de controle, registrar as verificações, cuidar da identificação e controlar as mudanças.
B4: Legenda: onde preencher
B5: Amarelo-claro | C5: Células de entrada. É aqui que você digita.
B6: Cinza | C6: Células calculadas ou fixas (rótulos, critérios, leituras, avisos). Não altere.
B7: Cinza em itálico | C7: Linha de exemplo (marcada com “Ex.”). Mostra o formato esperado e não entra nas contagens.
B8: Listas suspensas | C8: Tipo do controle, código do controle, conforme ou não, dono do item e checklist aceitam apenas as opções da lista.
B9: Comentários | C9: Células com triângulo vermelho no canto trazem uma dica de preenchimento. Passe o mouse sobre elas.
B11: As regras de cálculo
B12: Critério | C12: Com mínimo e máximo: faixa. Só com um deles: mínimo ou máximo. Sem nenhum: o controle é por atributo, e o resultado é conforme ou não.
B13: Dentro | C13: Controle por medida: o valor está entre o mínimo e o máximo. Controle por atributo: a resposta é Sim.
B14: Fora | C14: O valor está abaixo do mínimo ou acima do máximo, ou a resposta é Não.
B15: Fora sem reação registrada | C15: A leitura é Fora, e a coluna Reação tomada está vazia. É o aviso mais importante da planilha.
B16: Sem registro | C16: O controle está no plano, e não há verificação lançada na aba Registros.
B17: Desvio repetido: analisar a causa | C17: O mesmo controle tem mais de um resultado fora do critério. A reação não basta: abrir a análise de causa.
B18: Mudança a rever | C18: A mudança foi escrita sem a análise feita antes de mudar, ou sem quem autorizou.
B20: Ordem recomendada de preenchimento
B21: Passo 1 | C21: Aba Plano de controle: escreva a organização, o processo, o produto e a revisão do plano.
B22: Passo 2 | C22: Aba Plano de controle: para cada controle, a etapa, o que controlar, o tipo, o mínimo e o máximo, como medir, a frequência, quem mede, o registro e a reação.
B23: Passo 3 | C23: Aba Registros: lance cada verificação, com data, lote ou pedido, código do controle e resultado. Se o resultado sair do critério, escreva a reação tomada.
B24: Passo 4 | C24: Aba Rastreabilidade: descreva a identificação, a situação e a preservação em cada etapa, e liste o que pertence a clientes e a fornecedores.
B25: Passo 5 | C25: Aba Mudanças: registre cada mudança, com o motivo, a análise, quem autorizou e as ações decorrentes.
B26: Passo 6 | C26: Aba Painel: leia os desvios por controle, os desvios sem reação e os controles sem registro. Depois, valide na aba Checklist.
B28: Abas da planilha
B29: Plano de controle | C29: Até 20 controles. Calcula o texto do critério e a conferência de cada um.
B30: Registros | C30: Até 150 verificações, ligadas aos controles pelo código. Calcula a leitura e a conferência.
B31: Rastreabilidade | C31: Até 10 etapas, com identificação, situação e preservação, e até 8 itens de clientes e de fornecedores.
B32: Mudanças | C32: Até 12 mudanças. Calcula a conferência: análise e autorização.
B33: Painel | C33: Os indicadores gerais, a leitura de cada controle e o gráfico das verificações dentro do critério.
B34: Checklist | C34: Doze verificações de qualidade do controle, com percentual de conclusão.
B35: Exemplo 1 - Pizzaria | C35: O plano da cozinha e da expedição, com sete controles e os registros de uma semana.
B36: Exemplo 2 - Indústria | C36: O plano da extrusora 3, com sete controles e os registros de cinco lotes.
B38: Regras e premissas do modelo
B39: Poucos controles | C39: O modelo aceita 20. O usual é de cinco a dez por processo: os que pesam para o cliente, para a lei e para a etapa seguinte.
B40: Código do controle | C40: Os códigos K1 a K20 são fixos. Na aba Registros, cada verificação é ligada ao controle pelo código.
B41: Mínimo e máximo | C41: Digite só o número, na unidade informada. Para um controle por atributo, deixe os dois vazios e responda Sim ou Não no registro.
B42: Exemplos | C42: Os dados das abas de exemplo são ilustrativos, criados para este material.

Sheet Plano de controle
B1: Plano de controle
B2: Uma linha por controle: o que se confere, com que critério, como, quando, por quem, onde se registra e o que fazer se sair do critério.
B4: Organização e processo
B5: Produto ou serviço
B6: Revisão do plano e data
B8: # | C8: Etapa | D8: O que controlar | E8: Tipo | F8: Mínimo | G8: Máximo | H8: Unidade | I8: Como medir | J8: Frequência | K8: Quem mede | L8: Registro | M8: Reação se sair do critério | N8: Critério | O8: Conferência
C9: Do recebimento à entrega | D9: Característica ou parâmetro | E9: Lista | F9: Número | G9: Número | H9: °C, g, mm | I9: Método e instrumento | J9: Quando e quantos | K9: Uma função | L9: Onde fica o resultado | M9: Com o produto e com o processo | N9: Calculado | O9: Calculada
B10: K1 | N10: =IF(D10="","",IF(AND(F10="",G10=""),"Conforme ou não",TRIM(IF(G10="","mín. "&F10,IF(F10="","máx. "&G10,F10&" a "&G10))&" "&H10))) | O10: =IF(D10="","",IF(C10="","Falta a etapa",IF(E10="","Falta o tipo",IF(AND(F10<>"",G10<>"",F10>G10),"Mínimo maior que o máximo",IF(I10="","Falta como medir",IF(J10="","Falta a frequência",IF(K10="","Falta quem mede",IF(L10="","Falta o registro",IF(M10="","Falta a reação","OK")))))))))
B11: K2 | N11: =IF(D11="","",IF(AND(F11="",G11=""),"Conforme ou não",TRIM(IF(G11="","mín. "&F11,IF(F11="","máx. "&G11,F11&" a "&G11))&" "&H11))) | O11: =IF(D11="","",IF(C11="","Falta a etapa",IF(E11="","Falta o tipo",IF(AND(F11<>"",G11<>"",F11>G11),"Mínimo maior que o máximo",IF(I11="","Falta como medir",IF(J11="","Falta a frequência",IF(K11="","Falta quem mede",IF(L11="","Falta o registro",IF(M11="","Falta a reação","OK")))))))))
B12: K3 | N12: =IF(D12="","",IF(AND(F12="",G12=""),"Conforme ou não",TRIM(IF(G12="","mín. "&F12,IF(F12="","máx. "&G12,F12&" a "&G12))&" "&H12))) | O12: =IF(D12="","",IF(C12="","Falta a etapa",IF(E12="","Falta o tipo",IF(AND(F12<>"",G12<>"",F12>G12),"Mínimo maior que o máximo",IF(I12="","Falta como medir",IF(J12="","Falta a frequência",IF(K12="","Falta quem mede",IF(L12="","Falta o registro",IF(M12="","Falta a reação","OK")))))))))
B13: K4 | N13: =IF(D13="","",IF(AND(F13="",G13=""),"Conforme ou não",TRIM(IF(G13="","mín. "&F13,IF(F13="","máx. "&G13,F13&" a "&G13))&" "&H13))) | O13: =IF(D13="","",IF(C13="","Falta a etapa",IF(E13="","Falta o tipo",IF(AND(F13<>"",G13<>"",F13>G13),"Mínimo maior que o máximo",IF(I13="","Falta como medir",IF(J13="","Falta a frequência",IF(K13="","Falta quem mede",IF(L13="","Falta o registro",IF(M13="","Falta a reação","OK")))))))))
B14: K5 | N14: =IF(D14="","",IF(AND(F14="",G14=""),"Conforme ou não",TRIM(IF(G14="","mín. "&F14,IF(F14="","máx. "&G14,F14&" a "&G14))&" "&H14))) | O14: =IF(D14="","",IF(C14="","Falta a etapa",IF(E14="","Falta o tipo",IF(AND(F14<>"",G14<>"",F14>G14),"Mínimo maior que o máximo",IF(I14="","Falta como medir",IF(J14="","Falta a frequência",IF(K14="","Falta quem mede",IF(L14="","Falta o registro",IF(M14="","Falta a reação","OK")))))))))
B15: K6 | N15: =IF(D15="","",IF(AND(F15="",G15=""),"Conforme ou não",TRIM(IF(G15="","mín. "&F15,IF(F15="","máx. "&G15,F15&" a "&G15))&" "&H15))) | O15: =IF(D15="","",IF(C15="","Falta a etapa",IF(E15="","Falta o tipo",IF(AND(F15<>"",G15<>"",F15>G15),"Mínimo maior que o máximo",IF(I15="","Falta como medir",IF(J15="","Falta a frequência",IF(K15="","Falta quem mede",IF(L15="","Falta o registro",IF(M15="","Falta a reação","OK")))))))))
B16: K7 | N16: =IF(D16="","",IF(AND(F16="",G16=""),"Conforme ou não",TRIM(IF(G16="","mín. "&F16,IF(F16="","máx. "&G16,F16&" a "&G16))&" "&H16))) | O16: =IF(D16="","",IF(C16="","Falta a etapa",IF(E16="","Falta o tipo",IF(AND(F16<>"",G16<>"",F16>G16),"Mínimo maior que o máximo",IF(I16="","Falta como medir",IF(J16="","Falta a frequência",IF(K16="","Falta quem mede",IF(L16="","Falta o registro",IF(M16="","Falta a reação","OK")))))))))
B17: K8 | N17: =IF(D17="","",IF(AND(F17="",G17=""),"Conforme ou não",TRIM(IF(G17="","mín. "&F17,IF(F17="","máx. "&G17,F17&" a "&G17))&" "&H17))) | O17: =IF(D17="","",IF(C17="","Falta a etapa",IF(E17="","Falta o tipo",IF(AND(F17<>"",G17<>"",F17>G17),"Mínimo maior que o máximo",IF(I17="","Falta como medir",IF(J17="","Falta a frequência",IF(K17="","Falta quem mede",IF(L17="","Falta o registro",IF(M17="","Falta a reação","OK")))))))))
B18: K9 | N18: =IF(D18="","",IF(AND(F18="",G18=""),"Conforme ou não",TRIM(IF(G18="","mín. "&F18,IF(F18="","máx. "&G18,F18&" a "&G18))&" "&H18))) | O18: =IF(D18="","",IF(C18="","Falta a etapa",IF(E18="","Falta o tipo",IF(AND(F18<>"",G18<>"",F18>G18),"Mínimo maior que o máximo",IF(I18="","Falta como medir",IF(J18="","Falta a frequência",IF(K18="","Falta quem mede",IF(L18="","Falta o registro",IF(M18="","Falta a reação","OK")))))))))
B19: K10 | N19: =IF(D19="","",IF(AND(F19="",G19=""),"Conforme ou não",TRIM(IF(G19="","mín. "&F19,IF(F19="","máx. "&G19,F19&" a "&G19))&" "&H19))) | O19: =IF(D19="","",IF(C19="","Falta a etapa",IF(E19="","Falta o tipo",IF(AND(F19<>"",G19<>"",F19>G19),"Mínimo maior que o máximo",IF(I19="","Falta como medir",IF(J19="","Falta a frequência",IF(K19="","Falta quem mede",IF(L19="","Falta o registro",IF(M19="","Falta a reação","OK")))))))))
B20: K11 | N20: =IF(D20="","",IF(AND(F20="",G20=""),"Conforme ou não",TRIM(IF(G20="","mín. "&F20,IF(F20="","máx. "&G20,F20&" a "&G20))&" "&H20))) | O20: =IF(D20="","",IF(C20="","Falta a etapa",IF(E20="","Falta o tipo",IF(AND(F20<>"",G20<>"",F20>G20),"Mínimo maior que o máximo",IF(I20="","Falta como medir",IF(J20="","Falta a frequência",IF(K20="","Falta quem mede",IF(L20="","Falta o registro",IF(M20="","Falta a reação","OK")))))))))
B21: K12 | N21: =IF(D21="","",IF(AND(F21="",G21=""),"Conforme ou não",TRIM(IF(G21="","mín. "&F21,IF(F21="","máx. "&G21,F21&" a "&G21))&" "&H21))) | O21: =IF(D21="","",IF(C21="","Falta a etapa",IF(E21="","Falta o tipo",IF(AND(F21<>"",G21<>"",F21>G21),"Mínimo maior que o máximo",IF(I21="","Falta como medir",IF(J21="","Falta a frequência",IF(K21="","Falta quem mede",IF(L21="","Falta o registro",IF(M21="","Falta a reação","OK")))))))))
... B29: K20 | N29: =IF(D29="","",IF(AND(F29="",G29=""),"Conforme ou não",TRIM(IF(G29="","mín. "&F29,IF(F29="","máx. "&G29,F29&" a "&G29))&" "&H29))) | O29: =IF(D29="","",IF(C29="","Falta a etapa",IF(E29="","Falta o tipo",IF(AND(F29<>"",G29<>"",F29>G29),"Mínimo maior que o máximo",IF(I29="","Falta como medir",IF(J29="","Falta a frequência",IF(K29="","Falta quem mede",IF(L29="","Falta o registro",IF(M29="","Falta a reação","OK")))))))))
B31: Resumo automático
B32: Controles escritos | D32: =COUNTA(D10:D29) -> 0
B33: Por tipo | D33: =IF(D32=0,"",COUNTIF(E10:E29,"Produto")&" de produto, "&COUNTIF(E10:E29,"Processo")&" de processo")
B34: Por critério | D34: =IF(D32=0,"",(D32-COUNTIF(N10:N29,"Conforme ou não"))&" por medida, "&COUNTIF(N10:N29,"Conforme ou não")&" por atributo")
B35: Aviso | D35: =IF(D4="","Escreva a organização e o processo",IF(D32=0,"Escreva os controles",IF(COUNTIF(O10:O29,"OK")<D32,"Há controle a rever: veja a coluna Conferência",IF(COUNTIF(E10:E29,"Processo")=0,"Só há controles de produto: avalie controlar também o processo","OK")))) -> Escreva a organização e o processo

Sheet Registros
B1: Registros das verificações
B2: Uma linha por verificação. Para um controle por medida, digite o valor. Para um controle por atributo, responda Sim ou Não.
B4: # | C4: Data | D4: Lote ou pedido | E4: Controle | F4: O que se controla | G4: Critério | H4: Mín. | I4: Máx. | J4: Valor medido | K4: Conforme? | L4: Leitura | M4: Reação tomada | N4: Quem mediu | O4: Conferência
C5: Data | D5: A identificação | E5: Código | F5: Vem do plano | G5: Vem do plano | J5: Só o número | K5: Lista | L5: Calculada | M5: Só quando sair do critério | N5: Uma função | O5: Calculada
B6: Ex. | C6: 46457 | D6: Câmara, 2ª leitura | E6: K1 | F6: Temperatura da câmara fria | G6: 0 a 5 °C | H6: 0 | I6: 5 | J6: 7 | L6: Fora | M6: Insumos passados para o refrigerador reserva às 21h40. | N6: Pizzaiolo do turno | O6: OK
B7: 1 | F7: =IF(E7="","",IFERROR(INDEX('Plano de controle'!$D$10:$D$29,MATCH(E7,'Plano de controle'!$B$10:$B$29,0))&"","")) | G7: =IF(E7="","",IFERROR(INDEX('Plano de controle'!$N$10:$N$29,MATCH(E7,'Plano de controle'!$B$10:$B$29,0))&"","")) | H7: =IF(E7="","",IFERROR(IF(ISNUMBER(INDEX('Plano de controle'!$F$10:$F$29,MATCH(E7,'Plano de controle'!$B$10:$B$29,0))),INDEX('Plano de controle'!$F$10:$F$29,MATCH(E7,'Plano de controle'!$B$10:$B$29,0)),""),"")) | I7: =IF(E7="","",IFERROR(IF(ISNUMBER(INDEX('Plano de controle'!$G$10:$G$29,MATCH(E7,'Plano de controle'!$B$10:$B$29,0))),INDEX('Plano de controle'!$G$10:$G$29,MATCH(E7,'Plano de controle'!$B$10:$B$29,0)),""),"")) | L7: =IF(OR(E7="",F7=""),"",IF(AND(H7="",I7=""),IF(K7="","Falta o resultado",IF(K7="Sim","Dentro","Fora")),IF(J7="","Falta o valor",IF(AND(OR(H7="",J7>=H7),OR(I7="",J7<=I7)),"Dentro","Fora")))) | O7: =IF(E7="",IF(COUNTA(C7:D7,J7:K7,M7)>0,"Falta o controle",""),IF(F7="","Controle sem plano",IF(C7="","Falta a data",IF(D7="","Falta o lote ou o pedido",IF(LEFT(L7,5)="Falta",L7,IF(AND(L7="Fora",M7=""),"Fora sem reação registrada",IF(N7="","Falta quem mediu","OK")))))))
B8: 2 | F8: =IF(E8="","",IFERROR(INDEX('Plano de controle'!$D$10:$D$29,MATCH(E8,'Plano de controle'!$B$10:$B$29,0))&"","")) | G8: =IF(E8="","",IFERROR(INDEX('Plano de controle'!$N$10:$N$29,MATCH(E8,'Plano de controle'!$B$10:$B$29,0))&"","")) | H8: =IF(E8="","",IFERROR(IF(ISNUMBER(INDEX('Plano de controle'!$F$10:$F$29,MATCH(E8,'Plano de controle'!$B$10:$B$29,0))),INDEX('Plano de controle'!$F$10:$F$29,MATCH(E8,'Plano de controle'!$B$10:$B$29,0)),""),"")) | I8: =IF(E8="","",IFERROR(IF(ISNUMBER(INDEX('Plano de controle'!$G$10:$G$29,MATCH(E8,'Plano de controle'!$B$10:$B$29,0))),INDEX('Plano de controle'!$G$10:$G$29,MATCH(E8,'Plano de controle'!$B$10:$B$29,0)),""),"")) | L8: =IF(OR(E8="",F8=""),"",IF(AND(H8="",I8=""),IF(K8="","Falta o resultado",IF(K8="Sim","Dentro","Fora")),IF(J8="","Falta o valor",IF(AND(OR(H8="",J8>=H8),OR(I8="",J8<=I8)),"Dentro","Fora")))) | O8: =IF(E8="",IF(COUNTA(C8:D8,J8:K8,M8)>0,"Falta o controle",""),IF(F8="","Controle sem plano",IF(C8="","Falta a data",IF(D8="","Falta o lote ou o pedido",IF(LEFT(L8,5)="Falta",L8,IF(AND(L8="Fora",M8=""),"Fora sem reação registrada",IF(N8="","Falta quem mediu","OK")))))))
B9: 3 | F9: =IF(E9="","",IFERROR(INDEX('Plano de controle'!$D$10:$D$29,MATCH(E9,'Plano de controle'!$B$10:$B$29,0))&"","")) | G9: =IF(E9="","",IFERROR(INDEX('Plano de controle'!$N$10:$N$29,MATCH(E9,'Plano de controle'!$B$10:$B$29,0))&"","")) | H9: =IF(E9="","",IFERROR(IF(ISNUMBER(INDEX('Plano de controle'!$F$10:$F$29,MATCH(E9,'Plano de controle'!$B$10:$B$29,0))),INDEX('Plano de controle'!$F$10:$F$29,MATCH(E9,'Plano de controle'!$B$10:$B$29,0)),""),"")) | I9: =IF(E9="","",IFERROR(IF(ISNUMBER(INDEX('Plano de controle'!$G$10:$G$29,MATCH(E9,'Plano de controle'!$B$10:$B$29,0))),INDEX('Plano de controle'!$G$10:$G$29,MATCH(E9,'Plano de controle'!$B$10:$B$29,0)),""),"")) | L9: =IF(OR(E9="",F9=""),"",IF(AND(H9="",I9=""),IF(K9="","Falta o resultado",IF(K9="Sim","Dentro","Fora")),IF(J9="","Falta o valor",IF(AND(OR(H9="",J9>=H9),OR(I9="",J9<=I9)),"Dentro","Fora")))) | O9: =IF(E9="",IF(COUNTA(C9:D9,J9:K9,M9)>0,"Falta o controle",""),IF(F9="","Controle sem plano",IF(C9="","Falta a data",IF(D9="","Falta o lote ou o pedido",IF(LEFT(L9,5)="Falta",L9,IF(AND(L9="Fora",M9=""),"Fora sem reação registrada",IF(N9="","Falta quem mediu","OK")))))))
B10: 4 | F10: =IF(E10="","",IFERROR(INDEX('Plano de controle'!$D$10:$D$29,MATCH(E10,'Plano de controle'!$B$10:$B$29,0))&"","")) | G10: =IF(E10="","",IFERROR(INDEX('Plano de controle'!$N$10:$N$29,MATCH(E10,'Plano de controle'!$B$10:$B$29,0))&"","")) | H10: =IF(E10="","",IFERROR(IF(ISNUMBER(INDEX('Plano de controle'!$F$10:$F$29,MATCH(E10,'Plano de controle'!$B$10:$B$29,0))),INDEX('Plano de controle'!$F$10:$F$29,MATCH(E10,'Plano de controle'!$B$10:$B$29,0)),""),"")) | I10: =IF(E10="","",IFERROR(IF(ISNUMBER(INDEX('Plano de controle'!$G$10:$G$29,MATCH(E10,'Plano de controle'!$B$10:$B$29,0))),INDEX('Plano de controle'!$G$10:$G$29,MATCH(E10,'Plano de controle'!$B$10:$B$29,0)),""),"")) | L10: =IF(OR(E10="",F10=""),"",IF(AND(H10="",I10=""),IF(K10="","Falta o resultado",IF(K10="Sim","Dentro","Fora")),IF(J10="","Falta o valor",IF(AND(OR(H10="",J10>=H10),OR(I10="",J10<=I10)),"Dentro","Fora")))) | O10: =IF(E10="",IF(COUNTA(C10:D10,J10:K10,M10)>0,"Falta o controle",""),IF(F10="","Controle sem plano",IF(C10="","Falta a data",IF(D10="","Falta o lote ou o pedido",IF(LEFT(L10,5)="Falta",L10,IF(AND(L10="Fora",M10=""),"Fora sem reação registrada",IF(N10="","Falta quem mediu","OK")))))))
B11: 5 | F11: =IF(E11="","",IFERROR(INDEX('Plano de controle'!$D$10:$D$29,MATCH(E11,'Plano de controle'!$B$10:$B$29,0))&"","")) | G11: =IF(E11="","",IFERROR(INDEX('Plano de controle'!$N$10:$N$29,MATCH(E11,'Plano de controle'!$B$10:$B$29,0))&"","")) | H11: =IF(E11="","",IFERROR(IF(ISNUMBER(INDEX('Plano de controle'!$F$10:$F$29,MATCH(E11,'Plano de controle'!$B$10:$B$29,0))),INDEX('Plano de controle'!$F$10:$F$29,MATCH(E11,'Plano de controle'!$B$10:$B$29,0)),""),"")) | I11: =IF(E11="","",IFERROR(IF(ISNUMBER(INDEX('Plano de controle'!$G$10:$G$29,MATCH(E11,'Plano de controle'!$B$10:$B$29,0))),INDEX('Plano de controle'!$G$10:$G$29,MATCH(E11,'Plano de controle'!$B$10:$B$29,0)),""),"")) | L11: =IF(OR(E11="",F11=""),"",IF(AND(H11="",I11=""),IF(K11="","Falta o resultado",IF(K11="Sim","Dentro","Fora")),IF(J11="","Falta o valor",IF(AND(OR(H11="",J11>=H11),OR(I11="",J11<=I11)),"Dentro","Fora")))) | O11: =IF(E11="",IF(COUNTA(C11:D11,J11:K11,M11)>0,"Falta o controle",""),IF(F11="","Controle sem plano",IF(C11="","Falta a data",IF(D11="","Falta o lote ou o pedido",IF(LEFT(L11,5)="Falta",L11,IF(AND(L11="Fora",M11=""),"Fora sem reação registrada",IF(N11="","Falta quem mediu","OK")))))))
B12: 6 | F12: =IF(E12="","",IFERROR(INDEX('Plano de controle'!$D$10:$D$29,MATCH(E12,'Plano de controle'!$B$10:$B$29,0))&"","")) | G12: =IF(E12="","",IFERROR(INDEX('Plano de controle'!$N$10:$N$29,MATCH(E12,'Plano de controle'!$B$10:$B$29,0))&"","")) | H12: =IF(E12="","",IFERROR(IF(ISNUMBER(INDEX('Plano de controle'!$F$10:$F$29,MATCH(E12,'Plano de controle'!$B$10:$B$29,0))),INDEX('Plano de controle'!$F$10:$F$29,MATCH(E12,'Plano de controle'!$B$10:$B$29,0)),""),"")) | I12: =IF(E12="","",IFERROR(IF(ISNUMBER(INDEX('Plano de controle'!$G$10:$G$29,MATCH(E12,'Plano de controle'!$B$10:$B$29,0))),INDEX('Plano de controle'!$G$10:$G$29,MATCH(E12,'Plano de controle'!$B$10:$B$29,0)),""),"")) | L12: =IF(OR(E12="",F12=""),"",IF(AND(H12="",I12=""),IF(K12="","Falta o resultado",IF(K12="Sim","Dentro","Fora")),IF(J12="","Falta o valor",IF(AND(OR(H12="",J12>=H12),OR(I12="",J12<=I12)),"Dentro","Fora")))) | O12: =IF(E12="",IF(COUNTA(C12:D12,J12:K12,M12)>0,"Falta o controle",""),IF(F12="","Controle sem plano",IF(C12="","Falta a data",IF(D12="","Falta o lote ou o pedido",IF(LEFT(L12,5)="Falta",L12,IF(AND(L12="Fora",M12=""),"Fora sem reação registrada",IF(N12="","Falta quem mediu","OK")))))))
B13: 7 | F13: =IF(E13="","",IFERROR(INDEX('Plano de controle'!$D$10:$D$29,MATCH(E13,'Plano de controle'!$B$10:$B$29,0))&"","")) | G13: =IF(E13="","",IFERROR(INDEX('Plano de controle'!$N$10:$N$29,MATCH(E13,'Plano de controle'!$B$10:$B$29,0))&"","")) | H13: =IF(E13="","",IFERROR(IF(ISNUMBER(INDEX('Plano de controle'!$F$10:$F$29,MATCH(E13,'Plano de controle'!$B$10:$B$29,0))),INDEX('Plano de controle'!$F$10:$F$29,MATCH(E13,'Plano de controle'!$B$10:$B$29,0)),""),"")) | I13: =IF(E13="","",IFERROR(IF(ISNUMBER(INDEX('Plano de controle'!$G$10:$G$29,MATCH(E13,'Plano de controle'!$B$10:$B$29,0))),INDEX('Plano de controle'!$G$10:$G$29,MATCH(E13,'Plano de controle'!$B$10:$B$29,0)),""),"")) | L13: =IF(OR(E13="",F13=""),"",IF(AND(H13="",I13=""),IF(K13="","Falta o resultado",IF(K13="Sim","Dentro","Fora")),IF(J13="","Falta o valor",IF(AND(OR(H13="",J13>=H13),OR(I13="",J13<=I13)),"Dentro","Fora")))) | O13: =IF(E13="",IF(COUNTA(C13:D13,J13:K13,M13)>0,"Falta o controle",""),IF(F13="","Controle sem plano",IF(C13="","Falta a data",IF(D13="","Falta o lote ou o pedido",IF(LEFT(L13,5)="Falta",L13,IF(AND(L13="Fora",M13=""),"Fora sem reação registrada",IF(N13="","Falta quem mediu","OK")))))))
B14: 8 | F14: =IF(E14="","",IFERROR(INDEX('Plano de controle'!$D$10:$D$29,MATCH(E14,'Plano de controle'!$B$10:$B$29,0))&"","")) | G14: =IF(E14="","",IFERROR(INDEX('Plano de controle'!$N$10:$N$29,MATCH(E14,'Plano de controle'!$B$10:$B$29,0))&"","")) | H14: =IF(E14="","",IFERROR(IF(ISNUMBER(INDEX('Plano de controle'!$F$10:$F$29,MATCH(E14,'Plano de controle'!$B$10:$B$29,0))),INDEX('Plano de controle'!$F$10:$F$29,MATCH(E14,'Plano de controle'!$B$10:$B$29,0)),""),"")) | I14: =IF(E14="","",IFERROR(IF(ISNUMBER(INDEX('Plano de controle'!$G$10:$G$29,MATCH(E14,'Plano de controle'!$B$10:$B$29,0))),INDEX('Plano de controle'!$G$10:$G$29,MATCH(E14,'Plano de controle'!$B$10:$B$29,0)),""),"")) | L14: =IF(OR(E14="",F14=""),"",IF(AND(H14="",I14=""),IF(K14="","Falta o resultado",IF(K14="Sim","Dentro","Fora")),IF(J14="","Falta o valor",IF(AND(OR(H14="",J14>=H14),OR(I14="",J14<=I14)),"Dentro","Fora")))) | O14: =IF(E14="",IF(COUNTA(C14:D14,J14:K14,M14)>0,"Falta o controle",""),IF(F14="","Controle sem plano",IF(C14="","Falta a data",IF(D14="","Falta o lote ou o pedido",IF(LEFT(L14,5)="Falta",L14,IF(AND(L14="Fora",M14=""),"Fora sem reação registrada",IF(N14="","Falta quem mediu","OK")))))))
B15: 9 | F15: =IF(E15="","",IFERROR(INDEX('Plano de controle'!$D$10:$D$29,MATCH(E15,'Plano de controle'!$B$10:$B$29,0))&"","")) | G15: =IF(E15="","",IFERROR(INDEX('Plano de controle'!$N$10:$N$29,MATCH(E15,'Plano de controle'!$B$10:$B$29,0))&"","")) | H15: =IF(E15="","",IFERROR(IF(ISNUMBER(INDEX('Plano de controle'!$F$10:$F$29,MATCH(E15,'Plano de controle'!$B$10:$B$29,0))),INDEX('Plano de controle'!$F$10:$F$29,MATCH(E15,'Plano de controle'!$B$10:$B$29,0)),""),"")) | I15: =IF(E15="","",IFERROR(IF(ISNUMBER(INDEX('Plano de controle'!$G$10:$G$29,MATCH(E15,'Plano de controle'!$B$10:$B$29,0))),INDEX('Plano de controle'!$G$10:$G$29,MATCH(E15,'Plano de controle'!$B$10:$B$29,0)),""),"")) | L15: =IF(OR(E15="",F15=""),"",IF(AND(H15="",I15=""),IF(K15="","Falta o resultado",IF(K15="Sim","Dentro","Fora")),IF(J15="","Falta o valor",IF(AND(OR(H15="",J15>=H15),OR(I15="",J15<=I15)),"Dentro","Fora")))) | O15: =IF(E15="",IF(COUNTA(C15:D15,J15:K15,M15)>0,"Falta o controle",""),IF(F15="","Controle sem plano",IF(C15="","Falta a data",IF(D15="","Falta o lote ou o pedido",IF(LEFT(L15,5)="Falta",L15,IF(AND(L15="Fora",M15=""),"Fora sem reação registrada",IF(N15="","Falta quem mediu","OK")))))))
B16: 10 | F16: =IF(E16="","",IFERROR(INDEX('Plano de controle'!$D$10:$D$29,MATCH(E16,'Plano de controle'!$B$10:$B$29,0))&"","")) | G16: =IF(E16="","",IFERROR(INDEX('Plano de controle'!$N$10:$N$29,MATCH(E16,'Plano de controle'!$B$10:$B$29,0))&"","")) | H16: =IF(E16="","",IFERROR(IF(ISNUMBER(INDEX('Plano de controle'!$F$10:$F$29,MATCH(E16,'Plano de controle'!$B$10:$B$29,0))),INDEX('Plano de controle'!$F$10:$F$29,MATCH(E16,'Plano de controle'!$B$10:$B$29,0)),""),"")) | I16: =IF(E16="","",IFERROR(IF(ISNUMBER(INDEX('Plano de controle'!$G$10:$G$29,MATCH(E16,'Plano de controle'!$B$10:$B$29,0))),INDEX('Plano de controle'!$G$10:$G$29,MATCH(E16,'Plano de controle'!$B$10:$B$29,0)),""),"")) | L16: =IF(OR(E16="",F16=""),"",IF(AND(H16="",I16=""),IF(K16="","Falta o resultado",IF(K16="Sim","Dentro","Fora")),IF(J16="","Falta o valor",IF(AND(OR(H16="",J16>=H16),OR(I16="",J16<=I16)),"Dentro","Fora")))) | O16: =IF(E16="",IF(COUNTA(C16:D16,J16:K16,M16)>0,"Falta o controle",""),IF(F16="","Controle sem plano",IF(C16="","Falta a data",IF(D16="","Falta o lote ou o pedido",IF(LEFT(L16,5)="Falta",L16,IF(AND(L16="Fora",M16=""),"Fora sem reação registrada",IF(N16="","Falta quem mediu","OK")))))))
B17: 11 | F17: =IF(E17="","",IFERROR(INDEX('Plano de controle'!$D$10:$D$29,MATCH(E17,'Plano de controle'!$B$10:$B$29,0))&"","")) | G17: =IF(E17="","",IFERROR(INDEX('Plano de controle'!$N$10:$N$29,MATCH(E17,'Plano de controle'!$B$10:$B$29,0))&"","")) | H17: =IF(E17="","",IFERROR(IF(ISNUMBER(INDEX('Plano de controle'!$F$10:$F$29,MATCH(E17,'Plano de controle'!$B$10:$B$29,0))),INDEX('Plano de controle'!$F$10:$F$29,MATCH(E17,'Plano de controle'!$B$10:$B$29,0)),""),"")) | I17: =IF(E17="","",IFERROR(IF(ISNUMBER(INDEX('Plano de controle'!$G$10:$G$29,MATCH(E17,'Plano de controle'!$B$10:$B$29,0))),INDEX('Plano de controle'!$G$10:$G$29,MATCH(E17,'Plano de controle'!$B$10:$B$29,0)),""),"")) | L17: =IF(OR(E17="",F17=""),"",IF(AND(H17="",I17=""),IF(K17="","Falta o resultado",IF(K17="Sim","Dentro","Fora")),IF(J17="","Falta o valor",IF(AND(OR(H17="",J17>=H17),OR(I17="",J17<=I17)),"Dentro","Fora")))) | O17: =IF(E17="",IF(COUNTA(C17:D17,J17:K17,M17)>0,"Falta o controle",""),IF(F17="","Controle sem plano",IF(C17="","Falta a data",IF(D17="","Falta o lote ou o pedido",IF(LEFT(L17,5)="Falta",L17,IF(AND(L17="Fora",M17=""),"Fora sem reação registrada",IF(N17="","Falta quem mediu","OK")))))))
B18: 12 | F18: =IF(E18="","",IFERROR(INDEX('Plano de controle'!$D$10:$D$29,MATCH(E18,'Plano de controle'!$B$10:$B$29,0))&"","")) | G18: =IF(E18="","",IFERROR(INDEX('Plano de controle'!$N$10:$N$29,MATCH(E18,'Plano de controle'!$B$10:$B$29,0))&"","")) | H18: =IF(E18="","",IFERROR(IF(ISNUMBER(INDEX('Plano de controle'!$F$10:$F$29,MATCH(E18,'Plano de controle'!$B$10:$B$29,0))),INDEX('Plano de controle'!$F$10:$F$29,MATCH(E18,'Plano de controle'!$B$10:$B$29,0)),""),"")) | I18: =IF(E18="","",IFERROR(IF(ISNUMBER(INDEX('Plano de controle'!$G$10:$G$29,MATCH(E18,'Plano de controle'!$B$10:$B$29,0))),INDEX('Plano de controle'!$G$10:$G$29,MATCH(E18,'Plano de controle'!$B$10:$B$29,0)),""),"")) | L18: =IF(OR(E18="",F18=""),"",IF(AND(H18="",I18=""),IF(K18="","Falta o resultado",IF(K18="Sim","Dentro","Fora")),IF(J18="","Falta o valor",IF(AND(OR(H18="",J18>=H18),OR(I18="",J18<=I18)),"Dentro","Fora")))) | O18: =IF(E18="",IF(COUNTA(C18:D18,J18:K18,M18)>0,"Falta o controle",""),IF(F18="","Controle sem plano",IF(C18="","Falta a data",IF(D18="","Falta o lote ou o pedido",IF(LEFT(L18,5)="Falta",L18,IF(AND(L18="Fora",M18=""),"Fora sem reação registrada",IF(N18="","Falta quem mediu","OK")))))))
... B156: 150 | F156: =IF(E156="","",IFERROR(INDEX('Plano de controle'!$D$10:$D$29,MATCH(E156,'Plano de controle'!$B$10:$B$29,0))&"","")) | G156: =IF(E156="","",IFERROR(INDEX('Plano de controle'!$N$10:$N$29,MATCH(E156,'Plano de controle'!$B$10:$B$29,0))&"","")) | H156: =IF(E156="","",IFERROR(IF(ISNUMBER(INDEX('Plano de controle'!$F$10:$F$29,MATCH(E156,'Plano de controle'!$B$10:$B$29,0))),INDEX('Plano de controle'!$F$10:$F$29,MATCH(E156,'Plano de controle'!$B$10:$B$29,0)),""),"")) | I156: =IF(E156="","",IFERROR(IF(ISNUMBER(INDEX('Plano de controle'!$G$10:$G$29,MATCH(E156,'Plano de controle'!$B$10:$B$29,0))),INDEX('Plano de controle'!$G$10:$G$29,MATCH(E156,'Plano de controle'!$B$10:$B$29,0)),""),"")) | L156: =IF(OR(E156="",F156=""),"",IF(AND(H156="",I156=""),IF(K156="","Falta o resultado",IF(K156="Sim","Dentro","Fora")),IF(J156="","Falta o valor",IF(AND(OR(H156="",J156>=H156),OR(I156="",J156<=I156)),"Dentro","Fora")))) | O156: =IF(E156="",IF(COUNTA(C156:D156,J156:K156,M156)>0,"Falta o controle",""),IF(F156="","Controle sem plano",IF(C156="","Falta a data",IF(D156="","Falta o lote ou o pedido",IF(LEFT(L156,5)="Falta",L156,IF(AND(L156="Fora",M156=""),"Fora sem reação registrada",IF(N156="","Falta quem mediu","OK")))))))
B158: Resumo automático
B159: Verificações lançadas | E159: =COUNTA(E7:E156) -> 0
B160: Dentro do critério | E160: =COUNTIF(L7:L156,"Dentro") -> 0
B161: Fora do critério | E161: =COUNTIF(L7:L156,"Fora") -> 0
B162: Fora sem reação registrada | E162: =COUNTIF(O7:O156,"Fora sem reação registrada") -> 0
B163: Aviso | E163: =IF(E159=0,"Lance as verificações",IF(E162>0,"Há resultado fora do critério sem reação registrada",IF(COUNTIF(O7:O156,"<>OK")-COUNTBLANK(O7:O156)>0,"Há registro a rever: veja a coluna Conferência","OK"))) -> Lance as verificações

Sheet Rastreabilidade
B1: Identificação, rastreabilidade e preservação
B2: Em cada etapa: como o produto é identificado, como se sabe se já foi verificado, o que se registra e como ele é protegido.
B4: Identificação, situação e preservação, por etapa
B5: # | C5: Etapa | D5: Como o produto é identificado | E5: Como se sabe a situação | F5: O que se registra para rastrear | G5: Como se preserva | H5: Conferência
C6: A mesma do plano | D6: Etiqueta, comanda, lote | E6: Aprovado, aguardando, reprovado | F6: O registro que liga à etapa anterior | G6: Manuseio, embalagem, armazenagem | H6: Calculada
B7: 1 | H7: =IF(C7="",IF(COUNTA(D7:G7)>0,"Falta a etapa",""),IF(D7="","Falta a identificação",IF(E7="","Falta a situação","OK")))
B8: 2 | H8: =IF(C8="",IF(COUNTA(D8:G8)>0,"Falta a etapa",""),IF(D8="","Falta a identificação",IF(E8="","Falta a situação","OK")))
B9: 3 | H9: =IF(C9="",IF(COUNTA(D9:G9)>0,"Falta a etapa",""),IF(D9="","Falta a identificação",IF(E9="","Falta a situação","OK")))
B10: 4 | H10: =IF(C10="",IF(COUNTA(D10:G10)>0,"Falta a etapa",""),IF(D10="","Falta a identificação",IF(E10="","Falta a situação","OK")))
B11: 5 | H11: =IF(C11="",IF(COUNTA(D11:G11)>0,"Falta a etapa",""),IF(D11="","Falta a identificação",IF(E11="","Falta a situação","OK")))
B12: 6 | H12: =IF(C12="",IF(COUNTA(D12:G12)>0,"Falta a etapa",""),IF(D12="","Falta a identificação",IF(E12="","Falta a situação","OK")))
B13: 7 | H13: =IF(C13="",IF(COUNTA(D13:G13)>0,"Falta a etapa",""),IF(D13="","Falta a identificação",IF(E13="","Falta a situação","OK")))
B14: 8 | H14: =IF(C14="",IF(COUNTA(D14:G14)>0,"Falta a etapa",""),IF(D14="","Falta a identificação",IF(E14="","Falta a situação","OK")))
B15: 9 | H15: =IF(C15="",IF(COUNTA(D15:G15)>0,"Falta a etapa",""),IF(D15="","Falta a identificação",IF(E15="","Falta a situação","OK")))
B16: 10 | H16: =IF(C16="",IF(COUNTA(D16:G16)>0,"Falta a etapa",""),IF(D16="","Falta a identificação",IF(E16="","Falta a situação","OK")))
B18: Propriedade de clientes e de fornecedores
B19: # | C19: Item | D19: De quem é | E19: Como é identificado | F19: Como é cuidado | G19: Ocorrência e comunicação ao dono | H19: Conferência
C20: Material, ferramenta, embalagem, dado | D20: Lista | E20: Marca, código, cadastro | F20: Guarda, inspeção, acesso | G20: Perda ou dano, e quando o dono foi avisado | H20: Calculada
B21: 1 | H21: =IF(C21="",IF(COUNTA(D21:G21)>0,"Falta o item",""),IF(D21="","Falta o dono",IF(E21="","Falta a identificação",IF(F21="","Falta o cuidado","OK"))))
B22: 2 | H22: =IF(C22="",IF(COUNTA(D22:G22)>0,"Falta o item",""),IF(D22="","Falta o dono",IF(E22="","Falta a identificação",IF(F22="","Falta o cuidado","OK"))))
B23: 3 | H23: =IF(C23="",IF(COUNTA(D23:G23)>0,"Falta o item",""),IF(D23="","Falta o dono",IF(E23="","Falta a identificação",IF(F23="","Falta o cuidado","OK"))))
B24: 4 | H24: =IF(C24="",IF(COUNTA(D24:G24)>0,"Falta o item",""),IF(D24="","Falta o dono",IF(E24="","Falta a identificação",IF(F24="","Falta o cuidado","OK"))))
B25: 5 | H25: =IF(C25="",IF(COUNTA(D25:G25)>0,"Falta o item",""),IF(D25="","Falta o dono",IF(E25="","Falta a identificação",IF(F25="","Falta o cuidado","OK"))))
B26: 6 | H26: =IF(C26="",IF(COUNTA(D26:G26)>0,"Falta o item",""),IF(D26="","Falta o dono",IF(E26="","Falta a identificação",IF(F26="","Falta o cuidado","OK"))))
B27: 7 | H27: =IF(C27="",IF(COUNTA(D27:G27)>0,"Falta o item",""),IF(D27="","Falta o dono",IF(E27="","Falta a identificação",IF(F27="","Falta o cuidado","OK"))))
B28: 8 | H28: =IF(C28="",IF(COUNTA(D28:G28)>0,"Falta o item",""),IF(D28="","Falta o dono",IF(E28="","Falta a identificação",IF(F28="","Falta o cuidado","OK"))))
B30: Resumo automático
B31: Etapas descritas | D31: =COUNTA(C7:C16) -> 0
B32: Itens de clientes e de fornecedores | D32: =COUNTA(C21:C28) -> 0
B33: Ocorrências registradas | D33: =COUNTA(G21:G28) -> 0
B34: Aviso | D34: =IF(D31=0,"Descreva as etapas",IF(COUNTIF(H7:H16,"<>OK")-COUNTBLANK(H7:H16)+COUNTIF(H21:H28,"<>OK")-COUNTBLANK(H21:H28)>0,"Há linha a rever: veja a coluna Conferência",IF(D32=0,"Nenhum item de terceiros: confirme se é isso mesmo","OK"))) -> Descreva as etapas

Sheet Mudanças
B1: Mudanças na produção e no serviço
B2: Uma linha por mudança de insumo, método, equipamento, parâmetro ou pessoas. A análise vem antes de a mudança entrar em uso.
B4: # | C4: Data | D4: O que mudou | E4: Motivo | F4: Análise antes de mudar | G4: Quem autorizou | H4: Ações decorrentes | I4: Conferência
C5: Data | D5: De quê, para quê | E5: Por que mudar | F5: O que foi conferido ou testado | G5: Uma função | H5: Documentos, treinamento, plano de controle | I5: Calculada
B6: Ex. | C6: 46448 | D6: Farinha da marca B no lugar da marca A. | E6: Falta no fornecedor. | F6: Um lote de massa de teste: peso e ponto conferidos. | G6: Pizzaiolo líder | H6: Receita ajustada. Ficha da massa atualizada. | I6: OK
B7: 1 | I7: =IF(D7="",IF(COUNTA(C7,E7:H7)>0,"Falta o que mudou",""),IF(C7="","Falta a data",IF(F7="","Falta a análise",IF(G7="","Falta quem autorizou","OK"))))
B8: 2 | I8: =IF(D8="",IF(COUNTA(C8,E8:H8)>0,"Falta o que mudou",""),IF(C8="","Falta a data",IF(F8="","Falta a análise",IF(G8="","Falta quem autorizou","OK"))))
B9: 3 | I9: =IF(D9="",IF(COUNTA(C9,E9:H9)>0,"Falta o que mudou",""),IF(C9="","Falta a data",IF(F9="","Falta a análise",IF(G9="","Falta quem autorizou","OK"))))
B10: 4 | I10: =IF(D10="",IF(COUNTA(C10,E10:H10)>0,"Falta o que mudou",""),IF(C10="","Falta a data",IF(F10="","Falta a análise",IF(G10="","Falta quem autorizou","OK"))))
B11: 5 | I11: =IF(D11="",IF(COUNTA(C11,E11:H11)>0,"Falta o que mudou",""),IF(C11="","Falta a data",IF(F11="","Falta a análise",IF(G11="","Falta quem autorizou","OK"))))
B12: 6 | I12: =IF(D12="",IF(COUNTA(C12,E12:H12)>0,"Falta o que mudou",""),IF(C12="","Falta a data",IF(F12="","Falta a análise",IF(G12="","Falta quem autorizou","OK"))))
B13: 7 | I13: =IF(D13="",IF(COUNTA(C13,E13:H13)>0,"Falta o que mudou",""),IF(C13="","Falta a data",IF(F13="","Falta a análise",IF(G13="","Falta quem autorizou","OK"))))
B14: 8 | I14: =IF(D14="",IF(COUNTA(C14,E14:H14)>0,"Falta o que mudou",""),IF(C14="","Falta a data",IF(F14="","Falta a análise",IF(G14="","Falta quem autorizou","OK"))))
B15: 9 | I15: =IF(D15="",IF(COUNTA(C15,E15:H15)>0,"Falta o que mudou",""),IF(C15="","Falta a data",IF(F15="","Falta a análise",IF(G15="","Falta quem autorizou","OK"))))
B16: 10 | I16: =IF(D16="",IF(COUNTA(C16,E16:H16)>0,"Falta o que mudou",""),IF(C16="","Falta a data",IF(F16="","Falta a análise",IF(G16="","Falta quem autorizou","OK"))))
B17: 11 | I17: =IF(D17="",IF(COUNTA(C17,E17:H17)>0,"Falta o que mudou",""),IF(C17="","Falta a data",IF(F17="","Falta a análise",IF(G17="","Falta quem autorizou","OK"))))
B18: 12 | I18: =IF(D18="",IF(COUNTA(C18,E18:H18)>0,"Falta o que mudou",""),IF(C18="","Falta a data",IF(F18="","Falta a análise",IF(G18="","Falta quem autorizou","OK"))))
B20: Resumo automático
B21: Mudanças registradas | E21: =COUNTA(D7:D18) -> 0
B22: Com análise e autorização | E22: =COUNTIF(I7:I18,"OK") -> 0
B23: Aviso | E23: =IF(E21=0,"Nenhuma mudança registrada: confirme se o processo não mudou",IF(E22<E21,"Há mudança sem análise ou sem autorização","OK")) -> Nenhuma mudança registrada: confirme se o processo não mudou

Sheet Painel
B1: Painel do controle
B2: As verificações e os desvios por controle. Nada a preencher: tudo vem das outras abas.
B4: Organização e processo | D4: =IF('Plano de controle'!D4="","",'Plano de controle'!D4)
B6: Indicador | D6: Resultado | E6: Como se lê
B7: Controles no plano | D7: =COUNTA('Plano de controle'!D10:D29) -> 0 | E7: Da aba Plano de controle. O usual é de cinco a dez por processo.
B8: Verificações lançadas | D8: =COUNTA(Registros!E7:E156) -> 0 | E8: Da aba Registros.
B9: Dentro do critério | D9: =IF(COUNTIF(Registros!L7:L156,"Dentro")+COUNTIF(Registros!L7:L156,"Fora")=0,"",COUNTIF(Registros!L7:L156,"Dentro")/(COUNTIF(Registros!L7:L156,"Dentro")+COUNTIF(Registros!L7:L156,"Fora"))) | E9: Parte das verificações com leitura que atendeu ao critério.
B10: Fora do critério | D10: =COUNTIF(Registros!L7:L156,"Fora") -> 0 | E10: Cada uma pede uma reação, com o produto e com o processo.
B11: Fora sem reação registrada | D11: =COUNTIF(Registros!O7:O156,"Fora sem reação registrada") -> 0 | E11: O aviso mais grave: o que foi feito com o produto?
B12: Controles sem registro | D12: =COUNTIF(I18:I37,"Sem registro") -> 0 | E12: Estão no plano, e não há verificação lançada.
B13: Controles com desvio repetido | D13: =COUNTIF(I18:I37,"Desvio repetido: analisar a causa") -> 0 | E13: Mais de um resultado fora: a reação não basta.
B14: Mudanças: registradas, a rever | D14: =COUNTA(Mudanças!D7:D18)&" registradas, "&(COUNTA(Mudanças!D7:D18)-COUNTIF(Mudanças!I7:I18,"OK"))&" a rever" -> 0 registradas, 0 a rever | E14: A rever: sem a análise feita antes, ou sem quem autorizou.
B16: Leitura de cada controle
B17: # | C17: O que se controla | D17: Critério | E17: Verificações | F17: Fora | G17: Sem reação | H17: Dentro | I17: Leitura
B18: K1 | C18: =IF('Plano de controle'!D10="","",'Plano de controle'!D10) | D18: =IF(C18="","",'Plano de controle'!N10) | E18: =IF(C18="","",COUNTIF(Registros!E7:E156,B18)) | F18: =IF(C18="","",SUMPRODUCT((Registros!E7:E156=B18)*(Registros!L7:L156="Fora"))) | G18: =IF(C18="","",SUMPRODUCT((Registros!E7:E156=B18)*(Registros!O7:O156="Fora sem reação registrada"))) | H18: =IF(OR(C18="",N(E18)=0),"",1-F18/E18) | I18: =IF(C18="","",IF(E18=0,"Sem registro",IF(G18>0,"Fora sem reação: cobrar",IF(F18>1,"Desvio repetido: analisar a causa",IF(F18=1,"Um desvio, com reação","Dentro do critério")))))
B19: K2 | C19: =IF('Plano de controle'!D11="","",'Plano de controle'!D11) | D19: =IF(C19="","",'Plano de controle'!N11) | E19: =IF(C19="","",COUNTIF(Registros!E7:E156,B19)) | F19: =IF(C19="","",SUMPRODUCT((Registros!E7:E156=B19)*(Registros!L7:L156="Fora"))) | G19: =IF(C19="","",SUMPRODUCT((Registros!E7:E156=B19)*(Registros!O7:O156="Fora sem reação registrada"))) | H19: =IF(OR(C19="",N(E19)=0),"",1-F19/E19) | I19: =IF(C19="","",IF(E19=0,"Sem registro",IF(G19>0,"Fora sem reação: cobrar",IF(F19>1,"Desvio repetido: analisar a causa",IF(F19=1,"Um desvio, com reação","Dentro do critério")))))
B20: K3 | C20: =IF('Plano de controle'!D12="","",'Plano de controle'!D12) | D20: =IF(C20="","",'Plano de controle'!N12) | E20: =IF(C20="","",COUNTIF(Registros!E7:E156,B20)) | F20: =IF(C20="","",SUMPRODUCT((Registros!E7:E156=B20)*(Registros!L7:L156="Fora"))) | G20: =IF(C20="","",SUMPRODUCT((Registros!E7:E156=B20)*(Registros!O7:O156="Fora sem reação registrada"))) | H20: =IF(OR(C20="",N(E20)=0),"",1-F20/E20) | I20: =IF(C20="","",IF(E20=0,"Sem registro",IF(G20>0,"Fora sem reação: cobrar",IF(F20>1,"Desvio repetido: analisar a causa",IF(F20=1,"Um desvio, com reação","Dentro do critério")))))
B21: K4 | C21: =IF('Plano de controle'!D13="","",'Plano de controle'!D13) | D21: =IF(C21="","",'Plano de controle'!N13) | E21: =IF(C21="","",COUNTIF(Registros!E7:E156,B21)) | F21: =IF(C21="","",SUMPRODUCT((Registros!E7:E156=B21)*(Registros!L7:L156="Fora"))) | G21: =IF(C21="","",SUMPRODUCT((Registros!E7:E156=B21)*(Registros!O7:O156="Fora sem reação registrada"))) | H21: =IF(OR(C21="",N(E21)=0),"",1-F21/E21) | I21: =IF(C21="","",IF(E21=0,"Sem registro",IF(G21>0,"Fora sem reação: cobrar",IF(F21>1,"Desvio repetido: analisar a causa",IF(F21=1,"Um desvio, com reação","Dentro do critério")))))
B22: K5 | C22: =IF('Plano de controle'!D14="","",'Plano de controle'!D14) | D22: =IF(C22="","",'Plano de controle'!N14) | E22: =IF(C22="","",COUNTIF(Registros!E7:E156,B22)) | F22: =IF(C22="","",SUMPRODUCT((Registros!E7:E156=B22)*(Registros!L7:L156="Fora"))) | G22: =IF(C22="","",SUMPRODUCT((Registros!E7:E156=B22)*(Registros!O7:O156="Fora sem reação registrada"))) | H22: =IF(OR(C22="",N(E22)=0),"",1-F22/E22) | I22: =IF(C22="","",IF(E22=0,"Sem registro",IF(G22>0,"Fora sem reação: cobrar",IF(F22>1,"Desvio repetido: analisar a causa",IF(F22=1,"Um desvio, com reação","Dentro do critério")))))
B23: K6 | C23: =IF('Plano de controle'!D15="","",'Plano de controle'!D15) | D23: =IF(C23="","",'Plano de controle'!N15) | E23: =IF(C23="","",COUNTIF(Registros!E7:E156,B23)) | F23: =IF(C23="","",SUMPRODUCT((Registros!E7:E156=B23)*(Registros!L7:L156="Fora"))) | G23: =IF(C23="","",SUMPRODUCT((Registros!E7:E156=B23)*(Registros!O7:O156="Fora sem reação registrada"))) | H23: =IF(OR(C23="",N(E23)=0),"",1-F23/E23) | I23: =IF(C23="","",IF(E23=0,"Sem registro",IF(G23>0,"Fora sem reação: cobrar",IF(F23>1,"Desvio repetido: analisar a causa",IF(F23=1,"Um desvio, com reação","Dentro do critério")))))
B24: K7 | C24: =IF('Plano de controle'!D16="","",'Plano de controle'!D16) | D24: =IF(C24="","",'Plano de controle'!N16) | E24: =IF(C24="","",COUNTIF(Registros!E7:E156,B24)) | F24: =IF(C24="","",SUMPRODUCT((Registros!E7:E156=B24)*(Registros!L7:L156="Fora"))) | G24: =IF(C24="","",SUMPRODUCT((Registros!E7:E156=B24)*(Registros!O7:O156="Fora sem reação registrada"))) | H24: =IF(OR(C24="",N(E24)=0),"",1-F24/E24) | I24: =IF(C24="","",IF(E24=0,"Sem registro",IF(G24>0,"Fora sem reação: cobrar",IF(F24>1,"Desvio repetido: analisar a causa",IF(F24=1,"Um desvio, com reação","Dentro do critério")))))
B25: K8 | C25: =IF('Plano de controle'!D17="","",'Plano de controle'!D17) | D25: =IF(C25="","",'Plano de controle'!N17) | E25: =IF(C25="","",COUNTIF(Registros!E7:E156,B25)) | F25: =IF(C25="","",SUMPRODUCT((Registros!E7:E156=B25)*(Registros!L7:L156="Fora"))) | G25: =IF(C25="","",SUMPRODUCT((Registros!E7:E156=B25)*(Registros!O7:O156="Fora sem reação registrada"))) | H25: =IF(OR(C25="",N(E25)=0),"",1-F25/E25) | I25: =IF(C25="","",IF(E25=0,"Sem registro",IF(G25>0,"Fora sem reação: cobrar",IF(F25>1,"Desvio repetido: analisar a causa",IF(F25=1,"Um desvio, com reação","Dentro do critério")))))
B26: K9 | C26: =IF('Plano de controle'!D18="","",'Plano de controle'!D18) | D26: =IF(C26="","",'Plano de controle'!N18) | E26: =IF(C26="","",COUNTIF(Registros!E7:E156,B26)) | F26: =IF(C26="","",SUMPRODUCT((Registros!E7:E156=B26)*(Registros!L7:L156="Fora"))) | G26: =IF(C26="","",SUMPRODUCT((Registros!E7:E156=B26)*(Registros!O7:O156="Fora sem reação registrada"))) | H26: =IF(OR(C26="",N(E26)=0),"",1-F26/E26) | I26: =IF(C26="","",IF(E26=0,"Sem registro",IF(G26>0,"Fora sem reação: cobrar",IF(F26>1,"Desvio repetido: analisar a causa",IF(F26=1,"Um desvio, com reação","Dentro do critério")))))
B27: K10 | C27: =IF('Plano de controle'!D19="","",'Plano de controle'!D19) | D27: =IF(C27="","",'Plano de controle'!N19) | E27: =IF(C27="","",COUNTIF(Registros!E7:E156,B27)) | F27: =IF(C27="","",SUMPRODUCT((Registros!E7:E156=B27)*(Registros!L7:L156="Fora"))) | G27: =IF(C27="","",SUMPRODUCT((Registros!E7:E156=B27)*(Registros!O7:O156="Fora sem reação registrada"))) | H27: =IF(OR(C27="",N(E27)=0),"",1-F27/E27) | I27: =IF(C27="","",IF(E27=0,"Sem registro",IF(G27>0,"Fora sem reação: cobrar",IF(F27>1,"Desvio repetido: analisar a causa",IF(F27=1,"Um desvio, com reação","Dentro do critério")))))
B28: K11 | C28: =IF('Plano de controle'!D20="","",'Plano de controle'!D20) | D28: =IF(C28="","",'Plano de controle'!N20) | E28: =IF(C28="","",COUNTIF(Registros!E7:E156,B28)) | F28: =IF(C28="","",SUMPRODUCT((Registros!E7:E156=B28)*(Registros!L7:L156="Fora"))) | G28: =IF(C28="","",SUMPRODUCT((Registros!E7:E156=B28)*(Registros!O7:O156="Fora sem reação registrada"))) | H28: =IF(OR(C28="",N(E28)=0),"",1-F28/E28) | I28: =IF(C28="","",IF(E28=0,"Sem registro",IF(G28>0,"Fora sem reação: cobrar",IF(F28>1,"Desvio repetido: analisar a causa",IF(F28=1,"Um desvio, com reação","Dentro do critério")))))
B29: K12 | C29: =IF('Plano de controle'!D21="","",'Plano de controle'!D21) | D29: =IF(C29="","",'Plano de controle'!N21) | E29: =IF(C29="","",COUNTIF(Registros!E7:E156,B29)) | F29: =IF(C29="","",SUMPRODUCT((Registros!E7:E156=B29)*(Registros!L7:L156="Fora"))) | G29: =IF(C29="","",SUMPRODUCT((Registros!E7:E156=B29)*(Registros!O7:O156="Fora sem reação registrada"))) | H29: =IF(OR(C29="",N(E29)=0),"",1-F29/E29) | I29: =IF(C29="","",IF(E29=0,"Sem registro",IF(G29>0,"Fora sem reação: cobrar",IF(F29>1,"Desvio repetido: analisar a causa",IF(F29=1,"Um desvio, com reação","Dentro do critério")))))
B30: K13 | C30: =IF('Plano de controle'!D22="","",'Plano de controle'!D22) | D30: =IF(C30="","",'Plano de controle'!N22) | E30: =IF(C30="","",COUNTIF(Registros!E7:E156,B30)) | F30: =IF(C30="","",SUMPRODUCT((Registros!E7:E156=B30)*(Registros!L7:L156="Fora"))) | G30: =IF(C30="","",SUMPRODUCT((Registros!E7:E156=B30)*(Registros!O7:O156="Fora sem reação registrada"))) | H30: =IF(OR(C30="",N(E30)=0),"",1-F30/E30) | I30: =IF(C30="","",IF(E30=0,"Sem registro",IF(G30>0,"Fora sem reação: cobrar",IF(F30>1,"Desvio repetido: analisar a causa",IF(F30=1,"Um desvio, com reação","Dentro do critério")))))
B31: K14 | C31: =IF('Plano de controle'!D23="","",'Plano de controle'!D23) | D31: =IF(C31="","",'Plano de controle'!N23) | E31: =IF(C31="","",COUNTIF(Registros!E7:E156,B31)) | F31: =IF(C31="","",SUMPRODUCT((Registros!E7:E156=B31)*(Registros!L7:L156="Fora"))) | G31: =IF(C31="","",SUMPRODUCT((Registros!E7:E156=B31)*(Registros!O7:O156="Fora sem reação registrada"))) | H31: =IF(OR(C31="",N(E31)=0),"",1-F31/E31) | I31: =IF(C31="","",IF(E31=0,"Sem registro",IF(G31>0,"Fora sem reação: cobrar",IF(F31>1,"Desvio repetido: analisar a causa",IF(F31=1,"Um desvio, com reação","Dentro do critério")))))
B32: K15 | C32: =IF('Plano de controle'!D24="","",'Plano de controle'!D24) | D32: =IF(C32="","",'Plano de controle'!N24) | E32: =IF(C32="","",COUNTIF(Registros!E7:E156,B32)) | F32: =IF(C32="","",SUMPRODUCT((Registros!E7:E156=B32)*(Registros!L7:L156="Fora"))) | G32: =IF(C32="","",SUMPRODUCT((Registros!E7:E156=B32)*(Registros!O7:O156="Fora sem reação registrada"))) | H32: =IF(OR(C32="",N(E32)=0),"",1-F32/E32) | I32: =IF(C32="","",IF(E32=0,"Sem registro",IF(G32>0,"Fora sem reação: cobrar",IF(F32>1,"Desvio repetido: analisar a causa",IF(F32=1,"Um desvio, com reação","Dentro do critério")))))
B33: K16 | C33: =IF('Plano de controle'!D25="","",'Plano de controle'!D25) | D33: =IF(C33="","",'Plano de controle'!N25) | E33: =IF(C33="","",COUNTIF(Registros!E7:E156,B33)) | F33: =IF(C33="","",SUMPRODUCT((Registros!E7:E156=B33)*(Registros!L7:L156="Fora"))) | G33: =IF(C33="","",SUMPRODUCT((Registros!E7:E156=B33)*(Registros!O7:O156="Fora sem reação registrada"))) | H33: =IF(OR(C33="",N(E33)=0),"",1-F33/E33) | I33: =IF(C33="","",IF(E33=0,"Sem registro",IF(G33>0,"Fora sem reação: cobrar",IF(F33>1,"Desvio repetido: analisar a causa",IF(F33=1,"Um desvio, com reação","Dentro do critério")))))
B34: K17 | C34: =IF('Plano de controle'!D26="","",'Plano de controle'!D26) | D34: =IF(C34="","",'Plano de controle'!N26) | E34: =IF(C34="","",COUNTIF(Registros!E7:E156,B34)) | F34: =IF(C34="","",SUMPRODUCT((Registros!E7:E156=B34)*(Registros!L7:L156="Fora"))) | G34: =IF(C34="","",SUMPRODUCT((Registros!E7:E156=B34)*(Registros!O7:O156="Fora sem reação registrada"))) | H34: =IF(OR(C34="",N(E34)=0),"",1-F34/E34) | I34: =IF(C34="","",IF(E34=0,"Sem registro",IF(G34>0,"Fora sem reação: cobrar",IF(F34>1,"Desvio repetido: analisar a causa",IF(F34=1,"Um desvio, com reação","Dentro do critério")))))
B35: K18 | C35: =IF('Plano de controle'!D27="","",'Plano de controle'!D27) | D35: =IF(C35="","",'Plano de controle'!N27) | E35: =IF(C35="","",COUNTIF(Registros!E7:E156,B35)) | F35: =IF(C35="","",SUMPRODUCT((Registros!E7:E156=B35)*(Registros!L7:L156="Fora"))) | G35: =IF(C35="","",SUMPRODUCT((Registros!E7:E156=B35)*(Registros!O7:O156="Fora sem reação registrada"))) | H35: =IF(OR(C35="",N(E35)=0),"",1-F35/E35) | I35: =IF(C35="","",IF(E35=0,"Sem registro",IF(G35>0,"Fora sem reação: cobrar",IF(F35>1,"Desvio repetido: analisar a causa",IF(F35=1,"Um desvio, com reação","Dentro do critério")))))
B36: K19 | C36: =IF('Plano de controle'!D28="","",'Plano de controle'!D28) | D36: =IF(C36="","",'Plano de controle'!N28) | E36: =IF(C36="","",COUNTIF(Registros!E7:E156,B36)) | F36: =IF(C36="","",SUMPRODUCT((Registros!E7:E156=B36)*(Registros!L7:L156="Fora"))) | G36: =IF(C36="","",SUMPRODUCT((Registros!E7:E156=B36)*(Registros!O7:O156="Fora sem reação registrada"))) | H36: =IF(OR(C36="",N(E36)=0),"",1-F36/E36) | I36: =IF(C36="","",IF(E36=0,"Sem registro",IF(G36>0,"Fora sem reação: cobrar",IF(F36>1,"Desvio repetido: analisar a causa",IF(F36=1,"Um desvio, com reação","Dentro do critério")))))
B37: K20 | C37: =IF('Plano de controle'!D29="","",'Plano de controle'!D29) | D37: =IF(C37="","",'Plano de controle'!N29) | E37: =IF(C37="","",COUNTIF(Registros!E7:E156,B37)) | F37: =IF(C37="","",SUMPRODUCT((Registros!E7:E156=B37)*(Registros!L7:L156="Fora"))) | G37: =IF(C37="","",SUMPRODUCT((Registros!E7:E156=B37)*(Registros!O7:O156="Fora sem reação registrada"))) | H37: =IF(OR(C37="",N(E37)=0),"",1-F37/E37) | I37: =IF(C37="","",IF(E37=0,"Sem registro",IF(G37>0,"Fora sem reação: cobrar",IF(F37>1,"Desvio repetido: analisar a causa",IF(F37=1,"Um desvio, com reação","Dentro do critério")))))
B39: Resumo automático
B40: Aviso | D40: =IF(D7=0,"Escreva os controles na aba Plano de controle",IF(D8=0,"Lance as verificações na aba Registros",IF(D11>0,"Há resultado fora do critério sem reação registrada",IF(D12>0,"Há controle sem registro",IF(D13>0,"Há desvio que se repete: abra a análise de causa",IF(COUNTA(Mudanças!D7:D18)>COUNTIF(Mudanças!I7:I18,"OK"),"Há mudança sem análise ou sem autorização","OK")))))) -> Escreva os controles na aba Plano de controle

Sheet Checklist
B1: Checklist do controle de produção e de serviço
B2: Escolha o status de cada item na lista suspensa (coluna em amarelo-claro).
B4: # | C4: Item de verificação | D4: Status | E4: Observações
B5: 1 | C5: As etapas do processo estão listadas, do recebimento à entrega.
B6: 2 | C6: Cada controle diz o que medir, com o critério: mínimo, máximo ou padrão.
B7: 3 | C7: Cada controle diz como medir, com que instrumento e com que frequência.
B8: 4 | C8: Cada controle tem quem mede, onde registra e o que fazer quando o resultado sai do critério.
B9: 5 | C9: Os instrumentos usados nos controles estão calibrados ou verificados.
B10: 6 | C10: Quem executa conhece o plano, e a versão em uso no posto é a vigente.
B11: 7 | C11: Os registros estão em dia, e cada resultado fora do critério tem a reação registrada.
B12: 8 | C12: O produto é identificado em todas as etapas, e dá para saber se já foi verificado.
B13: 9 | C13: É possível ir do produto entregue aos insumos e aos registros, e voltar.
B14: 10 | C14: O que pertence ao cliente ou ao fornecedor está identificado e cuidado, e as ocorrências são comunicadas ao dono.
B15: 11 | C15: O produto é protegido no manuseio, na armazenagem e no transporte.
B16: 12 | C16: Toda mudança no processo tem análise, autorização e registro, antes de entrar em uso.
B18: Resumo automático
B19: Itens atendidos (Sim) | D19: =COUNTIF(D5:D16,"Sim") -> 0
B20: Itens parciais | D20: =COUNTIF(D5:D16,"Parcial") -> 0
B21: Itens não atendidos | D21: =COUNTIF(D5:D16,"Não") -> 0
B22: Itens sem resposta | D22: =COUNTBLANK(D5:D16) -> 12
B23: Percentual atendido | D23: =D19/ROWS(D5:D16) -> 0
B24: Situação | D24: =IF(D19=ROWS(D5:D16),"Validado",IF(D22>0,"Em andamento","Com pendências")) -> Em andamento

Sheet Exemplo 1 - Pizzaria
B1: Controle de produção e de serviço
B2: Exemplo preenchido, para consulta. Use as abas Plano de controle, Registros, Rastreabilidade e Mudanças para o seu processo.
B4: Organização | D4: Pizzaria (loja com salão e delivery)
B5: Processo | D5: Produzir e embalar (P2) e Entregar o pedido (P3)
B6: Produto ou serviço | D6: Pizza entregue em casa
B7: Plano de controle | D7: Revisão 2, de 01/03/2027. Pizzaiolo líder e líder da expedição, com o gerente da loja.
B8: Registros | D8: Noites de 08 a 14/03/2027, lidos em 15/03/2027.
B9: Origem | D9: Requisito 8.5.6 não atendido no diagnóstico de 2026, e objetivo O4: reduzir os pedidos refeitos.
B11: Plano de controle
B12: # | C12: Etapa | D12: O que controlar | E12: Tipo | F12: Mín. | G12: Máx. | H12: Unidade | I12: Como medir | J12: Frequência | K12: Quem · registro | L12: Reação se sair do critério
B13: K1 | C13: Receber e guardar insumos | D13: Temperatura da câmara fria | E13: Processo | F13: 0 | G13: 5 | H13: °C | I13: Termômetro da câmara, leitura no visor | J13: Duas vezes por turno | K13: Pizzaiolo do turno · Planilha de temperatura (FR-02) | L13: Avisar o gerente, passar os insumos para o refrigerador reserva e avaliar o que ficou acima de 5 °C por mais de duas horas.
B14: K2 | C14: Preparar a massa | D14: Peso da bola de massa da pizza grande | E14: Produto | F14: 380 | G14: 420 | H14: g | I14: Balança da bancada, média de cinco bolas | J14: Cada lote de massa | K14: Pizzaiolo do turno · Ficha do lote de massa | L14: Regular a divisora e pesar de novo o lote inteiro.
B15: K3 | C15: Montar | D15: Bancada e utensílios higienizados antes do turno | E15: Processo | H15: atributo | I15: Lista de abertura do turno, conferida no posto | J15: Cada turno | K15: Pizzaiolo líder · Lista de abertura do turno | L15: Higienizar antes de começar. Não montar pizza em bancada reprovada.
B16: K4 | C16: Assar | D16: Temperatura do forno | E16: Processo | F16: 280 | G16: 320 | H16: °C | I16: Termômetro do forno, no pico do turno | J16: Uma vez por hora | K16: Pizzaiolo do turno · Registro de regulagem do forno | L16: Regular o forno e segurar a entrada de pizzas até a temperatura voltar à faixa.
B17: K5 | C17: Conferir e embalar | D17: Pedidos com a etiqueta rubricada, em 20 conferidos | E17: Produto | F17: 20 | H17: pedidos | I17: Conferência da pizza com a etiqueta; amostra de 20 no fechamento | J17: Todo pedido | K17: Quem embala · Etiqueta rubricada | L17: Conferir de novo o pedido sem rubrica antes da saída e orientar quem embalou.
B18: K6 | C18: Expedir | D18: Maior espera da pizza pronta, na noite | E18: Processo | G18: 10 | H18: min | I18: Horários de pronto e de saída, no sistema de pedidos | J18: Todo pedido de entrega | K18: Líder da expedição · Sistema de pedidos | L18: Priorizar a saída. Acima de 15 minutos, refazer a pizza.
B19: K7 | C19: Expedir | D19: Temperatura da pizza na saída | E19: Produto | F19: 65 | H19: °C | I19: Termômetro de espeto, no centro da pizza | J19: Três pedidos por hora | K19: Líder da expedição · Planilha da expedição | L19: Reaquecer ou refazer, e conferir a bolsa térmica.
B21: Resumo por controle
B22: # | C22: O que se controla | E22: Verificações | F22: Fora | G22: Sem reação | I22: Dentro do critério | J22: Leitura
B23: K1 | C23: Temperatura da câmara fria | E23: =COUNTIF($E$33:$E$88,B23) -> 14 | F23: =SUMPRODUCT(($E$33:$E$88=B23)*($I$33:$I$88="Fora")) -> 1 | G23: =SUMPRODUCT(($E$33:$E$88=B23)*($I$33:$I$88="Fora")*($J$33:$J$88="")) -> 0 | I23: =IF(E23=0,"",1-F23/E23) -> 0.92857143 | J23: =IF(E23=0,"Sem registro",IF(G23>0,"Fora sem reação: cobrar",IF(F23>1,"Desvio repetido: analisar a causa",IF(F23=1,"Um desvio, com reação","Dentro do critério")))) -> Um desvio, com reação
B24: K2 | C24: Peso da bola de massa da pizza grande | E24: =COUNTIF($E$33:$E$88,B24) -> 7 | F24: =SUMPRODUCT(($E$33:$E$88=B24)*($I$33:$I$88="Fora")) -> 0 | G24: =SUMPRODUCT(($E$33:$E$88=B24)*($I$33:$I$88="Fora")*($J$33:$J$88="")) -> 0 | I24: =IF(E24=0,"",1-F24/E24) -> 1 | J24: =IF(E24=0,"Sem registro",IF(G24>0,"Fora sem reação: cobrar",IF(F24>1,"Desvio repetido: analisar a causa",IF(F24=1,"Um desvio, com reação","Dentro do critério")))) -> Dentro do critério
B25: K3 | C25: Bancada e utensílios higienizados antes do turno | E25: =COUNTIF($E$33:$E$88,B25) -> 7 | F25: =SUMPRODUCT(($E$33:$E$88=B25)*($I$33:$I$88="Fora")) -> 0 | G25: =SUMPRODUCT(($E$33:$E$88=B25)*($I$33:$I$88="Fora")*($J$33:$J$88="")) -> 0 | I25: =IF(E25=0,"",1-F25/E25) -> 1 | J25: =IF(E25=0,"Sem registro",IF(G25>0,"Fora sem reação: cobrar",IF(F25>1,"Desvio repetido: analisar a causa",IF(F25=1,"Um desvio, com reação","Dentro do critério")))) -> Dentro do critério
B26: K4 | C26: Temperatura do forno | E26: =COUNTIF($E$33:$E$88,B26) -> 7 | F26: =SUMPRODUCT(($E$33:$E$88=B26)*($I$33:$I$88="Fora")) -> 1 | G26: =SUMPRODUCT(($E$33:$E$88=B26)*($I$33:$I$88="Fora")*($J$33:$J$88="")) -> 0 | I26: =IF(E26=0,"",1-F26/E26) -> 0.85714286 | J26: =IF(E26=0,"Sem registro",IF(G26>0,"Fora sem reação: cobrar",IF(F26>1,"Desvio repetido: analisar a causa",IF(F26=1,"Um desvio, com reação","Dentro do critério")))) -> Um desvio, com reação
B27: K5 | C27: Pedidos com a etiqueta rubricada, em 20 conferidos | E27: =COUNTIF($E$33:$E$88,B27) -> 7 | F27: =SUMPRODUCT(($E$33:$E$88=B27)*($I$33:$I$88="Fora")) -> 1 | G27: =SUMPRODUCT(($E$33:$E$88=B27)*($I$33:$I$88="Fora")*($J$33:$J$88="")) -> 0 | I27: =IF(E27=0,"",1-F27/E27) -> 0.85714286 | J27: =IF(E27=0,"Sem registro",IF(G27>0,"Fora sem reação: cobrar",IF(F27>1,"Desvio repetido: analisar a causa",IF(F27=1,"Um desvio, com reação","Dentro do critério")))) -> Um desvio, com reação
B28: K6 | C28: Maior espera da pizza pronta, na noite | E28: =COUNTIF($E$33:$E$88,B28) -> 7 | F28: =SUMPRODUCT(($E$33:$E$88=B28)*($I$33:$I$88="Fora")) -> 2 | G28: =SUMPRODUCT(($E$33:$E$88=B28)*($I$33:$I$88="Fora")*($J$33:$J$88="")) -> 0 | I28: =IF(E28=0,"",1-F28/E28) -> 0.71428571 | J28: =IF(E28=0,"Sem registro",IF(G28>0,"Fora sem reação: cobrar",IF(F28>1,"Desvio repetido: analisar a causa",IF(F28=1,"Um desvio, com reação","Dentro do critério")))) -> Desvio repetido: analisar a causa
B29: K7 | C29: Temperatura da pizza na saída | E29: =COUNTIF($E$33:$E$88,B29) -> 7 | F29: =SUMPRODUCT(($E$33:$E$88=B29)*($I$33:$I$88="Fora")) -> 1 | G29: =SUMPRODUCT(($E$33:$E$88=B29)*($I$33:$I$88="Fora")*($J$33:$J$88="")) -> 1 | I29: =IF(E29=0,"",1-F29/E29) -> 0.85714286 | J29: =IF(E29=0,"Sem registro",IF(G29>0,"Fora sem reação: cobrar",IF(F29>1,"Desvio repetido: analisar a causa",IF(F29=1,"Um desvio, com reação","Dentro do critério")))) -> Fora sem reação: cobrar
B31: Registros
B32: Data | C32: Lote ou pedido | D32: O que se controla | E32: Controle | F32: Mín. | G32: Máx. | H32: Resultado | I32: Leitura | J32: Reação tomada
B33: 46454 | C33: Câmara, 1ª leitura | D33: Temperatura da câmara fria | E33: K1 | F33: =IFERROR(IF(ISNUMBER(INDEX($F$13:$F$19,MATCH(E33,$B$13:$B$19,0))),INDEX($F$13:$F$19,MATCH(E33,$B$13:$B$19,0)),""),"") -> 0 | G33: =IFERROR(IF(ISNUMBER(INDEX($G$13:$G$19,MATCH(E33,$B$13:$B$19,0))),INDEX($G$13:$G$19,MATCH(E33,$B$13:$B$19,0)),""),"") -> 5 | H33: 3.2 | I33: =IF(AND(F33="",G33=""),IF(H33="","Falta o resultado",IF(H33="Sim","Dentro","Fora")),IF(H33="","Falta o valor",IF(AND(OR(F33="",H33>=F33),OR(G33="",H33<=G33)),"Dentro","Fora"))) -> Dentro
B34: 46454 | C34: Câmara, 2ª leitura | D34: Temperatura da câmara fria | E34: K1 | F34: =IFERROR(IF(ISNUMBER(INDEX($F$13:$F$19,MATCH(E34,$B$13:$B$19,0))),INDEX($F$13:$F$19,MATCH(E34,$B$13:$B$19,0)),""),"") -> 0 | G34: =IFERROR(IF(ISNUMBER(INDEX($G$13:$G$19,MATCH(E34,$B$13:$B$19,0))),INDEX($G$13:$G$19,MATCH(E34,$B$13:$B$19,0)),""),"") -> 5 | H34: 3.5 | I34: =IF(AND(F34="",G34=""),IF(H34="","Falta o resultado",IF(H34="Sim","Dentro","Fora")),IF(H34="","Falta o valor",IF(AND(OR(F34="",H34>=F34),OR(G34="",H34<=G34)),"Dentro","Fora"))) -> Dentro
B35: 46454 | C35: Massa 08/03 | D35: Peso da bola de massa da pizza grande | E35: K2 | F35: =IFERROR(IF(ISNUMBER(INDEX($F$13:$F$19,MATCH(E35,$B$13:$B$19,0))),INDEX($F$13:$F$19,MATCH(E35,$B$13:$B$19,0)),""),"") -> 380 | G35: =IFERROR(IF(ISNUMBER(INDEX($G$13:$G$19,MATCH(E35,$B$13:$B$19,0))),INDEX($G$13:$G$19,MATCH(E35,$B$13:$B$19,0)),""),"") -> 420 | H35: 402 | I35: =IF(AND(F35="",G35=""),IF(H35="","Falta o resultado",IF(H35="Sim","Dentro","Fora")),IF(H35="","Falta o valor",IF(AND(OR(F35="",H35>=F35),OR(G35="",H35<=G35)),"Dentro","Fora"))) -> Dentro
B36: 46454 | C36: Turno 08/03 | D36: Bancada e utensílios higienizados antes do turno | E36: K3 | F36: =IFERROR(IF(ISNUMBER(INDEX($F$13:$F$19,MATCH(E36,$B$13:$B$19,0))),INDEX($F$13:$F$19,MATCH(E36,$B$13:$B$19,0)),""),"") | G36: =IFERROR(IF(ISNUMBER(INDEX($G$13:$G$19,MATCH(E36,$B$13:$B$19,0))),INDEX($G$13:$G$19,MATCH(E36,$B$13:$B$19,0)),""),"") | H36: Sim | I36: =IF(AND(F36="",G36=""),IF(H36="","Falta o resultado",IF(H36="Sim","Dentro","Fora")),IF(H36="","Falta o valor",IF(AND(OR(F36="",H36>=F36),OR(G36="",H36<=G36)),"Dentro","Fora"))) -> Dentro
