Workbook

Sheet Instruções
B1: Análise crítica pela direção — Como usar esta planilha
B2: Modelo para preparar a pauta, registrar as entradas e as decisões, e acompanhar as ações das análises anteriores.
B4: Legenda: onde preencher
B5: Amarelo-claro | C5: Células de entrada. É aqui que você digita.
B6: Cinza | C6: Células calculadas ou fixas (rótulos, entradas da norma, contagens, avisos). Não altere.
B7: Cinza em itálico | C7: Linha de exemplo (marcada com “Ex.”). Mostra o formato esperado e não entra nas contagens.
B8: Listas suspensas | C8: Colunas de tendência, situação, tipo, status e avaliação aceitam apenas as opções da lista.
B9: Comentários | C9: Células com triângulo vermelho no canto trazem uma dica de preenchimento. Passe o mouse sobre elas.
B11: As três situações de uma entrada
B12: Favorável | C12: O resultado atende ao planejado, e a tendência não preocupa. A direção registra a conclusão.
B13: Atenção | C13: O resultado não atende em parte, ou a tendência é de piora. A direção decide, ou registra por que não vai agir agora.
B14: Crítica | C14: O resultado compromete um objetivo, um cliente ou a operação. A direção decide na reunião.
B16: Ordem recomendada de preenchimento
B17: Passo 1 | C17: Aba Reunião: escreva a data, o período analisado e os participantes.
B18: Passo 2 | C18: Aba Ações anteriores: liste as ações decididas nas análises anteriores, com prazo e status.
B19: Passo 3 | C19: Aba Entradas: escreva o resultado, a tendência e a situação de cada entrada. Use “nada a relatar” quando for o caso.
B20: Passo 4 | C20: Aba Entradas: na reunião, escreva a conclusão da direção sobre cada entrada.
B21: Passo 5 | C21: Aba Saídas: registre cada decisão, com a entrada de origem, o tipo, o responsável, o prazo e o recurso.
B22: Passo 6 | C22: Aba Reunião: responda às quatro perguntas da avaliação do sistema, com justificativa.
B23: Passo 7 | C23: Aba Checklist: valide a análise crítica.
B25: Abas da planilha
B26: Reunião | C26: Dados da reunião, até 10 participantes, avaliação do sistema e situação da ata.
B27: Ações anteriores | C27: Até 15 ações das análises anteriores, com a situação de cada uma na data da reunião, e gráfico.
B28: Entradas | C28: As doze entradas, com resultado, tendência, situação, conclusão e número de decisões.
B29: Saídas | C29: Até 15 decisões, com conferência dos campos, contagem por tipo e valor total.
B30: Checklist | C30: Doze verificações de qualidade da análise crítica, com percentual de conclusão.
B31: Exemplo 1 - Pizzaria | C31: A primeira análise crítica de uma loja: entradas, decisões e avaliação do sistema.
B32: Exemplo 2 - Indústria | C32: Uma análise crítica semestral, com as ações das análises anteriores.
B34: Regras e premissas do modelo
B35: As doze entradas | C35: São os itens do requisito 9.3.2 da ISO 9001:2015, resumidos com palavras próprias. O item “c” tem sete partes, de c1 a c7.
B36: Situação da entrada | C36: As três situações são uma convenção deste modelo. A norma não classifica as entradas.
B37: Entrada crítica | C37: Pede pelo menos uma decisão na aba Saídas. Sem ela, a conferência mostra “Falta a decisão”.
B38: Entrada em atenção | C38: Pode ficar sem decisão, e o motivo vai na conclusão. A conferência mostra “Atenção sem decisão”, como lembrete.
B39: Situação da ação | C39: É calculada pela data da reunião, informada na aba Reunião. Se a data estiver em branco, a planilha usa a data de hoje.
B40: Primeira análise | C40: Na primeira análise crítica, a aba Ações anteriores fica em branco, e o aviso dela informa que não há ações.
B41: Exemplos | C41: Os dados das abas de exemplo são ilustrativos, criados para este material.

Sheet Reunião
B1: Reunião de análise crítica
B2: Dados da reunião, participantes e avaliação do sistema. A situação da ata é calculada no fim da página.
B4: Organização
B5: Data da reunião
B6: Período analisado
B7: Local
B8: Quem conduz
B9: Quem redige a ata
B10: Data da análise anterior
B11: Data prevista da próxima análise
B13: Participantes
B14: # | C14: Nome | D14: Função | E14: Alta direção? | F14: Presença | G14: Observação
B15: Ex. | C15: Maria Souza | D15: Diretora geral | E15: Sim | F15: Presente | G15: Conduz a reunião
B16: 1
B17: 2
B18: 3
B19: 4
B20: 5
B21: 6
B22: 7
B23: 8
B24: 9
B25: 10
B27: Avaliação do sistema
B28: Critério | D28: Pergunta | F28: Resposta | G28: Justificativa
B29: Adequado | D29: O sistema serve para a organização como ela é hoje?
B30: Suficiente | D30: O sistema cobre tudo o que precisa cobrir?
B31: Eficaz | D31: O sistema entrega os resultados planejados?
B32: Alinhado | D32: O sistema aponta para onde a direção quer ir?
B34: Resumo automático
B35: Participantes presentes | E35: =COUNTIF(F16:F25,"Presente") -> 0
B36: Alta direção presente | E36: =COUNTIFS(E16:E25,"Sim",F16:F25,"Presente") -> 0
B37: Meses desde a análise anterior | E37: =IF(OR(D5="",D10=""),"",ROUND((D5-D10)/30.4375,0))
B38: Entradas analisadas, de 12 | E38: =Entradas!E20 -> 0
B39: Decisões registradas | E39: =Saídas!E24 -> 0
B40: Ações anteriores atrasadas | E40: ='Ações anteriores'!E29 -> 0
B41: Situação da ata | E41: =IF(D5="","Informe a data da reunião",IF(E36=0,"Falta a presença da alta direção",IF(E38<12,"Há entrada sem análise: veja a aba Entradas",IF(Entradas!E25>0,"Há entrada crítica sem decisão",IF(COUNTIF(Saídas!K7:K21,"Falta*")+COUNTIF(Saídas!K7:K21,"Prazo*")>0,"Há decisão com o registro incompleto",IF(COUNTA(F29:F32)<4,"Falta a avaliação do sistema",IF(COUNTA(G29:G32)<4,"Falta a justificativa da avaliação",IF(D11="","Marque a data da próxima análise",IF(D11<=D5,"A próxima análise tem data anterior à reunião","OK"))))))))) -> Informe a data da reunião

Sheet Ações anteriores
B1: Ações das análises anteriores
B2: Entrada “a”. Uma ação por linha, com o que foi decidido nas análises anteriores. Na primeira análise, deixe em branco.
B4: Data de referência | D4: =IF(Reunião!D5="","",Reunião!D5) | E4: É a data da reunião. Se ela estiver em branco, a planilha usa a data de hoje.
B6: # | C6: Data da análise | D6: Ação decidida | E6: Responsável | F6: Prazo | G6: Status | H6: Concluída em | I6: Eficaz? | J6: Resultado ou observação | K6: Situação
C7: Da reunião que decidiu | D7: Como está na ata | E7: Nome ou cargo | F7: Combinado na ata | G7: Escolha na lista | H7: Só para as concluídas | I7: Funcionou? | J7: O que mudou depois da ação | K7: Calculada
B8: Ex. | C8: 46065 | D8: Contratar um analista para o Laboratório. | E8: Gerente de RH | F8: 46142 | G8: Concluída | H8: 46157 | I8: Sim | J8: Admissão em 15/05. | K8: Concluída com atraso
B9: 1 | K9: =IF(D9="","",IF(F9="","Falta o prazo",IF(G9="","Falta o status",IF(G9="Cancelada","Cancelada",IF(G9="Concluída",IF(H9="","Falta a data de conclusão",IF(H9<=F9,"Concluída no prazo","Concluída com atraso")),IF(F9<IF($D$4="",TODAY(),$D$4),"Atrasada","No prazo"))))))
B10: 2 | K10: =IF(D10="","",IF(F10="","Falta o prazo",IF(G10="","Falta o status",IF(G10="Cancelada","Cancelada",IF(G10="Concluída",IF(H10="","Falta a data de conclusão",IF(H10<=F10,"Concluída no prazo","Concluída com atraso")),IF(F10<IF($D$4="",TODAY(),$D$4),"Atrasada","No prazo"))))))
B11: 3 | K11: =IF(D11="","",IF(F11="","Falta o prazo",IF(G11="","Falta o status",IF(G11="Cancelada","Cancelada",IF(G11="Concluída",IF(H11="","Falta a data de conclusão",IF(H11<=F11,"Concluída no prazo","Concluída com atraso")),IF(F11<IF($D$4="",TODAY(),$D$4),"Atrasada","No prazo"))))))
B12: 4 | K12: =IF(D12="","",IF(F12="","Falta o prazo",IF(G12="","Falta o status",IF(G12="Cancelada","Cancelada",IF(G12="Concluída",IF(H12="","Falta a data de conclusão",IF(H12<=F12,"Concluída no prazo","Concluída com atraso")),IF(F12<IF($D$4="",TODAY(),$D$4),"Atrasada","No prazo"))))))
B13: 5 | K13: =IF(D13="","",IF(F13="","Falta o prazo",IF(G13="","Falta o status",IF(G13="Cancelada","Cancelada",IF(G13="Concluída",IF(H13="","Falta a data de conclusão",IF(H13<=F13,"Concluída no prazo","Concluída com atraso")),IF(F13<IF($D$4="",TODAY(),$D$4),"Atrasada","No prazo"))))))
B14: 6 | K14: =IF(D14="","",IF(F14="","Falta o prazo",IF(G14="","Falta o status",IF(G14="Cancelada","Cancelada",IF(G14="Concluída",IF(H14="","Falta a data de conclusão",IF(H14<=F14,"Concluída no prazo","Concluída com atraso")),IF(F14<IF($D$4="",TODAY(),$D$4),"Atrasada","No prazo"))))))
B15: 7 | K15: =IF(D15="","",IF(F15="","Falta o prazo",IF(G15="","Falta o status",IF(G15="Cancelada","Cancelada",IF(G15="Concluída",IF(H15="","Falta a data de conclusão",IF(H15<=F15,"Concluída no prazo","Concluída com atraso")),IF(F15<IF($D$4="",TODAY(),$D$4),"Atrasada","No prazo"))))))
B16: 8 | K16: =IF(D16="","",IF(F16="","Falta o prazo",IF(G16="","Falta o status",IF(G16="Cancelada","Cancelada",IF(G16="Concluída",IF(H16="","Falta a data de conclusão",IF(H16<=F16,"Concluída no prazo","Concluída com atraso")),IF(F16<IF($D$4="",TODAY(),$D$4),"Atrasada","No prazo"))))))
B17: 9 | K17: =IF(D17="","",IF(F17="","Falta o prazo",IF(G17="","Falta o status",IF(G17="Cancelada","Cancelada",IF(G17="Concluída",IF(H17="","Falta a data de conclusão",IF(H17<=F17,"Concluída no prazo","Concluída com atraso")),IF(F17<IF($D$4="",TODAY(),$D$4),"Atrasada","No prazo"))))))
B18: 10 | K18: =IF(D18="","",IF(F18="","Falta o prazo",IF(G18="","Falta o status",IF(G18="Cancelada","Cancelada",IF(G18="Concluída",IF(H18="","Falta a data de conclusão",IF(H18<=F18,"Concluída no prazo","Concluída com atraso")),IF(F18<IF($D$4="",TODAY(),$D$4),"Atrasada","No prazo"))))))
B19: 11 | K19: =IF(D19="","",IF(F19="","Falta o prazo",IF(G19="","Falta o status",IF(G19="Cancelada","Cancelada",IF(G19="Concluída",IF(H19="","Falta a data de conclusão",IF(H19<=F19,"Concluída no prazo","Concluída com atraso")),IF(F19<IF($D$4="",TODAY(),$D$4),"Atrasada","No prazo"))))))
B20: 12 | K20: =IF(D20="","",IF(F20="","Falta o prazo",IF(G20="","Falta o status",IF(G20="Cancelada","Cancelada",IF(G20="Concluída",IF(H20="","Falta a data de conclusão",IF(H20<=F20,"Concluída no prazo","Concluída com atraso")),IF(F20<IF($D$4="",TODAY(),$D$4),"Atrasada","No prazo"))))))
... B23: 15 | K23: =IF(D23="","",IF(F23="","Falta o prazo",IF(G23="","Falta o status",IF(G23="Cancelada","Cancelada",IF(G23="Concluída",IF(H23="","Falta a data de conclusão",IF(H23<=F23,"Concluída no prazo","Concluída com atraso")),IF(F23<IF($D$4="",TODAY(),$D$4),"Atrasada","No prazo"))))))
B25: Resumo automático | H25: Ações por situação
B26: Ações registradas | E26: =COUNTA(D9:D23) -> 0 | H26: Concluída no prazo | K26: =COUNTIF(K9:K23,"Concluída no prazo") -> 0
B27: Concluídas | E27: =COUNTIF(K9:K23,"Concluída*") -> 0 | H27: Concluída com atraso | K27: =COUNTIF(K9:K23,"Concluída com atraso") -> 0
B28: Percentual concluído, sem as canceladas | E28: =IF(E26-COUNTIF(K9:K23,"Cancelada")=0,"",E27/(E26-COUNTIF(K9:K23,"Cancelada"))) | H28: No prazo | K28: =COUNTIF(K9:K23,"No prazo") -> 0
B29: Atrasadas | E29: =COUNTIF(K9:K23,"Atrasada") -> 0 | H29: Atrasada | K29: =COUNTIF(K9:K23,"Atrasada") -> 0
B30: Concluídas e eficazes | E30: =COUNTIFS(G9:G23,"Concluída",I9:I23,"Sim") -> 0 | H30: Cancelada | K30: =COUNTIF(K9:K23,"Cancelada") -> 0
B31: Aviso | E31: =IF(E26=0,"Sem ações anteriores",IF(COUNTIF(K9:K23,"Falta*")>0,"Há ação com o registro incompleto: veja a coluna Situação",IF(COUNTIFS(G9:G23,"Concluída",I9:I23,"")>0,"Há ação concluída sem avaliação da eficácia",IF(E29>0,"Há ação atrasada: leve à reunião","OK")))) -> Sem ações anteriores

Sheet Entradas
B1: Entradas da análise crítica
B2: As doze entradas que a direção precisa considerar. Preencha antes da reunião. A conclusão é escrita na reunião.
B4: Item | C4: Entrada | D4: O que a direção quer saber | E4: Quem apresenta | F4: Fonte | G4: Resultado no período | H4: Tendência | I4: Situação | J4: Conclusão da direção | K4: Decisões | L4: Conferência
B5: 9.3.2 | C5: Fixa | D5: Fixo | E5: Nome ou cargo | F5: Documento ou sistema | G5: Fatos e números. Se não houver, escreva “nada a relatar” | H5: Escolha na lista | I5: Escolha na lista | J5: Uma frase, escrita na reunião | K5: Da aba Saídas | L5: Calculada
B6: a | C6: Ações das análises anteriores | D6: O que foi decidido nas análises anteriores, e o que foi feito. | K6: =COUNTIF(Saídas!$C$7:$C$21,B6) -> 0 | L6: =IF(COUNTA(E6:J6)=0,"Não analisada",IF(G6="","Falta o resultado",IF(H6="","Falta a tendência",IF(I6="","Falta a situação",IF(J6="","Falta a conclusão",IF(AND(I6="Crítica",K6=0),"Falta a decisão",IF(AND(I6="Atenção",K6=0),"Atenção sem decisão","Completa"))))))) -> Não analisada
B7: b | C7: Mudanças no contexto | D7: O que mudou fora e dentro da organização, e afeta o sistema. | K7: =COUNTIF(Saídas!$C$7:$C$21,B7) -> 0 | L7: =IF(COUNTA(E7:J7)=0,"Não analisada",IF(G7="","Falta o resultado",IF(H7="","Falta a tendência",IF(I7="","Falta a situação",IF(J7="","Falta a conclusão",IF(AND(I7="Crítica",K7=0),"Falta a decisão",IF(AND(I7="Atenção",K7=0),"Atenção sem decisão","Completa"))))))) -> Não analisada
B8: c1 | C8: Satisfação do cliente | D8: O que os clientes e as outras partes interessadas dizem. | K8: =COUNTIF(Saídas!$C$7:$C$21,B8) -> 0 | L8: =IF(COUNTA(E8:J8)=0,"Não analisada",IF(G8="","Falta o resultado",IF(H8="","Falta a tendência",IF(I8="","Falta a situação",IF(J8="","Falta a conclusão",IF(AND(I8="Crítica",K8=0),"Falta a decisão",IF(AND(I8="Atenção",K8=0),"Atenção sem decisão","Completa"))))))) -> Não analisada
B9: c2 | C9: Objetivos da qualidade | D9: Quanto de cada objetivo foi alcançado. | K9: =COUNTIF(Saídas!$C$7:$C$21,B9) -> 0 | L9: =IF(COUNTA(E9:J9)=0,"Não analisada",IF(G9="","Falta o resultado",IF(H9="","Falta a tendência",IF(I9="","Falta a situação",IF(J9="","Falta a conclusão",IF(AND(I9="Crítica",K9=0),"Falta a decisão",IF(AND(I9="Atenção",K9=0),"Atenção sem decisão","Completa"))))))) -> Não analisada
B10: c3 | C10: Processos e produtos | D10: Como os processos se saíram, e se o produto saiu conforme. | K10: =COUNTIF(Saídas!$C$7:$C$21,B10) -> 0 | L10: =IF(COUNTA(E10:J10)=0,"Não analisada",IF(G10="","Falta o resultado",IF(H10="","Falta a tendência",IF(I10="","Falta a situação",IF(J10="","Falta a conclusão",IF(AND(I10="Crítica",K10=0),"Falta a decisão",IF(AND(I10="Atenção",K10=0),"Atenção sem decisão","Completa"))))))) -> Não analisada
B11: c4 | C11: Não conformidades | D11: Quantas houve, de que tipo, e se as ações funcionaram. | K11: =COUNTIF(Saídas!$C$7:$C$21,B11) -> 0 | L11: =IF(COUNTA(E11:J11)=0,"Não analisada",IF(G11="","Falta o resultado",IF(H11="","Falta a tendência",IF(I11="","Falta a situação",IF(J11="","Falta a conclusão",IF(AND(I11="Crítica",K11=0),"Falta a decisão",IF(AND(I11="Atenção",K11=0),"Atenção sem decisão","Completa"))))))) -> Não analisada
B12: c5 | C12: Monitoramento e medição | D12: O que as medições do período mostram. | K12: =COUNTIF(Saídas!$C$7:$C$21,B12) -> 0 | L12: =IF(COUNTA(E12:J12)=0,"Não analisada",IF(G12="","Falta o resultado",IF(H12="","Falta a tendência",IF(I12="","Falta a situação",IF(J12="","Falta a conclusão",IF(AND(I12="Crítica",K12=0),"Falta a decisão",IF(AND(I12="Atenção",K12=0),"Atenção sem decisão","Completa"))))))) -> Não analisada
B13: c6 | C13: Auditorias | D13: O que as auditorias internas e externas constataram. | K13: =COUNTIF(Saídas!$C$7:$C$21,B13) -> 0 | L13: =IF(COUNTA(E13:J13)=0,"Não analisada",IF(G13="","Falta o resultado",IF(H13="","Falta a tendência",IF(I13="","Falta a situação",IF(J13="","Falta a conclusão",IF(AND(I13="Crítica",K13=0),"Falta a decisão",IF(AND(I13="Atenção",K13=0),"Atenção sem decisão","Completa"))))))) -> Não analisada
B14: c7 | C14: Provedores externos | D14: Como os fornecedores e os terceirizados se saíram. | K14: =COUNTIF(Saídas!$C$7:$C$21,B14) -> 0 | L14: =IF(COUNTA(E14:J14)=0,"Não analisada",IF(G14="","Falta o resultado",IF(H14="","Falta a tendência",IF(I14="","Falta a situação",IF(J14="","Falta a conclusão",IF(AND(I14="Crítica",K14=0),"Falta a decisão",IF(AND(I14="Atenção",K14=0),"Atenção sem decisão","Completa"))))))) -> Não analisada
B15: d | C15: Recursos | D15: Se as pessoas, os equipamentos e os sistemas são suficientes. | K15: =COUNTIF(Saídas!$C$7:$C$21,B15) -> 0 | L15: =IF(COUNTA(E15:J15)=0,"Não analisada",IF(G15="","Falta o resultado",IF(H15="","Falta a tendência",IF(I15="","Falta a situação",IF(J15="","Falta a conclusão",IF(AND(I15="Crítica",K15=0),"Falta a decisão",IF(AND(I15="Atenção",K15=0),"Atenção sem decisão","Completa"))))))) -> Não analisada
B16: e | C16: Riscos e oportunidades | D16: Se as ações sobre os riscos e as oportunidades funcionaram. | K16: =COUNTIF(Saídas!$C$7:$C$21,B16) -> 0 | L16: =IF(COUNTA(E16:J16)=0,"Não analisada",IF(G16="","Falta o resultado",IF(H16="","Falta a tendência",IF(I16="","Falta a situação",IF(J16="","Falta a conclusão",IF(AND(I16="Crítica",K16=0),"Falta a decisão",IF(AND(I16="Atenção",K16=0),"Atenção sem decisão","Completa"))))))) -> Não analisada
B17: f | C17: Oportunidades de melhoria | D17: O que pode ser feito melhor, mesmo sem problema. | K17: =COUNTIF(Saídas!$C$7:$C$21,B17) -> 0 | L17: =IF(COUNTA(E17:J17)=0,"Não analisada",IF(G17="","Falta o resultado",IF(H17="","Falta a tendência",IF(I17="","Falta a situação",IF(J17="","Falta a conclusão",IF(AND(I17="Crítica",K17=0),"Falta a decisão",IF(AND(I17="Atenção",K17=0),"Atenção sem decisão","Completa"))))))) -> Não analisada
B19: Resumo automático
B20: Entradas analisadas, de 12 | E20: =SUMPRODUCT((G6:G17<>"")*(I6:I17<>"")*(J6:J17<>"")) -> 0
B21: Favoráveis | E21: =COUNTIF(I6:I17,"Favorável") -> 0
B22: Em atenção | E22: =COUNTIF(I6:I17,"Atenção") -> 0
B23: Críticas | E23: =COUNTIF(I6:I17,"Crítica") -> 0
B24: Com tendência de piora | E24: =COUNTIF(H6:H17,"Piorando") -> 0
B25: Críticas sem decisão | E25: =COUNTIFS(I6:I17,"Crítica",K6:K17,0) -> 0
B26: Aviso | E26: =IF(COUNTIF(L6:L17,"Não analisada")=12,"Preencha as entradas",IF(COUNTIF(L6:L17,"Não analisada")>0,"Há entrada sem análise",IF(COUNTIF(L6:L17,"Falta a decisão")>0,"Há entrada crítica sem decisão: registre na aba Saídas",IF(COUNTIF(L6:L17,"Falta*")>0,"Há entrada com o registro incompleto: veja a coluna Conferência",IF(COUNTIF(L6:L17,"Atenção sem decisão")>0,"Há entrada em atenção sem decisão: confira se o motivo está na conclusão","OK"))))) -> Preencha as entradas

Sheet Saídas
B1: Saídas: decisões e ações
B2: Uma decisão por linha. Comece com verbo, e informe de que entrada a decisão veio.
B4: # | C4: Entrada | D4: Nome da entrada | E4: Tipo | F4: Decisão | G4: Responsável | H4: Prazo | I4: Recurso necessário | J4: Valor | K4: Conferência
C5: Item, de a até f | D5: Da aba Entradas | E5: Escolha na lista | F5: O que será feito | G5: Nome ou cargo | H5: Depois da reunião | I5: Pessoas, equipamento, serviço | J5: Em reais | K5: Calculada
B6: Ex. | C6: c3 | D6: Processos e produtos | E6: Recursos | F6: Aprovar a compra do medidor de espessura em linha para as extrusoras 3 e 4. | G6: Diretor geral | H6: 46568 | I6: Dois medidores, com instalação | J6: 96000 | K6: Completa
B7: 1 | D7: =IF(C7="","",IFERROR(VLOOKUP(C7,Entradas!$B$6:$C$17,2,FALSE()),"Entrada desconhecida")) | K7: =IF(COUNTA(C7,E7:J7)=0,"",IF(F7="","Falta a decisão",IF(C7="","Falta a entrada",IF(D7="Entrada desconhecida","Entrada desconhecida",IF(E7="","Falta o tipo",IF(G7="","Falta o responsável",IF(H7="","Falta o prazo",IF(AND(Reunião!$D$5<>"",H7<Reunião!$D$5),"Prazo anterior à reunião",IF(AND(E7="Recursos",I7="",J7=""),"Falta descrever o recurso","Completa")))))))))
B8: 2 | D8: =IF(C8="","",IFERROR(VLOOKUP(C8,Entradas!$B$6:$C$17,2,FALSE()),"Entrada desconhecida")) | K8: =IF(COUNTA(C8,E8:J8)=0,"",IF(F8="","Falta a decisão",IF(C8="","Falta a entrada",IF(D8="Entrada desconhecida","Entrada desconhecida",IF(E8="","Falta o tipo",IF(G8="","Falta o responsável",IF(H8="","Falta o prazo",IF(AND(Reunião!$D$5<>"",H8<Reunião!$D$5),"Prazo anterior à reunião",IF(AND(E8="Recursos",I8="",J8=""),"Falta descrever o recurso","Completa")))))))))
B9: 3 | D9: =IF(C9="","",IFERROR(VLOOKUP(C9,Entradas!$B$6:$C$17,2,FALSE()),"Entrada desconhecida")) | K9: =IF(COUNTA(C9,E9:J9)=0,"",IF(F9="","Falta a decisão",IF(C9="","Falta a entrada",IF(D9="Entrada desconhecida","Entrada desconhecida",IF(E9="","Falta o tipo",IF(G9="","Falta o responsável",IF(H9="","Falta o prazo",IF(AND(Reunião!$D$5<>"",H9<Reunião!$D$5),"Prazo anterior à reunião",IF(AND(E9="Recursos",I9="",J9=""),"Falta descrever o recurso","Completa")))))))))
B10: 4 | D10: =IF(C10="","",IFERROR(VLOOKUP(C10,Entradas!$B$6:$C$17,2,FALSE()),"Entrada desconhecida")) | K10: =IF(COUNTA(C10,E10:J10)=0,"",IF(F10="","Falta a decisão",IF(C10="","Falta a entrada",IF(D10="Entrada desconhecida","Entrada desconhecida",IF(E10="","Falta o tipo",IF(G10="","Falta o responsável",IF(H10="","Falta o prazo",IF(AND(Reunião!$D$5<>"",H10<Reunião!$D$5),"Prazo anterior à reunião",IF(AND(E10="Recursos",I10="",J10=""),"Falta descrever o recurso","Completa")))))))))
B11: 5 | D11: =IF(C11="","",IFERROR(VLOOKUP(C11,Entradas!$B$6:$C$17,2,FALSE()),"Entrada desconhecida")) | K11: =IF(COUNTA(C11,E11:J11)=0,"",IF(F11="","Falta a decisão",IF(C11="","Falta a entrada",IF(D11="Entrada desconhecida","Entrada desconhecida",IF(E11="","Falta o tipo",IF(G11="","Falta o responsável",IF(H11="","Falta o prazo",IF(AND(Reunião!$D$5<>"",H11<Reunião!$D$5),"Prazo anterior à reunião",IF(AND(E11="Recursos",I11="",J11=""),"Falta descrever o recurso","Completa")))))))))
B12: 6 | D12: =IF(C12="","",IFERROR(VLOOKUP(C12,Entradas!$B$6:$C$17,2,FALSE()),"Entrada desconhecida")) | K12: =IF(COUNTA(C12,E12:J12)=0,"",IF(F12="","Falta a decisão",IF(C12="","Falta a entrada",IF(D12="Entrada desconhecida","Entrada desconhecida",IF(E12="","Falta o tipo",IF(G12="","Falta o responsável",IF(H12="","Falta o prazo",IF(AND(Reunião!$D$5<>"",H12<Reunião!$D$5),"Prazo anterior à reunião",IF(AND(E12="Recursos",I12="",J12=""),"Falta descrever o recurso","Completa")))))))))
B13: 7 | D13: =IF(C13="","",IFERROR(VLOOKUP(C13,Entradas!$B$6:$C$17,2,FALSE()),"Entrada desconhecida")) | K13: =IF(COUNTA(C13,E13:J13)=0,"",IF(F13="","Falta a decisão",IF(C13="","Falta a entrada",IF(D13="Entrada desconhecida","Entrada desconhecida",IF(E13="","Falta o tipo",IF(G13="","Falta o responsável",IF(H13="","Falta o prazo",IF(AND(Reunião!$D$5<>"",H13<Reunião!$D$5),"Prazo anterior à reunião",IF(AND(E13="Recursos",I13="",J13=""),"Falta descrever o recurso","Completa")))))))))
B14: 8 | D14: =IF(C14="","",IFERROR(VLOOKUP(C14,Entradas!$B$6:$C$17,2,FALSE()),"Entrada desconhecida")) | K14: =IF(COUNTA(C14,E14:J14)=0,"",IF(F14="","Falta a decisão",IF(C14="","Falta a entrada",IF(D14="Entrada desconhecida","Entrada desconhecida",IF(E14="","Falta o tipo",IF(G14="","Falta o responsável",IF(H14="","Falta o prazo",IF(AND(Reunião!$D$5<>"",H14<Reunião!$D$5),"Prazo anterior à reunião",IF(AND(E14="Recursos",I14="",J14=""),"Falta descrever o recurso","Completa")))))))))
B15: 9 | D15: =IF(C15="","",IFERROR(VLOOKUP(C15,Entradas!$B$6:$C$17,2,FALSE()),"Entrada desconhecida")) | K15: =IF(COUNTA(C15,E15:J15)=0,"",IF(F15="","Falta a decisão",IF(C15="","Falta a entrada",IF(D15="Entrada desconhecida","Entrada desconhecida",IF(E15="","Falta o tipo",IF(G15="","Falta o responsável",IF(H15="","Falta o prazo",IF(AND(Reunião!$D$5<>"",H15<Reunião!$D$5),"Prazo anterior à reunião",IF(AND(E15="Recursos",I15="",J15=""),"Falta descrever o recurso","Completa")))))))))
B16: 10 | D16: =IF(C16="","",IFERROR(VLOOKUP(C16,Entradas!$B$6:$C$17,2,FALSE()),"Entrada desconhecida")) | K16: =IF(COUNTA(C16,E16:J16)=0,"",IF(F16="","Falta a decisão",IF(C16="","Falta a entrada",IF(D16="Entrada desconhecida","Entrada desconhecida",IF(E16="","Falta o tipo",IF(G16="","Falta o responsável",IF(H16="","Falta o prazo",IF(AND(Reunião!$D$5<>"",H16<Reunião!$D$5),"Prazo anterior à reunião",IF(AND(E16="Recursos",I16="",J16=""),"Falta descrever o recurso","Completa")))))))))
B17: 11 | D17: =IF(C17="","",IFERROR(VLOOKUP(C17,Entradas!$B$6:$C$17,2,FALSE()),"Entrada desconhecida")) | K17: =IF(COUNTA(C17,E17:J17)=0,"",IF(F17="","Falta a decisão",IF(C17="","Falta a entrada",IF(D17="Entrada desconhecida","Entrada desconhecida",IF(E17="","Falta o tipo",IF(G17="","Falta o responsável",IF(H17="","Falta o prazo",IF(AND(Reunião!$D$5<>"",H17<Reunião!$D$5),"Prazo anterior à reunião",IF(AND(E17="Recursos",I17="",J17=""),"Falta descrever o recurso","Completa")))))))))
B18: 12 | D18: =IF(C18="","",IFERROR(VLOOKUP(C18,Entradas!$B$6:$C$17,2,FALSE()),"Entrada desconhecida")) | K18: =IF(COUNTA(C18,E18:J18)=0,"",IF(F18="","Falta a decisão",IF(C18="","Falta a entrada",IF(D18="Entrada desconhecida","Entrada desconhecida",IF(E18="","Falta o tipo",IF(G18="","Falta o responsável",IF(H18="","Falta o prazo",IF(AND(Reunião!$D$5<>"",H18<Reunião!$D$5),"Prazo anterior à reunião",IF(AND(E18="Recursos",I18="",J18=""),"Falta descrever o recurso","Completa")))))))))
... B21: 15 | D21: =IF(C21="","",IFERROR(VLOOKUP(C21,Entradas!$B$6:$C$17,2,FALSE()),"Entrada desconhecida")) | K21: =IF(COUNTA(C21,E21:J21)=0,"",IF(F21="","Falta a decisão",IF(C21="","Falta a entrada",IF(D21="Entrada desconhecida","Entrada desconhecida",IF(E21="","Falta o tipo",IF(G21="","Falta o responsável",IF(H21="","Falta o prazo",IF(AND(Reunião!$D$5<>"",H21<Reunião!$D$5),"Prazo anterior à reunião",IF(AND(E21="Recursos",I21="",J21=""),"Falta descrever o recurso","Completa")))))))))
B23: Resumo automático
B24: Decisões registradas | E24: =COUNTA(F7:F21) -> 0
B25: De melhoria | E25: =COUNTIF(E7:E21,"Melhoria") -> 0
B26: De mudança no sistema | E26: =COUNTIF(E7:E21,"Mudança no sistema") -> 0
B27: De recursos | E27: =COUNTIF(E7:E21,"Recursos") -> 0
B28: Valor total aprovado | E28: =SUM(J7:J21) -> 0
B29: Aviso | E29: =IF(E24=0,"Registre as decisões",IF(COUNTIF(K7:K21,"Falta*")+COUNTIF(K7:K21,"Prazo*")>0,"Há decisão com o registro incompleto: veja a coluna Conferência",IF(COUNTIF(D7:D21,"Entrada desconhecida")>0,"Há decisão com entrada desconhecida: use os itens de a até f",IF(Entradas!E25>0,"Há entrada crítica sem decisão","OK")))) -> Registre as decisões

Sheet Checklist
B1: Checklist da análise crítica
B2: Escolha o status de cada item na lista suspensa (coluna em amarelo-claro).
B4: # | C4: Item de verificação | D4: Status | E4: Observações
B5: 1 | C5: A análise crítica está no calendário, com intervalo definido.
B6: 2 | C6: A alta direção conduz a reunião e participa dela.
B7: 3 | C7: A pauta traz todas as entradas que a norma pede.
B8: 4 | C8: As entradas foram enviadas aos participantes antes da reunião.
B9: 5 | C9: As ações das análises anteriores foram conferidas, uma a uma.
B10: 6 | C10: Cada entrada traz fatos e dados, com a tendência do período.
B11: 7 | C11: Cada entrada tem uma conclusão escrita.
B12: 8 | C12: As decisões tratam de melhoria, de mudanças no sistema e de recursos.
B13: 9 | C13: Cada decisão tem responsável e prazo.
B14: 10 | C14: Os recursos necessários foram aprovados na própria reunião.
B15: 11 | C15: A ata registra a avaliação do sistema: adequado, suficiente, eficaz e alinhado.
B16: 12 | C16: A ata foi guardada, e as decisões são acompanhadas até o fim.
B18: Resumo automático
B19: Itens atendidos (Sim) | D19: =COUNTIF(D5:D16,"Sim") -> 0
B20: Itens parciais | D20: =COUNTIF(D5:D16,"Parcial") -> 0
B21: Itens não atendidos | D21: =COUNTIF(D5:D16,"Não") -> 0
B22: Itens sem resposta | D22: =COUNTBLANK(D5:D16) -> 12
B23: Percentual atendido | D23: =D19/ROWS(D5:D16) -> 0
B24: Situação | D24: =IF(D19=ROWS(D5:D16),"Validado",IF(D22>0,"Em andamento","Com pendências")) -> Em andamento

Sheet Exemplo 1 - Pizzaria
B1: Análise crítica pela direção
B2: Exemplo preenchido, para consulta. Use as abas Reunião, Ações anteriores, Entradas e Saídas para a sua análise.
B4: Organização | D4: Pizzaria (loja com salão e delivery)
B5: Data da reunião | D5: 46370
B6: Período analisado | D6: Janeiro a novembro de 2026
B7: Participantes | D7: Dono da loja, Gerente da loja, Atendente líder, Pizzaiolo líder, Líder da expedição.
B8: Análise anterior | D8: Não houve: é a primeira análise crítica.
B9: Origem | D9: Lacuna do requisito 9.3 no diagnóstico de 02/10/2026: a loja nunca tinha feito análise crítica.
B11: Entradas analisadas
B12: Item | C12: Entrada | D12: Quem apresenta | E12: Resultado no período | F12: Tendência | G12: Situação | H12: Conclusão da direção | I12: Decisões | J12: Conferência
B13: a | C13: Ações das análises anteriores | D13: Gerente da loja | E13: Primeira análise crítica: não há ações anteriores. O ponto de partida é o diagnóstico, com 67% de atendimento. | F13: Sem histórico | G13: Atenção | H13: As lacunas do diagnóstico entram nesta pauta, cada uma na sua entrada. | I13: =COUNTIF($C$28:$C$35,B13&" ·*") -> 1 | J13: =IF(COUNTA(D13:H13)=0,"Não analisada",IF(E13="","Falta o resultado",IF(F13="","Falta a tendência",IF(G13="","Falta a situação",IF(H13="","Falta a conclusão",IF(AND(G13="Crítica",I13=0),"Falta a decisão",IF(AND(G13="Atenção",I13=0),"Atenção sem decisão","Completa"))))))) -> Completa
B14: b | C14: Mudanças no contexto | D14: Dono da loja | E14: Sistema de pedidos trocado em julho. Duas pizzarias novas no bairro. Preço do queijo em alta. | F14: Estável | G14: Atenção | H14: A concorrência pede atenção ao salão, que não tem padrão de atendimento. | I14: =COUNTIF($C$28:$C$35,B14&" ·*") -> 1 | J14: =IF(COUNTA(D14:H14)=0,"Não analisada",IF(E14="","Falta o resultado",IF(F14="","Falta a tendência",IF(G14="","Falta a situação",IF(H14="","Falta a conclusão",IF(AND(G14="Crítica",I14=0),"Falta a decisão",IF(AND(G14="Atenção",I14=0),"Atenção sem decisão","Completa"))))))) -> Completa
B15: c1 | C15: Satisfação do cliente | D15: Atendente líder | E15: Reclamações por 100 pedidos: 3,4 em outubro de 2025 e 1,7 em novembro de 2026. Não há pesquisa de satisfação. | F15: Melhorando | G15: Atenção | H15: A reclamação caiu, mas a loja só ouve quem reclama. | I15: =COUNTIF($C$28:$C$35,B15&" ·*") -> 1 | J15: =IF(COUNTA(D15:H15)=0,"Não analisada",IF(E15="","Falta o resultado",IF(F15="","Falta a tendência",IF(G15="","Falta a situação",IF(H15="","Falta a conclusão",IF(AND(G15="Crítica",I15=0),"Falta a decisão",IF(AND(G15="Atenção",I15=0),"Atenção sem decisão","Completa"))))))) -> Completa
B16: c2 | C16: Objetivos da qualidade | D16: Gerente da loja | E16: Entregas em até 40 minutos: 95% em novembro, para uma meta de 95%. Os quatro indicadores estão na meta. | F16: Melhorando | G16: Favorável | H16: Os objetivos do delivery foram alcançados. Manter. | I16: =COUNTIF($C$28:$C$35,B16&" ·*") -> 0 | J16: =IF(COUNTA(D16:H16)=0,"Não analisada",IF(E16="","Falta o resultado",IF(F16="","Falta a tendência",IF(G16="","Falta a situação",IF(H16="","Falta a conclusão",IF(AND(G16="Crítica",I16=0),"Falta a decisão",IF(AND(G16="Atenção",I16=0),"Atenção sem decisão","Completa"))))))) -> Completa
B17: c3 | C17: Processos e produtos | D17: Gerente da loja | E17: 63% dos elementos dos processos estão definidos. Quatro processos não têm indicador. O salão não tem padrão. | F17: Sem histórico | G17: Atenção | H17: O sistema cobre bem o delivery, e pouco o restante da loja. | I17: =COUNTIF($C$28:$C$35,B17&" ·*") -> 1 | J17: =IF(COUNTA(D17:H17)=0,"Não analisada",IF(E17="","Falta o resultado",IF(F17="","Falta a tendência",IF(G17="","Falta a situação",IF(H17="","Falta a conclusão",IF(AND(G17="Crítica",I17=0),"Falta a decisão",IF(AND(G17="Atenção",I17=0),"Atenção sem decisão","Completa"))))))) -> Completa
B18: c4 | C18: Não conformidades | D18: Gerente da loja | E18: Três registros abertos pela auditoria 2026-03. O RNC 2026-05 foi encerrado como eficaz. Os outros dois estão em verificação. | F18: Sem histórico | G18: Favorável | H18: O tratamento funciona. Manter. | I18: =COUNTIF($C$28:$C$35,B18&" ·*") -> 0 | J18: =IF(COUNTA(D18:H18)=0,"Não analisada",IF(E18="","Falta o resultado",IF(F18="","Falta a tendência",IF(G18="","Falta a situação",IF(H18="","Falta a conclusão",IF(AND(G18="Crítica",I18=0),"Falta a decisão",IF(AND(G18="Atenção",I18=0),"Atenção sem decisão","Completa"))))))) -> Completa
B19: c5 | C19: Monitoramento e medição | D19: Pizzaiolo líder | E19: Temperatura registrada em todos os turnos desde outubro. Pedidos refeitos: 2,0% em setembro e 1,4% em novembro. | F19: Melhorando | G19: Favorável | H19: As medições são feitas e usadas. Manter. | I19: =COUNTIF($C$28:$C$35,B19&" ·*") -> 0 | J19: =IF(COUNTA(D19:H19)=0,"Não analisada",IF(E19="","Falta o resultado",IF(F19="","Falta a tendência",IF(G19="","Falta a situação",IF(H19="","Falta a conclusão",IF(AND(G19="Crítica",I19=0),"Falta a decisão",IF(AND(G19="Atenção",I19=0),"Atenção sem decisão","Completa"))))))) -> Completa
B20: c6 | C20: Auditorias | D20: Atendente líder | E20: A auditoria 2026-03, no delivery: três não conformidades menores. O salão e as compras nunca foram auditados. | F20: Sem histórico | G20: Atenção | H20: O programa de auditoria precisa cobrir os outros processos. | I20: =COUNTIF($C$28:$C$35,B20&" ·*") -> 1 | J20: =IF(COUNTA(D20:H20)=0,"Não analisada",IF(E20="","Falta o resultado",IF(F20="","Falta a tendência",IF(G20="","Falta a situação",IF(H20="","Falta a conclusão",IF(AND(G20="Crítica",I20=0),"Falta a decisão",IF(AND(G20="Atenção",I20=0),"Atenção sem decisão","Completa"))))))) -> Completa
B21: c7 | C21: Provedores externos | D21: Gerente da loja | E21: O fornecedor de queijo atrasou três entregas no ano. O segundo fornecedor foi homologado em novembro. Não há avaliação registrada. | F21: Melhorando | G21: Atenção | H21: O desempenho dos fornecedores é conhecido de memória, sem registro. | I21: =COUNTIF($C$28:$C$35,B21&" ·*") -> 1 | J21: =IF(COUNTA(D21:H21)=0,"Não analisada",IF(E21="","Falta o resultado",IF(F21="","Falta a tendência",IF(G21="","Falta a situação",IF(H21="","Falta a conclusão",IF(AND(G21="Crítica",I21=0),"Falta a decisão",IF(AND(G21="Atenção",I21=0),"Atenção sem decisão","Completa"))))))) -> Completa
B22: d | C22: Recursos | D22: Dono da loja | E22: Nas noites de sexta e de sábado, o atendente do delivery também atende o salão. As motos e o forno atendem à demanda. | F22: Estável | G22: Atenção | H22: Falta uma pessoa no salão nas noites de pico. | I22: =COUNTIF($C$28:$C$35,B22&" ·*") -> 1 | J22: =IF(COUNTA(D22:H22)=0,"Não analisada",IF(E22="","Falta o resultado",IF(F22="","Falta a tendência",IF(G22="","Falta a situação",IF(H22="","Falta a conclusão",IF(AND(G22="Crítica",I22=0),"Falta a decisão",IF(AND(G22="Atenção",I22=0),"Atenção sem decisão","Completa"))))))) -> Completa
B23: e | C23: Riscos e oportunidades | D23: Gerente da loja | E23: Sete riscos com ação: seis ações concluídas. O treinamento do segundo pizzaiolo, do risco R6, está atrasado. | F23: Sem histórico | G23: Atenção | H23: As ações funcionaram nas duas noites de chuva de novembro. Falta concluir a do risco R6. | I23: =COUNTIF($C$28:$C$35,B23&" ·*") -> 1 | J23: =IF(COUNTA(D23:H23)=0,"Não analisada",IF(E23="","Falta o resultado",IF(F23="","Falta a tendência",IF(G23="","Falta a situação",IF(H23="","Falta a conclusão",IF(AND(G23="Crítica",I23=0),"Falta a decisão",IF(AND(G23="Atenção",I23=0),"Atenção sem decisão","Completa"))))))) -> Completa
B24: f | C24: Oportunidades de melhoria | D24: Todos | E24: Três sugestões: pesquisa de satisfação na caixa, cardápio com fotos no salão e pedido por aplicativo de mensagens com roteiro. | F24: Sem histórico | G24: Favorável | H24: A pesquisa de satisfação entra como decisão. As outras duas ficam para junho. | I24: =COUNTIF($C$28:$C$35,B24&" ·*") -> 0 | J24: =IF(COUNTA(D24:H24)=0,"Não analisada",IF(E24="","Falta o resultado",IF(F24="","Falta a tendência",IF(G24="","Falta a situação",IF(H24="","Falta a conclusão",IF(AND(G24="Crítica",I24=0),"Falta a decisão",IF(AND(G24="Atenção",I24=0),"Atenção sem decisão","Completa"))))))) -> Completa
B26: Saídas: decisões e ações
B27: Nº | C27: Entrada | D27: Tipo | E27: Decisão | F27: Responsável | H27: Recurso necessário | I27: Prazo | J27: Valor
B28: 1 | C28: a · Ações das análises anteriores | D28: Mudança no sistema | E28: Fazer a análise crítica a cada seis meses, com a pauta das doze entradas. | F28: Dono da loja | I28: 46552
B29: 2 | C29: b · Mudanças no contexto | D29: Mudança no sistema | E29: Descrever o atendimento no salão, com SIPOC e padrão de atendimento. | F29: Gerente da loja | I29: 46444
B30: 3 | C30: c1 · Satisfação do cliente | D30: Melhoria | E30: Criar uma pesquisa de satisfação de três perguntas, com acesso pelo código impresso na caixa. | F30: Atendente líder | H30: Impressão das etiquetas | I30: 46416 | J30: 300
B31: 4 | C31: c3 · Processos e produtos | D31: Mudança no sistema | E31: Definir indicador e meta para os quatro processos que não têm. | F31: Gerente da loja | I31: 46444
B32: 5 | C32: c6 · Auditorias | D32: Mudança no sistema | E32: Aprovar o programa de auditoria de 2027, com o salão e as compras. | F32: Gerente da loja | I32: 46402
B33: 6 | C33: c7 · Provedores externos | D33: Mudança no sistema | E33: Avaliar os fornecedores de insumos críticos a cada semestre, com registro. | F33: Gerente da loja | I33: 46416
B34: 7 | C34: d · Recursos | D34: Recursos | E34: Contratar um atendente de salão para as noites de sexta e de sábado. | F34: Dono da loja | H34: Um atendente, duas noites por semana, por seis meses | I34: 46416 | J34: 10800
B35: 8 | C35: e · Riscos e oportunidades | D35: Melhoria | E35: Treinar o segundo pizzaiolo na regulagem do forno, como previsto no risco R6. | F35: Pizzaiolo líder | H35: Oito horas de treinamento | I35: 46409
B37: Avaliação do sistema
B38: Critério | D38: Pergunta | F38: Resposta | G38: Justificativa
B39: Adequado | D39: O sistema serve para a organização como ela é hoje? | F39: Sim | G39: Os padrões descrevem o que a loja faz no delivery.
B40: Suficiente | D40: O sistema cobre tudo o que precisa cobrir? | F40: Parcial | G40: O salão, as compras e o treinamento ainda estão fora do sistema.
B41: Eficaz | D41: O sistema entrega os resultados planejados? | F41: Parcial | G41: Eficaz no delivery. Nos outros processos, não há indicador para dizer.
B42: Alinhado | D42: O sistema aponta para onde a direção quer ir? | F42: Sim | G42: Os objetivos apoiam a estratégia de crescer no delivery sem perder o salão.
B44: Resumo automático
B45: Entradas analisadas, de 12 | E45: =SUMPRODUCT((E13:E24<>"")*(G13:G24<>"")*(H13:H24<>"")) -> 12
...

Sheet Exemplo 2 - Indústria
B1: Análise crítica pela direção
B2: Exemplo preenchido, para consulta. Use as abas Reunião, Ações anteriores, Entradas e Saídas para a sua análise.
B4: Organização | D4: Indústria de embalagens plásticas
B5: Data da reunião | D5: 46436
B6: Período analisado | D6: Julho a dezembro de 2026, com o fechamento do ano
B7: Participantes | D7: Diretor geral, Gerente industrial, Gerente comercial, Gerente de Suprimentos, Gerente de RH, Coordenador da Qualidade.
B8: Análise anterior | D8: 46247
B9: Origem | D9: Calendário do sistema de gestão: análise crítica em fevereiro e em agosto.
B11: Entrada “a” · ações das análises anteriores
B12: Nº | C12: Data da análise | D12: Responsável | E12: Ação decidida | F12: Prazo | G12: Concluída em | H12: Eficácia e resultado | I12: Status | J12: Situação
B13: 1 | C13: 46065 | D13: Supervisor de manutenção | E13: Implantar a manutenção preventiva das extrusoras. | F13: 46203 | G13: 46199 | H13: Eficaz: sim. Paradas por quebra: de 14 para 5 por mês. | I13: Concluída | J13: =IF(E13="","",IF(F13="","Falta o prazo",IF(I13="","Falta o status",IF(I13="Cancelada","Cancelada",IF(I13="Concluída",IF(G13="","Falta a data de conclusão",IF(G13<=F13,"Concluída no prazo","Concluída com atraso")),IF(F13<$D$5,"Atrasada","No prazo")))))) -> Concluída no prazo
B14: 2 | C14: 46065 | D14: Gerente de RH | E14: Contratar um analista para o Laboratório. | F14: 46142 | G14: 46157 | H14: Eficaz: sim. Admissão em 15/05. | I14: Concluída | J14: =IF(E14="","",IF(F14="","Falta o prazo",IF(I14="","Falta o status",IF(I14="Cancelada","Cancelada",IF(I14="Concluída",IF(G14="","Falta a data de conclusão",IF(G14<=F14,"Concluída no prazo","Concluída com atraso")),IF(F14<$D$5,"Atrasada","No prazo")))))) -> Concluída com atraso
B15: 3 | C15: 46065 | D15: Gerente industrial | E15: Abrir um projeto de redução do refugo, com ciclo PDCA. | F15: 46112 | G15: 46101 | H15: Eficaz: parcial. Refugo de 3,4% para 2,6%. A meta é 2,0%. | I15: Concluída | J15: =IF(E15="","",IF(F15="","Falta o prazo",IF(I15="","Falta o status",IF(I15="Cancelada","Cancelada",IF(I15="Concluída",IF(G15="","Falta a data de conclusão",IF(G15<=F15,"Concluída no prazo","Concluída com atraso")),IF(F15<$D$5,"Atrasada","No prazo")))))) -> Concluída no prazo
B16: 4 | C16: 46065 | D16: Gerente comercial | E16: Rever a pesquisa de satisfação do cliente. | F16: 46171 | G16: 46170 | H16: Eficaz: sim. Pesquisa aplicada em novembro, com 41 respostas. | I16: Concluída | J16: =IF(E16="","",IF(F16="","Falta o prazo",IF(I16="","Falta o status",IF(I16="Cancelada","Cancelada",IF(I16="Concluída",IF(G16="","Falta a data de conclusão",IF(G16<=F16,"Concluída no prazo","Concluída com atraso")),IF(F16<$D$5,"Atrasada","No prazo")))))) -> Concluída no prazo
B17: 5 | C17: 46247 | D17: Coordenador da Qualidade | E17: Treinar os auditores internos nas diretrizes da ISO 19011. | F17: 46295 | G17: 46276 | H17: Eficaz: sim. Seis auditores treinados. | I17: Concluída | J17: =IF(E17="","",IF(F17="","Falta o prazo",IF(I17="","Falta o status",IF(I17="Cancelada","Cancelada",IF(I17="Concluída",IF(G17="","Falta a data de conclusão",IF(G17<=F17,"Concluída no prazo","Concluída com atraso")),IF(F17<$D$5,"Atrasada","No prazo")))))) -> Concluída no prazo
B18: 6 | C18: 46247 | D18: Coordenador da Qualidade | E18: Atualizar o mapa de processos com a nova linha de produção. | F18: 46356 | G18: 46315 | H18: Eficaz: sim. Mapa rev. 4. | I18: Concluída | J18: =IF(E18="","",IF(F18="","Falta o prazo",IF(I18="","Falta o status",IF(I18="Cancelada","Cancelada",IF(I18="Concluída",IF(G18="","Falta a data de conclusão",IF(G18<=F18,"Concluída no prazo","Concluída com atraso")),IF(F18<$D$5,"Atrasada","No prazo")))))) -> Concluída no prazo
B19: 7 | C19: 46247 | D19: Gerente de engenharia | E19: Orçar os medidores de espessura em linha para as extrusoras 3 e 4. | F19: 46356 | H19: Orçamento recebido. Compra não aprovada. | I19: Em andamento | J19: =IF(E19="","",IF(F19="","Falta o prazo",IF(I19="","Falta o status",IF(I19="Cancelada","Cancelada",IF(I19="Concluída",IF(G19="","Falta a data de conclusão",IF(G19<=F19,"Concluída no prazo","Concluída com atraso")),IF(F19<$D$5,"Atrasada","No prazo")))))) -> Atrasada
B20: 8 | C20: 46247 | D20: Gerente comercial | E20: Definir o indicador de prazo de entrega por cliente. | F20: 46325 | I20: Não iniciada | J20: =IF(E20="","",IF(F20="","Falta o prazo",IF(I20="","Falta o status",IF(I20="Cancelada","Cancelada",IF(I20="Concluída",IF(G20="","Falta a data de conclusão",IF(G20<=F20,"Concluída no prazo","Concluída com atraso")),IF(F20<$D$5,"Atrasada","No prazo")))))) -> Atrasada
B22: Ações por situação
B23: Concluída no prazo | E23: =COUNTIF(J13:J20,"Concluída no prazo") -> 5
B24: Concluída com atraso | E24: =COUNTIF(J13:J20,"Concluída com atraso") -> 1
B25: No prazo | E25: =COUNTIF(J13:J20,"No prazo") -> 0
B26: Atrasada | E26: =COUNTIF(J13:J20,"Atrasada") -> 2
B27: Cancelada | E27: =COUNTIF(J13:J20,"Cancelada") -> 0
B28: Percentual concluído, sem as canceladas | E28: =(E23+E24)/(SUM(E23:E27)-E27) -> 0.75
B34: Entradas analisadas
B35: Item | C35: Entrada | D35: Quem apresenta | E35: Resultado no período | F35: Tendência | G35: Situação | H35: Conclusão da direção | I35: Decisões | J35: Conferência
B36: a | C36: Ações das análises anteriores | D36: Coordenador da Qualidade | E36: Oito ações decididas em 2026: seis concluídas, uma delas com atraso, e duas atrasadas. | F36: Melhorando | G36: Atenção | H36: As duas ações atrasadas dependem de decisão da direção. | I36: =COUNTIF($C$51:$C$60,B36&" ·*") -> 1 | J36: =IF(COUNTA(D36:H36)=0,"Não analisada",IF(E36="","Falta o resultado",IF(F36="","Falta a tendência",IF(G36="","Falta a situação",IF(H36="","Falta a conclusão",IF(AND(G36="Crítica",I36=0),"Falta a decisão",IF(AND(G36="Atenção",I36=0),"Atenção sem decisão","Completa"))))))) -> Completa
B37: b | C37: Mudanças no contexto | D37: Diretor geral | E37: Extrusora 4 em operação desde setembro. Dois grandes clientes passam a exigir a certificação ISO 9001. Preço da resina ligado ao dólar. | F37: Estável | G37: Atenção | H37: A certificação deixou de ser um projeto e virou condição de venda. | I37: =COUNTIF($C$51:$C$60,B37&" ·*") -> 1 | J37: =IF(COUNTA(D37:H37)=0,"Não analisada",IF(E37="","Falta o resultado",IF(F37="","Falta a tendência",IF(G37="","Falta a situação",IF(H37="","Falta a conclusão",IF(AND(G37="Crítica",I37=0),"Falta a decisão",IF(AND(G37="Atenção",I37=0),"Atenção sem decisão","Completa"))))))) -> Completa
B38: c1 | C38: Satisfação do cliente | D38: Gerente comercial | E38: Nota da pesquisa: 8,4, para uma meta de 8,0. Reclamações por milhão de peças: 62, para um máximo de 50. Um só cliente fez 40% das reclamações. | F38: Estável | G38: Atenção | H38: A satisfação geral é boa. O problema está concentrado em um cliente. | I38: =COUNTIF($C$51:$C$60,B38&" ·*") -> 1 | J38: =IF(COUNTA(D38:H38)=0,"Não analisada",IF(E38="","Falta o resultado",IF(F38="","Falta a tendência",IF(G38="","Falta a situação",IF(H38="","Falta a conclusão",IF(AND(G38="Crítica",I38=0),"Falta a decisão",IF(AND(G38="Atenção",I38=0),"Atenção sem decisão","Completa"))))))) -> Completa
B39: c2 | C39: Objetivos da qualidade | D39: Coordenador da Qualidade | E39: Cinco objetivos: três na meta, um em atenção e um fora da meta. O refugo fechou o ano em 2,6%, para um máximo de 2,0%. | F39: Melhorando | G39: Atenção | H39: O objetivo de refugo não foi alcançado pelo segundo ano. | I39: =COUNTIF($C$51:$C$60,B39&" ·*") -> 1 | J39: =IF(COUNTA(D39:H39)=0,"Não analisada",IF(E39="","Falta o resultado",IF(F39="","Falta a tendência",IF(G39="","Falta a situação",IF(H39="","Falta a conclusão",IF(AND(G39="Crítica",I39=0),"Falta a decisão",IF(AND(G39="Atenção",I39=0),"Atenção sem decisão","Completa"))))))) -> Completa
B40: c3 | C40: Processos e produtos | D40: Gerente industrial | E40: Refugo acima da meta nos doze meses. Lotes reprovados na inspeção final: 1,1%. A variação de espessura é a primeira causa, nas extrusoras 3 e 4. | F40: Melhorando | G40: Crítica | H40: O ciclo PDCA reduziu o refugo, mas a causa principal depende de equipamento. | I40: =COUNTIF($C$51:$C$60,B40&" ·*") -> 1 | J40: =IF(COUNTA(D40:H40)=0,"Não analisada",IF(E40="","Falta o resultado",IF(F40="","Falta a tendência",IF(G40="","Falta a situação",IF(H40="","Falta a conclusão",IF(AND(G40="Crítica",I40=0),"Falta a decisão",IF(AND(G40="Atenção",I40=0),"Atenção sem decisão","Completa"))))))) -> Completa
B41: c4 | C41: Não conformidades | D41: Coordenador da Qualidade | E41: 38 registros em 2026: 30 encerrados, 27 deles como eficazes, e 8 em tratamento. O prazo médio de encerramento foi de 74 dias. | F41: Estável | G41: Atenção | H41: O tratamento é eficaz, mas lento. Dois registros têm prazo vencido. | I41: =COUNTIF($C$51:$C$60,B41&" ·*") -> 1 | J41: =IF(COUNTA(D41:H41)=0,"Não analisada",IF(E41="","Falta o resultado",IF(F41="","Falta a tendência",IF(G41="","Falta a situação",IF(H41="","Falta a conclusão",IF(AND(G41="Crítica",I41=0),"Falta a decisão",IF(AND(G41="Atenção",I41=0),"Atenção sem decisão","Completa"))))))) -> Completa
B42: c5 | C42: Monitoramento e medição | D42: Coordenador da Qualidade | E42: Painel com 18 indicadores: 12 na meta, 4 em atenção e 2 fora da meta. Instrumentos calibrados no prazo: 100%. | F42: Estável | G42: Favorável | H42: As medições são feitas e analisadas todo mês. Manter. | I42: =COUNTIF($C$51:$C$60,B42&" ·*") -> 0 | J42: =IF(COUNTA(D42:H42)=0,"Não analisada",IF(E42="","Falta o resultado",IF(F42="","Falta a tendência",IF(G42="","Falta a situação",IF(H42="","Falta a conclusão",IF(AND(G42="Crítica",I42=0),"Falta a decisão",IF(AND(G42="Atenção",I42=0),"Atenção sem decisão","Completa"))))))) -> Completa
B43: c6 | C43: Auditorias | D43: Coordenador da Qualidade | E43: Programa cumprido: 12 auditorias, nos 9 processos. Foram 10 não conformidades e 14 oportunidades de melhoria. A Produção teve 3 não conformidades. | F43: Estável | G43: Atenção | H43: A Produção concentra as não conformidades pelo segundo ciclo. | I43: =COUNTIF($C$51:$C$60,B43&" ·*") -> 1 | J43: =IF(COUNTA(D43:H43)=0,"Não analisada",IF(E43="","Falta o resultado",IF(F43="","Falta a tendência",IF(G43="","Falta a situação",IF(H43="","Falta a conclusão",IF(AND(G43="Crítica",I43=0),"Falta a decisão",IF(AND(G43="Atenção",I43=0),"Atenção sem decisão","Completa"))))))) -> Completa
B44: c7 | C44: Provedores externos | D44: Gerente de Suprimentos | E44: Doze fornecedores críticos avaliados: nove aprovados, dois com plano de ação e um reprovado. Nenhuma devolução por item errado desde novembro. | F44: Melhorando | G44: Favorável | H44: As ações do RNC 2026-31 funcionaram. Manter a avaliação semestral. | I44: =COUNTIF($C$51:$C$60,B44&" ·*") -> 0 | J44: =IF(COUNTA(D44:H44)=0,"Não analisada",IF(E44="","Falta o resultado",IF(F44="","Falta a tendência",IF(G44="","Falta a situação",IF(H44="","Falta a conclusão",IF(AND(G44="Crítica",I44=0),"Falta a decisão",IF(AND(G44="Atenção",I44=0),"Atenção sem decisão","Completa"))))))) -> Completa
B45: d | C45: Recursos | D45: Gerente de RH | E45: O Laboratório tem um analista a mais desde maio. A Qualidade tem seis auditores para doze auditorias, e as extrusoras 3 e 4 não têm medidor de espessura. | F45: Estável | G45: Atenção | H45: Faltam auditores e o equipamento de medição. | I45: =COUNTIF($C$51:$C$60,B45&" ·*") -> 1 | J45: =IF(COUNTA(D45:H45)=0,"Não analisada",IF(E45="","Falta o resultado",IF(F45="","Falta a tendência",IF(G45="","Falta a situação",IF(H45="","Falta a conclusão",IF(AND(G45="Crítica",I45=0),"Falta a decisão",IF(AND(G45="Atenção",I45=0),"Atenção sem decisão","Completa"))))))) -> Completa
B46: e | C46: Riscos e oportunidades | D46: Gerente de Suprimentos | E46: Oito riscos: cinco ações concluídas e uma atrasada. O segundo fornecedor de resina, do risco C1, não foi homologado. O risco continua crítico. | F46: Estável | G46: Crítica | H46: Um atraso do fornecedor único para a produção. A homologação depende de ensaios externos. | I46: =COUNTIF($C$51:$C$60,B46&" ·*") -> 1 | J46: =IF(COUNTA(D46:H46)=0,"Não analisada",IF(E46="","Falta o resultado",IF(F46="","Falta a tendência",IF(G46="","Falta a situação",IF(H46="","Falta a conclusão",IF(AND(G46="Crítica",I46=0),"Falta a decisão",IF(AND(G46="Atenção",I46=0),"Atenção sem decisão","Completa"))))))) -> Completa
B47: f | C47: Oportunidades de melhoria | D47: Gerente de engenharia | E47: Três oportunidades em andamento: linha com material reciclado, certificação e resina reciclada de menor custo. | F47: Sem histórico | G47: Favorável | H47: O lote piloto com resina reciclada pode começar no primeiro semestre. | I47: =COUNTIF($C$51:$C$60,B47&" ·*") -> 1 | J47: =IF(COUNTA(D47:H47)=0,"Não analisada",IF(E47="","Falta o resultado",IF(F47="","Falta a tendência",IF(G47="","Falta a situação",IF(H47="","Falta a conclusão",IF(AND(G47="Crítica",I47=0),"Falta a decisão",IF(AND(G47="Atenção",I47=0),"Atenção sem decisão","Completa"))))))) -> Completa
B49: Saídas: decisões e ações
...
